Workbook

Sheet Automatic Bread Maker
A1: Type | B1: Element
A2: State | B2: Initial state (→ Off)
A3: State | B3: Off
A4: Transition | B4: on (Off ⇒ On)
A5: Composite State | B5: On
A6: Transition | B6: on => off
A7: Composite State | B7: Setup
A8: State | B8: Initial state (Setup → Medium)
A9: Action | B9: delay=0; selectFirstCourse()
A10: State | B10: Medium
A11: Transition | B11: setup initial state => medium
A12: Transition | B12: medium => dark
... A56: History State | B56: additional elements

Sheet Automatic Bread Maker Grader #1
A1: Type | B1: Element | C1: Claude | D1: Notes
A2: State | B2: Initial state (→ Off)
A3: State | B3: Off
A4: Transition | B4: on (Off ⇒ On)
A5: Composite State | B5: On
A6: Transition | B6: on => off
A7: Composite State | B7: Setup
A8: State | B8: Initial state (Setup → Medium)
A9: Action | B9: delay=0; selectFirstCourse()
A10: State | B10: Medium
A11: Transition | B11: setup initial state => medium
A12: Transition | B12: medium => dark
A13: State | B13: Dark
... A56: History State | B56: additional elements

Sheet Automatic Bread Maker Grader #2
A1: Type | B1: Element | C1: Claude | D1: Notes
A2: State | B2: Initial state (→ Off)
A3: State | B3: Off
A4: Transition | B4: on (Off ⇒ On)
A5: Composite State | B5: On
A6: Transition | B6: on => off
A7: Composite State | B7: Setup
A8: State | B8: Initial state (Setup → Medium)
A9: Action | B9: delay=0; selectFirstCourse()
A10: State | B10: Medium
A11: Transition | B11: setup initial state => medium
A12: Transition | B12: medium => dark
A13: State | B13: Dark
... A56: History State | B56: additional elements

Sheet Metrics
A1: Claude Grader #1 | J1: Date
A2: Type | B2: Ground Truth Count | C2: True Positive | D2: False Positive | E2: False Negative | F2: Precision | G2: Recall | H2: F1 Score
A3: Composite State | B3: =COUNTIF('Automatic Bread Maker'!$A$2:$A$49, A3) -> 3 | C3: =SUMIF('Automatic Bread Maker Grader #1'!$A$2:$A$49, $A3, 'Automatic Bread Maker Grader #1'!$C$2:$C$49) -> 0 | D3: =SUMIF('Automatic Bread Maker Grader #1'!$A$50:$A$56, $A3, 'Automatic Bread Maker Grader #1'!$C$50:$C$56) -> 0 | E3: =COUNTIFS('Automatic Bread Maker Grader #1'!$A$2:$A$49, $A3, 'Automatic Bread Maker Grader #1'!$C$2:$C$49,0) -> 0 | F3: =IFERROR(C3 / (C3 + D3), "Not Available") -> Not Available | G3: =IFERROR(C3 / B3, "Not Available") -> 0 | H3: =IFERROR(2*((F3*G3)/(F3+G3)),"Not Available") -> Not Available
A4: State | B4: =COUNTIF('Automatic Bread Maker'!$A$2:$A$49, A4) -> 12 | C4: =SUMIF('Automatic Bread Maker Grader #1'!$A$2:$A$49, $A4, 'Automatic Bread Maker Grader #1'!$C$2:$C$49) -> 0 | D4: =SUMIF('Automatic Bread Maker Grader #1'!$A$50:$A$56, $A4, 'Automatic Bread Maker Grader #1'!$C$50:$C$56) -> 0 | E4: =COUNTIFS('Automatic Bread Maker Grader #1'!$A$2:$A$49, $A4, 'Automatic Bread Maker Grader #1'!$C$2:$C$49,0) -> 0 | F4: =IFERROR(C4 / (C4 + D4), "Not Available") -> Not Available | G4: =IFERROR(C4 / B4, "Not Available") -> 0 | H4: =IFERROR(2*((F4*G4)/(F4+G4)),"Not Available") -> Not Available
A5: Transition | B5: =COUNTIF('Automatic Bread Maker'!$A$2:$A$49, A5) -> 18 | C5: =SUMIF('Automatic Bread Maker Grader #1'!$A$2:$A$49, $A5, 'Automatic Bread Maker Grader #1'!$C$2:$C$49) -> 0 | D5: =SUMIF('Automatic Bread Maker Grader #1'!$A$50:$A$56, $A5, 'Automatic Bread Maker Grader #1'!$C$50:$C$56) -> 0 | E5: =COUNTIFS('Automatic Bread Maker Grader #1'!$A$2:$A$49, $A5, 'Automatic Bread Maker Grader #1'!$C$2:$C$49,0) -> 0 | F5: =IFERROR(C5 / (C5 + D5), "Not Available") -> Not Available | G5: =IFERROR(C5 / B5, "Not Available") -> 0 | H5: =IFERROR(2*((F5*G5)/(F5+G5)),"Not Available") -> Not Available
A6: Action | B6: =COUNTIF('Automatic Bread Maker'!$A$2:$A$49, A6) -> 10 | C6: =SUMIF('Automatic Bread Maker Grader #1'!$A$2:$A$49, $A6, 'Automatic Bread Maker Grader #1'!$C$2:$C$49) -> 0 | D6: =SUMIF('Automatic Bread Maker Grader #1'!$A$50:$A$56, $A6, 'Automatic Bread Maker Grader #1'!$C$50:$C$56) -> 0 | E6: =COUNTIFS('Automatic Bread Maker Grader #1'!$A$2:$A$49, $A6, 'Automatic Bread Maker Grader #1'!$C$2:$C$49,0) -> 0 | F6: =IFERROR(C6 / (C6 + D6), "Not Available") -> Not Available | G6: =IFERROR(C6 / B6, "Not Available") -> 0 | H6: =IFERROR(2*((F6*G6)/(F6+G6)),"Not Available") -> Not Available
A7: Region | B7: =COUNTIF('Automatic Bread Maker'!$A$2:$A$49, A7) -> 0 | C7: =SUMIF('Automatic Bread Maker Grader #1'!$A$2:$A$49, $A7, 'Automatic Bread Maker Grader #1'!$C$2:$C$49) -> 0 | D7: =SUMIF('Automatic Bread Maker Grader #1'!$A$50:$A$56, $A7, 'Automatic Bread Maker Grader #1'!$C$50:$C$56) -> 0 | E7: =COUNTIFS('Automatic Bread Maker Grader #1'!$A$2:$A$49, $A7, 'Automatic Bread Maker Grader #1'!$C$2:$C$49,0) -> 0 | F7: =IFERROR(C7 / (C7 + D7), "Not Available") -> Not Available | G7: =IFERROR(C7 / B7, "Not Available") -> Not Available | H7: =IFERROR(2*((F7*G7)/(F7+G7)),"Not Available") -> Not Available
A8: History State | B8: =COUNTIF('Automatic Bread Maker'!$A$2:$A$49, A8) -> 1 | C8: =SUMIF('Automatic Bread Maker Grader #1'!$A$2:$A$49, $A8, 'Automatic Bread Maker Grader #1'!$C$2:$C$49) -> 0 | D8: =SUMIF('Automatic Bread Maker Grader #1'!$A$50:$A$56, $A8, 'Automatic Bread Maker Grader #1'!$C$50:$C$56) -> 0 | E8: =COUNTIFS('Automatic Bread Maker Grader #1'!$A$2:$A$49, $A8, 'Automatic Bread Maker Grader #1'!$C$2:$C$49,0) -> 0 | F8: =IFERROR(C8 / (C8 + D8), "Not Available") -> Not Available | G8: =IFERROR(C8 / B8, "Not Available") -> 0 | H8: =IFERROR(2*((F8*G8)/(F8+G8)),"Not Available") -> Not Available
A9: Guard | B9: =COUNTIF('Automatic Bread Maker'!$A$2:$A$49, A9) -> 4 | C9: =SUMIF('Automatic Bread Maker Grader #1'!$A$2:$A$49, $A9, 'Automatic Bread Maker Grader #1'!$C$2:$C$49) -> 0 | D9: =SUMIF('Automatic Bread Maker Grader #1'!$A$50:$A$56, $A9, 'Automatic Bread Maker Grader #1'!$C$50:$C$56) -> 0 | E9: =COUNTIFS('Automatic Bread Maker Grader #1'!$A$2:$A$49, $A9, 'Automatic Bread Maker Grader #1'!$C$2:$C$49,0) -> 0 | F9: =IFERROR(C9 / (C9 + D9), "Not Available") -> Not Available | G9: =IFERROR(C9 / B9, "Not Available") -> 0 | H9: =IFERROR(2*((F9*G9)/(F9+G9)),"Not Available") -> Not Available
A10: Overall Score | B10: =SUM(B3:B9) -> 48 | C10: =SUM(C3:C9) -> 0 | D10: =SUM(D3:D9) -> 0 | E10: =SUM(E3:E9) -> 0 | F10: =IFERROR(C10 / (C10 + D10), "Not Available") -> Not Available | G10: =IFERROR(C10 / B10, "Not Available") -> 0 | H10: =IFERROR(2*((F10*G10)/(F10+G10)),"Not Available") -> Not Available
A12: Claude Grader #2
A13: Type | B13: Ground Truth Count | C13: True Positive | D13: False Positive | E13: False Negative | F13: Precision | G13: Recall | H13: F1 Score
A14: Composite state | B14: =COUNTIF('Automatic Bread Maker'!$A$2:$A$49, A14) -> 3 | C14: =SUMIF('Automatic Bread Maker Grader #2'!$A$2:$A$49, $A14, 'Automatic Bread Maker Grader #2'!$C$2:$C$49) -> 0 | D14: =SUMIF('Automatic Bread Maker Grader #2'!$A$50:$A$56, $A14, 'Automatic Bread Maker Grader #2'!$C$50:$C$56) -> 0 | E14: =COUNTIFS('Automatic Bread Maker Grader #2'!$A$2:$A$49, $A14, 'Automatic Bread Maker Grader #2'!$C$2:$C$49,0) -> 0 | F14: =IFERROR(C14 / (C14 + D14), "Not Available") -> Not Available | G14: =IFERROR(C14 / B14, "Not Available") -> 0 | H14: =IFERROR(2*((F14*G14)/(F14+G14)),"Not Available") -> Not Available
A15: State | B15: =COUNTIF('Automatic Bread Maker'!$A$2:$A$49, A15) -> 12 | C15: =SUMIF('Automatic Bread Maker Grader #2'!$A$2:$A$49, $A15, 'Automatic Bread Maker Grader #2'!$C$2:$C$49) -> 0 | D15: =SUMIF('Automatic Bread Maker Grader #2'!$A$50:$A$56, $A15, 'Automatic Bread Maker Grader #2'!$C$50:$C$56) -> 0 | E15: =COUNTIFS('Automatic Bread Maker Grader #2'!$A$2:$A$49, $A15, 'Automatic Bread Maker Grader #2'!$C$2:$C$49,0) -> 0 | F15: =IFERROR(C15 / (C15 + D15), "Not Available") -> Not Available | G15: =IFERROR(C15 / B15, "Not Available") -> 0 | H15: =IFERROR(2*((F15*G15)/(F15+G15)),"Not Available") -> Not Available
A16: Transition | B16: =COUNTIF('Automatic Bread Maker'!$A$2:$A$49, A16) -> 18 | C16: =SUMIF('Automatic Bread Maker Grader #2'!$A$2:$A$49, $A16, 'Automatic Bread Maker Grader #2'!$C$2:$C$49) -> 0 | D16: =SUMIF('Automatic Bread Maker Grader #2'!$A$50:$A$56, $A16, 'Automatic Bread Maker Grader #2'!$C$50:$C$56) -> 0 | E16: =COUNTIFS('Automatic Bread Maker Grader #2'!$A$2:$A$49, $A16, 'Automatic Bread Maker Grader #2'!$C$2:$C$49,0) -> 0 | F16: =IFERROR(C16 / (C16 + D16), "Not Available") -> Not Available | G16: =IFERROR(C16 / B16, "Not Available") -> 0 | H16: =IFERROR(2*((F16*G16)/(F16+G16)),"Not Available") -> Not Available
A17: Action | B17: =COUNTIF('Automatic Bread Maker'!$A$2:$A$49, A17) -> 10 | C17: =SUMIF('Automatic Bread Maker Grader #2'!$A$2:$A$49, $A17, 'Automatic Bread Maker Grader #2'!$C$2:$C$49) -> 0 | D17: =SUMIF('Automatic Bread Maker Grader #2'!$A$50:$A$56, $A17, 'Automatic Bread Maker Grader #2'!$C$50:$C$56) -> 0 | E17: =COUNTIFS('Automatic Bread Maker Grader #2'!$A$2:$A$49, $A17, 'Automatic Bread Maker Grader #2'!$C$2:$C$49,0) -> 0 | F17: =IFERROR(C17 / (C17 + D17), "Not Available") -> Not Available | G17: =IFERROR(C17 / B17, "Not Available") -> 0 | H17: =IFERROR(2*((F17*G17)/(F17+G17)),"Not Available") -> Not Available
A18: Region | B18: =COUNTIF('Automatic Bread Maker'!$A$2:$A$49, A18) -> 0 | C18: =SUMIF('Automatic Bread Maker Grader #2'!$A$2:$A$49, $A18, 'Automatic Bread Maker Grader #2'!$C$2:$C$49) -> 0 | D18: =SUMIF('Automatic Bread Maker Grader #2'!$A$50:$A$56, $A18, 'Automatic Bread Maker Grader #2'!$C$50:$C$56) -> 0 | E18: =COUNTIFS('Automatic Bread Maker Grader #2'!$A$2:$A$49, $A18, 'Automatic Bread Maker Grader #2'!$C$2:$C$49,0) -> 0 | F18: =IFERROR(C18 / (C18 + D18), "Not Available") -> Not Available | G18: =IFERROR(C18 / B18, "Not Available") -> Not Available | H18: =IFERROR(2*((F18*G18)/(F18+G18)),"Not Available") -> Not Available
A19: History State | B19: =COUNTIF('Automatic Bread Maker'!$A$2:$A$49, A19) -> 1 | C19: =SUMIF('Automatic Bread Maker Grader #2'!$A$2:$A$49, $A19, 'Automatic Bread Maker Grader #2'!$C$2:$C$49) -> 0 | D19: =SUMIF('Automatic Bread Maker Grader #2'!$A$50:$A$56, $A19, 'Automatic Bread Maker Grader #2'!$C$50:$C$56) -> 0 | E19: =COUNTIFS('Automatic Bread Maker Grader #2'!$A$2:$A$49, $A19, 'Automatic Bread Maker Grader #2'!$C$2:$C$49,0) -> 0 | F19: =IFERROR(C19 / (C19 + D19), "Not Available") -> Not Available | G19: =IFERROR(C19 / B19, "Not Available") -> 0 | H19: =IFERROR(2*((F19*G19)/(F19+G19)),"Not Available") -> Not Available
A20: Guard | B20: =COUNTIF('Automatic Bread Maker'!$A$2:$A$49, A20) -> 4 | C20: =SUMIF('Automatic Bread Maker Grader #2'!$A$2:$A$49, $A20, 'Automatic Bread Maker Grader #2'!$C$2:$C$49) -> 0 | D20: =SUMIF('Automatic Bread Maker Grader #2'!$A$50:$A$56, $A20, 'Automatic Bread Maker Grader #2'!$C$50:$C$56) -> 0 | E20: =COUNTIFS('Automatic Bread Maker Grader #2'!$A$2:$A$49, $A20, 'Automatic Bread Maker Grader #2'!$C$2:$C$49,0) -> 0 | F20: =IFERROR(C20 / (C20 + D20), "Not Available") -> Not Available | G20: =IFERROR(C20 / B20, "Not Available") -> 0 | H20: =IFERROR(2*((F20*G20)/(F20+G20)),"Not Available") -> Not Available
A21: Overall Score | B21: =SUM(B14:B20) -> 48 | C21: =SUM(C14:C20) -> 0 | D21: =SUM(D14:D20) -> 0 | E21: =SUM(E14:E20) -> 0 | F21: =IFERROR(C21 / (C21 + D21), "Not Available") -> Not Available | G21: =IFERROR(C21 / B21, "Not Available") -> 0 | H21: =IFERROR(2*((F21*G21)/(F21+G21)),"Not Available") -> Not Available

Sheet Inter-rater
A1: Type | B1: Element | C1: Rater 1 | D1: Rater 2 | F1: Confusion Matrix | L1: Cohen's Kappa
A2: ='Automatic Bread Maker Grader #1'!A3 -> State | B2: ='Automatic Bread Maker Grader #1'!B3 -> Off | C2: ='Automatic Bread Maker Grader #1'!C3 -> 0 | D2: #REF! | F2: Global | G2: 0 | H2: 0.5 | I2: 1 | J2: Row Totals | L2: Metric | M2: Value | N2: Note
A3: ='Automatic Bread Maker Grader #1'!A4 -> Transition | B3: ='Automatic Bread Maker Grader #1'!B4 -> on (Off ⇒ On) | C3: ='Automatic Bread Maker Grader #1'!C4 -> 0 | D3: #REF! | F3: 0 | G3: =COUNTIFS($C$2:$C$91, $F3, $D$2:$D$91, G$2) -> 0 | H3: =COUNTIFS($C$2:$C$47, $F3, $D$2:$D$47, H$2) -> 0 | I3: =COUNTIFS($C$2:$C$47, $F3, $D$2:$D$47, I$2)+MAX(D48-C48,0)+MAX(D49-C49,0)+MAX(D50-C50,0)+MAX(D51-C51,0)+MAX(D52-C52,0)+MAX(D53-C53,0)+MAX(D54-C54,0) -> #VALUE! | J3: =SUM(G3:I3) -> #VALUE! | L3: Observed Agreement (Po) | M3: =(G3+H4+I5)/COUNTA($C$2:$C$101) -> 0 | N3: This sums the diagonal of your matrix divided by total rows.
A4: ='Automatic Bread Maker Grader #1'!A5 -> Composite State | B4: ='Automatic Bread Maker Grader #1'!B5 -> On | C4: ='Automatic Bread Maker Grader #1'!C5 -> 0 | D4: #REF! | F4: 0.5 | G4: =COUNTIFS($C$2:$C$47, $F4, $D$2:$D$47, G$2) -> 0 | H4: =COUNTIFS($C$2:$C$47, $F4, $D$2:$D$47, H$2) -> 0 | I4: =COUNTIFS($C$2:$C$47, $F4, $D$2:$D$47, I$2) -> 0 | J4: =SUM(G4:I4) -> 0 | L4: Expected Agreement (Pe) | M4: {=SUMPRODUCT(J3:J5/COUNTA($C$2:$C$101), TRANSPOSE(G6:I6)/COUNTA($C$2:$C$101))} -> #VALUE! | N4: This computes the sum of row proportion times column proportion.
A5: ='Automatic Bread Maker Grader #1'!A2 -> State | B5: ='Automatic Bread Maker Grader #1'!B2 -> Initial state (→ Off) | C5: ='Automatic Bread Maker Grader #1'!C2 -> 0 | D5: #REF! | F5: 1 | G5: =COUNTIFS($C$2:$C$47, $F5, $D$2:$D$47, G$2)+MAX(C48-D48,0)+MAX(C49-D49,0)+MAX(C50-D50,0)+MAX(C51-D51,0)+MAX(C52-D52,0)+MAX(C53-D53,0)+MAX(C54-D54,0) -> #VALUE! | H5: =COUNTIFS($C$2:$C$47, $F5, $D$2:$D$47, H$2) -> 0 | I5: =COUNTIFS($C$2:$C$47, $F5, $D$2:$D$47, I$2)+ SUM(MIN(C48,D48), MIN(C49,D49), MIN(C50,D50), MIN(C51,D51), MIN(C52,D52), MIN(C53,D53), MIN(C54,D54)) -> 0 | J5: =SUM(G5:I5) -> #VALUE! | L5: Cohen's Kappa | M5: =(M3-M4)/(1-M4) -> #VALUE! | N5: (Po - Pe) / (1 - Pe)
A6: ='Automatic Bread Maker Grader #1'!A7 -> Composite State | B6: ='Automatic Bread Maker Grader #1'!B7 -> Setup | C6: ='Automatic Bread Maker Grader #1'!C7 -> 0 | D6: #REF! | F6: Column Totals | G6: =SUM(G3:G5) -> #VALUE! | H6: =SUM(H3:H5) -> 0 | I6: =SUM(I3:I5) -> #VALUE!
A7: ='Automatic Bread Maker Grader #1'!A8 -> State | B7: ='Automatic Bread Maker Grader #1'!B8 -> Initial state (Setup → Medium) | C7: ='Automatic Bread Maker Grader #1'!C8 -> 0 | D7: #REF!
A8: ='Automatic Bread Maker Grader #1'!A9 -> Action | B8: ='Automatic Bread Maker Grader #1'!B9 -> delay=0; selectFirstCourse() | C8: ='Automatic Bread Maker Grader #1'!C9 -> 0 | D8: #REF! | F8: Confusion Matrix (State) | L8: Cohen's Kappa (State)
A9: ='Automatic Bread Maker Grader #1'!A10 -> State | B9: ='Automatic Bread Maker Grader #1'!B10 -> Medium | C9: ='Automatic Bread Maker Grader #1'!C10 -> 0 | D9: #REF! | F9: State | G9: 0 | H9: 0.5 | I9: 1 | J9: Row Totals | L9: Metric | M9: Value | N9: Note
A10: ='Automatic Bread Maker Grader #1'!A11 -> Transition | B10: ='Automatic Bread Maker Grader #1'!B11 -> setup initial state => medium | C10: ='Automatic Bread Maker Grader #1'!C11 -> 0 | D10: #REF! | F10: 0 | G10: =COUNTIFS($A$2:$A$91,$F$9,$C$2:$C$91,$F10,$D$2:$D$91,G$9) -> 0 | H10: =COUNTIFS($A$2:$A$91,$F$9,$C$2:$C$91,$F10,$D$2:$D$91,H$9) -> 0 | I10: =COUNTIFS($A$2:$A$47,$F$9,$C$2:$C$47,$F10,$D$2:$D$47,I$9)+MAX(D48-C48,0) -> #VALUE! | J10: =SUM(G10:I10) -> #VALUE! | L10: Observed Agreement (Po) | M10: =(G10+H11+I12)/COUNTIF($A$2:$A$101,F9) -> #VALUE! | N10: This sums the diagonal of your matrix divided by total rows.
A11: ='Automatic Bread Maker Grader #1'!A12 -> Transition | B11: ='Automatic Bread Maker Grader #1'!B12 -> medium => dark | C11: ='Automatic Bread Maker Grader #1'!C12 -> 0 | D11: #REF! | F11: 0.5 | G11: =COUNTIFS($A$2:$A$91,$F$9,$C$2:$C$91,$F11,$D$2:$D$91,G$9) -> 0 | H11: =COUNTIFS($A$2:$A$91,$F$9,$C$2:$C$91,$F11,$D$2:$D$91,H$9) -> 0 | I11: =COUNTIFS($A$2:$A$91,$F$9,$C$2:$C$91,$F11,$D$2:$D$91,I$9) -> 0 | J11: =SUM(G11:I11) -> 0 | L11: Expected Agreement (Pe) | M11: {=SUMPRODUCT(J10:J12/COUNTIF($A$2:$A$101,F9), TRANSPOSE(G13:I13)/COUNTIF($A$2:$A$101,F9))} -> #VALUE! | N11: This computes the sum of row proportion times column proportion.
A12: ='Automatic Bread Maker Grader #1'!A13 -> State | B12: ='Automatic Bread Maker Grader #1'!B13 -> Dark | C12: ='Automatic Bread Maker Grader #1'!C13 -> 0 | D12: #REF! | F12: 1 | G12: =COUNTIFS($A$2:$A$47,$F$9,$C$2:$C$47,$F12,$D$2:$D$47,G$9)+MAX(C48-D48,0) -> #VALUE! | H12: =COUNTIFS($A$2:$A$91,$F$9,$C$2:$C$91,$F12,$D$2:$D$91,H$9) -> 0 | I12: =COUNTIFS($A$2:$A$47,$F$9,$C$2:$C$47,$F12,$D$2:$D$47,I$9)+MIN(C48-D48) -> #VALUE! | J12: =SUM(G12:I12) -> #VALUE! | L12: Cohen's Kappa | M12: =(M10-M11)/(1-M11) -> #VALUE! | N12: (Po - Pe) / (1 - Pe)
A13: ='Automatic Bread Maker Grader #1'!A14 -> Transition | B13: ='Automatic Bread Maker Grader #1'!B14 -> dark => light | C13: ='Automatic Bread Maker Grader #1'!C14 -> 0 | D13: #REF! | F13: Column Totals | G13: =SUM(G10:G12) -> #VALUE! | H13: =SUM(H10:H12) -> 0 | I13: =SUM(I10:I12) -> #VALUE!
A14: ='Automatic Bread Maker Grader #1'!A15 -> State | B14: ='Automatic Bread Maker Grader #1'!B15 -> Light | C14: ='Automatic Bread Maker Grader #1'!C15 -> 0 | D14: #REF!
A15: ='Automatic Bread Maker Grader #1'!A16 -> History State | B15: ='Automatic Bread Maker Grader #1'!B16 -> H | C15: ='Automatic Bread Maker Grader #1'!C16 -> 0 | D15: #REF! | F15: Confusion Matrix (Transition) | L15: Cohen's Kappa (Transition)
A16: ='Automatic Bread Maker Grader #1'!A17 -> Transition | B16: ='Automatic Bread Maker Grader #1'!B17 -> setup => H | C16: ='Automatic Bread Maker Grader #1'!C17 -> 0 | D16: #REF! | F16: Transition | G16: 0 | H16: 0.5 | I16: 1 | J16: Row Totals | L16: Metric | M16: Value | N16: Note
A17: ='Automatic Bread Maker Grader #1'!A18 -> Action | B17: ='Automatic Bread Maker Grader #1'!B18 -> selectNextCourse() | C17: ='Automatic Bread Maker Grader #1'!C18 -> 0 | D17: #REF! | F17: 0 | G17: =COUNTIFS($A$2:$A$91,$F$16,$C$2:$C$91,$F17,$D$2:$D$91,G$16) -> 0 | H17: =COUNTIFS($A$2:$A$91,$F$16,$C$2:$C$91,$F17,$D$2:$D$91,H$16) -> 0 | I17: =COUNTIFS($A$2:$A$47,$F$16,$C$2:$C$47,$F17,$D$2:$D$47,I$16) + MAX(D49-C49,0) -> #VALUE! | J17: =SUM(G17:I17) -> #VALUE! | L17: Observed Agreement (Po) | M17: =(G17+H18+I19)/COUNTIF($A$2:$A$101,F16) -> 0 | N17: This sums the diagonal of your matrix divided by total rows.
A18: ='Automatic Bread Maker Grader #1'!A19 -> Transition | B18: ='Automatic Bread Maker Grader #1'!B19 -> plus (Setup ⇒ Setup) | C18: ='Automatic Bread Maker Grader #1'!C19 -> 0 | D18: #REF! | F18: 0.5 | G18: =COUNTIFS($A$2:$A$91,$F$16,$C$2:$C$91,$F18,$D$2:$D$91,G$16) -> 0 | H18: =COUNTIFS($A$2:$A$91,$F$16,$C$2:$C$91,$F18,$D$2:$D$91,H$16) -> 0 | I18: =COUNTIFS($A$2:$A$91,$F$16,$C$2:$C$91,$F18,$D$2:$D$91,I$16) -> 0 | J18: =SUM(G18:I18) -> 0 | L18: Expected Agreement (Pe) | M18: {=SUMPRODUCT(J17:J19/COUNTIF($A$2:$A$101,F16), TRANSPOSE(G20:I20)/COUNTIF($A$2:$A$101,F16))} -> #VALUE! | N18: This computes the sum of row proportion times column proportion.
A19: ='Automatic Bread Maker Grader #1'!A20 -> Guard | B19: ='Automatic Bread Maker Grader #1'!B20 -> [delay <= 17*60+50] | C19: ='Automatic Bread Maker Grader #1'!C20 -> 0 | D19: #REF! | F19: 1 | G19: =COUNTIFS($A$2:$A$47,$F$16,$C$2:$C$47,$F19,$D$2:$D$47,G$16)+MAX(C49-D49,0) -> #VALUE! | H19: =COUNTIFS($A$2:$A$91,$F$16,$C$2:$C$91,$F19,$D$2:$D$91,H$16) -> 0 | I19: =COUNTIFS($A$2:$A$47,$F$16,$C$2:$C$47,$F19,$D$2:$D$47,I$16) + MIN(C49,D49) -> 0 | J19: =SUM(G19:I19) -> #VALUE! | L19: Cohen's Kappa | M19: =(M17-M18)/(1-M18) -> #VALUE! | N19: (Po - Pe) / (1 - Pe)
A20: ='Automatic Bread Maker Grader #1'!A21 -> Action | B20: ='Automatic Bread Maker Grader #1'!B21 -> delay = delay + 10 | C20: ='Automatic Bread Maker Grader #1'!C21 -> 0 | D20: #REF! | F20: Column Totals | G20: =SUM(G17:G19) -> #VALUE! | H20: =SUM(H17:H19) -> 0 | I20: =SUM(I17:I19) -> #VALUE!
A21: ='Automatic Bread Maker Grader #1'!A22 -> Transition | B21: ='Automatic Bread Maker Grader #1'!B22 -> minus (Setup ⇒ Setup) | C21: ='Automatic Bread Maker Grader #1'!C22 -> 0 | D21: #REF!
A22: ='Automatic Bread Maker Grader #1'!A23 -> Guard | B22: ='Automatic Bread Maker Grader #1'!B23 -> [delay >= 10] | C22: ='Automatic Bread Maker Grader #1'!C23 -> 0 | D22: #REF! | F22: Confusion Matrix (Composite State) | L22: Cohen's Kappa (Composite State)
A23: ='Automatic Bread Maker Grader #1'!A24 -> Action | B23: ='Automatic Bread Maker Grader #1'!B24 -> delay = delay - 10 | C23: ='Automatic Bread Maker Grader #1'!C24 -> 0 | D23: #REF! | F23: Composite State | G23: 0 | H23: 0.5 | I23: 1 | J23: Row Totals | L23: Metric | M23: Value | N23: Note
A24: ='Automatic Bread Maker Grader #1'!A25 -> Transition | B24: ='Automatic Bread Maker Grader #1'!B25 -> start (Setup ⇒ Countdown) | C24: ='Automatic Bread Maker Grader #1'!C25 -> 0 | D24: #REF! | F24: 0 | G24: =COUNTIFS($A$2:$A$91,$F$23,$C$2:$C$91,$F24,$D$2:$D$91,G$23) -> 0 | H24: =COUNTIFS($A$2:$A$91,$F$23,$C$2:$C$91,$F24,$D$2:$D$91,H$23) -> 0 | I24: =COUNTIFS($A$2:$A$47,$F$23,$C$2:$C$47,$F24,$D$2:$D$47,I$23) + MAX(D52-C52,0) -> #VALUE! | J24: =SUM(G24:I24) -> #VALUE! | L24: Observed Agreement (Po) | M24: =(G24+H25+I26)/COUNTIF($A$2:$A$101,F23) -> 0 | N24: This sums the diagonal of your matrix divided by total rows.
A25: ='Automatic Bread Maker Grader #1'!A26 -> Guard | B25: ='Automatic Bread Maker Grader #1'!B26 -> [delay > 0] | C25: ='Automatic Bread Maker Grader #1'!C26 -> 0 | D25: #REF! | F25: 0.5 | G25: =COUNTIFS($A$2:$A$91,$F$23,$C$2:$C$91,$F25,$D$2:$D$91,G$23) -> 0 | H25: =COUNTIFS($A$2:$A$91,$F$23,$C$2:$C$91,$F25,$D$2:$D$91,H$23) -> 0 | I25: =COUNTIFS($A$2:$A$91,$F$23,$C$2:$C$91,$F25,$D$2:$D$91,I$23) -> 0 | J25: =SUM(G25:I25) -> 0 | L25: Expected Agreement (Pe) | M25: {=SUMPRODUCT(J24:J26/COUNTIF($A$2:$A$101,F23), TRANSPOSE(G27:I27)/COUNTIF($A$2:$A$101,F23))} -> #VALUE! | N25: This computes the sum of row proportion times column proportion.
A26: ='Automatic Bread Maker Grader #1'!A27 -> Transition | B26: ='Automatic Bread Maker Grader #1'!B27 -> start (Setup ⇒ Baking) | C26: ='Automatic Bread Maker Grader #1'!C27 -> 0 | D26: #REF! | F26: 1 | G26: =COUNTIFS($A$2:$A$47,$F$23,$C$2:$C$47,$F26,$D$2:$D$47,G$23) + MAX(C52-D52,0) -> #VALUE! | H26: =COUNTIFS($A$2:$A$91,$F$23,$C$2:$C$91,$F26,$D$2:$D$91,H$23) -> 0 | I26: =COUNTIFS($A$2:$A$47,$F$23,$C$2:$C$47,$F26,$D$2:$D$47,I$23) + MIN(C52,D52) -> 0 | J26: =SUM(G26:I26) -> #VALUE! | L26: Cohen's Kappa | M26: =(M24-M25)/(1-M25) -> #VALUE! | N26: (Po - Pe) / (1 - Pe)
A27: ='Automatic Bread Maker Grader #1'!A28 -> Guard | B27: ='Automatic Bread Maker Grader #1'!B28 -> [delay == 0] | C27: ='Automatic Bread Maker Grader #1'!C28 -> 0 | D27: #REF! | F27: Column Totals | G27: =SUM(G24:G26) -> #VALUE! | H27: =SUM(H24:H26) -> 0 | I27: =SUM(I24:I26) -> #VALUE!
A28: ='Automatic Bread Maker Grader #1'!A29 -> State | B28: ='Automatic Bread Maker Grader #1'!B29 -> Countdown | C28: ='Automatic Bread Maker Grader #1'!C29 -> 0 | D28: #REF!
A29: ='Automatic Bread Maker Grader #1'!A30 -> Action | B29: ='Automatic Bread Maker Grader #1'!B30 -> setCourseTimes() | C29: ='Automatic Bread Maker Grader #1'!C30 -> 0 | D29: #REF! | F29: Confusion Matrix (Guard) | L29: Cohen's Kappa (Guard)
A30: ='Automatic Bread Maker Grader #1'!A31 -> Transition | B30: ='Automatic Bread Maker Grader #1'!B31 -> Countdown => baking | C30: ='Automatic Bread Maker Grader #1'!C31 -> 0 | D30: #REF! | F30: Guard | G30: 0 | H30: 0.5 | I30: 1 | J30: Row Totals | L30: Metric | M30: Value | N30: Note
A31: ='Automatic Bread Maker Grader #1'!A32 -> Transition | B31: ='Automatic Bread Maker Grader #1'!B32 -> Countdown => setup | C31: ='Automatic Bread Maker Grader #1'!C32 -> 0 | D31: #REF! | F31: 0 | G31: =COUNTIFS($A$2:$A$91,$F$30,$C$2:$C$91,$F31,$D$2:$D$91,G$30) -> 0 | H31: =COUNTIFS($A$2:$A$91,$F$30,$C$2:$C$91,$F31,$D$2:$D$91,H$30) -> 0 | I31: =COUNTIFS($A$2:$A$47,$F$30,$C$2:$C$47,$F31,$D$2:$D$47,I$30) + MAX(D50-C50,0) -> #VALUE! | J31: =SUM(G31:I31) -> #VALUE! | L31: Observed Agreement (Po) | M31: =(G31+H32+I33)/COUNTIF($A$2:$A$101,F30) -> 0 | N31: This sums the diagonal of your matrix divided by total rows.
A32: ='Automatic Bread Maker Grader #1'!A33 -> Action | B32: ='Automatic Bread Maker Grader #1'!B33 -> setCourseTimes() | C32: ='Automatic Bread Maker Grader #1'!C33 -> 0 | D32: #REF! | F32: 0.5 | G32: =COUNTIFS($A$2:$A$91,$F$30,$C$2:$C$91,$F32,$D$2:$D$91,G$30) -> 0 | H32: =COUNTIFS($A$2:$A$91,$F$30,$C$2:$C$91,$F32,$D$2:$D$91,H$30) -> 0 | I32: =COUNTIFS($A$2:$A$91,$F$30,$C$2:$C$91,$F32,$D$2:$D$91,I$30) -> 0 | J32: =SUM(G32:I32) -> 0 | L32: Expected Agreement (Pe) | M32: {=SUMPRODUCT(J31:J33/COUNTIF($A$2:$A$101,F30), TRANSPOSE(G34:I34)/COUNTIF($A$2:$A$101,F30))} -> #VALUE! | N32: This computes the sum of row proportion times column proportion.
A33: ='Automatic Bread Maker Grader #1'!A34 -> Composite State | B33: ='Automatic Bread Maker Grader #1'!B34 -> Baking | C33: ='Automatic Bread Maker Grader #1'!C34 -> 0 | D33: #REF! | F33: 1 | G33: =COUNTIFS($A$2:$A$47,$F$30,$C$2:$C$47,$F33,$D$2:$D$47,G$30) + MAX(C50-D50,0) -> #VALUE! | H33: =COUNTIFS($A$2:$A$91,$F$30,$C$2:$C$91,$F33,$D$2:$D$91,H$30) -> 0 | I33: =COUNTIFS($A$2:$A$47,$F$30,$C$2:$C$47,$F33,$D$2:$D$47,I$30) + MIN(C50,D50) -> 0 | J33: =SUM(G33:I33) -> #VALUE! | L33: Cohen's Kappa | M33: =(M31-M32)/(1-M32) -> #VALUE! | N33: (Po - Pe) / (1 - Pe)
A34: ='Automatic Bread Maker Grader #1'!A35 -> State | B34: ='Automatic Bread Maker Grader #1'!B35 -> Initial state | C34: ='Automatic Bread Maker Grader #1'!C35 -> 0 | D34: #REF! | F34: Column Totals | G34: =SUM(G31:G33) -> #VALUE! | H34: =SUM(H31:H33) -> 0 | I34: =SUM(I31:I33) -> #VALUE!
A35: ='Automatic Bread Maker Grader #1'!A36 -> State | B35: ='Automatic Bread Maker Grader #1'!B36 -> Kneading | C35: ='Automatic Bread Maker Grader #1'!C36 -> 0 | D35: #REF!
A36: ='Automatic Bread Maker Grader #1'!A37 -> Action | B36: ='Automatic Bread Maker Grader #1'!B37 -> startKneading() | C36: ='Automatic Bread Maker Grader #1'!C37 -> 0 | D36: #REF! | F36: Confusion Matrix (Action) | L36: Cohen's Kappa (Action)
A37: ='Automatic Bread Maker Grader #1'!A38 -> Action | B37: ='Automatic Bread Maker Grader #1'!B38 -> stopKneading() | C37: ='Automatic Bread Maker Grader #1'!C38 -> 0 | D37: #REF! | F37: Action | G37: 0 | H37: 0.5 | I37: 1 | J37: Row Totals | L37: Metric | M37: Value | N37: Note
A38: ='Automatic Bread Maker Grader #1'!A39 -> Transition | B38: ='Automatic Bread Maker Grader #1'!B39 -> baking initial state => kneading | C38: ='Automatic Bread Maker Grader #1'!C39 -> 0 | D38: #REF! | F38: 0 | G38: =COUNTIFS($A$2:$A$91,$F$37,$C$2:$C$91,$F38,$D$2:$D$91,G$37) -> 0 | H38: =COUNTIFS($A$2:$A$91,$F$37,$C$2:$C$91,$F38,$D$2:$D$91,H$37) -> 0 | I38: =COUNTIFS($A$2:$A$47,$F$37,$C$2:$C$47,$F38,$D$2:$D$47,I$37)+MAX(D51-C51,0) -> #VALUE! | J38: =SUM(G38:I38) -> #VALUE! | L38: Observed Agreement (Po) | M38: =(G38+H39+I40)/COUNTIF($A$2:$A$101,F37) -> 0 | N38: This sums the diagonal of your matrix divided by total rows.
A39: ='Automatic Bread Maker Grader #1'!A40 -> Transition | B39: ='Automatic Bread Maker Grader #1'!B40 -> kneading => rising | C39: ='Automatic Bread Maker Grader #1'!C40 -> 0 | D39: #REF! | F39: 0.5 | G39: =COUNTIFS($A$2:$A$91,$F$37,$C$2:$C$91,$F39,$D$2:$D$91,G$37) -> 0 | H39: =COUNTIFS($A$2:$A$91,$F$37,$C$2:$C$91,$F39,$D$2:$D$91,H$37) -> 0 | I39: =COUNTIFS($A$2:$A$91,$F$37,$C$2:$C$91,$F39,$D$2:$D$91,I$37) -> 0 | J39: =SUM(G39:I39) -> 0 | L39: Expected Agreement (Pe) | M39: {=SUMPRODUCT(J38:J40/COUNTIF($A$2:$A$101,F37), TRANSPOSE(G41:I41)/COUNTIF($A$2:$A$101,F37))} -> #VALUE! | N39: This computes the sum of row proportion times column proportion.
A40: ='Automatic Bread Maker Grader #1'!A41 -> State | B40: ='Automatic Bread Maker Grader #1'!B41 -> Rising | C40: ='Automatic Bread Maker Grader #1'!C41 -> 0 | D40: #REF! | F40: 1 | G40: =COUNTIFS($A$2:$A$47,$F$37,$C$2:$C$47,$F40,$D$2:$D$47,G$37)+MAX(C51-D51,0) -> #VALUE! | H40: =COUNTIFS($A$2:$A$91,$F$37,$C$2:$C$91,$F40,$D$2:$D$91,H$37) -> 0 | I40: =COUNTIFS($A$2:$A$47,$F$37,$C$2:$C$47,$F40,$D$2:$D$47,I$37) + MIN(C51,D51) -> 0 | J40: =SUM(G40:I40) -> #VALUE! | L40: Cohen's Kappa | M40: =(M38-M39)/(1-M39) -> #VALUE! | N40: (Po - Pe) / (1 - Pe)
...

Sheet Weighted Cohens Kappa
A1: Type | B1: Element | C1: Rater 1 | D1: Rater 2 | F1: Confusion Matrix | L1: Weight Matrix
A2: ='Automatic Bread Maker Grader #1'!A3 -> State | B2: ='Automatic Bread Maker Grader #1'!B3 -> Off | C2: ='Automatic Bread Maker Grader #1'!C3 -> 0 | D2: #REF! | F2: Global | G2: 0 | H2: 0.5 | I2: 1 | J2: Row Totals | L2: Global | M2: 0 | N2: 0.5 | O2: 1 | Q2: Global | R2: 0 | S2: 0.5 | T2: 1 | V2: Metric | W2: Value | X2: Note
A3: ='Automatic Bread Maker Grader #1'!A4 -> Transition | B3: ='Automatic Bread Maker Grader #1'!B4 -> on (Off ⇒ On) | C3: ='Automatic Bread Maker Grader #1'!C4 -> 0 | D3: #REF! | F3: 0 | G3: =COUNTIFS($C$2:$C$91, $F3, $D$2:$D$91, G$2) -> 0 | H3: =COUNTIFS($C$2:$C$47, $F3, $D$2:$D$47, H$2) -> 0 | I3: =COUNTIFS($C$2:$C$47, $F3, $D$2:$D$47, I$2)+MAX(D48-C48,0)+MAX(D49-C49,0)+MAX(D50-C50,0)+MAX(D51-C51,0)+MAX(D52-C52,0)+MAX(D53-C53,0)+MAX(D54-C54,0) -> #VALUE! | J3: =SUM(G3:I3) -> #VALUE! | L3: 0 | M3: =ABS(G$2-$F3)/1 -> 0 | N3: =ABS(H$2-$F3)/1 -> 0.5 | O3: =ABS(I$2-$F3)/1 -> 1 | Q3: 0 | R3: =($J3/$J$6) * (G$6/$J$6) -> #VALUE! | S3: =($J3/$J$6) * (H$6/$J$6) -> #VALUE! | T3: =($J3/$J$6) * (I$6/$J$6) -> #VALUE! | V3: Observed Weighted Disagreement (D_obs) | W3: =SUMPRODUCT(G3:I5, M3:O5) /$J$6 -> #VALUE! | X3: Sum of (confusion-matrix counts × weights) divided by total items.
A4: ='Automatic Bread Maker Grader #1'!A5 -> Composite State | B4: ='Automatic Bread Maker Grader #1'!B5 -> On | C4: ='Automatic Bread Maker Grader #1'!C5 -> 0 | D4: #REF! | F4: 0.5 | G4: =COUNTIFS($C$2:$C$47, $F4, $D$2:$D$47, G$2) -> 0 | H4: =COUNTIFS($C$2:$C$47, $F4, $D$2:$D$47, H$2) -> 0 | I4: =COUNTIFS($C$2:$C$47, $F4, $D$2:$D$47, I$2) -> 0 | J4: =SUM(G4:I4) -> 0 | L4: 0.5 | M4: =ABS(G$2-$F4)/1 -> 0.5 | N4: =ABS(H$2-$F4)/3 -> 0 | O4: =ABS(I$2-$F4)/1 -> 0.5 | Q4: 0.5 | R4: =($J4/$J$6) * (G$6/$J$6) -> #VALUE! | S4: =($J4/$J$6) * (H$6/$J$6) -> #VALUE! | T4: =($J4/$J$6) * (I$6/$J$6) -> #VALUE! | V4: Expected Weighted Disagreement (D_exp) | W4: =SUMPRODUCT(R3:T5, M3:O5) -> #VALUE! | X4: Sum of (expected cell proportions × weights) under chance agreement.
A5: ='Automatic Bread Maker Grader #1'!A2 -> State | B5: ='Automatic Bread Maker Grader #1'!B2 -> Initial state (→ Off) | C5: ='Automatic Bread Maker Grader #1'!C2 -> 0 | D5: #REF! | F5: 1 | G5: =COUNTIFS($C$2:$C$47, $F5, $D$2:$D$47, G$2)+MAX(C48-D48,0)+MAX(C49-D49,0)+MAX(C50-D50,0)+MAX(C51-D51,0)+MAX(C52-D52,0)+MAX(C53-D53,0)+MAX(C54-D54,0) -> #VALUE! | H5: =COUNTIFS($C$2:$C$47, $F5, $D$2:$D$47, H$2) -> 0 | I5: =COUNTIFS($C$2:$C$47, $F5, $D$2:$D$47, I$2)+ SUM(MIN(C48,D48), MIN(C49,D49), MIN(C50,D50), MIN(C51,D51), MIN(C52,D52), MIN(C53,D53), MIN(C54,D54)) -> 0 | J5: =SUM(G5:I5) -> #VALUE! | L5: 1 | M5: =ABS(G$2-$F5)/1 -> 1 | N5: =ABS(H$2-$F5)/1 -> 0.5 | O5: =ABS(I$2-$F5)/1 -> 0 | Q5: 1 | R5: =($J5/$J$6) * (G$6/$J$6) -> #VALUE! | S5: =($J5/$J$6) * (H$6/$J$6) -> #VALUE! | T5: =($J5/$J$6) * (I$6/$J$6) -> #VALUE! | V5: Cohen's Kappa | W5: =1-W3/W4 -> #VALUE! | X5: 1 - (D_obs / D_exp)
A6: ='Automatic Bread Maker Grader #1'!A7 -> Composite State | B6: ='Automatic Bread Maker Grader #1'!B7 -> Setup | C6: ='Automatic Bread Maker Grader #1'!C7 -> 0 | D6: #REF! | F6: Column Totals | G6: =SUM(G3:G5) -> #VALUE! | H6: =SUM(H3:H5) -> 0 | I6: =SUM(I3:I5) -> #VALUE! | J6: =SUM(G3:I5) -> #VALUE!
A7: ='Automatic Bread Maker Grader #1'!A8 -> State | B7: ='Automatic Bread Maker Grader #1'!B8 -> Initial state (Setup → Medium) | C7: ='Automatic Bread Maker Grader #1'!C8 -> 0 | D7: #REF!
A8: ='Automatic Bread Maker Grader #1'!A9 -> Action | B8: ='Automatic Bread Maker Grader #1'!B9 -> delay=0; selectFirstCourse() | C8: ='Automatic Bread Maker Grader #1'!C9 -> 0 | D8: #REF! | F8: Confusion Matrix (State)
A9: ='Automatic Bread Maker Grader #1'!A10 -> State | B9: ='Automatic Bread Maker Grader #1'!B10 -> Medium | C9: ='Automatic Bread Maker Grader #1'!C10 -> 0 | D9: #REF! | F9: State | G9: 0 | H9: 0.5 | I9: 1 | J9: Row Totals | L9: Global | M9: 0 | N9: 0.5 | O9: 1 | Q9: Global | R9: 0 | S9: 0.5 | T9: 1 | V9: Metric | W9: Value | X9: Note
A10: ='Automatic Bread Maker Grader #1'!A11 -> Transition | B10: ='Automatic Bread Maker Grader #1'!B11 -> setup initial state => medium | C10: ='Automatic Bread Maker Grader #1'!C11 -> 0 | D10: #REF! | F10: 0 | G10: =COUNTIFS($A$2:$A$91,$F$9,$C$2:$C$91,$F10,$D$2:$D$91,G$9) -> 0 | H10: =COUNTIFS($A$2:$A$91,$F$9,$C$2:$C$91,$F10,$D$2:$D$91,H$9) -> 0 | I10: =COUNTIFS($A$2:$A$47,$F$9,$C$2:$C$47,$F10,$D$2:$D$47,I$9)+MAX(D48-C48,0) -> #VALUE! | J10: =SUM(G10:I10) -> #VALUE! | L10: 0 | M10: =ABS(G$2-$F10)/1 -> 0 | N10: =ABS(H$2-$F10)/1 -> 0.5 | O10: =ABS(I$2-$F10)/1 -> 1 | Q10: 0 | R10: =($J10/$J$13) * (G$13/$J$13) -> #VALUE! | S10: =($J10/$J$13) * (H$13/$J$13) -> #VALUE! | T10: =($J10/$J$13) * (I$13/$J$13) -> #VALUE! | V10: Observed Weighted Disagreement (D_obs) | W10: =SUMPRODUCT(G10:I12, M10:O12) /$J$13 -> #VALUE! | X10: Sum of (confusion-matrix counts × weights) divided by total items.
A11: ='Automatic Bread Maker Grader #1'!A12 -> Transition | B11: ='Automatic Bread Maker Grader #1'!B12 -> medium => dark | C11: ='Automatic Bread Maker Grader #1'!C12 -> 0 | D11: #REF! | F11: 0.5 | G11: =COUNTIFS($A$2:$A$91,$F$9,$C$2:$C$91,$F11,$D$2:$D$91,G$9) -> 0 | H11: =COUNTIFS($A$2:$A$91,$F$9,$C$2:$C$91,$F11,$D$2:$D$91,H$9) -> 0 | I11: =COUNTIFS($A$2:$A$91,$F$9,$C$2:$C$91,$F11,$D$2:$D$91,I$9) -> 0 | J11: =SUM(G11:I11) -> 0 | L11: 0.5 | M11: =ABS(G$2-$F11)/1 -> 0.5 | N11: =ABS(H$2-$F11)/3 -> 0 | O11: =ABS(I$2-$F11)/1 -> 0.5 | Q11: 0.5 | R11: =($J11/$J$13) * (G$13/$J$13) -> #VALUE! | S11: =($J11/$J$13) * (H$13/$J$13) -> #VALUE! | T11: =($J11/$J$13) * (I$13/$J$13) -> #VALUE! | V11: Expected Weighted Disagreement (D_exp) | W11: =SUMPRODUCT(R10:T12, M10:O12) -> #VALUE! | X11: Sum of (expected cell proportions × weights) under chance agreement.
A12: ='Automatic Bread Maker Grader #1'!A13 -> State | B12: ='Automatic Bread Maker Grader #1'!B13 -> Dark | C12: ='Automatic Bread Maker Grader #1'!C13 -> 0 | D12: #REF! | F12: 1 | G12: =COUNTIFS($A$2:$A$47,$F$9,$C$2:$C$47,$F12,$D$2:$D$47,G$9)+MAX(C48-D48,0) -> #VALUE! | H12: =COUNTIFS($A$2:$A$91,$F$9,$C$2:$C$91,$F12,$D$2:$D$91,H$9) -> 0 | I12: =COUNTIFS($A$2:$A$47,$F$9,$C$2:$C$47,$F12,$D$2:$D$47,I$9)+MIN(C48-D48) -> #VALUE! | J12: =SUM(G12:I12) -> #VALUE! | L12: 1 | M12: =ABS(G$2-$F12)/1 -> 1 | N12: =ABS(H$2-$F12)/1 -> 0.5 | O12: =ABS(I$2-$F12)/1 -> 0 | Q12: 1 | R12: =($J12/$J$13) * (G$13/$J$13) -> #VALUE! | S12: =($J12/$J$13) * (H$13/$J$13) -> #VALUE! | T12: =($J12/$J$13) * (I$13/$J$13) -> #VALUE! | V12: Cohen's Kappa | W12: =1-W10/W11 -> #VALUE! | X12: 1 - (D_obs / D_exp)
A13: ='Automatic Bread Maker Grader #1'!A14 -> Transition | B13: ='Automatic Bread Maker Grader #1'!B14 -> dark => light | C13: ='Automatic Bread Maker Grader #1'!C14 -> 0 | D13: #REF! | F13: Column Totals | G13: =SUM(G10:G12) -> #VALUE! | H13: =SUM(H10:H12) -> 0 | I13: =SUM(I10:I12) -> #VALUE! | J13: =SUM(G10:I12) -> #VALUE!
A14: ='Automatic Bread Maker Grader #1'!A15 -> State | B14: ='Automatic Bread Maker Grader #1'!B15 -> Light | C14: ='Automatic Bread Maker Grader #1'!C15 -> 0 | D14: #REF!
A15: ='Automatic Bread Maker Grader #1'!A16 -> History State | B15: ='Automatic Bread Maker Grader #1'!B16 -> H | C15: ='Automatic Bread Maker Grader #1'!C16 -> 0 | D15: #REF! | F15: Confusion Matrix (Transition)
A16: ='Automatic Bread Maker Grader #1'!A17 -> Transition | B16: ='Automatic Bread Maker Grader #1'!B17 -> setup => H | C16: ='Automatic Bread Maker Grader #1'!C17 -> 0 | D16: #REF! | F16: Transition | G16: 0 | H16: 0.5 | I16: 1 | J16: Row Totals | L16: Global | M16: 0 | N16: 0.5 | O16: 1 | Q16: Global | R16: 0 | S16: 0.5 | T16: 1 | V16: Metric | W16: Value | X16: Note
A17: ='Automatic Bread Maker Grader #1'!A18 -> Action | B17: ='Automatic Bread Maker Grader #1'!B18 -> selectNextCourse() | C17: ='Automatic Bread Maker Grader #1'!C18 -> 0 | D17: #REF! | F17: 0 | G17: =COUNTIFS($A$2:$A$91,$F$16,$C$2:$C$91,$F17,$D$2:$D$91,G$16) -> 0 | H17: =COUNTIFS($A$2:$A$91,$F$16,$C$2:$C$91,$F17,$D$2:$D$91,H$16) -> 0 | I17: =COUNTIFS($A$2:$A$47,$F$16,$C$2:$C$47,$F17,$D$2:$D$47,I$16) + MAX(D49-C49,0) -> #VALUE! | J17: =SUM(G17:I17) -> #VALUE! | L17: 0 | M17: =ABS(G$2-$F17)/1 -> 0 | N17: =ABS(H$2-$F17)/1 -> 0.5 | O17: =ABS(I$2-$F17)/1 -> 1 | Q17: 0 | R17: =($J17/$J$20) * (G$20/$J$20) -> #VALUE! | S17: =($J17/$J$20) * (H$20/$J$20) -> #VALUE! | T17: =($J17/$J$20) * (I$20/$J$20) -> #VALUE! | V17: Observed Weighted Disagreement (D_obs) | W17: =SUMPRODUCT(G17:I19, M17:O19) /$J$20 -> #VALUE! | X17: Sum of (confusion-matrix counts × weights) divided by total items.
A18: ='Automatic Bread Maker Grader #1'!A19 -> Transition | B18: ='Automatic Bread Maker Grader #1'!B19 -> plus (Setup ⇒ Setup) | C18: ='Automatic Bread Maker Grader #1'!C19 -> 0 | D18: #REF! | F18: 0.5 | G18: =COUNTIFS($A$2:$A$91,$F$16,$C$2:$C$91,$F18,$D$2:$D$91,G$16) -> 0 | H18: =COUNTIFS($A$2:$A$91,$F$16,$C$2:$C$91,$F18,$D$2:$D$91,H$16) -> 0 | I18: =COUNTIFS($A$2:$A$91,$F$16,$C$2:$C$91,$F18,$D$2:$D$91,I$16) -> 0 | J18: =SUM(G18:I18) -> 0 | L18: 0.5 | M18: =ABS(G$2-$F18)/1 -> 0.5 | N18: =ABS(H$2-$F18)/3 -> 0 | O18: =ABS(I$2-$F18)/1 -> 0.5 | Q18: 0.5 | R18: =($J18/$J$20) * (G$20/$J$20) -> #VALUE! | S18: =($J18/$J$20) * (H$20/$J$20) -> #VALUE! | T18: =($J18/$J$20) * (I$20/$J$20) -> #VALUE! | V18: Expected Weighted Disagreement (D_exp) | W18: =SUMPRODUCT(R17:T19, M17:O19) -> #VALUE! | X18: Sum of (expected cell proportions × weights) under chance agreement.
A19: ='Automatic Bread Maker Grader #1'!A20 -> Guard | B19: ='Automatic Bread Maker Grader #1'!B20 -> [delay <= 17*60+50] | C19: ='Automatic Bread Maker Grader #1'!C20 -> 0 | D19: #REF! | F19: 1 | G19: =COUNTIFS($A$2:$A$47,$F$16,$C$2:$C$47,$F19,$D$2:$D$47,G$16)+MAX(C49-D49,0) -> #VALUE! | H19: =COUNTIFS($A$2:$A$91,$F$16,$C$2:$C$91,$F19,$D$2:$D$91,H$16) -> 0 | I19: =COUNTIFS($A$2:$A$47,$F$16,$C$2:$C$47,$F19,$D$2:$D$47,I$16) + MIN(C49,D49) -> 0 | J19: =SUM(G19:I19) -> #VALUE! | L19: 1 | M19: =ABS(G$2-$F19)/1 -> 1 | N19: =ABS(H$2-$F19)/1 -> 0.5 | O19: =ABS(I$2-$F19)/1 -> 0 | Q19: 1 | R19: =($J19/$J$20) * (G$20/$J$20) -> #VALUE! | S19: =($J19/$J$20) * (H$20/$J$20) -> #VALUE! | T19: =($J19/$J$20) * (I$20/$J$20) -> #VALUE! | V19: Cohen's Kappa | W19: =1-W17/W18 -> #VALUE! | X19: 1 - (D_obs / D_exp)
A20: ='Automatic Bread Maker Grader #1'!A21 -> Action | B20: ='Automatic Bread Maker Grader #1'!B21 -> delay = delay + 10 | C20: ='Automatic Bread Maker Grader #1'!C21 -> 0 | D20: #REF! | F20: Column Totals | G20: =SUM(G17:G19) -> #VALUE! | H20: =SUM(H17:H19) -> 0 | I20: =SUM(I17:I19) -> #VALUE! | J20: =SUM(G17:I19) -> #VALUE!
A21: ='Automatic Bread Maker Grader #1'!A22 -> Transition | B21: ='Automatic Bread Maker Grader #1'!B22 -> minus (Setup ⇒ Setup) | C21: ='Automatic Bread Maker Grader #1'!C22 -> 0 | D21: #REF!
A22: ='Automatic Bread Maker Grader #1'!A23 -> Guard | B22: ='Automatic Bread Maker Grader #1'!B23 -> [delay >= 10] | C22: ='Automatic Bread Maker Grader #1'!C23 -> 0 | D22: #REF! | F22: Confusion Matrix (Composite State)
A23: ='Automatic Bread Maker Grader #1'!A24 -> Action | B23: ='Automatic Bread Maker Grader #1'!B24 -> delay = delay - 10 | C23: ='Automatic Bread Maker Grader #1'!C24 -> 0 | D23: #REF! | F23: Composite State | G23: 0 | H23: 0.5 | I23: 1 | J23: Row Totals | L23: Global | M23: 0 | N23: 0.5 | O23: 1 | Q23: Global | R23: 0 | S23: 0.5 | T23: 1 | V23: Metric | W23: Value | X23: Note
A24: ='Automatic Bread Maker Grader #1'!A25 -> Transition | B24: ='Automatic Bread Maker Grader #1'!B25 -> start (Setup ⇒ Countdown) | C24: ='Automatic Bread Maker Grader #1'!C25 -> 0 | D24: #REF! | F24: 0 | G24: =COUNTIFS($A$2:$A$91,$F$23,$C$2:$C$91,$F24,$D$2:$D$91,G$23) -> 0 | H24: =COUNTIFS($A$2:$A$91,$F$23,$C$2:$C$91,$F24,$D$2:$D$91,H$23) -> 0 | I24: =COUNTIFS($A$2:$A$47,$F$23,$C$2:$C$47,$F24,$D$2:$D$47,I$23) + MAX(D52-C52,0) -> #VALUE! | J24: =SUM(G24:I24) -> #VALUE! | L24: 0 | M24: =ABS(G$2-$F24)/1 -> 0 | N24: =ABS(H$2-$F24)/1 -> 0.5 | O24: =ABS(I$2-$F24)/1 -> 1 | Q24: 0 | R24: =($J24/$J$27) * (G$27/$J$27) -> #VALUE! | S24: =($J24/$J$27) * (H$27/$J$27) -> #VALUE! | T24: =($J24/$J$27) * (I$27/$J$27) -> #VALUE! | V24: Observed Weighted Disagreement (D_obs) | W24: =SUMPRODUCT(G24:I26, M24:O26) /$J$27 -> #VALUE! | X24: Sum of (confusion-matrix counts × weights) divided by total items.
A25: ='Automatic Bread Maker Grader #1'!A26 -> Guard | B25: ='Automatic Bread Maker Grader #1'!B26 -> [delay > 0] | C25: ='Automatic Bread Maker Grader #1'!C26 -> 0 | D25: #REF! | F25: 0.5 | G25: =COUNTIFS($A$2:$A$91,$F$23,$C$2:$C$91,$F25,$D$2:$D$91,G$23) -> 0 | H25: =COUNTIFS($A$2:$A$91,$F$23,$C$2:$C$91,$F25,$D$2:$D$91,H$23) -> 0 | I25: =COUNTIFS($A$2:$A$91,$F$23,$C$2:$C$91,$F25,$D$2:$D$91,I$23) -> 0 | J25: =SUM(G25:I25) -> 0 | L25: 0.5 | M25: =ABS(G$2-$F25)/1 -> 0.5 | N25: =ABS(H$2-$F25)/3 -> 0 | O25: =ABS(I$2-$F25)/1 -> 0.5 | Q25: 0.5 | R25: =($J25/$J$27) * (G$27/$J$27) -> #VALUE! | S25: =($J25/$J$27) * (H$27/$J$27) -> #VALUE! | T25: =($J25/$J$27) * (I$27/$J$27) -> #VALUE! | V25: Expected Weighted Disagreement (D_exp) | W25: =SUMPRODUCT(R24:T26, M24:O26) -> #VALUE! | X25: Sum of (expected cell proportions × weights) under chance agreement.
A26: ='Automatic Bread Maker Grader #1'!A27 -> Transition | B26: ='Automatic Bread Maker Grader #1'!B27 -> start (Setup ⇒ Baking) | C26: ='Automatic Bread Maker Grader #1'!C27 -> 0 | D26: #REF! | F26: 1 | G26: =COUNTIFS($A$2:$A$47,$F$23,$C$2:$C$47,$F26,$D$2:$D$47,G$23) + MAX(C52-D52,0) -> #VALUE! | H26: =COUNTIFS($A$2:$A$91,$F$23,$C$2:$C$91,$F26,$D$2:$D$91,H$23) -> 0 | I26: =COUNTIFS($A$2:$A$47,$F$23,$C$2:$C$47,$F26,$D$2:$D$47,I$23) + MIN(C52,D52) -> 0 | J26: =SUM(G26:I26) -> #VALUE! | L26: 1 | M26: =ABS(G$2-$F26)/1 -> 1 | N26: =ABS(H$2-$F26)/1 -> 0.5 | O26: =ABS(I$2-$F26)/1 -> 0 | Q26: 1 | R26: =($J26/$J$27) * (G$27/$J$27) -> #VALUE! | S26: =($J26/$J$27) * (H$27/$J$27) -> #VALUE! | T26: =($J26/$J$27) * (I$27/$J$27) -> #VALUE! | V26: Cohen's Kappa | W26: =1-W24/W25 -> #VALUE! | X26: 1 - (D_obs / D_exp)
A27: ='Automatic Bread Maker Grader #1'!A28 -> Guard | B27: ='Automatic Bread Maker Grader #1'!B28 -> [delay == 0] | C27: ='Automatic Bread Maker Grader #1'!C28 -> 0 | D27: #REF! | F27: Column Totals | G27: =SUM(G24:G26) -> #VALUE! | H27: =SUM(H24:H26) -> 0 | I27: =SUM(I24:I26) -> #VALUE! | J27: =SUM(G24:I26) -> #VALUE!
A28: ='Automatic Bread Maker Grader #1'!A29 -> State | B28: ='Automatic Bread Maker Grader #1'!B29 -> Countdown | C28: ='Automatic Bread Maker Grader #1'!C29 -> 0 | D28: #REF!
A29: ='Automatic Bread Maker Grader #1'!A30 -> Action | B29: ='Automatic Bread Maker Grader #1'!B30 -> setCourseTimes() | C29: ='Automatic Bread Maker Grader #1'!C30 -> 0 | D29: #REF! | F29: Confusion Matrix (Guard)
A30: ='Automatic Bread Maker Grader #1'!A31 -> Transition | B30: ='Automatic Bread Maker Grader #1'!B31 -> Countdown => baking | C30: ='Automatic Bread Maker Grader #1'!C31 -> 0 | D30: #REF! | F30: Guard | G30: 0 | H30: 0.5 | I30: 1 | J30: Row Totals | L30: Global | M30: 0 | N30: 0.5 | O30: 1 | Q30: Global | R30: 0 | S30: 0.5 | T30: 1 | V30: Metric | W30: Value | X30: Note
A31: ='Automatic Bread Maker Grader #1'!A32 -> Transition | B31: ='Automatic Bread Maker Grader #1'!B32 -> Countdown => setup | C31: ='Automatic Bread Maker Grader #1'!C32 -> 0 | D31: #REF! | F31: 0 | G31: =COUNTIFS($A$2:$A$91,$F$30,$C$2:$C$91,$F31,$D$2:$D$91,G$30) -> 0 | H31: =COUNTIFS($A$2:$A$91,$F$30,$C$2:$C$91,$F31,$D$2:$D$91,H$30) -> 0 | I31: =COUNTIFS($A$2:$A$47,$F$30,$C$2:$C$47,$F31,$D$2:$D$47,I$30) + MAX(D50-C50,0) -> #VALUE! | J31: =SUM(G31:I31) -> #VALUE! | L31: 0 | M31: =ABS(G$2-$F31)/1 -> 0 | N31: =ABS(H$2-$F31)/1 -> 0.5 | O31: =ABS(I$2-$F31)/1 -> 1 | Q31: 0 | R31: =($J31/$J$34) * (G$34/$J$34) -> #VALUE! | S31: =($J31/$J$34) * (H$34/$J$34) -> #VALUE! | T31: =($J31/$J$34) * (I$34/$J$34) -> #VALUE! | V31: Observed Weighted Disagreement (D_obs) | W31: =SUMPRODUCT(G31:I33, M31:O33) /$J$34 -> #VALUE! | X31: Sum of (confusion-matrix counts × weights) divided by total items.
A32: ='Automatic Bread Maker Grader #1'!A33 -> Action | B32: ='Automatic Bread Maker Grader #1'!B33 -> setCourseTimes() | C32: ='Automatic Bread Maker Grader #1'!C33 -> 0 | D32: #REF! | F32: 0.5 | G32: =COUNTIFS($A$2:$A$91,$F$30,$C$2:$C$91,$F32,$D$2:$D$91,G$30) -> 0 | H32: =COUNTIFS($A$2:$A$91,$F$30,$C$2:$C$91,$F32,$D$2:$D$91,H$30) -> 0 | I32: =COUNTIFS($A$2:$A$91,$F$30,$C$2:$C$91,$F32,$D$2:$D$91,I$30) -> 0 | J32: =SUM(G32:I32) -> 0 | L32: 0.5 | M32: =ABS(G$2-$F32)/1 -> 0.5 | N32: =ABS(H$2-$F32)/3 -> 0 | O32: =ABS(I$2-$F32)/1 -> 0.5 | Q32: 0.5 | R32: =($J32/$J$34) * (G$34/$J$34) -> #VALUE! | S32: =($J32/$J$34) * (H$34/$J$34) -> #VALUE! | T32: =($J32/$J$34) * (I$34/$J$34) -> #VALUE! | V32: Expected Weighted Disagreement (D_exp) | W32: =SUMPRODUCT(R31:T33, M31:O33) -> #VALUE! | X32: Sum of (expected cell proportions × weights) under chance agreement.
A33: ='Automatic Bread Maker Grader #1'!A34 -> Composite State | B33: ='Automatic Bread Maker Grader #1'!B34 -> Baking | C33: ='Automatic Bread Maker Grader #1'!C34 -> 0 | D33: #REF! | F33: 1 | G33: =COUNTIFS($A$2:$A$47,$F$30,$C$2:$C$47,$F33,$D$2:$D$47,G$30) + MAX(C50-D50,0) -> #VALUE! | H33: =COUNTIFS($A$2:$A$91,$F$30,$C$2:$C$91,$F33,$D$2:$D$91,H$30) -> 0 | I33: =COUNTIFS($A$2:$A$47,$F$30,$C$2:$C$47,$F33,$D$2:$D$47,I$30) + MIN(C50,D50) -> 0 | J33: =SUM(G33:I33) -> #VALUE! | L33: 1 | M33: =ABS(G$2-$F33)/1 -> 1 | N33: =ABS(H$2-$F33)/1 -> 0.5 | O33: =ABS(I$2-$F33)/1 -> 0 | Q33: 1 | R33: =($J33/$J$34) * (G$34/$J$34) -> #VALUE! | S33: =($J33/$J$34) * (H$34/$J$34) -> #VALUE! | T33: =($J33/$J$34) * (I$34/$J$34) -> #VALUE! | V33: Cohen's Kappa | W33: =1-W31/W32 -> #VALUE! | X33: 1 - (D_obs / D_exp)
A34: ='Automatic Bread Maker Grader #1'!A35 -> State | B34: ='Automatic Bread Maker Grader #1'!B35 -> Initial state | C34: ='Automatic Bread Maker Grader #1'!C35 -> 0 | D34: #REF! | F34: Column Totals | G34: =SUM(G31:G33) -> #VALUE! | H34: =SUM(H31:H33) -> 0 | I34: =SUM(I31:I33) -> #VALUE! | J34: =SUM(G31:I33) -> #VALUE!
A35: ='Automatic Bread Maker Grader #1'!A36 -> State | B35: ='Automatic Bread Maker Grader #1'!B36 -> Kneading | C35: ='Automatic Bread Maker Grader #1'!C36 -> 0 | D35: #REF!
A36: ='Automatic Bread Maker Grader #1'!A37 -> Action | B36: ='Automatic Bread Maker Grader #1'!B37 -> startKneading() | C36: ='Automatic Bread Maker Grader #1'!C37 -> 0 | D36: #REF! | F36: Confusion Matrix (Action)
A37: ='Automatic Bread Maker Grader #1'!A38 -> Action | B37: ='Automatic Bread Maker Grader #1'!B38 -> stopKneading() | C37: ='Automatic Bread Maker Grader #1'!C38 -> 0 | D37: #REF! | F37: Action | G37: 0 | H37: 0.5 | I37: 1 | J37: Row Totals | L37: Global | M37: 0 | N37: 0.5 | O37: 1 | Q37: Global | R37: 0 | S37: 0.5 | T37: 1 | V37: Metric | W37: Value | X37: Note
A38: ='Automatic Bread Maker Grader #1'!A39 -> Transition | B38: ='Automatic Bread Maker Grader #1'!B39 -> baking initial state => kneading | C38: ='Automatic Bread Maker Grader #1'!C39 -> 0 | D38: #REF! | F38: 0 | G38: =COUNTIFS($A$2:$A$91,$F$37,$C$2:$C$91,$F38,$D$2:$D$91,G$37) -> 0 | H38: =COUNTIFS($A$2:$A$91,$F$37,$C$2:$C$91,$F38,$D$2:$D$91,H$37) -> 0 | I38: =COUNTIFS($A$2:$A$47,$F$37,$C$2:$C$47,$F38,$D$2:$D$47,I$37)+MAX(D51-C51,0) -> #VALUE! | J38: =SUM(G38:I38) -> #VALUE! | L38: 0 | M38: =ABS(G$2-$F38)/1 -> 0 | N38: =ABS(H$2-$F38)/1 -> 0.5 | O38: =ABS(I$2-$F38)/1 -> 1 | Q38: 0 | R38: =($J38/$J$41) * (G$41/$J$41) -> #VALUE! | S38: =($J38/$J$41) * (H$4/$J$41) -> #VALUE! | T38: =($J38/$J$41) * (I$41/$J$41) -> #VALUE! | V38: Observed Weighted Disagreement (D_obs) | W38: =SUMPRODUCT(G38:I40, M38:O40) /$J$41 -> #VALUE! | X38: Sum of (confusion-matrix counts × weights) divided by total items.
A39: ='Automatic Bread Maker Grader #1'!A40 -> Transition | B39: ='Automatic Bread Maker Grader #1'!B40 -> kneading => rising | C39: ='Automatic Bread Maker Grader #1'!C40 -> 0 | D39: #REF! | F39: 0.5 | G39: =COUNTIFS($A$2:$A$91,$F$37,$C$2:$C$91,$F39,$D$2:$D$91,G$37) -> 0 | H39: =COUNTIFS($A$2:$A$91,$F$37,$C$2:$C$91,$F39,$D$2:$D$91,H$37) -> 0 | I39: =COUNTIFS($A$2:$A$91,$F$37,$C$2:$C$91,$F39,$D$2:$D$91,I$37) -> 0 | J39: =SUM(G39:I39) -> 0 | L39: 0.5 | M39: =ABS(G$2-$F39)/1 -> 0.5 | N39: =ABS(H$2-$F39)/3 -> 0 | O39: =ABS(I$2-$F39)/1 -> 0.5 | Q39: 0.5 | R39: =($J39/$J$41) * (G$41/$J$41) -> #VALUE! | S39: =($J39/$J$41) * (H$41/$J$41) -> #VALUE! | T39: =($J39/$J$41) * (I$41/$J$41) -> #VALUE! | V39: Expected Weighted Disagreement (D_exp) | W39: =SUMPRODUCT(R38:T40, M38:O40) -> #VALUE! | X39: Sum of (expected cell proportions × weights) under chance agreement.
A40: ='Automatic Bread Maker Grader #1'!A41 -> State | B40: ='Automatic Bread Maker Grader #1'!B41 -> Rising | C40: ='Automatic Bread Maker Grader #1'!C41 -> 0 | D40: #REF! | F40: 1 | G40: =COUNTIFS($A$2:$A$47,$F$37,$C$2:$C$47,$F40,$D$2:$D$47,G$37)+MAX(C51-D51,0) -> #VALUE! | H40: =COUNTIFS($A$2:$A$91,$F$37,$C$2:$C$91,$F40,$D$2:$D$91,H$37) -> 0 | I40: =COUNTIFS($A$2:$A$47,$F$37,$C$2:$C$47,$F40,$D$2:$D$47,I$37) + MIN(C51,D51) -> 0 | J40: =SUM(G40:I40) -> #VALUE! | L40: 1 | M40: =ABS(G$2-$F40)/1 -> 1 | N40: =ABS(H$2-$F40)/1 -> 0.5 | O40: =ABS(I$2-$F40)/1 -> 0 | Q40: 1 | R40: =($J40/$J$41) * (G$41/$J$41) -> #VALUE! | S40: =($J40/$J$41) * (H$41/$J$41) -> #VALUE! | T40: =($J40/$J$41) * (I$41/$J$41) -> #VALUE! | V40: Cohen's Kappa | W40: =1-W38/W39 -> #VALUE! | X40: 1 - (D_obs / D_exp)
...
