Workbook

Sheet Dishwasher
A1: Type | B1: Element
A2: Composite State | B2: DishwasherOn
A3: Region | B3: Door
A4: State | B4: initial state (⇒ Closed)
A5: State | B5: Closed
A6: Transition | B6: open (Closed ⇒ Open)
A7: Transition | B7: lock (Closed ⇒ Locked)
A8: State | B8: Open
A9: Transition | B9: close (Open ⇒ Closed)
A10: State | B10: Locked
A11: Transition | B11: unlock (Locked ⇒ Closed)
A12: Region | B12: Washer
... A55: History State | B55: additional elements

Sheet Dishwasher Grader #1
A1: Type | B1: Element | C1: Claude | D1: Notes
A2: Composite State | B2: DishwasherOn
A3: Region | B3: Door
A4: State | B4: initial state (⇒ Closed)
A5: State | B5: Closed
A6: Transition | B6: open (Closed ⇒ Open)
A7: Transition | B7: lock (Closed ⇒ Locked)
A8: State | B8: Open
A9: Transition | B9: close (Open ⇒ Closed)
A10: State | B10: Locked
A11: Transition | B11: unlock (Locked ⇒ Closed)
A12: Region | B12: Washer
A13: State | B13: initial state
... A55: History State | B55: additional elements

Sheet Dishwasher Grader #2
A1: Type | B1: Element | C1: Claude | D1: Notes
A2: Composite State | B2: DishwasherOn | C2: 0
A3: Region | B3: Door | C3: 0
A4: State | B4: initial state (⇒ Closed) | C4: 0
A5: State | B5: Closed | C5: 0
A6: Transition | B6: open (Closed ⇒ Open) | C6: 0
A7: Transition | B7: lock (Closed ⇒ Locked) | C7: 0
A8: State | B8: Open | C8: 0
A9: Transition | B9: close (Open ⇒ Closed) | C9: 0
A10: State | B10: Locked | C10: 0
A11: Transition | B11: unlock (Locked ⇒ Closed) | C11: 0
A12: Region | B12: Washer | C12: 0
A13: State | B13: initial state | C13: 0
... A55: History State | B55: additional elements | C55: 0

Sheet Metrics
A1: Claude Grader #1 | J1: Date
A2: Type | B2: Ground Truth Count | C2: True Positive | D2: False Positive | E2: False Negative | F2: Precision | G2: Recall | H2: F1 Score
A3: Composite State | B3: =COUNTIF(Dishwasher!$A$2:$A$48, A3) -> 2 | C3: =SUMIF('Dishwasher Grader #1'!$A$2:$A$48, $A3, 'Dishwasher Grader #1'!$C$2:$C$48) -> 0 | D3: =SUMIF('Dishwasher Grader #1'!$A$49:$A$55, $A3, 'Dishwasher Grader #1'!$C$49:$C$55) -> 0 | E3: =COUNTIFS('Dishwasher Grader #1'!$A$2:$A$48, $A3, 'Dishwasher Grader #1'!$C$2:$C$48,0) -> 0 | F3: =IFERROR(C3 / (C3 + D3), "Not Available") -> Not Available | G3: =IFERROR(C3 / B3, "Not Available") -> 0 | H3: =IFERROR(2*((F3*G3)/(F3+G3)),"Not Available") -> Not Available
A4: State | B4: =COUNTIF(Dishwasher!$A$2:$A$48, A4) -> 12 | C4: =SUMIF('Dishwasher Grader #1'!$A$2:$A$48, $A4, 'Dishwasher Grader #1'!$C$2:$C$48) -> 0 | D4: =SUMIF('Dishwasher Grader #1'!$A$49:$A$55, $A4, 'Dishwasher Grader #1'!$C$49:$C$55) -> 0 | E4: =COUNTIFS('Dishwasher Grader #1'!$A$2:$A$48, $A4, 'Dishwasher Grader #1'!$C$2:$C$48,0) -> 0 | F4: =IFERROR(C4 / (C4 + D4), "Not Available") -> Not Available | G4: =IFERROR(C4 / B4, "Not Available") -> 0 | H4: =IFERROR(2*((F4*G4)/(F4+G4)),"Not Available") -> Not Available
A5: Transition | B5: =COUNTIF(Dishwasher!$A$2:$A$48, A5) -> 19 | C5: =SUMIF('Dishwasher Grader #1'!$A$2:$A$48, $A5, 'Dishwasher Grader #1'!$C$2:$C$48) -> 0 | D5: =SUMIF('Dishwasher Grader #1'!$A$49:$A$55, $A5, 'Dishwasher Grader #1'!$C$49:$C$55) -> 0 | E5: =COUNTIFS('Dishwasher Grader #1'!$A$2:$A$48, $A5, 'Dishwasher Grader #1'!$C$2:$C$48,0) -> 0 | F5: =IFERROR(C5 / (C5 + D5), "Not Available") -> Not Available | G5: =IFERROR(C5 / B5, "Not Available") -> 0 | H5: =IFERROR(2*((F5*G5)/(F5+G5)),"Not Available") -> Not Available
A6: Action | B6: =COUNTIF(Dishwasher!$A$2:$A$48, A6) -> 7 | C6: =SUMIF('Dishwasher Grader #1'!$A$2:$A$48, $A6, 'Dishwasher Grader #1'!$C$2:$C$48) -> 0 | D6: =SUMIF('Dishwasher Grader #1'!$A$49:$A$55, $A6, 'Dishwasher Grader #1'!$C$49:$C$55) -> 0 | E6: =COUNTIFS('Dishwasher Grader #1'!$A$2:$A$48, $A6, 'Dishwasher Grader #1'!$C$2:$C$48,0) -> 0 | F6: =IFERROR(C6 / (C6 + D6), "Not Available") -> Not Available | G6: =IFERROR(C6 / B6, "Not Available") -> 0 | H6: =IFERROR(2*((F6*G6)/(F6+G6)),"Not Available") -> Not Available
A7: Region | B7: =COUNTIF(Dishwasher!$A$2:$A$48, A7) -> 2 | C7: =SUMIF('Dishwasher Grader #1'!$A$2:$A$48, $A7, 'Dishwasher Grader #1'!$C$2:$C$48) -> 0 | D7: =SUMIF('Dishwasher Grader #1'!$A$49:$A$55, $A7, 'Dishwasher Grader #1'!$C$49:$C$55) -> 0 | E7: =COUNTIFS('Dishwasher Grader #1'!$A$2:$A$48, $A7, 'Dishwasher Grader #1'!$C$2:$C$48,0) -> 0 | F7: =IFERROR(C7 / (C7 + D7), "Not Available") -> Not Available | G7: =IFERROR(C7 / B7, "Not Available") -> 0 | H7: =IFERROR(2*((F7*G7)/(F7+G7)),"Not Available") -> Not Available
A8: History State | B8: =COUNTIF(Dishwasher!$A$2:$A$48, A8) -> 1 | C8: =SUMIF('Dishwasher Grader #1'!$A$2:$A$48, $A8, 'Dishwasher Grader #1'!$C$2:$C$48) -> 0 | D8: =SUMIF('Dishwasher Grader #1'!$A$49:$A$55, $A8, 'Dishwasher Grader #1'!$C$49:$C$55) -> 0 | E8: =COUNTIFS('Dishwasher Grader #1'!$A$2:$A$48, $A8, 'Dishwasher Grader #1'!$C$2:$C$48,0) -> 0 | F8: =IFERROR(C8 / (C8 + D8), "Not Available") -> Not Available | G8: =IFERROR(C8 / B8, "Not Available") -> 0 | H8: =IFERROR(2*((F8*G8)/(F8+G8)),"Not Available") -> Not Available
A9: Guard | B9: =COUNTIF(Dishwasher!$A$2:$A$48, A9) -> 4 | C9: =SUMIF('Dishwasher Grader #1'!$A$2:$A$48, $A9, 'Dishwasher Grader #1'!$C$2:$C$48) -> 0 | D9: =SUMIF('Dishwasher Grader #1'!$A$49:$A$55, $A9, 'Dishwasher Grader #1'!$C$49:$C$55) -> 0 | E9: =COUNTIFS('Dishwasher Grader #1'!$A$2:$A$48, $A9, 'Dishwasher Grader #1'!$C$2:$C$48,0) -> 0 | F9: =IFERROR(C9 / (C9 + D9), "Not Available") -> Not Available | G9: =IFERROR(C9 / B9, "Not Available") -> 0 | H9: =IFERROR(2*((F9*G9)/(F9+G9)),"Not Available") -> Not Available
A10: Overall Score | B10: =SUM(B3:B9) -> 47 | C10: =SUM(C3:C9) -> 0 | D10: =SUM(D3:D9) -> 0 | E10: =SUM(E3:E9) -> 0 | F10: =IFERROR(C10 / (C10 + D10), "Not Available") -> Not Available | G10: =IFERROR(C10 / B10, "Not Available") -> 0 | H10: =IFERROR(2*((F10*G10)/(F10+G10)),"Not Available") -> Not Available
A12: Claude Grader #2
A13: Type | B13: Ground Truth Count | C13: True Positive | D13: False Positive | E13: False Negative | F13: Precision | G13: Recall | H13: F1 Score
A14: Composite state | B14: =COUNTIF(Dishwasher!$A$2:$A$48, A14) -> 2 | C14: =SUMIF('Dishwasher Grader #2'!$A$2:$A$48, $A14, 'Dishwasher Grader #2'!$C$2:$C$48) -> 0 | D14: =SUMIF('Dishwasher Grader #2'!$A$49:$A$55, $A14, 'Dishwasher Grader #2'!$C$49:$C$55) -> 0 | E14: =COUNTIFS('Dishwasher Grader #2'!$A$2:$A$48, $A3, 'Dishwasher Grader #2'!$C$2:$C$48,0) -> 2 | F14: =IFERROR(C14 / (C14 + D14), "Not Available") -> Not Available | G14: =IFERROR(C14 / B14, "Not Available") -> 0 | H14: =IFERROR(2*((F14*G14)/(F14+G14)),"Not Available") -> Not Available
A15: State | B15: =COUNTIF(Dishwasher!$A$2:$A$48, A15) -> 12 | C15: =SUMIF('Dishwasher Grader #2'!$A$2:$A$48, $A15, 'Dishwasher Grader #2'!$C$2:$C$48) -> 0 | D15: =SUMIF('Dishwasher Grader #2'!$A$49:$A$55, $A15, 'Dishwasher Grader #2'!$C$49:$C$55) -> 0 | E15: =COUNTIFS('Dishwasher Grader #2'!$A$2:$A$48, $A4, 'Dishwasher Grader #2'!$C$2:$C$48,0) -> 12 | F15: =IFERROR(C15 / (C15 + D15), "Not Available") -> Not Available | G15: =IFERROR(C15 / B15, "Not Available") -> 0 | H15: =IFERROR(2*((F15*G15)/(F15+G15)),"Not Available") -> Not Available
A16: Transition | B16: =COUNTIF(Dishwasher!$A$2:$A$48, A16) -> 19 | C16: =SUMIF('Dishwasher Grader #2'!$A$2:$A$48, $A16, 'Dishwasher Grader #2'!$C$2:$C$48) -> 0 | D16: =SUMIF('Dishwasher Grader #2'!$A$49:$A$55, $A16, 'Dishwasher Grader #2'!$C$49:$C$55) -> 0 | E16: =COUNTIFS('Dishwasher Grader #2'!$A$2:$A$48, $A5, 'Dishwasher Grader #2'!$C$2:$C$48,0) -> 19 | F16: =IFERROR(C16 / (C16 + D16), "Not Available") -> Not Available | G16: =IFERROR(C16 / B16, "Not Available") -> 0 | H16: =IFERROR(2*((F16*G16)/(F16+G16)),"Not Available") -> Not Available
A17: Action | B17: =COUNTIF(Dishwasher!$A$2:$A$48, A17) -> 7 | C17: =SUMIF('Dishwasher Grader #2'!$A$2:$A$48, $A17, 'Dishwasher Grader #2'!$C$2:$C$48) -> 0 | D17: =SUMIF('Dishwasher Grader #2'!$A$49:$A$55, $A17, 'Dishwasher Grader #2'!$C$49:$C$55) -> 0 | E17: =COUNTIFS('Dishwasher Grader #2'!$A$2:$A$48, $A6, 'Dishwasher Grader #2'!$C$2:$C$48,0) -> 7 | F17: =IFERROR(C17 / (C17 + D17), "Not Available") -> Not Available | G17: =IFERROR(C17 / B17, "Not Available") -> 0 | H17: =IFERROR(2*((F17*G17)/(F17+G17)),"Not Available") -> Not Available
A18: Region | B18: =COUNTIF(Dishwasher!$A$2:$A$48, A18) -> 2 | C18: =SUMIF('Dishwasher Grader #2'!$A$2:$A$48, $A18, 'Dishwasher Grader #2'!$C$2:$C$48) -> 0 | D18: =SUMIF('Dishwasher Grader #2'!$A$49:$A$55, $A18, 'Dishwasher Grader #2'!$C$49:$C$55) -> 0 | E18: =COUNTIFS('Dishwasher Grader #2'!$A$2:$A$48, $A7, 'Dishwasher Grader #2'!$C$2:$C$48,0) -> 2 | F18: =IFERROR(C18 / (C18 + D18), "Not Available") -> Not Available | G18: =IFERROR(C18 / B18, "Not Available") -> 0 | H18: =IFERROR(2*((F18*G18)/(F18+G18)),"Not Available") -> Not Available
A19: History State | B19: =COUNTIF(Dishwasher!$A$2:$A$48, A19) -> 1 | C19: =SUMIF('Dishwasher Grader #2'!$A$2:$A$48, $A19, 'Dishwasher Grader #2'!$C$2:$C$48) -> 0 | D19: =SUMIF('Dishwasher Grader #2'!$A$49:$A$55, $A19, 'Dishwasher Grader #2'!$C$49:$C$55) -> 0 | E19: =COUNTIFS('Dishwasher Grader #2'!$A$2:$A$48, $A8, 'Dishwasher Grader #2'!$C$2:$C$48,0) -> 1 | F19: =IFERROR(C19 / (C19 + D19), "Not Available") -> Not Available | G19: =IFERROR(C19 / B19, "Not Available") -> 0 | H19: =IFERROR(2*((F19*G19)/(F19+G19)),"Not Available") -> Not Available
A20: Guard | B20: =COUNTIF(Dishwasher!$A$2:$A$48, A20) -> 4 | C20: =SUMIF('Dishwasher Grader #2'!$A$2:$A$48, $A20, 'Dishwasher Grader #2'!$C$2:$C$48) -> 0 | D20: =SUMIF('Dishwasher Grader #2'!$A$49:$A$55, $A20, 'Dishwasher Grader #2'!$C$49:$C$55) -> 0 | E20: =COUNTIFS('Dishwasher Grader #2'!$A$2:$A$48, $A9, 'Dishwasher Grader #2'!$C$2:$C$48,0) -> 4 | F20: =IFERROR(C20 / (C20 + D20), "Not Available") -> Not Available | G20: =IFERROR(C20 / B20, "Not Available") -> 0 | H20: =IFERROR(2*((F20*G20)/(F20+G20)),"Not Available") -> Not Available
A21: Overall Score | B21: =SUM(B14:B20) -> 47 | C21: =SUM(C14:C20) -> 0 | D21: =SUM(D14:D20) -> 0 | E21: =SUM(E14:E20) -> 47 | F21: =IFERROR(C21 / (C21 + D21), "Not Available") -> Not Available | G21: =IFERROR(C21 / B21, "Not Available") -> 0 | H21: =IFERROR(2*((F21*G21)/(F21+G21)),"Not Available") -> Not Available

Sheet Inter-rater
A1: Type | B1: Element | C1: Rater 1 | D1: Rater 2 | F1: Confusion Matrix | L1: Cohen's Kappa
A2: ='Dishwasher Grader #1'!A2 -> Composite State | B2: ='Dishwasher Grader #1'!B2 -> DishwasherOn | C2: ='Dishwasher Grader #1'!C2 | D2: ='Dishwasher Grader #2'!C2 -> 0 | F2: Global | G2: 0 | H2: 0.5 | I2: 1 | J2: Row Totals | L2: Metric | M2: Value | N2: Note
A3: ='Dishwasher Grader #1'!A3 -> Region | B3: ='Dishwasher Grader #1'!B3 -> Door | C3: ='Dishwasher Grader #1'!C3 | D3: ='Dishwasher Grader #2'!C3 -> 0 | F3: 0 | G3: =COUNTIFS($C$2:$C$92, $F3, $D$2:$D$92, G$2) -> 0 | H3: =COUNTIFS($C$2:$C$48, $F3, $D$2:$D$48, H$2) -> 0 | I3: =COUNTIFS($C$2:$C$48, $F3, $D$2:$D$48, I$2)+MAX(D49-C49,0)+MAX(D50-C50,0)+MAX(D51-C51,0)+MAX(D52-C52,0)+MAX(D53-C53,0)+MAX(D54-C54,0)+MAX(D55-C55,0) -> 0 | J3: =SUM(G3:I3) -> 0 | L3: Observed Agreement (Po) | M3: =(G3+H4+I5)/COUNTA($C$2:$C$102) -> #DIV/0! | N3: This sums the diagonal of your matrix divided by total rows.
A4: ='Dishwasher Grader #1'!A4 -> State | B4: ='Dishwasher Grader #1'!B4 -> initial state (⇒ Closed) | C4: ='Dishwasher Grader #1'!C4 | D4: ='Dishwasher Grader #2'!C4 -> 0 | F4: 0.5 | G4: =COUNTIFS($C$2:$C$48, $F4, $D$2:$D$48, G$2) -> 0 | H4: =COUNTIFS($C$2:$C$48, $F4, $D$2:$D$48, H$2) -> 0 | I4: =COUNTIFS($C$2:$C$48, $F4, $D$2:$D$48, I$2) -> 0 | J4: =SUM(G4:I4) -> 0 | L4: Expected Agreement (Pe) | M4: {=SUMPRODUCT(J3:J5/COUNTA($C$2:$C$102), TRANSPOSE(G6:I6)/COUNTA($C$2:$C$102))} -> #DIV/0! | N4: This computes the sum of row proportion times column proportion.
A5: ='Dishwasher Grader #1'!A5 -> State | B5: ='Dishwasher Grader #1'!B5 -> Closed | C5: ='Dishwasher Grader #1'!C5 | D5: ='Dishwasher Grader #2'!C5 -> 0 | F5: 1 | G5: =COUNTIFS($C$2:$C$48, $F5, $D$2:$D$48, G$2)+MAX(C49-D49,0)+MAX(C50-D50,0)+MAX(C51-D51,0)+MAX(C52-D52,0)+MAX(C53-D53,0)+MAX(C54-D54,0)+MAX(C55-D55,0) -> 0 | H5: =COUNTIFS($C$2:$C$48, $F5, $D$2:$D$48, H$2) -> 0 | I5: =COUNTIFS($C$2:$C$48, $F5, $D$2:$D$48, I$2)+ SUM(MIN(C49,D49), MIN(C50,D50), MIN(C51,D51), MIN(C52,D52), MIN(C53,D53), MIN(C54,D54), MIN(C55,D55)) -> 0 | J5: =SUM(G5:I5) -> 0 | L5: Cohen's Kappa | M5: =(M3-M4)/(1-M4) -> #DIV/0! | N5: (Po - Pe) / (1 - Pe)
A6: ='Dishwasher Grader #1'!A6 -> Transition | B6: ='Dishwasher Grader #1'!B6 -> open (Closed ⇒ Open) | C6: ='Dishwasher Grader #1'!C6 | D6: ='Dishwasher Grader #2'!C6 -> 0 | F6: Column Totals | G6: =SUM(G3:G5) -> 0 | H6: =SUM(H3:H5) -> 0 | I6: =SUM(I3:I5) -> 0
A7: ='Dishwasher Grader #1'!A7 -> Transition | B7: ='Dishwasher Grader #1'!B7 -> lock (Closed ⇒ Locked) | C7: ='Dishwasher Grader #1'!C7 | D7: ='Dishwasher Grader #2'!C7 -> 0
A8: ='Dishwasher Grader #1'!A8 -> State | B8: ='Dishwasher Grader #1'!B8 -> Open | C8: ='Dishwasher Grader #1'!C8 | D8: ='Dishwasher Grader #2'!C8 -> 0 | F8: Confusion Matrix (State) | L8: Cohen's Kappa (State)
A9: ='Dishwasher Grader #1'!A9 -> Transition | B9: ='Dishwasher Grader #1'!B9 -> close (Open ⇒ Closed) | C9: ='Dishwasher Grader #1'!C9 | D9: ='Dishwasher Grader #2'!C9 -> 0 | F9: State | G9: 0 | H9: 0.5 | I9: 1 | J9: Row Totals | L9: Metric | M9: Value | N9: Note
A10: ='Dishwasher Grader #1'!A10 -> State | B10: ='Dishwasher Grader #1'!B10 -> Locked | C10: ='Dishwasher Grader #1'!C10 | D10: ='Dishwasher Grader #2'!C10 -> 0 | F10: 0 | G10: =COUNTIFS($A$2:$A$92,$F$9,$C$2:$C$92,$F10,$D$2:$D$92,G$9) -> 0 | H10: =COUNTIFS($A$2:$A$92,$F$9,$C$2:$C$92,$F10,$D$2:$D$92,H$9) -> 0 | I10: =COUNTIFS($A$2:$A$48,$F$9,$C$2:$C$48,$F10,$D$2:$D$48,I$9)+MAX(D49-C49,0) -> 0 | J10: =SUM(G10:I10) -> 0 | L10: Observed Agreement (Po) | M10: =(G10+H11+I12)/COUNTIF($A$2:$A$102,F9) -> 0 | N10: This sums the diagonal of your matrix divided by total rows.
A11: ='Dishwasher Grader #1'!A11 -> Transition | B11: ='Dishwasher Grader #1'!B11 -> unlock (Locked ⇒ Closed) | C11: ='Dishwasher Grader #1'!C11 | D11: ='Dishwasher Grader #2'!C11 -> 0 | F11: 0.5 | G11: =COUNTIFS($A$2:$A$92,$F$9,$C$2:$C$92,$F11,$D$2:$D$92,G$9) -> 0 | H11: =COUNTIFS($A$2:$A$92,$F$9,$C$2:$C$92,$F11,$D$2:$D$92,H$9) -> 0 | I11: =COUNTIFS($A$2:$A$92,$F$9,$C$2:$C$92,$F11,$D$2:$D$92,I$9) -> 0 | J11: =SUM(G11:I11) -> 0 | L11: Expected Agreement (Pe) | M11: {=SUMPRODUCT(J10:J12/COUNTIF($A$2:$A$102,F9), TRANSPOSE(G13:I13)/COUNTIF($A$2:$A$102,F9))} -> 0 | N11: This computes the sum of row proportion times column proportion.
A12: ='Dishwasher Grader #1'!A12 -> Region | B12: ='Dishwasher Grader #1'!B12 -> Washer | C12: ='Dishwasher Grader #1'!C12 | D12: ='Dishwasher Grader #2'!C12 -> 0 | F12: 1 | G12: =COUNTIFS($A$2:$A$48,$F$9,$C$2:$C$48,$F12,$D$2:$D$48,G$9)+MAX(C49-D49,0) -> 0 | H12: =COUNTIFS($A$2:$A$92,$F$9,$C$2:$C$92,$F12,$D$2:$D$92,H$9) -> 0 | I12: =COUNTIFS($A$2:$A$48,$F$9,$C$2:$C$48,$F12,$D$2:$D$48,I$9)+MIN(C49-D49) -> 0 | J12: =SUM(G12:I12) -> 0 | L12: Cohen's Kappa | M12: =(M10-M11)/(1-M11) -> 0 | N12: (Po - Pe) / (1 - Pe)
A13: ='Dishwasher Grader #1'!A13 -> State | B13: ='Dishwasher Grader #1'!B13 -> initial state | C13: ='Dishwasher Grader #1'!C13 | D13: ='Dishwasher Grader #2'!C13 -> 0 | F13: Column Totals | G13: =SUM(G10:G12) -> 0 | H13: =SUM(H10:H12) -> 0 | I13: =SUM(I10:I12) -> 0
A14: ='Dishwasher Grader #1'!A14 -> Transition | B14: ='Dishwasher Grader #1'!B14 -> r =1; dT=20; (initial state ⇒ Idle) | C14: ='Dishwasher Grader #1'!C14 | D14: ='Dishwasher Grader #2'!C14 -> 0
A15: ='Dishwasher Grader #1'!A15 -> State | B15: ='Dishwasher Grader #1'!B15 -> Idle | C15: ='Dishwasher Grader #1'!C15 | D15: ='Dishwasher Grader #2'!C15 -> 0 | F15: Confusion Matrix (Transition) | L15: Cohen's Kappa (Transition)
A16: ='Dishwasher Grader #1'!A16 -> Transition | B16: ='Dishwasher Grader #1'!B16 -> selectProgram(n) (Idle ⇒ Idle) | C16: ='Dishwasher Grader #1'!C16 | D16: ='Dishwasher Grader #2'!C16 -> 0 | F16: Transition | G16: 0 | H16: 0.5 | I16: 1 | J16: Row Totals | L16: Metric | M16: Value | N16: Note
A17: ='Dishwasher Grader #1'!A17 -> Guard | B17: ='Dishwasher Grader #1'!B17 -> [n ≥ 1] | C17: ='Dishwasher Grader #1'!C17 | D17: ='Dishwasher Grader #2'!C17 -> 0 | F17: 0 | G17: =COUNTIFS($A$2:$A$92,$F$16,$C$2:$C$92,$F17,$D$2:$D$92,G$16) -> 0 | H17: =COUNTIFS($A$2:$A$92,$F$16,$C$2:$C$92,$F17,$D$2:$D$92,H$16) -> 0 | I17: =COUNTIFS($A$2:$A$48,$F$16,$C$2:$C$48,$F17,$D$2:$D$48,I$16) + MAX(D50-C50,0) -> 0 | J17: =SUM(G17:I17) -> 0 | L17: Observed Agreement (Po) | M17: =(G17+H18+I19)/COUNTIF($A$2:$A$102,F16) -> 0 | N17: This sums the diagonal of your matrix divided by total rows.
A18: ='Dishwasher Grader #1'!A18 -> Action | B18: ='Dishwasher Grader #1'!B18 -> r = n; | C18: ='Dishwasher Grader #1'!C18 | D18: ='Dishwasher Grader #2'!C18 -> 0 | F18: 0.5 | G18: =COUNTIFS($A$2:$A$92,$F$16,$C$2:$C$92,$F18,$D$2:$D$92,G$16) -> 0 | H18: =COUNTIFS($A$2:$A$92,$F$16,$C$2:$C$92,$F18,$D$2:$D$92,H$16) -> 0 | I18: =COUNTIFS($A$2:$A$92,$F$16,$C$2:$C$92,$F18,$D$2:$D$92,I$16) -> 0 | J18: =SUM(G18:I18) -> 0 | L18: Expected Agreement (Pe) | M18: {=SUMPRODUCT(J17:J19/COUNTIF($A$2:$A$102,F16), TRANSPOSE(G20:I20)/COUNTIF($A$2:$A$102,F16))} -> 0 | N18: This computes the sum of row proportion times column proportion.
A19: ='Dishwasher Grader #1'!A19 -> Transition | B19: ='Dishwasher Grader #1'!B19 -> toggleDryingTime (Idle ⇒ Idle) | C19: ='Dishwasher Grader #1'!C19 | D19: ='Dishwasher Grader #2'!C19 -> 0 | F19: 1 | G19: =COUNTIFS($A$2:$A$48,$F$16,$C$2:$C$48,$F19,$D$2:$D$48,G$16)+MAX(C50-D50,0) -> 0 | H19: =COUNTIFS($A$2:$A$92,$F$16,$C$2:$C$92,$F19,$D$2:$D$92,H$16) -> 0 | I19: =COUNTIFS($A$2:$A$48,$F$16,$C$2:$C$48,$F19,$D$2:$D$48,I$16) + MIN(C50,D50) -> 0 | J19: =SUM(G19:I19) -> 0 | L19: Cohen's Kappa | M19: =(M17-M18)/(1-M18) -> 0 | N19: (Po - Pe) / (1 - Pe)
A20: ='Dishwasher Grader #1'!A20 -> Action | B20: ='Dishwasher Grader #1'!B20 -> if dT = 20 then dT = 40 else dT = 20; | C20: ='Dishwasher Grader #1'!C20 | D20: ='Dishwasher Grader #2'!C20 -> 0 | F20: Column Totals | G20: =SUM(G17:G19) -> 0 | H20: =SUM(H17:H19) -> 0 | I20: =SUM(I17:I19) -> 0
A21: ='Dishwasher Grader #1'!A21 -> Transition | B21: ='Dishwasher Grader #1'!B21 -> start (Idle ⇒ Cleaning) | C21: ='Dishwasher Grader #1'!C21 | D21: ='Dishwasher Grader #2'!C21 -> 0
A22: ='Dishwasher Grader #1'!A22 -> Guard | B22: ='Dishwasher Grader #1'!B22 -> [door.isClosed()] | C22: ='Dishwasher Grader #1'!C22 | D22: ='Dishwasher Grader #2'!C22 -> 0 | F22: Confusion Matrix (Composite State) | L22: Cohen's Kappa (Composite State)
A23: ='Dishwasher Grader #1'!A23 -> Action | B23: ='Dishwasher Grader #1'!B23 -> door.lock(); c = 1; | C23: ='Dishwasher Grader #1'!C23 | D23: ='Dishwasher Grader #2'!C23 -> 0 | F23: Composite State | G23: 0 | H23: 0.5 | I23: 1 | J23: Row Totals | L23: Metric | M23: Value | N23: Note
A24: ='Dishwasher Grader #1'!A24 -> Composite State | B24: ='Dishwasher Grader #1'!B24 -> Cleaning | C24: ='Dishwasher Grader #1'!C24 | D24: ='Dishwasher Grader #2'!C24 -> 0 | F24: 0 | G24: =COUNTIFS($A$2:$A$92,$F$23,$C$2:$C$92,$F24,$D$2:$D$92,G$23) -> 0 | H24: =COUNTIFS($A$2:$A$92,$F$23,$C$2:$C$92,$F24,$D$2:$D$92,H$23) -> 0 | I24: =COUNTIFS($A$2:$A$48,$F$23,$C$2:$C$48,$F24,$D$2:$D$48,I$23) + MAX(D53-C53,0) -> 0 | J24: =SUM(G24:I24) -> 0 | L24: Observed Agreement (Po) | M24: =(G24+H25+I26)/COUNTIF($A$2:$A$102,F23) -> 0 | N24: This sums the diagonal of your matrix divided by total rows.
A25: ='Dishwasher Grader #1'!A25 -> State | B25: ='Dishwasher Grader #1'!B25 -> initial state (⇒ Intake) | C25: ='Dishwasher Grader #1'!C25 | D25: ='Dishwasher Grader #2'!C25 -> 0 | F25: 0.5 | G25: =COUNTIFS($A$2:$A$92,$F$23,$C$2:$C$92,$F25,$D$2:$D$92,G$23) -> 0 | H25: =COUNTIFS($A$2:$A$92,$F$23,$C$2:$C$92,$F25,$D$2:$D$92,H$23) -> 0 | I25: =COUNTIFS($A$2:$A$92,$F$23,$C$2:$C$92,$F25,$D$2:$D$92,I$23) -> 0 | J25: =SUM(G25:I25) -> 0 | L25: Expected Agreement (Pe) | M25: {=SUMPRODUCT(J24:J26/COUNTIF($A$2:$A$102,F23), TRANSPOSE(G27:I27)/COUNTIF($A$2:$A$102,F23))} -> 0 | N25: This computes the sum of row proportion times column proportion.
A26: ='Dishwasher Grader #1'!A26 -> State | B26: ='Dishwasher Grader #1'!B26 -> Intake | C26: ='Dishwasher Grader #1'!C26 | D26: ='Dishwasher Grader #2'!C26 -> 0 | F26: 1 | G26: =COUNTIFS($A$2:$A$48,$F$23,$C$2:$C$48,$F26,$D$2:$D$48,G$23) + MAX(C53-D53,0) -> 0 | H26: =COUNTIFS($A$2:$A$92,$F$23,$C$2:$C$92,$F26,$D$2:$D$92,H$23) -> 0 | I26: =COUNTIFS($A$2:$A$48,$F$23,$C$2:$C$48,$F26,$D$2:$D$48,I$23) + MIN(C53,D53) -> 0 | J26: =SUM(G26:I26) -> 0 | L26: Cohen's Kappa | M26: =(M24-M25)/(1-M25) -> 0 | N26: (Po - Pe) / (1 - Pe)
A27: ='Dishwasher Grader #1'!A27 -> Transition | B27: ='Dishwasher Grader #1'!B27 -> Intake ⇒ Washing | C27: ='Dishwasher Grader #1'!C27 | D27: ='Dishwasher Grader #2'!C27 -> 0 | F27: Column Totals | G27: =SUM(G24:G26) -> 0 | H27: =SUM(H24:H26) -> 0 | I27: =SUM(I24:I26) -> 0
A28: ='Dishwasher Grader #1'!A28 -> State | B28: ='Dishwasher Grader #1'!B28 -> Washing | C28: ='Dishwasher Grader #1'!C28 | D28: ='Dishwasher Grader #2'!C28 -> 0
A29: ='Dishwasher Grader #1'!A29 -> Transition | B29: ='Dishwasher Grader #1'!B29 -> after 10 min (Washing ⇒ Drain) | C29: ='Dishwasher Grader #1'!C29 | D29: ='Dishwasher Grader #2'!C29 -> 0 | F29: Confusion Matrix (Guard) | L29: Cohen's Kappa (Guard)
A30: ='Dishwasher Grader #1'!A30 -> State | B30: ='Dishwasher Grader #1'!B30 -> Drain | C30: ='Dishwasher Grader #1'!C30 | D30: ='Dishwasher Grader #2'!C30 -> 0 | F30: Guard | G30: 0 | H30: 0.5 | I30: 1 | J30: Row Totals | L30: Metric | M30: Value | N30: Note
A31: ='Dishwasher Grader #1'!A31 -> Guard | B31: ='Dishwasher Grader #1'!B31 -> [c < r] | C31: ='Dishwasher Grader #1'!C31 | D31: ='Dishwasher Grader #2'!C31 -> 0 | F31: 0 | G31: =COUNTIFS($A$2:$A$92,$F$30,$C$2:$C$92,$F31,$D$2:$D$92,G$30) -> 0 | H31: =COUNTIFS($A$2:$A$92,$F$30,$C$2:$C$92,$F31,$D$2:$D$92,H$30) -> 0 | I31: =COUNTIFS($A$2:$A$48,$F$30,$C$2:$C$48,$F31,$D$2:$D$48,I$30) + MAX(D51-C51,0) -> 0 | J31: =SUM(G31:I31) -> 0 | L31: Observed Agreement (Po) | M31: =(G31+H32+I33)/COUNTIF($A$2:$A$102,F30) -> 0 | N31: This sums the diagonal of your matrix divided by total rows.
A32: ='Dishwasher Grader #1'!A32 -> Transition | B32: ='Dishwasher Grader #1'!B32 -> Drain ⇒ Intake | C32: ='Dishwasher Grader #1'!C32 | D32: ='Dishwasher Grader #2'!C32 -> 0 | F32: 0.5 | G32: =COUNTIFS($A$2:$A$92,$F$30,$C$2:$C$92,$F32,$D$2:$D$92,G$30) -> 0 | H32: =COUNTIFS($A$2:$A$92,$F$30,$C$2:$C$92,$F32,$D$2:$D$92,H$30) -> 0 | I32: =COUNTIFS($A$2:$A$92,$F$30,$C$2:$C$92,$F32,$D$2:$D$92,I$30) -> 0 | J32: =SUM(G32:I32) -> 0 | L32: Expected Agreement (Pe) | M32: {=SUMPRODUCT(J31:J33/COUNTIF($A$2:$A$102,F30), TRANSPOSE(G34:I34)/COUNTIF($A$2:$A$102,F30))} -> 0 | N32: This computes the sum of row proportion times column proportion.
A33: ='Dishwasher Grader #1'!A33 -> Action | B33: ='Dishwasher Grader #1'!B33 -> c++ | C33: ='Dishwasher Grader #1'!C33 | D33: ='Dishwasher Grader #2'!C33 -> 0 | F33: 1 | G33: =COUNTIFS($A$2:$A$48,$F$30,$C$2:$C$48,$F33,$D$2:$D$48,G$30) + MAX(C51-D51,0) -> 0 | H33: =COUNTIFS($A$2:$A$92,$F$30,$C$2:$C$92,$F33,$D$2:$D$92,H$30) -> 0 | I33: =COUNTIFS($A$2:$A$48,$F$30,$C$2:$C$48,$F33,$D$2:$D$48,I$30) + MIN(C51,D51) -> 0 | J33: =SUM(G33:I33) -> 0 | L33: Cohen's Kappa | M33: =(M31-M32)/(1-M32) -> 0 | N33: (Po - Pe) / (1 - Pe)
A34: ='Dishwasher Grader #1'!A34 -> Transition | B34: ='Dishwasher Grader #1'!B34 -> (Drain ⇒ end state) | C34: ='Dishwasher Grader #1'!C34 | D34: ='Dishwasher Grader #2'!C34 -> 0 | F34: Column Totals | G34: =SUM(G31:G33) -> 0 | H34: =SUM(H31:H33) -> 0 | I34: =SUM(I31:I33) -> 0
A35: ='Dishwasher Grader #1'!A35 -> Guard | B35: ='Dishwasher Grader #1'!B35 -> [c ≥ r] | C35: ='Dishwasher Grader #1'!C35 | D35: ='Dishwasher Grader #2'!C35 -> 0
A36: ='Dishwasher Grader #1'!A36 -> History State | B36: ='Dishwasher Grader #1'!B36 -> History State for Cleaning | C36: ='Dishwasher Grader #1'!C36 | D36: ='Dishwasher Grader #2'!C36 -> 0 | F36: Confusion Matrix (Action) | L36: Cohen's Kappa (Action)
A37: ='Dishwasher Grader #1'!A37 -> Transition | B37: ='Dishwasher Grader #1'!B37 -> toggleDryingTime (Cleaning ⇒ History State) | C37: ='Dishwasher Grader #1'!C37 | D37: ='Dishwasher Grader #2'!C37 -> 0 | F37: Action | G37: 0 | H37: 0.5 | I37: 1 | J37: Row Totals | L37: Metric | M37: Value | N37: Note
A38: ='Dishwasher Grader #1'!A38 -> Action | B38: ='Dishwasher Grader #1'!B38 -> if dT = 20 then dT = 40 else dT = 20; | C38: ='Dishwasher Grader #1'!C38 | D38: ='Dishwasher Grader #2'!C38 -> 0 | F38: 0 | G38: =COUNTIFS($A$2:$A$92,$F$37,$C$2:$C$92,$F38,$D$2:$D$92,G$37) -> 0 | H38: =COUNTIFS($A$2:$A$92,$F$37,$C$2:$C$92,$F38,$D$2:$D$92,H$37) -> 0 | I38: =COUNTIFS($A$2:$A$48,$F$37,$C$2:$C$48,$F38,$D$2:$D$48,I$37)+MAX(D52-C52,0) -> 0 | J38: =SUM(G38:I38) -> 0 | L38: Observed Agreement (Po) | M38: =(G38+H39+I40)/COUNTIF($A$2:$A$102,F37) -> 0 | N38: This sums the diagonal of your matrix divided by total rows.
A39: ='Dishwasher Grader #1'!A39 -> Transition | B39: ='Dishwasher Grader #1'!B39 -> Cleaning ⇒ Drying | C39: ='Dishwasher Grader #1'!C39 | D39: ='Dishwasher Grader #2'!C39 -> 0 | F39: 0.5 | G39: =COUNTIFS($A$2:$A$92,$F$37,$C$2:$C$92,$F39,$D$2:$D$92,G$37) -> 0 | H39: =COUNTIFS($A$2:$A$92,$F$37,$C$2:$C$92,$F39,$D$2:$D$92,H$37) -> 0 | I39: =COUNTIFS($A$2:$A$92,$F$37,$C$2:$C$92,$F39,$D$2:$D$92,I$37) -> 0 | J39: =SUM(G39:I39) -> 0 | L39: Expected Agreement (Pe) | M39: {=SUMPRODUCT(J38:J40/COUNTIF($A$2:$A$102,F37), TRANSPOSE(G41:I41)/COUNTIF($A$2:$A$102,F37))} -> 0 | N39: This computes the sum of row proportion times column proportion.
A40: ='Dishwasher Grader #1'!A40 -> Action | B40: ='Dishwasher Grader #1'!B40 -> door.unlock(); | C40: ='Dishwasher Grader #1'!C40 | D40: ='Dishwasher Grader #2'!C40 -> 0 | F40: 1 | G40: =COUNTIFS($A$2:$A$48,$F$37,$C$2:$C$48,$F40,$D$2:$D$48,G$37)+MAX(C52-D52,0) -> 0 | H40: =COUNTIFS($A$2:$A$92,$F$37,$C$2:$C$92,$F40,$D$2:$D$92,H$37) -> 0 | I40: =COUNTIFS($A$2:$A$48,$F$37,$C$2:$C$48,$F40,$D$2:$D$48,I$37) + MIN(C52,D52) -> 0 | J40: =SUM(G40:I40) -> 0 | L40: Cohen's Kappa | M40: =(M38-M39)/(1-M39) -> 0 | N40: (Po - Pe) / (1 - Pe)
...

Sheet Weighted Cohens Kappa
A1: Type | B1: Element | C1: Rater 1 | D1: Rater 2 | F1: Confusion Matrix | L1: Weight Matrix
A2: ='Dishwasher Grader #1'!A2 -> Composite State | B2: ='Dishwasher Grader #1'!B2 -> DishwasherOn | C2: ='Dishwasher Grader #1'!C2 | D2: ='Dishwasher Grader #2'!C2 -> 0 | F2: Global | G2: 0 | H2: 0.5 | I2: 1 | J2: Row Totals | L2: Global | M2: 0 | N2: 0.5 | O2: 1 | Q2: Global | R2: 0 | S2: 0.5 | T2: 1 | V2: ="Metrics" & " " & F2 -> Metrics Global | W2: Value | X2: Note
A3: ='Dishwasher Grader #1'!A3 -> Region | B3: ='Dishwasher Grader #1'!B3 -> Door | C3: ='Dishwasher Grader #1'!C3 | D3: ='Dishwasher Grader #2'!C3 -> 0 | F3: 0 | G3: =COUNTIFS($C$2:$C$92, $F3, $D$2:$D$92, G$2) -> 0 | H3: =COUNTIFS($C$2:$C$48, $F3, $D$2:$D$48, H$2) -> 0 | I3: =COUNTIFS($C$2:$C$48, $F3, $D$2:$D$48, I$2)+MAX(D49-C49,0)+MAX(D50-C50,0)+MAX(D51-C51,0)+MAX(D52-C52,0)+MAX(D53-C53,0)+MAX(D54-C54,0)+MAX(D55-C55,0) -> 0 | J3: =SUM(G3:I3) -> 0 | L3: 0 | M3: =ABS(G$2-$F3)/1 -> 0 | N3: =ABS(H$2-$F3)/1 -> 0.5 | O3: =ABS(I$2-$F3)/1 -> 1 | Q3: 0 | R3: =($J3/$J$6) * (G$6/$J$6) -> #DIV/0! | S3: =($J3/$J$6) * (H$6/$J$6) -> #DIV/0! | T3: =($J3/$J$6) * (I$6/$J$6) -> #DIV/0! | V3: Observed Weighted Disagreement (D_obs) | W3: =SUMPRODUCT(G3:I5, M3:O5) /$J$6 -> #DIV/0! | X3: Sum of (confusion-matrix counts × weights) divided by total items.
A4: ='Dishwasher Grader #1'!A4 -> State | B4: ='Dishwasher Grader #1'!B4 -> initial state (⇒ Closed) | C4: ='Dishwasher Grader #1'!C4 | D4: ='Dishwasher Grader #2'!C4 -> 0 | F4: 0.5 | G4: =COUNTIFS($C$2:$C$48, $F4, $D$2:$D$48, G$2) -> 0 | H4: =COUNTIFS($C$2:$C$48, $F4, $D$2:$D$48, H$2) -> 0 | I4: =COUNTIFS($C$2:$C$48, $F4, $D$2:$D$48, I$2) -> 0 | J4: =SUM(G4:I4) -> 0 | L4: 0.5 | M4: =ABS(G$2-$F4)/1 -> 0.5 | N4: =ABS(H$2-$F4)/3 -> 0 | O4: =ABS(I$2-$F4)/1 -> 0.5 | Q4: 0.5 | R4: =($J4/$J$6) * (G$6/$J$6) -> #DIV/0! | S4: =($J4/$J$6) * (H$6/$J$6) -> #DIV/0! | T4: =($J4/$J$6) * (I$6/$J$6) -> #DIV/0! | V4: Expected Weighted Disagreement (D_exp) | W4: =SUMPRODUCT(R3:T5, M3:O5) -> #DIV/0! | X4: Sum of (expected cell proportions × weights) under chance agreement.
A5: ='Dishwasher Grader #1'!A5 -> State | B5: ='Dishwasher Grader #1'!B5 -> Closed | C5: ='Dishwasher Grader #1'!C5 | D5: ='Dishwasher Grader #2'!C5 -> 0 | F5: 1 | G5: =COUNTIFS($C$2:$C$48, $F5, $D$2:$D$48, G$2)+MAX(C49-D49,0)+MAX(C50-D50,0)+MAX(C51-D51,0)+MAX(C52-D52,0)+MAX(C53-D53,0)+MAX(C54-D54,0)+MAX(C55-D55,0) -> 0 | H5: =COUNTIFS($C$2:$C$48, $F5, $D$2:$D$48, H$2) -> 0 | I5: =COUNTIFS($C$2:$C$48, $F5, $D$2:$D$48, I$2)+ SUM(MIN(C49,D49), MIN(C50,D50), MIN(C51,D51), MIN(C52,D52), MIN(C53,D53), MIN(C54,D54), MIN(C55,D55)) -> 0 | J5: =SUM(G5:I5) -> 0 | L5: 1 | M5: =ABS(G$2-$F5)/1 -> 1 | N5: =ABS(H$2-$F5)/1 -> 0.5 | O5: =ABS(I$2-$F5)/1 -> 0 | Q5: 1 | R5: =($J5/$J$6) * (G$6/$J$6) -> #DIV/0! | S5: =($J5/$J$6) * (H$6/$J$6) -> #DIV/0! | T5: =($J5/$J$6) * (I$6/$J$6) -> #DIV/0! | V5: Cohen's Kappa | W5: =1-W3/W4 -> #DIV/0! | X5: 1 - (D_obs / D_exp)
A6: ='Dishwasher Grader #1'!A6 -> Transition | B6: ='Dishwasher Grader #1'!B6 -> open (Closed ⇒ Open) | C6: ='Dishwasher Grader #1'!C6 | D6: ='Dishwasher Grader #2'!C6 -> 0 | F6: Column Totals | G6: =SUM(G3:G5) -> 0 | H6: =SUM(H3:H5) -> 0 | I6: =SUM(I3:I5) -> 0 | J6: =SUM(G3:I5) -> 0
A7: ='Dishwasher Grader #1'!A7 -> Transition | B7: ='Dishwasher Grader #1'!B7 -> lock (Closed ⇒ Locked) | C7: ='Dishwasher Grader #1'!C7 | D7: ='Dishwasher Grader #2'!C7 -> 0
A8: ='Dishwasher Grader #1'!A8 -> State | B8: ='Dishwasher Grader #1'!B8 -> Open | C8: ='Dishwasher Grader #1'!C8 | D8: ='Dishwasher Grader #2'!C8 -> 0 | F8: Confusion Matrix (State)
A9: ='Dishwasher Grader #1'!A9 -> Transition | B9: ='Dishwasher Grader #1'!B9 -> close (Open ⇒ Closed) | C9: ='Dishwasher Grader #1'!C9 | D9: ='Dishwasher Grader #2'!C9 -> 0 | F9: State | G9: 0 | H9: 0.5 | I9: 1 | J9: Row Totals | L9: Global | M9: 0 | N9: 0.5 | O9: 1 | Q9: Global | R9: 0 | S9: 0.5 | T9: 1 | V9: ="Metrics" & " " & F9 -> Metrics State | W9: Value | X9: Note
A10: ='Dishwasher Grader #1'!A10 -> State | B10: ='Dishwasher Grader #1'!B10 -> Locked | C10: ='Dishwasher Grader #1'!C10 | D10: ='Dishwasher Grader #2'!C10 -> 0 | F10: 0 | G10: =COUNTIFS($A$2:$A$92,$F$9,$C$2:$C$92,$F10,$D$2:$D$92,G$9) -> 0 | H10: =COUNTIFS($A$2:$A$92,$F$9,$C$2:$C$92,$F10,$D$2:$D$92,H$9) -> 0 | I10: =COUNTIFS($A$2:$A$48,$F$9,$C$2:$C$48,$F10,$D$2:$D$48,I$9)+MAX(D49-C49,0) -> 0 | J10: =SUM(G10:I10) -> 0 | L10: 0 | M10: =ABS(G$2-$F10)/1 -> 0 | N10: =ABS(H$2-$F10)/1 -> 0.5 | O10: =ABS(I$2-$F10)/1 -> 1 | Q10: 0 | R10: =($J10/$J$13) * (G$13/$J$13) -> #DIV/0! | S10: =($J10/$J$13) * (H$13/$J$13) -> #DIV/0! | T10: =($J10/$J$13) * (I$13/$J$13) -> #DIV/0! | V10: Observed Weighted Disagreement (D_obs) | W10: =SUMPRODUCT(G10:I12, M10:O12) /$J$13 -> #DIV/0! | X10: Sum of (confusion-matrix counts × weights) divided by total items.
A11: ='Dishwasher Grader #1'!A11 -> Transition | B11: ='Dishwasher Grader #1'!B11 -> unlock (Locked ⇒ Closed) | C11: ='Dishwasher Grader #1'!C11 | D11: ='Dishwasher Grader #2'!C11 -> 0 | F11: 0.5 | G11: =COUNTIFS($A$2:$A$92,$F$9,$C$2:$C$92,$F11,$D$2:$D$92,G$9) -> 0 | H11: =COUNTIFS($A$2:$A$92,$F$9,$C$2:$C$92,$F11,$D$2:$D$92,H$9) -> 0 | I11: =COUNTIFS($A$2:$A$92,$F$9,$C$2:$C$92,$F11,$D$2:$D$92,I$9) -> 0 | J11: =SUM(G11:I11) -> 0 | L11: 0.5 | M11: =ABS(G$2-$F11)/1 -> 0.5 | N11: =ABS(H$2-$F11)/3 -> 0 | O11: =ABS(I$2-$F11)/1 -> 0.5 | Q11: 0.5 | R11: =($J11/$J$13) * (G$13/$J$13) -> #DIV/0! | S11: =($J11/$J$13) * (H$13/$J$13) -> #DIV/0! | T11: =($J11/$J$13) * (I$13/$J$13) -> #DIV/0! | V11: Expected Weighted Disagreement (D_exp) | W11: =SUMPRODUCT(R10:T12, M10:O12) -> #DIV/0! | X11: Sum of (expected cell proportions × weights) under chance agreement.
A12: ='Dishwasher Grader #1'!A12 -> Region | B12: ='Dishwasher Grader #1'!B12 -> Washer | C12: ='Dishwasher Grader #1'!C12 | D12: ='Dishwasher Grader #2'!C12 -> 0 | F12: 1 | G12: =COUNTIFS($A$2:$A$48,$F$9,$C$2:$C$48,$F12,$D$2:$D$48,G$9)+MAX(C49-D49,0) -> 0 | H12: =COUNTIFS($A$2:$A$92,$F$9,$C$2:$C$92,$F12,$D$2:$D$92,H$9) -> 0 | I12: =COUNTIFS($A$2:$A$48,$F$9,$C$2:$C$48,$F12,$D$2:$D$48,I$9)+MIN(C49-D49) -> 0 | J12: =SUM(G12:I12) -> 0 | L12: 1 | M12: =ABS(G$2-$F12)/1 -> 1 | N12: =ABS(H$2-$F12)/1 -> 0.5 | O12: =ABS(I$2-$F12)/1 -> 0 | Q12: 1 | R12: =($J12/$J$13) * (G$13/$J$13) -> #DIV/0! | S12: =($J12/$J$13) * (H$13/$J$13) -> #DIV/0! | T12: =($J12/$J$13) * (I$13/$J$13) -> #DIV/0! | V12: Cohen's Kappa | W12: =1-W10/W11 -> #DIV/0! | X12: 1 - (D_obs / D_exp)
A13: ='Dishwasher Grader #1'!A13 -> State | B13: ='Dishwasher Grader #1'!B13 -> initial state | C13: ='Dishwasher Grader #1'!C13 | D13: ='Dishwasher Grader #2'!C13 -> 0 | F13: Column Totals | G13: =SUM(G10:G12) -> 0 | H13: =SUM(H10:H12) -> 0 | I13: =SUM(I10:I12) -> 0 | J13: =SUM(G10:I12) -> 0
A14: ='Dishwasher Grader #1'!A14 -> Transition | B14: ='Dishwasher Grader #1'!B14 -> r =1; dT=20; (initial state ⇒ Idle) | C14: ='Dishwasher Grader #1'!C14 | D14: ='Dishwasher Grader #2'!C14 -> 0
A15: ='Dishwasher Grader #1'!A15 -> State | B15: ='Dishwasher Grader #1'!B15 -> Idle | C15: ='Dishwasher Grader #1'!C15 | D15: ='Dishwasher Grader #2'!C15 -> 0 | F15: Confusion Matrix (Transition)
A16: ='Dishwasher Grader #1'!A16 -> Transition | B16: ='Dishwasher Grader #1'!B16 -> selectProgram(n) (Idle ⇒ Idle) | C16: ='Dishwasher Grader #1'!C16 | D16: ='Dishwasher Grader #2'!C16 -> 0 | F16: Transition | G16: 0 | H16: 0.5 | I16: 1 | J16: Row Totals | L16: Global | M16: 0 | N16: 0.5 | O16: 1 | Q16: Global | R16: 0 | S16: 0.5 | T16: 1 | V16: ="Metrics" & " " & F16 -> Metrics Transition | W16: Value | X16: Note
A17: ='Dishwasher Grader #1'!A17 -> Guard | B17: ='Dishwasher Grader #1'!B17 -> [n ≥ 1] | C17: ='Dishwasher Grader #1'!C17 | D17: ='Dishwasher Grader #2'!C17 -> 0 | F17: 0 | G17: =COUNTIFS($A$2:$A$92,$F$16,$C$2:$C$92,$F17,$D$2:$D$92,G$16) -> 0 | H17: =COUNTIFS($A$2:$A$92,$F$16,$C$2:$C$92,$F17,$D$2:$D$92,H$16) -> 0 | I17: =COUNTIFS($A$2:$A$48,$F$16,$C$2:$C$48,$F17,$D$2:$D$48,I$16) + MAX(D50-C50,0) -> 0 | J17: =SUM(G17:I17) -> 0 | L17: 0 | M17: =ABS(G$2-$F17)/1 -> 0 | N17: =ABS(H$2-$F17)/1 -> 0.5 | O17: =ABS(I$2-$F17)/1 -> 1 | Q17: 0 | R17: =($J17/$J$20) * (G$20/$J$20) -> #DIV/0! | S17: =($J17/$J$20) * (H$20/$J$20) -> #DIV/0! | T17: =($J17/$J$20) * (I$20/$J$20) -> #DIV/0! | V17: Observed Weighted Disagreement (D_obs) | W17: =SUMPRODUCT(G17:I19, M17:O19) /$J$20 -> #DIV/0! | X17: Sum of (confusion-matrix counts × weights) divided by total items.
A18: ='Dishwasher Grader #1'!A18 -> Action | B18: ='Dishwasher Grader #1'!B18 -> r = n; | C18: ='Dishwasher Grader #1'!C18 | D18: ='Dishwasher Grader #2'!C18 -> 0 | F18: 0.5 | G18: =COUNTIFS($A$2:$A$92,$F$16,$C$2:$C$92,$F18,$D$2:$D$92,G$16) -> 0 | H18: =COUNTIFS($A$2:$A$92,$F$16,$C$2:$C$92,$F18,$D$2:$D$92,H$16) -> 0 | I18: =COUNTIFS($A$2:$A$92,$F$16,$C$2:$C$92,$F18,$D$2:$D$92,I$16) -> 0 | J18: =SUM(G18:I18) -> 0 | L18: 0.5 | M18: =ABS(G$2-$F18)/1 -> 0.5 | N18: =ABS(H$2-$F18)/3 -> 0 | O18: =ABS(I$2-$F18)/1 -> 0.5 | Q18: 0.5 | R18: =($J18/$J$20) * (G$20/$J$20) -> #DIV/0! | S18: =($J18/$J$20) * (H$20/$J$20) -> #DIV/0! | T18: =($J18/$J$20) * (I$20/$J$20) -> #DIV/0! | V18: Expected Weighted Disagreement (D_exp) | W18: =SUMPRODUCT(R17:T19, M17:O19) -> #DIV/0! | X18: Sum of (expected cell proportions × weights) under chance agreement.
A19: ='Dishwasher Grader #1'!A19 -> Transition | B19: ='Dishwasher Grader #1'!B19 -> toggleDryingTime (Idle ⇒ Idle) | C19: ='Dishwasher Grader #1'!C19 | D19: ='Dishwasher Grader #2'!C19 -> 0 | F19: 1 | G19: =COUNTIFS($A$2:$A$48,$F$16,$C$2:$C$48,$F19,$D$2:$D$48,G$16)+MAX(C50-D50,0) -> 0 | H19: =COUNTIFS($A$2:$A$92,$F$16,$C$2:$C$92,$F19,$D$2:$D$92,H$16) -> 0 | I19: =COUNTIFS($A$2:$A$48,$F$16,$C$2:$C$48,$F19,$D$2:$D$48,I$16) + MIN(C50,D50) -> 0 | J19: =SUM(G19:I19) -> 0 | L19: 1 | M19: =ABS(G$2-$F19)/1 -> 1 | N19: =ABS(H$2-$F19)/1 -> 0.5 | O19: =ABS(I$2-$F19)/1 -> 0 | Q19: 1 | R19: =($J19/$J$20) * (G$20/$J$20) -> #DIV/0! | S19: =($J19/$J$20) * (H$20/$J$20) -> #DIV/0! | T19: =($J19/$J$20) * (I$20/$J$20) -> #DIV/0! | V19: Cohen's Kappa | W19: =1-W17/W18 -> #DIV/0! | X19: 1 - (D_obs / D_exp)
A20: ='Dishwasher Grader #1'!A20 -> Action | B20: ='Dishwasher Grader #1'!B20 -> if dT = 20 then dT = 40 else dT = 20; | C20: ='Dishwasher Grader #1'!C20 | D20: ='Dishwasher Grader #2'!C20 -> 0 | F20: Column Totals | G20: =SUM(G17:G19) -> 0 | H20: =SUM(H17:H19) -> 0 | I20: =SUM(I17:I19) -> 0 | J20: =SUM(G17:I19) -> 0
A21: ='Dishwasher Grader #1'!A21 -> Transition | B21: ='Dishwasher Grader #1'!B21 -> start (Idle ⇒ Cleaning) | C21: ='Dishwasher Grader #1'!C21 | D21: ='Dishwasher Grader #2'!C21 -> 0
A22: ='Dishwasher Grader #1'!A22 -> Guard | B22: ='Dishwasher Grader #1'!B22 -> [door.isClosed()] | C22: ='Dishwasher Grader #1'!C22 | D22: ='Dishwasher Grader #2'!C22 -> 0 | F22: Confusion Matrix (Composite State)
A23: ='Dishwasher Grader #1'!A23 -> Action | B23: ='Dishwasher Grader #1'!B23 -> door.lock(); c = 1; | C23: ='Dishwasher Grader #1'!C23 | D23: ='Dishwasher Grader #2'!C23 -> 0 | F23: Composite State | G23: 0 | H23: 0.5 | I23: 1 | J23: Row Totals | L23: Global | M23: 0 | N23: 0.5 | O23: 1 | Q23: Global | R23: 0 | S23: 0.5 | T23: 1 | V23: ="Metrics" & " " & F23 -> Metrics Composite State | W23: Value | X23: Note
A24: ='Dishwasher Grader #1'!A24 -> Composite State | B24: ='Dishwasher Grader #1'!B24 -> Cleaning | C24: ='Dishwasher Grader #1'!C24 | D24: ='Dishwasher Grader #2'!C24 -> 0 | F24: 0 | G24: =COUNTIFS($A$2:$A$92,$F$23,$C$2:$C$92,$F24,$D$2:$D$92,G$23) -> 0 | H24: =COUNTIFS($A$2:$A$92,$F$23,$C$2:$C$92,$F24,$D$2:$D$92,H$23) -> 0 | I24: =COUNTIFS($A$2:$A$48,$F$23,$C$2:$C$48,$F24,$D$2:$D$48,I$23) + MAX(D53-C53,0) -> 0 | J24: =SUM(G24:I24) -> 0 | L24: 0 | M24: =ABS(G$2-$F24)/1 -> 0 | N24: =ABS(H$2-$F24)/1 -> 0.5 | O24: =ABS(I$2-$F24)/1 -> 1 | Q24: 0 | R24: =($J24/$J$27) * (G$27/$J$27) -> #DIV/0! | S24: =($J24/$J$27) * (H$27/$J$27) -> #DIV/0! | T24: =($J24/$J$27) * (I$27/$J$27) -> #DIV/0! | V24: Observed Weighted Disagreement (D_obs) | W24: =SUMPRODUCT(G24:I26, M24:O26) /$J$27 -> #DIV/0! | X24: Sum of (confusion-matrix counts × weights) divided by total items.
A25: ='Dishwasher Grader #1'!A25 -> State | B25: ='Dishwasher Grader #1'!B25 -> initial state (⇒ Intake) | C25: ='Dishwasher Grader #1'!C25 | D25: ='Dishwasher Grader #2'!C25 -> 0 | F25: 0.5 | G25: =COUNTIFS($A$2:$A$92,$F$23,$C$2:$C$92,$F25,$D$2:$D$92,G$23) -> 0 | H25: =COUNTIFS($A$2:$A$92,$F$23,$C$2:$C$92,$F25,$D$2:$D$92,H$23) -> 0 | I25: =COUNTIFS($A$2:$A$92,$F$23,$C$2:$C$92,$F25,$D$2:$D$92,I$23) -> 0 | J25: =SUM(G25:I25) -> 0 | L25: 0.5 | M25: =ABS(G$2-$F25)/1 -> 0.5 | N25: =ABS(H$2-$F25)/3 -> 0 | O25: =ABS(I$2-$F25)/1 -> 0.5 | Q25: 0.5 | R25: =($J25/$J$27) * (G$27/$J$27) -> #DIV/0! | S25: =($J25/$J$27) * (H$27/$J$27) -> #DIV/0! | T25: =($J25/$J$27) * (I$27/$J$27) -> #DIV/0! | V25: Expected Weighted Disagreement (D_exp) | W25: =SUMPRODUCT(R24:T26, M24:O26) -> #DIV/0! | X25: Sum of (expected cell proportions × weights) under chance agreement.
A26: ='Dishwasher Grader #1'!A26 -> State | B26: ='Dishwasher Grader #1'!B26 -> Intake | C26: ='Dishwasher Grader #1'!C26 | D26: ='Dishwasher Grader #2'!C26 -> 0 | F26: 1 | G26: =COUNTIFS($A$2:$A$48,$F$23,$C$2:$C$48,$F26,$D$2:$D$48,G$23) + MAX(C53-D53,0) -> 0 | H26: =COUNTIFS($A$2:$A$92,$F$23,$C$2:$C$92,$F26,$D$2:$D$92,H$23) -> 0 | I26: =COUNTIFS($A$2:$A$48,$F$23,$C$2:$C$48,$F26,$D$2:$D$48,I$23) + MIN(C53,D53) -> 0 | J26: =SUM(G26:I26) -> 0 | L26: 1 | M26: =ABS(G$2-$F26)/1 -> 1 | N26: =ABS(H$2-$F26)/1 -> 0.5 | O26: =ABS(I$2-$F26)/1 -> 0 | Q26: 1 | R26: =($J26/$J$27) * (G$27/$J$27) -> #DIV/0! | S26: =($J26/$J$27) * (H$27/$J$27) -> #DIV/0! | T26: =($J26/$J$27) * (I$27/$J$27) -> #DIV/0! | V26: Cohen's Kappa | W26: =1-W24/W25 -> #DIV/0! | X26: 1 - (D_obs / D_exp)
A27: ='Dishwasher Grader #1'!A27 -> Transition | B27: ='Dishwasher Grader #1'!B27 -> Intake ⇒ Washing | C27: ='Dishwasher Grader #1'!C27 | D27: ='Dishwasher Grader #2'!C27 -> 0 | F27: Column Totals | G27: =SUM(G24:G26) -> 0 | H27: =SUM(H24:H26) -> 0 | I27: =SUM(I24:I26) -> 0 | J27: =SUM(G24:I26) -> 0
A28: ='Dishwasher Grader #1'!A28 -> State | B28: ='Dishwasher Grader #1'!B28 -> Washing | C28: ='Dishwasher Grader #1'!C28 | D28: ='Dishwasher Grader #2'!C28 -> 0
A29: ='Dishwasher Grader #1'!A29 -> Transition | B29: ='Dishwasher Grader #1'!B29 -> after 10 min (Washing ⇒ Drain) | C29: ='Dishwasher Grader #1'!C29 | D29: ='Dishwasher Grader #2'!C29 -> 0 | F29: Confusion Matrix (Guard)
A30: ='Dishwasher Grader #1'!A30 -> State | B30: ='Dishwasher Grader #1'!B30 -> Drain | C30: ='Dishwasher Grader #1'!C30 | D30: ='Dishwasher Grader #2'!C30 -> 0 | F30: Guard | G30: 0 | H30: 0.5 | I30: 1 | J30: Row Totals | L30: Global | M30: 0 | N30: 0.5 | O30: 1 | Q30: Global | R30: 0 | S30: 0.5 | T30: 1 | V30: ="Metrics" & " " & F30 -> Metrics Guard | W30: Value | X30: Note
A31: ='Dishwasher Grader #1'!A31 -> Guard | B31: ='Dishwasher Grader #1'!B31 -> [c < r] | C31: ='Dishwasher Grader #1'!C31 | D31: ='Dishwasher Grader #2'!C31 -> 0 | F31: 0 | G31: =COUNTIFS($A$2:$A$92,$F$30,$C$2:$C$92,$F31,$D$2:$D$92,G$30) -> 0 | H31: =COUNTIFS($A$2:$A$92,$F$30,$C$2:$C$92,$F31,$D$2:$D$92,H$30) -> 0 | I31: =COUNTIFS($A$2:$A$48,$F$30,$C$2:$C$48,$F31,$D$2:$D$48,I$30) + MAX(D51-C51,0) -> 0 | J31: =SUM(G31:I31) -> 0 | L31: 0 | M31: =ABS(G$2-$F31)/1 -> 0 | N31: =ABS(H$2-$F31)/1 -> 0.5 | O31: =ABS(I$2-$F31)/1 -> 1 | Q31: 0 | R31: =($J31/$J$34) * (G$34/$J$34) -> #DIV/0! | S31: =($J31/$J$34) * (H$34/$J$34) -> #DIV/0! | T31: =($J31/$J$34) * (I$34/$J$34) -> #DIV/0! | V31: Observed Weighted Disagreement (D_obs) | W31: =SUMPRODUCT(G31:I33, M31:O33) /$J$34 -> #DIV/0! | X31: Sum of (confusion-matrix counts × weights) divided by total items.
A32: ='Dishwasher Grader #1'!A32 -> Transition | B32: ='Dishwasher Grader #1'!B32 -> Drain ⇒ Intake | C32: ='Dishwasher Grader #1'!C32 | D32: ='Dishwasher Grader #2'!C32 -> 0 | F32: 0.5 | G32: =COUNTIFS($A$2:$A$92,$F$30,$C$2:$C$92,$F32,$D$2:$D$92,G$30) -> 0 | H32: =COUNTIFS($A$2:$A$92,$F$30,$C$2:$C$92,$F32,$D$2:$D$92,H$30) -> 0 | I32: =COUNTIFS($A$2:$A$92,$F$30,$C$2:$C$92,$F32,$D$2:$D$92,I$30) -> 0 | J32: =SUM(G32:I32) -> 0 | L32: 0.5 | M32: =ABS(G$2-$F32)/1 -> 0.5 | N32: =ABS(H$2-$F32)/3 -> 0 | O32: =ABS(I$2-$F32)/1 -> 0.5 | Q32: 0.5 | R32: =($J32/$J$34) * (G$34/$J$34) -> #DIV/0! | S32: =($J32/$J$34) * (H$34/$J$34) -> #DIV/0! | T32: =($J32/$J$34) * (I$34/$J$34) -> #DIV/0! | V32: Expected Weighted Disagreement (D_exp) | W32: =SUMPRODUCT(R31:T33, M31:O33) -> #DIV/0! | X32: Sum of (expected cell proportions × weights) under chance agreement.
A33: ='Dishwasher Grader #1'!A33 -> Action | B33: ='Dishwasher Grader #1'!B33 -> c++ | C33: ='Dishwasher Grader #1'!C33 | D33: ='Dishwasher Grader #2'!C33 -> 0 | F33: 1 | G33: =COUNTIFS($A$2:$A$48,$F$30,$C$2:$C$48,$F33,$D$2:$D$48,G$30) + MAX(C51-D51,0) -> 0 | H33: =COUNTIFS($A$2:$A$92,$F$30,$C$2:$C$92,$F33,$D$2:$D$92,H$30) -> 0 | I33: =COUNTIFS($A$2:$A$48,$F$30,$C$2:$C$48,$F33,$D$2:$D$48,I$30) + MIN(C51,D51) -> 0 | J33: =SUM(G33:I33) -> 0 | L33: 1 | M33: =ABS(G$2-$F33)/1 -> 1 | N33: =ABS(H$2-$F33)/1 -> 0.5 | O33: =ABS(I$2-$F33)/1 -> 0 | Q33: 1 | R33: =($J33/$J$34) * (G$34/$J$34) -> #DIV/0! | S33: =($J33/$J$34) * (H$34/$J$34) -> #DIV/0! | T33: =($J33/$J$34) * (I$34/$J$34) -> #DIV/0! | V33: Cohen's Kappa | W33: =1-W31/W32 -> #DIV/0! | X33: 1 - (D_obs / D_exp)
A34: ='Dishwasher Grader #1'!A34 -> Transition | B34: ='Dishwasher Grader #1'!B34 -> (Drain ⇒ end state) | C34: ='Dishwasher Grader #1'!C34 | D34: ='Dishwasher Grader #2'!C34 -> 0 | F34: Column Totals | G34: =SUM(G31:G33) -> 0 | H34: =SUM(H31:H33) -> 0 | I34: =SUM(I31:I33) -> 0 | J34: =SUM(G31:I33) -> 0
A35: ='Dishwasher Grader #1'!A35 -> Guard | B35: ='Dishwasher Grader #1'!B35 -> [c ≥ r] | C35: ='Dishwasher Grader #1'!C35 | D35: ='Dishwasher Grader #2'!C35 -> 0
A36: ='Dishwasher Grader #1'!A36 -> History State | B36: ='Dishwasher Grader #1'!B36 -> History State for Cleaning | C36: ='Dishwasher Grader #1'!C36 | D36: ='Dishwasher Grader #2'!C36 -> 0 | F36: Confusion Matrix (Action)
A37: ='Dishwasher Grader #1'!A37 -> Transition | B37: ='Dishwasher Grader #1'!B37 -> toggleDryingTime (Cleaning ⇒ History State) | C37: ='Dishwasher Grader #1'!C37 | D37: ='Dishwasher Grader #2'!C37 -> 0 | F37: Action | G37: 0 | H37: 0.5 | I37: 1 | J37: Row Totals | L37: Global | M37: 0 | N37: 0.5 | O37: 1 | Q37: Global | R37: 0 | S37: 0.5 | T37: 1 | V37: ="Metrics" & " " & F37 -> Metrics Action | W37: Value | X37: Note
A38: ='Dishwasher Grader #1'!A38 -> Action | B38: ='Dishwasher Grader #1'!B38 -> if dT = 20 then dT = 40 else dT = 20; | C38: ='Dishwasher Grader #1'!C38 | D38: ='Dishwasher Grader #2'!C38 -> 0 | F38: 0 | G38: =COUNTIFS($A$2:$A$92,$F$37,$C$2:$C$92,$F38,$D$2:$D$92,G$37) -> 0 | H38: =COUNTIFS($A$2:$A$92,$F$37,$C$2:$C$92,$F38,$D$2:$D$92,H$37) -> 0 | I38: =COUNTIFS($A$2:$A$48,$F$37,$C$2:$C$48,$F38,$D$2:$D$48,I$37)+MAX(D52-C52,0) -> 0 | J38: =SUM(G38:I38) -> 0 | L38: 0 | M38: =ABS(G$2-$F38)/1 -> 0 | N38: =ABS(H$2-$F38)/1 -> 0.5 | O38: =ABS(I$2-$F38)/1 -> 1 | Q38: 0 | R38: =($J38/$J$41) * (G$41/$J$41) -> #DIV/0! | S38: =($J38/$J$41) * (H$41/$J$41) -> #DIV/0! | T38: =($J38/$J$41) * (I$41/$J$41) -> #DIV/0! | V38: Observed Weighted Disagreement (D_obs) | W38: =SUMPRODUCT(G38:I40, M38:O40) /$J$41 -> #DIV/0! | X38: Sum of (confusion-matrix counts × weights) divided by total items.
A39: ='Dishwasher Grader #1'!A39 -> Transition | B39: ='Dishwasher Grader #1'!B39 -> Cleaning ⇒ Drying | C39: ='Dishwasher Grader #1'!C39 | D39: ='Dishwasher Grader #2'!C39 -> 0 | F39: 0.5 | G39: =COUNTIFS($A$2:$A$92,$F$37,$C$2:$C$92,$F39,$D$2:$D$92,G$37) -> 0 | H39: =COUNTIFS($A$2:$A$92,$F$37,$C$2:$C$92,$F39,$D$2:$D$92,H$37) -> 0 | I39: =COUNTIFS($A$2:$A$92,$F$37,$C$2:$C$92,$F39,$D$2:$D$92,I$37) -> 0 | J39: =SUM(G39:I39) -> 0 | L39: 0.5 | M39: =ABS(G$2-$F39)/1 -> 0.5 | N39: =ABS(H$2-$F39)/3 -> 0 | O39: =ABS(I$2-$F39)/1 -> 0.5 | Q39: 0.5 | R39: =($J39/$J$41) * (G$41/$J$41) -> #DIV/0! | S39: =($J39/$J$41) * (H$41/$J$41) -> #DIV/0! | T39: =($J39/$J$41) * (I$41/$J$41) -> #DIV/0! | V39: Expected Weighted Disagreement (D_exp) | W39: =SUMPRODUCT(R38:T40, M38:O40) -> #DIV/0! | X39: Sum of (expected cell proportions × weights) under chance agreement.
A40: ='Dishwasher Grader #1'!A40 -> Action | B40: ='Dishwasher Grader #1'!B40 -> door.unlock(); | C40: ='Dishwasher Grader #1'!C40 | D40: ='Dishwasher Grader #2'!C40 -> 0 | F40: 1 | G40: =COUNTIFS($A$2:$A$48,$F$37,$C$2:$C$48,$F40,$D$2:$D$48,G$37)+MAX(C52-D52,0) -> 0 | H40: =COUNTIFS($A$2:$A$92,$F$37,$C$2:$C$92,$F40,$D$2:$D$92,H$37) -> 0 | I40: =COUNTIFS($A$2:$A$48,$F$37,$C$2:$C$48,$F40,$D$2:$D$48,I$37) + MIN(C52,D52) -> 0 | J40: =SUM(G40:I40) -> 0 | L40: 1 | M40: =ABS(G$2-$F40)/1 -> 1 | N40: =ABS(H$2-$F40)/1 -> 0.5 | O40: =ABS(I$2-$F40)/1 -> 0 | Q40: 1 | R40: =($J40/$J$41) * (G$41/$J$41) -> #DIV/0! | S40: =($J40/$J$41) * (H$41/$J$41) -> #DIV/0! | T40: =($J40/$J$41) * (I$41/$J$41) -> #DIV/0! | V40: Cohen's Kappa | W40: =1-W38/W39 -> #DIV/0! | X40: 1 - (D_obs / D_exp)
...
