Workbook

Sheet Spa Manager
A1: Type | B1: Element
A2: Composite State | B2: SpaManager
A3: Region | B3: Jacuzzi
A4: State | B4: initial state (Jacuzzi → Off)
A5: State | B5: Off
A6: Composite State | B6: On (Jacuzzi)
A7: Transition | B7: on (Off ⇒ On)
A8: Transition | B8: off (On ⇒ Off)
A9: State | B9: initial state (Level1)
A10: State | B10: Level1
A11: Transition | B11: up (Level1 ⇒ Level2)
A12: State | B12: Level2
... A52: History State | B52: additional elements

Sheet Grader #1
A1: Type | B1: Element | C1: Rater 1 | D1: Notes
A2: Composite State | B2: SpaManager | C2: 1
A3: Region | B3: Jacuzzi | C3: 1
A4: State | B4: initial state (Jacuzzi → Off) | C4: 1
A5: State | B5: Off | C5: 1
A6: Composite State | B6: On (Jacuzzi) | C6: 1
A7: Transition | B7: on (Off ⇒ On) | C7: 1
A8: Transition | B8: off (On ⇒ Off) | C8: 1
A9: State | B9: initial state (Level1) | C9: 1
A10: State | B10: Level1 | C10: 1
A11: Transition | B11: up (Level1 ⇒ Level2) | C11: 1
A12: State | B12: Level2 | C12: 1
A13: Transition | B13: up (Level2 ⇒ Level3) | C13: 1
... A19: State | B19: Paused | C19: 1
A20: Transition | B20: pause (On⇒ Pause) | C20: 0 | D20: Not an external transistion
A21: Transition | B21: after 2min (Paused ⇒ History State) | C21: 1
A22: Region | B22: Sauna | C22: 1
A23: State | B23: initial state (Sauna → Off) | C23: 1
A24: State | B24: Off | C24: 1
A25: Composite State | B25: On (Sauna) | C25: 1
A26: Transition | B26: on (Off ⇒ On) | C26: 1
A27: Transition | B27: off (On ⇒ Off) | C27: 1
A28: Region | B28: Heater | C28: 1
A29: State | B29: initial state (Heater → Heat) | C29: 1
A30: State | B30: Heat | C30: 1
A31: Transition | B31: Heat ⇒ Idle | C31: 1
A32: Guard | B32: [temp ≥ 90°C] | C32: 1
... A52: History State | B52: additional elements | C52: 0

Sheet Grader #2
A1: Type | B1: Element | C1: Rater 2 | D1: Notes
A2: Composite State | B2: SpaManager | C2: 1
A3: Region | B3: Jacuzzi | C3: 1
A4: State | B4: initial state (Jacuzzi → Off) | C4: 1
A5: State | B5: Off | C5: 1
A6: Composite State | B6: On (Jacuzzi) | C6: 1
A7: Transition | B7: on (Off ⇒ On) | C7: 1
A8: Transition | B8: off (On ⇒ Off) | C8: 1
A9: State | B9: initial state (Level1) | C9: 1
A10: State | B10: Level1 | C10: 1
A11: Transition | B11: up (Level1 ⇒ Level2) | C11: 1
A12: State | B12: Level2 | C12: 1
A13: Transition | B13: up (Level2 ⇒ Level3) | C13: 1
... A19: State | B19: Paused | C19: 1
A20: Transition | B20: pause (On⇒ Pause) | C20: 0.5 | D20: every level can get to it, but not like in solution
A21: Transition | B21: after 2min (Paused ⇒ History State) | C21: 1
A22: Region | B22: Sauna | C22: 1
A23: State | B23: initial state (Sauna → Off) | C23: 1
A24: State | B24: Off | C24: 1
A25: Composite State | B25: On (Sauna) | C25: 1
A26: Transition | B26: on (Off ⇒ On) | C26: 1
A27: Transition | B27: off (On ⇒ Off) | C27: 1
A28: Region | B28: Heater | C28: 1
A29: State | B29: initial state (Heater → Heat) | C29: 1
A30: State | B30: Heat | C30: 1
A31: Transition | B31: Heat ⇒ Idle | C31: 1 | D31: maintaining
A32: Guard | B32: [temp ≥ 90°C] | C32: 1
A33: State | B33: Idle | C33: 1
A34: Transition | B34: Idle ⇒ Heat | C34: 1
A35: Guard | B35: [temp < 85°C] | C35: 1
A36: Reion | B36: Fan | C36: 1
A37: State | B37: initial state (Fan → Off) | C37: 1
A38: State | B38: Off | C38: 1
A39: Transition | B39: Off ⇒ On | C39: 1
A40: Guard | B40: [humidity > 40% && exceedTime > 3min] | C40: 1 | D40: shown with additional state
A41: Region | B41: Water | C41: 1
A42: State | B42: initial state (Water → Idle) | C42: 1
A43: State | B43: Idle | C43: 1
A44: Transition | B44: Idle ⇒ Idle | C44: 1
A45: Guard | B45: disperse [humidity < 40% && !Fan.On && timeSinceLast ≥ 15min] | C45: 1
...

Sheet Metrics
A1: Claude Grader #1 | J1: Date
A2: Type | B2: Ground Truth Count | C2: True Positive | D2: False Positive | E2: False Negative | F2: Precision | G2: Recall | H2: F1 Score | J2: Feburary 28, 2026
A3: Composite State | B3: =COUNTIF('Spa Manager'!$A$2:$A$45, A3) -> 3 | C3: =SUMIF('Grader #1'!$A$2:$A$45, $A3, 'Grader #1'!$C$2:$C$45) -> 3 | D3: =SUMIF('Grader #1'!A$46:A$52, A3, 'Grader #1'!$C$46:$C$52) -> 0 | E3: =COUNTIFS('Grader #1'!$A$2:$A$45, $A3, 'Grader #1'!$C$2:$C$45,0) -> 0 | F3: =IFERROR(C3 / (C3 + D3), "Not Available") -> 1 | G3: =IFERROR(C3 / B3, "Not Available") -> 1 | H3: =IFERROR(2*((F3*G3)/(F3+G3)),"Not Available") -> 1
A4: State | B4: =COUNTIF('Spa Manager'!$A$2:$A$45, A4) -> 16 | C4: =SUMIF('Grader #1'!$A$2:$A$45, $A4, 'Grader #1'!$C$2:$C$45) -> 16 | D4: =SUMIF('Grader #1'!A$46:A$52, A4, 'Grader #1'!$C$46:$C$52) -> 0 | E4: =COUNTIFS('Grader #1'!$A$2:$A$45, $A4, 'Grader #1'!$C$2:$C$45,0) -> 0 | F4: =IFERROR(C4 / (C4 + D4), "Not Available") -> 1 | G4: =IFERROR(C4 / B4, "Not Available") -> 1 | H4: =IFERROR(2*((F4*G4)/(F4+G4)),"Not Available") -> 1 | J4: Grader #1 ID
A5: Transition | B5: =COUNTIF('Spa Manager'!$A$2:$A$45, A5) -> 15 | C5: =SUMIF('Grader #1'!$A$2:$A$45, $A5, 'Grader #1'!$C$2:$C$45) -> 13.5 | D5: =SUMIF('Grader #1'!A$46:A$52, A5, 'Grader #1'!$C$46:$C$52) -> 0 | E5: =COUNTIFS('Grader #1'!$A$2:$A$45, $A5, 'Grader #1'!$C$2:$C$45,0) -> 1 | F5: =IFERROR(C5 / (C5 + D5), "Not Available") -> 1 | G5: =IFERROR(C5 / B5, "Not Available") -> 0.9 | H5: =IFERROR(2*((F5*G5)/(F5+G5)),"Not Available") -> 0.94736842 | J5: 1
A6: Action | B6: =COUNTIF('Spa Manager'!$A$2:$A$45, A6) -> 0 | C6: =SUMIF('Grader #1'!$A$2:$A$45, $A6, 'Grader #1'!$C$2:$C$45) -> 0 | D6: =SUMIF('Grader #1'!A$46:A$52, A6, 'Grader #1'!$C$46:$C$52) -> 0 | E6: =COUNTIFS('Grader #1'!$A$2:$A$45, $A6, 'Grader #1'!$C$2:$C$45,0) -> 0 | F6: =IFERROR(C6 / (C6 + D6), "Not Available") -> Not Available | G6: =IFERROR(C6 / B6, "Not Available") -> Not Available | H6: =IFERROR(2*((F6*G6)/(F6+G6)),"Not Available") -> Not Available
A7: Region | B7: =COUNTIF('Spa Manager'!$A$2:$A$45, A7) -> 5 | C7: =SUMIF('Grader #1'!$A$2:$A$45, $A7, 'Grader #1'!$C$2:$C$45) -> 5 | D7: =SUMIF('Grader #1'!A$46:A$52, A7, 'Grader #1'!$C$46:$C$52) -> 0 | E7: =COUNTIFS('Grader #1'!$A$2:$A$45, $A7, 'Grader #1'!$C$2:$C$45,0) -> 0 | F7: =IFERROR(C7 / (C7 + D7), "Not Available") -> 1 | G7: =IFERROR(C7 / B7, "Not Available") -> 1 | H7: =IFERROR(2*((F7*G7)/(F7+G7)),"Not Available") -> 1 | J7: Grader #2 ID
A8: History State | B8: =COUNTIF('Spa Manager'!$A$2:$A$45, A8) -> 1 | C8: =SUMIF('Grader #1'!$A$2:$A$45, $A8, 'Grader #1'!$C$2:$C$45) -> 1 | D8: =SUMIF('Grader #1'!A$46:A$52, A8, 'Grader #1'!$C$46:$C$52) -> 0 | E8: =COUNTIFS('Grader #1'!$A$2:$A$45, $A8, 'Grader #1'!$C$2:$C$45,0) -> 0 | F8: =IFERROR(C8 / (C8 + D8), "Not Available") -> 1 | G8: =IFERROR(C8 / B8, "Not Available") -> 1 | H8: =IFERROR(2*((F8*G8)/(F8+G8)),"Not Available") -> 1 | J8: 2
A9: Guard | B9: =COUNTIF('Spa Manager'!$A$2:$A$45, A9) -> 4 | C9: =SUMIF('Grader #1'!$A$2:$A$45, $A9, 'Grader #1'!$C$2:$C$45) -> 4 | D9: =SUMIF('Grader #1'!A$46:A$52, A9, 'Grader #1'!$C$46:$C$52) -> 0 | E9: =COUNTIFS('Grader #1'!$A$2:$A$45, $A9, 'Grader #1'!$C$2:$C$45,0) -> 0 | F9: =IFERROR(C9 / (C9 + D9), "Not Available") -> 1 | G9: =IFERROR(C9 / B9, "Not Available") -> 1 | H9: =IFERROR(2*((F9*G9)/(F9+G9)),"Not Available") -> 1
A10: Overall Score | B10: =SUM(B3:B9) -> 44 | C10: =SUM(C3:C9) -> 42.5 | D10: =SUM(D3:D9) -> 0 | E10: =SUM(E3:E9) -> 1 | F10: =IFERROR(C10 / (C10 + D10), "Not Available") -> 1 | G10: =IFERROR(C10 / B10, "Not Available") -> 0.96590909 | H10: =IFERROR(2*((F10*G10)/(F10+G10)),"Not Available") -> 0.98265896 | J10: LLM Used
J11: Claude 4.5 Sonnet
A12: Claude Grader #2
A13: Type | B13: Ground Truth Count | C13: True Positive | D13: False Positive | E13: False Negative | F13: Precision | G13: Recall | H13: F1 Score
A14: Composite state | B14: =COUNTIF('Spa Manager'!$A$2:$A$45, A14) -> 3 | C14: =SUMIF('Grader #2'!$A$2:$A$45, $A14, 'Grader #2'!$C$2:$C$45) -> 3 | D14: =SUMIF('Grader #2'!A$46:A$52, A14, 'Grader #2'!$C$46:$C$53) -> 0 | E14: =COUNTIFS('Grader #2'!$A$2:$A$45, $A14, 'Grader #2'!$C$2:$C$45,0) -> 0 | F14: =IFERROR(C14 / (C14 + D14), "Not Available") -> 1 | G14: =IFERROR(C14 / B14, "Not Available") -> 1 | H14: =IFERROR(2*((F14*G14)/(F14+G14)),"Not Available") -> 1
A15: State | B15: =COUNTIF('Spa Manager'!$A$2:$A$45, A15) -> 16 | C15: =SUMIF('Grader #2'!$A$2:$A$45, $A15, 'Grader #2'!$C$2:$C$45) -> 16 | D15: =SUMIF('Grader #2'!A$46:A$52, A15, 'Grader #2'!$C$46:$C$53) -> 0 | E15: =COUNTIFS('Grader #2'!$A$2:$A$45, $A15, 'Grader #2'!$C$2:$C$45,0) -> 0 | F15: =IFERROR(C15 / (C15 + D15), "Not Available") -> 1 | G15: =IFERROR(C15 / B15, "Not Available") -> 1 | H15: =IFERROR(2*((F15*G15)/(F15+G15)),"Not Available") -> 1
A16: Transition | B16: =COUNTIF('Spa Manager'!$A$2:$A$45, A16) -> 15 | C16: =SUMIF('Grader #2'!$A$2:$A$45, $A16, 'Grader #2'!$C$2:$C$45) -> 14 | D16: =SUMIF('Grader #2'!A$46:A$52, A16, 'Grader #2'!$C$46:$C$53) -> 0 | E16: =COUNTIFS('Grader #2'!$A$2:$A$45, $A16, 'Grader #2'!$C$2:$C$45,0) -> 0 | F16: =IFERROR(C16 / (C16 + D16), "Not Available") -> 1 | G16: =IFERROR(C16 / B16, "Not Available") -> 0.93333333 | H16: =IFERROR(2*((F16*G16)/(F16+G16)),"Not Available") -> 0.96551724
A17: Action | B17: =COUNTIF('Spa Manager'!$A$2:$A$45, A17) -> 0 | C17: =SUMIF('Grader #2'!$A$2:$A$45, $A17, 'Grader #2'!$C$2:$C$45) -> 0 | D17: =SUMIF('Grader #2'!A$46:A$52, A17, 'Grader #2'!$C$46:$C$53) -> 0 | E17: =COUNTIFS('Grader #2'!$A$2:$A$45, $A17, 'Grader #2'!$C$2:$C$45,0) -> 0 | F17: =IFERROR(C17 / (C17 + D17), "Not Available") -> Not Available | G17: =IFERROR(C17 / B17, "Not Available") -> Not Available | H17: =IFERROR(2*((F17*G17)/(F17+G17)),"Not Available") -> Not Available
A18: Region | B18: =COUNTIF('Spa Manager'!$A$2:$A$45, A18) -> 5 | C18: =SUMIF('Grader #2'!$A$2:$A$45, $A18, 'Grader #2'!$C$2:$C$45) -> 4 | D18: =SUMIF('Grader #2'!A$46:A$52, A18, 'Grader #2'!$C$46:$C$53) -> 0 | E18: =COUNTIFS('Grader #2'!$A$2:$A$45, $A18, 'Grader #2'!$C$2:$C$45,0) -> 0 | F18: =IFERROR(C18 / (C18 + D18), "Not Available") -> 1 | G18: =IFERROR(C18 / B18, "Not Available") -> 0.8 | H18: =IFERROR(2*((F18*G18)/(F18+G18)),"Not Available") -> 0.88888889
A19: History State | B19: =COUNTIF('Spa Manager'!$A$2:$A$45, A19) -> 1 | C19: =SUMIF('Grader #2'!$A$2:$A$45, $A19, 'Grader #2'!$C$2:$C$45) -> 1 | D19: =SUMIF('Grader #2'!A$46:A$52, A19, 'Grader #2'!$C$46:$C$53) -> 0 | E19: =COUNTIFS('Grader #2'!$A$2:$A$45, $A19, 'Grader #2'!$C$2:$C$45,0) -> 0 | F19: =IFERROR(C19 / (C19 + D19), "Not Available") -> 1 | G19: =IFERROR(C19 / B19, "Not Available") -> 1 | H19: =IFERROR(2*((F19*G19)/(F19+G19)),"Not Available") -> 1
A20: Guard | B20: =COUNTIF('Spa Manager'!$A$2:$A$45, A20) -> 4 | C20: =SUMIF('Grader #2'!$A$2:$A$45, $A20, 'Grader #2'!$C$2:$C$45) -> 4 | D20: =SUMIF('Grader #2'!A$46:A$52, A20, 'Grader #2'!$C$46:$C$53) -> 0 | E20: =COUNTIFS('Grader #2'!$A$2:$A$45, $A20, 'Grader #2'!$C$2:$C$45,0) -> 0 | F20: =IFERROR(C20 / (C20 + D20), "Not Available") -> 1 | G20: =IFERROR(C20 / B20, "Not Available") -> 1 | H20: =IFERROR(2*((F20*G20)/(F20+G20)),"Not Available") -> 1
A21: Overall Score | B21: =SUM(B14:B20) -> 44 | C21: =SUM(C14:C20) -> 42 | D21: =SUM(D14:D20) -> 0 | E21: =SUM(E14:E20) -> 0 | F21: =IFERROR(C21 / (C21 + D21), "Not Available") -> 1 | G21: =IFERROR(C21 / B21, "Not Available") -> 0.95454545 | H21: =IFERROR(2*((F21*G21)/(F21+G21)),"Not Available") -> 0.97674419

Sheet Inter-rater
A1: Type | B1: Element | C1: Rater 1 | D1: Rater 2 | F1: Confusion Matrix | L1: Cohen's Kappa
A2: ='Spa Manager'!A2 -> Composite State | B2: ='Spa Manager'!B2 -> SpaManager | C2: ='Grader #1'!C2 -> 1 | D2: ='Grader #2'!C2 -> 1 | F2: Global | G2: 0 | H2: 0.5 | I2: 1 | J2: Row Totals | L2: Metric | M2: Value | N2: Note
A3: ='Spa Manager'!A3 -> Region | B3: ='Spa Manager'!B3 -> Jacuzzi | C3: ='Grader #1'!C3 -> 1 | D3: ='Grader #2'!C3 -> 1 | F3: 0 | G3: =COUNTIFS($C$2:$C$90, $F3, $D$2:$D$90, G$2) -> 7 | H3: =COUNTIFS($C$2:$C$46, $F3, $D$2:$D$46, H$2) -> 1 | I3: =COUNTIFS($C$2:$C$46, $F3, $D$2:$D$46, I$2)+MAX(D47-C47,0)+MAX(D48-C48,0)+MAX(D49-C49,0)+MAX(D50-C50,0)+MAX(D51-C51,0)+MAX(D52-C52,0)+MAX(D53-C53,0) -> 0 | J3: =SUM(G3:I3) -> 8 | L3: Observed Agreement (Po) | M3: =(G3+H4+I5)/COUNTA($C$2:$C$100) -> 0.98039216 | N3: This sums the diagonal of your matrix divided by total rows.
A4: ='Spa Manager'!A4 -> State | B4: ='Spa Manager'!B4 -> initial state (Jacuzzi → Off) | C4: ='Grader #1'!C4 -> 1 | D4: ='Grader #2'!C4 -> 1 | F4: 0.5 | G4: =COUNTIFS($C$2:$C$46, $F4, $D$2:$D$46, G$2) -> 0 | H4: =COUNTIFS($C$2:$C$46, $F4, $D$2:$D$46, H$2) -> 1 | I4: =COUNTIFS($C$2:$C$46, $F4, $D$2:$D$46, I$2) -> 0 | J4: =SUM(G4:I4) -> 1 | L4: Expected Agreement (Pe) | M4: {=SUMPRODUCT(J3:J5/COUNTA($C$2:$C$100), TRANSPOSE(G6:I6)/COUNTA($C$2:$C$100))} -> 0.70049981 | N4: This computes the sum of row proportion times column proportion.
A5: ='Spa Manager'!A5 -> State | B5: ='Spa Manager'!B5 -> Off | C5: ='Grader #1'!C5 -> 1 | D5: ='Grader #2'!C5 -> 1 | F5: 1 | G5: =COUNTIFS($C$2:$C$46, $F5, $D$2:$D$46, G$2)+MAX(C47-D47,0)+MAX(C48-D48,0)+MAX(C49-D49,0)+MAX(C50-D50,0)+MAX(C51-D51,0)+MAX(C52-D52,0)+MAX(C53-D53,0) -> 0 | H5: =COUNTIFS($C$2:$C$46, $F5, $D$2:$D$46, H$2) -> 0 | I5: =COUNTIFS($C$2:$C$46, $F5, $D$2:$D$46, I$2)+ SUM(MIN(C47,D47), MIN(C48,D48), MIN(C49,D49), MIN(C50,D50), MIN(C51,D51), MIN(C52,D52), MIN(C53,D53)) -> 42 | J5: =SUM(G5:I5) -> 42 | L5: Cohen's Kappa | M5: =(M3-M4)/(1-M4) -> 0.93453145 | N5: (Po - Pe) / (1 - Pe)
A6: ='Spa Manager'!A6 -> Composite State | B6: ='Spa Manager'!B6 -> On (Jacuzzi) | C6: ='Grader #1'!C6 -> 1 | D6: ='Grader #2'!C6 -> 1 | F6: Column Totals | G6: =SUM(G3:G5) -> 7 | H6: =SUM(H3:H5) -> 2 | I6: =SUM(I3:I5) -> 42
A7: ='Spa Manager'!A7 -> Transition | B7: ='Spa Manager'!B7 -> on (Off ⇒ On) | C7: ='Grader #1'!C7 -> 1 | D7: ='Grader #2'!C7 -> 1
A8: ='Spa Manager'!A8 -> Transition | B8: ='Spa Manager'!B8 -> off (On ⇒ Off) | C8: ='Grader #1'!C8 -> 1 | D8: ='Grader #2'!C8 -> 1 | F8: Confusion Matrix (State) | L8: Cohen's Kappa (State)
A9: ='Spa Manager'!A9 -> State | B9: ='Spa Manager'!B9 -> initial state (Level1) | C9: ='Grader #1'!C9 -> 1 | D9: ='Grader #2'!C9 -> 1 | F9: State | G9: 0 | H9: 0.5 | I9: 1 | J9: Row Totals | L9: Metric | M9: Value | N9: Note
A10: ='Spa Manager'!A10 -> State | B10: ='Spa Manager'!B10 -> Level1 | C10: ='Grader #1'!C10 -> 1 | D10: ='Grader #2'!C10 -> 1 | F10: 0 | G10: =COUNTIFS($A$2:$A$90,$F$9,$C$2:$C$90,$F10,$D$2:$D$90,G$9) -> 1 | H10: =COUNTIFS($A$2:$A$90,$F$9,$C$2:$C$90,$F10,$D$2:$D$90,H$9) -> 0 | I10: =COUNTIFS($A$2:$A$46,$F$9,$C$2:$C$46,$F10,$D$2:$D$46,I$9)+MAX(D47-C47,0) -> 0 | J10: =SUM(G10:I10) -> 1 | L10: Observed Agreement (Po) | M10: =(G10+H11+I12)/COUNTIF($A$2:$A$100,F9) -> 1 | N10: This sums the diagonal of your matrix divided by total rows.
A11: ='Spa Manager'!A11 -> Transition | B11: ='Spa Manager'!B11 -> up (Level1 ⇒ Level2) | C11: ='Grader #1'!C11 -> 1 | D11: ='Grader #2'!C11 -> 1 | F11: 0.5 | G11: =COUNTIFS($A$2:$A$90,$F$9,$C$2:$C$90,$F11,$D$2:$D$90,G$9) -> 0 | H11: =COUNTIFS($A$2:$A$90,$F$9,$C$2:$C$90,$F11,$D$2:$D$90,H$9) -> 0 | I11: =COUNTIFS($A$2:$A$90,$F$9,$C$2:$C$90,$F11,$D$2:$D$90,I$9) -> 0 | J11: =SUM(G11:I11) -> 0 | L11: Expected Agreement (Pe) | M11: {=SUMPRODUCT(J10:J12/COUNTIF($A$2:$A$100,F9), TRANSPOSE(G13:I13)/COUNTIF($A$2:$A$100,F9))} -> 0.88927336 | N11: This computes the sum of row proportion times column proportion.
A12: ='Spa Manager'!A12 -> State | B12: ='Spa Manager'!B12 -> Level2 | C12: ='Grader #1'!C12 -> 1 | D12: ='Grader #2'!C12 -> 1 | F12: 1 | G12: =COUNTIFS($A$2:$A$46,$F$9,$C$2:$C$46,$F12,$D$2:$D$46,G$9)+MAX(C47-D47,0) -> 0 | H12: =COUNTIFS($A$2:$A$90,$F$9,$C$2:$C$90,$F12,$D$2:$D$90,H$9) -> 0 | I12: =COUNTIFS($A$2:$A$46,$F$9,$C$2:$C$46,$F12,$D$2:$D$46,I$9)+MIN(C47-D47) -> 16 | J12: =SUM(G12:I12) -> 16 | L12: Cohen's Kappa | M12: =(M10-M11)/(1-M11) -> 1 | N12: (Po - Pe) / (1 - Pe)
A13: ='Spa Manager'!A13 -> Transition | B13: ='Spa Manager'!B13 -> up (Level2 ⇒ Level3) | C13: ='Grader #1'!C13 -> 1 | D13: ='Grader #2'!C13 -> 1 | F13: Column Totals | G13: =SUM(G10:G12) -> 1 | H13: =SUM(H10:H12) -> 0 | I13: =SUM(I10:I12) -> 16
A14: ='Spa Manager'!A14 -> Transition | B14: ='Spa Manager'!B14 -> down (Level2 ⇒ Level1) | C14: ='Grader #1'!C14 -> 1 | D14: ='Grader #2'!C14 -> 1
A15: ='Spa Manager'!A15 -> State | B15: ='Spa Manager'!B15 -> Level3 | C15: ='Grader #1'!C15 -> 1 | D15: ='Grader #2'!C15 -> 1 | F15: Confusion Matrix (Transition) | L15: Cohen's Kappa (Transition)
A16: ='Spa Manager'!A16 -> Transition | B16: ='Spa Manager'!B16 -> down (Level3 ⇒ Level2) | C16: ='Grader #1'!C16 -> 1 | D16: ='Grader #2'!C16 -> 1 | F16: Transition | G16: 0 | H16: 0.5 | I16: 1 | J16: Row Totals | L16: Metric | M16: Value | N16: Note
A17: ='Spa Manager'!A17 -> History State | B17: ='Spa Manager'!B17 -> History State for Jacuzzi On | C17: ='Grader #1'!C17 -> 1 | D17: ='Grader #2'!C17 -> 1 | F17: 0 | G17: =COUNTIFS($A$2:$A$90,$F$16,$C$2:$C$90,$F17,$D$2:$D$90,G$16) -> 1 | H17: =COUNTIFS($A$2:$A$90,$F$16,$C$2:$C$90,$F17,$D$2:$D$90,H$16) -> 1 | I17: =COUNTIFS($A$2:$A$46,$F$16,$C$2:$C$46,$F17,$D$2:$D$46,I$16) + MAX(D48-C48,0) -> 0 | J17: =SUM(G17:I17) -> 2 | L17: Observed Agreement (Po) | M17: =(G17+H18+I19)/COUNTIF($A$2:$A$100,F16) -> 0.9375 | N17: This sums the diagonal of your matrix divided by total rows.
A18: ='Spa Manager'!A18 -> Transition | B18: ='Spa Manager'!B18 -> setPattern(PatternType type) (On⇒ History State) | C18: ='Grader #1'!C18 -> 0.5 | D18: ='Grader #2'!C18 -> 0.5 | F18: 0.5 | G18: =COUNTIFS($A$2:$A$90,$F$16,$C$2:$C$90,$F18,$D$2:$D$90,G$16) -> 0 | H18: =COUNTIFS($A$2:$A$90,$F$16,$C$2:$C$90,$F18,$D$2:$D$90,H$16) -> 1 | I18: =COUNTIFS($A$2:$A$90,$F$16,$C$2:$C$90,$F18,$D$2:$D$90,I$16) -> 0 | J18: =SUM(G18:I18) -> 1 | L18: Expected Agreement (Pe) | M18: {=SUMPRODUCT(J17:J19/COUNTIF($A$2:$A$100,F16), TRANSPOSE(G20:I20)/COUNTIF($A$2:$A$100,F16))} -> 0.67578125 | N18: This computes the sum of row proportion times column proportion.
A19: ='Spa Manager'!A19 -> State | B19: ='Spa Manager'!B19 -> Paused | C19: ='Grader #1'!C19 -> 1 | D19: ='Grader #2'!C19 -> 1 | F19: 1 | G19: =COUNTIFS($A$2:$A$46,$F$16,$C$2:$C$46,$F19,$D$2:$D$46,G$16)+MAX(C48-D48,0) -> 0 | H19: =COUNTIFS($A$2:$A$90,$F$16,$C$2:$C$90,$F19,$D$2:$D$90,H$16) -> 0 | I19: =COUNTIFS($A$2:$A$46,$F$16,$C$2:$C$46,$F19,$D$2:$D$46,I$16) + MIN(C48,D48) -> 13 | J19: =SUM(G19:I19) -> 13 | L19: Cohen's Kappa | M19: =(M17-M18)/(1-M18) -> 0.80722892 | N19: (Po - Pe) / (1 - Pe)
A20: ='Spa Manager'!A20 -> Transition | B20: ='Spa Manager'!B20 -> pause (On⇒ Pause) | C20: ='Grader #1'!C20 -> 0 | D20: ='Grader #2'!C20 -> 0.5 | F20: Column Totals | G20: =SUM(G17:G19) -> 1 | H20: =SUM(H17:H19) -> 2 | I20: =SUM(I17:I19) -> 13
A21: ='Spa Manager'!A21 -> Transition | B21: ='Spa Manager'!B21 -> after 2min (Paused ⇒ History State) | C21: ='Grader #1'!C21 -> 1 | D21: ='Grader #2'!C21 -> 1
A22: ='Spa Manager'!A22 -> Region | B22: ='Spa Manager'!B22 -> Sauna | C22: ='Grader #1'!C22 -> 1 | D22: ='Grader #2'!C22 -> 1 | F22: Confusion Matrix (Composite State) | L22: Cohen's Kappa (Composite State)
A23: ='Spa Manager'!A23 -> State | B23: ='Spa Manager'!B23 -> initial state (Sauna → Off) | C23: ='Grader #1'!C23 -> 1 | D23: ='Grader #2'!C23 -> 1 | F23: Composite State | G23: 0 | H23: 0.5 | I23: 1 | J23: Row Totals | L23: Metric | M23: Value | N23: Note
A24: ='Spa Manager'!A24 -> State | B24: ='Spa Manager'!B24 -> Off | C24: ='Grader #1'!C24 -> 1 | D24: ='Grader #2'!C24 -> 1 | F24: 0 | G24: =COUNTIFS($A$2:$A$90,$F$23,$C$2:$C$90,$F24,$D$2:$D$90,G$23) -> 1 | H24: =COUNTIFS($A$2:$A$90,$F$23,$C$2:$C$90,$F24,$D$2:$D$90,H$23) -> 0 | I24: =COUNTIFS($A$2:$A$46,$F$23,$C$2:$C$46,$F24,$D$2:$D$46,I$23) + MAX(D51-C51,0) -> 0 | J24: =SUM(G24:I24) -> 1 | L24: Observed Agreement (Po) | M24: =(G24+H25+I26)/COUNTIF($A$2:$A$100,F23) -> 1 | N24: This sums the diagonal of your matrix divided by total rows.
A25: ='Spa Manager'!A25 -> Composite State | B25: ='Spa Manager'!B25 -> On (Sauna) | C25: ='Grader #1'!C25 -> 1 | D25: ='Grader #2'!C25 -> 1 | F25: 0.5 | G25: =COUNTIFS($A$2:$A$90,$F$23,$C$2:$C$90,$F25,$D$2:$D$90,G$23) -> 0 | H25: =COUNTIFS($A$2:$A$90,$F$23,$C$2:$C$90,$F25,$D$2:$D$90,H$23) -> 0 | I25: =COUNTIFS($A$2:$A$90,$F$23,$C$2:$C$90,$F25,$D$2:$D$90,I$23) -> 0 | J25: =SUM(G25:I25) -> 0 | L25: Expected Agreement (Pe) | M25: {=SUMPRODUCT(J24:J26/COUNTIF($A$2:$A$100,F23), TRANSPOSE(G27:I27)/COUNTIF($A$2:$A$100,F23))} -> 0.625 | N25: This computes the sum of row proportion times column proportion.
A26: ='Spa Manager'!A26 -> Transition | B26: ='Spa Manager'!B26 -> on (Off ⇒ On) | C26: ='Grader #1'!C26 -> 1 | D26: ='Grader #2'!C26 -> 1 | F26: 1 | G26: =COUNTIFS($A$2:$A$46,$F$23,$C$2:$C$46,$F26,$D$2:$D$46,G$23) + MAX(C51-D51,0) -> 0 | H26: =COUNTIFS($A$2:$A$90,$F$23,$C$2:$C$90,$F26,$D$2:$D$90,H$23) -> 0 | I26: =COUNTIFS($A$2:$A$46,$F$23,$C$2:$C$46,$F26,$D$2:$D$46,I$23) + MIN(C51,D51) -> 3 | J26: =SUM(G26:I26) -> 3 | L26: Cohen's Kappa | M26: =(M24-M25)/(1-M25) -> 1 | N26: (Po - Pe) / (1 - Pe)
A27: ='Spa Manager'!A27 -> Transition | B27: ='Spa Manager'!B27 -> off (On ⇒ Off) | C27: ='Grader #1'!C27 -> 1 | D27: ='Grader #2'!C27 -> 1 | F27: Column Totals | G27: =SUM(G24:G26) -> 1 | H27: =SUM(H24:H26) -> 0 | I27: =SUM(I24:I26) -> 3
A28: ='Spa Manager'!A28 -> Region | B28: ='Spa Manager'!B28 -> Heater | C28: ='Grader #1'!C28 -> 1 | D28: ='Grader #2'!C28 -> 1
A29: ='Spa Manager'!A29 -> State | B29: ='Spa Manager'!B29 -> initial state (Heater → Heat) | C29: ='Grader #1'!C29 -> 1 | D29: ='Grader #2'!C29 -> 1 | F29: Confusion Matrix (Guard) | L29: Cohen's Kappa (Guard)
A30: ='Spa Manager'!A30 -> State | B30: ='Spa Manager'!B30 -> Heat | C30: ='Grader #1'!C30 -> 1 | D30: ='Grader #2'!C30 -> 1 | F30: Guard | G30: 0 | H30: 0.5 | I30: 1 | J30: Row Totals | L30: Metric | M30: Value | N30: Note
A31: ='Spa Manager'!A31 -> Transition | B31: ='Spa Manager'!B31 -> Heat ⇒ Idle | C31: ='Grader #1'!C31 -> 1 | D31: ='Grader #2'!C31 -> 1 | F31: 0 | G31: =COUNTIFS($A$2:$A$90,$F$30,$C$2:$C$90,$F31,$D$2:$D$90,G$30) -> 1 | H31: =COUNTIFS($A$2:$A$90,$F$30,$C$2:$C$90,$F31,$D$2:$D$90,H$30) -> 0 | I31: =COUNTIFS($A$2:$A$46,$F$30,$C$2:$C$46,$F31,$D$2:$D$46,I$30) + MAX(D49-C49,0) -> 0 | J31: =SUM(G31:I31) -> 1 | L31: Observed Agreement (Po) | M31: =(G31+H32+I33)/COUNTIF($A$2:$A$100,F30) -> 1 | N31: This sums the diagonal of your matrix divided by total rows.
A32: ='Spa Manager'!A32 -> Guard | B32: ='Spa Manager'!B32 -> [temp ≥ 90°C] | C32: ='Grader #1'!C32 -> 1 | D32: ='Grader #2'!C32 -> 1 | F32: 0.5 | G32: =COUNTIFS($A$2:$A$90,$F$30,$C$2:$C$90,$F32,$D$2:$D$90,G$30) -> 0 | H32: =COUNTIFS($A$2:$A$90,$F$30,$C$2:$C$90,$F32,$D$2:$D$90,H$30) -> 0 | I32: =COUNTIFS($A$2:$A$90,$F$30,$C$2:$C$90,$F32,$D$2:$D$90,I$30) -> 0 | J32: =SUM(G32:I32) -> 0 | L32: Expected Agreement (Pe) | M32: {=SUMPRODUCT(J31:J33/COUNTIF($A$2:$A$100,F30), TRANSPOSE(G34:I34)/COUNTIF($A$2:$A$100,F30))} -> 0.68 | N32: This computes the sum of row proportion times column proportion.
A33: ='Spa Manager'!A33 -> State | B33: ='Spa Manager'!B33 -> Idle | C33: ='Grader #1'!C33 -> 1 | D33: ='Grader #2'!C33 -> 1 | F33: 1 | G33: =COUNTIFS($A$2:$A$46,$F$30,$C$2:$C$46,$F33,$D$2:$D$46,G$30) + MAX(C49-D49,0) -> 0 | H33: =COUNTIFS($A$2:$A$90,$F$30,$C$2:$C$90,$F33,$D$2:$D$90,H$30) -> 0 | I33: =COUNTIFS($A$2:$A$46,$F$30,$C$2:$C$46,$F33,$D$2:$D$46,I$30) + MIN(C49,D49) -> 4 | J33: =SUM(G33:I33) -> 4 | L33: Cohen's Kappa | M33: =(M31-M32)/(1-M32) -> 1 | N33: (Po - Pe) / (1 - Pe)
A34: ='Spa Manager'!A34 -> Transition | B34: ='Spa Manager'!B34 -> Idle ⇒ Heat | C34: ='Grader #1'!C34 -> 1 | D34: ='Grader #2'!C34 -> 1 | F34: Column Totals | G34: =SUM(G31:G33) -> 1 | H34: =SUM(H31:H33) -> 0 | I34: =SUM(I31:I33) -> 4
A35: ='Spa Manager'!A35 -> Guard | B35: ='Spa Manager'!B35 -> [temp < 85°C] | C35: ='Grader #1'!C35 -> 1 | D35: ='Grader #2'!C35 -> 1
A36: ='Spa Manager'!A36 -> Region | B36: ='Spa Manager'!B36 -> Fan | C36: ='Grader #1'!C36 -> 1 | D36: ='Grader #2'!C36 -> 1 | F36: Confusion Matrix (Action) | L36: Cohen's Kappa (Action)
A37: ='Spa Manager'!A37 -> State | B37: ='Spa Manager'!B37 -> initial state (Fan → Off) | C37: ='Grader #1'!C37 -> 1 | D37: ='Grader #2'!C37 -> 1 | F37: Action | G37: 0 | H37: 0.5 | I37: 1 | J37: Row Totals | L37: Metric | M37: Value | N37: Note
A38: ='Spa Manager'!A38 -> State | B38: ='Spa Manager'!B38 -> Off | C38: ='Grader #1'!C38 -> 1 | D38: ='Grader #2'!C38 -> 1 | F38: 0 | G38: =COUNTIFS($A$2:$A$90,$F$37,$C$2:$C$90,$F38,$D$2:$D$90,G$37) -> 1 | H38: =COUNTIFS($A$2:$A$90,$F$37,$C$2:$C$90,$F38,$D$2:$D$90,H$37) -> 0 | I38: =COUNTIFS($A$2:$A$46,$F$37,$C$2:$C$46,$F38,$D$2:$D$46,I$37)+MAX(D50-C50,0) -> 0 | J38: =SUM(G38:I38) -> 1 | L38: Observed Agreement (Po) | M38: =(G38+H39+I40)/COUNTIF($A$2:$A$100,F37) -> 1 | N38: This sums the diagonal of your matrix divided by total rows.
A39: ='Spa Manager'!A39 -> Transition | B39: ='Spa Manager'!B39 -> Off ⇒ On | C39: ='Grader #1'!C39 -> 1 | D39: ='Grader #2'!C39 -> 1 | F39: 0.5 | G39: =COUNTIFS($A$2:$A$90,$F$37,$C$2:$C$90,$F39,$D$2:$D$90,G$37) -> 0 | H39: =COUNTIFS($A$2:$A$90,$F$37,$C$2:$C$90,$F39,$D$2:$D$90,H$37) -> 0 | I39: =COUNTIFS($A$2:$A$90,$F$37,$C$2:$C$90,$F39,$D$2:$D$90,I$37) -> 0 | J39: =SUM(G39:I39) -> 0 | L39: Expected Agreement (Pe) | M39: {=SUMPRODUCT(J38:J40/COUNTIF($A$2:$A$100,F37), TRANSPOSE(G41:I41)/COUNTIF($A$2:$A$100,F37))} -> 1 | N39: This computes the sum of row proportion times column proportion.
A40: ='Spa Manager'!A40 -> Guard | B40: ='Spa Manager'!B40 -> [humidity > 40% && exceedTime > 3min] | C40: ='Grader #1'!C40 -> 1 | D40: ='Grader #2'!C40 -> 1 | F40: 1 | G40: =COUNTIFS($A$2:$A$46,$F$37,$C$2:$C$46,$F40,$D$2:$D$46,G$37)+MAX(C50-D50,0) -> 0 | H40: =COUNTIFS($A$2:$A$90,$F$37,$C$2:$C$90,$F40,$D$2:$D$90,H$37) -> 0 | I40: =COUNTIFS($A$2:$A$46,$F$37,$C$2:$C$46,$F40,$D$2:$D$46,I$37) + MIN(C50,D50) -> 0 | J40: =SUM(G40:I40) -> 0 | L40: Cohen's Kappa | M40: =(M38-M39)/(1-M39) -> #DIV/0! | N40: (Po - Pe) / (1 - Pe)
...

Sheet Weighted Cohens Kappa
A1: Type | B1: Element | C1: Rater 1 | D1: Rater 2 | F1: Confusion Matrix | L1: Weight Matrix
A2: ='Spa Manager'!A2 -> Composite State | B2: ='Spa Manager'!B2 -> SpaManager | C2: ='Grader #1'!C2 -> 1 | D2: ='Grader #2'!C2 -> 1 | F2: Global | G2: 0 | H2: 0.5 | I2: 1 | J2: Row Totals | L2: Global | M2: 0 | N2: 0.5 | O2: 1 | Q2: Global | R2: 0 | S2: 0.5 | T2: 1 | V2: Metric | W2: Value | X2: Note
A3: ='Spa Manager'!A3 -> Region | B3: ='Spa Manager'!B3 -> Jacuzzi | C3: ='Grader #1'!C3 -> 1 | D3: ='Grader #2'!C3 -> 1 | F3: 0 | G3: =COUNTIFS($C$2:$C$90, $F3, $D$2:$D$90, G$2) -> 7 | H3: =COUNTIFS($C$2:$C$46, $F3, $D$2:$D$46, H$2) -> 1 | I3: =COUNTIFS($C$2:$C$46, $F3, $D$2:$D$46, I$2)+MAX(D47-C47,0)+MAX(D48-C48,0)+MAX(D49-C49,0)+MAX(D50-C50,0)+MAX(D51-C51,0)+MAX(D52-C52,0)+MAX(D53-C53,0) -> 0 | J3: =SUM(G3:I3) -> 8 | L3: 0 | M3: =ABS(G$2-$F3)/1 -> 0 | N3: =ABS(H$2-$F3)/1 -> 0.5 | O3: =ABS(I$2-$F3)/1 -> 1 | Q3: 0 | R3: =($J3/$J$6) * (G$6/$J$6) -> 0.021530181 | S3: =($J3/$J$6) * (H$6/$J$6) -> 0.0061514802 | T3: =($J3/$J$6) * (I$6/$J$6) -> 0.12918108 | V3: Observed Weighted Disagreement (D_obs) | W3: =SUMPRODUCT(G3:I5, M3:O5) /$J$6 -> 0.0098039216 | X3: Sum of (confusion-matrix counts × weights) divided by total items.
A4: ='Spa Manager'!A4 -> State | B4: ='Spa Manager'!B4 -> initial state (Jacuzzi → Off) | C4: ='Grader #1'!C4 -> 1 | D4: ='Grader #2'!C4 -> 1 | F4: 0.5 | G4: =COUNTIFS($C$2:$C$46, $F4, $D$2:$D$46, G$2) -> 0 | H4: =COUNTIFS($C$2:$C$46, $F4, $D$2:$D$46, H$2) -> 1 | I4: =COUNTIFS($C$2:$C$46, $F4, $D$2:$D$46, I$2) -> 0 | J4: =SUM(G4:I4) -> 1 | L4: 0.5 | M4: =ABS(G$2-$F4)/1 -> 0.5 | N4: =ABS(H$2-$F4)/3 -> 0 | O4: =ABS(I$2-$F4)/1 -> 0.5 | Q4: 0.5 | R4: =($J4/$J$6) * (G$6/$J$6) -> 0.0026912726 | S4: =($J4/$J$6) * (H$6/$J$6) -> 0.00076893503 | T4: =($J4/$J$6) * (I$6/$J$6) -> 0.016147636 | V4: Expected Weighted Disagreement (D_exp) | W4: =SUMPRODUCT(R3:T5, M3:O5) -> 0.27085736 | X4: Sum of (expected cell proportions × weights) under chance agreement.
A5: ='Spa Manager'!A5 -> State | B5: ='Spa Manager'!B5 -> Off | C5: ='Grader #1'!C5 -> 1 | D5: ='Grader #2'!C5 -> 1 | F5: 1 | G5: =COUNTIFS($C$2:$C$46, $F5, $D$2:$D$46, G$2)+MAX(C47-D47,0)+MAX(C48-D48,0)+MAX(C49-D49,0)+MAX(C50-D50,0)+MAX(C51-D51,0)+MAX(C52-D52,0)+MAX(C53-D53,0) -> 0 | H5: =COUNTIFS($C$2:$C$46, $F5, $D$2:$D$46, H$2) -> 0 | I5: =COUNTIFS($C$2:$C$46, $F5, $D$2:$D$46, I$2)+ SUM(MIN(C47,D47), MIN(C48,D48), MIN(C49,D49), MIN(C50,D50), MIN(C51,D51), MIN(C52,D52), MIN(C53,D53)) -> 42 | J5: =SUM(G5:I5) -> 42 | L5: 1 | M5: =ABS(G$2-$F5)/1 -> 1 | N5: =ABS(H$2-$F5)/1 -> 0.5 | O5: =ABS(I$2-$F5)/1 -> 0 | Q5: 1 | R5: =($J5/$J$6) * (G$6/$J$6) -> 0.11303345 | S5: =($J5/$J$6) * (H$6/$J$6) -> 0.032295271 | T5: =($J5/$J$6) * (I$6/$J$6) -> 0.67820069 | V5: Cohen's Kappa | W5: =1-W3/W4 -> 0.96380412 | X5: 1 - (D_obs / D_exp)
A6: ='Spa Manager'!A6 -> Composite State | B6: ='Spa Manager'!B6 -> On (Jacuzzi) | C6: ='Grader #1'!C6 -> 1 | D6: ='Grader #2'!C6 -> 1 | F6: Column Totals | G6: =SUM(G3:G5) -> 7 | H6: =SUM(H3:H5) -> 2 | I6: =SUM(I3:I5) -> 42 | J6: =SUM(G3:I5) -> 51
A7: ='Spa Manager'!A7 -> Transition | B7: ='Spa Manager'!B7 -> on (Off ⇒ On) | C7: ='Grader #1'!C7 -> 1 | D7: ='Grader #2'!C7 -> 1
A8: ='Spa Manager'!A8 -> Transition | B8: ='Spa Manager'!B8 -> off (On ⇒ Off) | C8: ='Grader #1'!C8 -> 1 | D8: ='Grader #2'!C8 -> 1 | F8: Confusion Matrix (State)
A9: ='Spa Manager'!A9 -> State | B9: ='Spa Manager'!B9 -> initial state (Level1) | C9: ='Grader #1'!C9 -> 1 | D9: ='Grader #2'!C9 -> 1 | F9: State | G9: 0 | H9: 0.5 | I9: 1 | J9: Row Totals | L9: Global | M9: 0 | N9: 0.5 | O9: 1 | Q9: Global | R9: 0 | S9: 0.5 | T9: 1 | V9: Metric | W9: Value | X9: Note
A10: ='Spa Manager'!A10 -> State | B10: ='Spa Manager'!B10 -> Level1 | C10: ='Grader #1'!C10 -> 1 | D10: ='Grader #2'!C10 -> 1 | F10: 0 | G10: =COUNTIFS($A$2:$A$90,$F$9,$C$2:$C$90,$F10,$D$2:$D$90,G$9) -> 1 | H10: =COUNTIFS($A$2:$A$90,$F$9,$C$2:$C$90,$F10,$D$2:$D$90,H$9) -> 0 | I10: =COUNTIFS($A$2:$A$46,$F$9,$C$2:$C$46,$F10,$D$2:$D$46,I$9)+MAX(D47-C47,0) -> 0 | J10: =SUM(G10:I10) -> 1 | L10: 0 | M10: =ABS(G$2-$F10)/1 -> 0 | N10: =ABS(H$2-$F10)/1 -> 0.5 | O10: =ABS(I$2-$F10)/1 -> 1 | Q10: 0 | R10: =($J10/$J$13) * (G$13/$J$13) -> 0.0034602076 | S10: =($J10/$J$13) * (H$13/$J$13) -> 0 | T10: =($J10/$J$13) * (I$13/$J$13) -> 0.055363322 | V10: Observed Weighted Disagreement (D_obs) | W10: =SUMPRODUCT(G10:I12, M10:O12) /$J$13 -> 0 | X10: Sum of (confusion-matrix counts × weights) divided by total items.
A11: ='Spa Manager'!A11 -> Transition | B11: ='Spa Manager'!B11 -> up (Level1 ⇒ Level2) | C11: ='Grader #1'!C11 -> 1 | D11: ='Grader #2'!C11 -> 1 | F11: 0.5 | G11: =COUNTIFS($A$2:$A$90,$F$9,$C$2:$C$90,$F11,$D$2:$D$90,G$9) -> 0 | H11: =COUNTIFS($A$2:$A$90,$F$9,$C$2:$C$90,$F11,$D$2:$D$90,H$9) -> 0 | I11: =COUNTIFS($A$2:$A$90,$F$9,$C$2:$C$90,$F11,$D$2:$D$90,I$9) -> 0 | J11: =SUM(G11:I11) -> 0 | L11: 0.5 | M11: =ABS(G$2-$F11)/1 -> 0.5 | N11: =ABS(H$2-$F11)/3 -> 0 | O11: =ABS(I$2-$F11)/1 -> 0.5 | Q11: 0.5 | R11: =($J11/$J$13) * (G$13/$J$13) -> 0 | S11: =($J11/$J$13) * (H$13/$J$13) -> 0 | T11: =($J11/$J$13) * (I$13/$J$13) -> 0 | V11: Expected Weighted Disagreement (D_exp) | W11: =SUMPRODUCT(R10:T12, M10:O12) -> 0.11072664 | X11: Sum of (expected cell proportions × weights) under chance agreement.
A12: ='Spa Manager'!A12 -> State | B12: ='Spa Manager'!B12 -> Level2 | C12: ='Grader #1'!C12 -> 1 | D12: ='Grader #2'!C12 -> 1 | F12: 1 | G12: =COUNTIFS($A$2:$A$46,$F$9,$C$2:$C$46,$F12,$D$2:$D$46,G$9)+MAX(C47-D47,0) -> 0 | H12: =COUNTIFS($A$2:$A$90,$F$9,$C$2:$C$90,$F12,$D$2:$D$90,H$9) -> 0 | I12: =COUNTIFS($A$2:$A$46,$F$9,$C$2:$C$46,$F12,$D$2:$D$46,I$9)+MIN(C47-D47) -> 16 | J12: =SUM(G12:I12) -> 16 | L12: 1 | M12: =ABS(G$2-$F12)/1 -> 1 | N12: =ABS(H$2-$F12)/1 -> 0.5 | O12: =ABS(I$2-$F12)/1 -> 0 | Q12: 1 | R12: =($J12/$J$13) * (G$13/$J$13) -> 0.055363322 | S12: =($J12/$J$13) * (H$13/$J$13) -> 0 | T12: =($J12/$J$13) * (I$13/$J$13) -> 0.88581315 | V12: Cohen's Kappa | W12: =1-W10/W11 -> 1 | X12: 1 - (D_obs / D_exp)
A13: ='Spa Manager'!A13 -> Transition | B13: ='Spa Manager'!B13 -> up (Level2 ⇒ Level3) | C13: ='Grader #1'!C13 -> 1 | D13: ='Grader #2'!C13 -> 1 | F13: Column Totals | G13: =SUM(G10:G12) -> 1 | H13: =SUM(H10:H12) -> 0 | I13: =SUM(I10:I12) -> 16 | J13: =SUM(G10:I12) -> 17
A14: ='Spa Manager'!A14 -> Transition | B14: ='Spa Manager'!B14 -> down (Level2 ⇒ Level1) | C14: ='Grader #1'!C14 -> 1 | D14: ='Grader #2'!C14 -> 1
A15: ='Spa Manager'!A15 -> State | B15: ='Spa Manager'!B15 -> Level3 | C15: ='Grader #1'!C15 -> 1 | D15: ='Grader #2'!C15 -> 1 | F15: Confusion Matrix (Transition)
A16: ='Spa Manager'!A16 -> Transition | B16: ='Spa Manager'!B16 -> down (Level3 ⇒ Level2) | C16: ='Grader #1'!C16 -> 1 | D16: ='Grader #2'!C16 -> 1 | F16: Transition | G16: 0 | H16: 0.5 | I16: 1 | J16: Row Totals | L16: Global | M16: 0 | N16: 0.5 | O16: 1 | Q16: Global | R16: 0 | S16: 0.5 | T16: 1 | V16: Metric | W16: Value | X16: Note
A17: ='Spa Manager'!A17 -> History State | B17: ='Spa Manager'!B17 -> History State for Jacuzzi On | C17: ='Grader #1'!C17 -> 1 | D17: ='Grader #2'!C17 -> 1 | F17: 0 | G17: =COUNTIFS($A$2:$A$90,$F$16,$C$2:$C$90,$F17,$D$2:$D$90,G$16) -> 1 | H17: =COUNTIFS($A$2:$A$90,$F$16,$C$2:$C$90,$F17,$D$2:$D$90,H$16) -> 1 | I17: =COUNTIFS($A$2:$A$46,$F$16,$C$2:$C$46,$F17,$D$2:$D$46,I$16) + MAX(D48-C48,0) -> 0 | J17: =SUM(G17:I17) -> 2 | L17: 0 | M17: =ABS(G$2-$F17)/1 -> 0 | N17: =ABS(H$2-$F17)/1 -> 0.5 | O17: =ABS(I$2-$F17)/1 -> 1 | Q17: 0 | R17: =($J17/$J$20) * (G$20/$J$20) -> 0.0078125 | S17: =($J17/$J$20) * (H$20/$J$20) -> 0.015625 | T17: =($J17/$J$20) * (I$20/$J$20) -> 0.1015625 | V17: Observed Weighted Disagreement (D_obs) | W17: =SUMPRODUCT(G17:I19, M17:O19) /$J$20 -> 0.03125 | X17: Sum of (confusion-matrix counts × weights) divided by total items.
A18: ='Spa Manager'!A18 -> Transition | B18: ='Spa Manager'!B18 -> setPattern(PatternType type) (On⇒ History State) | C18: ='Grader #1'!C18 -> 0.5 | D18: ='Grader #2'!C18 -> 0.5 | F18: 0.5 | G18: =COUNTIFS($A$2:$A$90,$F$16,$C$2:$C$90,$F18,$D$2:$D$90,G$16) -> 0 | H18: =COUNTIFS($A$2:$A$90,$F$16,$C$2:$C$90,$F18,$D$2:$D$90,H$16) -> 1 | I18: =COUNTIFS($A$2:$A$90,$F$16,$C$2:$C$90,$F18,$D$2:$D$90,I$16) -> 0 | J18: =SUM(G18:I18) -> 1 | L18: 0.5 | M18: =ABS(G$2-$F18)/1 -> 0.5 | N18: =ABS(H$2-$F18)/3 -> 0 | O18: =ABS(I$2-$F18)/1 -> 0.5 | Q18: 0.5 | R18: =($J18/$J$20) * (G$20/$J$20) -> 0.00390625 | S18: =($J18/$J$20) * (H$20/$J$20) -> 0.0078125 | T18: =($J18/$J$20) * (I$20/$J$20) -> 0.05078125 | V18: Expected Weighted Disagreement (D_exp) | W18: =SUMPRODUCT(R17:T19, M17:O19) -> 0.23828125 | X18: Sum of (expected cell proportions × weights) under chance agreement.
A19: ='Spa Manager'!A19 -> State | B19: ='Spa Manager'!B19 -> Paused | C19: ='Grader #1'!C19 -> 1 | D19: ='Grader #2'!C19 -> 1 | F19: 1 | G19: =COUNTIFS($A$2:$A$46,$F$16,$C$2:$C$46,$F19,$D$2:$D$46,G$16)+MAX(C48-D48,0) -> 0 | H19: =COUNTIFS($A$2:$A$90,$F$16,$C$2:$C$90,$F19,$D$2:$D$90,H$16) -> 0 | I19: =COUNTIFS($A$2:$A$46,$F$16,$C$2:$C$46,$F19,$D$2:$D$46,I$16) + MIN(C48,D48) -> 13 | J19: =SUM(G19:I19) -> 13 | L19: 1 | M19: =ABS(G$2-$F19)/1 -> 1 | N19: =ABS(H$2-$F19)/1 -> 0.5 | O19: =ABS(I$2-$F19)/1 -> 0 | Q19: 1 | R19: =($J19/$J$20) * (G$20/$J$20) -> 0.05078125 | S19: =($J19/$J$20) * (H$20/$J$20) -> 0.1015625 | T19: =($J19/$J$20) * (I$20/$J$20) -> 0.66015625 | V19: Cohen's Kappa | W19: =1-W17/W18 -> 0.86885246 | X19: 1 - (D_obs / D_exp)
A20: ='Spa Manager'!A20 -> Transition | B20: ='Spa Manager'!B20 -> pause (On⇒ Pause) | C20: ='Grader #1'!C20 -> 0 | D20: ='Grader #2'!C20 -> 0.5 | F20: Column Totals | G20: =SUM(G17:G19) -> 1 | H20: =SUM(H17:H19) -> 2 | I20: =SUM(I17:I19) -> 13 | J20: =SUM(G17:I19) -> 16
A21: ='Spa Manager'!A21 -> Transition | B21: ='Spa Manager'!B21 -> after 2min (Paused ⇒ History State) | C21: ='Grader #1'!C21 -> 1 | D21: ='Grader #2'!C21 -> 1
A22: ='Spa Manager'!A22 -> Region | B22: ='Spa Manager'!B22 -> Sauna | C22: ='Grader #1'!C22 -> 1 | D22: ='Grader #2'!C22 -> 1 | F22: Confusion Matrix (Composite State)
A23: ='Spa Manager'!A23 -> State | B23: ='Spa Manager'!B23 -> initial state (Sauna → Off) | C23: ='Grader #1'!C23 -> 1 | D23: ='Grader #2'!C23 -> 1 | F23: Composite State | G23: 0 | H23: 0.5 | I23: 1 | J23: Row Totals | L23: Global | M23: 0 | N23: 0.5 | O23: 1 | Q23: Global | R23: 0 | S23: 0.5 | T23: 1 | V23: Metric | W23: Value | X23: Note
A24: ='Spa Manager'!A24 -> State | B24: ='Spa Manager'!B24 -> Off | C24: ='Grader #1'!C24 -> 1 | D24: ='Grader #2'!C24 -> 1 | F24: 0 | G24: =COUNTIFS($A$2:$A$90,$F$23,$C$2:$C$90,$F24,$D$2:$D$90,G$23) -> 1 | H24: =COUNTIFS($A$2:$A$90,$F$23,$C$2:$C$90,$F24,$D$2:$D$90,H$23) -> 0 | I24: =COUNTIFS($A$2:$A$46,$F$23,$C$2:$C$46,$F24,$D$2:$D$46,I$23) + MAX(D51-C51,0) -> 0 | J24: =SUM(G24:I24) -> 1 | L24: 0 | M24: =ABS(G$2-$F24)/1 -> 0 | N24: =ABS(H$2-$F24)/1 -> 0.5 | O24: =ABS(I$2-$F24)/1 -> 1 | Q24: 0 | R24: =($J24/$J$27) * (G$27/$J$27) -> 0.0625 | S24: =($J24/$J$27) * (H$27/$J$27) -> 0 | T24: =($J24/$J$27) * (I$27/$J$27) -> 0.1875 | V24: Observed Weighted Disagreement (D_obs) | W24: =SUMPRODUCT(G24:I26, M24:O26) /$J$27 -> 0 | X24: Sum of (confusion-matrix counts × weights) divided by total items.
A25: ='Spa Manager'!A25 -> Composite State | B25: ='Spa Manager'!B25 -> On (Sauna) | C25: ='Grader #1'!C25 -> 1 | D25: ='Grader #2'!C25 -> 1 | F25: 0.5 | G25: =COUNTIFS($A$2:$A$90,$F$23,$C$2:$C$90,$F25,$D$2:$D$90,G$23) -> 0 | H25: =COUNTIFS($A$2:$A$90,$F$23,$C$2:$C$90,$F25,$D$2:$D$90,H$23) -> 0 | I25: =COUNTIFS($A$2:$A$90,$F$23,$C$2:$C$90,$F25,$D$2:$D$90,I$23) -> 0 | J25: =SUM(G25:I25) -> 0 | L25: 0.5 | M25: =ABS(G$2-$F25)/1 -> 0.5 | N25: =ABS(H$2-$F25)/3 -> 0 | O25: =ABS(I$2-$F25)/1 -> 0.5 | Q25: 0.5 | R25: =($J25/$J$27) * (G$27/$J$27) -> 0 | S25: =($J25/$J$27) * (H$27/$J$27) -> 0 | T25: =($J25/$J$27) * (I$27/$J$27) -> 0 | V25: Expected Weighted Disagreement (D_exp) | W25: =SUMPRODUCT(R24:T26, M24:O26) -> 0.375 | X25: Sum of (expected cell proportions × weights) under chance agreement.
A26: ='Spa Manager'!A26 -> Transition | B26: ='Spa Manager'!B26 -> on (Off ⇒ On) | C26: ='Grader #1'!C26 -> 1 | D26: ='Grader #2'!C26 -> 1 | F26: 1 | G26: =COUNTIFS($A$2:$A$46,$F$23,$C$2:$C$46,$F26,$D$2:$D$46,G$23) + MAX(C51-D51,0) -> 0 | H26: =COUNTIFS($A$2:$A$90,$F$23,$C$2:$C$90,$F26,$D$2:$D$90,H$23) -> 0 | I26: =COUNTIFS($A$2:$A$46,$F$23,$C$2:$C$46,$F26,$D$2:$D$46,I$23) + MIN(C51,D51) -> 3 | J26: =SUM(G26:I26) -> 3 | L26: 1 | M26: =ABS(G$2-$F26)/1 -> 1 | N26: =ABS(H$2-$F26)/1 -> 0.5 | O26: =ABS(I$2-$F26)/1 -> 0 | Q26: 1 | R26: =($J26/$J$27) * (G$27/$J$27) -> 0.1875 | S26: =($J26/$J$27) * (H$27/$J$27) -> 0 | T26: =($J26/$J$27) * (I$27/$J$27) -> 0.5625 | V26: Cohen's Kappa | W26: =1-W24/W25 -> 1 | X26: 1 - (D_obs / D_exp)
A27: ='Spa Manager'!A27 -> Transition | B27: ='Spa Manager'!B27 -> off (On ⇒ Off) | C27: ='Grader #1'!C27 -> 1 | D27: ='Grader #2'!C27 -> 1 | F27: Column Totals | G27: =SUM(G24:G26) -> 1 | H27: =SUM(H24:H26) -> 0 | I27: =SUM(I24:I26) -> 3 | J27: =SUM(G24:I26) -> 4
A28: ='Spa Manager'!A28 -> Region | B28: ='Spa Manager'!B28 -> Heater | C28: ='Grader #1'!C28 -> 1 | D28: ='Grader #2'!C28 -> 1
A29: ='Spa Manager'!A29 -> State | B29: ='Spa Manager'!B29 -> initial state (Heater → Heat) | C29: ='Grader #1'!C29 -> 1 | D29: ='Grader #2'!C29 -> 1 | F29: Confusion Matrix (Guard)
A30: ='Spa Manager'!A30 -> State | B30: ='Spa Manager'!B30 -> Heat | C30: ='Grader #1'!C30 -> 1 | D30: ='Grader #2'!C30 -> 1 | F30: Guard | G30: 0 | H30: 0.5 | I30: 1 | J30: Row Totals | L30: Global | M30: 0 | N30: 0.5 | O30: 1 | Q30: Global | R30: 0 | S30: 0.5 | T30: 1 | V30: Metric | W30: Value | X30: Note
A31: ='Spa Manager'!A31 -> Transition | B31: ='Spa Manager'!B31 -> Heat ⇒ Idle | C31: ='Grader #1'!C31 -> 1 | D31: ='Grader #2'!C31 -> 1 | F31: 0 | G31: =COUNTIFS($A$2:$A$90,$F$30,$C$2:$C$90,$F31,$D$2:$D$90,G$30) -> 1 | H31: =COUNTIFS($A$2:$A$90,$F$30,$C$2:$C$90,$F31,$D$2:$D$90,H$30) -> 0 | I31: =COUNTIFS($A$2:$A$46,$F$30,$C$2:$C$46,$F31,$D$2:$D$46,I$30) + MAX(D49-C49,0) -> 0 | J31: =SUM(G31:I31) -> 1 | L31: 0 | M31: =ABS(G$2-$F31)/1 -> 0 | N31: =ABS(H$2-$F31)/1 -> 0.5 | O31: =ABS(I$2-$F31)/1 -> 1 | Q31: 0 | R31: =($J31/$J$34) * (G$34/$J$34) -> 0.04 | S31: =($J31/$J$34) * (H$34/$J$34) -> 0 | T31: =($J31/$J$34) * (I$34/$J$34) -> 0.16 | V31: Observed Weighted Disagreement (D_obs) | W31: =SUMPRODUCT(G31:I33, M31:O33) /$J$34 -> 0 | X31: Sum of (confusion-matrix counts × weights) divided by total items.
A32: ='Spa Manager'!A32 -> Guard | B32: ='Spa Manager'!B32 -> [temp ≥ 90°C] | C32: ='Grader #1'!C32 -> 1 | D32: ='Grader #2'!C32 -> 1 | F32: 0.5 | G32: =COUNTIFS($A$2:$A$90,$F$30,$C$2:$C$90,$F32,$D$2:$D$90,G$30) -> 0 | H32: =COUNTIFS($A$2:$A$90,$F$30,$C$2:$C$90,$F32,$D$2:$D$90,H$30) -> 0 | I32: =COUNTIFS($A$2:$A$90,$F$30,$C$2:$C$90,$F32,$D$2:$D$90,I$30) -> 0 | J32: =SUM(G32:I32) -> 0 | L32: 0.5 | M32: =ABS(G$2-$F32)/1 -> 0.5 | N32: =ABS(H$2-$F32)/3 -> 0 | O32: =ABS(I$2-$F32)/1 -> 0.5 | Q32: 0.5 | R32: =($J32/$J$34) * (G$34/$J$34) -> 0 | S32: =($J32/$J$34) * (H$34/$J$34) -> 0 | T32: =($J32/$J$34) * (I$34/$J$34) -> 0 | V32: Expected Weighted Disagreement (D_exp) | W32: =SUMPRODUCT(R31:T33, M31:O33) -> 0.32 | X32: Sum of (expected cell proportions × weights) under chance agreement.
A33: ='Spa Manager'!A33 -> State | B33: ='Spa Manager'!B33 -> Idle | C33: ='Grader #1'!C33 -> 1 | D33: ='Grader #2'!C33 -> 1 | F33: 1 | G33: =COUNTIFS($A$2:$A$46,$F$30,$C$2:$C$46,$F33,$D$2:$D$46,G$30) + MAX(C49-D49,0) -> 0 | H33: =COUNTIFS($A$2:$A$90,$F$30,$C$2:$C$90,$F33,$D$2:$D$90,H$30) -> 0 | I33: =COUNTIFS($A$2:$A$46,$F$30,$C$2:$C$46,$F33,$D$2:$D$46,I$30) + MIN(C49,D49) -> 4 | J33: =SUM(G33:I33) -> 4 | L33: 1 | M33: =ABS(G$2-$F33)/1 -> 1 | N33: =ABS(H$2-$F33)/1 -> 0.5 | O33: =ABS(I$2-$F33)/1 -> 0 | Q33: 1 | R33: =($J33/$J$34) * (G$34/$J$34) -> 0.16 | S33: =($J33/$J$34) * (H$34/$J$34) -> 0 | T33: =($J33/$J$34) * (I$34/$J$34) -> 0.64 | V33: Cohen's Kappa | W33: =1-W31/W32 -> 1 | X33: 1 - (D_obs / D_exp)
A34: ='Spa Manager'!A34 -> Transition | B34: ='Spa Manager'!B34 -> Idle ⇒ Heat | C34: ='Grader #1'!C34 -> 1 | D34: ='Grader #2'!C34 -> 1 | F34: Column Totals | G34: =SUM(G31:G33) -> 1 | H34: =SUM(H31:H33) -> 0 | I34: =SUM(I31:I33) -> 4 | J34: =SUM(G31:I33) -> 5
A35: ='Spa Manager'!A35 -> Guard | B35: ='Spa Manager'!B35 -> [temp < 85°C] | C35: ='Grader #1'!C35 -> 1 | D35: ='Grader #2'!C35 -> 1
A36: ='Spa Manager'!A36 -> Region | B36: ='Spa Manager'!B36 -> Fan | C36: ='Grader #1'!C36 -> 1 | D36: ='Grader #2'!C36 -> 1 | F36: Confusion Matrix (Action)
A37: ='Spa Manager'!A37 -> State | B37: ='Spa Manager'!B37 -> initial state (Fan → Off) | C37: ='Grader #1'!C37 -> 1 | D37: ='Grader #2'!C37 -> 1 | F37: Action | G37: 0 | H37: 0.5 | I37: 1 | J37: Row Totals | L37: Global | M37: 0 | N37: 0.5 | O37: 1 | Q37: Global | R37: 0 | S37: 0.5 | T37: 1 | V37: Metric | W37: Value | X37: Note
A38: ='Spa Manager'!A38 -> State | B38: ='Spa Manager'!B38 -> Off | C38: ='Grader #1'!C38 -> 1 | D38: ='Grader #2'!C38 -> 1 | F38: 0 | G38: =COUNTIFS($A$2:$A$90,$F$37,$C$2:$C$90,$F38,$D$2:$D$90,G$37) -> 1 | H38: =COUNTIFS($A$2:$A$90,$F$37,$C$2:$C$90,$F38,$D$2:$D$90,H$37) -> 0 | I38: =COUNTIFS($A$2:$A$46,$F$37,$C$2:$C$46,$F38,$D$2:$D$46,I$37)+MAX(D50-C50,0) -> 0 | J38: =SUM(G38:I38) -> 1 | L38: 0 | M38: =ABS(G$2-$F38)/1 -> 0 | N38: =ABS(H$2-$F38)/1 -> 0.5 | O38: =ABS(I$2-$F38)/1 -> 1 | Q38: 0 | R38: =($J38/$J$27) * (G$27/$J$27) -> 0.0625 | S38: =($J38/$J$27) * (H$27/$J$27) -> 0 | T38: =($J38/$J$27) * (I$27/$J$27) -> 0.1875 | V38: Observed Weighted Disagreement (D_obs) | W38: =SUMPRODUCT(G38:I40, M38:O40) /$J$41 -> 0 | X38: Sum of (confusion-matrix counts × weights) divided by total items.
A39: ='Spa Manager'!A39 -> Transition | B39: ='Spa Manager'!B39 -> Off ⇒ On | C39: ='Grader #1'!C39 -> 1 | D39: ='Grader #2'!C39 -> 1 | F39: 0.5 | G39: =COUNTIFS($A$2:$A$90,$F$37,$C$2:$C$90,$F39,$D$2:$D$90,G$37) -> 0 | H39: =COUNTIFS($A$2:$A$90,$F$37,$C$2:$C$90,$F39,$D$2:$D$90,H$37) -> 0 | I39: =COUNTIFS($A$2:$A$90,$F$37,$C$2:$C$90,$F39,$D$2:$D$90,I$37) -> 0 | J39: =SUM(G39:I39) -> 0 | L39: 0.5 | M39: =ABS(G$2-$F39)/1 -> 0.5 | N39: =ABS(H$2-$F39)/3 -> 0 | O39: =ABS(I$2-$F39)/1 -> 0.5 | Q39: 0.5 | R39: =($J39/$J$27) * (G$27/$J$27) -> 0 | S39: =($J39/$J$27) * (H$27/$J$27) -> 0 | T39: =($J39/$J$27) * (I$27/$J$27) -> 0 | V39: Expected Weighted Disagreement (D_exp) | W39: =SUMPRODUCT(R38:T40, M38:O40) -> 0.1875 | X39: Sum of (expected cell proportions × weights) under chance agreement.
A40: ='Spa Manager'!A40 -> Guard | B40: ='Spa Manager'!B40 -> [humidity > 40% && exceedTime > 3min] | C40: ='Grader #1'!C40 -> 1 | D40: ='Grader #2'!C40 -> 1 | F40: 1 | G40: =COUNTIFS($A$2:$A$46,$F$37,$C$2:$C$46,$F40,$D$2:$D$46,G$37)+MAX(C50-D50,0) -> 0 | H40: =COUNTIFS($A$2:$A$90,$F$37,$C$2:$C$90,$F40,$D$2:$D$90,H$37) -> 0 | I40: =COUNTIFS($A$2:$A$46,$F$37,$C$2:$C$46,$F40,$D$2:$D$46,I$37) + MIN(C50,D50) -> 0 | J40: =SUM(G40:I40) -> 0 | L40: 1 | M40: =ABS(G$2-$F40)/1 -> 1 | N40: =ABS(H$2-$F40)/1 -> 0.5 | O40: =ABS(I$2-$F40)/1 -> 0 | Q40: 1 | R40: =($J40/$J$27) * (G$27/$J$27) -> 0 | S40: =($J40/$J$27) * (H$27/$J$27) -> 0 | T40: =($J40/$J$27) * (I$27/$J$27) -> 0 | V40: Cohen's Kappa | W40: =1-W38/W39 -> 1 | X40: 1 - (D_obs / D_exp)
...
