Workbook

Sheet Chess Clock
A1: Type | B1: Element
A2: State | B2: initial state (off)
A3: Transition | B3: initial state (off) => off
A4: State | B4: Off
A5: Transition | B5: off => on
A6: Composite State | B6: On
A7: State | B7: initial state (on)
A8: Composite State | B8: GameSetup
A9: Region | B9: GameSetup Region 1
A10: State | B10: Initial state (region 1)
A11: State | B11: TimingSelection
A12: Action | B12: incrTimingProgram()
... A53: History State | B53: additional elements

Sheet Human Grading
A1: Type | B1: Element | C1: Human | D1: Notes
A2: State | B2: initial state (off) | C2: 1
A3: Transition | B3: initial state (off) => off | C3: 1
A4: State | B4: Off | C4: 1
A5: Transition | B5: off => on | C5: 1
A6: Composite State | B6: On | C6: 1
A7: State | B7: initial state (on) | C7: 1
A8: Composite State | B8: GameSetup | C8: 1
A9: Region | B9: GameSetup Region 1 | C9: 1 | D9: doesnt have parralel regions but its equivalent
A10: State | B10: Initial state (region 1) | C10: 1
A11: State | B11: TimingSelection | C11: 1
A12: Action | B12: incrTimingProgram() | C12: 1
A13: Action | B13: decrTimingProgram() | C13: 1
A14: Transition | B14: timing selection => timing selection | C14: 1
A15: Transition | B15: game setup => ready to start | C15: 0
A16: Region | B16: GameSetup Region 2 | C16: 0
A17: State | B17: Initial state (region 2) | C17: 1 | D17: shown with swaporientation()
A18: State | B18: WhiteKingOnLeft | C18: 1
A19: State | B19: WhiteKingOnRight | C19: 1
A20: Transition | B20: initial state => white king on left | C20: 1
A21: Transition | B21: white king on left => white king on right | C21: 1
A22: Transition | B22: white king on right => white king on left | C22: 1
A23: State | B23: ReadyToStart | C23: 0
A24: Transition | B24: ready to start => game running | C24: 1 | D24: from setup to gameActive
A25: Composite State | B25: GameRunning | C25: 1
A26: History State | B26: H | C26: 1
A27: State | B27: WhiteClockRunning | C27: 1
A28: Action | B28: startTimer(wc) | C28: 1 | D28: represented as countdown as a DO action
A29: Action | B29: stopTimer(wc) | C29: 1
A30: Guard | B30: [wc > 0] | C30: 1
A31: Action | B31: decrTimer(wc) | C31: 1
A32: Transition | B32: white clock running => white clock running | C32: 1 | D32: because of the DO ACTION, this is equivalent
A33: State | B33: BlackClockRunning | C33: 1
A34: Action | B34: startTimer(bc) | C34: 1
A35: Action | B35: stopTimer(bc) | C35: 1
A36: Guard | B36: [bc > 0] | C36: 1
A37: Action | B37: decrTimer(bc) | C37: 1
A38: Transition | B38: balck clock running => black clock running | C38: 1 | D38: because of the DO ACTION, this is equivalent
A39: Transition | B39: game running => game paused | C39: 1
A40: Transition | B40: game running => game finished | C40: 0
...

Sheet LLM Grading
A1: Type | B1: Element | C1: LLM | D1: Notes
A2: State | B2: initial state (off) | C2: 1 | D2: Correctly represented with [*] --> Off
A3: Transition | B3: initial state (off) => off | C3: 1 | D3: Correctly represented with [*] --> Off
A4: State | B4: Off | C4: 1 | D4: Off state is present
A5: Transition | B5: off => on | C5: 1 | D5: Off --> On : onOff transition is present
A6: Composite State | B6: On | C6: 1 | D6: On composite state is present
A7: State | B7: initial state (on) | C7: 1 | D7: [*] --> Setup within On state
A8: Composite State | B8: GameSetup | C8: 0.5 | D8: Setup composite state exists but lacks parallel regions for timing and orientation
A9: Region | B9: GameSetup Region 1 | C9: 0 | D9: No parallel regions defined; timing selection is within Setup but not as a separate region
A10: State | B10: Initial state (region 1) | C10: 0 | D10: No separate region 1 with initial state
A11: State | B11: TimingSelection | C11: 1 | D11: TimingSelection state exists within Setup
A12: Action | B12: incrTimingProgram() | C12: 1 | D12: selectNextTiming() action on plus event is semantically equivalent
A13: Action | B13: decrTimingProgram() | C13: 1 | D13: selectPreviousTiming() action on minus event is semantically equivalent
... A53: History State | B53: additional elements | C53: 0 | D53: Only one history state H which is appropriate

Sheet Metrics
A1: Claude Grader Human | J1: Date
A2: Type | B2: Ground Truth Count | C2: True Positive | D2: False Positive | E2: False Negative | F2: Precision | G2: Recall | H2: F1 Score | J2: March 16th, 2026
A3: Composite State | B3: =COUNTIF('Chess Clock'!$A$2:$A$46, A3) -> 3 | C3: =SUMIF('Human Grading'!$A$2:$A$46, $A3, 'Human Grading'!$C$2:$C$46) -> 3 | D3: =SUMIF('Human Grading'!$A$47:$A$53, $A3, 'Human Grading'!$C$47:$C$53) -> 0 | E3: =COUNTIFS('Human Grading'!$A$2:$A$46, $A3, 'Human Grading'!$C$2:$C$46,0) -> 0 | F3: =IFERROR(C3 / (C3 + D3), "Not Available") -> 1 | G3: =IFERROR(C3 / B3, "Not Available") -> 1 | H3: =IFERROR(2*((F3*G3)/(F3+G3)),"Not Available") -> 1
A4: State | B4: =COUNTIF('Chess Clock'!$A$2:$A$46, A4) -> 13 | C4: =SUMIF('Human Grading'!$A$2:$A$46, $A4, 'Human Grading'!$C$2:$C$46) -> 11.5 | D4: =SUMIF('Human Grading'!$A$47:$A$53, $A4, 'Human Grading'!$C$47:$C$53) -> 0 | E4: =COUNTIFS('Human Grading'!$A$2:$A$46, $A4, 'Human Grading'!$C$2:$C$46,0) -> 1 | F4: =IFERROR(C4 / (C4 + D4), "Not Available") -> 1 | G4: =IFERROR(C4 / B4, "Not Available") -> 0.88461538 | H4: =IFERROR(2*((F4*G4)/(F4+G4)),"Not Available") -> 0.93877551 | J4: LLM Used
A5: Transition | B5: =COUNTIF('Chess Clock'!$A$2:$A$46, A5) -> 14 | C5: =SUMIF('Human Grading'!$A$2:$A$46, $A5, 'Human Grading'!$C$2:$C$46) -> 12 | D5: =SUMIF('Human Grading'!$A$47:$A$53, $A5, 'Human Grading'!$C$47:$C$53) -> 0 | E5: =COUNTIFS('Human Grading'!$A$2:$A$46, $A5, 'Human Grading'!$C$2:$C$46,0) -> 2 | F5: =IFERROR(C5 / (C5 + D5), "Not Available") -> 1 | G5: =IFERROR(C5 / B5, "Not Available") -> 0.85714286 | H5: =IFERROR(2*((F5*G5)/(F5+G5)),"Not Available") -> 0.92307692 | J5: Claude 4.5 Sonnet
A6: Action | B6: =COUNTIF('Chess Clock'!$A$2:$A$46, A6) -> 8 | C6: =SUMIF('Human Grading'!$A$2:$A$46, $A6, 'Human Grading'!$C$2:$C$46) -> 8 | D6: =SUMIF('Human Grading'!$A$47:$A$53, $A6, 'Human Grading'!$C$47:$C$53) -> 0 | E6: =COUNTIFS('Human Grading'!$A$2:$A$46, $A6, 'Human Grading'!$C$2:$C$46,0) -> 0 | F6: =IFERROR(C6 / (C6 + D6), "Not Available") -> 1 | G6: =IFERROR(C6 / B6, "Not Available") -> 1 | H6: =IFERROR(2*((F6*G6)/(F6+G6)),"Not Available") -> 1
A7: Region | B7: =COUNTIF('Chess Clock'!$A$2:$A$44, A7) -> 2 | C7: =SUMIF('Human Grading'!$A$2:$A$46, $A7, 'Human Grading'!$C$2:$C$46) -> 1 | D7: =SUMIF('Human Grading'!$A$47:$A$53, $A7, 'Human Grading'!$C$47:$C$53) -> 0 | E7: =COUNTIFS('Human Grading'!$A$2:$A$46, $A7, 'Human Grading'!$C$2:$C$46,0) -> 1 | F7: =IFERROR(C7 / (C7 + D8), "Not Available") -> 1 | G7: =IFERROR(C7 / B7, "Not Available") -> 0.5 | H7: =IFERROR(2*((F7*G7)/(F7+G7)),"Not Available") -> 0.66666667
A8: History State | B8: =COUNTIF('Chess Clock'!$A$2:$A$46, A8) -> 1 | C8: =SUMIF('Human Grading'!$A$2:$A$46, $A8, 'Human Grading'!$C$2:$C$46) -> 1 | D8: =SUMIF('Human Grading'!$A$47:$A$53, $A8, 'Human Grading'!$C$47:$C$53) -> 0 | E8: =COUNTIFS('Human Grading'!$A$2:$A$46, $A8, 'Human Grading'!$C$2:$C$46,0) -> 0 | F8: =IFERROR(C8 / (C8 +#REF!), "Not Available") -> Not Available | G8: =IFERROR(C8 / B8, "Not Available") -> 1 | H8: =IFERROR(2*((F8*G8)/(F8+G8)),"Not Available") -> Not Available
A9: Guard | B9: =COUNTIF('Chess Clock'!$A$2:$A$44, A9) -> 4 | C9: =SUMIF('Human Grading'!$A$2:$A$46, $A9, 'Human Grading'!$C$2:$C$46) -> 4 | D9: =SUMIF('Human Grading'!$A$47:$A$53, $A9, 'Human Grading'!$C$47:$C$53) -> 0 | E9: =COUNTIFS('Human Grading'!$A$2:$A$46, $A9, 'Human Grading'!$C$2:$C$46,0) -> 0 | F9: =IFERROR(C9 / (C9 + D9), "Not Available") -> 1 | G9: =IFERROR(C9 / B9, "Not Available") -> 1 | H9: =IFERROR(2*((F9*G9)/(F9+G9)),"Not Available") -> 1
A10: Overall Score | B10: =SUM(B3:B9) -> 45 | C10: =SUM(C3:C9) -> 40.5 | D10: =SUM(D3:D9) -> 0 | E10: =SUM(E3:E9) -> 4 | F10: =IFERROR(C10 / (C10 + D10), "Not Available") -> 1 | G10: =IFERROR(C10 / B10, "Not Available") -> 0.9 | H10: =IFERROR(2*((F10*G10)/(F10+G10)),"Not Available") -> 0.94736842
A12: Claude Grader LLM
A13: Type | B13: Ground Truth Count | C13: True Positive | D13: False Positive | E13: False Negative | F13: Precision | G13: Recall | H13: F1 Score
A14: Composite state | B14: =COUNTIF('Chess Clock'!$A$2:$A$46, A14) -> 3 | C14: =SUMIF('LLM Grading'!$A$2:$A$46, $A14, 'LLM Grading'!$C$2:$C$46) -> 2.5 | D14: =SUMIF('LLM Grading'!$A$47:$A$53, $A3, 'LLM Grading'!$C$47:$C$53) -> 0 | E14: =COUNTIFS('LLM Grading'!$A$2:$A$46, $A3, 'LLM Grading'!$C$2:$C$46,0) -> 0 | F14: =IFERROR(C14 / (C14 + D14), "Not Available") -> 1 | G14: =IFERROR(C14 / B14, "Not Available") -> 0.83333333 | H14: =IFERROR(2*((F14*G14)/(F14+G14)),"Not Available") -> 0.90909091
A15: State | B15: =COUNTIF('Chess Clock'!$A$2:$A$46, A15) -> 13 | C15: =SUMIF('LLM Grading'!$A$2:$A$46, $A15, 'LLM Grading'!$C$2:$C$46) -> 8 | D15: =SUMIF('LLM Grading'!$A$47:$A$53, $A4, 'LLM Grading'!$C$47:$C$53) -> 2 | E15: =COUNTIFS('LLM Grading'!$A$2:$A$46, $A4, 'LLM Grading'!$C$2:$C$46,0) -> 4 | F15: =IFERROR(C15 / (C15 + D15), "Not Available") -> 0.8 | G15: =IFERROR(C15 / B15, "Not Available") -> 0.61538462 | H15: =IFERROR(2*((F15*G15)/(F15+G15)),"Not Available") -> 0.69565217
A16: Transition | B16: =COUNTIF('Chess Clock'!$A$2:$A$46, A16) -> 14 | C16: =SUMIF('LLM Grading'!$A$2:$A$46, $A16, 'LLM Grading'!$C$2:$C$46) -> 8 | D16: =SUMIF('LLM Grading'!$A$47:$A$53, $A5, 'LLM Grading'!$C$47:$C$53) -> 0 | E16: =COUNTIFS('LLM Grading'!$A$2:$A$46, $A5, 'LLM Grading'!$C$2:$C$46,0) -> 5 | F16: =IFERROR(C16 / (C16 + D16), "Not Available") -> 1 | G16: =IFERROR(C16 / B16, "Not Available") -> 0.57142857 | H16: =IFERROR(2*((F16*G16)/(F16+G16)),"Not Available") -> 0.72727273
A17: Action | B17: =COUNTIF('Chess Clock'!$A$2:$A$46, A17) -> 8 | C17: =SUMIF('LLM Grading'!$A$2:$A$46, $A17, 'LLM Grading'!$C$2:$C$46) -> 8 | D17: =SUMIF('LLM Grading'!$A$47:$A$53, $A6, 'LLM Grading'!$C$47:$C$53) -> 1 | E17: =COUNTIFS('LLM Grading'!$A$2:$A$46, $A6, 'LLM Grading'!$C$2:$C$46,0) -> 0 | F17: =IFERROR(C17 / (C17 + D17), "Not Available") -> 0.88888889 | G17: =IFERROR(C17 / B17, "Not Available") -> 1 | H17: =IFERROR(2*((F17*G17)/(F17+G17)),"Not Available") -> 0.94117647
A18: Region | B18: =COUNTIF('Chess Clock'!$A$2:$A$46, A18) -> 2 | C18: =SUMIF('LLM Grading'!$A$2:$A$46, $A18, 'LLM Grading'!$C$2:$C$46) -> 0 | D18: =SUMIF('LLM Grading'!$A$47:$A$53, $A7, 'LLM Grading'!$C$47:$C$53) -> 0 | E18: =COUNTIFS('LLM Grading'!$A$2:$A$46, $A7, 'LLM Grading'!$C$2:$C$46,0) -> 2 | F18: =IFERROR(C18 / (C18 + D18), "Not Available") -> Not Available | G18: =IFERROR(C18 / B18, "Not Available") -> 0 | H18: =IFERROR(2*((F18*G18)/(F18+G18)),"Not Available") -> Not Available
A19: History State | B19: =COUNTIF('Chess Clock'!$A$2:$A$46, A19) -> 1 | C19: =SUMIF('LLM Grading'!$A$2:$A$46, $A19, 'LLM Grading'!$C$2:$C$46) -> 1 | D19: =SUMIF('LLM Grading'!$A$47:$A$53, $A8, 'LLM Grading'!$C$47:$C$53) -> 0 | E19: =COUNTIFS('LLM Grading'!$A$2:$A$46, $A8, 'LLM Grading'!$C$2:$C$46,0) -> 0 | F19: =IFERROR(C19 / (C19 + D19), "Not Available") -> 1 | G19: =IFERROR(C19 / B19, "Not Available") -> 1 | H19: =IFERROR(2*((F19*G19)/(F19+G19)),"Not Available") -> 1
A20: Guard | B20: =COUNTIF('Chess Clock'!$A$2:$A$46, A20) -> 4 | C20: =SUMIF('LLM Grading'!$A$2:$A$46, $A20, 'LLM Grading'!$C$2:$C$46) -> 2 | D20: =SUMIF('LLM Grading'!$A$47:$A$53, $A9, 'LLM Grading'!$C$47:$C$53) -> 0 | E20: =COUNTIFS('LLM Grading'!$A$2:$A$46, $A9, 'LLM Grading'!$C$2:$C$46,0) -> 2 | F20: =IFERROR(C20 / (C20 + D20), "Not Available") -> 1 | G20: =IFERROR(C20 / B20, "Not Available") -> 0.5 | H20: =IFERROR(2*((F20*G20)/(F20+G20)),"Not Available") -> 0.66666667
A21: Overall Score | B21: =SUM(B14:B20) -> 45 | C21: =SUM(C14:C20) -> 29.5 | D21: =SUM(D14:D20) -> 3 | E21: =SUM(E14:E20) -> 13 | F21: =IFERROR(C21 / (C21 + D21), "Not Available") -> 0.90769231 | G21: =IFERROR(C21 / B21, "Not Available") -> 0.65555556 | H21: =IFERROR(2*((F21*G21)/(F21+G21)),"Not Available") -> 0.76129032

Sheet Inter-rater
A1: Type | B1: Element | C1: Human | D1: LLM | F1: Confusion Matrix | L1: Cohen's Kappa
A2: ='Human Grading'!A2 -> State | B2: ='Human Grading'!B2 -> initial state (off) | C2: ='Human Grading'!C2 -> 1 | D2: ='LLM Grading'!C2 -> 1 | F2: Global | G2: 0 | H2: 0.5 | I2: 1 | J2: Row Totals | L2: Metric | M2: Value | N2: Note
A3: ='Human Grading'!A3 -> Transition | B3: ='Human Grading'!B3 -> initial state (off) => off | C3: ='Human Grading'!C3 -> 1 | D3: ='LLM Grading'!C3 -> 1 | F3: 0 | G3: =COUNTIFS($C$2:$C$90, $F3, $D$2:$D$90, G$2) -> 6 | H3: =COUNTIFS($C$2:$C$46, $F3, $D$2:$D$46, H$2) -> 3 | I3: =COUNTIFS($C$2:$C$46, $F3, $D$2:$D$46, I$2)+MAX(D47-C47,0)+MAX(D48-C48,0)+MAX(D49-C49,0)+MAX(D50-C50,0)+MAX(D51-C51,0)+MAX(D52-C52,0)+MAX(D53-C53,0) -> 3 | J3: =SUM(G3:I3) -> 12 | L3: Observed Agreement (Po) | M3: =(G3+H4+I5)/COUNTA($C$2:$C$100) -> 0.65384615 | N3: This sums the diagonal of your matrix divided by total rows.
A4: ='Human Grading'!A4 -> State | B4: ='Human Grading'!B4 -> Off | C4: ='Human Grading'!C4 -> 1 | D4: ='LLM Grading'!C4 -> 1 | F4: 0.5 | G4: =COUNTIFS($C$2:$C$46, $F4, $D$2:$D$46, G$2) -> 0 | H4: =COUNTIFS($C$2:$C$46, $F4, $D$2:$D$46, H$2) -> 1 | I4: =COUNTIFS($C$2:$C$46, $F4, $D$2:$D$46, I$2) -> 0 | J4: =SUM(G4:I4) -> 1 | L4: Expected Agreement (Pe) | M4: {=SUMPRODUCT(J3:J5/COUNTA($C$2:$C$100), TRANSPOSE(G6:I6)/COUNTA($C$2:$C$100))} -> 0.52551775 | N4: This computes the sum of row proportion times column proportion.
A5: ='Human Grading'!A5 -> Transition | B5: ='Human Grading'!B5 -> off => on | C5: ='Human Grading'!C5 -> 1 | D5: ='LLM Grading'!C5 -> 1 | F5: 1 | G5: =COUNTIFS($C$2:$C$46, $F5, $D$2:$D$46, G$2)+MAX(C47-D47,0)+MAX(C48-D48,0)+MAX(C49-D49,0)+MAX(C50-D50,0)+MAX(C51-D51,0)+MAX(C52-D52,0)+MAX(C53-D53,0) -> 12 | H5: =COUNTIFS($C$2:$C$46, $F5, $D$2:$D$46, H$2) -> 1 | I5: =COUNTIFS($C$2:$C$46, $F5, $D$2:$D$46, I$2)+ SUM(MIN(C47,D47), MIN(C48,D48), MIN(C49,D49), MIN(C50,D50), MIN(C51,D51), MIN(C52,D52), MIN(C53,D53)) -> 27 | J5: =SUM(G5:I5) -> 40 | L5: Cohen's Kappa | M5: =(M3-M4)/(1-M4) -> 0.27045986 | N5: (Po - Pe) / (1 - Pe)
A6: ='Human Grading'!A6 -> Composite State | B6: ='Human Grading'!B6 -> On | C6: ='Human Grading'!C6 -> 1 | D6: ='LLM Grading'!C6 -> 1 | F6: Column Totals | G6: =SUM(G3:G5) -> 18 | H6: =SUM(H3:H5) -> 5 | I6: =SUM(I3:I5) -> 30
A7: ='Human Grading'!A7 -> State | B7: ='Human Grading'!B7 -> initial state (on) | C7: ='Human Grading'!C7 -> 1 | D7: ='LLM Grading'!C7 -> 1
A8: ='Human Grading'!A8 -> Composite State | B8: ='Human Grading'!B8 -> GameSetup | C8: ='Human Grading'!C8 -> 1 | D8: ='LLM Grading'!C8 -> 0.5 | F8: Confusion Matrix (State) | L8: Cohen's Kappa (State)
A9: ='Human Grading'!A9 -> Region | B9: ='Human Grading'!B9 -> GameSetup Region 1 | C9: ='Human Grading'!C9 -> 1 | D9: ='LLM Grading'!C9 -> 0 | F9: State | G9: 0 | H9: 0.5 | I9: 1 | J9: Row Totals | L9: Metric | M9: Value | N9: Note
A10: ='Human Grading'!A10 -> State | B10: ='Human Grading'!B10 -> Initial state (region 1) | C10: ='Human Grading'!C10 -> 1 | D10: ='LLM Grading'!C10 -> 0 | F10: 0 | G10: =COUNTIFS($A$2:$A$90,$F$9,$C$2:$C$90,$F10,$D$2:$D$90,G$9) -> 0 | H10: =COUNTIFS($A$2:$A$90,$F$9,$C$2:$C$90,$F10,$D$2:$D$90,H$9) -> 1 | I10: =COUNTIFS($A$2:$A$46,$F$9,$C$2:$C$46,$F10,$D$2:$D$46,I$9)+MAX(D47-C47,0) -> 2 | J10: =SUM(G10:I10) -> 3 | L10: Observed Agreement (Po) | M10: =(G10+H11+I12)/COUNTIF($A$2:$A$100,F9) -> 0.42857143 | N10: This sums the diagonal of your matrix divided by total rows.
A11: ='Human Grading'!A11 -> State | B11: ='Human Grading'!B11 -> TimingSelection | C11: ='Human Grading'!C11 -> 1 | D11: ='LLM Grading'!C11 -> 1 | F11: 0.5 | G11: =COUNTIFS($A$2:$A$90,$F$9,$C$2:$C$90,$F11,$D$2:$D$90,G$9) -> 0 | H11: =COUNTIFS($A$2:$A$90,$F$9,$C$2:$C$90,$F11,$D$2:$D$90,H$9) -> 1 | I11: =COUNTIFS($A$2:$A$90,$F$9,$C$2:$C$90,$F11,$D$2:$D$90,I$9) -> 0 | J11: =SUM(G11:I11) -> 1 | L11: Expected Agreement (Pe) | M11: {=SUMPRODUCT(J10:J12/COUNTIF($A$2:$A$100,F9), TRANSPOSE(G13:I13)/COUNTIF($A$2:$A$100,F9))} -> 0.39285714 | N11: This computes the sum of row proportion times column proportion.
A12: ='Human Grading'!A12 -> Action | B12: ='Human Grading'!B12 -> incrTimingProgram() | C12: ='Human Grading'!C12 -> 1 | D12: ='LLM Grading'!C12 -> 1 | F12: 1 | G12: =COUNTIFS($A$2:$A$46,$F$9,$C$2:$C$46,$F12,$D$2:$D$46,G$9)+MAX(C47-D47,0) -> 4 | H12: =COUNTIFS($A$2:$A$90,$F$9,$C$2:$C$90,$F12,$D$2:$D$90,H$9) -> 0 | I12: =COUNTIFS($A$2:$A$46,$F$9,$C$2:$C$46,$F12,$D$2:$D$46,I$9)+MIN(C47-D47) -> 5 | J12: =SUM(G12:I12) -> 9 | L12: Cohen's Kappa | M12: =(M10-M11)/(1-M11) -> 0.058823529 | N12: (Po - Pe) / (1 - Pe)
A13: ='Human Grading'!A13 -> Action | B13: ='Human Grading'!B13 -> decrTimingProgram() | C13: ='Human Grading'!C13 -> 1 | D13: ='LLM Grading'!C13 -> 1 | F13: Column Totals | G13: =SUM(G10:G12) -> 4 | H13: =SUM(H10:H12) -> 2 | I13: =SUM(I10:I12) -> 7
A14: ='Human Grading'!A14 -> Transition | B14: ='Human Grading'!B14 -> timing selection => timing selection | C14: ='Human Grading'!C14 -> 1 | D14: ='LLM Grading'!C14 -> 1
A15: ='Human Grading'!A15 -> Transition | B15: ='Human Grading'!B15 -> game setup => ready to start | C15: ='Human Grading'!C15 -> 0 | D15: ='LLM Grading'!C15 -> 0.5 | F15: Confusion Matrix (Transition) | L15: Cohen's Kappa (Transition)
A16: ='Human Grading'!A16 -> Region | B16: ='Human Grading'!B16 -> GameSetup Region 2 | C16: ='Human Grading'!C16 -> 0 | D16: ='LLM Grading'!C16 -> 0 | F16: Transition | G16: 0 | H16: 0.5 | I16: 1 | J16: Row Totals | L16: Metric | M16: Value | N16: Note
A17: ='Human Grading'!A17 -> State | B17: ='Human Grading'!B17 -> Initial state (region 2) | C17: ='Human Grading'!C17 -> 1 | D17: ='LLM Grading'!C17 -> 0 | F17: 0 | G17: =COUNTIFS($A$2:$A$90,$F$16,$C$2:$C$90,$F17,$D$2:$D$90,G$16) -> 1 | H17: =COUNTIFS($A$2:$A$90,$F$16,$C$2:$C$90,$F17,$D$2:$D$90,H$16) -> 2 | I17: =COUNTIFS($A$2:$A$46,$F$16,$C$2:$C$46,$F17,$D$2:$D$46,I$16) + MAX(D48-C48,0) -> 0 | J17: =SUM(G17:I17) -> 3 | L17: Observed Agreement (Po) | M17: =(G17+H18+I19)/COUNTIF($A$2:$A$100,F16) -> 0.53333333 | N17: This sums the diagonal of your matrix divided by total rows.
A18: ='Human Grading'!A18 -> State | B18: ='Human Grading'!B18 -> WhiteKingOnLeft | C18: ='Human Grading'!C18 -> 1 | D18: ='LLM Grading'!C18 -> 0 | F18: 0.5 | G18: =COUNTIFS($A$2:$A$90,$F$16,$C$2:$C$90,$F18,$D$2:$D$90,G$16) -> 0 | H18: =COUNTIFS($A$2:$A$90,$F$16,$C$2:$C$90,$F18,$D$2:$D$90,H$16) -> 0 | I18: =COUNTIFS($A$2:$A$90,$F$16,$C$2:$C$90,$F18,$D$2:$D$90,I$16) -> 0 | J18: =SUM(G18:I18) -> 0 | L18: Expected Agreement (Pe) | M18: {=SUMPRODUCT(J17:J19/COUNTIF($A$2:$A$100,F16), TRANSPOSE(G20:I20)/COUNTIF($A$2:$A$100,F16))} -> 0.45333333 | N18: This computes the sum of row proportion times column proportion.
A19: ='Human Grading'!A19 -> State | B19: ='Human Grading'!B19 -> WhiteKingOnRight | C19: ='Human Grading'!C19 -> 1 | D19: ='LLM Grading'!C19 -> 0 | F19: 1 | G19: =COUNTIFS($A$2:$A$46,$F$16,$C$2:$C$46,$F19,$D$2:$D$46,G$16)+MAX(C48-D48,0) -> 5 | H19: =COUNTIFS($A$2:$A$90,$F$16,$C$2:$C$90,$F19,$D$2:$D$90,H$16) -> 0 | I19: =COUNTIFS($A$2:$A$46,$F$16,$C$2:$C$46,$F19,$D$2:$D$46,I$16) + MIN(C48,D48) -> 7 | J19: =SUM(G19:I19) -> 12 | L19: Cohen's Kappa | M19: =(M17-M18)/(1-M18) -> 0.14634146 | N19: (Po - Pe) / (1 - Pe)
A20: ='Human Grading'!A20 -> Transition | B20: ='Human Grading'!B20 -> initial state => white king on left | C20: ='Human Grading'!C20 -> 1 | D20: ='LLM Grading'!C20 -> 0 | F20: Column Totals | G20: =SUM(G17:G19) -> 6 | H20: =SUM(H17:H19) -> 2 | I20: =SUM(I17:I19) -> 7
A21: ='Human Grading'!A21 -> Transition | B21: ='Human Grading'!B21 -> white king on left => white king on right | C21: ='Human Grading'!C21 -> 1 | D21: ='LLM Grading'!C21 -> 0
A22: ='Human Grading'!A22 -> Transition | B22: ='Human Grading'!B22 -> white king on right => white king on left | C22: ='Human Grading'!C22 -> 1 | D22: ='LLM Grading'!C22 -> 0 | F22: Confusion Matrix (Composite State) | L22: Cohen's Kappa (Composite State)
A23: ='Human Grading'!A23 -> State | B23: ='Human Grading'!B23 -> ReadyToStart | C23: ='Human Grading'!C23 -> 0 | D23: ='LLM Grading'!C23 -> 0.5 | F23: Composite State | G23: 0 | H23: 0.5 | I23: 1 | J23: Row Totals | L23: Metric | M23: Value | N23: Note
A24: ='Human Grading'!A24 -> Transition | B24: ='Human Grading'!B24 -> ready to start => game running | C24: ='Human Grading'!C24 -> 1 | D24: ='LLM Grading'!C24 -> 1 | F24: 0 | G24: =COUNTIFS($A$2:$A$90,$F$23,$C$2:$C$90,$F24,$D$2:$D$90,G$23) -> 1 | H24: =COUNTIFS($A$2:$A$90,$F$23,$C$2:$C$90,$F24,$D$2:$D$90,H$23) -> 0 | I24: =COUNTIFS($A$2:$A$46,$F$23,$C$2:$C$46,$F24,$D$2:$D$46,I$23) + MAX(D51-C51,0) -> 0 | J24: =SUM(G24:I24) -> 1 | L24: Observed Agreement (Po) | M24: =(G24+H25+I26)/COUNTIF($A$2:$A$100,F23) -> 0.75 | N24: This sums the diagonal of your matrix divided by total rows.
A25: ='Human Grading'!A25 -> Composite State | B25: ='Human Grading'!B25 -> GameRunning | C25: ='Human Grading'!C25 -> 1 | D25: ='LLM Grading'!C25 -> 1 | F25: 0.5 | G25: =COUNTIFS($A$2:$A$90,$F$23,$C$2:$C$90,$F25,$D$2:$D$90,G$23) -> 0 | H25: =COUNTIFS($A$2:$A$90,$F$23,$C$2:$C$90,$F25,$D$2:$D$90,H$23) -> 0 | I25: =COUNTIFS($A$2:$A$90,$F$23,$C$2:$C$90,$F25,$D$2:$D$90,I$23) -> 0 | J25: =SUM(G25:I25) -> 0 | L25: Expected Agreement (Pe) | M25: {=SUMPRODUCT(J24:J26/COUNTIF($A$2:$A$100,F23), TRANSPOSE(G27:I27)/COUNTIF($A$2:$A$100,F23))} -> 0.4375 | N25: This computes the sum of row proportion times column proportion.
A26: ='Human Grading'!A26 -> History State | B26: ='Human Grading'!B26 -> H | C26: ='Human Grading'!C26 -> 1 | D26: ='LLM Grading'!C26 -> 1 | F26: 1 | G26: =COUNTIFS($A$2:$A$46,$F$23,$C$2:$C$46,$F26,$D$2:$D$46,G$23) + MAX(C51-D51,0) -> 0 | H26: =COUNTIFS($A$2:$A$90,$F$23,$C$2:$C$90,$F26,$D$2:$D$90,H$23) -> 1 | I26: =COUNTIFS($A$2:$A$46,$F$23,$C$2:$C$46,$F26,$D$2:$D$46,I$23) + MIN(C51,D51) -> 2 | J26: =SUM(G26:I26) -> 3 | L26: Cohen's Kappa | M26: =(M24-M25)/(1-M25) -> 0.55555556 | N26: (Po - Pe) / (1 - Pe)
A27: ='Human Grading'!A27 -> State | B27: ='Human Grading'!B27 -> WhiteClockRunning | C27: ='Human Grading'!C27 -> 1 | D27: ='LLM Grading'!C27 -> 1 | F27: Column Totals | G27: =SUM(G24:G26) -> 1 | H27: =SUM(H24:H26) -> 1 | I27: =SUM(I24:I26) -> 2
A28: ='Human Grading'!A28 -> Action | B28: ='Human Grading'!B28 -> startTimer(wc) | C28: ='Human Grading'!C28 -> 1 | D28: ='LLM Grading'!C28 -> 1
A29: ='Human Grading'!A29 -> Action | B29: ='Human Grading'!B29 -> stopTimer(wc) | C29: ='Human Grading'!C29 -> 1 | D29: ='LLM Grading'!C29 -> 1 | F29: Confusion Matrix (Guard) | L29: Cohen's Kappa (Guard)
A30: ='Human Grading'!A30 -> Guard | B30: ='Human Grading'!B30 -> [wc > 0] | C30: ='Human Grading'!C30 -> 1 | D30: ='LLM Grading'!C30 -> 0 | F30: Guard | G30: 0 | H30: 0.5 | I30: 1 | J30: Row Totals | L30: Metric | M30: Value | N30: Note
A31: ='Human Grading'!A31 -> Action | B31: ='Human Grading'!B31 -> decrTimer(wc) | C31: ='Human Grading'!C31 -> 1 | D31: ='LLM Grading'!C31 -> 1 | F31: 0 | G31: =COUNTIFS($A$2:$A$90,$F$30,$C$2:$C$90,$F31,$D$2:$D$90,G$30) -> 1 | H31: =COUNTIFS($A$2:$A$90,$F$30,$C$2:$C$90,$F31,$D$2:$D$90,H$30) -> 0 | I31: =COUNTIFS($A$2:$A$46,$F$30,$C$2:$C$46,$F31,$D$2:$D$46,I$30) + MAX(D49-C49,0) -> 0 | J31: =SUM(G31:I31) -> 1 | L31: Observed Agreement (Po) | M31: =(G31+H32+I33)/COUNTIF($A$2:$A$100,F30) -> 0.6 | N31: This sums the diagonal of your matrix divided by total rows.
A32: ='Human Grading'!A32 -> Transition | B32: ='Human Grading'!B32 -> white clock running => white clock running | C32: ='Human Grading'!C32 -> 1 | D32: ='LLM Grading'!C32 -> 0 | F32: 0.5 | G32: =COUNTIFS($A$2:$A$90,$F$30,$C$2:$C$90,$F32,$D$2:$D$90,G$30) -> 0 | H32: =COUNTIFS($A$2:$A$90,$F$30,$C$2:$C$90,$F32,$D$2:$D$90,H$30) -> 0 | I32: =COUNTIFS($A$2:$A$90,$F$30,$C$2:$C$90,$F32,$D$2:$D$90,I$30) -> 0 | J32: =SUM(G32:I32) -> 0 | L32: Expected Agreement (Pe) | M32: {=SUMPRODUCT(J31:J33/COUNTIF($A$2:$A$100,F30), TRANSPOSE(G34:I34)/COUNTIF($A$2:$A$100,F30))} -> 0.44 | N32: This computes the sum of row proportion times column proportion.
A33: ='Human Grading'!A33 -> State | B33: ='Human Grading'!B33 -> BlackClockRunning | C33: ='Human Grading'!C33 -> 1 | D33: ='LLM Grading'!C33 -> 1 | F33: 1 | G33: =COUNTIFS($A$2:$A$46,$F$30,$C$2:$C$46,$F33,$D$2:$D$46,G$30) + MAX(C49-D49,0) -> 2 | H33: =COUNTIFS($A$2:$A$90,$F$30,$C$2:$C$90,$F33,$D$2:$D$90,H$30) -> 0 | I33: =COUNTIFS($A$2:$A$46,$F$30,$C$2:$C$46,$F33,$D$2:$D$46,I$30) + MIN(C49,D49) -> 2 | J33: =SUM(G33:I33) -> 4 | L33: Cohen's Kappa | M33: =(M31-M32)/(1-M32) -> 0.28571429 | N33: (Po - Pe) / (1 - Pe)
A34: ='Human Grading'!A34 -> Action | B34: ='Human Grading'!B34 -> startTimer(bc) | C34: ='Human Grading'!C34 -> 1 | D34: ='LLM Grading'!C34 -> 1 | F34: Column Totals | G34: =SUM(G31:G33) -> 3 | H34: =SUM(H31:H33) -> 0 | I34: =SUM(I31:I33) -> 2
A35: ='Human Grading'!A35 -> Action | B35: ='Human Grading'!B35 -> stopTimer(bc) | C35: ='Human Grading'!C35 -> 1 | D35: ='LLM Grading'!C35 -> 1
A36: ='Human Grading'!A36 -> Guard | B36: ='Human Grading'!B36 -> [bc > 0] | C36: ='Human Grading'!C36 -> 1 | D36: ='LLM Grading'!C36 -> 0 | F36: Confusion Matrix (Action) | L36: Cohen's Kappa (Action)
A37: ='Human Grading'!A37 -> Action | B37: ='Human Grading'!B37 -> decrTimer(bc) | C37: ='Human Grading'!C37 -> 1 | D37: ='LLM Grading'!C37 -> 1 | F37: Action | G37: 0 | H37: 0.5 | I37: 1 | J37: Row Totals | L37: Metric | M37: Value | N37: Note
A38: ='Human Grading'!A38 -> Transition | B38: ='Human Grading'!B38 -> balck clock running => black clock running | C38: ='Human Grading'!C38 -> 1 | D38: ='LLM Grading'!C38 -> 0 | F38: 0 | G38: =COUNTIFS($A$2:$A$90,$F$37,$C$2:$C$90,$F38,$D$2:$D$90,G$37) -> 0 | H38: =COUNTIFS($A$2:$A$90,$F$37,$C$2:$C$90,$F38,$D$2:$D$90,H$37) -> 0 | I38: =COUNTIFS($A$2:$A$46,$F$37,$C$2:$C$46,$F38,$D$2:$D$46,I$37)+MAX(D50-C50,0) -> 1 | J38: =SUM(G38:I38) -> 1 | L38: Observed Agreement (Po) | M38: =(G38+H39+I40)/COUNTIF($A$2:$A$100,F37) -> 0.88888889 | N38: This sums the diagonal of your matrix divided by total rows.
A39: ='Human Grading'!A39 -> Transition | B39: ='Human Grading'!B39 -> game running => game paused | C39: ='Human Grading'!C39 -> 1 | D39: ='LLM Grading'!C39 -> 1 | F39: 0.5 | G39: =COUNTIFS($A$2:$A$90,$F$37,$C$2:$C$90,$F39,$D$2:$D$90,G$37) -> 0 | H39: =COUNTIFS($A$2:$A$90,$F$37,$C$2:$C$90,$F39,$D$2:$D$90,H$37) -> 0 | I39: =COUNTIFS($A$2:$A$90,$F$37,$C$2:$C$90,$F39,$D$2:$D$90,I$37) -> 0 | J39: =SUM(G39:I39) -> 0 | L39: Expected Agreement (Pe) | M39: {=SUMPRODUCT(J38:J40/COUNTIF($A$2:$A$100,F37), TRANSPOSE(G41:I41)/COUNTIF($A$2:$A$100,F37))} -> 0.88888889 | N39: This computes the sum of row proportion times column proportion.
A40: ='Human Grading'!A40 -> Transition | B40: ='Human Grading'!B40 -> game running => game finished | C40: ='Human Grading'!C40 -> 0 | D40: ='LLM Grading'!C40 -> 0.5 | F40: 1 | G40: =COUNTIFS($A$2:$A$46,$F$37,$C$2:$C$46,$F40,$D$2:$D$46,G$37)+MAX(C50-D50,0) -> 0 | H40: =COUNTIFS($A$2:$A$90,$F$37,$C$2:$C$90,$F40,$D$2:$D$90,H$37) -> 0 | I40: =COUNTIFS($A$2:$A$46,$F$37,$C$2:$C$46,$F40,$D$2:$D$46,I$37) + MIN(C50,D50) -> 8 | J40: =SUM(G40:I40) -> 8 | L40: Cohen's Kappa | M40: =(M38-M39)/(1-M39) -> 0 | N40: (Po - Pe) / (1 - Pe)
...

Sheet Weighted Cohens Kappa
A1: Type | B1: Element | C1: Human | D1: LLM | F1: Confusion Matrix | L1: Weight Matrix
A2: ='Human Grading'!A2 -> State | B2: ='Human Grading'!B2 -> initial state (off) | C2: ='Human Grading'!C2 -> 1 | D2: ='Human Grading'!C2 -> 1 | F2: Global | G2: 0 | H2: 0.5 | I2: 1 | J2: Row Totals | L2: Global | M2: 0 | N2: 0.5 | O2: 1 | Q2: Global | R2: 0 | S2: 0.5 | T2: 1 | V2: ="Metrics" & " " & F2 -> Metrics Global | W2: Value | X2: Note
A3: ='Human Grading'!A3 -> Transition | B3: ='Human Grading'!B3 -> initial state (off) => off | C3: ='Human Grading'!C3 -> 1 | D3: ='Human Grading'!C3 -> 1 | F3: 0 | G3: =COUNTIFS($C$2:$C$90, $F3, $D$2:$D$90, G$2) -> 11 | H3: =COUNTIFS($C$2:$C$46, $F3, $D$2:$D$46, H$2) -> 0 | I3: =COUNTIFS($C$2:$C$46, $F3, $D$2:$D$46, I$2)+MAX(D47-C47,0)+MAX(D48-C48,0)+MAX(D49-C49,0)+MAX(D50-C50,0)+MAX(D51-C51,0)+MAX(D52-C52,0)+MAX(D53-C53,0) -> 0 | J3: =SUM(G3:I3) -> 11 | L3: 0 | M3: =ABS(G$2-$F3)/1 -> 0 | N3: =ABS(H$2-$F3)/1 -> 0.5 | O3: =ABS(I$2-$F3)/1 -> 1 | Q3: 0 | R3: =($J3/$J$6) * (G$6/$J$6) -> 0.044748521 | S3: =($J3/$J$6) * (H$6/$J$6) -> 0.0040680473 | T3: =($J3/$J$6) * (I$6/$J$6) -> 0.16272189 | V3: Observed Weighted Disagreement (D_obs) | W3: =SUMPRODUCT(G3:I5, M3:O5) /$J$6 -> 0 | X3: Sum of (confusion-matrix counts × weights) divided by total items.
A4: ='Human Grading'!A4 -> State | B4: ='Human Grading'!B4 -> Off | C4: ='Human Grading'!C4 -> 1 | D4: ='Human Grading'!C4 -> 1 | F4: 0.5 | G4: =COUNTIFS($C$2:$C$46, $F4, $D$2:$D$46, G$2) -> 0 | H4: =COUNTIFS($C$2:$C$46, $F4, $D$2:$D$46, H$2) -> 1 | I4: =COUNTIFS($C$2:$C$46, $F4, $D$2:$D$46, I$2) -> 0 | J4: =SUM(G4:I4) -> 1 | L4: 0.5 | M4: =ABS(G$2-$F4)/1 -> 0.5 | N4: =ABS(H$2-$F4)/3 -> 0 | O4: =ABS(I$2-$F4)/1 -> 0.5 | Q4: 0.5 | R4: =($J4/$J$6) * (G$6/$J$6) -> 0.0040680473 | S4: =($J4/$J$6) * (H$6/$J$6) -> 0.00036982249 | T4: =($J4/$J$6) * (I$6/$J$6) -> 0.014792899 | V4: Expected Weighted Disagreement (D_exp) | W4: =SUMPRODUCT(R3:T5, M3:O5) -> 0.34430473 | X4: Sum of (expected cell proportions × weights) under chance agreement.
A5: ='Human Grading'!A5 -> Transition | B5: ='Human Grading'!B5 -> off => on | C5: ='Human Grading'!C5 -> 1 | D5: ='Human Grading'!C5 -> 1 | F5: 1 | G5: =COUNTIFS($C$2:$C$46, $F5, $D$2:$D$46, G$2)+MAX(C47-D47,0)+MAX(C48-D48,0)+MAX(C49-D49,0)+MAX(C50-D50,0)+MAX(C51-D51,0)+MAX(C52-D52,0)+MAX(C53-D53,0) -> 0 | H5: =COUNTIFS($C$2:$C$46, $F5, $D$2:$D$46, H$2) -> 0 | I5: =COUNTIFS($C$2:$C$46, $F5, $D$2:$D$46, I$2)+ SUM(MIN(C47,D47), MIN(C48,D48), MIN(C49,D49), MIN(C50,D50), MIN(C51,D51), MIN(C52,D52), MIN(C53,D53)) -> 40 | J5: =SUM(G5:I5) -> 40 | L5: 1 | M5: =ABS(G$2-$F5)/1 -> 1 | N5: =ABS(H$2-$F5)/1 -> 0.5 | O5: =ABS(I$2-$F5)/1 -> 0 | Q5: 1 | R5: =($J5/$J$6) * (G$6/$J$6) -> 0.16272189 | S5: =($J5/$J$6) * (H$6/$J$6) -> 0.014792899 | T5: =($J5/$J$6) * (I$6/$J$6) -> 0.59171598 | V5: Cohen's Kappa | W5: =1-W3/W4 -> 1 | X5: 1 - (D_obs / D_exp)
A6: ='Human Grading'!A6 -> Composite State | B6: ='Human Grading'!B6 -> On | C6: ='Human Grading'!C6 -> 1 | D6: ='Human Grading'!C6 -> 1 | F6: Column Totals | G6: =SUM(G3:G5) -> 11 | H6: =SUM(H3:H5) -> 1 | I6: =SUM(I3:I5) -> 40 | J6: =SUM(G3:I5) -> 52
A7: ='Human Grading'!A7 -> State | B7: ='Human Grading'!B7 -> initial state (on) | C7: ='Human Grading'!C7 -> 1 | D7: ='Human Grading'!C7 -> 1
A8: ='Human Grading'!A8 -> Composite State | B8: ='Human Grading'!B8 -> GameSetup | C8: ='Human Grading'!C8 -> 1 | D8: ='Human Grading'!C8 -> 1 | F8: Confusion Matrix (State)
A9: ='Human Grading'!A9 -> Region | B9: ='Human Grading'!B9 -> GameSetup Region 1 | C9: ='Human Grading'!C9 -> 1 | D9: ='Human Grading'!C9 -> 1 | F9: State | G9: 0 | H9: 0.5 | I9: 1 | J9: Row Totals | L9: Global | M9: 0 | N9: 0.5 | O9: 1 | Q9: Global | R9: 0 | S9: 0.5 | T9: 1 | V9: ="Metrics" & " " & F9 -> Metrics State | W9: Value | X9: Note
A10: ='Human Grading'!A10 -> State | B10: ='Human Grading'!B10 -> Initial state (region 1) | C10: ='Human Grading'!C10 -> 1 | D10: ='Human Grading'!C10 -> 1 | F10: 0 | G10: =COUNTIFS($A$2:$A$90,$F$9,$C$2:$C$90,$F10,$D$2:$D$90,G$9) -> 2 | H10: =COUNTIFS($A$2:$A$90,$F$9,$C$2:$C$90,$F10,$D$2:$D$90,H$9) -> 0 | I10: =COUNTIFS($A$2:$A$46,$F$9,$C$2:$C$46,$F10,$D$2:$D$46,I$9)+MAX(D47-C47,0) -> 0 | J10: =SUM(G10:I10) -> 2 | L10: 0 | M10: =ABS(G$2-$F10)/1 -> 0 | N10: =ABS(H$2-$F10)/1 -> 0.5 | O10: =ABS(I$2-$F10)/1 -> 1 | Q10: 0 | R10: =($J10/$J$13) * (G$13/$J$13) -> 0.020408163 | S10: =($J10/$J$13) * (H$13/$J$13) -> 0.010204082 | T10: =($J10/$J$13) * (I$13/$J$13) -> 0.1122449 | V10: Observed Weighted Disagreement (D_obs) | W10: =SUMPRODUCT(G10:I12, M10:O12) /$J$13 -> 0 | X10: Sum of (confusion-matrix counts × weights) divided by total items.
A11: ='Human Grading'!A11 -> State | B11: ='Human Grading'!B11 -> TimingSelection | C11: ='Human Grading'!C11 -> 1 | D11: ='Human Grading'!C11 -> 1 | F11: 0.5 | G11: =COUNTIFS($A$2:$A$90,$F$9,$C$2:$C$90,$F11,$D$2:$D$90,G$9) -> 0 | H11: =COUNTIFS($A$2:$A$90,$F$9,$C$2:$C$90,$F11,$D$2:$D$90,H$9) -> 1 | I11: =COUNTIFS($A$2:$A$90,$F$9,$C$2:$C$90,$F11,$D$2:$D$90,I$9) -> 0 | J11: =SUM(G11:I11) -> 1 | L11: 0.5 | M11: =ABS(G$2-$F11)/1 -> 0.5 | N11: =ABS(H$2-$F11)/3 -> 0 | O11: =ABS(I$2-$F11)/1 -> 0.5 | Q11: 0.5 | R11: =($J11/$J$13) * (G$13/$J$13) -> 0.010204082 | S11: =($J11/$J$13) * (H$13/$J$13) -> 0.0051020408 | T11: =($J11/$J$13) * (I$13/$J$13) -> 0.056122449 | V11: Expected Weighted Disagreement (D_exp) | W11: =SUMPRODUCT(R10:T12, M10:O12) -> 0.29081633 | X11: Sum of (expected cell proportions × weights) under chance agreement.
A12: ='Human Grading'!A12 -> Action | B12: ='Human Grading'!B12 -> incrTimingProgram() | C12: ='Human Grading'!C12 -> 1 | D12: ='Human Grading'!C12 -> 1 | F12: 1 | G12: =COUNTIFS($A$2:$A$46,$F$9,$C$2:$C$46,$F12,$D$2:$D$46,G$9)+MAX(C47-D47,0) -> 0 | H12: =COUNTIFS($A$2:$A$90,$F$9,$C$2:$C$90,$F12,$D$2:$D$90,H$9) -> 0 | I12: =COUNTIFS($A$2:$A$46,$F$9,$C$2:$C$46,$F12,$D$2:$D$46,I$9)+MIN(C47-D47) -> 11 | J12: =SUM(G12:I12) -> 11 | L12: 1 | M12: =ABS(G$2-$F12)/1 -> 1 | N12: =ABS(H$2-$F12)/1 -> 0.5 | O12: =ABS(I$2-$F12)/1 -> 0 | Q12: 1 | R12: =($J12/$J$13) * (G$13/$J$13) -> 0.1122449 | S12: =($J12/$J$13) * (H$13/$J$13) -> 0.056122449 | T12: =($J12/$J$13) * (I$13/$J$13) -> 0.61734694 | V12: Cohen's Kappa | W12: =1-W10/W11 -> 1 | X12: 1 - (D_obs / D_exp)
A13: ='Human Grading'!A13 -> Action | B13: ='Human Grading'!B13 -> decrTimingProgram() | C13: ='Human Grading'!C13 -> 1 | D13: ='Human Grading'!C13 -> 1 | F13: Column Totals | G13: =SUM(G10:G12) -> 2 | H13: =SUM(H10:H12) -> 1 | I13: =SUM(I10:I12) -> 11 | J13: =SUM(G10:I12) -> 14
A14: ='Human Grading'!A14 -> Transition | B14: ='Human Grading'!B14 -> timing selection => timing selection | C14: ='Human Grading'!C14 -> 1 | D14: ='Human Grading'!C14 -> 1
A15: ='Human Grading'!A15 -> Transition | B15: ='Human Grading'!B15 -> game setup => ready to start | C15: ='Human Grading'!C15 -> 0 | D15: ='Human Grading'!C15 -> 0 | F15: Confusion Matrix (Transition)
A16: ='Human Grading'!A16 -> Region | B16: ='Human Grading'!B16 -> GameSetup Region 2 | C16: ='Human Grading'!C16 -> 0 | D16: ='Human Grading'!C16 -> 0 | F16: Transition | G16: 0 | H16: 0.5 | I16: 1 | J16: Row Totals | L16: Global | M16: 0 | N16: 0.5 | O16: 1 | Q16: Global | R16: 0 | S16: 0.5 | T16: 1 | V16: ="Metrics" & " " & F16 -> Metrics Transition | W16: Value | X16: Note
A17: ='Human Grading'!A17 -> State | B17: ='Human Grading'!B17 -> Initial state (region 2) | C17: ='Human Grading'!C17 -> 1 | D17: ='Human Grading'!C17 -> 1 | F17: 0 | G17: =COUNTIFS($A$2:$A$90,$F$16,$C$2:$C$90,$F17,$D$2:$D$90,G$16) -> 3 | H17: =COUNTIFS($A$2:$A$90,$F$16,$C$2:$C$90,$F17,$D$2:$D$90,H$16) -> 0 | I17: =COUNTIFS($A$2:$A$46,$F$16,$C$2:$C$46,$F17,$D$2:$D$46,I$16) + MAX(D48-C48,0) -> 0 | J17: =SUM(G17:I17) -> 3 | L17: 0 | M17: =ABS(G$2-$F17)/1 -> 0 | N17: =ABS(H$2-$F17)/1 -> 0.5 | O17: =ABS(I$2-$F17)/1 -> 1 | Q17: 0 | R17: =($J17/$J$20) * (G$20/$J$20) -> 0.04 | S17: =($J17/$J$20) * (H$20/$J$20) -> 0 | T17: =($J17/$J$20) * (I$20/$J$20) -> 0.16 | V17: Observed Weighted Disagreement (D_obs) | W17: =SUMPRODUCT(G17:I19, M17:O19) /$J$20 -> 0 | X17: Sum of (confusion-matrix counts × weights) divided by total items.
A18: ='Human Grading'!A18 -> State | B18: ='Human Grading'!B18 -> WhiteKingOnLeft | C18: ='Human Grading'!C18 -> 1 | D18: ='Human Grading'!C18 -> 1 | F18: 0.5 | G18: =COUNTIFS($A$2:$A$90,$F$16,$C$2:$C$90,$F18,$D$2:$D$90,G$16) -> 0 | H18: =COUNTIFS($A$2:$A$90,$F$16,$C$2:$C$90,$F18,$D$2:$D$90,H$16) -> 0 | I18: =COUNTIFS($A$2:$A$90,$F$16,$C$2:$C$90,$F18,$D$2:$D$90,I$16) -> 0 | J18: =SUM(G18:I18) -> 0 | L18: 0.5 | M18: =ABS(G$2-$F18)/1 -> 0.5 | N18: =ABS(H$2-$F18)/3 -> 0 | O18: =ABS(I$2-$F18)/1 -> 0.5 | Q18: 0.5 | R18: =($J18/$J$20) * (G$20/$J$20) -> 0 | S18: =($J18/$J$20) * (H$20/$J$20) -> 0 | T18: =($J18/$J$20) * (I$20/$J$20) -> 0 | V18: Expected Weighted Disagreement (D_exp) | W18: =SUMPRODUCT(R17:T19, M17:O19) -> 0.32 | X18: Sum of (expected cell proportions × weights) under chance agreement.
A19: ='Human Grading'!A19 -> State | B19: ='Human Grading'!B19 -> WhiteKingOnRight | C19: ='Human Grading'!C19 -> 1 | D19: ='Human Grading'!C19 -> 1 | F19: 1 | G19: =COUNTIFS($A$2:$A$46,$F$16,$C$2:$C$46,$F19,$D$2:$D$46,G$16)+MAX(C48-D48,0) -> 0 | H19: =COUNTIFS($A$2:$A$90,$F$16,$C$2:$C$90,$F19,$D$2:$D$90,H$16) -> 0 | I19: =COUNTIFS($A$2:$A$46,$F$16,$C$2:$C$46,$F19,$D$2:$D$46,I$16) + MIN(C48,D48) -> 12 | J19: =SUM(G19:I19) -> 12 | L19: 1 | M19: =ABS(G$2-$F19)/1 -> 1 | N19: =ABS(H$2-$F19)/1 -> 0.5 | O19: =ABS(I$2-$F19)/1 -> 0 | Q19: 1 | R19: =($J19/$J$20) * (G$20/$J$20) -> 0.16 | S19: =($J19/$J$20) * (H$20/$J$20) -> 0 | T19: =($J19/$J$20) * (I$20/$J$20) -> 0.64 | V19: Cohen's Kappa | W19: =1-W17/W18 -> 1 | X19: 1 - (D_obs / D_exp)
A20: ='Human Grading'!A20 -> Transition | B20: ='Human Grading'!B20 -> initial state => white king on left | C20: ='Human Grading'!C20 -> 1 | D20: ='Human Grading'!C20 -> 1 | F20: Column Totals | G20: =SUM(G17:G19) -> 3 | H20: =SUM(H17:H19) -> 0 | I20: =SUM(I17:I19) -> 12 | J20: =SUM(G17:I19) -> 15
A21: ='Human Grading'!A21 -> Transition | B21: ='Human Grading'!B21 -> white king on left => white king on right | C21: ='Human Grading'!C21 -> 1 | D21: ='Human Grading'!C21 -> 1
A22: ='Human Grading'!A22 -> Transition | B22: ='Human Grading'!B22 -> white king on right => white king on left | C22: ='Human Grading'!C22 -> 1 | D22: ='Human Grading'!C22 -> 1 | F22: Confusion Matrix (Composite State)
A23: ='Human Grading'!A23 -> State | B23: ='Human Grading'!B23 -> ReadyToStart | C23: ='Human Grading'!C23 -> 0 | D23: ='Human Grading'!C23 -> 0 | F23: Composite State | G23: 0 | H23: 0.5 | I23: 1 | J23: Row Totals | L23: Global | M23: 0 | N23: 0.5 | O23: 1 | Q23: Global | R23: 0 | S23: 0.5 | T23: 1 | V23: ="Metrics" & " " & F23 -> Metrics Composite State | W23: Value | X23: Note
A24: ='Human Grading'!A24 -> Transition | B24: ='Human Grading'!B24 -> ready to start => game running | C24: ='Human Grading'!C24 -> 1 | D24: ='Human Grading'!C24 -> 1 | F24: 0 | G24: =COUNTIFS($A$2:$A$90,$F$23,$C$2:$C$90,$F24,$D$2:$D$90,G$23) -> 1 | H24: =COUNTIFS($A$2:$A$90,$F$23,$C$2:$C$90,$F24,$D$2:$D$90,H$23) -> 0 | I24: =COUNTIFS($A$2:$A$46,$F$23,$C$2:$C$46,$F24,$D$2:$D$46,I$23) + MAX(D51-C51,0) -> 0 | J24: =SUM(G24:I24) -> 1 | L24: 0 | M24: =ABS(G$2-$F24)/1 -> 0 | N24: =ABS(H$2-$F24)/1 -> 0.5 | O24: =ABS(I$2-$F24)/1 -> 1 | Q24: 0 | R24: =($J24/$J$27) * (G$27/$J$27) -> 0.0625 | S24: =($J24/$J$27) * (H$27/$J$27) -> 0 | T24: =($J24/$J$27) * (I$27/$J$27) -> 0.1875 | V24: Observed Weighted Disagreement (D_obs) | W24: =SUMPRODUCT(G24:I26, M24:O26) /$J$27 -> 0 | X24: Sum of (confusion-matrix counts × weights) divided by total items.
A25: ='Human Grading'!A25 -> Composite State | B25: ='Human Grading'!B25 -> GameRunning | C25: ='Human Grading'!C25 -> 1 | D25: ='Human Grading'!C25 -> 1 | F25: 0.5 | G25: =COUNTIFS($A$2:$A$90,$F$23,$C$2:$C$90,$F25,$D$2:$D$90,G$23) -> 0 | H25: =COUNTIFS($A$2:$A$90,$F$23,$C$2:$C$90,$F25,$D$2:$D$90,H$23) -> 0 | I25: =COUNTIFS($A$2:$A$90,$F$23,$C$2:$C$90,$F25,$D$2:$D$90,I$23) -> 0 | J25: =SUM(G25:I25) -> 0 | L25: 0.5 | M25: =ABS(G$2-$F25)/1 -> 0.5 | N25: =ABS(H$2-$F25)/3 -> 0 | O25: =ABS(I$2-$F25)/1 -> 0.5 | Q25: 0.5 | R25: =($J25/$J$27) * (G$27/$J$27) -> 0 | S25: =($J25/$J$27) * (H$27/$J$27) -> 0 | T25: =($J25/$J$27) * (I$27/$J$27) -> 0 | V25: Expected Weighted Disagreement (D_exp) | W25: =SUMPRODUCT(R24:T26, M24:O26) -> 0.375 | X25: Sum of (expected cell proportions × weights) under chance agreement.
A26: ='Human Grading'!A26 -> History State | B26: ='Human Grading'!B26 -> H | C26: ='Human Grading'!C26 -> 1 | D26: ='Human Grading'!C26 -> 1 | F26: 1 | G26: =COUNTIFS($A$2:$A$46,$F$23,$C$2:$C$46,$F26,$D$2:$D$46,G$23) + MAX(C51-D51,0) -> 0 | H26: =COUNTIFS($A$2:$A$90,$F$23,$C$2:$C$90,$F26,$D$2:$D$90,H$23) -> 0 | I26: =COUNTIFS($A$2:$A$46,$F$23,$C$2:$C$46,$F26,$D$2:$D$46,I$23) + MIN(C51,D51) -> 3 | J26: =SUM(G26:I26) -> 3 | L26: 1 | M26: =ABS(G$2-$F26)/1 -> 1 | N26: =ABS(H$2-$F26)/1 -> 0.5 | O26: =ABS(I$2-$F26)/1 -> 0 | Q26: 1 | R26: =($J26/$J$27) * (G$27/$J$27) -> 0.1875 | S26: =($J26/$J$27) * (H$27/$J$27) -> 0 | T26: =($J26/$J$27) * (I$27/$J$27) -> 0.5625 | V26: Cohen's Kappa | W26: =1-W24/W25 -> 1 | X26: 1 - (D_obs / D_exp)
A27: ='Human Grading'!A27 -> State | B27: ='Human Grading'!B27 -> WhiteClockRunning | C27: ='Human Grading'!C27 -> 1 | D27: ='Human Grading'!C27 -> 1 | F27: Column Totals | G27: =SUM(G24:G26) -> 1 | H27: =SUM(H24:H26) -> 0 | I27: =SUM(I24:I26) -> 3 | J27: =SUM(G24:I26) -> 4
A28: ='Human Grading'!A28 -> Action | B28: ='Human Grading'!B28 -> startTimer(wc) | C28: ='Human Grading'!C28 -> 1 | D28: ='Human Grading'!C28 -> 1
A29: ='Human Grading'!A29 -> Action | B29: ='Human Grading'!B29 -> stopTimer(wc) | C29: ='Human Grading'!C29 -> 1 | D29: ='Human Grading'!C29 -> 1 | F29: Confusion Matrix (Guard)
A30: ='Human Grading'!A30 -> Guard | B30: ='Human Grading'!B30 -> [wc > 0] | C30: ='Human Grading'!C30 -> 1 | D30: ='Human Grading'!C30 -> 1 | F30: Guard | G30: 0 | H30: 0.5 | I30: 1 | J30: Row Totals | L30: Global | M30: 0 | N30: 0.5 | O30: 1 | Q30: Global | R30: 0 | S30: 0.5 | T30: 1 | V30: ="Metrics" & " " & F30 -> Metrics Guard | W30: Value | X30: Note
A31: ='Human Grading'!A31 -> Action | B31: ='Human Grading'!B31 -> decrTimer(wc) | C31: ='Human Grading'!C31 -> 1 | D31: ='Human Grading'!C31 -> 1 | F31: 0 | G31: =COUNTIFS($A$2:$A$90,$F$30,$C$2:$C$90,$F31,$D$2:$D$90,G$30) -> 1 | H31: =COUNTIFS($A$2:$A$90,$F$30,$C$2:$C$90,$F31,$D$2:$D$90,H$30) -> 0 | I31: =COUNTIFS($A$2:$A$46,$F$30,$C$2:$C$46,$F31,$D$2:$D$46,I$30) + MAX(D49-C49,0) -> 0 | J31: =SUM(G31:I31) -> 1 | L31: 0 | M31: =ABS(G$2-$F31)/1 -> 0 | N31: =ABS(H$2-$F31)/1 -> 0.5 | O31: =ABS(I$2-$F31)/1 -> 1 | Q31: 0 | R31: =($J31/$J$34) * (G$34/$J$34) -> 0.04 | S31: =($J31/$J$34) * (H$34/$J$34) -> 0 | T31: =($J31/$J$34) * (I$34/$J$34) -> 0.16 | V31: Observed Weighted Disagreement (D_obs) | W31: =SUMPRODUCT(G31:I33, M31:O33) /$J$34 -> 0 | X31: Sum of (confusion-matrix counts × weights) divided by total items.
A32: ='Human Grading'!A32 -> Transition | B32: ='Human Grading'!B32 -> white clock running => white clock running | C32: ='Human Grading'!C32 -> 1 | D32: ='Human Grading'!C32 -> 1 | F32: 0.5 | G32: =COUNTIFS($A$2:$A$90,$F$30,$C$2:$C$90,$F32,$D$2:$D$90,G$30) -> 0 | H32: =COUNTIFS($A$2:$A$90,$F$30,$C$2:$C$90,$F32,$D$2:$D$90,H$30) -> 0 | I32: =COUNTIFS($A$2:$A$90,$F$30,$C$2:$C$90,$F32,$D$2:$D$90,I$30) -> 0 | J32: =SUM(G32:I32) -> 0 | L32: 0.5 | M32: =ABS(G$2-$F32)/1 -> 0.5 | N32: =ABS(H$2-$F32)/3 -> 0 | O32: =ABS(I$2-$F32)/1 -> 0.5 | Q32: 0.5 | R32: =($J32/$J$34) * (G$34/$J$34) -> 0 | S32: =($J32/$J$34) * (H$34/$J$34) -> 0 | T32: =($J32/$J$34) * (I$34/$J$34) -> 0 | V32: Expected Weighted Disagreement (D_exp) | W32: =SUMPRODUCT(R31:T33, M31:O33) -> 0.32 | X32: Sum of (expected cell proportions × weights) under chance agreement.
A33: ='Human Grading'!A33 -> State | B33: ='Human Grading'!B33 -> BlackClockRunning | C33: ='Human Grading'!C33 -> 1 | D33: ='Human Grading'!C33 -> 1 | F33: 1 | G33: =COUNTIFS($A$2:$A$46,$F$30,$C$2:$C$46,$F33,$D$2:$D$46,G$30) + MAX(C49-D49,0) -> 0 | H33: =COUNTIFS($A$2:$A$90,$F$30,$C$2:$C$90,$F33,$D$2:$D$90,H$30) -> 0 | I33: =COUNTIFS($A$2:$A$46,$F$30,$C$2:$C$46,$F33,$D$2:$D$46,I$30) + MIN(C49,D49) -> 4 | J33: =SUM(G33:I33) -> 4 | L33: 1 | M33: =ABS(G$2-$F33)/1 -> 1 | N33: =ABS(H$2-$F33)/1 -> 0.5 | O33: =ABS(I$2-$F33)/1 -> 0 | Q33: 1 | R33: =($J33/$J$34) * (G$34/$J$34) -> 0.16 | S33: =($J33/$J$34) * (H$34/$J$34) -> 0 | T33: =($J33/$J$34) * (I$34/$J$34) -> 0.64 | V33: Cohen's Kappa | W33: =1-W31/W32 -> 1 | X33: 1 - (D_obs / D_exp)
A34: ='Human Grading'!A34 -> Action | B34: ='Human Grading'!B34 -> startTimer(bc) | C34: ='Human Grading'!C34 -> 1 | D34: ='Human Grading'!C34 -> 1 | F34: Column Totals | G34: =SUM(G31:G33) -> 1 | H34: =SUM(H31:H33) -> 0 | I34: =SUM(I31:I33) -> 4 | J34: =SUM(G31:I33) -> 5
A35: ='Human Grading'!A35 -> Action | B35: ='Human Grading'!B35 -> stopTimer(bc) | C35: ='Human Grading'!C35 -> 1 | D35: ='Human Grading'!C35 -> 1
A36: ='Human Grading'!A36 -> Guard | B36: ='Human Grading'!B36 -> [bc > 0] | C36: ='Human Grading'!C36 -> 1 | D36: ='Human Grading'!C36 -> 1 | F36: Confusion Matrix (Action)
A37: ='Human Grading'!A37 -> Action | B37: ='Human Grading'!B37 -> decrTimer(bc) | C37: ='Human Grading'!C37 -> 1 | D37: ='Human Grading'!C37 -> 1 | F37: Action | G37: 0 | H37: 0.5 | I37: 1 | J37: Row Totals | L37: Global | M37: 0 | N37: 0.5 | O37: 1 | Q37: Global | R37: 0 | S37: 0.5 | T37: 1 | V37: ="Metrics" & " " & F37 -> Metrics Action | W37: Value | X37: Note
A38: ='Human Grading'!A38 -> Transition | B38: ='Human Grading'!B38 -> balck clock running => black clock running | C38: ='Human Grading'!C38 -> 1 | D38: ='Human Grading'!C38 -> 1 | F38: 0 | G38: =COUNTIFS($A$2:$A$90,$F$37,$C$2:$C$90,$F38,$D$2:$D$90,G$37) -> 1 | H38: =COUNTIFS($A$2:$A$90,$F$37,$C$2:$C$90,$F38,$D$2:$D$90,H$37) -> 0 | I38: =COUNTIFS($A$2:$A$46,$F$37,$C$2:$C$46,$F38,$D$2:$D$46,I$37)+MAX(D50-C50,0) -> 0 | J38: =SUM(G38:I38) -> 1 | L38: 0 | M38: =ABS(G$2-$F38)/1 -> 0 | N38: =ABS(H$2-$F38)/1 -> 0.5 | O38: =ABS(I$2-$F38)/1 -> 1 | Q38: 0 | R38: =($J38/$J$41) * (G$41/$J$41) -> 0.012345679 | S38: =($J38/$J$41) * (H$41/$J$41) -> 0 | T38: =($J38/$J$41) * (I$41/$J$41) -> 0.098765432 | V38: Observed Weighted Disagreement (D_obs) | W38: =SUMPRODUCT(G38:I40, M38:O40) /$J$41 -> 0 | X38: Sum of (confusion-matrix counts × weights) divided by total items.
A39: ='Human Grading'!A39 -> Transition | B39: ='Human Grading'!B39 -> game running => game paused | C39: ='Human Grading'!C39 -> 1 | D39: ='Human Grading'!C39 -> 1 | F39: 0.5 | G39: =COUNTIFS($A$2:$A$90,$F$37,$C$2:$C$90,$F39,$D$2:$D$90,G$37) -> 0 | H39: =COUNTIFS($A$2:$A$90,$F$37,$C$2:$C$90,$F39,$D$2:$D$90,H$37) -> 0 | I39: =COUNTIFS($A$2:$A$90,$F$37,$C$2:$C$90,$F39,$D$2:$D$90,I$37) -> 0 | J39: =SUM(G39:I39) -> 0 | L39: 0.5 | M39: =ABS(G$2-$F39)/1 -> 0.5 | N39: =ABS(H$2-$F39)/3 -> 0 | O39: =ABS(I$2-$F39)/1 -> 0.5 | Q39: 0.5 | R39: =($J39/$J$41) * (G$41/$J$41) -> 0 | S39: =($J39/$J$41) * (H$41/$J$41) -> 0 | T39: =($J39/$J$41) * (I$41/$J$41) -> 0 | V39: Expected Weighted Disagreement (D_exp) | W39: =SUMPRODUCT(R38:T40, M38:O40) -> 0.19753086 | X39: Sum of (expected cell proportions × weights) under chance agreement.
A40: ='Human Grading'!A40 -> Transition | B40: ='Human Grading'!B40 -> game running => game finished | C40: ='Human Grading'!C40 -> 0 | D40: ='Human Grading'!C40 -> 0 | F40: 1 | G40: =COUNTIFS($A$2:$A$46,$F$37,$C$2:$C$46,$F40,$D$2:$D$46,G$37)+MAX(C50-D50,0) -> 0 | H40: =COUNTIFS($A$2:$A$90,$F$37,$C$2:$C$90,$F40,$D$2:$D$90,H$37) -> 0 | I40: =COUNTIFS($A$2:$A$46,$F$37,$C$2:$C$46,$F40,$D$2:$D$46,I$37) + MIN(C50,D50) -> 8 | J40: =SUM(G40:I40) -> 8 | L40: 1 | M40: =ABS(G$2-$F40)/1 -> 1 | N40: =ABS(H$2-$F40)/1 -> 0.5 | O40: =ABS(I$2-$F40)/1 -> 0 | Q40: 1 | R40: =($J40/$J$41) * (G$41/$J$41) -> 0.098765432 | S40: =($J40/$J$41) * (H$41/$J$41) -> 0 | T40: =($J40/$J$41) * (I$41/$J$41) -> 0.79012346 | V40: Cohen's Kappa | W40: =1-W38/W39 -> 1 | X40: 1 - (D_obs / D_exp)
...
