Workbook

Sheet Train Automation System
A1: Type | B1: Element
A2: ='GPT-5 Generation'!A2 -> State | B2: ='GPT-5 Generation'!B2 -> Initial state (→ Scheduled)
A3: ='GPT-5 Generation'!A3 -> State | B3: ='GPT-5 Generation'!B3 -> Scheduled
A4: ='GPT-5 Generation'!A4 -> Transition | B4: ='GPT-5 Generation'!B4 -> at beginningStopDuration (Scheduled ⇒ Active)
A5: ='GPT-5 Generation'!A5 -> Action | B5: ='GPT-5 Generation'!B5 -> pOn; setCS;
A6: ='GPT-5 Generation'!A6 -> Composite State | B6: ='GPT-5 Generation'!B6 -> Active
A7: ='GPT-5 Generation'!A7 -> Region | B7: ='GPT-5 Generation'!B7 -> TrainControl
A8: ='GPT-5 Generation'!A8 -> Composite State | B8: ='GPT-5 Generation'!B8 -> TrainMovement
A9: ='GPT-5 Generation'!A9 -> State | B9: ='GPT-5 Generation'!B9 -> Initial state (TrainMovement → AtStation)
A10: ='GPT-5 Generation'!A10 -> State | B10: ='GPT-5 Generation'!B10 -> AtStation
A11: ='GPT-5 Generation'!A11 -> Action | B11: ='GPT-5 Generation'!B11 -> entry / openDoors()
A12: ='GPT-5 Generation'!A12 -> Action | B12: ='GPT-5 Generation'!B12 -> exit / closeDoors()
A13: ='GPT-5 Generation'!A13 -> Transition | B13: ='GPT-5 Generation'!B13 -> after stopDuration (AtStation ⇒ StopNotRequired)
... A78: ='GPT-5 Generation'!A78 -> History State | B78: ='GPT-5 Generation'!B78 -> additional elements

Sheet GPT-5 Generation
A1: Type | B1: Element | C1: GPT-5 | D1: Notes
A2: State | B2: Initial state (→ Scheduled) | C2: 0 | D2: Student model starts with Inactive state instead of Scheduled; initial state points to Inactive not Scheduled.
A3: State | B3: Scheduled | C3: 0 | D3: No Scheduled state exists in student submission; uses Inactive state which does not represent the scheduled waiting period.
A4: Transition | B4: at beginningStopDuration (Scheduled ⇒ Active) | C4: 0.5 | D4: Transition exists from Inactive to Active with scheduledStopBegins event but does not match the expected atBeginningStopDuration semantics exactly.
A5: Action | B5: pOn; setCS; | C5: 1 | D5: Actions pOn() and setCS(firstSegment) are present on the Inactive to Active transition.
A6: Composite State | B6: Active | C6: 1 | D6: Active composite state is present and contains the required regions.
A7: Region | B7: TrainControl | C7: 0.5 | D7: Student has Operation region which serves similar purpose but is named differently; contains Journey and EmergencyStopped states.
A8: Composite State | B8: TrainMovement | C8: 1 | D8: Journey composite state in student submission represents the train movement logic equivalent to TrainMovement.
A9: State | B9: Initial state (TrainMovement → AtStation) | C9: 1 | D9: Initial state in Journey points to InitialStationStop which represents the station stop behavior.
A10: State | B10: AtStation | C10: 1 | D10: InitialStationStop and DwellingAtStation states together represent AtStation behavior; doors open and close appropriately.
A11: Action | B11: entry / openDoors() | C11: 1 | D11: openDoors() action is present when entering DwellingAtStation after stoppedDetected.
A12: Action | B12: exit / closeDoors() | C12: 1 | D12: closeDoors() action is present when leaving DwellingAtStation and InitialStationStop states.
A13: Transition | B13: after stopDuration (AtStation ⇒ StopNotRequired) | C13: 1 | D13: Transition from InitialStationStop and DwellingAtStation to Running after stopDuration with setSpeed action.
... A78: History State | B78: additional elements | C78: 0 | D78: No fundamentally incorrect additional history states present.

Sheet Claude Sonnet 4.5 Gen
A1: Type | B1: Element | C1: Rater 2 | D1: Notes
A2: State | B2: Initial state (→ Scheduled) | C2: 0 | D2: Student model starts with Off state instead of Scheduled; no Scheduled state exists
A3: State | B3: Scheduled | C3: 0 | D3: No Scheduled state in student submission
A4: Transition | B4: at_beginningStopDuration (Scheduled ⇒ Active) | C4: 0 | D4: No Scheduled state or corresponding transition exists
A5: Action | B5: pOn; setCS; | C5: 0.5 | D5: pOn() exists on Off→On transition but setCS is in WaitingAtFirstStation entry action not on transition
A6: Composite State | B6: Active | C6: 1 | D6: On state serves as the active composite state containing all train operations
A7: Region | B7: TrainControl | C7: 1 | D7: Journey region contains train control logic
A8: Composite State | B8: TrainMovement | C8: 1 | D8: Moving composite state represents train movement behavior
A9: State | B9: Initial state (TrainMovement → AtStation) | C9: 0 | D9: Initial state in Journey region goes to WaitingAtFirstStation not AtStation
A10: State | B10: AtStation | C10: 0.5 | D10: StoppedAtStation exists but represents intermediate stations; WaitingAtFirstStation represents first station
A11: Entry Action | B11: openDoors() | C11: 1 | D11: DoorsOpening state with entry/openDoors() in StoppedAtStation composite
A12: Exit Action | B12: closeDoors() | C12: 0.5 | D12: DoorsClosing state exists but not modeled as exit action of parent state
A13: Transition | B13: after stopDuration (AtStation ⇒ StopNotRequired) | C13: 0.5 | D13: WaitingAtStation→DoorsClosing uses afterStopDuration but goes to Moving not a separate StopNotRequired state
... A78: History State | B78: additional elements | C78: 0 | D78: No fundamentally incorrect additional history states

Sheet Metrics
A1: Generated by GPT-5 | J1: Date
A2: Type | B2: Ground Truth Count | C2: True Positive | D2: False Positive | E2: False Negative | F2: Precision | G2: Recall | H2: F1 Score | J2: March 16th, 2026
A3: Composite State | B3: =COUNTIF('Train Automation System'!$A$2:$A$71, A3) -> 2 | C3: =SUMIF('GPT-5 Generation'!$A$2:$A$71, $A3, 'GPT-5 Generation'!$C$2:$C$71) -> 2 | D3: =SUMIF('GPT-5 Generation'!$A$72:$A$78, $A3, 'GPT-5 Generation'!$C$72:$C$78) -> 0 | E3: =COUNTIFS('GPT-5 Generation'!$A$2:$A$71, $A3, 'GPT-5 Generation'!$C$2:$C$71,0) -> 0 | F3: =IFERROR(C3 / (C3 + D3), "Not Available") -> 1 | G3: =IFERROR(C3 / B3, "Not Available") -> 1 | H3: =IFERROR(2*((F3*G3)/(F3+G3)),"Not Available") -> 1
A4: State | B4: =COUNTIF('Train Automation System'!$A$2:$A$71, A4) -> 17 | C4: =SUMIF('GPT-5 Generation'!$A$2:$A$71, $A4, 'GPT-5 Generation'!$C$2:$C$71) -> 14 | D4: =SUMIF('GPT-5 Generation'!$A$72:$A$78, $A4, 'GPT-5 Generation'!$C$72:$C$78) -> 0 | E4: =COUNTIFS('GPT-5 Generation'!$A$2:$A$71, $A4, 'GPT-5 Generation'!$C$2:$C$71,0) -> 3 | F4: =IFERROR(C4 / (C4 + D4), "Not Available") -> 1 | G4: =IFERROR(C4 / B4, "Not Available") -> 0.82352941 | H4: =IFERROR(2*((F4*G4)/(F4+G4)),"Not Available") -> 0.90322581 | J4: Grading LLM
A5: Transition | B5: =COUNTIF('Train Automation System'!$A$2:$A$71, A5) -> 20 | C5: =SUMIF('GPT-5 Generation'!$A$2:$A$71, $A5, 'GPT-5 Generation'!$C$2:$C$71) -> 19 | D5: =SUMIF('GPT-5 Generation'!$A$72:$A$78, $A5, 'GPT-5 Generation'!$C$72:$C$78) -> 0 | E5: =COUNTIFS('GPT-5 Generation'!$A$2:$A$71, $A5, 'GPT-5 Generation'!$C$2:$C$71,0) -> 0 | F5: =IFERROR(C5 / (C5 + D5), "Not Available") -> 1 | G5: =IFERROR(C5 / B5, "Not Available") -> 0.95 | H5: =IFERROR(2*((F5*G5)/(F5+G5)),"Not Available") -> 0.97435897 | J5: Claude Sonnet 4.5
A6: Action | B6: =COUNTIF('Train Automation System'!$A$2:$A$71, A6) -> 12 | C6: =SUMIF('GPT-5 Generation'!$A$2:$A$71, $A6, 'GPT-5 Generation'!$C$2:$C$71) -> 11.5 | D6: =SUMIF('GPT-5 Generation'!$A$72:$A$78, $A6, 'GPT-5 Generation'!$C$72:$C$78) -> 0 | E6: =COUNTIFS('GPT-5 Generation'!$A$2:$A$71, $A6, 'GPT-5 Generation'!$C$2:$C$71,0) -> 0 | F6: =IFERROR(C6 / (C6 + D6), "Not Available") -> 1 | G6: =IFERROR(C6 / B6, "Not Available") -> 0.95833333 | H6: =IFERROR(2*((F6*G6)/(F6+G6)),"Not Available") -> 0.9787234
A7: Region | B7: =COUNTIF('Train Automation System'!$A$2:$A$71, A7) -> 4 | C7: =SUMIF('GPT-5 Generation'!$A$2:$A$71, $A7, 'GPT-5 Generation'!$C$2:$C$71) -> 3.5 | D7: =SUMIF('GPT-5 Generation'!$A$72:$A$78, $A7, 'GPT-5 Generation'!$C$72:$C$78) -> 0 | E7: =COUNTIFS('GPT-5 Generation'!$A$2:$A$71, $A7, 'GPT-5 Generation'!$C$2:$C$71,0) -> 0 | F7: =IFERROR(C7 / (C7 + D7), "Not Available") -> 1 | G7: =IFERROR(C7 / B7, "Not Available") -> 0.875 | H7: =IFERROR(2*((F7*G7)/(F7+G7)),"Not Available") -> 0.93333333 | J7: Generation LLMs
A8: History State | B8: =COUNTIF('Train Automation System'!$A$2:$A$71, A8) -> 1 | C8: =SUMIF('GPT-5 Generation'!$A$2:$A$71, $A8, 'GPT-5 Generation'!$C$2:$C$71) -> 1 | D8: =SUMIF('GPT-5 Generation'!$A$72:$A$78, $A8, 'GPT-5 Generation'!$C$72:$C$78) -> 0 | E8: =COUNTIFS('GPT-5 Generation'!$A$2:$A$71, $A8, 'GPT-5 Generation'!$C$2:$C$71,0) -> 0 | F8: =IFERROR(C8 / (C8 + D8), "Not Available") -> 1 | G8: =IFERROR(C8 / B8, "Not Available") -> 1 | H8: =IFERROR(2*((F8*G8)/(F8+G8)),"Not Available") -> 1 | J8: GPT-5
A9: Guard | B9: =COUNTIF('Train Automation System'!$A$2:$A$71, A9) -> 14 | C9: =SUMIF('GPT-5 Generation'!$A$2:$A$71, $A9, 'GPT-5 Generation'!$C$2:$C$71) -> 14 | D9: =SUMIF('GPT-5 Generation'!$A$72:$A$78, $A9, 'GPT-5 Generation'!$C$72:$C$78) -> 0 | E9: =COUNTIFS('GPT-5 Generation'!$A$2:$A$71, $A9, 'GPT-5 Generation'!$C$2:$C$71,0) -> 0 | F9: =IFERROR(C9 / (C9 + D9), "Not Available") -> 1 | G9: =IFERROR(C9 / B9, "Not Available") -> 1 | H9: =IFERROR(2*((F9*G9)/(F9+G9)),"Not Available") -> 1 | J9: Claude Sonnet 4.5
A10: Overall Score | B10: =SUM(B3:B9) -> 70 | C10: =SUM(C3:C9) -> 65 | D10: =SUM(D3:D9) -> 0 | E10: =SUM(E3:E9) -> 3 | F10: =IFERROR(C10 / (C10 + D10), "Not Available") -> 1 | G10: =IFERROR(C10 / B10, "Not Available") -> 0.92857143 | H10: =IFERROR(2*((F10*G10)/(F10+G10)),"Not Available") -> 0.96296296
A12: Generated by Claude Sonnet 4.5
A13: Type | B13: Ground Truth Count | C13: True Positive | D13: False Positive | E13: False Negative | F13: Precision | G13: Recall | H13: F1 Score
A14: Composite state | B14: =COUNTIF('Train Automation System'!$A$2:$A$71, A14) -> 2 | C14: =SUMIF('Claude Sonnet 4.5 Gen'!$A$2:$A$71, $A14, 'Claude Sonnet 4.5 Gen'!$C$2:$C$71) -> 2 | D14: =SUMIF('Claude Sonnet 4.5 Gen'!$A$72:$A$78, $A14, 'Claude Sonnet 4.5 Gen'!$C$72:$C$78) -> 0 | E14: =COUNTIFS('Claude Sonnet 4.5 Gen'!$A$2:$A$71, $A14, 'Claude Sonnet 4.5 Gen'!$C$2:$C$71,0) -> 0 | F14: =IFERROR(C14 / (C14 + D14), "Not Available") -> 1 | G14: =IFERROR(C14 / B14, "Not Available") -> 1 | H14: =IFERROR(2*((F14*G14)/(F14+G14)),"Not Available") -> 1
A15: State | B15: =COUNTIF('Train Automation System'!$A$2:$A$71, A15) -> 17 | C15: =SUMIF('Claude Sonnet 4.5 Gen'!$A$2:$A$71, $A15, 'Claude Sonnet 4.5 Gen'!$C$2:$C$71) -> 6.5 | D15: =SUMIF('Claude Sonnet 4.5 Gen'!$A$72:$A$78, $A15, 'Claude Sonnet 4.5 Gen'!$C$72:$C$78) -> 0 | E15: =COUNTIFS('Claude Sonnet 4.5 Gen'!$A$2:$A$71, $A15, 'Claude Sonnet 4.5 Gen'!$C$2:$C$71,0) -> 10 | F15: =IFERROR(C15 / (C15 + D15), "Not Available") -> 1 | G15: =IFERROR(C15 / B15, "Not Available") -> 0.38235294 | H15: =IFERROR(2*((F15*G15)/(F15+G15)),"Not Available") -> 0.55319149
A16: Transition | B16: =COUNTIF('Train Automation System'!$A$2:$A$71, A16) -> 20 | C16: =SUMIF('Claude Sonnet 4.5 Gen'!$A$2:$A$71, $A16, 'Claude Sonnet 4.5 Gen'!$C$2:$C$71) -> 10 | D16: =SUMIF('Claude Sonnet 4.5 Gen'!$A$72:$A$78, $A16, 'Claude Sonnet 4.5 Gen'!$C$72:$C$78) -> 0 | E16: =COUNTIFS('Claude Sonnet 4.5 Gen'!$A$2:$A$71, $A16, 'Claude Sonnet 4.5 Gen'!$C$2:$C$71,0) -> 7 | F16: =IFERROR(C16 / (C16 + D16), "Not Available") -> 1 | G16: =IFERROR(C16 / B16, "Not Available") -> 0.5 | H16: =IFERROR(2*((F16*G16)/(F16+G16)),"Not Available") -> 0.66666667
A17: Action | B17: =COUNTIF('Train Automation System'!$A$2:$A$71, A17) -> 12 | C17: =SUMIF('Claude Sonnet 4.5 Gen'!$A$2:$A$71, $A17, 'Claude Sonnet 4.5 Gen'!$C$2:$C$71) -> 4.5 | D17: =SUMIF('Claude Sonnet 4.5 Gen'!$A$72:$A$78, $A17, 'Claude Sonnet 4.5 Gen'!$C$72:$C$78) -> 0 | E17: =COUNTIFS('Claude Sonnet 4.5 Gen'!$A$2:$A$71, $A17, 'Claude Sonnet 4.5 Gen'!$C$2:$C$71,0) -> 0 | F17: =IFERROR(C17 / (C17 + D17), "Not Available") -> 1 | G17: =IFERROR(C17 / B17, "Not Available") -> 0.375 | H17: =IFERROR(2*((F17*G17)/(F17+G17)),"Not Available") -> 0.54545455
A18: Region | B18: =COUNTIF('Train Automation System'!$A$2:$A$71, A18) -> 4 | C18: =SUMIF('Claude Sonnet 4.5 Gen'!$A$2:$A$71, $A18, 'Claude Sonnet 4.5 Gen'!$C$2:$C$71) -> 4 | D18: =SUMIF('Claude Sonnet 4.5 Gen'!$A$72:$A$78, $A18, 'Claude Sonnet 4.5 Gen'!$C$72:$C$78) -> 0 | E18: =COUNTIFS('Claude Sonnet 4.5 Gen'!$A$2:$A$71, $A18, 'Claude Sonnet 4.5 Gen'!$C$2:$C$71,0) -> 0 | F18: =IFERROR(C18 / (C18 + D18), "Not Available") -> 1 | G18: =IFERROR(C18 / B18, "Not Available") -> 1 | H18: =IFERROR(2*((F18*G18)/(F18+G18)),"Not Available") -> 1
A19: History State | B19: =COUNTIF('Train Automation System'!$A$2:$A$71, A19) -> 1 | C19: =SUMIF('Claude Sonnet 4.5 Gen'!$A$2:$A$71, $A19, 'Claude Sonnet 4.5 Gen'!$C$2:$C$71) -> 1 | D19: =SUMIF('Claude Sonnet 4.5 Gen'!$A$72:$A$78, $A19, 'Claude Sonnet 4.5 Gen'!$C$72:$C$78) -> 0 | E19: =COUNTIFS('Claude Sonnet 4.5 Gen'!$A$2:$A$71, $A19, 'Claude Sonnet 4.5 Gen'!$C$2:$C$71,0) -> 0 | F19: =IFERROR(C19 / (C19 + D19), "Not Available") -> 1 | G19: =IFERROR(C19 / B19, "Not Available") -> 1 | H19: =IFERROR(2*((F19*G19)/(F19+G19)),"Not Available") -> 1
A20: Guard | B20: =COUNTIF('Train Automation System'!$A$2:$A$71, A20) -> 14 | C20: =SUMIF('Claude Sonnet 4.5 Gen'!$A$2:$A$71, $A20, 'Claude Sonnet 4.5 Gen'!$C$2:$C$71) -> 8 | D20: =SUMIF('Claude Sonnet 4.5 Gen'!$A$72:$A$78, $A20, 'Claude Sonnet 4.5 Gen'!$C$72:$C$78) -> 0 | E20: =COUNTIFS('Claude Sonnet 4.5 Gen'!$A$2:$A$71, $A20, 'Claude Sonnet 4.5 Gen'!$C$2:$C$71,0) -> 4 | F20: =IFERROR(C20 / (C20 + D20), "Not Available") -> 1 | G20: =IFERROR(C20 / B20, "Not Available") -> 0.57142857 | H20: =IFERROR(2*((F20*G20)/(F20+G20)),"Not Available") -> 0.72727273
A21: Overall Score | B21: =SUM(B14:B20) -> 70 | C21: =SUM(C14:C20) -> 36 | D21: =SUM(D14:D20) -> 0 | E21: =SUM(E14:E20) -> 21 | F21: =IFERROR(C21 / (C21 + D21), "Not Available") -> 1 | G21: =IFERROR(C21 / B21, "Not Available") -> 0.51428571 | H21: =IFERROR(2*((F21*G21)/(F21+G21)),"Not Available") -> 0.67924528

Sheet Inter-rater
A1: Type | B1: Element | C1: GPT-5 | D1: Claude Sonnet 4.5 | F1: Confusion Matrix | L1: Cohen's Kappa
A2: ='GPT-5 Generation'!A2 -> State | B2: ='GPT-5 Generation'!B2 -> Initial state (→ Scheduled) | C2: ='GPT-5 Generation'!C2 -> 0 | D2: ='Claude Sonnet 4.5 Gen'!C2 -> 0 | F2: Global | G2: 0 | H2: 0.5 | I2: 1 | J2: Row Totals | L2: Metric | M2: Value | N2: Note
A3: ='GPT-5 Generation'!A3 -> State | B3: ='GPT-5 Generation'!B3 -> Scheduled | C3: ='GPT-5 Generation'!C3 -> 0 | D3: ='Claude Sonnet 4.5 Gen'!C3 -> 0 | F3: 0 | G3: =COUNTIFS($C$2:$C$115, $F3, $D$2:$D$115, G$2) -> 10 | H3: =COUNTIFS($C$2:$C$71, $F3, $D$2:$D$71, H$2) -> 0 | I3: =COUNTIFS($C$2:$C$71, $F3, $D$2:$D$71, I$2)+MAX(D72-C72,0)+MAX(D73-C73,0)+MAX(D74-C74,0)+MAX(D75-C75,0)+MAX(D76-C76,0)+MAX(D77-C77,0)+MAX(D78-C78,0) -> 0 | J3: =SUM(G3:I3) -> 10 | L3: Observed Agreement (Po) | M3: =(G3+H4+I5)/COUNTA($C$2:$C$125) -> 0.54545455 | N3: This sums the diagonal of your matrix divided by total rows.
A4: ='GPT-5 Generation'!A4 -> Transition | B4: ='GPT-5 Generation'!B4 -> at beginningStopDuration (Scheduled ⇒ Active) | C4: ='GPT-5 Generation'!C4 -> 0.5 | D4: ='Claude Sonnet 4.5 Gen'!C4 -> 0 | F4: 0.5 | G4: =COUNTIFS($C$2:$C$71, $F4, $D$2:$D$71, G$2) -> 1 | H4: =COUNTIFS($C$2:$C$71, $F4, $D$2:$D$71, H$2) -> 2 | I4: =COUNTIFS($C$2:$C$71, $F4, $D$2:$D$71, I$2) -> 1 | J4: =SUM(G4:I4) -> 4 | L4: Expected Agreement (Pe) | M4: {=SUMPRODUCT(J3:J5/COUNTA($C$2:$C$125), TRANSPOSE(G6:I6)/COUNTA($C$2:$C$125))} -> 0.38876708 | N4: This computes the sum of row proportion times column proportion.
A5: ='GPT-5 Generation'!A5 -> Action | B5: ='GPT-5 Generation'!B5 -> pOn; setCS; | C5: ='GPT-5 Generation'!C5 -> 1 | D5: ='Claude Sonnet 4.5 Gen'!C5 -> 0.5 | F5: 1 | G5: =COUNTIFS($C$2:$C$71, $F5, $D$2:$D$71, G$2)+MAX(C72-D72,0)+MAX(C73-D73,0)+MAX(C74-D74,0)+MAX(C75-D75,0)+MAX(C76-D76,0)+MAX(C77-D77,0)+MAX(C78-D78,0) -> 17 | H5: =COUNTIFS($C$2:$C$71, $F5, $D$2:$D$71, H$2) -> 16 | I5: =COUNTIFS($C$2:$C$71, $F5, $D$2:$D$71, I$2)+ SUM(MIN(C72,D72), MIN(C73,D73), MIN(C74,D74), MIN(C75,D75), MIN(C76,D76), MIN(C77,D77), MIN(C78,D78)) -> 30 | J5: =SUM(G5:I5) -> 63 | L5: Cohen's Kappa | M5: =(M3-M4)/(1-M4) -> 0.25634658 | N5: (Po - Pe) / (1 - Pe)
A6: ='GPT-5 Generation'!A6 -> Composite State | B6: ='GPT-5 Generation'!B6 -> Active | C6: ='GPT-5 Generation'!C6 -> 1 | D6: ='Claude Sonnet 4.5 Gen'!C6 -> 1 | F6: Column Totals | G6: =SUM(G3:G5) -> 28 | H6: =SUM(H3:H5) -> 18 | I6: =SUM(I3:I5) -> 31
A7: ='GPT-5 Generation'!A7 -> Region | B7: ='GPT-5 Generation'!B7 -> TrainControl | C7: ='GPT-5 Generation'!C7 -> 0.5 | D7: ='Claude Sonnet 4.5 Gen'!C7 -> 1
A8: ='GPT-5 Generation'!A8 -> Composite State | B8: ='GPT-5 Generation'!B8 -> TrainMovement | C8: ='GPT-5 Generation'!C8 -> 1 | D8: ='Claude Sonnet 4.5 Gen'!C8 -> 1 | F8: Confusion Matrix (State) | L8: Cohen's Kappa (State)
A9: ='GPT-5 Generation'!A9 -> State | B9: ='GPT-5 Generation'!B9 -> Initial state (TrainMovement → AtStation) | C9: ='GPT-5 Generation'!C9 -> 1 | D9: ='Claude Sonnet 4.5 Gen'!C9 -> 0 | F9: State | G9: 0 | H9: 0.5 | I9: 1 | J9: Row Totals | L9: Metric | M9: Value | N9: Note
A10: ='GPT-5 Generation'!A10 -> State | B10: ='GPT-5 Generation'!B10 -> AtStation | C10: ='GPT-5 Generation'!C10 -> 1 | D10: ='Claude Sonnet 4.5 Gen'!C10 -> 0.5 | F10: 0 | G10: =COUNTIFS($A$2:$A$115,$F$9,$C$2:$C$115,$F10,$D$2:$D$115,G$9) -> 4 | H10: =COUNTIFS($A$2:$A$115,$F$9,$C$2:$C$115,$F10,$D$2:$D$115,H$9) -> 0 | I10: =COUNTIFS($A$2:$A$71,$F$9,$C$2:$C$71,$F10,$D$2:$D$71,I$9)+MAX(D72-C72,0) -> 0 | J10: =SUM(G10:I10) -> 4 | L10: Observed Agreement (Po) | M10: =(G10+H11+I12)/COUNTIF($A$2:$A$125,F9) -> 0.55555556 | N10: This sums the diagonal of your matrix divided by total rows.
A11: ='GPT-5 Generation'!A11 -> Action | B11: ='GPT-5 Generation'!B11 -> entry / openDoors() | C11: ='GPT-5 Generation'!C11 -> 1 | D11: ='Claude Sonnet 4.5 Gen'!C11 -> 1 | F11: 0.5 | G11: =COUNTIFS($A$2:$A$115,$F$9,$C$2:$C$115,$F11,$D$2:$D$115,G$9) -> 0 | H11: =COUNTIFS($A$2:$A$115,$F$9,$C$2:$C$115,$F11,$D$2:$D$115,H$9) -> 0 | I11: =COUNTIFS($A$2:$A$115,$F$9,$C$2:$C$115,$F11,$D$2:$D$115,I$9) -> 0 | J11: =SUM(G11:I11) -> 0 | L11: Expected Agreement (Pe) | M11: {=SUMPRODUCT(J10:J12/COUNTIF($A$2:$A$125,F9), TRANSPOSE(G13:I13)/COUNTIF($A$2:$A$125,F9))} -> 0.39506173 | N11: This computes the sum of row proportion times column proportion.
A12: ='GPT-5 Generation'!A12 -> Action | B12: ='GPT-5 Generation'!B12 -> exit / closeDoors() | C12: ='GPT-5 Generation'!C12 -> 1 | D12: ='Claude Sonnet 4.5 Gen'!C12 -> 0.5 | F12: 1 | G12: =COUNTIFS($A$2:$A$71,$F$9,$C$2:$C$71,$F12,$D$2:$D$71,G$9)+MAX(C72-D72,0) -> 7 | H12: =COUNTIFS($A$2:$A$115,$F$9,$C$2:$C$115,$F12,$D$2:$D$115,H$9) -> 1 | I12: =COUNTIFS($A$2:$A$71,$F$9,$C$2:$C$71,$F12,$D$2:$D$71,I$9)+MIN(C72-D72) -> 6 | J12: =SUM(G12:I12) -> 14 | L12: Cohen's Kappa | M12: =(M10-M11)/(1-M11) -> 0.26530612 | N12: (Po - Pe) / (1 - Pe)
A13: ='GPT-5 Generation'!A13 -> Transition | B13: ='GPT-5 Generation'!B13 -> after stopDuration (AtStation ⇒ StopNotRequired) | C13: ='GPT-5 Generation'!C13 -> 1 | D13: ='Claude Sonnet 4.5 Gen'!C13 -> 0.5 | F13: Column Totals | G13: =SUM(G10:G12) -> 11 | H13: =SUM(H10:H12) -> 1 | I13: =SUM(I10:I12) -> 6
A14: ='GPT-5 Generation'!A14 -> Guard | B14: ='GPT-5 Generation'!B14 -> [!isLastStop()] | C14: ='GPT-5 Generation'!C14 -> 1 | D14: ='Claude Sonnet 4.5 Gen'!C14 -> 1
A15: ='GPT-5 Generation'!A15 -> Transition | B15: ='GPT-5 Generation'!B15 -> after stopDuration (AtStation ⇒ Arrived) | C15: ='GPT-5 Generation'!C15 -> 0.5 | D15: ='Claude Sonnet 4.5 Gen'!C15 -> 0.5 | F15: Confusion Matrix (Transition) | L15: Cohen's Kappa (Transition)
A16: ='GPT-5 Generation'!A16 -> Guard | B16: ='GPT-5 Generation'!B16 -> [isLastStop()] | C16: ='GPT-5 Generation'!C16 -> 1 | D16: ='Claude Sonnet 4.5 Gen'!C16 -> 1 | F16: Transition | G16: 0 | H16: 0.5 | I16: 1 | J16: Row Totals | L16: Metric | M16: Value | N16: Note
A17: ='GPT-5 Generation'!A17 -> Action | B17: ='GPT-5 Generation'!B17 -> pOff; | C17: ='GPT-5 Generation'!C17 -> 1 | D17: ='Claude Sonnet 4.5 Gen'!C17 -> 1 | F17: 0 | G17: =COUNTIFS($A$2:$A$115,$F$16,$C$2:$C$115,$F17,$D$2:$D$115,G$16) -> 1 | H17: =COUNTIFS($A$2:$A$115,$F$16,$C$2:$C$115,$F17,$D$2:$D$115,H$16) -> 0 | I17: =COUNTIFS($A$2:$A$71,$F$16,$C$2:$C$71,$F17,$D$2:$D$71,I$16) + MAX(D73-C73,0) -> 0 | J17: =SUM(G17:I17) -> 1 | L17: Observed Agreement (Po) | M17: =(G17+H18+I19)/COUNTIF($A$2:$A$125,F16) -> 0.42857143 | N17: This sums the diagonal of your matrix divided by total rows.
A18: ='GPT-5 Generation'!A18 -> State | B18: ='GPT-5 Generation'!B18 -> StopNotRequired | C18: ='GPT-5 Generation'!C18 -> 1 | D18: ='Claude Sonnet 4.5 Gen'!C18 -> 0 | F18: 0.5 | G18: =COUNTIFS($A$2:$A$115,$F$16,$C$2:$C$115,$F18,$D$2:$D$115,G$16) -> 1 | H18: =COUNTIFS($A$2:$A$115,$F$16,$C$2:$C$115,$F18,$D$2:$D$115,H$16) -> 1 | I18: =COUNTIFS($A$2:$A$115,$F$16,$C$2:$C$115,$F18,$D$2:$D$115,I$16) -> 0 | J18: =SUM(G18:I18) -> 2 | L18: Expected Agreement (Pe) | M18: {=SUMPRODUCT(J17:J19/COUNTIF($A$2:$A$125,F16), TRANSPOSE(G20:I20)/COUNTIF($A$2:$A$125,F16))} -> 0.33106576 | N18: This computes the sum of row proportion times column proportion.
A19: ='GPT-5 Generation'!A19 -> Action | B19: ='GPT-5 Generation'!B19 -> entry / setSpeed() | C19: ='GPT-5 Generation'!C19 -> 1 | D19: ='Claude Sonnet 4.5 Gen'!C19 -> 0.5 | F19: 1 | G19: =COUNTIFS($A$2:$A$71,$F$16,$C$2:$C$71,$F19,$D$2:$D$71,G$16)+MAX(C73-D73,0) -> 6 | H19: =COUNTIFS($A$2:$A$115,$F$16,$C$2:$C$115,$F19,$D$2:$D$115,H$16) -> 5 | I19: =COUNTIFS($A$2:$A$71,$F$16,$C$2:$C$71,$F19,$D$2:$D$71,I$16) + MIN(C73,D73) -> 7 | J19: =SUM(G19:I19) -> 18 | L19: Cohen's Kappa | M19: =(M17-M18)/(1-M18) -> 0.14576271 | N19: (Po - Pe) / (1 - Pe)
A20: ='GPT-5 Generation'!A20 -> Transition | B20: ='GPT-5 Generation'!B20 -> enteringSegment (StopNotRequired ⇒ StopNotRequired) | C20: ='GPT-5 Generation'!C20 -> 1 | D20: ='Claude Sonnet 4.5 Gen'!C20 -> 0.5 | F20: Column Totals | G20: =SUM(G17:G19) -> 8 | H20: =SUM(H17:H19) -> 6 | I20: =SUM(I17:I19) -> 7
A21: ='GPT-5 Generation'!A21 -> Guard | B21: ='GPT-5 Generation'!B21 -> [isRegularSegment()] | C21: ='GPT-5 Generation'!C21 -> 1 | D21: ='Claude Sonnet 4.5 Gen'!C21 -> 1
A22: ='GPT-5 Generation'!A22 -> Transition | B22: ='GPT-5 Generation'!B22 -> enteringSegment (StopNotRequired ⇒ ApproachingRedLight) | C22: ='GPT-5 Generation'!C22 -> 1 | D22: ='Claude Sonnet 4.5 Gen'!C22 -> 0 | F22: Confusion Matrix (Composite State) | L22: Cohen's Kappa (Composite State)
A23: ='GPT-5 Generation'!A23 -> Guard | B23: ='GPT-5 Generation'!B23 -> [isTrafficLightSegment() && isRed()] | C23: ='GPT-5 Generation'!C23 -> 1 | D23: ='Claude Sonnet 4.5 Gen'!C23 -> 1 | F23: Composite State | G23: 0 | H23: 0.5 | I23: 1 | J23: Row Totals | L23: Metric | M23: Value | N23: Note
A24: ='GPT-5 Generation'!A24 -> Transition | B24: ='GPT-5 Generation'!B24 -> enteringSegment (StopNotRequired ⇒ StopNotRequired) | C24: ='GPT-5 Generation'!C24 -> 1 | D24: ='Claude Sonnet 4.5 Gen'!C24 -> 1 | F24: 0 | G24: =COUNTIFS($A$2:$A$115,$F$23,$C$2:$C$115,$F24,$D$2:$D$115,G$23) -> 1 | H24: =COUNTIFS($A$2:$A$115,$F$23,$C$2:$C$115,$F24,$D$2:$D$115,H$23) -> 0 | I24: =COUNTIFS($A$2:$A$71,$F$23,$C$2:$C$71,$F24,$D$2:$D$71,I$23) + MAX(D76-C76,0) -> 0 | J24: =SUM(G24:I24) -> 1 | L24: Observed Agreement (Po) | M24: =(G24+H25+I26)/COUNTIF($A$2:$A$125,F23) -> 1 | N24: This sums the diagonal of your matrix divided by total rows.
A25: ='GPT-5 Generation'!A25 -> Guard | B25: ='GPT-5 Generation'!B25 -> [isTrafficLightSegment() && !isRed()] | C25: ='GPT-5 Generation'!C25 -> 1 | D25: ='Claude Sonnet 4.5 Gen'!C25 -> 1 | F25: 0.5 | G25: =COUNTIFS($A$2:$A$115,$F$23,$C$2:$C$115,$F25,$D$2:$D$115,G$23) -> 0 | H25: =COUNTIFS($A$2:$A$115,$F$23,$C$2:$C$115,$F25,$D$2:$D$115,H$23) -> 0 | I25: =COUNTIFS($A$2:$A$115,$F$23,$C$2:$C$115,$F25,$D$2:$D$115,I$23) -> 0 | J25: =SUM(G25:I25) -> 0 | L25: Expected Agreement (Pe) | M25: {=SUMPRODUCT(J24:J26/COUNTIF($A$2:$A$125,F23), TRANSPOSE(G27:I27)/COUNTIF($A$2:$A$125,F23))} -> 0.55555556 | N25: This computes the sum of row proportion times column proportion.
A26: ='GPT-5 Generation'!A26 -> Transition | B26: ='GPT-5 Generation'!B26 -> enteringSegment (StopNotRequired ⇒ ApproachingStation) | C26: ='GPT-5 Generation'!C26 -> 1 | D26: ='Claude Sonnet 4.5 Gen'!C26 -> 0 | F26: 1 | G26: =COUNTIFS($A$2:$A$71,$F$23,$C$2:$C$71,$F26,$D$2:$D$71,G$23) + MAX(C76-D76,0) -> 0 | H26: =COUNTIFS($A$2:$A$115,$F$23,$C$2:$C$115,$F26,$D$2:$D$115,H$23) -> 0 | I26: =COUNTIFS($A$2:$A$71,$F$23,$C$2:$C$71,$F26,$D$2:$D$71,I$23) + MIN(C76,D76) -> 2 | J26: =SUM(G26:I26) -> 2 | L26: Cohen's Kappa | M26: =(M24-M25)/(1-M25) -> 1 | N26: (Po - Pe) / (1 - Pe)
A27: ='GPT-5 Generation'!A27 -> Guard | B27: ='GPT-5 Generation'!B27 -> [isStationSegment() && stopRequired()] | C27: ='GPT-5 Generation'!C27 -> 1 | D27: ='Claude Sonnet 4.5 Gen'!C27 -> 1 | F27: Column Totals | G27: =SUM(G24:G26) -> 1 | H27: =SUM(H24:H26) -> 0 | I27: =SUM(I24:I26) -> 2
A28: ='GPT-5 Generation'!A28 -> State | B28: ='GPT-5 Generation'!B28 -> ApproachingRedLight | C28: ='GPT-5 Generation'!C28 -> 1 | D28: ='Claude Sonnet 4.5 Gen'!C28 -> 0
A29: ='GPT-5 Generation'!A29 -> Action | B29: ='GPT-5 Generation'!B29 -> entry / stopAL | C29: ='GPT-5 Generation'!C29 -> 1 | D29: ='Claude Sonnet 4.5 Gen'!C29 -> 1 | F29: Confusion Matrix (Guard) | L29: Cohen's Kappa (Guard)
A30: ='GPT-5 Generation'!A30 -> Transition | B30: ='GPT-5 Generation'!B30 -> stopped (ApproachingRedLight ⇒ AtRedTrafficLight) | C30: ='GPT-5 Generation'!C30 -> 1 | D30: ='Claude Sonnet 4.5 Gen'!C30 -> 0 | F30: Guard | G30: 0 | H30: 0.5 | I30: 1 | J30: Row Totals | L30: Metric | M30: Value | N30: Note
A31: ='GPT-5 Generation'!A31 -> State | B31: ='GPT-5 Generation'!B31 -> AtRedTrafficLight | C31: ='GPT-5 Generation'!C31 -> 1 | D31: ='Claude Sonnet 4.5 Gen'!C31 -> 1 | F31: 0 | G31: =COUNTIFS($A$2:$A$115,$F$30,$C$2:$C$115,$F31,$D$2:$D$115,G$30) -> 1 | H31: =COUNTIFS($A$2:$A$115,$F$30,$C$2:$C$115,$F31,$D$2:$D$115,H$30) -> 0 | I31: =COUNTIFS($A$2:$A$71,$F$30,$C$2:$C$71,$F31,$D$2:$D$71,I$30) + MAX(D74-C74,0) -> 0 | J31: =SUM(G31:I31) -> 1 | L31: Observed Agreement (Po) | M31: =(G31+H32+I33)/COUNTIF($A$2:$A$125,F30) -> 0.46666667 | N31: This sums the diagonal of your matrix divided by total rows.
A32: ='GPT-5 Generation'!A32 -> Transition | B32: ='GPT-5 Generation'!B32 -> green (AtRedTrafficLight ⇒ StopNotRequired) | C32: ='GPT-5 Generation'!C32 -> 1 | D32: ='Claude Sonnet 4.5 Gen'!C32 -> 0.5 | F32: 0.5 | G32: =COUNTIFS($A$2:$A$115,$F$30,$C$2:$C$115,$F32,$D$2:$D$115,G$30) -> 0 | H32: =COUNTIFS($A$2:$A$115,$F$30,$C$2:$C$115,$F32,$D$2:$D$115,H$30) -> 0 | I32: =COUNTIFS($A$2:$A$115,$F$30,$C$2:$C$115,$F32,$D$2:$D$115,I$30) -> 0 | J32: =SUM(G32:I32) -> 0 | L32: Expected Agreement (Pe) | M32: {=SUMPRODUCT(J31:J33/COUNTIF($A$2:$A$125,F30), TRANSPOSE(G34:I34)/COUNTIF($A$2:$A$125,F30))} -> 0.39555556 | N32: This computes the sum of row proportion times column proportion.
A33: ='GPT-5 Generation'!A33 -> State | B33: ='GPT-5 Generation'!B33 -> ApproachingStation | C33: ='GPT-5 Generation'!C33 -> 1 | D33: ='Claude Sonnet 4.5 Gen'!C33 -> 0 | F33: 1 | G33: =COUNTIFS($A$2:$A$71,$F$30,$C$2:$C$71,$F33,$D$2:$D$71,G$30) + MAX(C74-D74,0) -> 4 | H33: =COUNTIFS($A$2:$A$115,$F$30,$C$2:$C$115,$F33,$D$2:$D$115,H$30) -> 4 | I33: =COUNTIFS($A$2:$A$71,$F$30,$C$2:$C$71,$F33,$D$2:$D$71,I$30) + MIN(C74,D74) -> 6 | J33: =SUM(G33:I33) -> 14 | L33: Cohen's Kappa | M33: =(M31-M32)/(1-M32) -> 0.11764706 | N33: (Po - Pe) / (1 - Pe)
A34: ='GPT-5 Generation'!A34 -> Action | B34: ='GPT-5 Generation'!B34 -> entry / stopAL | C34: ='GPT-5 Generation'!C34 -> 1 | D34: ='Claude Sonnet 4.5 Gen'!C34 -> 1 | F34: Column Totals | G34: =SUM(G31:G33) -> 5 | H34: =SUM(H31:H33) -> 4 | I34: =SUM(I31:I33) -> 6
A35: ='GPT-5 Generation'!A35 -> Transition | B35: ='GPT-5 Generation'!B35 -> stopped (ApproachingStation ⇒ AtStation) | C35: ='GPT-5 Generation'!C35 -> 1 | D35: ='Claude Sonnet 4.5 Gen'!C35 -> 0
A36: ='GPT-5 Generation'!A36 -> History State | B36: ='GPT-5 Generation'!B36 -> History State for TrainMovement | C36: ='GPT-5 Generation'!C36 -> 1 | D36: ='Claude Sonnet 4.5 Gen'!C36 -> 1 | F36: Confusion Matrix (Action) | L36: Cohen's Kappa (Action)
A37: ='GPT-5 Generation'!A37 -> State | B37: ='GPT-5 Generation'!B37 -> Emergency | C37: ='GPT-5 Generation'!C37 -> 1 | D37: ='Claude Sonnet 4.5 Gen'!C37 -> 1 | F37: Action | G37: 0 | H37: 0.5 | I37: 1 | J37: Row Totals | L37: Metric | M37: Value | N37: Note
A38: ='GPT-5 Generation'!A38 -> Transition | B38: ='GPT-5 Generation'!B38 -> emergency (TrainMovement ⇒ Emergency) | C38: ='GPT-5 Generation'!C38 -> 1 | D38: ='Claude Sonnet 4.5 Gen'!C38 -> 1 | F38: 0 | G38: =COUNTIFS($A$2:$A$115,F37,$C$2:$C$115,$F38,$D$2:$D$115,G37) -> 1 | H38: =COUNTIFS($A$2:$A$115,F37,$C$2:$C$115,$F38,$D$2:$D$115,H37) -> 0 | I38: =COUNTIFS($A$2:$A$71,F37,$C$2:$C$71,$F38,$D$2:$D$71,I37)+MAX(D75-C75,0) -> 0 | J38: =SUM(G38:I38) -> 1 | L38: Observed Agreement (Po) | M38: =(G38+H39+I40)/COUNTIF($A$2:$A$125,F37) -> 0.46153846 | N38: This sums the diagonal of your matrix divided by total rows.
A39: ='GPT-5 Generation'!A39 -> Action | B39: ='GPT-5 Generation'!B39 -> eStop; | C39: ='GPT-5 Generation'!C39 -> 1 | D39: ='Claude Sonnet 4.5 Gen'!C39 -> 1 | F39: 0.5 | G39: =COUNTIFS($A$2:$A$115,F37,$C$2:$C$115,$F39,$D$2:$D$115,G37) -> 0 | H39: =COUNTIFS($A$2:$A$115,F37,$C$2:$C$115,$F38,$D$2:$D$115,H37) -> 0 | I39: =COUNTIFS($A$2:$A$115,F37,$C$2:$C$115,$F39,$D$2:$D$115,I37) -> 0 | J39: =SUM(G39:I39) -> 0 | L39: Expected Agreement (Pe) | M39: {=SUMPRODUCT(J38:J40/COUNTIF($A$2:$A$125,F37), TRANSPOSE(G41:I41)/COUNTIF($A$2:$A$125,F37))} -> 0.33136095 | N39: This computes the sum of row proportion times column proportion.
A40: ='GPT-5 Generation'!A40 -> Transition | B40: ='GPT-5 Generation'!B40 -> clear (Emergency ⇒ History State) | C40: ='GPT-5 Generation'!C40 -> 1 | D40: ='Claude Sonnet 4.5 Gen'!C40 -> 1 | F40: 1 | G40: =COUNTIFS($A$2:$A$71,F37,$C$2:$C$71,$F40,$D$2:$D$71,G37)+MAX(C75-D75,0) -> 0 | H40: =COUNTIFS($A$2:$A$115,F37,$C$2:$C$115,$F40,$D$2:$D$115,H37) -> 6 | I40: =COUNTIFS($A$2:$A$71,F37,$C$2:$C$71,$F40,$D$2:$D$71,I37) + MIN(C75,D75) -> 5 | J40: =SUM(G40:I40) -> 11 | L40: Cohen's Kappa | M40: =(M38-M39)/(1-M39) -> 0.19469027 | N40: (Po - Pe) / (1 - Pe)
...

Sheet Weighted Cohens Kappa
A1: Type | B1: Element | C1: GPT-5 | D1: Claude Sonnet 4.5 | F1: Confusion Matrix | L1: Weight Matrix
A2: ='GPT-5 Generation'!A2 -> State | B2: ='GPT-5 Generation'!B2 -> Initial state (→ Scheduled) | C2: ='GPT-5 Generation'!C2 -> 0 | D2: ='Claude Sonnet 4.5 Gen'!C2 -> 0 | F2: Global | G2: 0 | H2: 0.5 | I2: 1 | J2: Row Totals | L2: Global | M2: 0 | N2: 0.5 | O2: 1 | Q2: Global | R2: 0 | S2: 0.5 | T2: 1 | V2: ="Metrics" & " " & F2 -> Metrics Global | W2: Value | X2: Note
A3: ='GPT-5 Generation'!A3 -> State | B3: ='GPT-5 Generation'!B3 -> Scheduled | C3: ='GPT-5 Generation'!C3 -> 0 | D3: ='Claude Sonnet 4.5 Gen'!C3 -> 0 | F3: 0 | G3: =COUNTIFS($C$2:$C$115, $F3, $D$2:$D$115, G$2) -> 10 | H3: =COUNTIFS($C$2:$C$71, $F3, $D$2:$D$71, H$2) -> 0 | I3: =COUNTIFS($C$2:$C$71, $F3, $D$2:$D$71, I$2)+MAX(D72-C72,0)+MAX(D73-C73,0)+MAX(D74-C74,0)+MAX(D75-C75,0)+MAX(D76-C76,0)+MAX(D77-C77,0)+MAX(D78-C78,0) -> 0 | J3: =SUM(G3:I3) -> 10 | L3: 0 | M3: =ABS(G$2-$F3)/1 -> 0 | N3: =ABS(H$2-$F3)/1 -> 0.5 | O3: =ABS(I$2-$F3)/1 -> 1 | Q3: 0 | R3: =($J3/$J$6) * (G$6/$J$6) -> 0.047225502 | S3: =($J3/$J$6) * (H$6/$J$6) -> 0.030359251 | T3: =($J3/$J$6) * (I$6/$J$6) -> 0.052285377 | V3: Observed Weighted Disagreement (D_obs) | W3: =SUMPRODUCT(G3:I5, M3:O5) /$J$6 -> 0.33766234 | X3: Sum of (confusion-matrix counts × weights) divided by total items.
A4: ='GPT-5 Generation'!A4 -> Transition | B4: ='GPT-5 Generation'!B4 -> at beginningStopDuration (Scheduled ⇒ Active) | C4: ='GPT-5 Generation'!C4 -> 0.5 | D4: ='Claude Sonnet 4.5 Gen'!C4 -> 0 | F4: 0.5 | G4: =COUNTIFS($C$2:$C$71, $F4, $D$2:$D$71, G$2) -> 1 | H4: =COUNTIFS($C$2:$C$71, $F4, $D$2:$D$71, H$2) -> 2 | I4: =COUNTIFS($C$2:$C$71, $F4, $D$2:$D$71, I$2) -> 1 | J4: =SUM(G4:I4) -> 4 | L4: 0.5 | M4: =ABS(G$2-$F4)/1 -> 0.5 | N4: =ABS(H$2-$F4)/3 -> 0 | O4: =ABS(I$2-$F4)/1 -> 0.5 | Q4: 0.5 | R4: =($J4/$J$6) * (G$6/$J$6) -> 0.018890201 | S4: =($J4/$J$6) * (H$6/$J$6) -> 0.0121437 | T4: =($J4/$J$6) * (I$6/$J$6) -> 0.020914151 | V4: Expected Weighted Disagreement (D_exp) | W4: =SUMPRODUCT(R3:T5, M3:O5) -> 0.48051948 | X4: Sum of (expected cell proportions × weights) under chance agreement.
A5: ='GPT-5 Generation'!A5 -> Action | B5: ='GPT-5 Generation'!B5 -> pOn; setCS; | C5: ='GPT-5 Generation'!C5 -> 1 | D5: ='Claude Sonnet 4.5 Gen'!C5 -> 0.5 | F5: 1 | G5: =COUNTIFS($C$2:$C$71, $F5, $D$2:$D$71, G$2)+MAX(C72-D72,0)+MAX(C73-D73,0)+MAX(C74-D74,0)+MAX(C75-D75,0)+MAX(C76-D76,0)+MAX(C77-D77,0)+MAX(C78-D78,0) -> 17 | H5: =COUNTIFS($C$2:$C$71, $F5, $D$2:$D$71, H$2) -> 16 | I5: =COUNTIFS($C$2:$C$71, $F5, $D$2:$D$71, I$2)+ SUM(MIN(C72,D72), MIN(C73,D73), MIN(C74,D74), MIN(C75,D75), MIN(C76,D76), MIN(C77,D77), MIN(C78,D78)) -> 30 | J5: =SUM(G5:I5) -> 63 | L5: 1 | M5: =ABS(G$2-$F5)/1 -> 1 | N5: =ABS(H$2-$F5)/1 -> 0.5 | O5: =ABS(I$2-$F5)/1 -> 0 | Q5: 1 | R5: =($J5/$J$6) * (G$6/$J$6) -> 0.29752066 | S5: =($J5/$J$6) * (H$6/$J$6) -> 0.19126328 | T5: =($J5/$J$6) * (I$6/$J$6) -> 0.32939787 | V5: Cohen's Kappa | W5: =1-W3/W4 -> 0.2972973 | X5: 1 - (D_obs / D_exp)
A6: ='GPT-5 Generation'!A6 -> Composite State | B6: ='GPT-5 Generation'!B6 -> Active | C6: ='GPT-5 Generation'!C6 -> 1 | D6: ='Claude Sonnet 4.5 Gen'!C6 -> 1 | F6: Column Totals | G6: =SUM(G3:G5) -> 28 | H6: =SUM(H3:H5) -> 18 | I6: =SUM(I3:I5) -> 31 | J6: =SUM(G3:I5) -> 77
A7: ='GPT-5 Generation'!A7 -> Region | B7: ='GPT-5 Generation'!B7 -> TrainControl | C7: ='GPT-5 Generation'!C7 -> 0.5 | D7: ='Claude Sonnet 4.5 Gen'!C7 -> 1
A8: ='GPT-5 Generation'!A8 -> Composite State | B8: ='GPT-5 Generation'!B8 -> TrainMovement | C8: ='GPT-5 Generation'!C8 -> 1 | D8: ='Claude Sonnet 4.5 Gen'!C8 -> 1 | F8: Confusion Matrix (State)
A9: ='GPT-5 Generation'!A9 -> State | B9: ='GPT-5 Generation'!B9 -> Initial state (TrainMovement → AtStation) | C9: ='GPT-5 Generation'!C9 -> 1 | D9: ='Claude Sonnet 4.5 Gen'!C9 -> 0 | F9: State | G9: 0 | H9: 0.5 | I9: 1 | J9: Row Totals | L9: Global | M9: 0 | N9: 0.5 | O9: 1 | Q9: Global | R9: 0 | S9: 0.5 | T9: 1 | V9: ="Metrics" & " " & F9 -> Metrics State | W9: Value | X9: Note
A10: ='GPT-5 Generation'!A10 -> State | B10: ='GPT-5 Generation'!B10 -> AtStation | C10: ='GPT-5 Generation'!C10 -> 1 | D10: ='Claude Sonnet 4.5 Gen'!C10 -> 0.5 | F10: 0 | G10: =COUNTIFS($A$2:$A$115,$F$9,$C$2:$C$115,$F10,$D$2:$D$115,G$9) -> 4 | H10: =COUNTIFS($A$2:$A$115,$F$9,$C$2:$C$115,$F10,$D$2:$D$115,H$9) -> 0 | I10: =COUNTIFS($A$2:$A$71,$F$9,$C$2:$C$71,$F10,$D$2:$D$71,I$9)+MAX(D72-C72,0) -> 0 | J10: =SUM(G10:I10) -> 4 | L10: 0 | M10: =ABS(G$2-$F10)/1 -> 0 | N10: =ABS(H$2-$F10)/1 -> 0.5 | O10: =ABS(I$2-$F10)/1 -> 1 | Q10: 0 | R10: =($J10/$J$13) * (G$13/$J$13) -> 0.13580247 | S10: =($J10/$J$13) * (H$13/$J$13) -> 0.012345679 | T10: =($J10/$J$13) * (I$13/$J$13) -> 0.074074074 | V10: Observed Weighted Disagreement (D_obs) | W10: =SUMPRODUCT(G10:I12, M10:O12) /$J$13 -> 0.41666667 | X10: Sum of (confusion-matrix counts × weights) divided by total items.
A11: ='GPT-5 Generation'!A11 -> Action | B11: ='GPT-5 Generation'!B11 -> entry / openDoors() | C11: ='GPT-5 Generation'!C11 -> 1 | D11: ='Claude Sonnet 4.5 Gen'!C11 -> 1 | F11: 0.5 | G11: =COUNTIFS($A$2:$A$115,$F$9,$C$2:$C$115,$F11,$D$2:$D$115,G$9) -> 0 | H11: =COUNTIFS($A$2:$A$115,$F$9,$C$2:$C$115,$F11,$D$2:$D$115,H$9) -> 0 | I11: =COUNTIFS($A$2:$A$115,$F$9,$C$2:$C$115,$F11,$D$2:$D$115,I$9) -> 0 | J11: =SUM(G11:I11) -> 0 | L11: 0.5 | M11: =ABS(G$2-$F11)/1 -> 0.5 | N11: =ABS(H$2-$F11)/3 -> 0 | O11: =ABS(I$2-$F11)/1 -> 0.5 | Q11: 0.5 | R11: =($J11/$J$13) * (G$13/$J$13) -> 0 | S11: =($J11/$J$13) * (H$13/$J$13) -> 0 | T11: =($J11/$J$13) * (I$13/$J$13) -> 0 | V11: Expected Weighted Disagreement (D_exp) | W11: =SUMPRODUCT(R10:T12, M10:O12) -> 0.57716049 | X11: Sum of (expected cell proportions × weights) under chance agreement.
A12: ='GPT-5 Generation'!A12 -> Action | B12: ='GPT-5 Generation'!B12 -> exit / closeDoors() | C12: ='GPT-5 Generation'!C12 -> 1 | D12: ='Claude Sonnet 4.5 Gen'!C12 -> 0.5 | F12: 1 | G12: =COUNTIFS($A$2:$A$71,$F$9,$C$2:$C$71,$F12,$D$2:$D$71,G$9)+MAX(C72-D72,0) -> 7 | H12: =COUNTIFS($A$2:$A$115,$F$9,$C$2:$C$115,$F12,$D$2:$D$115,H$9) -> 1 | I12: =COUNTIFS($A$2:$A$71,$F$9,$C$2:$C$71,$F12,$D$2:$D$71,I$9)+MIN(C72-D72) -> 6 | J12: =SUM(G12:I12) -> 14 | L12: 1 | M12: =ABS(G$2-$F12)/1 -> 1 | N12: =ABS(H$2-$F12)/1 -> 0.5 | O12: =ABS(I$2-$F12)/1 -> 0 | Q12: 1 | R12: =($J12/$J$13) * (G$13/$J$13) -> 0.47530864 | S12: =($J12/$J$13) * (H$13/$J$13) -> 0.043209877 | T12: =($J12/$J$13) * (I$13/$J$13) -> 0.25925926 | V12: Cohen's Kappa | W12: =1-W10/W11 -> 0.27807487 | X12: 1 - (D_obs / D_exp)
A13: ='GPT-5 Generation'!A13 -> Transition | B13: ='GPT-5 Generation'!B13 -> after stopDuration (AtStation ⇒ StopNotRequired) | C13: ='GPT-5 Generation'!C13 -> 1 | D13: ='Claude Sonnet 4.5 Gen'!C13 -> 0.5 | F13: Column Totals | G13: =SUM(G10:G12) -> 11 | H13: =SUM(H10:H12) -> 1 | I13: =SUM(I10:I12) -> 6 | J13: =SUM(G10:I12) -> 18
A14: ='GPT-5 Generation'!A14 -> Guard | B14: ='GPT-5 Generation'!B14 -> [!isLastStop()] | C14: ='GPT-5 Generation'!C14 -> 1 | D14: ='Claude Sonnet 4.5 Gen'!C14 -> 1
A15: ='GPT-5 Generation'!A15 -> Transition | B15: ='GPT-5 Generation'!B15 -> after stopDuration (AtStation ⇒ Arrived) | C15: ='GPT-5 Generation'!C15 -> 0.5 | D15: ='Claude Sonnet 4.5 Gen'!C15 -> 0.5 | F15: Confusion Matrix (Transition)
A16: ='GPT-5 Generation'!A16 -> Guard | B16: ='GPT-5 Generation'!B16 -> [isLastStop()] | C16: ='GPT-5 Generation'!C16 -> 1 | D16: ='Claude Sonnet 4.5 Gen'!C16 -> 1 | F16: Transition | G16: 0 | H16: 0.5 | I16: 1 | J16: Row Totals | L16: Global | M16: 0 | N16: 0.5 | O16: 1 | Q16: Global | R16: 0 | S16: 0.5 | T16: 1 | V16: ="Metrics" & " " & F16 -> Metrics Transition | W16: Value | X16: Note
A17: ='GPT-5 Generation'!A17 -> Action | B17: ='GPT-5 Generation'!B17 -> pOff; | C17: ='GPT-5 Generation'!C17 -> 1 | D17: ='Claude Sonnet 4.5 Gen'!C17 -> 1 | F17: 0 | G17: =COUNTIFS($A$2:$A$115,$F$16,$C$2:$C$115,$F17,$D$2:$D$115,G$16) -> 1 | H17: =COUNTIFS($A$2:$A$115,$F$16,$C$2:$C$115,$F17,$D$2:$D$115,H$16) -> 0 | I17: =COUNTIFS($A$2:$A$71,$F$16,$C$2:$C$71,$F17,$D$2:$D$71,I$16) + MAX(D73-C73,0) -> 0 | J17: =SUM(G17:I17) -> 1 | L17: 0 | M17: =ABS(G$2-$F17)/1 -> 0 | N17: =ABS(H$2-$F17)/1 -> 0.5 | O17: =ABS(I$2-$F17)/1 -> 1 | Q17: 0 | R17: =($J17/$J$20) * (G$20/$J$20) -> 0.01814059 | S17: =($J17/$J$20) * (H$20/$J$20) -> 0.013605442 | T17: =($J17/$J$20) * (I$20/$J$20) -> 0.015873016 | V17: Observed Weighted Disagreement (D_obs) | W17: =SUMPRODUCT(G17:I19, M17:O19) /$J$20 -> 0.42857143 | X17: Sum of (confusion-matrix counts × weights) divided by total items.
A18: ='GPT-5 Generation'!A18 -> State | B18: ='GPT-5 Generation'!B18 -> StopNotRequired | C18: ='GPT-5 Generation'!C18 -> 1 | D18: ='Claude Sonnet 4.5 Gen'!C18 -> 0 | F18: 0.5 | G18: =COUNTIFS($A$2:$A$115,$F$16,$C$2:$C$115,$F18,$D$2:$D$115,G$16) -> 1 | H18: =COUNTIFS($A$2:$A$115,$F$16,$C$2:$C$115,$F18,$D$2:$D$115,H$16) -> 1 | I18: =COUNTIFS($A$2:$A$115,$F$16,$C$2:$C$115,$F18,$D$2:$D$115,I$16) -> 0 | J18: =SUM(G18:I18) -> 2 | L18: 0.5 | M18: =ABS(G$2-$F18)/1 -> 0.5 | N18: =ABS(H$2-$F18)/3 -> 0 | O18: =ABS(I$2-$F18)/1 -> 0.5 | Q18: 0.5 | R18: =($J18/$J$20) * (G$20/$J$20) -> 0.036281179 | S18: =($J18/$J$20) * (H$20/$J$20) -> 0.027210884 | T18: =($J18/$J$20) * (I$20/$J$20) -> 0.031746032 | V18: Expected Weighted Disagreement (D_exp) | W18: =SUMPRODUCT(R17:T19, M17:O19) -> 0.50566893 | X18: Sum of (expected cell proportions × weights) under chance agreement.
A19: ='GPT-5 Generation'!A19 -> Action | B19: ='GPT-5 Generation'!B19 -> entry / setSpeed() | C19: ='GPT-5 Generation'!C19 -> 1 | D19: ='Claude Sonnet 4.5 Gen'!C19 -> 0.5 | F19: 1 | G19: =COUNTIFS($A$2:$A$71,$F$16,$C$2:$C$71,$F19,$D$2:$D$71,G$16)+MAX(C73-D73,0) -> 6 | H19: =COUNTIFS($A$2:$A$115,$F$16,$C$2:$C$115,$F19,$D$2:$D$115,H$16) -> 5 | I19: =COUNTIFS($A$2:$A$71,$F$16,$C$2:$C$71,$F19,$D$2:$D$71,I$16) + MIN(C73,D73) -> 7 | J19: =SUM(G19:I19) -> 18 | L19: 1 | M19: =ABS(G$2-$F19)/1 -> 1 | N19: =ABS(H$2-$F19)/1 -> 0.5 | O19: =ABS(I$2-$F19)/1 -> 0 | Q19: 1 | R19: =($J19/$J$20) * (G$20/$J$20) -> 0.32653061 | S19: =($J19/$J$20) * (H$20/$J$20) -> 0.24489796 | T19: =($J19/$J$20) * (I$20/$J$20) -> 0.28571429 | V19: Cohen's Kappa | W19: =1-W17/W18 -> 0.15246637 | X19: 1 - (D_obs / D_exp)
A20: ='GPT-5 Generation'!A20 -> Transition | B20: ='GPT-5 Generation'!B20 -> enteringSegment (StopNotRequired ⇒ StopNotRequired) | C20: ='GPT-5 Generation'!C20 -> 1 | D20: ='Claude Sonnet 4.5 Gen'!C20 -> 0.5 | F20: Column Totals | G20: =SUM(G17:G19) -> 8 | H20: =SUM(H17:H19) -> 6 | I20: =SUM(I17:I19) -> 7 | J20: =SUM(G17:I19) -> 21
A21: ='GPT-5 Generation'!A21 -> Guard | B21: ='GPT-5 Generation'!B21 -> [isRegularSegment()] | C21: ='GPT-5 Generation'!C21 -> 1 | D21: ='Claude Sonnet 4.5 Gen'!C21 -> 1
A22: ='GPT-5 Generation'!A22 -> Transition | B22: ='GPT-5 Generation'!B22 -> enteringSegment (StopNotRequired ⇒ ApproachingRedLight) | C22: ='GPT-5 Generation'!C22 -> 1 | D22: ='Claude Sonnet 4.5 Gen'!C22 -> 0 | F22: Confusion Matrix (Composite State)
A23: ='GPT-5 Generation'!A23 -> Guard | B23: ='GPT-5 Generation'!B23 -> [isTrafficLightSegment() && isRed()] | C23: ='GPT-5 Generation'!C23 -> 1 | D23: ='Claude Sonnet 4.5 Gen'!C23 -> 1 | F23: Composite State | G23: 0 | H23: 0.5 | I23: 1 | J23: Row Totals | L23: Global | M23: 0 | N23: 0.5 | O23: 1 | Q23: Global | R23: 0 | S23: 0.5 | T23: 1 | V23: ="Metrics" & " " & F23 -> Metrics Composite State | W23: Value | X23: Note
A24: ='GPT-5 Generation'!A24 -> Transition | B24: ='GPT-5 Generation'!B24 -> enteringSegment (StopNotRequired ⇒ StopNotRequired) | C24: ='GPT-5 Generation'!C24 -> 1 | D24: ='Claude Sonnet 4.5 Gen'!C24 -> 1 | F24: 0 | G24: =COUNTIFS($A$2:$A$115,$F$23,$C$2:$C$115,$F24,$D$2:$D$115,G$23) -> 1 | H24: =COUNTIFS($A$2:$A$115,$F$23,$C$2:$C$115,$F24,$D$2:$D$115,H$23) -> 0 | I24: =COUNTIFS($A$2:$A$71,$F$23,$C$2:$C$71,$F24,$D$2:$D$71,I$23) + MAX(D76-C76,0) -> 0 | J24: =SUM(G24:I24) -> 1 | L24: 0 | M24: =ABS(G$2-$F24)/1 -> 0 | N24: =ABS(H$2-$F24)/1 -> 0.5 | O24: =ABS(I$2-$F24)/1 -> 1 | Q24: 0 | R24: =($J24/$J$27) * (G$27/$J$27) -> 0.11111111 | S24: =($J24/$J$27) * (H$27/$J$27) -> 0 | T24: =($J24/$J$27) * (I$27/$J$27) -> 0.22222222 | V24: Observed Weighted Disagreement (D_obs) | W24: =SUMPRODUCT(G24:I26, M24:O26) /$J$27 -> 0 | X24: Sum of (confusion-matrix counts × weights) divided by total items.
A25: ='GPT-5 Generation'!A25 -> Guard | B25: ='GPT-5 Generation'!B25 -> [isTrafficLightSegment() && !isRed()] | C25: ='GPT-5 Generation'!C25 -> 1 | D25: ='Claude Sonnet 4.5 Gen'!C25 -> 1 | F25: 0.5 | G25: =COUNTIFS($A$2:$A$115,$F$23,$C$2:$C$115,$F25,$D$2:$D$115,G$23) -> 0 | H25: =COUNTIFS($A$2:$A$115,$F$23,$C$2:$C$115,$F25,$D$2:$D$115,H$23) -> 0 | I25: =COUNTIFS($A$2:$A$115,$F$23,$C$2:$C$115,$F25,$D$2:$D$115,I$23) -> 0 | J25: =SUM(G25:I25) -> 0 | L25: 0.5 | M25: =ABS(G$2-$F25)/1 -> 0.5 | N25: =ABS(H$2-$F25)/3 -> 0 | O25: =ABS(I$2-$F25)/1 -> 0.5 | Q25: 0.5 | R25: =($J25/$J$27) * (G$27/$J$27) -> 0 | S25: =($J25/$J$27) * (H$27/$J$27) -> 0 | T25: =($J25/$J$27) * (I$27/$J$27) -> 0 | V25: Expected Weighted Disagreement (D_exp) | W25: =SUMPRODUCT(R24:T26, M24:O26) -> 0.44444444 | X25: Sum of (expected cell proportions × weights) under chance agreement.
A26: ='GPT-5 Generation'!A26 -> Transition | B26: ='GPT-5 Generation'!B26 -> enteringSegment (StopNotRequired ⇒ ApproachingStation) | C26: ='GPT-5 Generation'!C26 -> 1 | D26: ='Claude Sonnet 4.5 Gen'!C26 -> 0 | F26: 1 | G26: =COUNTIFS($A$2:$A$71,$F$23,$C$2:$C$71,$F26,$D$2:$D$71,G$23) + MAX(C76-D76,0) -> 0 | H26: =COUNTIFS($A$2:$A$115,$F$23,$C$2:$C$115,$F26,$D$2:$D$115,H$23) -> 0 | I26: =COUNTIFS($A$2:$A$71,$F$23,$C$2:$C$71,$F26,$D$2:$D$71,I$23) + MIN(C76,D76) -> 2 | J26: =SUM(G26:I26) -> 2 | L26: 1 | M26: =ABS(G$2-$F26)/1 -> 1 | N26: =ABS(H$2-$F26)/1 -> 0.5 | O26: =ABS(I$2-$F26)/1 -> 0 | Q26: 1 | R26: =($J26/$J$27) * (G$27/$J$27) -> 0.22222222 | S26: =($J26/$J$27) * (H$27/$J$27) -> 0 | T26: =($J26/$J$27) * (I$27/$J$27) -> 0.44444444 | V26: Cohen's Kappa | W26: =1-W24/W25 -> 1 | X26: 1 - (D_obs / D_exp)
A27: ='GPT-5 Generation'!A27 -> Guard | B27: ='GPT-5 Generation'!B27 -> [isStationSegment() && stopRequired()] | C27: ='GPT-5 Generation'!C27 -> 1 | D27: ='Claude Sonnet 4.5 Gen'!C27 -> 1 | F27: Column Totals | G27: =SUM(G24:G26) -> 1 | H27: =SUM(H24:H26) -> 0 | I27: =SUM(I24:I26) -> 2 | J27: =SUM(G24:I26) -> 3
A28: ='GPT-5 Generation'!A28 -> State | B28: ='GPT-5 Generation'!B28 -> ApproachingRedLight | C28: ='GPT-5 Generation'!C28 -> 1 | D28: ='Claude Sonnet 4.5 Gen'!C28 -> 0
A29: ='GPT-5 Generation'!A29 -> Action | B29: ='GPT-5 Generation'!B29 -> entry / stopAL | C29: ='GPT-5 Generation'!C29 -> 1 | D29: ='Claude Sonnet 4.5 Gen'!C29 -> 1 | F29: Confusion Matrix (Guard)
A30: ='GPT-5 Generation'!A30 -> Transition | B30: ='GPT-5 Generation'!B30 -> stopped (ApproachingRedLight ⇒ AtRedTrafficLight) | C30: ='GPT-5 Generation'!C30 -> 1 | D30: ='Claude Sonnet 4.5 Gen'!C30 -> 0 | F30: Guard | G30: 0 | H30: 0.5 | I30: 1 | J30: Row Totals | L30: Global | M30: 0 | N30: 0.5 | O30: 1 | Q30: Global | R30: 0 | S30: 0.5 | T30: 1 | V30: ="Metrics" & " " & F30 -> Metrics Guard | W30: Value | X30: Note
A31: ='GPT-5 Generation'!A31 -> State | B31: ='GPT-5 Generation'!B31 -> AtRedTrafficLight | C31: ='GPT-5 Generation'!C31 -> 1 | D31: ='Claude Sonnet 4.5 Gen'!C31 -> 1 | F31: 0 | G31: =COUNTIFS($A$2:$A$115,$F$30,$C$2:$C$115,$F31,$D$2:$D$115,G$30) -> 1 | H31: =COUNTIFS($A$2:$A$115,$F$30,$C$2:$C$115,$F31,$D$2:$D$115,H$30) -> 0 | I31: =COUNTIFS($A$2:$A$71,$F$30,$C$2:$C$71,$F31,$D$2:$D$71,I$30) + MAX(D74-C74,0) -> 0 | J31: =SUM(G31:I31) -> 1 | L31: 0 | M31: =ABS(G$2-$F31)/1 -> 0 | N31: =ABS(H$2-$F31)/1 -> 0.5 | O31: =ABS(I$2-$F31)/1 -> 1 | Q31: 0 | R31: =($J31/$J$34) * (G$34/$J$34) -> 0.022222222 | S31: =($J31/$J$34) * (H$34/$J$34) -> 0.017777778 | T31: =($J31/$J$34) * (I$34/$J$34) -> 0.026666667 | V31: Observed Weighted Disagreement (D_obs) | W31: =SUMPRODUCT(G31:I33, M31:O33) /$J$34 -> 0.4 | X31: Sum of (confusion-matrix counts × weights) divided by total items.
A32: ='GPT-5 Generation'!A32 -> Transition | B32: ='GPT-5 Generation'!B32 -> green (AtRedTrafficLight ⇒ StopNotRequired) | C32: ='GPT-5 Generation'!C32 -> 1 | D32: ='Claude Sonnet 4.5 Gen'!C32 -> 0.5 | F32: 0.5 | G32: =COUNTIFS($A$2:$A$115,$F$30,$C$2:$C$115,$F32,$D$2:$D$115,G$30) -> 0 | H32: =COUNTIFS($A$2:$A$115,$F$30,$C$2:$C$115,$F32,$D$2:$D$115,H$30) -> 0 | I32: =COUNTIFS($A$2:$A$115,$F$30,$C$2:$C$115,$F32,$D$2:$D$115,I$30) -> 0 | J32: =SUM(G32:I32) -> 0 | L32: 0.5 | M32: =ABS(G$2-$F32)/1 -> 0.5 | N32: =ABS(H$2-$F32)/3 -> 0 | O32: =ABS(I$2-$F32)/1 -> 0.5 | Q32: 0.5 | R32: =($J32/$J$34) * (G$34/$J$34) -> 0 | S32: =($J32/$J$34) * (H$34/$J$34) -> 0 | T32: =($J32/$J$34) * (I$34/$J$34) -> 0 | V32: Expected Weighted Disagreement (D_exp) | W32: =SUMPRODUCT(R31:T33, M31:O33) -> 0.47111111 | X32: Sum of (expected cell proportions × weights) under chance agreement.
A33: ='GPT-5 Generation'!A33 -> State | B33: ='GPT-5 Generation'!B33 -> ApproachingStation | C33: ='GPT-5 Generation'!C33 -> 1 | D33: ='Claude Sonnet 4.5 Gen'!C33 -> 0 | F33: 1 | G33: =COUNTIFS($A$2:$A$71,$F$30,$C$2:$C$71,$F33,$D$2:$D$71,G$30) + MAX(C74-D74,0) -> 4 | H33: =COUNTIFS($A$2:$A$115,$F$30,$C$2:$C$115,$F33,$D$2:$D$115,H$30) -> 4 | I33: =COUNTIFS($A$2:$A$71,$F$30,$C$2:$C$71,$F33,$D$2:$D$71,I$30) + MIN(C74,D74) -> 6 | J33: =SUM(G33:I33) -> 14 | L33: 1 | M33: =ABS(G$2-$F33)/1 -> 1 | N33: =ABS(H$2-$F33)/1 -> 0.5 | O33: =ABS(I$2-$F33)/1 -> 0 | Q33: 1 | R33: =($J33/$J$34) * (G$34/$J$34) -> 0.31111111 | S33: =($J33/$J$34) * (H$34/$J$34) -> 0.24888889 | T33: =($J33/$J$34) * (I$34/$J$34) -> 0.37333333 | V33: Cohen's Kappa | W33: =1-W31/W32 -> 0.1509434 | X33: 1 - (D_obs / D_exp)
A34: ='GPT-5 Generation'!A34 -> Action | B34: ='GPT-5 Generation'!B34 -> entry / stopAL | C34: ='GPT-5 Generation'!C34 -> 1 | D34: ='Claude Sonnet 4.5 Gen'!C34 -> 1 | F34: Column Totals | G34: =SUM(G31:G33) -> 5 | H34: =SUM(H31:H33) -> 4 | I34: =SUM(I31:I33) -> 6 | J34: =SUM(G31:I33) -> 15
A35: ='GPT-5 Generation'!A35 -> Transition | B35: ='GPT-5 Generation'!B35 -> stopped (ApproachingStation ⇒ AtStation) | C35: ='GPT-5 Generation'!C35 -> 1 | D35: ='Claude Sonnet 4.5 Gen'!C35 -> 0
A36: ='GPT-5 Generation'!A36 -> History State | B36: ='GPT-5 Generation'!B36 -> History State for TrainMovement | C36: ='GPT-5 Generation'!C36 -> 1 | D36: ='Claude Sonnet 4.5 Gen'!C36 -> 1 | F36: Confusion Matrix (Action)
A37: ='GPT-5 Generation'!A37 -> State | B37: ='GPT-5 Generation'!B37 -> Emergency | C37: ='GPT-5 Generation'!C37 -> 1 | D37: ='Claude Sonnet 4.5 Gen'!C37 -> 1 | F37: Action | G37: 0 | H37: 0.5 | I37: 1 | J37: Row Totals | L37: Global | M37: 0 | N37: 0.5 | O37: 1 | Q37: Global | R37: 0 | S37: 0.5 | T37: 1 | V37: ="Metrics" & " " & F37 -> Metrics Action | W37: Value | X37: Note
A38: ='GPT-5 Generation'!A38 -> Transition | B38: ='GPT-5 Generation'!B38 -> emergency (TrainMovement ⇒ Emergency) | C38: ='GPT-5 Generation'!C38 -> 1 | D38: ='Claude Sonnet 4.5 Gen'!C38 -> 1 | F38: 0 | G38: =COUNTIFS($A$2:$A$115,F37,$C$2:$C$115,$F38,$D$2:$D$115,G37) -> 1 | H38: =COUNTIFS($A$2:$A$115,F37,$C$2:$C$115,$F38,$D$2:$D$115,H37) -> 0 | I38: =COUNTIFS($A$2:$A$71,F37,$C$2:$C$71,$F38,$D$2:$D$71,I37)+MAX(D75-C75,0) -> 0 | J38: =SUM(G38:I38) -> 1 | L38: 0 | M38: =ABS(G$2-$F38)/1 -> 0 | N38: =ABS(H$2-$F38)/1 -> 0.5 | O38: =ABS(I$2-$F38)/1 -> 1 | Q38: 0 | R38: =($J38/$J$41) * (G$41/$J$41) -> 0.0069444444 | S38: =($J38/$J$41) * (H$41/$J$41) -> 0.041666667 | T38: =($J38/$J$41) * (I$41/$J$41) -> 0.034722222 | V38: Observed Weighted Disagreement (D_obs) | W38: =SUMPRODUCT(G38:I40, M38:O40) /$J$41 -> 0.25 | X38: Sum of (confusion-matrix counts × weights) divided by total items.
A39: ='GPT-5 Generation'!A39 -> Action | B39: ='GPT-5 Generation'!B39 -> eStop; | C39: ='GPT-5 Generation'!C39 -> 1 | D39: ='Claude Sonnet 4.5 Gen'!C39 -> 1 | F39: 0.5 | G39: =COUNTIFS($A$2:$A$115,F37,$C$2:$C$115,$F39,$D$2:$D$115,G37) -> 0 | H39: =COUNTIFS($A$2:$A$115,F37,$C$2:$C$115,$F38,$D$2:$D$115,H37) -> 0 | I39: =COUNTIFS($A$2:$A$115,F37,$C$2:$C$115,$F39,$D$2:$D$115,I37) -> 0 | J39: =SUM(G39:I39) -> 0 | L39: 0.5 | M39: =ABS(G$2-$F39)/1 -> 0.5 | N39: =ABS(H$2-$F39)/3 -> 0 | O39: =ABS(I$2-$F39)/1 -> 0.5 | Q39: 0.5 | R39: =($J39/$J$41) * (G$41/$J$41) -> 0 | S39: =($J39/$J$41) * (H$41/$J$41) -> 0 | T39: =($J39/$J$41) * (I$41/$J$41) -> 0 | V39: Expected Weighted Disagreement (D_exp) | W39: =SUMPRODUCT(R38:T40, M38:O40) -> 0.36111111 | X39: Sum of (expected cell proportions × weights) under chance agreement.
A40: ='GPT-5 Generation'!A40 -> Transition | B40: ='GPT-5 Generation'!B40 -> clear (Emergency ⇒ History State) | C40: ='GPT-5 Generation'!C40 -> 1 | D40: ='Claude Sonnet 4.5 Gen'!C40 -> 1 | F40: 1 | G40: =COUNTIFS($A$2:$A$71,F37,$C$2:$C$71,$F40,$D$2:$D$71,G37)+MAX(C75-D75,0) -> 0 | H40: =COUNTIFS($A$2:$A$115,F37,$C$2:$C$115,$F40,$D$2:$D$115,H37) -> 6 | I40: =COUNTIFS($A$2:$A$71,F37,$C$2:$C$71,$F40,$D$2:$D$71,I37) + MIN(C75,D75) -> 5 | J40: =SUM(G40:I40) -> 11 | L40: 1 | M40: =ABS(G$2-$F40)/1 -> 1 | N40: =ABS(H$2-$F40)/1 -> 0.5 | O40: =ABS(I$2-$F40)/1 -> 0 | Q40: 1 | R40: =($J40/$J$41) * (G$41/$J$41) -> 0.076388889 | S40: =($J40/$J$41) * (H$41/$J$41) -> 0.45833333 | T40: =($J40/$J$41) * (I$41/$J$41) -> 0.38194444 | V40: Cohen's Kappa | W40: =1-W38/W39 -> 0.30769231 | X40: 1 - (D_obs / D_exp)
...
