Workbook

Sheet Wumple
A1: Type | B1: Element
A2: State | B2: Initial state (→ Watch)
A3: Action | B3: time=0:00:00; alarmTime=0:00:00; alarm=false; flashAlert=false; cdTime=0:00:00
A4: Composite State | B4: Watch
A5: Region | B5: Light
A6: State | B6: Initial state (Light → Off)
A7: State | B7: Off
A8: Action | B8: entry / lightOff()
A9: Transition | B9: D (Off ⇒ On)
A10: State | B10: On
A11: Action | B11: entry / lightOn()
A12: Transition | B12: D (On ⇒ Off)
... A116: History State | B116: additional elements

Sheet GPT-5 Generation
A1: Type | B1: Element | C1: GPT-5 Generation | D1: Notes
A2: State | B2: Initial state (→ Watch) | C2: 1 | D2: Represented as [*] --> Watch
A3: Action | B3: time=0:00:00; alarmTime=0:00:00; alarm=false; flashAlert=false; cdTime=0:00:00 | C3: 0 | D3: No initialization action on the initial transition to Watch
A4: Composite State | B4: Watch | C4: 1 | D4: Watch is correctly modeled as a composite state with multiple regions
A5: Region | B5: Light | C5: 0.5 | D5: Represented as region Backlight which captures similar functionality but differs in structure (missing Flash state)
A6: State | B6: Initial state (Light → Off) | C6: 1 | D6: Represented as [*] --> BacklightOff in Backlight region
A7: State | B7: Off | C7: 1 | D7: Represented as BacklightOff state
A8: Action | B8: entry / lightOff() | C8: 1 | D8: Represented as entry / turnBacklightOff() which is semantically equivalent
A9: Transition | B9: D (Off ⇒ On) | C9: 1 | D9: Represented as BacklightOff --> BacklightOn : D
A10: State | B10: On | C10: 1 | D10: Represented as BacklightOn state
A11: Action | B11: entry / lightOn() | C11: 1 | D11: Represented as entry / turnBacklightOn() which is semantically equivalent
A12: Transition | B12: D (On ⇒ Off) | C12: 1 | D12: Represented as BacklightOn --> BacklightOff : D
A13: Transition | B13: after 10sec (On ⇒ Off) | C13: 1 | D13: Represented as BacklightOn --> BacklightOff : after10sec
... A116: History State | B116: additional elements | C116: 0 | D116: No fundamentally incorrect history states present

Sheet Claude Sonnet 4.5 Gen
A1: Type | B1: Element | C1: Claude Sonnet 4.5 Generation | D1: Notes
A2: State | B2: Initial state (→ Watch) | C2: 1 | D2: Initial state correctly transitions to Watch composite state
A3: Action | B3: time=0:00:00; alarmTime=0:00:00; alarm=false; flashAlert=false; cdTime=0:00:00 | C3: 0 | D3: No initialization action present in student submission
A4: Composite State | B4: Watch | C4: 1 | D4: Watch composite state correctly defined
A5: Region | B5: Light | C5: 1 | D5: Backlight region present (named Backlight instead of Light but semantically equivalent)
A6: State | B6: Initial state (Light → Off) | C6: 1 | D6: Initial state correctly transitions to BacklightOff
A7: State | B7: Off | C7: 1 | D7: BacklightOff state represents the off state
A8: Action | B8: entry / lightOff() | C8: 0.5 | D8: turnOffBacklight() action present but not as entry action on Off state
A9: Transition | B9: D (Off ⇒ On) | C9: 1 | D9: D button transition from BacklightOff to BacklightOn present
A10: State | B10: On | C10: 1 | D10: BacklightOn state present
A11: Action | B11: entry / lightOn() | C11: 0.5 | D11: turnOnBacklight() action present but not as entry action on On state
A12: Transition | B12: D (On ⇒ Off) | C12: 1 | D12: D button transition from BacklightOn to BacklightOff present
A13: Transition | B13: after 10sec (On ⇒ Off) | C13: 1 | D13: after_10sec transition from BacklightOn to BacklightOff present
... A116: History State | B116: additional elements | C116: 0 | D116: No fundamentally incorrect history states present

Sheet Metrics
A1: Generated by GPT-5 | J1: Date
A2: Type | B2: Ground Truth Count | C2: True Positive | D2: False Positive | E2: False Negative | F2: Precision | G2: Recall | H2: F1 Score | J2: March 16th, 2026
A3: Composite State | B3: =COUNTIF(Wumple!$A$2:$A$109, A3) -> 5 | C3: =SUMIF('GPT-5 Generation'!$A$2:$A$109, $A3, 'GPT-5 Generation'!$C$2:$C$109) -> 4 | D3: =SUMIF('GPT-5 Generation'!$A$110:$A$116, $A3, 'GPT-5 Generation'!$C$110:$C$116) -> 0 | E3: =COUNTIFS('GPT-5 Generation'!$A$2:$A$109, $A3, 'GPT-5 Generation'!$C$2:$C$109,0) -> 1 | F3: =IFERROR(C3 / (C3 + D3), "Not Available") -> 1 | G3: =IFERROR(C3 / B3, "Not Available") -> 0.8 | H3: =IFERROR(2*((F3*G3)/(F3+G3)),"Not Available") -> 0.88888889
A4: State | B4: =COUNTIF(Wumple!$A$2:$A$109, A4) -> 24 | C4: =SUMIF('GPT-5 Generation'!$A$2:$A$109, $A4, 'GPT-5 Generation'!$C$2:$C$109) -> 22.5 | D4: =SUMIF('GPT-5 Generation'!$A$110:$A$116, $A4, 'GPT-5 Generation'!$C$110:$C$116) -> 0 | E4: =COUNTIFS('GPT-5 Generation'!$A$2:$A$109, $A4, 'GPT-5 Generation'!$C$2:$C$109,0) -> 1 | F4: =IFERROR(C4 / (C4 + D4), "Not Available") -> 1 | G4: =IFERROR(C4 / B4, "Not Available") -> 0.9375 | H4: =IFERROR(2*((F4*G4)/(F4+G4)),"Not Available") -> 0.96774194 | J4: Grading LLM
A5: Transition | B5: =COUNTIF(Wumple!$A$2:$A$109, A5) -> 37 | C5: =SUMIF('GPT-5 Generation'!$A$2:$A$109, $A5, 'GPT-5 Generation'!$C$2:$C$109) -> 33.5 | D5: =SUMIF('GPT-5 Generation'!$A$110:$A$116, $A5, 'GPT-5 Generation'!$C$110:$C$116) -> 0 | E5: =COUNTIFS('GPT-5 Generation'!$A$2:$A$109, $A5, 'GPT-5 Generation'!$C$2:$C$109,0) -> 3 | F5: =IFERROR(C5 / (C5 + D5), "Not Available") -> 1 | G5: =IFERROR(C5 / B5, "Not Available") -> 0.90540541 | H5: =IFERROR(2*((F5*G5)/(F5+G5)),"Not Available") -> 0.95035461 | J5: Claude Sonnet 4.5
A6: Action | B6: =COUNTIF(Wumple!$A$2:$A$109, A6) -> 36 | C6: =SUMIF('GPT-5 Generation'!$A$2:$A$109, $A6, 'GPT-5 Generation'!$C$2:$C$109) -> 31.5 | D6: =SUMIF('GPT-5 Generation'!$A$110:$A$116, $A6, 'GPT-5 Generation'!$C$110:$C$116) -> 0 | E6: =COUNTIFS('GPT-5 Generation'!$A$2:$A$109, $A6, 'GPT-5 Generation'!$C$2:$C$109,0) -> 4 | F6: =IFERROR(C6 / (C6 + D6), "Not Available") -> 1 | G6: =IFERROR(C6 / B6, "Not Available") -> 0.875 | H6: =IFERROR(2*((F6*G6)/(F6+G6)),"Not Available") -> 0.93333333
A7: Region | B7: =COUNTIF(Wumple!$A$2:$A$109, A7) -> 2 | C7: =SUMIF('GPT-5 Generation'!$A$2:$A$109, $A7, 'GPT-5 Generation'!$C$2:$C$109) -> 1.5 | D7: =SUMIF('GPT-5 Generation'!$A$110:$A$116, $A7, 'GPT-5 Generation'!$C$110:$C$116) -> 2 | E7: =COUNTIFS('GPT-5 Generation'!$A$2:$A$109, $A7, 'GPT-5 Generation'!$C$2:$C$109,0) -> 0 | F7: =IFERROR(C7 / (C7 + D7), "Not Available") -> 0.42857143 | G7: =IFERROR(C7 / B7, "Not Available") -> 0.75 | H7: =IFERROR(2*((F7*G7)/(F7+G7)),"Not Available") -> 0.54545455 | J7: Generation LLMs
A8: History State | B8: =COUNTIF(Wumple!$A$2:$A$109, A8) -> 1 | C8: =SUMIF('GPT-5 Generation'!$A$2:$A$109, $A8, 'GPT-5 Generation'!$C$2:$C$109) -> 1 | D8: =SUMIF('GPT-5 Generation'!$A$110:$A$116, $A8, 'GPT-5 Generation'!$C$110:$C$116) -> 0 | E8: =COUNTIFS('GPT-5 Generation'!$A$2:$A$109, $A8, 'GPT-5 Generation'!$C$2:$C$109,0) -> 0 | F8: =IFERROR(C8 / (C8 + D8), "Not Available") -> 1 | G8: =IFERROR(C8 / B8, "Not Available") -> 1 | H8: =IFERROR(2*((F8*G8)/(F8+G8)),"Not Available") -> 1 | J8: GPT-5
A9: Guard | B9: =COUNTIF(Wumple!$A$2:$A$109, A9) -> 3 | C9: =SUMIF('GPT-5 Generation'!$A$2:$A$109, $A9, 'GPT-5 Generation'!$C$2:$C$109) -> 1 | D9: =SUMIF('GPT-5 Generation'!$A$110:$A$116, $A9, 'GPT-5 Generation'!$C$110:$C$116) -> 0 | E9: =COUNTIFS('GPT-5 Generation'!$A$2:$A$109, $A9, 'GPT-5 Generation'!$C$2:$C$109,0) -> 2 | F9: =IFERROR(C9 / (C9 + D9), "Not Available") -> 1 | G9: =IFERROR(C9 / B9, "Not Available") -> 0.33333333 | H9: =IFERROR(2*((F9*G9)/(F9+G9)),"Not Available") -> 0.5 | J9: Claude Sonnet 4.5
A10: Overall Score | B10: =SUM(B3:B9) -> 108 | C10: =SUM(C4:C9) -> 91 | D10: =SUM(D3:D9) -> 2 | E10: =SUM(E3:E9) -> 11 | F10: =IFERROR(C10 / (C10 + D10), "Not Available") -> 0.97849462 | G10: =IFERROR(C10 / B10, "Not Available") -> 0.84259259 | H10: =IFERROR(2*((F10*G10)/(F10+G10)),"Not Available") -> 0.90547264
A12: Generated by Claude Sonnet 4.5
A13: Type | B13: Ground Truth Count | C13: True Positive | D13: False Positive | E13: False Negative | F13: Precision | G13: Recall | H13: F1 Score
A14: Composite state | B14: =COUNTIF(Wumple!$A$2:$A$109, A3) -> 5 | C14: =SUMIF('Claude Sonnet 4.5 Gen'!$A$2:$A$109, $A14, 'Claude Sonnet 4.5 Gen'!$C$2:$C$109) -> 4 | D14: =SUMIF('Claude Sonnet 4.5 Gen'!$A$110:$A$116, $A14, 'Claude Sonnet 4.5 Gen'!$C$110:$C$116) -> 0 | E14: =COUNTIFS('Claude Sonnet 4.5 Gen'!$A$2:$A$109, $A14, 'Claude Sonnet 4.5 Gen'!$C$2:$C$109,0) -> 1 | F14: =IFERROR(C14 / (C14 + D14), "Not Available") -> 1 | G14: =IFERROR(C14 / B14, "Not Available") -> 0.8 | H14: =IFERROR(2*((F14*G14)/(F14+G14)),"Not Available") -> 0.88888889
A15: State | B15: =COUNTIF(Wumple!$A$2:$A$109, A4) -> 24 | C15: =SUMIF('Claude Sonnet 4.5 Gen'!$A$2:$A$109, $A15, 'Claude Sonnet 4.5 Gen'!$C$2:$C$109) -> 22.5 | D15: =SUMIF('Claude Sonnet 4.5 Gen'!$A$110:$A$116, $A15, 'Claude Sonnet 4.5 Gen'!$C$110:$C$116) -> 0 | E15: =COUNTIFS('Claude Sonnet 4.5 Gen'!$A$2:$A$109, $A15, 'Claude Sonnet 4.5 Gen'!$C$2:$C$109,0) -> 1 | F15: =IFERROR(C15 / (C15 + D15), "Not Available") -> 1 | G15: =IFERROR(C15 / B15, "Not Available") -> 0.9375 | H15: =IFERROR(2*((F15*G15)/(F15+G15)),"Not Available") -> 0.96774194
A16: Transition | B16: =COUNTIF(Wumple!$A$2:$A$109, A5) -> 37 | C16: =SUMIF('Claude Sonnet 4.5 Gen'!$A$2:$A$109, $A16, 'Claude Sonnet 4.5 Gen'!$C$2:$C$109) -> 33 | D16: =SUMIF('Claude Sonnet 4.5 Gen'!$A$110:$A$116, $A16, 'Claude Sonnet 4.5 Gen'!$C$110:$C$116) -> 0 | E16: =COUNTIFS('Claude Sonnet 4.5 Gen'!$A$2:$A$109, $A16, 'Claude Sonnet 4.5 Gen'!$C$2:$C$109,0) -> 4 | F16: =IFERROR(C16 / (C16 + D16), "Not Available") -> 1 | G16: =IFERROR(C16 / B16, "Not Available") -> 0.89189189 | H16: =IFERROR(2*((F16*G16)/(F16+G16)),"Not Available") -> 0.94285714
A17: Action | B17: =COUNTIF(Wumple!$A$2:$A$109, A6) -> 36 | C17: =SUMIF('Claude Sonnet 4.5 Gen'!$A$2:$A$109, $A17, 'Claude Sonnet 4.5 Gen'!$C$2:$C$109) -> 6.5 | D17: =SUMIF('Claude Sonnet 4.5 Gen'!$A$110:$A$116, $A17, 'Claude Sonnet 4.5 Gen'!$C$110:$C$116) -> 0 | E17: =COUNTIFS('Claude Sonnet 4.5 Gen'!$A$2:$A$109, $A17, 'Claude Sonnet 4.5 Gen'!$C$2:$C$109,0) -> 23 | F17: =IFERROR(C17 / (C17 + D17), "Not Available") -> 1 | G17: =IFERROR(C17 / B17, "Not Available") -> 0.18055556 | H17: =IFERROR(2*((F17*G17)/(F17+G17)),"Not Available") -> 0.30588235
A18: Region | B18: =COUNTIF(Wumple!$A$2:$A$109, A7) -> 2 | C18: =SUMIF('Claude Sonnet 4.5 Gen'!$A$2:$A$109, $A18, 'Claude Sonnet 4.5 Gen'!$C$2:$C$109) -> 2 | D18: =SUMIF('Claude Sonnet 4.5 Gen'!$A$110:$A$116, $A18, 'Claude Sonnet 4.5 Gen'!$C$110:$C$116) -> 0 | E18: =COUNTIFS('Claude Sonnet 4.5 Gen'!$A$2:$A$109, $A18, 'Claude Sonnet 4.5 Gen'!$C$2:$C$109,0) -> 0 | F18: =IFERROR(C18 / (C18 + D18), "Not Available") -> 1 | G18: =IFERROR(C18 / B18, "Not Available") -> 1 | H18: =IFERROR(2*((F18*G18)/(F18+G18)),"Not Available") -> 1
A19: History State | B19: =COUNTIF(Wumple!$A$2:$A$109, A8) -> 1 | C19: =SUMIF('Claude Sonnet 4.5 Gen'!$A$2:$A$109, $A19, 'Claude Sonnet 4.5 Gen'!$C$2:$C$109) -> 1 | D19: =SUMIF('Claude Sonnet 4.5 Gen'!$A$110:$A$116, $A19, 'Claude Sonnet 4.5 Gen'!$C$110:$C$116) -> 0 | E19: =COUNTIFS('Claude Sonnet 4.5 Gen'!$A$2:$A$109, $A19, 'Claude Sonnet 4.5 Gen'!$C$2:$C$109,0) -> 0 | F19: =IFERROR(C19 / (C19 + D19), "Not Available") -> 1 | G19: =IFERROR(C19 / B19, "Not Available") -> 1 | H19: =IFERROR(2*((F19*G19)/(F19+G19)),"Not Available") -> 1
A20: Guard | B20: =COUNTIF(Wumple!$A$2:$A$109, A9) -> 3 | C20: =SUMIF('Claude Sonnet 4.5 Gen'!$A$2:$A$109, $A20, 'Claude Sonnet 4.5 Gen'!$C$2:$C$109) -> 1 | D20: =SUMIF('Claude Sonnet 4.5 Gen'!$A$110:$A$116, $A20, 'Claude Sonnet 4.5 Gen'!$C$110:$C$116) -> 0 | E20: =COUNTIFS('Claude Sonnet 4.5 Gen'!$A$2:$A$109, $A20, 'Claude Sonnet 4.5 Gen'!$C$2:$C$109,0) -> 2 | F20: =IFERROR(C20 / (C20 + D20), "Not Available") -> 1 | G20: =IFERROR(C20 / B20, "Not Available") -> 0.33333333 | H20: =IFERROR(2*((F20*G20)/(F20+G20)),"Not Available") -> 0.5
A21: Overall Score | B21: =SUM(B14:B20) -> 108 | C21: =SUM(C14:C20) -> 70 | D21: =SUM(D14:D20) -> 0 | E21: =SUM(E14:E20) -> 31 | F21: =IFERROR(C21 / (C21 + D21), "Not Available") -> 1 | G21: =IFERROR(C21 / B21, "Not Available") -> 0.64814815 | H21: =IFERROR(2*((F21*G21)/(F21+G21)),"Not Available") -> 0.78651685

Sheet Inter-rater
A1: Type | B1: Element | C1: GPT-5 | D1: Claude Sonnet 4.5 | F1: Confusion Matrix | L1: Cohen's Kappa
A2: =Wumple!A2 -> State | B2: =Wumple!B2 -> Initial state (→ Watch) | C2: ='GPT-5 Generation'!C2 -> 1 | D2: ='Claude Sonnet 4.5 Gen'!C2 -> 1 | F2: Global | G2: 0 | H2: 0.5 | I2: 1 | J2: Row Totals | L2: Metric | M2: Value | N2: Note
A3: =Wumple!A3 -> Action | B3: =Wumple!B3 -> time=0:00:00; alarmTime=0:00:00; alarm=false; flashAlert=false; cdTime=0:00:00 | C3: ='GPT-5 Generation'!C3 -> 0 | D3: ='Claude Sonnet 4.5 Gen'!C3 -> 0 | F3: 0 | G3: =COUNTIFS($C$2:$C$153, $F3, $D$2:$D$153, G$2) -> 16 | H3: =COUNTIFS($C$2:$C$109, $F3, $D$2:$D$109, H$2) -> 1 | I3: =COUNTIFS($C$2:$C$109, $F3, $D$2:$D$109, I$2)+MAX(D110-C110,0)+MAX(D111-C111,0)+MAX(D112-C112,0)+MAX(D113-C113,0)+MAX(D114-C114,0)+MAX(D115-C115,0)+MAX(D116-C116,0) -> 0 | J3: =SUM(G3:I3) -> 17 | L3: Observed Agreement (Po) | M3: =(G3+H4+I5)/COUNTA($C$2:$C$163) -> 0.67826087 | N3: This sums the diagonal of your matrix divided by total rows.
A4: =Wumple!A4 -> Composite State | B4: =Wumple!B4 -> Watch | C4: ='GPT-5 Generation'!C4 -> 1 | D4: ='Claude Sonnet 4.5 Gen'!C4 -> 1 | F4: 0.5 | G4: =COUNTIFS($C$2:$C$109, $F4, $D$2:$D$109, G$2) -> 1 | H4: =COUNTIFS($C$2:$C$109, $F4, $D$2:$D$109, H$2) -> 1 | I4: =COUNTIFS($C$2:$C$109, $F4, $D$2:$D$109, I$2) -> 2 | J4: =SUM(G4:I4) -> 4 | L4: Expected Agreement (Pe) | M4: {=SUMPRODUCT(J3:J5/COUNTA($C$2:$C$163), TRANSPOSE(G6:I6)/COUNTA($C$2:$C$163))} -> 0.50691871 | N4: This computes the sum of row proportion times column proportion.
A5: =Wumple!A5 -> Region | B5: =Wumple!B5 -> Light | C5: ='GPT-5 Generation'!C5 -> 0.5 | D5: ='Claude Sonnet 4.5 Gen'!C5 -> 1 | F5: 1 | G5: =COUNTIFS($C$2:$C$109, $F5, $D$2:$D$109, G$2)+MAX(C110-D110,0)+MAX(C111-D111,0)+MAX(C112-D112,0)+MAX(C113-D113,0)+MAX(C114-D114,0)+MAX(C115-D115,0)+MAX(C116-D116,0) -> 22 | H5: =COUNTIFS($C$2:$C$109, $F5, $D$2:$D$109, H$2) -> 12 | I5: =COUNTIFS($C$2:$C$109, $F5, $D$2:$D$109, I$2)+ SUM(MIN(C110,D110), MIN(C111,D111), MIN(C112,D112), MIN(C113,D113), MIN(C114,D114), MIN(C115,D115), MIN(C116,D116)) -> 61 | J5: =SUM(G5:I5) -> 95 | L5: Cohen's Kappa | M5: =(M3-M4)/(1-M4) -> 0.34749272 | N5: (Po - Pe) / (1 - Pe)
A6: =Wumple!A6 -> State | B6: =Wumple!B6 -> Initial state (Light → Off) | C6: ='GPT-5 Generation'!C6 -> 1 | D6: ='Claude Sonnet 4.5 Gen'!C6 -> 1 | F6: Column Totals | G6: =SUM(G3:G5) -> 39 | H6: =SUM(H3:H5) -> 14 | I6: =SUM(I3:I5) -> 63
A7: =Wumple!A7 -> State | B7: =Wumple!B7 -> Off | C7: ='GPT-5 Generation'!C7 -> 1 | D7: ='Claude Sonnet 4.5 Gen'!C7 -> 1
A8: =Wumple!A8 -> Action | B8: =Wumple!B8 -> entry / lightOff() | C8: ='GPT-5 Generation'!C8 -> 1 | D8: ='Claude Sonnet 4.5 Gen'!C8 -> 0.5 | F8: Confusion Matrix (State) | L8: Cohen's Kappa (State)
A9: =Wumple!A9 -> Transition | B9: =Wumple!B9 -> D (Off ⇒ On) | C9: ='GPT-5 Generation'!C9 -> 1 | D9: ='Claude Sonnet 4.5 Gen'!C9 -> 1 | F9: State | G9: 0 | H9: 0.5 | I9: 1 | J9: Row Totals | L9: Metric | M9: Value | N9: Note
A10: =Wumple!A10 -> State | B10: =Wumple!B10 -> On | C10: ='GPT-5 Generation'!C10 -> 1 | D10: ='Claude Sonnet 4.5 Gen'!C10 -> 1 | F10: 0 | G10: =COUNTIFS($A$2:$A$153,$F$9,$C$2:$C$153,$F10,$D$2:$D$153,G$9) -> 2 | H10: =COUNTIFS($A$2:$A$153,$F$9,$C$2:$C$153,$F10,$D$2:$D$153,H$9) -> 0 | I10: =COUNTIFS($A$2:$A$109,$F$9,$C$2:$C$109,$F10,$D$2:$D$109,I$9)+MAX(D110-C110,0) -> 0 | J10: =SUM(G10:I10) -> 2 | L10: Observed Agreement (Po) | M10: =(G10+H11+I12)/COUNTIF($A$2:$A$163,F9) -> 1 | N10: This sums the diagonal of your matrix divided by total rows.
A11: =Wumple!A11 -> Action | B11: =Wumple!B11 -> entry / lightOn() | C11: ='GPT-5 Generation'!C11 -> 1 | D11: ='Claude Sonnet 4.5 Gen'!C11 -> 0.5 | F11: 0.5 | G11: =COUNTIFS($A$2:$A$153,$F$9,$C$2:$C$153,$F11,$D$2:$D$153,G$9) -> 0 | H11: =COUNTIFS($A$2:$A$153,$F$9,$C$2:$C$153,$F11,$D$2:$D$153,H$9) -> 1 | I11: =COUNTIFS($A$2:$A$153,$F$9,$C$2:$C$153,$F11,$D$2:$D$153,I$9) -> 0 | J11: =SUM(G11:I11) -> 1 | L11: Expected Agreement (Pe) | M11: {=SUMPRODUCT(J10:J12/COUNTIF($A$2:$A$163,F9), TRANSPOSE(G13:I13)/COUNTIF($A$2:$A$163,F9))} -> 0.7824 | N11: This computes the sum of row proportion times column proportion.
A12: =Wumple!A12 -> Transition | B12: =Wumple!B12 -> D (On ⇒ Off) | C12: ='GPT-5 Generation'!C12 -> 1 | D12: ='Claude Sonnet 4.5 Gen'!C12 -> 1 | F12: 1 | G12: =COUNTIFS($A$2:$A$109,$F$9,$C$2:$C$109,$F12,$D$2:$D$109,G$9)+MAX(C110-D110,0) -> 0 | H12: =COUNTIFS($A$2:$A$153,$F$9,$C$2:$C$153,$F12,$D$2:$D$153,H$9) -> 0 | I12: =COUNTIFS($A$2:$A$109,$F$9,$C$2:$C$109,$F12,$D$2:$D$109,I$9)+MIN(C110-D110) -> 22 | J12: =SUM(G12:I12) -> 22 | L12: Cohen's Kappa | M12: =(M10-M11)/(1-M11) -> 1 | N12: (Po - Pe) / (1 - Pe)
A13: =Wumple!A13 -> Transition | B13: =Wumple!B13 -> after 10sec (On ⇒ Off) | C13: ='GPT-5 Generation'!C13 -> 1 | D13: ='Claude Sonnet 4.5 Gen'!C13 -> 1 | F13: Column Totals | G13: =SUM(G10:G12) -> 2 | H13: =SUM(H10:H12) -> 1 | I13: =SUM(I10:I12) -> 22
A14: =Wumple!A14 -> Transition | B14: =Wumple!B14 -> flash (On ⇒ Flash) | C14: ='GPT-5 Generation'!C14 -> 0 | D14: ='Claude Sonnet 4.5 Gen'!C14 -> 0
A15: =Wumple!A15 -> Guard | B15: =Wumple!B15 -> [flashAlert] | C15: ='GPT-5 Generation'!C15 -> 0 | D15: ='Claude Sonnet 4.5 Gen'!C15 -> 0 | F15: Confusion Matrix (Transition) | L15: Cohen's Kappa (Transition)
A16: =Wumple!A16 -> State | B16: =Wumple!B16 -> Flash | C16: ='GPT-5 Generation'!C16 -> 0 | D16: ='Claude Sonnet 4.5 Gen'!C16 -> 0 | F16: Transition | G16: 0 | H16: 0.5 | I16: 1 | J16: Row Totals | L16: Metric | M16: Value | N16: Note
A17: =Wumple!A17 -> Action | B17: =Wumple!B17 -> do / flash5Sec() | C17: ='GPT-5 Generation'!C17 -> 0 | D17: ='Claude Sonnet 4.5 Gen'!C17 -> 0 | F17: 0 | G17: =COUNTIFS($A$2:$A$153,$F$16,$C$2:$C$153,$F17,$D$2:$D$153,G$16) -> 4 | H17: =COUNTIFS($A$2:$A$153,$F$16,$C$2:$C$153,$F17,$D$2:$D$153,H$16) -> 0 | I17: =COUNTIFS($A$2:$A$109,$F$16,$C$2:$C$109,$F17,$D$2:$D$109,I$16) + MAX(D111-C111,0) -> 0 | J17: =SUM(G17:I17) -> 4 | L17: Observed Agreement (Po) | M17: =(G17+H18+I19)/COUNTIF($A$2:$A$163,F16) -> 0.94736842 | N17: This sums the diagonal of your matrix divided by total rows.
A18: =Wumple!A18 -> Transition | B18: =Wumple!B18 -> flash (Flash ⇒ Off) | C18: ='GPT-5 Generation'!C18 -> 0 | D18: ='Claude Sonnet 4.5 Gen'!C18 -> 0 | F18: 0.5 | G18: =COUNTIFS($A$2:$A$153,$F$16,$C$2:$C$153,$F18,$D$2:$D$153,G$16) -> 0 | H18: =COUNTIFS($A$2:$A$153,$F$16,$C$2:$C$153,$F18,$D$2:$D$153,H$16) -> 0 | I18: =COUNTIFS($A$2:$A$153,$F$16,$C$2:$C$153,$F18,$D$2:$D$153,I$16) -> 1 | J18: =SUM(G18:I18) -> 1 | L18: Expected Agreement (Pe) | M18: {=SUMPRODUCT(J17:J19/COUNTIF($A$2:$A$163,F16), TRANSPOSE(G20:I20)/COUNTIF($A$2:$A$163,F16))} -> 0.76800554 | N18: This computes the sum of row proportion times column proportion.
A19: =Wumple!A19 -> Guard | B19: =Wumple!B19 -> [flashAlert] | C19: ='GPT-5 Generation'!C19 -> 0 | D19: ='Claude Sonnet 4.5 Gen'!C19 -> 0 | F19: 1 | G19: =COUNTIFS($A$2:$A$109,$F$16,$C$2:$C$109,$F19,$D$2:$D$109,G$16)+MAX(C111-D111,0) -> 1 | H19: =COUNTIFS($A$2:$A$153,$F$16,$C$2:$C$153,$F19,$D$2:$D$153,H$16) -> 0 | I19: =COUNTIFS($A$2:$A$109,$F$16,$C$2:$C$109,$F19,$D$2:$D$109,I$16) + MIN(C111,D111) -> 32 | J19: =SUM(G19:I19) -> 33 | L19: Cohen's Kappa | M19: =(M17-M18)/(1-M18) -> 0.77313433 | N19: (Po - Pe) / (1 - Pe)
A20: =Wumple!A20 -> Transition | B20: =Wumple!B20 -> anyButton (Flash ⇒ Off) | C20: ='GPT-5 Generation'!C20 -> 0 | D20: ='Claude Sonnet 4.5 Gen'!C20 -> 0 | F20: Column Totals | G20: =SUM(G17:G19) -> 5 | H20: =SUM(H17:H19) -> 0 | I20: =SUM(I17:I19) -> 33
A21: =Wumple!A21 -> Region | B21: =Wumple!B21 -> WatchMode | C21: ='GPT-5 Generation'!C21 -> 1 | D21: ='Claude Sonnet 4.5 Gen'!C21 -> 1
A22: =Wumple!A22 -> State | B22: =Wumple!B22 -> Initial state (WatchMode → AlarmOff) | C22: ='GPT-5 Generation'!C22 -> 0.5 | D22: ='Claude Sonnet 4.5 Gen'!C22 -> 0.5 | F22: Confusion Matrix (Composite State) | L22: Cohen's Kappa (Composite State)
A23: =Wumple!A23 -> Composite State | B23: =Wumple!B23 -> AlarmOff | C23: ='GPT-5 Generation'!C23 -> 0 | D23: ='Claude Sonnet 4.5 Gen'!C23 -> 0 | F23: Composite State | G23: 0 | H23: 0.5 | I23: 1 | J23: Row Totals | L23: Metric | M23: Value | N23: Note
A24: =Wumple!A24 -> State | B24: =Wumple!B24 -> Initial state (AlarmOff → TimeKeepingMode) | C24: ='GPT-5 Generation'!C24 -> 1 | D24: ='Claude Sonnet 4.5 Gen'!C24 -> 1 | F24: 0 | G24: =COUNTIFS($A$2:$A$153,$F$23,$C$2:$C$153,$F24,$D$2:$D$153,G$23) -> 2 | H24: =COUNTIFS($A$2:$A$153,$F$23,$C$2:$C$153,$F24,$D$2:$D$153,H$23) -> 0 | I24: =COUNTIFS($A$2:$A$109,$F$23,$C$2:$C$109,$F24,$D$2:$D$109,I$23) + MAX(D114-C114,0) -> 0 | J24: =SUM(G24:I24) -> 2 | L24: Observed Agreement (Po) | M24: =(G24+H25+I26)/COUNTIF($A$2:$A$163,F23) -> 1 | N24: This sums the diagonal of your matrix divided by total rows.
A25: =Wumple!A25 -> Composite State | B25: =Wumple!B25 -> TimeKeepingMode | C25: ='GPT-5 Generation'!C25 -> 1 | D25: ='Claude Sonnet 4.5 Gen'!C25 -> 1 | F25: 0.5 | G25: =COUNTIFS($A$2:$A$153,$F$23,$C$2:$C$153,$F25,$D$2:$D$153,G$23) -> 0 | H25: =COUNTIFS($A$2:$A$153,$F$23,$C$2:$C$153,$F25,$D$2:$D$153,H$23) -> 0 | I25: =COUNTIFS($A$2:$A$153,$F$23,$C$2:$C$153,$F25,$D$2:$D$153,I$23) -> 0 | J25: =SUM(G25:I25) -> 0 | L25: Expected Agreement (Pe) | M25: {=SUMPRODUCT(J24:J26/COUNTIF($A$2:$A$163,F23), TRANSPOSE(G27:I27)/COUNTIF($A$2:$A$163,F23))} -> 0.55555556 | N25: This computes the sum of row proportion times column proportion.
A26: =Wumple!A26 -> State | B26: =Wumple!B26 -> Initial state (TimeKeepingMode → Idle) | C26: ='GPT-5 Generation'!C26 -> 1 | D26: ='Claude Sonnet 4.5 Gen'!C26 -> 1 | F26: 1 | G26: =COUNTIFS($A$2:$A$109,$F$23,$C$2:$C$109,$F26,$D$2:$D$109,G$23) + MAX(C114-D114,0) -> 0 | H26: =COUNTIFS($A$2:$A$153,$F$23,$C$2:$C$153,$F26,$D$2:$D$153,H$23) -> 0 | I26: =COUNTIFS($A$2:$A$109,$F$23,$C$2:$C$109,$F26,$D$2:$D$109,I$23) + MIN(C114,D114) -> 4 | J26: =SUM(G26:I26) -> 4 | L26: Cohen's Kappa | M26: =(M24-M25)/(1-M25) -> 1 | N26: (Po - Pe) / (1 - Pe)
A27: =Wumple!A27 -> State | B27: =Wumple!B27 -> Idle | C27: ='GPT-5 Generation'!C27 -> 1 | D27: ='Claude Sonnet 4.5 Gen'!C27 -> 1 | F27: Column Totals | G27: =SUM(G24:G26) -> 2 | H27: =SUM(H24:H26) -> 0 | I27: =SUM(I24:I26) -> 4
A28: =Wumple!A28 -> Action | B28: =Wumple!B28 -> do / displayTime() | C28: ='GPT-5 Generation'!C28 -> 1 | D28: ='Claude Sonnet 4.5 Gen'!C28 -> 0
A29: =Wumple!A29 -> Transition | B29: =Wumple!B29 -> B2sec (Idle ⇒ Idle) | C29: ='GPT-5 Generation'!C29 -> 0.5 | D29: ='Claude Sonnet 4.5 Gen'!C29 -> 1 | F29: Confusion Matrix (Guard) | L29: Cohen's Kappa (Guard)
A30: =Wumple!A30 -> Action | B30: =Wumple!B30 -> toggleFlashAlert() | C30: ='GPT-5 Generation'!C30 -> 0.5 | D30: ='Claude Sonnet 4.5 Gen'!C30 -> 0 | F30: Guard | G30: 0 | H30: 0.5 | I30: 1 | J30: Row Totals | L30: Metric | M30: Value | N30: Note
A31: =Wumple!A31 -> Transition | B31: =Wumple!B31 -> B (Idle ⇒ Idle) | C31: ='GPT-5 Generation'!C31 -> 1 | D31: ='Claude Sonnet 4.5 Gen'!C31 -> 1 | F31: 0 | G31: =COUNTIFS($A$2:$A$153,$F$30,$C$2:$C$153,$F31,$D$2:$D$153,G$30) -> 3 | H31: =COUNTIFS($A$2:$A$153,$F$30,$C$2:$C$153,$F31,$D$2:$D$153,H$30) -> 0 | I31: =COUNTIFS($A$2:$A$109,$F$30,$C$2:$C$109,$F31,$D$2:$D$109,I$30) + MAX(D112-C112,0) -> 0 | J31: =SUM(G31:I31) -> 3 | L31: Observed Agreement (Po) | M31: =(G31+H32+I33)/COUNTIF($A$2:$A$163,F30) -> 1 | N31: This sums the diagonal of your matrix divided by total rows.
A32: =Wumple!A32 -> Action | B32: =Wumple!B32 -> toggleAlarm() | C32: ='GPT-5 Generation'!C32 -> 1 | D32: ='Claude Sonnet 4.5 Gen'!C32 -> 0 | F32: 0.5 | G32: =COUNTIFS($A$2:$A$153,$F$30,$C$2:$C$153,$F32,$D$2:$D$153,G$30) -> 0 | H32: =COUNTIFS($A$2:$A$153,$F$30,$C$2:$C$153,$F32,$D$2:$D$153,H$30) -> 0 | I32: =COUNTIFS($A$2:$A$153,$F$30,$C$2:$C$153,$F32,$D$2:$D$153,I$30) -> 0 | J32: =SUM(G32:I32) -> 0 | L32: Expected Agreement (Pe) | M32: {=SUMPRODUCT(J31:J33/COUNTIF($A$2:$A$163,F30), TRANSPOSE(G34:I34)/COUNTIF($A$2:$A$163,F30))} -> 0.625 | N32: This computes the sum of row proportion times column proportion.
A33: =Wumple!A33 -> Transition | B33: =Wumple!B33 -> C (Idle ⇒ Seconds) | C33: ='GPT-5 Generation'!C33 -> 1 | D33: ='Claude Sonnet 4.5 Gen'!C33 -> 1 | F33: 1 | G33: =COUNTIFS($A$2:$A$109,$F$30,$C$2:$C$109,$F33,$D$2:$D$109,G$30) + MAX(C112-D112,0) -> 0 | H33: =COUNTIFS($A$2:$A$153,$F$30,$C$2:$C$153,$F33,$D$2:$D$153,H$30) -> 0 | I33: =COUNTIFS($A$2:$A$109,$F$30,$C$2:$C$109,$F33,$D$2:$D$109,I$30) + MIN(C112,D112) -> 1 | J33: =SUM(G33:I33) -> 1 | L33: Cohen's Kappa | M33: =(M31-M32)/(1-M32) -> 1 | N33: (Po - Pe) / (1 - Pe)
A34: =Wumple!A34 -> Action | B34: =Wumple!B34 -> flashSeconds() | C34: ='GPT-5 Generation'!C34 -> 1 | D34: ='Claude Sonnet 4.5 Gen'!C34 -> 0 | F34: Column Totals | G34: =SUM(G31:G33) -> 3 | H34: =SUM(H31:H33) -> 0 | I34: =SUM(I31:I33) -> 1
A35: =Wumple!A35 -> Transition | B35: =Wumple!B35 -> A (TimeKeepingMode ⇒ AlarmMode) | C35: ='GPT-5 Generation'!C35 -> 1 | D35: ='Claude Sonnet 4.5 Gen'!C35 -> 1
A36: =Wumple!A36 -> State | B36: =Wumple!B36 -> Seconds | C36: ='GPT-5 Generation'!C36 -> 1 | D36: ='Claude Sonnet 4.5 Gen'!C36 -> 1 | F36: Confusion Matrix (Action) | L36: Cohen's Kappa (Action)
A37: =Wumple!A37 -> Transition | B37: =Wumple!B37 -> B (Seconds ⇒ Seconds) | C37: ='GPT-5 Generation'!C37 -> 1 | D37: ='Claude Sonnet 4.5 Gen'!C37 -> 1 | F37: Action | G37: 0 | H37: 0.5 | I37: 1 | J37: Row Totals | L37: Metric | M37: Value | N37: Note
A38: =Wumple!A38 -> Action | B38: =Wumple!B38 -> time+=1sec | C38: ='GPT-5 Generation'!C38 -> 1 | D38: ='Claude Sonnet 4.5 Gen'!C38 -> 0.5 | F38: 0 | G38: =COUNTIFS($A$2:$A$153,F37,$C$2:$C$153,$F38,$D$2:$D$153,G37) -> 4 | H38: =COUNTIFS($A$2:$A$153,F37,$C$2:$C$153,$F38,$D$2:$D$153,H37) -> 1 | I38: =COUNTIFS($A$2:$A$109,F37,$C$2:$C$109,$F38,$D$2:$D$109,I37)+MAX(D113-C113,0) -> 0 | J38: =SUM(G38:I38) -> 5 | L38: Observed Agreement (Po) | M38: =(G38+H39+I40)/COUNTIF($A$2:$A$163,F37) -> 0.10810811 | N38: This sums the diagonal of your matrix divided by total rows.
A39: =Wumple!A39 -> Transition | B39: =Wumple!B39 -> C (Seconds ⇒ Minutes) | C39: ='GPT-5 Generation'!C39 -> 1 | D39: ='Claude Sonnet 4.5 Gen'!C39 -> 1 | F39: 0.5 | G39: =COUNTIFS($A$2:$A$153,F37,$C$2:$C$153,$F39,$D$2:$D$153,G37) -> 1 | H39: =COUNTIFS($A$2:$A$153,F37,$C$2:$C$153,$F39,$D$2:$D$153,H37) -> 0 | I39: =COUNTIFS($A$2:$A$153,F37,$C$2:$C$153,$F39,$D$2:$D$153,I37) -> 0 | J39: =SUM(G39:I39) -> 1 | L39: Expected Agreement (Pe) | M39: {=SUMPRODUCT(J38:J40/COUNTIF($A$2:$A$163,F37), TRANSPOSE(G41:I41)/COUNTIF($A$2:$A$163,F37))} -> 0.097151205 | N39: This computes the sum of row proportion times column proportion.
A40: =Wumple!A40 -> Action | B40: =Wumple!B40 -> flashMinutes() | C40: ='GPT-5 Generation'!C40 -> 1 | D40: ='Claude Sonnet 4.5 Gen'!C40 -> 0 | F40: 1 | G40: =COUNTIFS($A$2:$A$109,F37,$C$2:$C$109,$F40,$D$2:$D$109,G37)+MAX(C113-D113,0) -> 19 | H40: =COUNTIFS($A$2:$A$153,F37,$C$2:$C$153,$F40,$D$2:$D$153,H37) -> 12 | I40: =COUNTIFS($A$2:$A$109,F37,$C$2:$C$109,$F40,$D$2:$D$109,I37) + MIN(C113,D113) -> 0 | J40: =SUM(G40:I40) -> 31 | L40: Cohen's Kappa | M40: =(M38-M39)/(1-M39) -> 0.012135922 | N40: (Po - Pe) / (1 - Pe)
...

Sheet Weighted Cohens Kappa
A1: Type | B1: Element | C1: GPT-5 | D1: Claude Sonnet 4.5 | F1: Confusion Matrix | L1: Weight Matrix
A2: =Wumple!A2 -> State | B2: =Wumple!B2 -> Initial state (→ Watch) | C2: ='GPT-5 Generation'!C2 -> 1 | D2: ='Claude Sonnet 4.5 Gen'!C2 -> 1 | F2: Global | G2: 0 | H2: 0.5 | I2: 1 | J2: Row Totals | L2: Global | M2: 0 | N2: 0.5 | O2: 1 | Q2: Global | R2: 0 | S2: 0.5 | T2: 1 | V2: ="Metrics" & " " & F2 -> Metrics Global | W2: Value | X2: Note
A3: =Wumple!A3 -> Action | B3: =Wumple!B3 -> time=0:00:00; alarmTime=0:00:00; alarm=false; flashAlert=false; cdTime=0:00:00 | C3: ='GPT-5 Generation'!C3 -> 0 | D3: ='Claude Sonnet 4.5 Gen'!C3 -> 0 | F3: 0 | G3: =COUNTIFS($C$2:$C$116, $F3, $D$2:$D$116, G$2) -> 16 | H3: =COUNTIFS($C$2:$C$109, $F3, $D$2:$D$109, H$2) -> 1 | I3: =COUNTIFS($C$2:$C$109, $F3, $D$2:$D$109, I$2)+MAX(D110-C110,0)+MAX(D111-C111,0)+MAX(D112-C112,0)+MAX(D113-C113,0)+MAX(D114-C114,0)+MAX(D115-C115,0)+MAX(D116-C116,0) -> 0 | J3: =SUM(G3:I3) -> 17 | L3: 0 | M3: =ABS(G$2-$F3)/1 -> 0 | N3: =ABS(H$2-$F3)/1 -> 0.5 | O3: =ABS(I$2-$F3)/1 -> 1 | Q3: 0 | R3: =($J3/$J$6) * (G$6/$J$6) -> 0.0492717 | S3: =($J3/$J$6) * (H$6/$J$6) -> 0.017687277 | T3: =($J3/$J$6) * (I$6/$J$6) -> 0.079592747 | V3: Observed Weighted Disagreement (D_obs) | W3: =SUMPRODUCT(G3:I5, M3:O5) /$J$6 -> 0.25862069 | X3: Sum of (confusion-matrix counts × weights) divided by total items.
A4: =Wumple!A4 -> Composite State | B4: =Wumple!B4 -> Watch | C4: ='GPT-5 Generation'!C4 -> 1 | D4: ='Claude Sonnet 4.5 Gen'!C4 -> 1 | F4: 0.5 | G4: =COUNTIFS($C$2:$C$109, $F4, $D$2:$D$109, G$2) -> 1 | H4: =COUNTIFS($C$2:$C$109, $F4, $D$2:$D$109, H$2) -> 1 | I4: =COUNTIFS($C$2:$C$109, $F4, $D$2:$D$109, I$2) -> 2 | J4: =SUM(G4:I4) -> 4 | L4: 0.5 | M4: =ABS(G$2-$F4)/1 -> 0.5 | N4: =ABS(H$2-$F4)/3 -> 0 | O4: =ABS(I$2-$F4)/1 -> 0.5 | Q4: 0.5 | R4: =($J4/$J$6) * (G$6/$J$6) -> 0.011593341 | S4: =($J4/$J$6) * (H$6/$J$6) -> 0.0041617122 | T4: =($J4/$J$6) * (I$6/$J$6) -> 0.018727705 | V4: Expected Weighted Disagreement (D_exp) | W4: =SUMPRODUCT(R3:T5, M3:O5) -> 0.4283591 | X4: Sum of (expected cell proportions × weights) under chance agreement.
A5: =Wumple!A5 -> Region | B5: =Wumple!B5 -> Light | C5: ='GPT-5 Generation'!C5 -> 0.5 | D5: ='Claude Sonnet 4.5 Gen'!C5 -> 1 | F5: 1 | G5: =COUNTIFS($C$2:$C$109, $F5, $D$2:$D$109, G$2)+MAX(C110-D110,0)+MAX(C111-D111,0)+MAX(C112-D112,0)+MAX(C113-D113,0)+MAX(C114-D114,0)+MAX(C115-D115,0)+MAX(C116-D116,0) -> 22 | H5: =COUNTIFS($C$2:$C$109, $F5, $D$2:$D$109, H$2) -> 12 | I5: =COUNTIFS($C$2:$C$109, $F5, $D$2:$D$109, I$2)+ SUM(MIN(C110,D110), MIN(C111,D111), MIN(C112,D112), MIN(C113,D113), MIN(C114,D114), MIN(C115,D115), MIN(C116,D116)) -> 61 | J5: =SUM(G5:I5) -> 95 | L5: 1 | M5: =ABS(G$2-$F5)/1 -> 1 | N5: =ABS(H$2-$F5)/1 -> 0.5 | O5: =ABS(I$2-$F5)/1 -> 0 | Q5: 1 | R5: =($J5/$J$6) * (G$6/$J$6) -> 0.27534185 | S5: =($J5/$J$6) * (H$6/$J$6) -> 0.098840666 | T5: =($J5/$J$6) * (I$6/$J$6) -> 0.444783 | V5: Cohen's Kappa | W5: =1-W3/W4 -> 0.3962526 | X5: 1 - (D_obs / D_exp)
A6: =Wumple!A6 -> State | B6: =Wumple!B6 -> Initial state (Light → Off) | C6: ='GPT-5 Generation'!C6 -> 1 | D6: ='Claude Sonnet 4.5 Gen'!C6 -> 1 | F6: Column Totals | G6: =SUM(G3:G5) -> 39 | H6: =SUM(H3:H5) -> 14 | I6: =SUM(I3:I5) -> 63 | J6: =SUM(G3:I5) -> 116
A7: =Wumple!A7 -> State | B7: =Wumple!B7 -> Off | C7: ='GPT-5 Generation'!C7 -> 1 | D7: ='Claude Sonnet 4.5 Gen'!C7 -> 1
A8: =Wumple!A8 -> Action | B8: =Wumple!B8 -> entry / lightOff() | C8: ='GPT-5 Generation'!C8 -> 1 | D8: ='Claude Sonnet 4.5 Gen'!C8 -> 0.5 | F8: Confusion Matrix (State)
A9: =Wumple!A9 -> Transition | B9: =Wumple!B9 -> D (Off ⇒ On) | C9: ='GPT-5 Generation'!C9 -> 1 | D9: ='Claude Sonnet 4.5 Gen'!C9 -> 1 | F9: State | G9: 0 | H9: 0.5 | I9: 1 | J9: Row Totals | L9: Global | M9: 0 | N9: 0.5 | O9: 1 | Q9: Global | R9: 0 | S9: 0.5 | T9: 1 | V9: ="Metrics" & " " & F9 -> Metrics State | W9: Value | X9: Note
A10: =Wumple!A10 -> State | B10: =Wumple!B10 -> On | C10: ='GPT-5 Generation'!C10 -> 1 | D10: ='Claude Sonnet 4.5 Gen'!C10 -> 1 | F10: 0 | G10: =COUNTIFS($A$2:$A$116,$F$9,$C$2:$C$116,$F10,$D$2:$D$116,G$9) -> 2 | H10: =COUNTIFS($A$2:$A$116,$F$9,$C$2:$C$116,$F10,$D$2:$D$116,H$9) -> 0 | I10: =COUNTIFS($A$2:$A$109,$F$9,$C$2:$C$109,$F10,$D$2:$D$109,I$9)+MAX(D110-C110,0) -> 0 | J10: =SUM(G10:I10) -> 2 | L10: 0 | M10: =ABS(G$2-$F10)/1 -> 0 | N10: =ABS(H$2-$F10)/1 -> 0.5 | O10: =ABS(I$2-$F10)/1 -> 1 | Q10: 0 | R10: =($J10/$J$13) * (G$13/$J$13) -> 0.0064 | S10: =($J10/$J$13) * (H$13/$J$13) -> 0.0032 | T10: =($J10/$J$13) * (I$13/$J$13) -> 0.0704 | V10: Observed Weighted Disagreement (D_obs) | W10: =SUMPRODUCT(G10:I12, M10:O12) /$J$13 -> 0 | X10: Sum of (confusion-matrix counts × weights) divided by total items.
A11: =Wumple!A11 -> Action | B11: =Wumple!B11 -> entry / lightOn() | C11: ='GPT-5 Generation'!C11 -> 1 | D11: ='Claude Sonnet 4.5 Gen'!C11 -> 0.5 | F11: 0.5 | G11: =COUNTIFS($A$2:$A$116,$F$9,$C$2:$C$116,$F11,$D$2:$D$116,G$9) -> 0 | H11: =COUNTIFS($A$2:$A$116,$F$9,$C$2:$C$116,$F11,$D$2:$D$116,H$9) -> 1 | I11: =COUNTIFS($A$2:$A$116,$F$9,$C$2:$C$116,$F11,$D$2:$D$116,I$9) -> 0 | J11: =SUM(G11:I11) -> 1 | L11: 0.5 | M11: =ABS(G$2-$F11)/1 -> 0.5 | N11: =ABS(H$2-$F11)/3 -> 0 | O11: =ABS(I$2-$F11)/1 -> 0.5 | Q11: 0.5 | R11: =($J11/$J$13) * (G$13/$J$13) -> 0.0032 | S11: =($J11/$J$13) * (H$13/$J$13) -> 0.0016 | T11: =($J11/$J$13) * (I$13/$J$13) -> 0.0352 | V11: Expected Weighted Disagreement (D_exp) | W11: =SUMPRODUCT(R10:T12, M10:O12) -> 0.1792 | X11: Sum of (expected cell proportions × weights) under chance agreement.
A12: =Wumple!A12 -> Transition | B12: =Wumple!B12 -> D (On ⇒ Off) | C12: ='GPT-5 Generation'!C12 -> 1 | D12: ='Claude Sonnet 4.5 Gen'!C12 -> 1 | F12: 1 | G12: =COUNTIFS($A$2:$A$109,$F$9,$C$2:$C$109,$F12,$D$2:$D$109,G$9)+MAX(C110-D110,0) -> 0 | H12: =COUNTIFS($A$2:$A$116,$F$9,$C$2:$C$116,$F12,$D$2:$D$116,H$9) -> 0 | I12: =COUNTIFS($A$2:$A$109,$F$9,$C$2:$C$109,$F12,$D$2:$D$109,I$9)+MIN(C110-D110) -> 22 | J12: =SUM(G12:I12) -> 22 | L12: 1 | M12: =ABS(G$2-$F12)/1 -> 1 | N12: =ABS(H$2-$F12)/1 -> 0.5 | O12: =ABS(I$2-$F12)/1 -> 0 | Q12: 1 | R12: =($J12/$J$13) * (G$13/$J$13) -> 0.0704 | S12: =($J12/$J$13) * (H$13/$J$13) -> 0.0352 | T12: =($J12/$J$13) * (I$13/$J$13) -> 0.7744 | V12: Cohen's Kappa | W12: =1-W10/W11 -> 1 | X12: 1 - (D_obs / D_exp)
A13: =Wumple!A13 -> Transition | B13: =Wumple!B13 -> after 10sec (On ⇒ Off) | C13: ='GPT-5 Generation'!C13 -> 1 | D13: ='Claude Sonnet 4.5 Gen'!C13 -> 1 | F13: Column Totals | G13: =SUM(G10:G12) -> 2 | H13: =SUM(H10:H12) -> 1 | I13: =SUM(I10:I12) -> 22 | J13: =SUM(G10:I12) -> 25
A14: =Wumple!A14 -> Transition | B14: =Wumple!B14 -> flash (On ⇒ Flash) | C14: ='GPT-5 Generation'!C14 -> 0 | D14: ='Claude Sonnet 4.5 Gen'!C14 -> 0
A15: =Wumple!A15 -> Guard | B15: =Wumple!B15 -> [flashAlert] | C15: ='GPT-5 Generation'!C15 -> 0 | D15: ='Claude Sonnet 4.5 Gen'!C15 -> 0 | F15: Confusion Matrix (Transition)
A16: =Wumple!A16 -> State | B16: =Wumple!B16 -> Flash | C16: ='GPT-5 Generation'!C16 -> 0 | D16: ='Claude Sonnet 4.5 Gen'!C16 -> 0 | F16: Transition | G16: 0 | H16: 0.5 | I16: 1 | J16: Row Totals | L16: Global | M16: 0 | N16: 0.5 | O16: 1 | Q16: Global | R16: 0 | S16: 0.5 | T16: 1 | V16: ="Metrics" & " " & F16 -> Metrics Transition | W16: Value | X16: Note
A17: =Wumple!A17 -> Action | B17: =Wumple!B17 -> do / flash5Sec() | C17: ='GPT-5 Generation'!C17 -> 0 | D17: ='Claude Sonnet 4.5 Gen'!C17 -> 0 | F17: 0 | G17: =COUNTIFS($A$2:$A$116,$F$16,$C$2:$C$116,$F17,$D$2:$D$116,G$16) -> 4 | H17: =COUNTIFS($A$2:$A$116,$F$16,$C$2:$C$116,$F17,$D$2:$D$116,H$16) -> 0 | I17: =COUNTIFS($A$2:$A$109,$F$16,$C$2:$C$109,$F17,$D$2:$D$109,I$16) + MAX(D111-C111,0) -> 0 | J17: =SUM(G17:I17) -> 4 | L17: 0 | M17: =ABS(G$2-$F17)/1 -> 0 | N17: =ABS(H$2-$F17)/1 -> 0.5 | O17: =ABS(I$2-$F17)/1 -> 1 | Q17: 0 | R17: =($J17/$J$20) * (G$20/$J$20) -> 0.013850416 | S17: =($J17/$J$20) * (H$20/$J$20) -> 0 | T17: =($J17/$J$20) * (I$20/$J$20) -> 0.091412742 | V17: Observed Weighted Disagreement (D_obs) | W17: =SUMPRODUCT(G17:I19, M17:O19) /$J$20 -> 0.039473684 | X17: Sum of (confusion-matrix counts × weights) divided by total items.
A18: =Wumple!A18 -> Transition | B18: =Wumple!B18 -> flash (Flash ⇒ Off) | C18: ='GPT-5 Generation'!C18 -> 0 | D18: ='Claude Sonnet 4.5 Gen'!C18 -> 0 | F18: 0.5 | G18: =COUNTIFS($A$2:$A$116,$F$16,$C$2:$C$116,$F18,$D$2:$D$116,G$16) -> 0 | H18: =COUNTIFS($A$2:$A$116,$F$16,$C$2:$C$116,$F18,$D$2:$D$116,H$16) -> 0 | I18: =COUNTIFS($A$2:$A$116,$F$16,$C$2:$C$116,$F18,$D$2:$D$116,I$16) -> 1 | J18: =SUM(G18:I18) -> 1 | L18: 0.5 | M18: =ABS(G$2-$F18)/1 -> 0.5 | N18: =ABS(H$2-$F18)/3 -> 0 | O18: =ABS(I$2-$F18)/1 -> 0.5 | Q18: 0.5 | R18: =($J18/$J$20) * (G$20/$J$20) -> 0.0034626039 | S18: =($J18/$J$20) * (H$20/$J$20) -> 0 | T18: =($J18/$J$20) * (I$20/$J$20) -> 0.022853186 | V18: Expected Weighted Disagreement (D_exp) | W18: =SUMPRODUCT(R17:T19, M17:O19) -> 0.21883657 | X18: Sum of (expected cell proportions × weights) under chance agreement.
A19: =Wumple!A19 -> Guard | B19: =Wumple!B19 -> [flashAlert] | C19: ='GPT-5 Generation'!C19 -> 0 | D19: ='Claude Sonnet 4.5 Gen'!C19 -> 0 | F19: 1 | G19: =COUNTIFS($A$2:$A$109,$F$16,$C$2:$C$109,$F19,$D$2:$D$109,G$16)+MAX(C111-D111,0) -> 1 | H19: =COUNTIFS($A$2:$A$116,$F$16,$C$2:$C$116,$F19,$D$2:$D$116,H$16) -> 0 | I19: =COUNTIFS($A$2:$A$109,$F$16,$C$2:$C$109,$F19,$D$2:$D$109,I$16) + MIN(C111,D111) -> 32 | J19: =SUM(G19:I19) -> 33 | L19: 1 | M19: =ABS(G$2-$F19)/1 -> 1 | N19: =ABS(H$2-$F19)/1 -> 0.5 | O19: =ABS(I$2-$F19)/1 -> 0 | Q19: 1 | R19: =($J19/$J$20) * (G$20/$J$20) -> 0.11426593 | S19: =($J19/$J$20) * (H$20/$J$20) -> 0 | T19: =($J19/$J$20) * (I$20/$J$20) -> 0.75415512 | V19: Cohen's Kappa | W19: =1-W17/W18 -> 0.81962025 | X19: 1 - (D_obs / D_exp)
A20: =Wumple!A20 -> Transition | B20: =Wumple!B20 -> anyButton (Flash ⇒ Off) | C20: ='GPT-5 Generation'!C20 -> 0 | D20: ='Claude Sonnet 4.5 Gen'!C20 -> 0 | F20: Column Totals | G20: =SUM(G17:G19) -> 5 | H20: =SUM(H17:H19) -> 0 | I20: =SUM(I17:I19) -> 33 | J20: =SUM(G17:I19) -> 38
A21: =Wumple!A21 -> Region | B21: =Wumple!B21 -> WatchMode | C21: ='GPT-5 Generation'!C21 -> 1 | D21: ='Claude Sonnet 4.5 Gen'!C21 -> 1
A22: =Wumple!A22 -> State | B22: =Wumple!B22 -> Initial state (WatchMode → AlarmOff) | C22: ='GPT-5 Generation'!C22 -> 0.5 | D22: ='Claude Sonnet 4.5 Gen'!C22 -> 0.5 | F22: Confusion Matrix (Composite State)
A23: =Wumple!A23 -> Composite State | B23: =Wumple!B23 -> AlarmOff | C23: ='GPT-5 Generation'!C23 -> 0 | D23: ='Claude Sonnet 4.5 Gen'!C23 -> 0 | F23: Composite State | G23: 0 | H23: 0.5 | I23: 1 | J23: Row Totals | L23: Global | M23: 0 | N23: 0.5 | O23: 1 | Q23: Global | R23: 0 | S23: 0.5 | T23: 1 | V23: ="Metrics" & " " & F23 -> Metrics Composite State | W23: Value | X23: Note
A24: =Wumple!A24 -> State | B24: =Wumple!B24 -> Initial state (AlarmOff → TimeKeepingMode) | C24: ='GPT-5 Generation'!C24 -> 1 | D24: ='Claude Sonnet 4.5 Gen'!C24 -> 1 | F24: 0 | G24: =COUNTIFS($A$2:$A$116,$F$23,$C$2:$C$116,$F24,$D$2:$D$116,G$23) -> 2 | H24: =COUNTIFS($A$2:$A$116,$F$23,$C$2:$C$116,$F24,$D$2:$D$116,H$23) -> 0 | I24: =COUNTIFS($A$2:$A$109,$F$23,$C$2:$C$109,$F24,$D$2:$D$109,I$23) + MAX(D114-C114,0) -> 0 | J24: =SUM(G24:I24) -> 2 | L24: 0 | M24: =ABS(G$2-$F24)/1 -> 0 | N24: =ABS(H$2-$F24)/1 -> 0.5 | O24: =ABS(I$2-$F24)/1 -> 1 | Q24: 0 | R24: =($J24/$J$27) * (G$27/$J$27) -> 0.11111111 | S24: =($J24/$J$27) * (H$27/$J$27) -> 0 | T24: =($J24/$J$27) * (I$27/$J$27) -> 0.22222222 | V24: Observed Weighted Disagreement (D_obs) | W24: =SUMPRODUCT(G24:I26, M24:O26) /$J$27 -> 0 | X24: Sum of (confusion-matrix counts × weights) divided by total items.
A25: =Wumple!A25 -> Composite State | B25: =Wumple!B25 -> TimeKeepingMode | C25: ='GPT-5 Generation'!C25 -> 1 | D25: ='Claude Sonnet 4.5 Gen'!C25 -> 1 | F25: 0.5 | G25: =COUNTIFS($A$2:$A$116,$F$23,$C$2:$C$116,$F25,$D$2:$D$116,G$23) -> 0 | H25: =COUNTIFS($A$2:$A$116,$F$23,$C$2:$C$116,$F25,$D$2:$D$116,H$23) -> 0 | I25: =COUNTIFS($A$2:$A$116,$F$23,$C$2:$C$116,$F25,$D$2:$D$116,I$23) -> 0 | J25: =SUM(G25:I25) -> 0 | L25: 0.5 | M25: =ABS(G$2-$F25)/1 -> 0.5 | N25: =ABS(H$2-$F25)/3 -> 0 | O25: =ABS(I$2-$F25)/1 -> 0.5 | Q25: 0.5 | R25: =($J25/$J$27) * (G$27/$J$27) -> 0 | S25: =($J25/$J$27) * (H$27/$J$27) -> 0 | T25: =($J25/$J$27) * (I$27/$J$27) -> 0 | V25: Expected Weighted Disagreement (D_exp) | W25: =SUMPRODUCT(R24:T26, M24:O26) -> 0.44444444 | X25: Sum of (expected cell proportions × weights) under chance agreement.
A26: =Wumple!A26 -> State | B26: =Wumple!B26 -> Initial state (TimeKeepingMode → Idle) | C26: ='GPT-5 Generation'!C26 -> 1 | D26: ='Claude Sonnet 4.5 Gen'!C26 -> 1 | F26: 1 | G26: =COUNTIFS($A$2:$A$109,$F$23,$C$2:$C$109,$F26,$D$2:$D$109,G$23) + MAX(C114-D114,0) -> 0 | H26: =COUNTIFS($A$2:$A$116,$F$23,$C$2:$C$116,$F26,$D$2:$D$116,H$23) -> 0 | I26: =COUNTIFS($A$2:$A$109,$F$23,$C$2:$C$109,$F26,$D$2:$D$109,I$23) + MIN(C114,D114) -> 4 | J26: =SUM(G26:I26) -> 4 | L26: 1 | M26: =ABS(G$2-$F26)/1 -> 1 | N26: =ABS(H$2-$F26)/1 -> 0.5 | O26: =ABS(I$2-$F26)/1 -> 0 | Q26: 1 | R26: =($J26/$J$27) * (G$27/$J$27) -> 0.22222222 | S26: =($J26/$J$27) * (H$27/$J$27) -> 0 | T26: =($J26/$J$27) * (I$27/$J$27) -> 0.44444444 | V26: Cohen's Kappa | W26: =1-W24/W25 -> 1 | X26: 1 - (D_obs / D_exp)
A27: =Wumple!A27 -> State | B27: =Wumple!B27 -> Idle | C27: ='GPT-5 Generation'!C27 -> 1 | D27: ='Claude Sonnet 4.5 Gen'!C27 -> 1 | F27: Column Totals | G27: =SUM(G24:G26) -> 2 | H27: =SUM(H24:H26) -> 0 | I27: =SUM(I24:I26) -> 4 | J27: =SUM(G24:I26) -> 6
A28: =Wumple!A28 -> Action | B28: =Wumple!B28 -> do / displayTime() | C28: ='GPT-5 Generation'!C28 -> 1 | D28: ='Claude Sonnet 4.5 Gen'!C28 -> 0
A29: =Wumple!A29 -> Transition | B29: =Wumple!B29 -> B2sec (Idle ⇒ Idle) | C29: ='GPT-5 Generation'!C29 -> 0.5 | D29: ='Claude Sonnet 4.5 Gen'!C29 -> 1 | F29: Confusion Matrix (Guard)
A30: =Wumple!A30 -> Action | B30: =Wumple!B30 -> toggleFlashAlert() | C30: ='GPT-5 Generation'!C30 -> 0.5 | D30: ='Claude Sonnet 4.5 Gen'!C30 -> 0 | F30: Guard | G30: 0 | H30: 0.5 | I30: 1 | J30: Row Totals | L30: Global | M30: 0 | N30: 0.5 | O30: 1 | Q30: Global | R30: 0 | S30: 0.5 | T30: 1 | V30: ="Metrics" & " " & F30 -> Metrics Guard | W30: Value | X30: Note
A31: =Wumple!A31 -> Transition | B31: =Wumple!B31 -> B (Idle ⇒ Idle) | C31: ='GPT-5 Generation'!C31 -> 1 | D31: ='Claude Sonnet 4.5 Gen'!C31 -> 1 | F31: 0 | G31: =COUNTIFS($A$2:$A$116,$F$30,$C$2:$C$116,$F31,$D$2:$D$116,G$30) -> 3 | H31: =COUNTIFS($A$2:$A$116,$F$30,$C$2:$C$116,$F31,$D$2:$D$116,H$30) -> 0 | I31: =COUNTIFS($A$2:$A$109,$F$30,$C$2:$C$109,$F31,$D$2:$D$109,I$30) + MAX(D112-C112,0) -> 0 | J31: =SUM(G31:I31) -> 3 | L31: 0 | M31: =ABS(G$2-$F31)/1 -> 0 | N31: =ABS(H$2-$F31)/1 -> 0.5 | O31: =ABS(I$2-$F31)/1 -> 1 | Q31: 0 | R31: =($J31/$J$34) * (G$34/$J$34) -> 0.5625 | S31: =($J31/$J$34) * (H$34/$J$34) -> 0 | T31: =($J31/$J$34) * (I$34/$J$34) -> 0.1875 | V31: Observed Weighted Disagreement (D_obs) | W31: =SUMPRODUCT(G31:I33, M31:O33) /$J$34 -> 0 | X31: Sum of (confusion-matrix counts × weights) divided by total items.
A32: =Wumple!A32 -> Action | B32: =Wumple!B32 -> toggleAlarm() | C32: ='GPT-5 Generation'!C32 -> 1 | D32: ='Claude Sonnet 4.5 Gen'!C32 -> 0 | F32: 0.5 | G32: =COUNTIFS($A$2:$A$116,$F$30,$C$2:$C$116,$F32,$D$2:$D$116,G$30) -> 0 | H32: =COUNTIFS($A$2:$A$116,$F$30,$C$2:$C$116,$F32,$D$2:$D$116,H$30) -> 0 | I32: =COUNTIFS($A$2:$A$116,$F$30,$C$2:$C$116,$F32,$D$2:$D$116,I$30) -> 0 | J32: =SUM(G32:I32) -> 0 | L32: 0.5 | M32: =ABS(G$2-$F32)/1 -> 0.5 | N32: =ABS(H$2-$F32)/3 -> 0 | O32: =ABS(I$2-$F32)/1 -> 0.5 | Q32: 0.5 | R32: =($J32/$J$34) * (G$34/$J$34) -> 0 | S32: =($J32/$J$34) * (H$34/$J$34) -> 0 | T32: =($J32/$J$34) * (I$34/$J$34) -> 0 | V32: Expected Weighted Disagreement (D_exp) | W32: =SUMPRODUCT(R31:T33, M31:O33) -> 0.375 | X32: Sum of (expected cell proportions × weights) under chance agreement.
A33: =Wumple!A33 -> Transition | B33: =Wumple!B33 -> C (Idle ⇒ Seconds) | C33: ='GPT-5 Generation'!C33 -> 1 | D33: ='Claude Sonnet 4.5 Gen'!C33 -> 1 | F33: 1 | G33: =COUNTIFS($A$2:$A$109,$F$30,$C$2:$C$109,$F33,$D$2:$D$109,G$30) + MAX(C112-D112,0) -> 0 | H33: =COUNTIFS($A$2:$A$116,$F$30,$C$2:$C$116,$F33,$D$2:$D$116,H$30) -> 0 | I33: =COUNTIFS($A$2:$A$109,$F$30,$C$2:$C$109,$F33,$D$2:$D$109,I$30) + MIN(C112,D112) -> 1 | J33: =SUM(G33:I33) -> 1 | L33: 1 | M33: =ABS(G$2-$F33)/1 -> 1 | N33: =ABS(H$2-$F33)/1 -> 0.5 | O33: =ABS(I$2-$F33)/1 -> 0 | Q33: 1 | R33: =($J33/$J$34) * (G$34/$J$34) -> 0.1875 | S33: =($J33/$J$34) * (H$34/$J$34) -> 0 | T33: =($J33/$J$34) * (I$34/$J$34) -> 0.0625 | V33: Cohen's Kappa | W33: =1-W31/W32 -> 1 | X33: 1 - (D_obs / D_exp)
A34: =Wumple!A34 -> Action | B34: =Wumple!B34 -> flashSeconds() | C34: ='GPT-5 Generation'!C34 -> 1 | D34: ='Claude Sonnet 4.5 Gen'!C34 -> 0 | F34: Column Totals | G34: =SUM(G31:G33) -> 3 | H34: =SUM(H31:H33) -> 0 | I34: =SUM(I31:I33) -> 1 | J34: =SUM(G31:I33) -> 4
A35: =Wumple!A35 -> Transition | B35: =Wumple!B35 -> A (TimeKeepingMode ⇒ AlarmMode) | C35: ='GPT-5 Generation'!C35 -> 1 | D35: ='Claude Sonnet 4.5 Gen'!C35 -> 1
A36: =Wumple!A36 -> State | B36: =Wumple!B36 -> Seconds | C36: ='GPT-5 Generation'!C36 -> 1 | D36: ='Claude Sonnet 4.5 Gen'!C36 -> 1 | F36: Confusion Matrix (Action)
A37: =Wumple!A37 -> Transition | B37: =Wumple!B37 -> B (Seconds ⇒ Seconds) | C37: ='GPT-5 Generation'!C37 -> 1 | D37: ='Claude Sonnet 4.5 Gen'!C37 -> 1 | F37: Action | G37: 0 | H37: 0.5 | I37: 1 | J37: Row Totals | L37: Global | M37: 0 | N37: 0.5 | O37: 1 | Q37: Global | R37: 0 | S37: 0.5 | T37: 1 | V37: ="Metrics" & " " & F37 -> Metrics Action | W37: Value | X37: Note
A38: =Wumple!A38 -> Action | B38: =Wumple!B38 -> time+=1sec | C38: ='GPT-5 Generation'!C38 -> 1 | D38: ='Claude Sonnet 4.5 Gen'!C38 -> 0.5 | F38: 0 | G38: =COUNTIFS($A$2:$A$116,F37,$C$2:$C$116,$F38,$D$2:$D$116,G37) -> 4 | H38: =COUNTIFS($A$2:$A$116,F37,$C$2:$C$116,$F38,$D$2:$D$116,H37) -> 1 | I38: =COUNTIFS($A$2:$A$109,F37,$C$2:$C$109,$F38,$D$2:$D$109,I37)+MAX(D113-C113,0) -> 0 | J38: =SUM(G38:I38) -> 5 | L38: 0 | M38: =ABS(G$2-$F38)/1 -> 0 | N38: =ABS(H$2-$F38)/1 -> 0.5 | O38: =ABS(I$2-$F38)/1 -> 1 | Q38: 0 | R38: =($J38/$J$41) * (G$41/$J$41) -> 0.083102493 | S38: =($J38/$J$41) * (H$41/$J$41) -> 0.04501385 | T38: =($J38/$J$41) * (I$41/$J$41) -> 0 | V38: Observed Weighted Disagreement (D_obs) | W38: =SUMPRODUCT(G38:I40, M38:O40) /$J$41 -> 0.68421053 | X38: Sum of (confusion-matrix counts × weights) divided by total items.
A39: =Wumple!A39 -> Transition | B39: =Wumple!B39 -> C (Seconds ⇒ Minutes) | C39: ='GPT-5 Generation'!C39 -> 1 | D39: ='Claude Sonnet 4.5 Gen'!C39 -> 1 | F39: 0.5 | G39: =COUNTIFS($A$2:$A$116,F37,$C$2:$C$116,$F39,$D$2:$D$116,G37) -> 1 | H39: =COUNTIFS($A$2:$A$116,F37,$C$2:$C$116,$F38,$D$2:$D$116,H37) -> 1 | I39: =COUNTIFS($A$2:$A$116,F37,$C$2:$C$116,$F39,$D$2:$D$116,I37) -> 0 | J39: =SUM(G39:I39) -> 2 | L39: 0.5 | M39: =ABS(G$2-$F39)/1 -> 0.5 | N39: =ABS(H$2-$F39)/3 -> 0 | O39: =ABS(I$2-$F39)/1 -> 0.5 | Q39: 0.5 | R39: =($J39/$J$41) * (G$41/$J$41) -> 0.033240997 | S39: =($J39/$J$41) * (H$41/$J$41) -> 0.01800554 | T39: =($J39/$J$41) * (I$41/$J$41) -> 0 | V39: Expected Weighted Disagreement (D_exp) | W39: =SUMPRODUCT(R38:T40, M38:O40) -> 0.69390582 | X39: Sum of (expected cell proportions × weights) under chance agreement.
A40: =Wumple!A40 -> Action | B40: =Wumple!B40 -> flashMinutes() | C40: ='GPT-5 Generation'!C40 -> 1 | D40: ='Claude Sonnet 4.5 Gen'!C40 -> 0 | F40: 1 | G40: =COUNTIFS($A$2:$A$109,F37,$C$2:$C$109,$F40,$D$2:$D$109,G37)+MAX(C113-D113,0) -> 19 | H40: =COUNTIFS($A$2:$A$116,F37,$C$2:$C$116,$F40,$D$2:$D$116,H37) -> 12 | I40: =COUNTIFS($A$2:$A$109,F37,$C$2:$C$109,$F40,$D$2:$D$109,I37) + MIN(C113,D113) -> 0 | J40: =SUM(G40:I40) -> 31 | L40: 1 | M40: =ABS(G$2-$F40)/1 -> 1 | N40: =ABS(H$2-$F40)/1 -> 0.5 | O40: =ABS(I$2-$F40)/1 -> 0 | Q40: 1 | R40: =($J40/$J$41) * (G$41/$J$41) -> 0.51523546 | S40: =($J40/$J$41) * (H$41/$J$41) -> 0.27908587 | T40: =($J40/$J$41) * (I$41/$J$41) -> 0 | V40: Cohen's Kappa | W40: =1-W38/W39 -> 0.013972056 | X40: 1 - (D_obs / D_exp)
...
