Workbook

Sheet Dishwasher
A1: Type | B1: Element
A2: Composite State | B2: DishwasherOn
A3: Region | B3: Door
A4: State | B4: initial state (⇒ Closed)
A5: State | B5: Closed
A6: Transition | B6: open (Closed ⇒ Open)
A7: Transition | B7: lock (Closed ⇒ Locked)
A8: State | B8: Open
A9: Transition | B9: close (Open ⇒ Closed)
A10: State | B10: Locked
A11: Transition | B11: unlock (Locked ⇒ Closed)
A12: Region | B12: Washer
... A55: History State | B55: additional elements

Sheet CombinedHumanGrading
A1: Type | B1: Element | C1: Claude | D1: Notes
A2: Composite State | B2: DishwasherOn | C2: 1
A3: Region | B3: Door | C3: 0
A4: State | B4: initial state (⇒ Closed) | C4: 0
A5: State | B5: Closed | C5: 0
A6: Transition | B6: open (Closed ⇒ Open) | C6: 0
A7: Transition | B7: lock (Closed ⇒ Locked) | C7: 0
A8: State | B8: Open | C8: 1
A9: Transition | B9: close (Open ⇒ Closed) | C9: 0
A10: State | B10: Locked | C10: 0
A11: Transition | B11: unlock (Locked ⇒ Closed) | C11: 0
A12: Region | B12: Washer | C12: 1 | D12: represented as whats modelled
A13: State | B13: initial state | C13: 1
A14: Transition | B14: r =1; dT=20; (initial state ⇒ Idle) | C14: 0.5 | D14: transition but no values
A15: State | B15: Idle | C15: 1
A16: Transition | B16: selectProgram(n) (Idle ⇒ Idle) | C16: 0
A17: Guard | B17: [n ≥ 1] | C17: 0
A18: Action | B18: r = n; | C18: 0
A19: Transition | B19: toggleDryingTime (Idle ⇒ Idle) | C19: 1
A20: Action | B20: if dT = 20 then dT = 40 else dT = 20; | C20: 1
A21: Transition | B21: start (Idle ⇒ Cleaning) | C21: 1
A22: Guard | B22: [door.isClosed()] | C22: 1
A23: Action | B23: door.lock(); c = 1; | C23: 1
A24: Composite State | B24: Cleaning | C24: 1
A25: State | B25: initial state (⇒ Intake) | C25: 1
A26: State | B26: Intake | C26: 1
... A32: Transition | B32: Drain ⇒ Intake | C32: 1
A33: Action | B33: c++ | C33: 0.5 | D33: it says decrement cycle? should be increment
A34: Transition | B34: (Drain ⇒ end state) | C34: 1 | D34: equivalent
A35: Guard | B35: [c ≥ r] | C35: 1
A36: History State | B36: History State for Cleaning | C36: 0 | D36: same logic but missing history state, ours does a self loop
A37: Transition | B37: toggleDryingTime (Cleaning ⇒ History State) | C37: 1
A38: Action | B38: if dT = 20 then dT = 40 else dT = 20; | C38: 1
A39: Transition | B39: Cleaning ⇒ Drying | C39: 1 | D39: same logic since ours doesnt have a end state
A40: Action | B40: door.unlock(); | C40: 1
A41: State | B41: Drying | C41: 1
A42: Transition | B42: after dT min (Drying ⇒ Idle) | C42: 1
A43: Transition | B43: extend DryingTime (Drying ⇒ Drying) | C43: 1
A44: Action | B44: dT = 40; | C44: 1
A45: Transition | B45: open (Drying ⇒ Suspended) | C45: 1 | D45: same logic
...

Sheet Gemini 3.1 Pro Preview Grading
A1: Type | B1: Element | C1: Gemini 3.1 Pro Preview Grading | D1: Notes
A2: Composite State | B2: DishwasherOn | C2: 0 | D2: No overall composite state for the dishwasher
A3: Region | B3: Door | C3: 0 | D3: No parallel region for the door
A4: State | B4: initial state (⇒ Closed) | C4: 0 | D4: No initial state for door
A5: State | B5: Closed | C5: 0 | D5: No explicit Closed state
A6: Transition | B6: open (Closed ⇒ Open) | C6: 0 | D6: No explicit open transition from Closed
A7: Transition | B7: lock (Closed ⇒ Locked) | C7: 0 | D7: Handled as an action rather than a state transition
A8: State | B8: Open | C8: 0.5 | D8: DoorOpen state exists but only during the drying phase
A9: Transition | B9: close (Open ⇒ Closed) | C9: 0.5 | D9: Close transition exists but goes directly to Drying
A10: State | B10: Locked | C10: 0 | D10: No explicit Locked state
A11: Transition | B11: unlock (Locked ⇒ Closed) | C11: 0 | D11: Handled as an action rather than a state transition
A12: Region | B12: Washer | C12: 0 | D12: No parallel region for washer
A13: State | B13: initial state | C13: 1 | D13: Initial state to Idle is present
... A55: History State | B55: additional elements | C55: 0 | D55: No incorrect additional history states

Sheet Metrics
A1: Claude Grader Human | J1: Date
A2: Type | B2: Ground Truth Count | C2: True Positive | D2: False Positive | E2: False Negative | F2: Precision | G2: Recall | H2: F1 Score | J2: May 6th, 2026
A3: Composite State | B3: =COUNTIF(Dishwasher!$A$2:$A$48, A3) -> 2 | C3: =SUMIF(CombinedHumanGrading!$A$2:$A$48, $A3, CombinedHumanGrading!$C$2:$C$48) -> 2 | D3: =SUMIF(CombinedHumanGrading!$A$49:$A$55, $A3, CombinedHumanGrading!$C$49:$C$55) -> 0 | E3: =COUNTIFS(CombinedHumanGrading!$A$2:$A$48, $A3, CombinedHumanGrading!$C$2:$C$48,0) -> 0 | F3: =IFERROR(C3 / (C3 + D3), "Not Available") -> 1 | G3: =IFERROR(C3 / B3, "Not Available") -> 1 | H3: =IFERROR(2*((F3*G3)/(F3+G3)),"Not Available") -> 1
A4: State | B4: =COUNTIF(Dishwasher!$A$2:$A$48, A4) -> 12 | C4: =SUMIF(CombinedHumanGrading!$A$2:$A$48, $A4, CombinedHumanGrading!$C$2:$C$48) -> 9 | D4: =SUMIF(CombinedHumanGrading!$A$49:$A$55, $A4, CombinedHumanGrading!$C$49:$C$55) -> 0 | E4: =COUNTIFS(CombinedHumanGrading!$A$2:$A$48, $A4, CombinedHumanGrading!$C$2:$C$48,0) -> 3 | F4: =IFERROR(C4 / (C4 + D4), "Not Available") -> 1 | G4: =IFERROR(C4 / B4, "Not Available") -> 0.75 | H4: =IFERROR(2*((F4*G4)/(F4+G4)),"Not Available") -> 0.85714286 | J4: Generation LLM
A5: Transition | B5: =COUNTIF(Dishwasher!$A$2:$A$48, A5) -> 19 | C5: =SUMIF(CombinedHumanGrading!$A$2:$A$48, $A5, CombinedHumanGrading!$C$2:$C$48) -> 13.5 | D5: =SUMIF(CombinedHumanGrading!$A$49:$A$55, $A5, CombinedHumanGrading!$C$49:$C$55) -> 0 | E5: =COUNTIFS(CombinedHumanGrading!$A$2:$A$48, $A5, CombinedHumanGrading!$C$2:$C$48,0) -> 5 | F5: =IFERROR(C5 / (C5 + D5), "Not Available") -> 1 | G5: =IFERROR(C5 / B5, "Not Available") -> 0.71052632 | H5: =IFERROR(2*((F5*G5)/(F5+G5)),"Not Available") -> 0.83076923 | J5: Claude 4.5 Sonnet
A6: Action | B6: =COUNTIF(Dishwasher!$A$2:$A$48, A6) -> 7 | C6: =SUMIF(CombinedHumanGrading!$A$2:$A$48, $A6, CombinedHumanGrading!$C$2:$C$48) -> 5.5 | D6: =SUMIF(CombinedHumanGrading!$A$49:$A$55, $A6, CombinedHumanGrading!$C$49:$C$55) -> 0 | E6: =COUNTIFS(CombinedHumanGrading!$A$2:$A$48, $A6, CombinedHumanGrading!$C$2:$C$48,0) -> 1 | F6: =IFERROR(C6 / (C6 + D6), "Not Available") -> 1 | G6: =IFERROR(C6 / B6, "Not Available") -> 0.78571429 | H6: =IFERROR(2*((F6*G6)/(F6+G6)),"Not Available") -> 0.88
A7: Region | B7: =COUNTIF(Dishwasher!$A$2:$A$48, A7) -> 2 | C7: =SUMIF(CombinedHumanGrading!$A$2:$A$48, $A7, CombinedHumanGrading!$C$2:$C$48) -> 1 | D7: =SUMIF(CombinedHumanGrading!$A$49:$A$55, $A7, CombinedHumanGrading!$C$49:$C$55) -> 0 | E7: =COUNTIFS(CombinedHumanGrading!$A$2:$A$48, $A7, CombinedHumanGrading!$C$2:$C$48,0) -> 1 | F7: =IFERROR(C7 / (C7 + D7), "Not Available") -> 1 | G7: =IFERROR(C7 / B7, "Not Available") -> 0.5 | H7: =IFERROR(2*((F7*G7)/(F7+G7)),"Not Available") -> 0.66666667 | J7: Grading LLMs
A8: History State | B8: =COUNTIF(Dishwasher!$A$2:$A$48, A8) -> 1 | C8: =SUMIF(CombinedHumanGrading!$A$2:$A$48, $A8, CombinedHumanGrading!$C$2:$C$48) -> 0 | D8: =SUMIF(CombinedHumanGrading!$A$49:$A$55, $A8, CombinedHumanGrading!$C$49:$C$55) -> 0 | E8: =COUNTIFS(CombinedHumanGrading!$A$2:$A$48, $A8, CombinedHumanGrading!$C$2:$C$48,0) -> 1 | F8: =IFERROR(C8 / (C8 + D8), "Not Available") -> Not Available | G8: =IFERROR(C8 / B8, "Not Available") -> 0 | H8: =IFERROR(2*((F8*G8)/(F8+G8)),"Not Available") -> Not Available | J8: Gemini 3.1 Pro Preview
A9: Guard | B9: =COUNTIF(Dishwasher!$A$2:$A$48, A9) -> 4 | C9: =SUMIF(CombinedHumanGrading!$A$2:$A$48, $A9, CombinedHumanGrading!$C$2:$C$48) -> 3 | D9: =SUMIF(CombinedHumanGrading!$A$49:$A$55, $A9, CombinedHumanGrading!$C$49:$C$55) -> 0 | E9: =COUNTIFS(CombinedHumanGrading!$A$2:$A$48, $A9, CombinedHumanGrading!$C$2:$C$48,0) -> 1 | F9: =IFERROR(C9 / (C9 + D9), "Not Available") -> 1 | G9: =IFERROR(C9 / B9, "Not Available") -> 0.75 | H9: =IFERROR(2*((F9*G9)/(F9+G9)),"Not Available") -> 0.85714286
A10: Overall Score | B10: =SUM(B3:B9) -> 47 | C10: =SUM(C3:C9) -> 34 | D10: =SUM(D3:D9) -> 0 | E10: =SUM(E3:E9) -> 12 | F10: =IFERROR(C10 / (C10 + D10), "Not Available") -> 1 | G10: =IFERROR(C10 / B10, "Not Available") -> 0.72340426 | H10: =IFERROR(2*((F10*G10)/(F10+G10)),"Not Available") -> 0.83950617
A12: Graded by Gemini 3.1 Pro Preview
A13: Type | B13: Ground Truth Count | C13: True Positive | D13: False Positive | E13: False Negative | F13: Precision | G13: Recall | H13: F1 Score
A14: Composite state | B14: =COUNTIF(Dishwasher!$A$2:$A$48, A14) -> 2 | C14: =SUMIF('Gemini 3.1 Pro Preview Grading'!$A$2:$A$48, $A14, 'Gemini 3.1 Pro Preview Grading'!$C$2:$C$48) -> 1 | D14: =SUMIF('Gemini 3.1 Pro Preview Grading'!$A$49:$A$55, $A14, 'Gemini 3.1 Pro Preview Grading'!$C$49:$C$55) -> 0 | E14: =COUNTIFS('Gemini 3.1 Pro Preview Grading'!$A$2:$A$48, $A3, 'Gemini 3.1 Pro Preview Grading'!$C$2:$C$48,0) -> 1 | F14: =IFERROR(C14 / (C14 + D14), "Not Available") -> 1 | G14: =IFERROR(C14 / B14, "Not Available") -> 0.5 | H14: =IFERROR(2*((F14*G14)/(F14+G14)),"Not Available") -> 0.66666667
A15: State | B15: =COUNTIF(Dishwasher!$A$2:$A$48, A15) -> 12 | C15: =SUMIF('Gemini 3.1 Pro Preview Grading'!$A$2:$A$48, $A15, 'Gemini 3.1 Pro Preview Grading'!$C$2:$C$48) -> 8.5 | D15: =SUMIF('Gemini 3.1 Pro Preview Grading'!$A$49:$A$55, $A15, 'Gemini 3.1 Pro Preview Grading'!$C$49:$C$55) -> 0 | E15: =COUNTIFS('Gemini 3.1 Pro Preview Grading'!$A$2:$A$48, $A4, 'Gemini 3.1 Pro Preview Grading'!$C$2:$C$48,0) -> 3 | F15: =IFERROR(C15 / (C15 + D15), "Not Available") -> 1 | G15: =IFERROR(C15 / B15, "Not Available") -> 0.70833333 | H15: =IFERROR(2*((F15*G15)/(F15+G15)),"Not Available") -> 0.82926829
A16: Transition | B16: =COUNTIF(Dishwasher!$A$2:$A$48, A16) -> 19 | C16: =SUMIF('Gemini 3.1 Pro Preview Grading'!$A$2:$A$48, $A16, 'Gemini 3.1 Pro Preview Grading'!$C$2:$C$48) -> 12.5 | D16: =SUMIF('Gemini 3.1 Pro Preview Grading'!$A$49:$A$55, $A16, 'Gemini 3.1 Pro Preview Grading'!$C$49:$C$55) -> 0 | E16: =COUNTIFS('Gemini 3.1 Pro Preview Grading'!$A$2:$A$48, $A5, 'Gemini 3.1 Pro Preview Grading'!$C$2:$C$48,0) -> 5 | F16: =IFERROR(C16 / (C16 + D16), "Not Available") -> 1 | G16: =IFERROR(C16 / B16, "Not Available") -> 0.65789474 | H16: =IFERROR(2*((F16*G16)/(F16+G16)),"Not Available") -> 0.79365079
A17: Action | B17: =COUNTIF(Dishwasher!$A$2:$A$48, A17) -> 7 | C17: =SUMIF('Gemini 3.1 Pro Preview Grading'!$A$2:$A$48, $A17, 'Gemini 3.1 Pro Preview Grading'!$C$2:$C$48) -> 5.5 | D17: =SUMIF('Gemini 3.1 Pro Preview Grading'!$A$49:$A$55, $A17, 'Gemini 3.1 Pro Preview Grading'!$C$49:$C$55) -> 0 | E17: =COUNTIFS('Gemini 3.1 Pro Preview Grading'!$A$2:$A$48, $A6, 'Gemini 3.1 Pro Preview Grading'!$C$2:$C$48,0) -> 1 | F17: =IFERROR(C17 / (C17 + D17), "Not Available") -> 1 | G17: =IFERROR(C17 / B17, "Not Available") -> 0.78571429 | H17: =IFERROR(2*((F17*G17)/(F17+G17)),"Not Available") -> 0.88
A18: Region | B18: =COUNTIF(Dishwasher!$A$2:$A$48, A18) -> 2 | C18: =SUMIF('Gemini 3.1 Pro Preview Grading'!$A$2:$A$48, $A18, 'Gemini 3.1 Pro Preview Grading'!$C$2:$C$48) -> 0 | D18: =SUMIF('Gemini 3.1 Pro Preview Grading'!$A$49:$A$55, $A18, 'Gemini 3.1 Pro Preview Grading'!$C$49:$C$55) -> 0 | E18: =COUNTIFS('Gemini 3.1 Pro Preview Grading'!$A$2:$A$48, $A7, 'Gemini 3.1 Pro Preview Grading'!$C$2:$C$48,0) -> 2 | F18: =IFERROR(C18 / (C18 + D18), "Not Available") -> Not Available | G18: =IFERROR(C18 / B18, "Not Available") -> 0 | H18: =IFERROR(2*((F18*G18)/(F18+G18)),"Not Available") -> Not Available
A19: History State | B19: =COUNTIF(Dishwasher!$A$2:$A$48, A19) -> 1 | C19: =SUMIF('Gemini 3.1 Pro Preview Grading'!$A$2:$A$48, $A19, 'Gemini 3.1 Pro Preview Grading'!$C$2:$C$48) -> 0 | D19: =SUMIF('Gemini 3.1 Pro Preview Grading'!$A$49:$A$55, $A19, 'Gemini 3.1 Pro Preview Grading'!$C$49:$C$55) -> 0 | E19: =COUNTIFS('Gemini 3.1 Pro Preview Grading'!$A$2:$A$48, $A8, 'Gemini 3.1 Pro Preview Grading'!$C$2:$C$48,0) -> 1 | F19: =IFERROR(C19 / (C19 + D19), "Not Available") -> Not Available | G19: =IFERROR(C19 / B19, "Not Available") -> 0 | H19: =IFERROR(2*((F19*G19)/(F19+G19)),"Not Available") -> Not Available
A20: Guard | B20: =COUNTIF(Dishwasher!$A$2:$A$48, A20) -> 4 | C20: =SUMIF('Gemini 3.1 Pro Preview Grading'!$A$2:$A$48, $A20, 'Gemini 3.1 Pro Preview Grading'!$C$2:$C$48) -> 2 | D20: =SUMIF('Gemini 3.1 Pro Preview Grading'!$A$49:$A$55, $A20, 'Gemini 3.1 Pro Preview Grading'!$C$49:$C$55) -> 0 | E20: =COUNTIFS('Gemini 3.1 Pro Preview Grading'!$A$2:$A$48, $A9, 'Gemini 3.1 Pro Preview Grading'!$C$2:$C$48,0) -> 2 | F20: =IFERROR(C20 / (C20 + D20), "Not Available") -> 1 | G20: =IFERROR(C20 / B20, "Not Available") -> 0.5 | H20: =IFERROR(2*((F20*G20)/(F20+G20)),"Not Available") -> 0.66666667
A21: Overall Score | B21: =SUM(B14:B20) -> 47 | C21: =SUM(C14:C20) -> 29.5 | D21: =SUM(D14:D20) -> 0 | E21: =SUM(E14:E20) -> 15 | F21: =IFERROR(C21 / (C21 + D21), "Not Available") -> 1 | G21: =IFERROR(C21 / B21, "Not Available") -> 0.62765957 | H21: =IFERROR(2*((F21*G21)/(F21+G21)),"Not Available") -> 0.77124183

Sheet Inter-rater
A1: Type | B1: Element | C1: CombinedHumanGrading | D1: Gemini 3.1 Pro Preview | F1: Confusion Matrix | L1: Cohen's Kappa
A2: =CombinedHumanGrading!A2 -> Composite State | B2: =CombinedHumanGrading!B2 -> DishwasherOn | C2: =CombinedHumanGrading!C2 -> 1 | D2: ='Gemini 3.1 Pro Preview Grading'!C2 -> 0 | F2: Global | G2: 0 | H2: 0.5 | I2: 1 | J2: Row Totals | L2: Metric | M2: Value | N2: Note
A3: =CombinedHumanGrading!A3 -> Region | B3: =CombinedHumanGrading!B3 -> Door | C3: =CombinedHumanGrading!C3 -> 0 | D3: ='Gemini 3.1 Pro Preview Grading'!C3 -> 0 | F3: 0 | G3: =COUNTIFS($C$2:$C$92, $F3, $D$2:$D$92, G$2) -> 18 | H3: =COUNTIFS($C$2:$C$48, $F3, $D$2:$D$48, H$2) -> 1 | I3: =COUNTIFS($C$2:$C$48, $F3, $D$2:$D$48, I$2)+MAX(D49-C49,0)+MAX(D50-C50,0)+MAX(D51-C51,0)+MAX(D52-C52,0)+MAX(D53-C53,0)+MAX(D54-C54,0)+MAX(D55-C55,0) -> 0 | J3: =SUM(G3:I3) -> 19 | L3: Observed Agreement (Po) | M3: =(G3+H4+I5)/COUNTA($C$2:$C$102) -> 0.81481481 | N3: This sums the diagonal of your matrix divided by total rows.
A4: =CombinedHumanGrading!A4 -> State | B4: =CombinedHumanGrading!B4 -> initial state (⇒ Closed) | C4: =CombinedHumanGrading!C4 -> 0 | D4: ='Gemini 3.1 Pro Preview Grading'!C4 -> 0 | F4: 0.5 | G4: =COUNTIFS($C$2:$C$48, $F4, $D$2:$D$48, G$2) -> 1 | H4: =COUNTIFS($C$2:$C$48, $F4, $D$2:$D$48, H$2) -> 0 | I4: =COUNTIFS($C$2:$C$48, $F4, $D$2:$D$48, I$2) -> 1 | J4: =SUM(G4:I4) -> 2 | L4: Expected Agreement (Pe) | M4: {=SUMPRODUCT(J3:J5/COUNTA($C$2:$C$102), TRANSPOSE(G6:I6)/COUNTA($C$2:$C$102))} -> 0.45233196 | N4: This computes the sum of row proportion times column proportion.
A5: =CombinedHumanGrading!A5 -> State | B5: =CombinedHumanGrading!B5 -> Closed | C5: =CombinedHumanGrading!C5 -> 0 | D5: ='Gemini 3.1 Pro Preview Grading'!C5 -> 0 | F5: 1 | G5: =COUNTIFS($C$2:$C$48, $F5, $D$2:$D$48, G$2)+MAX(C49-D49,0)+MAX(C50-D50,0)+MAX(C51-D51,0)+MAX(C52-D52,0)+MAX(C53-D53,0)+MAX(C54-D54,0)+MAX(C55-D55,0) -> 3 | H5: =COUNTIFS($C$2:$C$48, $F5, $D$2:$D$48, H$2) -> 4 | I5: =COUNTIFS($C$2:$C$48, $F5, $D$2:$D$48, I$2)+ SUM(MIN(C49,D49), MIN(C50,D50), MIN(C51,D51), MIN(C52,D52), MIN(C53,D53), MIN(C54,D54), MIN(C55,D55)) -> 26 | J5: =SUM(G5:I5) -> 33 | L5: Cohen's Kappa | M5: =(M3-M4)/(1-M4) -> 0.661866 | N5: (Po - Pe) / (1 - Pe)
A6: =CombinedHumanGrading!A6 -> Transition | B6: =CombinedHumanGrading!B6 -> open (Closed ⇒ Open) | C6: =CombinedHumanGrading!C6 -> 0 | D6: ='Gemini 3.1 Pro Preview Grading'!C6 -> 0 | F6: Column Totals | G6: =SUM(G3:G5) -> 22 | H6: =SUM(H3:H5) -> 5 | I6: =SUM(I3:I5) -> 27
A7: =CombinedHumanGrading!A7 -> Transition | B7: =CombinedHumanGrading!B7 -> lock (Closed ⇒ Locked) | C7: =CombinedHumanGrading!C7 -> 0 | D7: ='Gemini 3.1 Pro Preview Grading'!C7 -> 0
A8: =CombinedHumanGrading!A8 -> State | B8: =CombinedHumanGrading!B8 -> Open | C8: =CombinedHumanGrading!C8 -> 1 | D8: ='Gemini 3.1 Pro Preview Grading'!C8 -> 0.5 | F8: Confusion Matrix (State) | L8: Cohen's Kappa (State)
A9: =CombinedHumanGrading!A9 -> Transition | B9: =CombinedHumanGrading!B9 -> close (Open ⇒ Closed) | C9: =CombinedHumanGrading!C9 -> 0 | D9: ='Gemini 3.1 Pro Preview Grading'!C9 -> 0.5 | F9: State | G9: 0 | H9: 0.5 | I9: 1 | J9: Row Totals | L9: Metric | M9: Value | N9: Note
A10: =CombinedHumanGrading!A10 -> State | B10: =CombinedHumanGrading!B10 -> Locked | C10: =CombinedHumanGrading!C10 -> 0 | D10: ='Gemini 3.1 Pro Preview Grading'!C10 -> 0 | F10: 0 | G10: =COUNTIFS($A$2:$A$92,$F$9,$C$2:$C$92,$F10,$D$2:$D$92,G$9) -> 4 | H10: =COUNTIFS($A$2:$A$92,$F$9,$C$2:$C$92,$F10,$D$2:$D$92,H$9) -> 0 | I10: =COUNTIFS($A$2:$A$48,$F$9,$C$2:$C$48,$F10,$D$2:$D$48,I$9)+MAX(D49-C49,0) -> 0 | J10: =SUM(G10:I10) -> 4 | L10: Observed Agreement (Po) | M10: =(G10+H11+I12)/COUNTIF($A$2:$A$102,F9) -> 0.92307692 | N10: This sums the diagonal of your matrix divided by total rows.
A11: =CombinedHumanGrading!A11 -> Transition | B11: =CombinedHumanGrading!B11 -> unlock (Locked ⇒ Closed) | C11: =CombinedHumanGrading!C11 -> 0 | D11: ='Gemini 3.1 Pro Preview Grading'!C11 -> 0 | F11: 0.5 | G11: =COUNTIFS($A$2:$A$92,$F$9,$C$2:$C$92,$F11,$D$2:$D$92,G$9) -> 0 | H11: =COUNTIFS($A$2:$A$92,$F$9,$C$2:$C$92,$F11,$D$2:$D$92,H$9) -> 0 | I11: =COUNTIFS($A$2:$A$92,$F$9,$C$2:$C$92,$F11,$D$2:$D$92,I$9) -> 0 | J11: =SUM(G11:I11) -> 0 | L11: Expected Agreement (Pe) | M11: {=SUMPRODUCT(J10:J12/COUNTIF($A$2:$A$102,F9), TRANSPOSE(G13:I13)/COUNTIF($A$2:$A$102,F9))} -> 0.52071006 | N11: This computes the sum of row proportion times column proportion.
A12: =CombinedHumanGrading!A12 -> Region | B12: =CombinedHumanGrading!B12 -> Washer | C12: =CombinedHumanGrading!C12 -> 1 | D12: ='Gemini 3.1 Pro Preview Grading'!C12 -> 0 | F12: 1 | G12: =COUNTIFS($A$2:$A$48,$F$9,$C$2:$C$48,$F12,$D$2:$D$48,G$9)+MAX(C49-D49,0) -> 0 | H12: =COUNTIFS($A$2:$A$92,$F$9,$C$2:$C$92,$F12,$D$2:$D$92,H$9) -> 1 | I12: =COUNTIFS($A$2:$A$48,$F$9,$C$2:$C$48,$F12,$D$2:$D$48,I$9)+MIN(C49-D49) -> 8 | J12: =SUM(G12:I12) -> 9 | L12: Cohen's Kappa | M12: =(M10-M11)/(1-M11) -> 0.83950617 | N12: (Po - Pe) / (1 - Pe)
A13: =CombinedHumanGrading!A13 -> State | B13: =CombinedHumanGrading!B13 -> initial state | C13: =CombinedHumanGrading!C13 -> 1 | D13: ='Gemini 3.1 Pro Preview Grading'!C13 -> 1 | F13: Column Totals | G13: =SUM(G10:G12) -> 4 | H13: =SUM(H10:H12) -> 1 | I13: =SUM(I10:I12) -> 8
A14: =CombinedHumanGrading!A14 -> Transition | B14: =CombinedHumanGrading!B14 -> r =1; dT=20; (initial state ⇒ Idle) | C14: =CombinedHumanGrading!C14 -> 0.5 | D14: ='Gemini 3.1 Pro Preview Grading'!C14 -> 0
A15: =CombinedHumanGrading!A15 -> State | B15: =CombinedHumanGrading!B15 -> Idle | C15: =CombinedHumanGrading!C15 -> 1 | D15: ='Gemini 3.1 Pro Preview Grading'!C15 -> 1 | F15: Confusion Matrix (Transition) | L15: Cohen's Kappa (Transition)
A16: =CombinedHumanGrading!A16 -> Transition | B16: =CombinedHumanGrading!B16 -> selectProgram(n) (Idle ⇒ Idle) | C16: =CombinedHumanGrading!C16 -> 0 | D16: ='Gemini 3.1 Pro Preview Grading'!C16 -> 0 | F16: Transition | G16: 0 | H16: 0.5 | I16: 1 | J16: Row Totals | L16: Metric | M16: Value | N16: Note
A17: =CombinedHumanGrading!A17 -> Guard | B17: =CombinedHumanGrading!B17 -> [n ≥ 1] | C17: =CombinedHumanGrading!C17 -> 0 | D17: ='Gemini 3.1 Pro Preview Grading'!C17 -> 0 | F17: 0 | G17: =COUNTIFS($A$2:$A$92,$F$16,$C$2:$C$92,$F17,$D$2:$D$92,G$16) -> 5 | H17: =COUNTIFS($A$2:$A$92,$F$16,$C$2:$C$92,$F17,$D$2:$D$92,H$16) -> 1 | I17: =COUNTIFS($A$2:$A$48,$F$16,$C$2:$C$48,$F17,$D$2:$D$48,I$16) + MAX(D50-C50,0) -> 0 | J17: =SUM(G17:I17) -> 6 | L17: Observed Agreement (Po) | M17: =(G17+H18+I19)/COUNTIF($A$2:$A$102,F16) -> 0.8 | N17: This sums the diagonal of your matrix divided by total rows.
A18: =CombinedHumanGrading!A18 -> Action | B18: =CombinedHumanGrading!B18 -> r = n; | C18: =CombinedHumanGrading!C18 -> 0 | D18: ='Gemini 3.1 Pro Preview Grading'!C18 -> 0 | F18: 0.5 | G18: =COUNTIFS($A$2:$A$92,$F$16,$C$2:$C$92,$F18,$D$2:$D$92,G$16) -> 1 | H18: =COUNTIFS($A$2:$A$92,$F$16,$C$2:$C$92,$F18,$D$2:$D$92,H$16) -> 0 | I18: =COUNTIFS($A$2:$A$92,$F$16,$C$2:$C$92,$F18,$D$2:$D$92,I$16) -> 0 | J18: =SUM(G18:I18) -> 1 | L18: Expected Agreement (Pe) | M18: {=SUMPRODUCT(J17:J19/COUNTIF($A$2:$A$102,F16), TRANSPOSE(G20:I20)/COUNTIF($A$2:$A$102,F16))} -> 0.455 | N18: This computes the sum of row proportion times column proportion.
A19: =CombinedHumanGrading!A19 -> Transition | B19: =CombinedHumanGrading!B19 -> toggleDryingTime (Idle ⇒ Idle) | C19: =CombinedHumanGrading!C19 -> 1 | D19: ='Gemini 3.1 Pro Preview Grading'!C19 -> 1 | F19: 1 | G19: =COUNTIFS($A$2:$A$48,$F$16,$C$2:$C$48,$F19,$D$2:$D$48,G$16)+MAX(C50-D50,0) -> 0 | H19: =COUNTIFS($A$2:$A$92,$F$16,$C$2:$C$92,$F19,$D$2:$D$92,H$16) -> 2 | I19: =COUNTIFS($A$2:$A$48,$F$16,$C$2:$C$48,$F19,$D$2:$D$48,I$16) + MIN(C50,D50) -> 11 | J19: =SUM(G19:I19) -> 13 | L19: Cohen's Kappa | M19: =(M17-M18)/(1-M18) -> 0.63302752 | N19: (Po - Pe) / (1 - Pe)
A20: =CombinedHumanGrading!A20 -> Action | B20: =CombinedHumanGrading!B20 -> if dT = 20 then dT = 40 else dT = 20; | C20: =CombinedHumanGrading!C20 -> 1 | D20: ='Gemini 3.1 Pro Preview Grading'!C20 -> 1 | F20: Column Totals | G20: =SUM(G17:G19) -> 6 | H20: =SUM(H17:H19) -> 3 | I20: =SUM(I17:I19) -> 11
A21: =CombinedHumanGrading!A21 -> Transition | B21: =CombinedHumanGrading!B21 -> start (Idle ⇒ Cleaning) | C21: =CombinedHumanGrading!C21 -> 1 | D21: ='Gemini 3.1 Pro Preview Grading'!C21 -> 1
A22: =CombinedHumanGrading!A22 -> Guard | B22: =CombinedHumanGrading!B22 -> [door.isClosed()] | C22: =CombinedHumanGrading!C22 -> 1 | D22: ='Gemini 3.1 Pro Preview Grading'!C22 -> 0 | F22: Confusion Matrix (Composite State) | L22: Cohen's Kappa (Composite State)
A23: =CombinedHumanGrading!A23 -> Action | B23: =CombinedHumanGrading!B23 -> door.lock(); c = 1; | C23: =CombinedHumanGrading!C23 -> 1 | D23: ='Gemini 3.1 Pro Preview Grading'!C23 -> 0.5 | F23: Composite State | G23: 0 | H23: 0.5 | I23: 1 | J23: Row Totals | L23: Metric | M23: Value | N23: Note
A24: =CombinedHumanGrading!A24 -> Composite State | B24: =CombinedHumanGrading!B24 -> Cleaning | C24: =CombinedHumanGrading!C24 -> 1 | D24: ='Gemini 3.1 Pro Preview Grading'!C24 -> 1 | F24: 0 | G24: =COUNTIFS($A$2:$A$92,$F$23,$C$2:$C$92,$F24,$D$2:$D$92,G$23) -> 1 | H24: =COUNTIFS($A$2:$A$92,$F$23,$C$2:$C$92,$F24,$D$2:$D$92,H$23) -> 0 | I24: =COUNTIFS($A$2:$A$48,$F$23,$C$2:$C$48,$F24,$D$2:$D$48,I$23) + MAX(D53-C53,0) -> 0 | J24: =SUM(G24:I24) -> 1 | L24: Observed Agreement (Po) | M24: =(G24+H25+I26)/COUNTIF($A$2:$A$102,F23) -> 0.66666667 | N24: This sums the diagonal of your matrix divided by total rows.
A25: =CombinedHumanGrading!A25 -> State | B25: =CombinedHumanGrading!B25 -> initial state (⇒ Intake) | C25: =CombinedHumanGrading!C25 -> 1 | D25: ='Gemini 3.1 Pro Preview Grading'!C25 -> 1 | F25: 0.5 | G25: =COUNTIFS($A$2:$A$92,$F$23,$C$2:$C$92,$F25,$D$2:$D$92,G$23) -> 0 | H25: =COUNTIFS($A$2:$A$92,$F$23,$C$2:$C$92,$F25,$D$2:$D$92,H$23) -> 0 | I25: =COUNTIFS($A$2:$A$92,$F$23,$C$2:$C$92,$F25,$D$2:$D$92,I$23) -> 0 | J25: =SUM(G25:I25) -> 0 | L25: Expected Agreement (Pe) | M25: {=SUMPRODUCT(J24:J26/COUNTIF($A$2:$A$102,F23), TRANSPOSE(G27:I27)/COUNTIF($A$2:$A$102,F23))} -> 0.44444444 | N25: This computes the sum of row proportion times column proportion.
A26: =CombinedHumanGrading!A26 -> State | B26: =CombinedHumanGrading!B26 -> Intake | C26: =CombinedHumanGrading!C26 -> 1 | D26: ='Gemini 3.1 Pro Preview Grading'!C26 -> 1 | F26: 1 | G26: =COUNTIFS($A$2:$A$48,$F$23,$C$2:$C$48,$F26,$D$2:$D$48,G$23) + MAX(C53-D53,0) -> 1 | H26: =COUNTIFS($A$2:$A$92,$F$23,$C$2:$C$92,$F26,$D$2:$D$92,H$23) -> 0 | I26: =COUNTIFS($A$2:$A$48,$F$23,$C$2:$C$48,$F26,$D$2:$D$48,I$23) + MIN(C53,D53) -> 1 | J26: =SUM(G26:I26) -> 2 | L26: Cohen's Kappa | M26: =(M24-M25)/(1-M25) -> 0.4 | N26: (Po - Pe) / (1 - Pe)
A27: =CombinedHumanGrading!A27 -> Transition | B27: =CombinedHumanGrading!B27 -> Intake ⇒ Washing | C27: =CombinedHumanGrading!C27 -> 1 | D27: ='Gemini 3.1 Pro Preview Grading'!C27 -> 1 | F27: Column Totals | G27: =SUM(G24:G26) -> 2 | H27: =SUM(H24:H26) -> 0 | I27: =SUM(I24:I26) -> 1
A28: =CombinedHumanGrading!A28 -> State | B28: =CombinedHumanGrading!B28 -> Washing | C28: =CombinedHumanGrading!C28 -> 1 | D28: ='Gemini 3.1 Pro Preview Grading'!C28 -> 1
A29: =CombinedHumanGrading!A29 -> Transition | B29: =CombinedHumanGrading!B29 -> after 10 min (Washing ⇒ Drain) | C29: =CombinedHumanGrading!C29 -> 1 | D29: ='Gemini 3.1 Pro Preview Grading'!C29 -> 1 | F29: Confusion Matrix (Guard) | L29: Cohen's Kappa (Guard)
A30: =CombinedHumanGrading!A30 -> State | B30: =CombinedHumanGrading!B30 -> Drain | C30: =CombinedHumanGrading!C30 -> 1 | D30: ='Gemini 3.1 Pro Preview Grading'!C30 -> 1 | F30: Guard | G30: 0 | H30: 0.5 | I30: 1 | J30: Row Totals | L30: Metric | M30: Value | N30: Note
A31: =CombinedHumanGrading!A31 -> Guard | B31: =CombinedHumanGrading!B31 -> [c < r] | C31: =CombinedHumanGrading!C31 -> 1 | D31: ='Gemini 3.1 Pro Preview Grading'!C31 -> 1 | F31: 0 | G31: =COUNTIFS($A$2:$A$92,$F$30,$C$2:$C$92,$F31,$D$2:$D$92,G$30) -> 2 | H31: =COUNTIFS($A$2:$A$92,$F$30,$C$2:$C$92,$F31,$D$2:$D$92,H$30) -> 0 | I31: =COUNTIFS($A$2:$A$48,$F$30,$C$2:$C$48,$F31,$D$2:$D$48,I$30) + MAX(D51-C51,0) -> 0 | J31: =SUM(G31:I31) -> 2 | L31: Observed Agreement (Po) | M31: =(G31+H32+I33)/COUNTIF($A$2:$A$102,F30) -> 0.8 | N31: This sums the diagonal of your matrix divided by total rows.
A32: =CombinedHumanGrading!A32 -> Transition | B32: =CombinedHumanGrading!B32 -> Drain ⇒ Intake | C32: =CombinedHumanGrading!C32 -> 1 | D32: ='Gemini 3.1 Pro Preview Grading'!C32 -> 1 | F32: 0.5 | G32: =COUNTIFS($A$2:$A$92,$F$30,$C$2:$C$92,$F32,$D$2:$D$92,G$30) -> 0 | H32: =COUNTIFS($A$2:$A$92,$F$30,$C$2:$C$92,$F32,$D$2:$D$92,H$30) -> 0 | I32: =COUNTIFS($A$2:$A$92,$F$30,$C$2:$C$92,$F32,$D$2:$D$92,I$30) -> 0 | J32: =SUM(G32:I32) -> 0 | L32: Expected Agreement (Pe) | M32: {=SUMPRODUCT(J31:J33/COUNTIF($A$2:$A$102,F30), TRANSPOSE(G34:I34)/COUNTIF($A$2:$A$102,F30))} -> 0.48 | N32: This computes the sum of row proportion times column proportion.
A33: =CombinedHumanGrading!A33 -> Action | B33: =CombinedHumanGrading!B33 -> c++ | C33: =CombinedHumanGrading!C33 -> 0.5 | D33: ='Gemini 3.1 Pro Preview Grading'!C33 -> 1 | F33: 1 | G33: =COUNTIFS($A$2:$A$48,$F$30,$C$2:$C$48,$F33,$D$2:$D$48,G$30) + MAX(C51-D51,0) -> 1 | H33: =COUNTIFS($A$2:$A$92,$F$30,$C$2:$C$92,$F33,$D$2:$D$92,H$30) -> 0 | I33: =COUNTIFS($A$2:$A$48,$F$30,$C$2:$C$48,$F33,$D$2:$D$48,I$30) + MIN(C51,D51) -> 2 | J33: =SUM(G33:I33) -> 3 | L33: Cohen's Kappa | M33: =(M31-M32)/(1-M32) -> 0.61538462 | N33: (Po - Pe) / (1 - Pe)
A34: =CombinedHumanGrading!A34 -> Transition | B34: =CombinedHumanGrading!B34 -> (Drain ⇒ end state) | C34: =CombinedHumanGrading!C34 -> 1 | D34: ='Gemini 3.1 Pro Preview Grading'!C34 -> 1 | F34: Column Totals | G34: =SUM(G31:G33) -> 3 | H34: =SUM(H31:H33) -> 0 | I34: =SUM(I31:I33) -> 2
A35: =CombinedHumanGrading!A35 -> Guard | B35: =CombinedHumanGrading!B35 -> [c ≥ r] | C35: =CombinedHumanGrading!C35 -> 1 | D35: ='Gemini 3.1 Pro Preview Grading'!C35 -> 1
A36: =CombinedHumanGrading!A36 -> History State | B36: =CombinedHumanGrading!B36 -> History State for Cleaning | C36: =CombinedHumanGrading!C36 -> 0 | D36: ='Gemini 3.1 Pro Preview Grading'!C36 -> 0 | F36: Confusion Matrix (Action) | L36: Cohen's Kappa (Action)
A37: =CombinedHumanGrading!A37 -> Transition | B37: =CombinedHumanGrading!B37 -> toggleDryingTime (Cleaning ⇒ History State) | C37: =CombinedHumanGrading!C37 -> 1 | D37: ='Gemini 3.1 Pro Preview Grading'!C37 -> 0.5 | F37: Action | G37: 0 | H37: 0.5 | I37: 1 | J37: Row Totals | L37: Metric | M37: Value | N37: Note
A38: =CombinedHumanGrading!A38 -> Action | B38: =CombinedHumanGrading!B38 -> if dT = 20 then dT = 40 else dT = 20; | C38: =CombinedHumanGrading!C38 -> 1 | D38: ='Gemini 3.1 Pro Preview Grading'!C38 -> 1 | F38: 0 | G38: =COUNTIFS($A$2:$A$92,$F$37,$C$2:$C$92,$F38,$D$2:$D$92,G$37) -> 2 | H38: =COUNTIFS($A$2:$A$92,$F$37,$C$2:$C$92,$F38,$D$2:$D$92,H$37) -> 0 | I38: =COUNTIFS($A$2:$A$48,$F$37,$C$2:$C$48,$F38,$D$2:$D$48,I$37)+MAX(D52-C52,0) -> 0 | J38: =SUM(G38:I38) -> 2 | L38: Observed Agreement (Po) | M38: =(G38+H39+I40)/COUNTIF($A$2:$A$102,F37) -> 0.75 | N38: This sums the diagonal of your matrix divided by total rows.
A39: =CombinedHumanGrading!A39 -> Transition | B39: =CombinedHumanGrading!B39 -> Cleaning ⇒ Drying | C39: =CombinedHumanGrading!C39 -> 1 | D39: ='Gemini 3.1 Pro Preview Grading'!C39 -> 1 | F39: 0.5 | G39: =COUNTIFS($A$2:$A$92,$F$37,$C$2:$C$92,$F39,$D$2:$D$92,G$37) -> 0 | H39: =COUNTIFS($A$2:$A$92,$F$37,$C$2:$C$92,$F39,$D$2:$D$92,H$37) -> 0 | I39: =COUNTIFS($A$2:$A$92,$F$37,$C$2:$C$92,$F39,$D$2:$D$92,I$37) -> 1 | J39: =SUM(G39:I39) -> 1 | L39: Expected Agreement (Pe) | M39: {=SUMPRODUCT(J38:J40/COUNTIF($A$2:$A$102,F37), TRANSPOSE(G41:I41)/COUNTIF($A$2:$A$102,F37))} -> 0.46875 | N39: This computes the sum of row proportion times column proportion.
A40: =CombinedHumanGrading!A40 -> Action | B40: =CombinedHumanGrading!B40 -> door.unlock(); | C40: =CombinedHumanGrading!C40 -> 1 | D40: ='Gemini 3.1 Pro Preview Grading'!C40 -> 1 | F40: 1 | G40: =COUNTIFS($A$2:$A$48,$F$37,$C$2:$C$48,$F40,$D$2:$D$48,G$37)+MAX(C52-D52,0) -> 0 | H40: =COUNTIFS($A$2:$A$92,$F$37,$C$2:$C$92,$F40,$D$2:$D$92,H$37) -> 1 | I40: =COUNTIFS($A$2:$A$48,$F$37,$C$2:$C$48,$F40,$D$2:$D$48,I$37) + MIN(C52,D52) -> 4 | J40: =SUM(G40:I40) -> 5 | L40: Cohen's Kappa | M40: =(M38-M39)/(1-M39) -> 0.52941176 | N40: (Po - Pe) / (1 - Pe)
...

Sheet Weighted Cohens Kappa
A1: Type | B1: Element | C1: CombinedHumanGrading | D1: Gemini 3.1 Pro Preview | F1: Confusion Matrix | L1: Weight Matrix
A2: =CombinedHumanGrading!A2 -> Composite State | B2: =CombinedHumanGrading!B2 -> DishwasherOn | C2: =CombinedHumanGrading!C2 -> 1 | D2: ='Gemini 3.1 Pro Preview Grading'!C2 -> 0 | F2: Global | G2: 0 | H2: 0.5 | I2: 1 | J2: Row Totals | L2: Global | M2: 0 | N2: 0.5 | O2: 1 | Q2: Global | R2: 0 | S2: 0.5 | T2: 1 | V2: ="Metrics" & " " & F2 -> Metrics Global | W2: Value | X2: Note
A3: =CombinedHumanGrading!A3 -> Region | B3: =CombinedHumanGrading!B3 -> Door | C3: =CombinedHumanGrading!C3 -> 0 | D3: ='Gemini 3.1 Pro Preview Grading'!C3 -> 0 | F3: 0 | G3: =COUNTIFS($C$2:$C$92, $F3, $D$2:$D$92, G$2) -> 18 | H3: =COUNTIFS($C$2:$C$48, $F3, $D$2:$D$48, H$2) -> 1 | I3: =COUNTIFS($C$2:$C$48, $F3, $D$2:$D$48, I$2)+MAX(D49-C49,0)+MAX(D50-C50,0)+MAX(D51-C51,0)+MAX(D52-C52,0)+MAX(D53-C53,0)+MAX(D54-C54,0)+MAX(D55-C55,0) -> 0 | J3: =SUM(G3:I3) -> 19 | L3: 0 | M3: =ABS(G$2-$F3)/1 -> 0 | N3: =ABS(H$2-$F3)/1 -> 0.5 | O3: =ABS(I$2-$F3)/1 -> 1 | Q3: 0 | R3: =($J3/$J$6) * (G$6/$J$6) -> 0.14334705 | S3: =($J3/$J$6) * (H$6/$J$6) -> 0.032578875 | T3: =($J3/$J$6) * (I$6/$J$6) -> 0.17592593 | V3: Observed Weighted Disagreement (D_obs) | W3: =SUMPRODUCT(G3:I5, M3:O5) /$J$6 -> 0.12037037 | X3: Sum of (confusion-matrix counts × weights) divided by total items.
A4: =CombinedHumanGrading!A4 -> State | B4: =CombinedHumanGrading!B4 -> initial state (⇒ Closed) | C4: =CombinedHumanGrading!C4 -> 0 | D4: ='Gemini 3.1 Pro Preview Grading'!C4 -> 0 | F4: 0.5 | G4: =COUNTIFS($C$2:$C$48, $F4, $D$2:$D$48, G$2) -> 1 | H4: =COUNTIFS($C$2:$C$48, $F4, $D$2:$D$48, H$2) -> 0 | I4: =COUNTIFS($C$2:$C$48, $F4, $D$2:$D$48, I$2) -> 1 | J4: =SUM(G4:I4) -> 2 | L4: 0.5 | M4: =ABS(G$2-$F4)/1 -> 0.5 | N4: =ABS(H$2-$F4)/3 -> 0 | O4: =ABS(I$2-$F4)/1 -> 0.5 | Q4: 0.5 | R4: =($J4/$J$6) * (G$6/$J$6) -> 0.015089163 | S4: =($J4/$J$6) * (H$6/$J$6) -> 0.0034293553 | T4: =($J4/$J$6) * (I$6/$J$6) -> 0.018518519 | V4: Expected Weighted Disagreement (D_exp) | W4: =SUMPRODUCT(R3:T5, M3:O5) -> 0.48628258 | X4: Sum of (expected cell proportions × weights) under chance agreement.
A5: =CombinedHumanGrading!A5 -> State | B5: =CombinedHumanGrading!B5 -> Closed | C5: =CombinedHumanGrading!C5 -> 0 | D5: ='Gemini 3.1 Pro Preview Grading'!C5 -> 0 | F5: 1 | G5: =COUNTIFS($C$2:$C$48, $F5, $D$2:$D$48, G$2)+MAX(C49-D49,0)+MAX(C50-D50,0)+MAX(C51-D51,0)+MAX(C52-D52,0)+MAX(C53-D53,0)+MAX(C54-D54,0)+MAX(C55-D55,0) -> 3 | H5: =COUNTIFS($C$2:$C$48, $F5, $D$2:$D$48, H$2) -> 4 | I5: =COUNTIFS($C$2:$C$48, $F5, $D$2:$D$48, I$2)+ SUM(MIN(C49,D49), MIN(C50,D50), MIN(C51,D51), MIN(C52,D52), MIN(C53,D53), MIN(C54,D54), MIN(C55,D55)) -> 26 | J5: =SUM(G5:I5) -> 33 | L5: 1 | M5: =ABS(G$2-$F5)/1 -> 1 | N5: =ABS(H$2-$F5)/1 -> 0.5 | O5: =ABS(I$2-$F5)/1 -> 0 | Q5: 1 | R5: =($J5/$J$6) * (G$6/$J$6) -> 0.24897119 | S5: =($J5/$J$6) * (H$6/$J$6) -> 0.056584362 | T5: =($J5/$J$6) * (I$6/$J$6) -> 0.30555556 | V5: Cohen's Kappa | W5: =1-W3/W4 -> 0.75246827 | X5: 1 - (D_obs / D_exp)
A6: =CombinedHumanGrading!A6 -> Transition | B6: =CombinedHumanGrading!B6 -> open (Closed ⇒ Open) | C6: =CombinedHumanGrading!C6 -> 0 | D6: ='Gemini 3.1 Pro Preview Grading'!C6 -> 0 | F6: Column Totals | G6: =SUM(G3:G5) -> 22 | H6: =SUM(H3:H5) -> 5 | I6: =SUM(I3:I5) -> 27 | J6: =SUM(G3:I5) -> 54
A7: =CombinedHumanGrading!A7 -> Transition | B7: =CombinedHumanGrading!B7 -> lock (Closed ⇒ Locked) | C7: =CombinedHumanGrading!C7 -> 0 | D7: ='Gemini 3.1 Pro Preview Grading'!C7 -> 0
A8: =CombinedHumanGrading!A8 -> State | B8: =CombinedHumanGrading!B8 -> Open | C8: =CombinedHumanGrading!C8 -> 1 | D8: ='Gemini 3.1 Pro Preview Grading'!C8 -> 0.5 | F8: Confusion Matrix (State)
A9: =CombinedHumanGrading!A9 -> Transition | B9: =CombinedHumanGrading!B9 -> close (Open ⇒ Closed) | C9: =CombinedHumanGrading!C9 -> 0 | D9: ='Gemini 3.1 Pro Preview Grading'!C9 -> 0.5 | F9: State | G9: 0 | H9: 0.5 | I9: 1 | J9: Row Totals | L9: Global | M9: 0 | N9: 0.5 | O9: 1 | Q9: Global | R9: 0 | S9: 0.5 | T9: 1 | V9: ="Metrics" & " " & F9 -> Metrics State | W9: Value | X9: Note
A10: =CombinedHumanGrading!A10 -> State | B10: =CombinedHumanGrading!B10 -> Locked | C10: =CombinedHumanGrading!C10 -> 0 | D10: ='Gemini 3.1 Pro Preview Grading'!C10 -> 0 | F10: 0 | G10: =COUNTIFS($A$2:$A$92,$F$9,$C$2:$C$92,$F10,$D$2:$D$92,G$9) -> 4 | H10: =COUNTIFS($A$2:$A$92,$F$9,$C$2:$C$92,$F10,$D$2:$D$92,H$9) -> 0 | I10: =COUNTIFS($A$2:$A$48,$F$9,$C$2:$C$48,$F10,$D$2:$D$48,I$9)+MAX(D49-C49,0) -> 0 | J10: =SUM(G10:I10) -> 4 | L10: 0 | M10: =ABS(G$2-$F10)/1 -> 0 | N10: =ABS(H$2-$F10)/1 -> 0.5 | O10: =ABS(I$2-$F10)/1 -> 1 | Q10: 0 | R10: =($J10/$J$13) * (G$13/$J$13) -> 0.094674556 | S10: =($J10/$J$13) * (H$13/$J$13) -> 0.023668639 | T10: =($J10/$J$13) * (I$13/$J$13) -> 0.18934911 | V10: Observed Weighted Disagreement (D_obs) | W10: =SUMPRODUCT(G10:I12, M10:O12) /$J$13 -> 0.038461538 | X10: Sum of (confusion-matrix counts × weights) divided by total items.
A11: =CombinedHumanGrading!A11 -> Transition | B11: =CombinedHumanGrading!B11 -> unlock (Locked ⇒ Closed) | C11: =CombinedHumanGrading!C11 -> 0 | D11: ='Gemini 3.1 Pro Preview Grading'!C11 -> 0 | F11: 0.5 | G11: =COUNTIFS($A$2:$A$92,$F$9,$C$2:$C$92,$F11,$D$2:$D$92,G$9) -> 0 | H11: =COUNTIFS($A$2:$A$92,$F$9,$C$2:$C$92,$F11,$D$2:$D$92,H$9) -> 0 | I11: =COUNTIFS($A$2:$A$92,$F$9,$C$2:$C$92,$F11,$D$2:$D$92,I$9) -> 0 | J11: =SUM(G11:I11) -> 0 | L11: 0.5 | M11: =ABS(G$2-$F11)/1 -> 0.5 | N11: =ABS(H$2-$F11)/3 -> 0 | O11: =ABS(I$2-$F11)/1 -> 0.5 | Q11: 0.5 | R11: =($J11/$J$13) * (G$13/$J$13) -> 0 | S11: =($J11/$J$13) * (H$13/$J$13) -> 0 | T11: =($J11/$J$13) * (I$13/$J$13) -> 0 | V11: Expected Weighted Disagreement (D_exp) | W11: =SUMPRODUCT(R10:T12, M10:O12) -> 0.4408284 | X11: Sum of (expected cell proportions × weights) under chance agreement.
A12: =CombinedHumanGrading!A12 -> Region | B12: =CombinedHumanGrading!B12 -> Washer | C12: =CombinedHumanGrading!C12 -> 1 | D12: ='Gemini 3.1 Pro Preview Grading'!C12 -> 0 | F12: 1 | G12: =COUNTIFS($A$2:$A$48,$F$9,$C$2:$C$48,$F12,$D$2:$D$48,G$9)+MAX(C49-D49,0) -> 0 | H12: =COUNTIFS($A$2:$A$92,$F$9,$C$2:$C$92,$F12,$D$2:$D$92,H$9) -> 1 | I12: =COUNTIFS($A$2:$A$48,$F$9,$C$2:$C$48,$F12,$D$2:$D$48,I$9)+MIN(C49-D49) -> 8 | J12: =SUM(G12:I12) -> 9 | L12: 1 | M12: =ABS(G$2-$F12)/1 -> 1 | N12: =ABS(H$2-$F12)/1 -> 0.5 | O12: =ABS(I$2-$F12)/1 -> 0 | Q12: 1 | R12: =($J12/$J$13) * (G$13/$J$13) -> 0.21301775 | S12: =($J12/$J$13) * (H$13/$J$13) -> 0.053254438 | T12: =($J12/$J$13) * (I$13/$J$13) -> 0.4260355 | V12: Cohen's Kappa | W12: =1-W10/W11 -> 0.91275168 | X12: 1 - (D_obs / D_exp)
A13: =CombinedHumanGrading!A13 -> State | B13: =CombinedHumanGrading!B13 -> initial state | C13: =CombinedHumanGrading!C13 -> 1 | D13: ='Gemini 3.1 Pro Preview Grading'!C13 -> 1 | F13: Column Totals | G13: =SUM(G10:G12) -> 4 | H13: =SUM(H10:H12) -> 1 | I13: =SUM(I10:I12) -> 8 | J13: =SUM(G10:I12) -> 13
A14: =CombinedHumanGrading!A14 -> Transition | B14: =CombinedHumanGrading!B14 -> r =1; dT=20; (initial state ⇒ Idle) | C14: =CombinedHumanGrading!C14 -> 0.5 | D14: ='Gemini 3.1 Pro Preview Grading'!C14 -> 0
A15: =CombinedHumanGrading!A15 -> State | B15: =CombinedHumanGrading!B15 -> Idle | C15: =CombinedHumanGrading!C15 -> 1 | D15: ='Gemini 3.1 Pro Preview Grading'!C15 -> 1 | F15: Confusion Matrix (Transition)
A16: =CombinedHumanGrading!A16 -> Transition | B16: =CombinedHumanGrading!B16 -> selectProgram(n) (Idle ⇒ Idle) | C16: =CombinedHumanGrading!C16 -> 0 | D16: ='Gemini 3.1 Pro Preview Grading'!C16 -> 0 | F16: Transition | G16: 0 | H16: 0.5 | I16: 1 | J16: Row Totals | L16: Global | M16: 0 | N16: 0.5 | O16: 1 | Q16: Global | R16: 0 | S16: 0.5 | T16: 1 | V16: ="Metrics" & " " & F16 -> Metrics Transition | W16: Value | X16: Note
A17: =CombinedHumanGrading!A17 -> Guard | B17: =CombinedHumanGrading!B17 -> [n ≥ 1] | C17: =CombinedHumanGrading!C17 -> 0 | D17: ='Gemini 3.1 Pro Preview Grading'!C17 -> 0 | F17: 0 | G17: =COUNTIFS($A$2:$A$92,$F$16,$C$2:$C$92,$F17,$D$2:$D$92,G$16) -> 5 | H17: =COUNTIFS($A$2:$A$92,$F$16,$C$2:$C$92,$F17,$D$2:$D$92,H$16) -> 1 | I17: =COUNTIFS($A$2:$A$48,$F$16,$C$2:$C$48,$F17,$D$2:$D$48,I$16) + MAX(D50-C50,0) -> 0 | J17: =SUM(G17:I17) -> 6 | L17: 0 | M17: =ABS(G$2-$F17)/1 -> 0 | N17: =ABS(H$2-$F17)/1 -> 0.5 | O17: =ABS(I$2-$F17)/1 -> 1 | Q17: 0 | R17: =($J17/$J$20) * (G$20/$J$20) -> 0.09 | S17: =($J17/$J$20) * (H$20/$J$20) -> 0.045 | T17: =($J17/$J$20) * (I$20/$J$20) -> 0.165 | V17: Observed Weighted Disagreement (D_obs) | W17: =SUMPRODUCT(G17:I19, M17:O19) /$J$20 -> 0.1 | X17: Sum of (confusion-matrix counts × weights) divided by total items.
A18: =CombinedHumanGrading!A18 -> Action | B18: =CombinedHumanGrading!B18 -> r = n; | C18: =CombinedHumanGrading!C18 -> 0 | D18: ='Gemini 3.1 Pro Preview Grading'!C18 -> 0 | F18: 0.5 | G18: =COUNTIFS($A$2:$A$92,$F$16,$C$2:$C$92,$F18,$D$2:$D$92,G$16) -> 1 | H18: =COUNTIFS($A$2:$A$92,$F$16,$C$2:$C$92,$F18,$D$2:$D$92,H$16) -> 0 | I18: =COUNTIFS($A$2:$A$92,$F$16,$C$2:$C$92,$F18,$D$2:$D$92,I$16) -> 0 | J18: =SUM(G18:I18) -> 1 | L18: 0.5 | M18: =ABS(G$2-$F18)/1 -> 0.5 | N18: =ABS(H$2-$F18)/3 -> 0 | O18: =ABS(I$2-$F18)/1 -> 0.5 | Q18: 0.5 | R18: =($J18/$J$20) * (G$20/$J$20) -> 0.015 | S18: =($J18/$J$20) * (H$20/$J$20) -> 0.0075 | T18: =($J18/$J$20) * (I$20/$J$20) -> 0.0275 | V18: Expected Weighted Disagreement (D_exp) | W18: =SUMPRODUCT(R17:T19, M17:O19) -> 0.4525 | X18: Sum of (expected cell proportions × weights) under chance agreement.
A19: =CombinedHumanGrading!A19 -> Transition | B19: =CombinedHumanGrading!B19 -> toggleDryingTime (Idle ⇒ Idle) | C19: =CombinedHumanGrading!C19 -> 1 | D19: ='Gemini 3.1 Pro Preview Grading'!C19 -> 1 | F19: 1 | G19: =COUNTIFS($A$2:$A$48,$F$16,$C$2:$C$48,$F19,$D$2:$D$48,G$16)+MAX(C50-D50,0) -> 0 | H19: =COUNTIFS($A$2:$A$92,$F$16,$C$2:$C$92,$F19,$D$2:$D$92,H$16) -> 2 | I19: =COUNTIFS($A$2:$A$48,$F$16,$C$2:$C$48,$F19,$D$2:$D$48,I$16) + MIN(C50,D50) -> 11 | J19: =SUM(G19:I19) -> 13 | L19: 1 | M19: =ABS(G$2-$F19)/1 -> 1 | N19: =ABS(H$2-$F19)/1 -> 0.5 | O19: =ABS(I$2-$F19)/1 -> 0 | Q19: 1 | R19: =($J19/$J$20) * (G$20/$J$20) -> 0.195 | S19: =($J19/$J$20) * (H$20/$J$20) -> 0.0975 | T19: =($J19/$J$20) * (I$20/$J$20) -> 0.3575 | V19: Cohen's Kappa | W19: =1-W17/W18 -> 0.77900552 | X19: 1 - (D_obs / D_exp)
A20: =CombinedHumanGrading!A20 -> Action | B20: =CombinedHumanGrading!B20 -> if dT = 20 then dT = 40 else dT = 20; | C20: =CombinedHumanGrading!C20 -> 1 | D20: ='Gemini 3.1 Pro Preview Grading'!C20 -> 1 | F20: Column Totals | G20: =SUM(G17:G19) -> 6 | H20: =SUM(H17:H19) -> 3 | I20: =SUM(I17:I19) -> 11 | J20: =SUM(G17:I19) -> 20
A21: =CombinedHumanGrading!A21 -> Transition | B21: =CombinedHumanGrading!B21 -> start (Idle ⇒ Cleaning) | C21: =CombinedHumanGrading!C21 -> 1 | D21: ='Gemini 3.1 Pro Preview Grading'!C21 -> 1
A22: =CombinedHumanGrading!A22 -> Guard | B22: =CombinedHumanGrading!B22 -> [door.isClosed()] | C22: =CombinedHumanGrading!C22 -> 1 | D22: ='Gemini 3.1 Pro Preview Grading'!C22 -> 0 | F22: Confusion Matrix (Composite State)
A23: =CombinedHumanGrading!A23 -> Action | B23: =CombinedHumanGrading!B23 -> door.lock(); c = 1; | C23: =CombinedHumanGrading!C23 -> 1 | D23: ='Gemini 3.1 Pro Preview Grading'!C23 -> 0.5 | F23: Composite State | G23: 0 | H23: 0.5 | I23: 1 | J23: Row Totals | L23: Global | M23: 0 | N23: 0.5 | O23: 1 | Q23: Global | R23: 0 | S23: 0.5 | T23: 1 | V23: ="Metrics" & " " & F23 -> Metrics Composite State | W23: Value | X23: Note
A24: =CombinedHumanGrading!A24 -> Composite State | B24: =CombinedHumanGrading!B24 -> Cleaning | C24: =CombinedHumanGrading!C24 -> 1 | D24: ='Gemini 3.1 Pro Preview Grading'!C24 -> 1 | F24: 0 | G24: =COUNTIFS($A$2:$A$92,$F$23,$C$2:$C$92,$F24,$D$2:$D$92,G$23) -> 1 | H24: =COUNTIFS($A$2:$A$92,$F$23,$C$2:$C$92,$F24,$D$2:$D$92,H$23) -> 0 | I24: =COUNTIFS($A$2:$A$48,$F$23,$C$2:$C$48,$F24,$D$2:$D$48,I$23) + MAX(D53-C53,0) -> 0 | J24: =SUM(G24:I24) -> 1 | L24: 0 | M24: =ABS(G$2-$F24)/1 -> 0 | N24: =ABS(H$2-$F24)/1 -> 0.5 | O24: =ABS(I$2-$F24)/1 -> 1 | Q24: 0 | R24: =($J24/$J$27) * (G$27/$J$27) -> 0.22222222 | S24: =($J24/$J$27) * (H$27/$J$27) -> 0 | T24: =($J24/$J$27) * (I$27/$J$27) -> 0.11111111 | V24: Observed Weighted Disagreement (D_obs) | W24: =SUMPRODUCT(G24:I26, M24:O26) /$J$27 -> 0.33333333 | X24: Sum of (confusion-matrix counts × weights) divided by total items.
A25: =CombinedHumanGrading!A25 -> State | B25: =CombinedHumanGrading!B25 -> initial state (⇒ Intake) | C25: =CombinedHumanGrading!C25 -> 1 | D25: ='Gemini 3.1 Pro Preview Grading'!C25 -> 1 | F25: 0.5 | G25: =COUNTIFS($A$2:$A$92,$F$23,$C$2:$C$92,$F25,$D$2:$D$92,G$23) -> 0 | H25: =COUNTIFS($A$2:$A$92,$F$23,$C$2:$C$92,$F25,$D$2:$D$92,H$23) -> 0 | I25: =COUNTIFS($A$2:$A$92,$F$23,$C$2:$C$92,$F25,$D$2:$D$92,I$23) -> 0 | J25: =SUM(G25:I25) -> 0 | L25: 0.5 | M25: =ABS(G$2-$F25)/1 -> 0.5 | N25: =ABS(H$2-$F25)/3 -> 0 | O25: =ABS(I$2-$F25)/1 -> 0.5 | Q25: 0.5 | R25: =($J25/$J$27) * (G$27/$J$27) -> 0 | S25: =($J25/$J$27) * (H$27/$J$27) -> 0 | T25: =($J25/$J$27) * (I$27/$J$27) -> 0 | V25: Expected Weighted Disagreement (D_exp) | W25: =SUMPRODUCT(R24:T26, M24:O26) -> 0.55555556 | X25: Sum of (expected cell proportions × weights) under chance agreement.
A26: =CombinedHumanGrading!A26 -> State | B26: =CombinedHumanGrading!B26 -> Intake | C26: =CombinedHumanGrading!C26 -> 1 | D26: ='Gemini 3.1 Pro Preview Grading'!C26 -> 1 | F26: 1 | G26: =COUNTIFS($A$2:$A$48,$F$23,$C$2:$C$48,$F26,$D$2:$D$48,G$23) + MAX(C53-D53,0) -> 1 | H26: =COUNTIFS($A$2:$A$92,$F$23,$C$2:$C$92,$F26,$D$2:$D$92,H$23) -> 0 | I26: =COUNTIFS($A$2:$A$48,$F$23,$C$2:$C$48,$F26,$D$2:$D$48,I$23) + MIN(C53,D53) -> 1 | J26: =SUM(G26:I26) -> 2 | L26: 1 | M26: =ABS(G$2-$F26)/1 -> 1 | N26: =ABS(H$2-$F26)/1 -> 0.5 | O26: =ABS(I$2-$F26)/1 -> 0 | Q26: 1 | R26: =($J26/$J$27) * (G$27/$J$27) -> 0.44444444 | S26: =($J26/$J$27) * (H$27/$J$27) -> 0 | T26: =($J26/$J$27) * (I$27/$J$27) -> 0.22222222 | V26: Cohen's Kappa | W26: =1-W24/W25 -> 0.4 | X26: 1 - (D_obs / D_exp)
A27: =CombinedHumanGrading!A27 -> Transition | B27: =CombinedHumanGrading!B27 -> Intake ⇒ Washing | C27: =CombinedHumanGrading!C27 -> 1 | D27: ='Gemini 3.1 Pro Preview Grading'!C27 -> 1 | F27: Column Totals | G27: =SUM(G24:G26) -> 2 | H27: =SUM(H24:H26) -> 0 | I27: =SUM(I24:I26) -> 1 | J27: =SUM(G24:I26) -> 3
A28: =CombinedHumanGrading!A28 -> State | B28: =CombinedHumanGrading!B28 -> Washing | C28: =CombinedHumanGrading!C28 -> 1 | D28: ='Gemini 3.1 Pro Preview Grading'!C28 -> 1
A29: =CombinedHumanGrading!A29 -> Transition | B29: =CombinedHumanGrading!B29 -> after 10 min (Washing ⇒ Drain) | C29: =CombinedHumanGrading!C29 -> 1 | D29: ='Gemini 3.1 Pro Preview Grading'!C29 -> 1 | F29: Confusion Matrix (Guard)
A30: =CombinedHumanGrading!A30 -> State | B30: =CombinedHumanGrading!B30 -> Drain | C30: =CombinedHumanGrading!C30 -> 1 | D30: ='Gemini 3.1 Pro Preview Grading'!C30 -> 1 | F30: Guard | G30: 0 | H30: 0.5 | I30: 1 | J30: Row Totals | L30: Global | M30: 0 | N30: 0.5 | O30: 1 | Q30: Global | R30: 0 | S30: 0.5 | T30: 1 | V30: ="Metrics" & " " & F30 -> Metrics Guard | W30: Value | X30: Note
A31: =CombinedHumanGrading!A31 -> Guard | B31: =CombinedHumanGrading!B31 -> [c < r] | C31: =CombinedHumanGrading!C31 -> 1 | D31: ='Gemini 3.1 Pro Preview Grading'!C31 -> 1 | F31: 0 | G31: =COUNTIFS($A$2:$A$92,$F$30,$C$2:$C$92,$F31,$D$2:$D$92,G$30) -> 2 | H31: =COUNTIFS($A$2:$A$92,$F$30,$C$2:$C$92,$F31,$D$2:$D$92,H$30) -> 0 | I31: =COUNTIFS($A$2:$A$48,$F$30,$C$2:$C$48,$F31,$D$2:$D$48,I$30) + MAX(D51-C51,0) -> 0 | J31: =SUM(G31:I31) -> 2 | L31: 0 | M31: =ABS(G$2-$F31)/1 -> 0 | N31: =ABS(H$2-$F31)/1 -> 0.5 | O31: =ABS(I$2-$F31)/1 -> 1 | Q31: 0 | R31: =($J31/$J$34) * (G$34/$J$34) -> 0.24 | S31: =($J31/$J$34) * (H$34/$J$34) -> 0 | T31: =($J31/$J$34) * (I$34/$J$34) -> 0.16 | V31: Observed Weighted Disagreement (D_obs) | W31: =SUMPRODUCT(G31:I33, M31:O33) /$J$34 -> 0.2 | X31: Sum of (confusion-matrix counts × weights) divided by total items.
A32: =CombinedHumanGrading!A32 -> Transition | B32: =CombinedHumanGrading!B32 -> Drain ⇒ Intake | C32: =CombinedHumanGrading!C32 -> 1 | D32: ='Gemini 3.1 Pro Preview Grading'!C32 -> 1 | F32: 0.5 | G32: =COUNTIFS($A$2:$A$92,$F$30,$C$2:$C$92,$F32,$D$2:$D$92,G$30) -> 0 | H32: =COUNTIFS($A$2:$A$92,$F$30,$C$2:$C$92,$F32,$D$2:$D$92,H$30) -> 0 | I32: =COUNTIFS($A$2:$A$92,$F$30,$C$2:$C$92,$F32,$D$2:$D$92,I$30) -> 0 | J32: =SUM(G32:I32) -> 0 | L32: 0.5 | M32: =ABS(G$2-$F32)/1 -> 0.5 | N32: =ABS(H$2-$F32)/3 -> 0 | O32: =ABS(I$2-$F32)/1 -> 0.5 | Q32: 0.5 | R32: =($J32/$J$34) * (G$34/$J$34) -> 0 | S32: =($J32/$J$34) * (H$34/$J$34) -> 0 | T32: =($J32/$J$34) * (I$34/$J$34) -> 0 | V32: Expected Weighted Disagreement (D_exp) | W32: =SUMPRODUCT(R31:T33, M31:O33) -> 0.52 | X32: Sum of (expected cell proportions × weights) under chance agreement.
A33: =CombinedHumanGrading!A33 -> Action | B33: =CombinedHumanGrading!B33 -> c++ | C33: =CombinedHumanGrading!C33 -> 0.5 | D33: ='Gemini 3.1 Pro Preview Grading'!C33 -> 1 | F33: 1 | G33: =COUNTIFS($A$2:$A$48,$F$30,$C$2:$C$48,$F33,$D$2:$D$48,G$30) + MAX(C51-D51,0) -> 1 | H33: =COUNTIFS($A$2:$A$92,$F$30,$C$2:$C$92,$F33,$D$2:$D$92,H$30) -> 0 | I33: =COUNTIFS($A$2:$A$48,$F$30,$C$2:$C$48,$F33,$D$2:$D$48,I$30) + MIN(C51,D51) -> 2 | J33: =SUM(G33:I33) -> 3 | L33: 1 | M33: =ABS(G$2-$F33)/1 -> 1 | N33: =ABS(H$2-$F33)/1 -> 0.5 | O33: =ABS(I$2-$F33)/1 -> 0 | Q33: 1 | R33: =($J33/$J$34) * (G$34/$J$34) -> 0.36 | S33: =($J33/$J$34) * (H$34/$J$34) -> 0 | T33: =($J33/$J$34) * (I$34/$J$34) -> 0.24 | V33: Cohen's Kappa | W33: =1-W31/W32 -> 0.61538462 | X33: 1 - (D_obs / D_exp)
A34: =CombinedHumanGrading!A34 -> Transition | B34: =CombinedHumanGrading!B34 -> (Drain ⇒ end state) | C34: =CombinedHumanGrading!C34 -> 1 | D34: ='Gemini 3.1 Pro Preview Grading'!C34 -> 1 | F34: Column Totals | G34: =SUM(G31:G33) -> 3 | H34: =SUM(H31:H33) -> 0 | I34: =SUM(I31:I33) -> 2 | J34: =SUM(G31:I33) -> 5
A35: =CombinedHumanGrading!A35 -> Guard | B35: =CombinedHumanGrading!B35 -> [c ≥ r] | C35: =CombinedHumanGrading!C35 -> 1 | D35: ='Gemini 3.1 Pro Preview Grading'!C35 -> 1
A36: =CombinedHumanGrading!A36 -> History State | B36: =CombinedHumanGrading!B36 -> History State for Cleaning | C36: =CombinedHumanGrading!C36 -> 0 | D36: ='Gemini 3.1 Pro Preview Grading'!C36 -> 0 | F36: Confusion Matrix (Action)
A37: =CombinedHumanGrading!A37 -> Transition | B37: =CombinedHumanGrading!B37 -> toggleDryingTime (Cleaning ⇒ History State) | C37: =CombinedHumanGrading!C37 -> 1 | D37: ='Gemini 3.1 Pro Preview Grading'!C37 -> 0.5 | F37: Action | G37: 0 | H37: 0.5 | I37: 1 | J37: Row Totals | L37: Global | M37: 0 | N37: 0.5 | O37: 1 | Q37: Global | R37: 0 | S37: 0.5 | T37: 1 | V37: ="Metrics" & " " & F37 -> Metrics Action | W37: Value | X37: Note
A38: =CombinedHumanGrading!A38 -> Action | B38: =CombinedHumanGrading!B38 -> if dT = 20 then dT = 40 else dT = 20; | C38: =CombinedHumanGrading!C38 -> 1 | D38: ='Gemini 3.1 Pro Preview Grading'!C38 -> 1 | F38: 0 | G38: =COUNTIFS($A$2:$A$92,$F$37,$C$2:$C$92,$F38,$D$2:$D$92,G$37) -> 2 | H38: =COUNTIFS($A$2:$A$92,$F$37,$C$2:$C$92,$F38,$D$2:$D$92,H$37) -> 0 | I38: =COUNTIFS($A$2:$A$48,$F$37,$C$2:$C$48,$F38,$D$2:$D$48,I$37)+MAX(D52-C52,0) -> 0 | J38: =SUM(G38:I38) -> 2 | L38: 0 | M38: =ABS(G$2-$F38)/1 -> 0 | N38: =ABS(H$2-$F38)/1 -> 0.5 | O38: =ABS(I$2-$F38)/1 -> 1 | Q38: 0 | R38: =($J38/$J$41) * (G$41/$J$41) -> 0.0625 | S38: =($J38/$J$41) * (H$41/$J$41) -> 0.03125 | T38: =($J38/$J$41) * (I$41/$J$41) -> 0.15625 | V38: Observed Weighted Disagreement (D_obs) | W38: =SUMPRODUCT(G38:I40, M38:O40) /$J$41 -> 0.125 | X38: Sum of (confusion-matrix counts × weights) divided by total items.
A39: =CombinedHumanGrading!A39 -> Transition | B39: =CombinedHumanGrading!B39 -> Cleaning ⇒ Drying | C39: =CombinedHumanGrading!C39 -> 1 | D39: ='Gemini 3.1 Pro Preview Grading'!C39 -> 1 | F39: 0.5 | G39: =COUNTIFS($A$2:$A$92,$F$37,$C$2:$C$92,$F39,$D$2:$D$92,G$37) -> 0 | H39: =COUNTIFS($A$2:$A$92,$F$37,$C$2:$C$92,$F39,$D$2:$D$92,H$37) -> 0 | I39: =COUNTIFS($A$2:$A$92,$F$37,$C$2:$C$92,$F39,$D$2:$D$92,I$37) -> 1 | J39: =SUM(G39:I39) -> 1 | L39: 0.5 | M39: =ABS(G$2-$F39)/1 -> 0.5 | N39: =ABS(H$2-$F39)/3 -> 0 | O39: =ABS(I$2-$F39)/1 -> 0.5 | Q39: 0.5 | R39: =($J39/$J$41) * (G$41/$J$41) -> 0.03125 | S39: =($J39/$J$41) * (H$41/$J$41) -> 0.015625 | T39: =($J39/$J$41) * (I$41/$J$41) -> 0.078125 | V39: Expected Weighted Disagreement (D_exp) | W39: =SUMPRODUCT(R38:T40, M38:O40) -> 0.421875 | X39: Sum of (expected cell proportions × weights) under chance agreement.
A40: =CombinedHumanGrading!A40 -> Action | B40: =CombinedHumanGrading!B40 -> door.unlock(); | C40: =CombinedHumanGrading!C40 -> 1 | D40: ='Gemini 3.1 Pro Preview Grading'!C40 -> 1 | F40: 1 | G40: =COUNTIFS($A$2:$A$48,$F$37,$C$2:$C$48,$F40,$D$2:$D$48,G$37)+MAX(C52-D52,0) -> 0 | H40: =COUNTIFS($A$2:$A$92,$F$37,$C$2:$C$92,$F40,$D$2:$D$92,H$37) -> 1 | I40: =COUNTIFS($A$2:$A$48,$F$37,$C$2:$C$48,$F40,$D$2:$D$48,I$37) + MIN(C52,D52) -> 4 | J40: =SUM(G40:I40) -> 5 | L40: 1 | M40: =ABS(G$2-$F40)/1 -> 1 | N40: =ABS(H$2-$F40)/1 -> 0.5 | O40: =ABS(I$2-$F40)/1 -> 0 | Q40: 1 | R40: =($J40/$J$41) * (G$41/$J$41) -> 0.15625 | S40: =($J40/$J$41) * (H$41/$J$41) -> 0.078125 | T40: =($J40/$J$41) * (I$41/$J$41) -> 0.390625 | V40: Cohen's Kappa | W40: =1-W38/W39 -> 0.7037037 | X40: 1 - (D_obs / D_exp)
...
