Workbook

Sheet SSC7
A1: Type | B1: Element
A2: State | B2: Initial state (→ Active)
A3: Composite State | B3: Active
A4: State | B4: Initial state (Active → Ready)
A5: State | B5: Ready
A6: Transition | B6: scannedNr (Ready ⇒ Ready)
A7: Guard | B7: [!existsNr()]
A8: Action | B8: error()
A9: Transition | B9: productCodeEntered (Ready ⇒ Ready)
A10: Guard | B10: [!existsCode()]
A11: Action | B11: error()
A12: Transition | B12: productCodeEntered (Ready ⇒ WeighItem)
... A74: History State | B74: additional elements

Sheet GPT-5 Generation
A1: Type | B1: Element | C1: GPT-5 Generation | D1: Notes
A2: State | B2: Initial state (→ Active) | C2: 1 | D2: Represented as [*] --> Shopping where Shopping is the main composite state equivalent to Active
A3: Composite State | B3: Active | C3: 1 | D3: Represented by Shopping composite state which contains all main operational substates
A4: State | B4: Initial state (Active → Ready) | C4: 1 | D4: Represented as [*] --> ReadyForNextItem within Shopping composite state
A5: State | B5: Ready | C5: 1 | D5: Represented as ReadyForNextItem state
A6: Transition | B6: scannedNr (Ready ⇒ Ready) | C6: 1 | D6: Represented as barcodeScanned(code) [!barcodeExists(code)] / showError() self-transition on ReadyForNextItem
A7: Guard | B7: [!existsNr()] | C7: 1 | D7: Represented as [!barcodeExists(code)] guard condition
A8: Action | B8: error() | C8: 1 | D8: Represented as showError() action
A9: Transition | B9: productCodeEntered (Ready ⇒ Ready) | C9: 1 | D9: Represented as productCodeEntered(code) [!productCodeExists(code)] / showError() self-transition
A10: Guard | B10: [!existsCode()] | C10: 1 | D10: Represented as [!productCodeExists(code)] guard condition
A11: Action | B11: error() | C11: 1 | D11: Represented as showError() action
A12: Transition | B12: productCodeEntered (Ready ⇒ WeighItem) | C12: 1 | D12: Represented as productCodeEntered(code) [productCodeExists(code)] / requestItemWeight(code) to WeighingProductCodeItem
A13: Guard | B13: [existsCode()] | C13: 1 | D13: Represented as [productCodeExists(code)] guard condition
... A74: History State | B74: additional elements | C74: 0 | D74: No additional incorrect history states present

Sheet Claude Sonnet 4.5 Gen
A1: Type | B1: Element | C1: Claude Sonnet 4.5 Generation | D1: Notes
A2: State | B2: Initial state (→ Active) | C2: 1 | D2: Correctly represented as [*] --> Active
A3: Composite State | B3: Active | C3: 1 | D3: Correctly represented as a composite state containing substates
A4: State | B4: Initial state (Active → Ready) | C4: 1 | D4: Correctly represented as [*] --> ReadyForNextItem within Active
A5: State | B5: Ready | C5: 1 | D5: Represented as ReadyForNextItem which captures the same semantic meaning
A6: Transition | B6: scannedNr (Ready ⇒ Ready) | C6: 1 | D6: Represented as scanBarcode(code) [!codeExists] / showError() transition from ReadyForNextItem to ReadyForNextItem
A7: Guard | B7: [!existsNr()] | C7: 1 | D7: Represented as [!codeExists] guard on the scanBarcode self-transition
A8: Action | B8: error() | C8: 1 | D8: Represented as showError() action which captures the same semantic intent
A9: Transition | B9: productCodeEntered (Ready ⇒ Ready) | C9: 1 | D9: Represented as productCodeEntered(code) [!codeExists] / showError() from EnteringProductCode to ReadyForNextItem
A10: Guard | B10: [!existsCode()] | C10: 1 | D10: Represented as [!codeExists] guard on the productCodeEntered transition
A11: Action | B11: error() | C11: 1 | D11: Represented as showError() action on the invalid product code transition
A12: Transition | B12: productCodeEntered (Ready ⇒ WeighItem) | C12: 1 | D12: Represented as productCodeEntered(code) [codeExists] from EnteringProductCode to WeighingItem
A13: Guard | B13: [existsCode()] | C13: 1 | D13: Represented as [codeExists] guard on the transition to WeighingItem
... A74: History State | B74: additional elements | C74: 0 | D74: Only one history state H as expected

Sheet Metrics
A1: Generated by GPT-5 | J1: Date
A2: Type | B2: Ground Truth Count | C2: True Positive | D2: False Positive | E2: False Negative | F2: Precision | G2: Recall | H2: F1 Score | J2: 46098
A3: Composite State | B3: =COUNTIF('SSC7'!$A$2:$A$67, A3) -> 1 | C3: =SUMIF('GPT-5 Generation'!$A$2:$A$67, $A3, 'GPT-5 Generation'!$C$2:$C$67) -> 1 | D3: =SUMIF('GPT-5 Generation'!$A$68:$A$74, $A3, 'GPT-5 Generation'!$C$68:$C$74) -> 0 | E3: =COUNTIFS('GPT-5 Generation'!$A$2:$A$67, $A3, 'GPT-5 Generation'!$C$2:$C$67,0) -> 0 | F3: =IFERROR(C3 / (C3 + D3), "Not Available") -> 1 | G3: =IFERROR(C3 / B3, "Not Available") -> 1 | H3: =IFERROR(2*((F3*G3)/(F3+G3)),"Not Available") -> 1
A4: State | B4: =COUNTIF('SSC7'!$A$2:$A$67, A4) -> 9 | C4: =SUMIF('GPT-5 Generation'!$A$2:$A$67, $A4, 'GPT-5 Generation'!$C$2:$C$67) -> 9 | D4: =SUMIF('GPT-5 Generation'!$A$68:$A$74, $A4, 'GPT-5 Generation'!$C$68:$C$74) -> 0 | E4: =COUNTIFS('GPT-5 Generation'!$A$2:$A$67, $A4, 'GPT-5 Generation'!$C$2:$C$67,0) -> 0 | F4: =IFERROR(C4 / (C4 + D4), "Not Available") -> 1 | G4: =IFERROR(C4 / B4, "Not Available") -> 1 | H4: =IFERROR(2*((F4*G4)/(F4+G4)),"Not Available") -> 1 | J4: Grading LLM
A5: Transition | B5: =COUNTIF('SSC7'!$A$2:$A$67, A5) -> 23 | C5: =SUMIF('GPT-5 Generation'!$A$2:$A$67, $A5, 'GPT-5 Generation'!$C$2:$C$67) -> 23 | D5: =SUMIF('GPT-5 Generation'!$A$68:$A$74, $A5, 'GPT-5 Generation'!$C$68:$C$74) -> 0 | E5: =COUNTIFS('GPT-5 Generation'!$A$2:$A$67, $A5, 'GPT-5 Generation'!$C$2:$C$67,0) -> 0 | F5: =IFERROR(C5 / (C5 + D5), "Not Available") -> 1 | G5: =IFERROR(C5 / B5, "Not Available") -> 1 | H5: =IFERROR(2*((F5*G6)/(F5+G6)),"Not Available") -> 1 | J5: Claude Sonnet 4.5
A6: Action | B6: =COUNTIF('SSC7'!$A$2:$A$67, A6) -> 21 | C6: =SUMIF('GPT-5 Generation'!$A$2:$A$67, $A6, 'GPT-5 Generation'!$C$2:$C$67) -> 21 | D6: =SUMIF('GPT-5 Generation'!$A$68:$A$74, $A6, 'GPT-5 Generation'!$C$68:$C$74) -> 0 | E6: =COUNTIFS('GPT-5 Generation'!$A$2:$A$67, $A6, 'GPT-5 Generation'!$C$2:$C$67,0) -> 0 | F6: =IFERROR(C6 / (C6 + D6), "Not Available") -> 1 | G6: =IFERROR(C6 / B6, "Not Available") -> 1 | H6: =IFERROR(2*((F6*#REF!)/(F6+#REF!)),"Not Available") -> Not Available
A7: Region | B7: =COUNTIF('SSC7'!$A$2:$A$67, A7) -> 0 | C7: =SUMIF('GPT-5 Generation'!$A$2:$A$67, $A7, 'GPT-5 Generation'!$C$2:$C$67) -> 0 | D7: =SUMIF('GPT-5 Generation'!$A$68:$A$74, $A7, 'GPT-5 Generation'!$C$68:$C$74) -> 0 | F7: =IFERROR(C7 / (C7 + D7), "Not Available") -> Not Available | G7: =IFERROR(C7 / B7, "Not Available") -> Not Available | H7: =IFERROR(2*((F7*G7)/(F7+G7)),"Not Available") -> Not Available | J7: Generation LLMs
A8: History State | B8: =COUNTIF('SSC7'!$A$2:$A$67, A8) -> 1 | C8: =SUMIF('GPT-5 Generation'!$A$2:$A$67, $A8, 'GPT-5 Generation'!$C$2:$C$67) -> 1 | D8: =SUMIF('GPT-5 Generation'!$A$68:$A$74, $A8, 'GPT-5 Generation'!$C$68:$C$74) -> 0 | E8: =COUNTIFS('GPT-5 Generation'!$A$2:$A$67, $A7, 'GPT-5 Generation'!$C$2:$C$67,0) -> 0 | F8: =IFERROR(C8 / (C8 + D8), "Not Available") -> 1 | G8: =IFERROR(C8 / B8, "Not Available") -> 1 | H8: =IFERROR(2*((F8*G9)/(F8+G9)),"Not Available") -> 1 | J8: GPT-5.5
A9: Guard | B9: =COUNTIF('SSC7'!$A$2:$A$67, A9) -> 11 | C9: =SUMIF('GPT-5 Generation'!$A$2:$A$67, $A9, 'GPT-5 Generation'!$C$2:$C$67) -> 11 | D9: =SUMIF('GPT-5 Generation'!$A$68:$A$74, $A9, 'GPT-5 Generation'!$C$68:$C$74) -> 0 | E9: =COUNTIFS('GPT-5 Generation'!$A$2:$A$67, $A9, 'GPT-5 Generation'!$C$2:$C$67,0) -> 0 | F9: =IFERROR(C9 / (C9 + D9), "Not Available") -> 1 | G9: =IFERROR(C9 / B9, "Not Available") -> 1 | H9: =IFERROR(2*((F9*#REF!)/(F9+#REF!)),"Not Available") -> Not Available | J9: Claude Sonnet 4.6
A10: Overall Score | B10: =SUM(B3:B9) -> 66 | C10: =SUM(C4:C9) -> 65 | D10: =SUM(D3:D9) -> 0 | E10: =SUM(E3:E9) -> 0 | F10: =IFERROR(C10 / (C10 + D10), "Not Available") -> 1 | G10: =IFERROR(C10 / B10, "Not Available") -> 0.98484848 | H10: =IFERROR(2*((F10*G10)/(F10+G10)),"Not Available") -> 0.99236641
A12: Generated by Claude Sonnet 4.5
A13: Type | B13: Ground Truth Count | C13: True Positive | D13: False Positive | E13: False Negative | F13: Precision | G13: Recall | H13: F1 Score
A14: Composite state | B14: =COUNTIF('SSC7'!$A$2:$A$67, A3) -> 1 | C14: =SUMIF('Claude Sonnet 4.5 Gen'!$A$2:$A$67, $A14, 'Claude Sonnet 4.5 Gen'!$C$2:$C$67) -> 1 | D14: =SUMIF('Claude Sonnet 4.5 Gen'!$A$68:$A$74, $A14, 'Claude Sonnet 4.5 Gen'!$C$68:$C$74) -> 0 | E14: =COUNTIFS('Claude Sonnet 4.5 Gen'!$A$2:$A$67, $A14, 'Claude Sonnet 4.5 Gen'!$C$2:$C$67,0) -> 0 | F14: =IFERROR(C14 / (C14 + D14), "Not Available") -> 1 | G14: =IFERROR(C14 / B14, "Not Available") -> 1 | H14: =IFERROR(2*((F14*G14)/(F14+G14)),"Not Available") -> 1
A15: State | B15: =COUNTIF('SSC7'!$A$2:$A$67, A4) -> 9 | C15: =SUMIF('Claude Sonnet 4.5 Gen'!$A$2:$A$67, $A15, 'Claude Sonnet 4.5 Gen'!$C$2:$C$67) -> 9 | D15: =SUMIF('Claude Sonnet 4.5 Gen'!$A$68:$A$74, $A15, 'Claude Sonnet 4.5 Gen'!$C$68:$C$74) -> 2 | E15: =COUNTIFS('Claude Sonnet 4.5 Gen'!$A$2:$A$67, $A15, 'Claude Sonnet 4.5 Gen'!$C$2:$C$67,0) -> 0 | F15: =IFERROR(C15 / (C15 + D15), "Not Available") -> 0.81818182 | G15: =IFERROR(C15 / B15, "Not Available") -> 1 | H15: =IFERROR(2*((F15*G15)/(F15+G15)),"Not Available") -> 0.9
A16: Transition | B16: =COUNTIF('SSC7'!$A$2:$A$67, A5) -> 23 | C16: =SUMIF('Claude Sonnet 4.5 Gen'!$A$2:$A$67, $A16, 'Claude Sonnet 4.5 Gen'!$C$2:$C$67) -> 22.5 | D16: =SUMIF('Claude Sonnet 4.5 Gen'!$A$68:$A$74, $A16, 'Claude Sonnet 4.5 Gen'!$C$68:$C$74) -> 1 | E16: =COUNTIFS('Claude Sonnet 4.5 Gen'!$A$2:$A$67, $A16, 'Claude Sonnet 4.5 Gen'!$C$2:$C$67,0) -> 0 | F16: =IFERROR(C16 / (C16 + D16), "Not Available") -> 0.95744681 | G16: =IFERROR(C16 / B16, "Not Available") -> 0.97826087 | H16: =IFERROR(2*((F16*G16)/(F16+G16)),"Not Available") -> 0.96774194
A17: Action | B17: =COUNTIF('SSC7'!$A$2:$A$67, A6) -> 21 | C17: =SUMIF('Claude Sonnet 4.5 Gen'!$A$2:$A$67, $A17, 'Claude Sonnet 4.5 Gen'!$C$2:$C$67) -> 14.5 | D17: =SUMIF('Claude Sonnet 4.5 Gen'!$A$68:$A$74, $A17, 'Claude Sonnet 4.5 Gen'!$C$68:$C$74) -> 1 | E17: =COUNTIFS('Claude Sonnet 4.5 Gen'!$A$2:$A$67, $A17, 'Claude Sonnet 4.5 Gen'!$C$2:$C$67,0) -> 6 | F17: =IFERROR(C17 / (C17 + D17), "Not Available") -> 0.93548387 | G17: =IFERROR(C17 / B17, "Not Available") -> 0.69047619 | H17: =IFERROR(2*((F17*G17)/(F17+G17)),"Not Available") -> 0.79452055
A18: Region | B18: =COUNTIF('SSC7'!$A$2:$A$67, A7) -> 0 | C18: =SUMIF('Claude Sonnet 4.5 Gen'!$A$2:$A$67, $A18, 'Claude Sonnet 4.5 Gen'!$C$2:$C$67) -> 0 | D18: =SUMIF('Claude Sonnet 4.5 Gen'!$A$68:$A$74, $A18, 'Claude Sonnet 4.5 Gen'!$C$68:$C$74) -> 0 | E18: =COUNTIFS('Claude Sonnet 4.5 Gen'!$A$2:$A$67, $A18, 'Claude Sonnet 4.5 Gen'!$C$2:$C$67,0) -> 0 | F18: =IFERROR(C18 / (C18 + D18), "Not Available") -> Not Available | G18: =IFERROR(C18 / B18, "Not Available") -> Not Available | H18: =IFERROR(2*((F18*G18)/(F18+G18)),"Not Available") -> Not Available
A19: History State | B19: =COUNTIF('SSC7'!$A$2:$A$67, A8) -> 1 | C19: =SUMIF('Claude Sonnet 4.5 Gen'!$A$2:$A$67, $A19, 'Claude Sonnet 4.5 Gen'!$C$2:$C$67) -> 0.5 | D19: =SUMIF('Claude Sonnet 4.5 Gen'!$A$68:$A$74, $A19, 'Claude Sonnet 4.5 Gen'!$C$68:$C$74) -> 0 | E19: =COUNTIFS('Claude Sonnet 4.5 Gen'!$A$2:$A$67, $A19, 'Claude Sonnet 4.5 Gen'!$C$2:$C$67,0) -> 0 | F19: =IFERROR(C19 / (C19 + D19), "Not Available") -> 1 | G19: =IFERROR(C19 / B19, "Not Available") -> 0.5 | H19: =IFERROR(2*((F19*G19)/(F19+G19)),"Not Available") -> 0.66666667
A20: Guard | B20: =COUNTIF('SSC7'!$A$2:$A$67, A9) -> 11 | C20: =SUMIF('Claude Sonnet 4.5 Gen'!$A$2:$A$67, $A20, 'Claude Sonnet 4.5 Gen'!$C$2:$C$67) -> 11 | D20: =SUMIF('Claude Sonnet 4.5 Gen'!$A$68:$A$74, $A20, 'Claude Sonnet 4.5 Gen'!$C$68:$C$74) -> 0 | E20: =COUNTIFS('Claude Sonnet 4.5 Gen'!$A$2:$A$67, $A20, 'Claude Sonnet 4.5 Gen'!$C$2:$C$67,0) -> 0 | F20: =IFERROR(C20 / (C20 + D20), "Not Available") -> 1 | G20: =IFERROR(C20 / B20, "Not Available") -> 1 | H20: =IFERROR(2*((F20*G20)/(F20+G20)),"Not Available") -> 1
A21: Overall Score | B21: =SUM(B14:B20) -> 66 | C21: =SUM(C14:C20) -> 58.5 | D21: =SUM(D14:D20) -> 4 | E21: =SUM(E14:E20) -> 6 | F21: =IFERROR(C21 / (C21 + D21), "Not Available") -> 0.936 | G21: =IFERROR(C21 / B21, "Not Available") -> 0.88636364 | H21: =IFERROR(2*((F21*G21)/(F21+G21)),"Not Available") -> 0.91050584

Sheet Inter-rater
A1: Type | B1: Element | C1: GPT-5 | D1: Claude Sonnet 4.5 | F1: Confusion Matrix | L1: Cohen's Kappa
A2: ='SSC7'!A2 -> State | B2: ='SSC7'!B2 -> Initial state (→ Active) | C2: ='GPT-5 Generation'!C2 -> 1 | D2: ='Claude Sonnet 4.5 Gen'!C2 -> 1 | F2: Global | G2: 0 | H2: 0.5 | I2: 1 | J2: Row Totals | L2: Metric | M2: Value | N2: Note
A3: ='SSC7'!A3 -> Composite State | B3: ='SSC7'!B3 -> Active | C3: ='GPT-5 Generation'!C3 -> 1 | D3: ='Claude Sonnet 4.5 Gen'!C3 -> 1 | F3: 0 | G3: =COUNTIFS($C$2:$C$111, $F3, $D$2:$D$111, G$2) -> 4 | H3: =COUNTIFS($C$2:$C$67, $F3, $D$2:$D$67, H$2) -> 0 | I3: =COUNTIFS($C$2:$C$67, $F3, $D$2:$D$67, I$2)+MAX(D68-C68,0)+MAX(D69-C69,0)+MAX(D70-C70,0)+MAX(D71-C71,0)+MAX(D72-C72,0)+MAX(D73-C73,0)+MAX(D74-C74,0) -> 4 | J3: =SUM(G3:I3) -> 8 | L3: Observed Agreement (Po) | M3: =(G3+H4+I5)/COUNTA($C$2:$C$121) -> 0.83561644 | N3: This sums the diagonal of your matrix divided by total rows.
A4: ='SSC7'!A4 -> State | B4: ='SSC7'!B4 -> Initial state (Active → Ready) | C4: ='GPT-5 Generation'!C4 -> 1 | D4: ='Claude Sonnet 4.5 Gen'!C4 -> 1 | F4: 0.5 | G4: =COUNTIFS($C$2:$C$67, $F4, $D$2:$D$67, G$2) -> 0 | H4: =COUNTIFS($C$2:$C$67, $F4, $D$2:$D$67, H$2) -> 0 | I4: =COUNTIFS($C$2:$C$67, $F4, $D$2:$D$67, I$2) -> 0 | J4: =SUM(G4:I4) -> 0 | L4: Expected Agreement (Pe) | M4: {=SUMPRODUCT(J3:J5/COUNTA($C$2:$C$121), TRANSPOSE(G6:I6)/COUNTA($C$2:$C$121))} -> 0.77050103 | N4: This computes the sum of row proportion times column proportion.
A5: ='SSC7'!A5 -> State | B5: ='SSC7'!B5 -> Ready | C5: ='GPT-5 Generation'!C5 -> 1 | D5: ='Claude Sonnet 4.5 Gen'!C5 -> 1 | F5: 1 | G5: =COUNTIFS($C$2:$C$67, $F5, $D$2:$D$67, G$2)+MAX(C68-D68,0)+MAX(C69-D69,0)+MAX(C70-D70,0)+MAX(C71-D71,0)+MAX(C72-D72,0)+MAX(C73-D73,0)+MAX(C74-D74,0) -> 6 | H5: =COUNTIFS($C$2:$C$67, $F5, $D$2:$D$67, H$2) -> 3 | I5: =COUNTIFS($C$2:$C$67, $F5, $D$2:$D$67, I$2)+ SUM(MIN(C68,D68), MIN(C69,D69), MIN(C70,D70), MIN(C71,D71), MIN(C72,D72), MIN(C73,D73), MIN(C74,D74)) -> 57 | J5: =SUM(G5:I5) -> 66 | L5: Cohen's Kappa | M5: =(M3-M4)/(1-M4) -> 0.28372854 | N5: (Po - Pe) / (1 - Pe)
A6: ='SSC7'!A6 -> Transition | B6: ='SSC7'!B6 -> scannedNr (Ready ⇒ Ready) | C6: ='GPT-5 Generation'!C6 -> 1 | D6: ='Claude Sonnet 4.5 Gen'!C6 -> 1 | F6: Column Totals | G6: =SUM(G3:G5) -> 10 | H6: =SUM(H3:H5) -> 3 | I6: =SUM(I3:I5) -> 61
A7: ='SSC7'!A7 -> Guard | B7: ='SSC7'!B7 -> [!existsNr()] | C7: ='GPT-5 Generation'!C7 -> 1 | D7: ='Claude Sonnet 4.5 Gen'!C7 -> 1
A8: ='SSC7'!A8 -> Action | B8: ='SSC7'!B8 -> error() | C8: ='GPT-5 Generation'!C8 -> 1 | D8: ='Claude Sonnet 4.5 Gen'!C8 -> 1 | F8: Confusion Matrix (State) | L8: Cohen's Kappa (State)
A9: ='SSC7'!A9 -> Transition | B9: ='SSC7'!B9 -> productCodeEntered (Ready ⇒ Ready) | C9: ='GPT-5 Generation'!C9 -> 1 | D9: ='Claude Sonnet 4.5 Gen'!C9 -> 1 | F9: State | G9: 0 | H9: 0.5 | I9: 1 | J9: Row Totals | L9: Metric | M9: Value | N9: Note
A10: ='SSC7'!A10 -> Guard | B10: ='SSC7'!B10 -> [!existsCode()] | C10: ='GPT-5 Generation'!C10 -> 1 | D10: ='Claude Sonnet 4.5 Gen'!C10 -> 1 | F10: 0 | G10: =COUNTIFS($A$2:$A$111,$F$9,$C$2:$C$111,$F10,$D$2:$D$111,G$9) -> 0 | H10: =COUNTIFS($A$2:$A$111,$F$9,$C$2:$C$111,$F10,$D$2:$D$111,H$9) -> 0 | I10: =COUNTIFS($A$2:$A$67,$F$9,$C$2:$C$67,$F10,$D$2:$D$67,I$9)+MAX(D68-C68,0) -> 2 | J10: =SUM(G10:I10) -> 2 | L10: Observed Agreement (Po) | M10: =(G10+H11+I12)/COUNTIF($A$2:$A$121,F9) -> 0.7 | N10: This sums the diagonal of your matrix divided by total rows.
A11: ='SSC7'!A11 -> Action | B11: ='SSC7'!B11 -> error() | C11: ='GPT-5 Generation'!C11 -> 1 | D11: ='Claude Sonnet 4.5 Gen'!C11 -> 1 | F11: 0.5 | G11: =COUNTIFS($A$2:$A$111,$F$9,$C$2:$C$111,$F11,$D$2:$D$111,G$9) -> 0 | H11: =COUNTIFS($A$2:$A$111,$F$9,$C$2:$C$111,$F11,$D$2:$D$111,H$9) -> 0 | I11: =COUNTIFS($A$2:$A$111,$F$9,$C$2:$C$111,$F11,$D$2:$D$111,I$9) -> 0 | J11: =SUM(G11:I11) -> 0 | L11: Expected Agreement (Pe) | M11: {=SUMPRODUCT(J10:J12/COUNTIF($A$2:$A$121,F9), TRANSPOSE(G13:I13)/COUNTIF($A$2:$A$121,F9))} -> 0.63 | N11: This computes the sum of row proportion times column proportion.
A12: ='SSC7'!A12 -> Transition | B12: ='SSC7'!B12 -> productCodeEntered (Ready ⇒ WeighItem) | C12: ='GPT-5 Generation'!C12 -> 1 | D12: ='Claude Sonnet 4.5 Gen'!C12 -> 1 | F12: 1 | G12: =COUNTIFS($A$2:$A$67,$F$9,$C$2:$C$67,$F12,$D$2:$D$67,G$9)+MAX(C68-D68,0) -> 0 | H12: =COUNTIFS($A$2:$A$111,$F$9,$C$2:$C$111,$F12,$D$2:$D$111,H$9) -> 0 | I12: =COUNTIFS($A$2:$A$67,$F$9,$C$2:$C$67,$F12,$D$2:$D$67,I$9)+MIN(C68-D68) -> 7 | J12: =SUM(G12:I12) -> 7 | L12: Cohen's Kappa | M12: =(M10-M11)/(1-M11) -> 0.18918919 | N12: (Po - Pe) / (1 - Pe)
A13: ='SSC7'!A13 -> Guard | B13: ='SSC7'!B13 -> [existsCode()] | C13: ='GPT-5 Generation'!C13 -> 1 | D13: ='Claude Sonnet 4.5 Gen'!C13 -> 1 | F13: Column Totals | G13: =SUM(G10:G12) -> 0 | H13: =SUM(H10:H12) -> 0 | I13: =SUM(I10:I12) -> 9
A14: ='SSC7'!A14 -> Transition | B14: ='SSC7'!B14 -> scannedNr (Ready ⇒ CheckWeight) | C14: ='GPT-5 Generation'!C14 -> 1 | D14: ='Claude Sonnet 4.5 Gen'!C14 -> 1
A15: ='SSC7'!A15 -> Guard | B15: ='SSC7'!B15 -> [existsNr()] | C15: ='GPT-5 Generation'!C15 -> 1 | D15: ='Claude Sonnet 4.5 Gen'!C15 -> 1 | F15: Confusion Matrix (Transition) | L15: Cohen's Kappa (Transition)
A16: ='SSC7'!A16 -> Action | B16: ='SSC7'!B16 -> addItem() | C16: ='GPT-5 Generation'!C16 -> 1 | D16: ='Claude Sonnet 4.5 Gen'!C16 -> 1 | F16: Transition | G16: 0 | H16: 0.5 | I16: 1 | J16: Row Totals | L16: Metric | M16: Value | N16: Note
A17: ='SSC7'!A17 -> Transition | B17: ='SSC7'!B17 -> cancelCheckout (Ready ⇒ Override) | C17: ='GPT-5 Generation'!C17 -> 1 | D17: ='Claude Sonnet 4.5 Gen'!C17 -> 1 | F17: 0 | G17: =COUNTIFS($A$2:$A$111,$F$16,$C$2:$C$111,$F17,$D$2:$D$111,G$16) -> 0 | H17: =COUNTIFS($A$2:$A$111,$F$16,$C$2:$C$111,$F17,$D$2:$D$111,H$16) -> 0 | I17: =COUNTIFS($A$2:$A$67,$F$16,$C$2:$C$67,$F17,$D$2:$D$67,I$16) + MAX(D69-C69,0) -> 1 | J17: =SUM(G17:I17) -> 1 | L17: Observed Agreement (Po) | M17: =(G17+H18+I19)/COUNTIF($A$2:$A$121,F16) -> 0.91666667 | N17: This sums the diagonal of your matrix divided by total rows.
A18: ='SSC7'!A18 -> Action | B18: ='SSC7'!B18 -> setTypeEverything() | C18: ='GPT-5 Generation'!C18 -> 1 | D18: ='Claude Sonnet 4.5 Gen'!C18 -> 0 | F18: 0.5 | G18: =COUNTIFS($A$2:$A$111,$F$16,$C$2:$C$111,$F18,$D$2:$D$111,G$16) -> 0 | H18: =COUNTIFS($A$2:$A$111,$F$16,$C$2:$C$111,$F18,$D$2:$D$111,H$16) -> 0 | I18: =COUNTIFS($A$2:$A$111,$F$16,$C$2:$C$111,$F18,$D$2:$D$111,I$16) -> 0 | J18: =SUM(G18:I18) -> 0 | L18: Expected Agreement (Pe) | M18: {=SUMPRODUCT(J17:J19/COUNTIF($A$2:$A$121,F16), TRANSPOSE(G20:I20)/COUNTIF($A$2:$A$121,F16))} -> 0.91840278 | N18: This computes the sum of row proportion times column proportion.
A19: ='SSC7'!A19 -> Transition | B19: ='SSC7'!B19 -> removeItem (Ready ⇒ Override) | C19: ='GPT-5 Generation'!C19 -> 1 | D19: ='Claude Sonnet 4.5 Gen'!C19 -> 1 | F19: 1 | G19: =COUNTIFS($A$2:$A$67,$F$16,$C$2:$C$67,$F19,$D$2:$D$67,G$16)+MAX(C69-D69,0) -> 0 | H19: =COUNTIFS($A$2:$A$111,$F$16,$C$2:$C$111,$F19,$D$2:$D$111,H$16) -> 1 | I19: =COUNTIFS($A$2:$A$67,$F$16,$C$2:$C$67,$F19,$D$2:$D$67,I$16) + MIN(C69,D69) -> 22 | J19: =SUM(G19:I19) -> 23 | L19: Cohen's Kappa | M19: =(M17-M18)/(1-M18) -> -0.021276596 | N19: (Po - Pe) / (1 - Pe)
A20: ='SSC7'!A20 -> Guard | B20: ='SSC7'!B20 -> [billHasItem()] | C20: ='GPT-5 Generation'!C20 -> 1 | D20: ='Claude Sonnet 4.5 Gen'!C20 -> 1 | F20: Column Totals | G20: =SUM(G17:G19) -> 0 | H20: =SUM(H17:H19) -> 1 | I20: =SUM(I17:I19) -> 23
A21: ='SSC7'!A21 -> Action | B21: ='SSC7'!B21 -> setTypeItem() | C21: ='GPT-5 Generation'!C21 -> 1 | D21: ='Claude Sonnet 4.5 Gen'!C21 -> 0
A22: ='SSC7'!A22 -> Transition | B22: ='SSC7'!B22 -> broughtOwnBag (Ready ⇒ WeighBag) | C22: ='GPT-5 Generation'!C22 -> 1 | D22: ='Claude Sonnet 4.5 Gen'!C22 -> 1 | F22: Confusion Matrix (Composite State) | L22: Cohen's Kappa (Composite State)
A23: ='SSC7'!A23 -> Transition | B23: ='SSC7'!B23 -> pay (Ready ⇒ PayRequested) | C23: ='GPT-5 Generation'!C23 -> 1 | D23: ='Claude Sonnet 4.5 Gen'!C23 -> 1 | F23: Composite State | G23: 0 | H23: 0.5 | I23: 1 | J23: Row Totals | L23: Metric | M23: Value | N23: Note
A24: ='SSC7'!A24 -> Guard | B24: ='SSC7'!B24 -> [billHasItem()] | C24: ='GPT-5 Generation'!C24 -> 1 | D24: ='Claude Sonnet 4.5 Gen'!C24 -> 1 | F24: 0 | G24: =COUNTIFS($A$2:$A$111,$F$23,$C$2:$C$111,$F24,$D$2:$D$111,G$23) -> 1 | H24: =COUNTIFS($A$2:$A$111,$F$23,$C$2:$C$111,$F24,$D$2:$D$111,H$23) -> 0 | I24: =COUNTIFS($A$2:$A$67,$F$23,$C$2:$C$67,$F24,$D$2:$D$67,I$23) + MAX(D72-C72,0) -> 0 | J24: =SUM(G24:I24) -> 1 | L24: Observed Agreement (Po) | M24: =(G24+H25+I26)/COUNTIF($A$2:$A$121,F23) -> 1 | N24: This sums the diagonal of your matrix divided by total rows.
A25: ='SSC7'!A25 -> Action | B25: ='SSC7'!B25 -> sendPaymentRequest() | C25: ='GPT-5 Generation'!C25 -> 1 | D25: ='Claude Sonnet 4.5 Gen'!C25 -> 1 | F25: 0.5 | G25: =COUNTIFS($A$2:$A$111,$F$23,$C$2:$C$111,$F25,$D$2:$D$111,G$23) -> 0 | H25: =COUNTIFS($A$2:$A$111,$F$23,$C$2:$C$111,$F25,$D$2:$D$111,H$23) -> 0 | I25: =COUNTIFS($A$2:$A$111,$F$23,$C$2:$C$111,$F25,$D$2:$D$111,I$23) -> 0 | J25: =SUM(G25:I25) -> 0 | L25: Expected Agreement (Pe) | M25: {=SUMPRODUCT(J24:J26/COUNTIF($A$2:$A$121,F23), TRANSPOSE(G27:I27)/COUNTIF($A$2:$A$121,F23))} -> 0.5 | N25: This computes the sum of row proportion times column proportion.
A26: ='SSC7'!A26 -> State | B26: ='SSC7'!B26 -> WeighItem | C26: ='GPT-5 Generation'!C26 -> 1 | D26: ='Claude Sonnet 4.5 Gen'!C26 -> 1 | F26: 1 | G26: =COUNTIFS($A$2:$A$67,$F$23,$C$2:$C$67,$F26,$D$2:$D$67,G$23) + MAX(C72-D72,0) -> 0 | H26: =COUNTIFS($A$2:$A$111,$F$23,$C$2:$C$111,$F26,$D$2:$D$111,H$23) -> 0 | I26: =COUNTIFS($A$2:$A$67,$F$23,$C$2:$C$67,$F26,$D$2:$D$67,I$23) + MIN(C72,D72) -> 1 | J26: =SUM(G26:I26) -> 1 | L26: Cohen's Kappa | M26: =(M24-M25)/(1-M25) -> 1 | N26: (Po - Pe) / (1 - Pe)
A27: ='SSC7'!A27 -> Transition | B27: ='SSC7'!B27 -> cancel (WeighItem ⇒ Ready) | C27: ='GPT-5 Generation'!C27 -> 1 | D27: ='Claude Sonnet 4.5 Gen'!C27 -> 1 | F27: Column Totals | G27: =SUM(G24:G26) -> 1 | H27: =SUM(H24:H26) -> 0 | I27: =SUM(I24:I26) -> 1
A28: ='SSC7'!A28 -> Transition | B28: ='SSC7'!B28 -> weighedItem (WeighItem ⇒ CheckWeight) | C28: ='GPT-5 Generation'!C28 -> 1 | D28: ='Claude Sonnet 4.5 Gen'!C28 -> 1
A29: ='SSC7'!A29 -> Action | B29: ='SSC7'!B29 -> addWeighedItem() | C29: ='GPT-5 Generation'!C29 -> 1 | D29: ='Claude Sonnet 4.5 Gen'!C29 -> 1 | F29: Confusion Matrix (Guard) | L29: Cohen's Kappa (Guard)
A30: ='SSC7'!A30 -> State | B30: ='SSC7'!B30 -> CheckWeight | C30: ='GPT-5 Generation'!C30 -> 1 | D30: ='Claude Sonnet 4.5 Gen'!C30 -> 1 | F30: Guard | G30: 0 | H30: 0.5 | I30: 1 | J30: Row Totals | L30: Metric | M30: Value | N30: Note
A31: ='SSC7'!A31 -> Transition | B31: ='SSC7'!B31 -> secWeighedItem (CheckWeight ⇒ Ready) | C31: ='GPT-5 Generation'!C31 -> 1 | D31: ='Claude Sonnet 4.5 Gen'!C31 -> 1 | F31: 0 | G31: =COUNTIFS($A$2:$A$111,$F$30,$C$2:$C$111,$F31,$D$2:$D$111,G$30) -> 1 | H31: =COUNTIFS($A$2:$A$111,$F$30,$C$2:$C$111,$F31,$D$2:$D$111,H$30) -> 0 | I31: =COUNTIFS($A$2:$A$67,$F$30,$C$2:$C$67,$F31,$D$2:$D$67,I$30) + MAX(D70-C70,0) -> 0 | J31: =SUM(G31:I31) -> 1 | L31: Observed Agreement (Po) | M31: =(G31+H32+I33)/COUNTIF($A$2:$A$121,F30) -> 1 | N31: This sums the diagonal of your matrix divided by total rows.
A32: ='SSC7'!A32 -> Guard | B32: ='SSC7'!B32 -> [weightMatched()] | C32: ='GPT-5 Generation'!C32 -> 1 | D32: ='Claude Sonnet 4.5 Gen'!C32 -> 1 | F32: 0.5 | G32: =COUNTIFS($A$2:$A$111,$F$30,$C$2:$C$111,$F32,$D$2:$D$111,G$30) -> 0 | H32: =COUNTIFS($A$2:$A$111,$F$30,$C$2:$C$111,$F32,$D$2:$D$111,H$30) -> 0 | I32: =COUNTIFS($A$2:$A$111,$F$30,$C$2:$C$111,$F32,$D$2:$D$111,I$30) -> 0 | J32: =SUM(G32:I32) -> 0 | L32: Expected Agreement (Pe) | M32: {=SUMPRODUCT(J31:J33/COUNTIF($A$2:$A$121,F30), TRANSPOSE(G34:I34)/COUNTIF($A$2:$A$121,F30))} -> 0.84722222 | N32: This computes the sum of row proportion times column proportion.
A33: ='SSC7'!A33 -> Transition | B33: ='SSC7'!B33 -> secWeighedItem (CheckWeight ⇒ Override) | C33: ='GPT-5 Generation'!C33 -> 1 | D33: ='Claude Sonnet 4.5 Gen'!C33 -> 1 | F33: 1 | G33: =COUNTIFS($A$2:$A$67,$F$30,$C$2:$C$67,$F33,$D$2:$D$67,G$30) + MAX(C70-D70,0) -> 0 | H33: =COUNTIFS($A$2:$A$111,$F$30,$C$2:$C$111,$F33,$D$2:$D$111,H$30) -> 0 | I33: =COUNTIFS($A$2:$A$67,$F$30,$C$2:$C$67,$F33,$D$2:$D$67,I$30) + MIN(C70,D70) -> 11 | J33: =SUM(G33:I33) -> 11 | L33: Cohen's Kappa | M33: =(M31-M32)/(1-M32) -> 1 | N33: (Po - Pe) / (1 - Pe)
A34: ='SSC7'!A34 -> Guard | B34: ='SSC7'!B34 -> [!weightMatched()] | C34: ='GPT-5 Generation'!C34 -> 1 | D34: ='Claude Sonnet 4.5 Gen'!C34 -> 1 | F34: Column Totals | G34: =SUM(G31:G33) -> 1 | H34: =SUM(H31:H33) -> 0 | I34: =SUM(I31:I33) -> 11
A35: ='SSC7'!A35 -> Action | B35: ='SSC7'!B35 -> setTypeItem() | C35: ='GPT-5 Generation'!C35 -> 1 | D35: ='Claude Sonnet 4.5 Gen'!C35 -> 0
A36: ='SSC7'!A36 -> Transition | B36: ='SSC7'!B36 -> cancelCheckout (CheckWeight ⇒ Override) | C36: ='GPT-5 Generation'!C36 -> 1 | D36: ='Claude Sonnet 4.5 Gen'!C36 -> 1 | F36: Confusion Matrix (Action) | L36: Cohen's Kappa (Action)
A37: ='SSC7'!A37 -> Action | B37: ='SSC7'!B37 -> setTypeEverything() | C37: ='GPT-5 Generation'!C37 -> 1 | D37: ='Claude Sonnet 4.5 Gen'!C37 -> 0 | F37: Action | G37: 0 | H37: 0.5 | I37: 1 | J37: Row Totals | L37: Metric | M37: Value | N37: Note
A38: ='SSC7'!A38 -> State | B38: ='SSC7'!B38 -> WeighBag | C38: ='GPT-5 Generation'!C38 -> 1 | D38: ='Claude Sonnet 4.5 Gen'!C38 -> 1 | F38: 0 | G38: =COUNTIFS($A$2:$A$111,F37,$C$2:$C$111,$F38,$D$2:$D$111,G37) -> 0 | H38: =COUNTIFS($A$2:$A$111,F37,$C$2:$C$111,$F38,$D$2:$D$111,H37) -> 0 | I38: =COUNTIFS($A$2:$A$67,F37,$C$2:$C$67,$F38,$D$2:$D$67,I37)+MAX(D71-C71,0) -> 1 | J38: =SUM(G38:I38) -> 1 | L38: Observed Agreement (Po) | M38: =(G38+H39+I40)/COUNTIF($A$2:$A$121,F37) -> 0.63636364 | N38: This sums the diagonal of your matrix divided by total rows.
A39: ='SSC7'!A39 -> Transition | B39: ='SSC7'!B39 -> secWeighedItem (WeighBag ⇒ Ready) | C39: ='GPT-5 Generation'!C39 -> 1 | D39: ='Claude Sonnet 4.5 Gen'!C39 -> 1 | F39: 0.5 | G39: =COUNTIFS($A$2:$A$111,F37,$C$2:$C$111,$F39,$D$2:$D$111,G37) -> 0 | H39: =COUNTIFS($A$2:$A$111,F37,$C$2:$C$111,$F39,$D$2:$D$111,H37) -> 0 | I39: =COUNTIFS($A$2:$A$111,F37,$C$2:$C$111,$F39,$D$2:$D$111,I37) -> 0 | J39: =SUM(G39:I39) -> 0 | L39: Expected Agreement (Pe) | M39: {=SUMPRODUCT(J38:J40/COUNTIF($A$2:$A$121,F37), TRANSPOSE(G41:I41)/COUNTIF($A$2:$A$121,F37))} -> 0.66322314 | N39: This computes the sum of row proportion times column proportion.
A40: ='SSC7'!A40 -> Action | B40: ='SSC7'!B40 -> addBag() | C40: ='GPT-5 Generation'!C40 -> 1 | D40: ='Claude Sonnet 4.5 Gen'!C40 -> 1 | F40: 1 | G40: =COUNTIFS($A$2:$A$67,F37,$C$2:$C$67,$F40,$D$2:$D$67,G37)+MAX(C71-D71,0) -> 6 | H40: =COUNTIFS($A$2:$A$111,F37,$C$2:$C$111,$F40,$D$2:$D$111,H37) -> 1 | I40: =COUNTIFS($A$2:$A$67,F37,$C$2:$C$67,$F40,$D$2:$D$67,I37) + MIN(C71,D71) -> 14 | J40: =SUM(G40:I40) -> 21 | L40: Cohen's Kappa | M40: =(M38-M39)/(1-M39) -> -0.079754601 | N40: (Po - Pe) / (1 - Pe)
...

Sheet Weighted Cohens Kappa
A1: Type | B1: Element | C1: GPT-5 | D1: Claude Sonnet 4.5 | F1: Confusion Matrix | L1: Weight Matrix
A2: ='SSC7'!A2 -> State | B2: ='SSC7'!B2 -> Initial state (→ Active) | C2: ='GPT-5 Generation'!C2 -> 1 | D2: ='Claude Sonnet 4.5 Gen'!C2 -> 1 | F2: Global | G2: 0 | H2: 0.5 | I2: 1 | J2: Row Totals | L2: Global | M2: 0 | N2: 0.5 | O2: 1 | Q2: Global | R2: 0 | S2: 0.5 | T2: 1 | V2: ="Metrics" & " " & F2 -> Metrics Global | W2: Value | X2: Note
A3: ='SSC7'!A3 -> Composite State | B3: ='SSC7'!B3 -> Active | C3: ='GPT-5 Generation'!C3 -> 1 | D3: ='Claude Sonnet 4.5 Gen'!C3 -> 1 | F3: 0 | G3: =COUNTIFS($C$2:$C$74, $F3, $D$2:$D$74, G$2) -> 4 | H3: =COUNTIFS($C$2:$C$67, $F3, $D$2:$D$67, H$2) -> 0 | I3: =COUNTIFS($C$2:$C$67, $F3, $D$2:$D$67, I$2)+MAX(D68-C68,0)+MAX(D69-C69,0)+MAX(D70-C70,0)+MAX(D71-C71,0)+MAX(D72-C72,0)+MAX(D73-C73,0)+MAX(D74-C74,0) -> 4 | J3: =SUM(G3:I3) -> 8 | L3: 0 | M3: =ABS(G$2-$F3)/1 -> 0 | N3: =ABS(H$2-$F3)/1 -> 0.5 | O3: =ABS(I$2-$F3)/1 -> 1 | Q3: 0 | R3: =($J3/$J$6) * (G$6/$J$6) -> 0.014609204 | S3: =($J3/$J$6) * (H$6/$J$6) -> 0.0043827611 | T3: =($J3/$J$6) * (I$6/$J$6) -> 0.089116143 | V3: Observed Weighted Disagreement (D_obs) | W3: =SUMPRODUCT(G3:I5, M3:O5) /$J$6 -> 0.15540541 | X3: Sum of (confusion-matrix counts × weights) divided by total items.
A4: ='SSC7'!A4 -> State | B4: ='SSC7'!B4 -> Initial state (Active → Ready) | C4: ='GPT-5 Generation'!C4 -> 1 | D4: ='Claude Sonnet 4.5 Gen'!C4 -> 1 | F4: 0.5 | G4: =COUNTIFS($C$2:$C$67, $F4, $D$2:$D$67, G$2) -> 0 | H4: =COUNTIFS($C$2:$C$67, $F4, $D$2:$D$67, H$2) -> 0 | I4: =COUNTIFS($C$2:$C$67, $F4, $D$2:$D$67, I$2) -> 0 | J4: =SUM(G4:I4) -> 0 | L4: 0.5 | M4: =ABS(G$2-$F4)/1 -> 0.5 | N4: =ABS(H$2-$F4)/3 -> 0 | O4: =ABS(I$2-$F4)/1 -> 0.5 | Q4: 0.5 | R4: =($J4/$J$6) * (G$6/$J$6) -> 0 | S4: =($J4/$J$6) * (H$6/$J$6) -> 0 | T4: =($J4/$J$6) * (I$6/$J$6) -> 0 | V4: Expected Weighted Disagreement (D_exp) | W4: =SUMPRODUCT(R3:T5, M3:O5) -> 0.22991234 | X4: Sum of (expected cell proportions × weights) under chance agreement.
A5: ='SSC7'!A5 -> State | B5: ='SSC7'!B5 -> Ready | C5: ='GPT-5 Generation'!C5 -> 1 | D5: ='Claude Sonnet 4.5 Gen'!C5 -> 1 | F5: 1 | G5: =COUNTIFS($C$2:$C$67, $F5, $D$2:$D$67, G$2)+MAX(C68-D68,0)+MAX(C69-D69,0)+MAX(C70-D70,0)+MAX(C71-D71,0)+MAX(C72-D72,0)+MAX(C73-D73,0)+MAX(C74-D74,0) -> 6 | H5: =COUNTIFS($C$2:$C$67, $F5, $D$2:$D$67, H$2) -> 3 | I5: =COUNTIFS($C$2:$C$67, $F5, $D$2:$D$67, I$2)+ SUM(MIN(C68,D68), MIN(C69,D69), MIN(C70,D70), MIN(C71,D71), MIN(C72,D72), MIN(C73,D73), MIN(C74,D74)) -> 57 | J5: =SUM(G5:I5) -> 66 | L5: 1 | M5: =ABS(G$2-$F5)/1 -> 1 | N5: =ABS(H$2-$F5)/1 -> 0.5 | O5: =ABS(I$2-$F5)/1 -> 0 | Q5: 1 | R5: =($J5/$J$6) * (G$6/$J$6) -> 0.12052593 | S5: =($J5/$J$6) * (H$6/$J$6) -> 0.036157779 | T5: =($J5/$J$6) * (I$6/$J$6) -> 0.73520818 | V5: Cohen's Kappa | W5: =1-W3/W4 -> 0.32406672 | X5: 1 - (D_obs / D_exp)
A6: ='SSC7'!A6 -> Transition | B6: ='SSC7'!B6 -> scannedNr (Ready ⇒ Ready) | C6: ='GPT-5 Generation'!C6 -> 1 | D6: ='Claude Sonnet 4.5 Gen'!C6 -> 1 | F6: Column Totals | G6: =SUM(G3:G5) -> 10 | H6: =SUM(H3:H5) -> 3 | I6: =SUM(I3:I5) -> 61 | J6: =SUM(G3:I5) -> 74
A7: ='SSC7'!A7 -> Guard | B7: ='SSC7'!B7 -> [!existsNr()] | C7: ='GPT-5 Generation'!C7 -> 1 | D7: ='Claude Sonnet 4.5 Gen'!C7 -> 1
A8: ='SSC7'!A8 -> Action | B8: ='SSC7'!B8 -> error() | C8: ='GPT-5 Generation'!C8 -> 1 | D8: ='Claude Sonnet 4.5 Gen'!C8 -> 1 | F8: Confusion Matrix (State)
A9: ='SSC7'!A9 -> Transition | B9: ='SSC7'!B9 -> productCodeEntered (Ready ⇒ Ready) | C9: ='GPT-5 Generation'!C9 -> 1 | D9: ='Claude Sonnet 4.5 Gen'!C9 -> 1 | F9: State | G9: 0 | H9: 0.5 | I9: 1 | J9: Row Totals | L9: Global | M9: 0 | N9: 0.5 | O9: 1 | Q9: Global | R9: 0 | S9: 0.5 | T9: 1 | V9: ="Metrics" & " " & F9 -> Metrics State | W9: Value | X9: Note
A10: ='SSC7'!A10 -> Guard | B10: ='SSC7'!B10 -> [!existsCode()] | C10: ='GPT-5 Generation'!C10 -> 1 | D10: ='Claude Sonnet 4.5 Gen'!C10 -> 1 | F10: 0 | G10: =COUNTIFS($A$2:$A$74,$F$9,$C$2:$C$74,$F10,$D$2:$D$74,G$9) -> 0 | H10: =COUNTIFS($A$2:$A$74,$F$9,$C$2:$C$74,$F10,$D$2:$D$74,H$9) -> 0 | I10: =COUNTIFS($A$2:$A$67,$F$9,$C$2:$C$67,$F10,$D$2:$D$67,I$9)+MAX(D68-C68,0) -> 2 | J10: =SUM(G10:I10) -> 2 | L10: 0 | M10: =ABS(G$2-$F10)/1 -> 0 | N10: =ABS(H$2-$F10)/1 -> 0.5 | O10: =ABS(I$2-$F10)/1 -> 1 | Q10: 0 | R10: =($J10/$J$13) * (G$13/$J$13) -> 0 | S10: =($J10/$J$13) * (H$13/$J$13) -> 0 | T10: =($J10/$J$13) * (I$13/$J$13) -> 0.22222222 | V10: Observed Weighted Disagreement (D_obs) | W10: =SUMPRODUCT(G10:I12, M10:O12) /$J$13 -> 0.22222222 | X10: Sum of (confusion-matrix counts × weights) divided by total items.
A11: ='SSC7'!A11 -> Action | B11: ='SSC7'!B11 -> error() | C11: ='GPT-5 Generation'!C11 -> 1 | D11: ='Claude Sonnet 4.5 Gen'!C11 -> 1 | F11: 0.5 | G11: =COUNTIFS($A$2:$A$74,$F$9,$C$2:$C$74,$F11,$D$2:$D$74,G$9) -> 0 | H11: =COUNTIFS($A$2:$A$74,$F$9,$C$2:$C$74,$F11,$D$2:$D$74,H$9) -> 0 | I11: =COUNTIFS($A$2:$A$74,$F$9,$C$2:$C$74,$F11,$D$2:$D$74,I$9) -> 0 | J11: =SUM(G11:I11) -> 0 | L11: 0.5 | M11: =ABS(G$2-$F11)/1 -> 0.5 | N11: =ABS(H$2-$F11)/3 -> 0 | O11: =ABS(I$2-$F11)/1 -> 0.5 | Q11: 0.5 | R11: =($J11/$J$13) * (G$13/$J$13) -> 0 | S11: =($J11/$J$13) * (H$13/$J$13) -> 0 | T11: =($J11/$J$13) * (I$13/$J$13) -> 0 | V11: Expected Weighted Disagreement (D_exp) | W11: =SUMPRODUCT(R10:T12, M10:O12) -> 0.22222222 | X11: Sum of (expected cell proportions × weights) under chance agreement.
A12: ='SSC7'!A12 -> Transition | B12: ='SSC7'!B12 -> productCodeEntered (Ready ⇒ WeighItem) | C12: ='GPT-5 Generation'!C12 -> 1 | D12: ='Claude Sonnet 4.5 Gen'!C12 -> 1 | F12: 1 | G12: =COUNTIFS($A$2:$A$67,$F$9,$C$2:$C$67,$F12,$D$2:$D$67,G$9)+MAX(C68-D68,0) -> 0 | H12: =COUNTIFS($A$2:$A$74,$F$9,$C$2:$C$74,$F12,$D$2:$D$74,H$9) -> 0 | I12: =COUNTIFS($A$2:$A$67,$F$9,$C$2:$C$67,$F12,$D$2:$D$67,I$9)+MIN(C68-D68) -> 7 | J12: =SUM(G12:I12) -> 7 | L12: 1 | M12: =ABS(G$2-$F12)/1 -> 1 | N12: =ABS(H$2-$F12)/1 -> 0.5 | O12: =ABS(I$2-$F12)/1 -> 0 | Q12: 1 | R12: =($J12/$J$13) * (G$13/$J$13) -> 0 | S12: =($J12/$J$13) * (H$13/$J$13) -> 0 | T12: =($J12/$J$13) * (I$13/$J$13) -> 0.77777778 | V12: Cohen's Kappa | W12: =1-W10/W11 -> 0 | X12: 1 - (D_obs / D_exp)
A13: ='SSC7'!A13 -> Guard | B13: ='SSC7'!B13 -> [existsCode()] | C13: ='GPT-5 Generation'!C13 -> 1 | D13: ='Claude Sonnet 4.5 Gen'!C13 -> 1 | F13: Column Totals | G13: =SUM(G10:G12) -> 0 | H13: =SUM(H10:H12) -> 0 | I13: =SUM(I10:I12) -> 9 | J13: =SUM(G10:I12) -> 9
A14: ='SSC7'!A14 -> Transition | B14: ='SSC7'!B14 -> scannedNr (Ready ⇒ CheckWeight) | C14: ='GPT-5 Generation'!C14 -> 1 | D14: ='Claude Sonnet 4.5 Gen'!C14 -> 1
A15: ='SSC7'!A15 -> Guard | B15: ='SSC7'!B15 -> [existsNr()] | C15: ='GPT-5 Generation'!C15 -> 1 | D15: ='Claude Sonnet 4.5 Gen'!C15 -> 1 | F15: Confusion Matrix (Transition)
A16: ='SSC7'!A16 -> Action | B16: ='SSC7'!B16 -> addItem() | C16: ='GPT-5 Generation'!C16 -> 1 | D16: ='Claude Sonnet 4.5 Gen'!C16 -> 1 | F16: Transition | G16: 0 | H16: 0.5 | I16: 1 | J16: Row Totals | L16: Global | M16: 0 | N16: 0.5 | O16: 1 | Q16: Global | R16: 0 | S16: 0.5 | T16: 1 | V16: ="Metrics" & " " & F16 -> Metrics Transition | W16: Value | X16: Note
A17: ='SSC7'!A17 -> Transition | B17: ='SSC7'!B17 -> cancelCheckout (Ready ⇒ Override) | C17: ='GPT-5 Generation'!C17 -> 1 | D17: ='Claude Sonnet 4.5 Gen'!C17 -> 1 | F17: 0 | G17: =COUNTIFS($A$2:$A$74,$F$16,$C$2:$C$74,$F17,$D$2:$D$74,G$16) -> 0 | H17: =COUNTIFS($A$2:$A$74,$F$16,$C$2:$C$74,$F17,$D$2:$D$74,H$16) -> 0 | I17: =COUNTIFS($A$2:$A$67,$F$16,$C$2:$C$67,$F17,$D$2:$D$67,I$16) + MAX(D69-C69,0) -> 1 | J17: =SUM(G17:I17) -> 1 | L17: 0 | M17: =ABS(G$2-$F17)/1 -> 0 | N17: =ABS(H$2-$F17)/1 -> 0.5 | O17: =ABS(I$2-$F17)/1 -> 1 | Q17: 0 | R17: =($J17/$J$20) * (G$20/$J$20) -> 0 | S17: =($J17/$J$20) * (H$20/$J$20) -> 0.0017361111 | T17: =($J17/$J$20) * (I$20/$J$20) -> 0.039930556 | V17: Observed Weighted Disagreement (D_obs) | W17: =SUMPRODUCT(G17:I19, M17:O19) /$J$20 -> 0.0625 | X17: Sum of (confusion-matrix counts × weights) divided by total items.
A18: ='SSC7'!A18 -> Action | B18: ='SSC7'!B18 -> setTypeEverything() | C18: ='GPT-5 Generation'!C18 -> 1 | D18: ='Claude Sonnet 4.5 Gen'!C18 -> 0 | F18: 0.5 | G18: =COUNTIFS($A$2:$A$74,$F$16,$C$2:$C$74,$F18,$D$2:$D$74,G$16) -> 0 | H18: =COUNTIFS($A$2:$A$74,$F$16,$C$2:$C$74,$F18,$D$2:$D$74,H$16) -> 0 | I18: =COUNTIFS($A$2:$A$74,$F$16,$C$2:$C$74,$F18,$D$2:$D$74,I$16) -> 0 | J18: =SUM(G18:I18) -> 0 | L18: 0.5 | M18: =ABS(G$2-$F18)/1 -> 0.5 | N18: =ABS(H$2-$F18)/3 -> 0 | O18: =ABS(I$2-$F18)/1 -> 0.5 | Q18: 0.5 | R18: =($J18/$J$20) * (G$20/$J$20) -> 0 | S18: =($J18/$J$20) * (H$20/$J$20) -> 0 | T18: =($J18/$J$20) * (I$20/$J$20) -> 0 | V18: Expected Weighted Disagreement (D_exp) | W18: =SUMPRODUCT(R17:T19, M17:O19) -> 0.060763889 | X18: Sum of (expected cell proportions × weights) under chance agreement.
A19: ='SSC7'!A19 -> Transition | B19: ='SSC7'!B19 -> removeItem (Ready ⇒ Override) | C19: ='GPT-5 Generation'!C19 -> 1 | D19: ='Claude Sonnet 4.5 Gen'!C19 -> 1 | F19: 1 | G19: =COUNTIFS($A$2:$A$67,$F$16,$C$2:$C$67,$F19,$D$2:$D$67,G$16)+MAX(C69-D69,0) -> 0 | H19: =COUNTIFS($A$2:$A$74,$F$16,$C$2:$C$74,$F19,$D$2:$D$74,H$16) -> 1 | I19: =COUNTIFS($A$2:$A$67,$F$16,$C$2:$C$67,$F19,$D$2:$D$67,I$16) + MIN(C69,D69) -> 22 | J19: =SUM(G19:I19) -> 23 | L19: 1 | M19: =ABS(G$2-$F19)/1 -> 1 | N19: =ABS(H$2-$F19)/1 -> 0.5 | O19: =ABS(I$2-$F19)/1 -> 0 | Q19: 1 | R19: =($J19/$J$20) * (G$20/$J$20) -> 0 | S19: =($J19/$J$20) * (H$20/$J$20) -> 0.039930556 | T19: =($J19/$J$20) * (I$20/$J$20) -> 0.91840278 | V19: Cohen's Kappa | W19: =1-W17/W18 -> -0.028571429 | X19: 1 - (D_obs / D_exp)
A20: ='SSC7'!A20 -> Guard | B20: ='SSC7'!B20 -> [billHasItem()] | C20: ='GPT-5 Generation'!C20 -> 1 | D20: ='Claude Sonnet 4.5 Gen'!C20 -> 1 | F20: Column Totals | G20: =SUM(G17:G19) -> 0 | H20: =SUM(H17:H19) -> 1 | I20: =SUM(I17:I19) -> 23 | J20: =SUM(G17:I19) -> 24
A21: ='SSC7'!A21 -> Action | B21: ='SSC7'!B21 -> setTypeItem() | C21: ='GPT-5 Generation'!C21 -> 1 | D21: ='Claude Sonnet 4.5 Gen'!C21 -> 0
A22: ='SSC7'!A22 -> Transition | B22: ='SSC7'!B22 -> broughtOwnBag (Ready ⇒ WeighBag) | C22: ='GPT-5 Generation'!C22 -> 1 | D22: ='Claude Sonnet 4.5 Gen'!C22 -> 1 | F22: Confusion Matrix (Composite State)
A23: ='SSC7'!A23 -> Transition | B23: ='SSC7'!B23 -> pay (Ready ⇒ PayRequested) | C23: ='GPT-5 Generation'!C23 -> 1 | D23: ='Claude Sonnet 4.5 Gen'!C23 -> 1 | F23: Composite State | G23: 0 | H23: 0.5 | I23: 1 | J23: Row Totals | L23: Global | M23: 0 | N23: 0.5 | O23: 1 | Q23: Global | R23: 0 | S23: 0.5 | T23: 1 | V23: ="Metrics" & " " & F23 -> Metrics Composite State | W23: Value | X23: Note
A24: ='SSC7'!A24 -> Guard | B24: ='SSC7'!B24 -> [billHasItem()] | C24: ='GPT-5 Generation'!C24 -> 1 | D24: ='Claude Sonnet 4.5 Gen'!C24 -> 1 | F24: 0 | G24: =COUNTIFS($A$2:$A$74,$F$23,$C$2:$C$74,$F24,$D$2:$D$74,G$23) -> 1 | H24: =COUNTIFS($A$2:$A$74,$F$23,$C$2:$C$74,$F24,$D$2:$D$74,H$23) -> 0 | I24: =COUNTIFS($A$2:$A$67,$F$23,$C$2:$C$67,$F24,$D$2:$D$67,I$23) + MAX(D72-C72,0) -> 0 | J24: =SUM(G24:I24) -> 1 | L24: 0 | M24: =ABS(G$2-$F24)/1 -> 0 | N24: =ABS(H$2-$F24)/1 -> 0.5 | O24: =ABS(I$2-$F24)/1 -> 1 | Q24: 0 | R24: =($J24/$J$27) * (G$27/$J$27) -> 0.25 | S24: =($J24/$J$27) * (H$27/$J$27) -> 0 | T24: =($J24/$J$27) * (I$27/$J$27) -> 0.25 | V24: Observed Weighted Disagreement (D_obs) | W24: =SUMPRODUCT(G24:I26, M24:O26) /$J$27 -> 0 | X24: Sum of (confusion-matrix counts × weights) divided by total items.
A25: ='SSC7'!A25 -> Action | B25: ='SSC7'!B25 -> sendPaymentRequest() | C25: ='GPT-5 Generation'!C25 -> 1 | D25: ='Claude Sonnet 4.5 Gen'!C25 -> 1 | F25: 0.5 | G25: =COUNTIFS($A$2:$A$74,$F$23,$C$2:$C$74,$F25,$D$2:$D$74,G$23) -> 0 | H25: =COUNTIFS($A$2:$A$74,$F$23,$C$2:$C$74,$F25,$D$2:$D$74,H$23) -> 0 | I25: =COUNTIFS($A$2:$A$74,$F$23,$C$2:$C$74,$F25,$D$2:$D$74,I$23) -> 0 | J25: =SUM(G25:I25) -> 0 | L25: 0.5 | M25: =ABS(G$2-$F25)/1 -> 0.5 | N25: =ABS(H$2-$F25)/3 -> 0 | O25: =ABS(I$2-$F25)/1 -> 0.5 | Q25: 0.5 | R25: =($J25/$J$27) * (G$27/$J$27) -> 0 | S25: =($J25/$J$27) * (H$27/$J$27) -> 0 | T25: =($J25/$J$27) * (I$27/$J$27) -> 0 | V25: Expected Weighted Disagreement (D_exp) | W25: =SUMPRODUCT(R24:T26, M24:O26) -> 0.5 | X25: Sum of (expected cell proportions × weights) under chance agreement.
A26: ='SSC7'!A26 -> State | B26: ='SSC7'!B26 -> WeighItem | C26: ='GPT-5 Generation'!C26 -> 1 | D26: ='Claude Sonnet 4.5 Gen'!C26 -> 1 | F26: 1 | G26: =COUNTIFS($A$2:$A$67,$F$23,$C$2:$C$67,$F26,$D$2:$D$67,G$23) + MAX(C72-D72,0) -> 0 | H26: =COUNTIFS($A$2:$A$74,$F$23,$C$2:$C$74,$F26,$D$2:$D$74,H$23) -> 0 | I26: =COUNTIFS($A$2:$A$67,$F$23,$C$2:$C$67,$F26,$D$2:$D$67,I$23) + MIN(C72,D72) -> 1 | J26: =SUM(G26:I26) -> 1 | L26: 1 | M26: =ABS(G$2-$F26)/1 -> 1 | N26: =ABS(H$2-$F26)/1 -> 0.5 | O26: =ABS(I$2-$F26)/1 -> 0 | Q26: 1 | R26: =($J26/$J$27) * (G$27/$J$27) -> 0.25 | S26: =($J26/$J$27) * (H$27/$J$27) -> 0 | T26: =($J26/$J$27) * (I$27/$J$27) -> 0.25 | V26: Cohen's Kappa | W26: =1-W24/W25 -> 1 | X26: 1 - (D_obs / D_exp)
A27: ='SSC7'!A27 -> Transition | B27: ='SSC7'!B27 -> cancel (WeighItem ⇒ Ready) | C27: ='GPT-5 Generation'!C27 -> 1 | D27: ='Claude Sonnet 4.5 Gen'!C27 -> 1 | F27: Column Totals | G27: =SUM(G24:G26) -> 1 | H27: =SUM(H24:H26) -> 0 | I27: =SUM(I24:I26) -> 1 | J27: =SUM(G24:I26) -> 2
A28: ='SSC7'!A28 -> Transition | B28: ='SSC7'!B28 -> weighedItem (WeighItem ⇒ CheckWeight) | C28: ='GPT-5 Generation'!C28 -> 1 | D28: ='Claude Sonnet 4.5 Gen'!C28 -> 1
A29: ='SSC7'!A29 -> Action | B29: ='SSC7'!B29 -> addWeighedItem() | C29: ='GPT-5 Generation'!C29 -> 1 | D29: ='Claude Sonnet 4.5 Gen'!C29 -> 1 | F29: Confusion Matrix (Guard)
A30: ='SSC7'!A30 -> State | B30: ='SSC7'!B30 -> CheckWeight | C30: ='GPT-5 Generation'!C30 -> 1 | D30: ='Claude Sonnet 4.5 Gen'!C30 -> 1 | F30: Guard | G30: 0 | H30: 0.5 | I30: 1 | J30: Row Totals | L30: Global | M30: 0 | N30: 0.5 | O30: 1 | Q30: Global | R30: 0 | S30: 0.5 | T30: 1 | V30: ="Metrics" & " " & F30 -> Metrics Guard | W30: Value | X30: Note
A31: ='SSC7'!A31 -> Transition | B31: ='SSC7'!B31 -> secWeighedItem (CheckWeight ⇒ Ready) | C31: ='GPT-5 Generation'!C31 -> 1 | D31: ='Claude Sonnet 4.5 Gen'!C31 -> 1 | F31: 0 | G31: =COUNTIFS($A$2:$A$74,$F$30,$C$2:$C$74,$F31,$D$2:$D$74,G$30) -> 1 | H31: =COUNTIFS($A$2:$A$74,$F$30,$C$2:$C$74,$F31,$D$2:$D$74,H$30) -> 0 | I31: =COUNTIFS($A$2:$A$67,$F$30,$C$2:$C$67,$F31,$D$2:$D$67,I$30) + MAX(D70-C70,0) -> 0 | J31: =SUM(G31:I31) -> 1 | L31: 0 | M31: =ABS(G$2-$F31)/1 -> 0 | N31: =ABS(H$2-$F31)/1 -> 0.5 | O31: =ABS(I$2-$F31)/1 -> 1 | Q31: 0 | R31: =($J31/$J$34) * (G$34/$J$34) -> 0.0069444444 | S31: =($J31/$J$34) * (H$34/$J$34) -> 0 | T31: =($J31/$J$34) * (I$34/$J$34) -> 0.076388889 | V31: Observed Weighted Disagreement (D_obs) | W31: =SUMPRODUCT(G31:I33, M31:O33) /$J$34 -> 0 | X31: Sum of (confusion-matrix counts × weights) divided by total items.
A32: ='SSC7'!A32 -> Guard | B32: ='SSC7'!B32 -> [weightMatched()] | C32: ='GPT-5 Generation'!C32 -> 1 | D32: ='Claude Sonnet 4.5 Gen'!C32 -> 1 | F32: 0.5 | G32: =COUNTIFS($A$2:$A$74,$F$30,$C$2:$C$74,$F32,$D$2:$D$74,G$30) -> 0 | H32: =COUNTIFS($A$2:$A$74,$F$30,$C$2:$C$74,$F32,$D$2:$D$74,H$30) -> 0 | I32: =COUNTIFS($A$2:$A$74,$F$30,$C$2:$C$74,$F32,$D$2:$D$74,I$30) -> 0 | J32: =SUM(G32:I32) -> 0 | L32: 0.5 | M32: =ABS(G$2-$F32)/1 -> 0.5 | N32: =ABS(H$2-$F32)/3 -> 0 | O32: =ABS(I$2-$F32)/1 -> 0.5 | Q32: 0.5 | R32: =($J32/$J$34) * (G$34/$J$34) -> 0 | S32: =($J32/$J$34) * (H$34/$J$34) -> 0 | T32: =($J32/$J$34) * (I$34/$J$34) -> 0 | V32: Expected Weighted Disagreement (D_exp) | W32: =SUMPRODUCT(R31:T33, M31:O33) -> 0.15277778 | X32: Sum of (expected cell proportions × weights) under chance agreement.
A33: ='SSC7'!A33 -> Transition | B33: ='SSC7'!B33 -> secWeighedItem (CheckWeight ⇒ Override) | C33: ='GPT-5 Generation'!C33 -> 1 | D33: ='Claude Sonnet 4.5 Gen'!C33 -> 1 | F33: 1 | G33: =COUNTIFS($A$2:$A$67,$F$30,$C$2:$C$67,$F33,$D$2:$D$67,G$30) + MAX(C70-D70,0) -> 0 | H33: =COUNTIFS($A$2:$A$74,$F$30,$C$2:$C$74,$F33,$D$2:$D$74,H$30) -> 0 | I33: =COUNTIFS($A$2:$A$67,$F$30,$C$2:$C$67,$F33,$D$2:$D$67,I$30) + MIN(C70,D70) -> 11 | J33: =SUM(G33:I33) -> 11 | L33: 1 | M33: =ABS(G$2-$F33)/1 -> 1 | N33: =ABS(H$2-$F33)/1 -> 0.5 | O33: =ABS(I$2-$F33)/1 -> 0 | Q33: 1 | R33: =($J33/$J$34) * (G$34/$J$34) -> 0.076388889 | S33: =($J33/$J$34) * (H$34/$J$34) -> 0 | T33: =($J33/$J$34) * (I$34/$J$34) -> 0.84027778 | V33: Cohen's Kappa | W33: =1-W31/W32 -> 1 | X33: 1 - (D_obs / D_exp)
A34: ='SSC7'!A34 -> Guard | B34: ='SSC7'!B34 -> [!weightMatched()] | C34: ='GPT-5 Generation'!C34 -> 1 | D34: ='Claude Sonnet 4.5 Gen'!C34 -> 1 | F34: Column Totals | G34: =SUM(G31:G33) -> 1 | H34: =SUM(H31:H33) -> 0 | I34: =SUM(I31:I33) -> 11 | J34: =SUM(G31:I33) -> 12
A35: ='SSC7'!A35 -> Action | B35: ='SSC7'!B35 -> setTypeItem() | C35: ='GPT-5 Generation'!C35 -> 1 | D35: ='Claude Sonnet 4.5 Gen'!C35 -> 0
A36: ='SSC7'!A36 -> Transition | B36: ='SSC7'!B36 -> cancelCheckout (CheckWeight ⇒ Override) | C36: ='GPT-5 Generation'!C36 -> 1 | D36: ='Claude Sonnet 4.5 Gen'!C36 -> 1 | F36: Confusion Matrix (Action)
A37: ='SSC7'!A37 -> Action | B37: ='SSC7'!B37 -> setTypeEverything() | C37: ='GPT-5 Generation'!C37 -> 1 | D37: ='Claude Sonnet 4.5 Gen'!C37 -> 0 | F37: Action | G37: 0 | H37: 0.5 | I37: 1 | J37: Row Totals | L37: Global | M37: 0 | N37: 0.5 | O37: 1 | Q37: Global | R37: 0 | S37: 0.5 | T37: 1 | V37: ="Metrics" & " " & F37 -> Metrics Action | W37: Value | X37: Note
A38: ='SSC7'!A38 -> State | B38: ='SSC7'!B38 -> WeighBag | C38: ='GPT-5 Generation'!C38 -> 1 | D38: ='Claude Sonnet 4.5 Gen'!C38 -> 1 | F38: 0 | G38: =COUNTIFS($A$2:$A$74,F37,$C$2:$C$74,$F38,$D$2:$D$74,G37) -> 0 | H38: =COUNTIFS($A$2:$A$74,F37,$C$2:$C$74,$F38,$D$2:$D$74,H37) -> 0 | I38: =COUNTIFS($A$2:$A$67,F37,$C$2:$C$67,$F38,$D$2:$D$67,I37)+MAX(D71-C71,0) -> 1 | J38: =SUM(G38:I38) -> 1 | L38: 0 | M38: =ABS(G$2-$F38)/1 -> 0 | N38: =ABS(H$2-$F38)/1 -> 0.5 | O38: =ABS(I$2-$F38)/1 -> 1 | Q38: 0 | R38: =($J38/$J$41) * (G$41/$J$41) -> 0.012396694 | S38: =($J38/$J$41) * (H$41/$J$41) -> 0.0020661157 | T38: =($J38/$J$41) * (I$41/$J$41) -> 0.030991736 | V38: Observed Weighted Disagreement (D_obs) | W38: =SUMPRODUCT(G38:I40, M38:O40) /$J$41 -> 0.34090909 | X38: Sum of (confusion-matrix counts × weights) divided by total items.
A39: ='SSC7'!A39 -> Transition | B39: ='SSC7'!B39 -> secWeighedItem (WeighBag ⇒ Ready) | C39: ='GPT-5 Generation'!C39 -> 1 | D39: ='Claude Sonnet 4.5 Gen'!C39 -> 1 | F39: 0.5 | G39: =COUNTIFS($A$2:$A$74,F37,$C$2:$C$74,$F39,$D$2:$D$74,G37) -> 0 | H39: =COUNTIFS($A$2:$A$74,F37,$C$2:$C$74,$F38,$D$2:$D$74,H37) -> 0 | I39: =COUNTIFS($A$2:$A$74,F37,$C$2:$C$74,$F39,$D$2:$D$74,I37) -> 0 | J39: =SUM(G39:I39) -> 0 | L39: 0.5 | M39: =ABS(G$2-$F39)/1 -> 0.5 | N39: =ABS(H$2-$F39)/3 -> 0 | O39: =ABS(I$2-$F39)/1 -> 0.5 | Q39: 0.5 | R39: =($J39/$J$41) * (G$41/$J$41) -> 0 | S39: =($J39/$J$41) * (H$41/$J$41) -> 0 | T39: =($J39/$J$41) * (I$41/$J$41) -> 0 | V39: Expected Weighted Disagreement (D_exp) | W39: =SUMPRODUCT(R38:T40, M38:O40) -> 0.31404959 | X39: Sum of (expected cell proportions × weights) under chance agreement.
A40: ='SSC7'!A40 -> Action | B40: ='SSC7'!B40 -> addBag() | C40: ='GPT-5 Generation'!C40 -> 1 | D40: ='Claude Sonnet 4.5 Gen'!C40 -> 1 | F40: 1 | G40: =COUNTIFS($A$2:$A$67,F37,$C$2:$C$67,$F40,$D$2:$D$67,G37)+MAX(C71-D71,0) -> 6 | H40: =COUNTIFS($A$2:$A$74,F37,$C$2:$C$74,$F40,$D$2:$D$74,H37) -> 1 | I40: =COUNTIFS($A$2:$A$67,F37,$C$2:$C$67,$F40,$D$2:$D$67,I37) + MIN(C71,D71) -> 14 | J40: =SUM(G40:I40) -> 21 | L40: 1 | M40: =ABS(G$2-$F40)/1 -> 1 | N40: =ABS(H$2-$F40)/1 -> 0.5 | O40: =ABS(I$2-$F40)/1 -> 0 | Q40: 1 | R40: =($J40/$J$41) * (G$41/$J$41) -> 0.26033058 | S40: =($J40/$J$41) * (H$41/$J$41) -> 0.04338843 | T40: =($J40/$J$41) * (I$41/$J$41) -> 0.65082645 | V40: Cohen's Kappa | W40: =1-W38/W39 -> -0.085526316 | X40: 1 - (D_obs / D_exp)
...
