Workbook

Sheet Thermonix
A1: Type | B1: Element
A2: State | B2: initial state (⇒ TransportationMode)
A3: State | B3: TransportationMode
A4: Transition | B4: selectorPressed (TransportationMode ⇒ On)
A5: State | B5: PreparingOff
A6: Transition | B6: selectorReleased (PreparingOff ⇒ On)
A7: Transition | B7: after 5sec (PreparingOff ⇒ Off)
A8: State | B8: Off
A9: Transition | B9: selectorPressed (Off ⇒ On)
A10: Composite State | B10: On
A11: History State | B11: History State for On
A12: Transition | B12: selectorHeld (On ⇒ PreparingOff)
... A51: History State | B51: additional elements

Sheet Thermonix Grader #1
A1: Type | B1: Element | C1: Rater 1 | D1: Notes
A2: State | B2: initial state (⇒ TransportationMode) | C2: 1
A3: State | B3: TransportationMode | C3: 1
A4: Transition | B4: selectorPressed (TransportationMode ⇒ On) | C4: 1 | D4: goes to homescreen instead of on, same concept, problem doesnt specify a ON mode
A5: State | B5: PreparingOff | C5: 1 | D5: shutting down state
A6: Transition | B6: selectorReleased (PreparingOff ⇒ On) | C6: 1 | D6: goes back to homescreen
A7: Transition | B7: after 5sec (PreparingOff ⇒ Off) | C7: 1 | D7: shows shutdown message, then turns off
A8: State | B8: Off | C8: 1
A9: Transition | B9: selectorPressed (Off ⇒ On) | C9: 1
A10: Composite State | B10: On | C10: 0
A11: History State | B11: History State for On | C11: 0
A12: Transition | B12: selectorHeld (On ⇒ PreparingOff) | C12: 1
A13: Transition | B13: bowlRemoved (On ⇒ On) | C13: 1 | D13: same logic but shown with homescreen instead of on
A14: State | B14: Initial State (On ⇒ Home) | C14: 0
A15: State | B15: Home | C15: 1
A16: Transition | B16: after 14min 30sec (Home ⇒ Preparing Shutdown) | C16: 1
A17: Transition | B17: start (Home ⇒ PromptToAdd) | C17: 1
A18: Guard | B18: [!bowlRemoved()] | C18: 1 | D18: shown in [bowlplaced] (recipeselected => addingIngredients)
A19: Action | B19: setIngredients() | C19: 1 | D19: select recipe
A20: State | B20: Preparing Shutdown | C20: 1
A21: Transition | B21: after 30sec (Preparing Shutdown ⇒ Off) | C21: 1
A22: Transition | B22: cancel (Preparing Shutdown ⇒ Home) | C22: 1
A23: State | B23: PromptToAdd | C23: 0
A24: Transition | B24: next (PromptToAdd ⇒ PromptToAdd) | C24: 0
A25: Guard | B25: [weightCorrect() && moreIngredientsRequired()] | C25: 0
A26: Action | B26: setIngredients() | C26: 0
A27: Transition | B27: next (PromptToAdd ⇒ Chop) | C27: 1
A28: Guard | B28: [weightCorrect() && !moreIngredientsRequired()] | C28: 0.5 | D28: correctAmount is not detailed enough
A29: Action | B29: setChoppingSpeedAndTime() | C29: 0
A30: State | B30: Chop | C30: 1
A31: Transition | B31: next (Chop ⇒ PromptToAdd) | C31: 0
A32: Guard | B32: [choppingTimeDone && moreIngredientsRequired()] | C32: 0
A33: Action | B33: setIngredients() | C33: 0
A34: Transition | B34: next (Chop ⇒ Cook) | C34: 1
A35: Guard | B35: [choppingTimeDone && !moreIngredientsRequired()] | C35: 0
A36: Action | B36: setCookingSpeedAndTime() | C36: 0
A37: State | B37: Cook | C37: 1
A38: Transition | B38: after choppingTime (Cook ⇒ PromptToAdd) | C38: 1
A39: Guard | B39: [choppingTimeDone && moreIngredientsRequired()] | C39: 0.5
A40: Action | B40: setIngredients() | C40: 0
...

Sheet Thermonix Grader #2
A1: Type | B1: Element | C1: Rater 2 | D1: Notes
A2: State | B2: initial state (⇒ TransportationMode) | C2: 1
A3: State | B3: TransportationMode | C3: 1
A4: Transition | B4: selectorPressed (TransportationMode ⇒ On) | C4: 1
A5: State | B5: PreparingOff | C5: 1
A6: Transition | B6: selectorReleased (PreparingOff ⇒ On) | C6: 1
A7: Transition | B7: after 5sec (PreparingOff ⇒ Off) | C7: 1
A8: State | B8: Off | C8: 1
A9: Transition | B9: selectorPressed (Off ⇒ On) | C9: 1
A10: Composite State | B10: On | C10: 1 | D10: RecipeExecution
A11: History State | B11: History State for On | C11: 0
A12: Transition | B12: selectorHeld (On ⇒ PreparingOff) | C12: 0.5 | D12: home screen
A13: Transition | B13: bowlRemoved (On ⇒ On) | C13: 1
A14: State | B14: Initial State (On ⇒ Home) | C14: 0
A15: State | B15: Home | C15: 1
A16: Transition | B16: after 14min 30sec (Home ⇒ Preparing Shutdown) | C16: 1
A17: Transition | B17: start (Home ⇒ PromptToAdd) | C17: 1
A18: Guard | B18: [!bowlRemoved()] | C18: 1
A19: Action | B19: setIngredients() | C19: 1
A20: State | B20: Preparing Shutdown | C20: 1
A21: Transition | B21: after 30sec (Preparing Shutdown ⇒ Off) | C21: 1
A22: Transition | B22: cancel (Preparing Shutdown ⇒ Home) | C22: 1
A23: State | B23: PromptToAdd | C23: 0
A24: Transition | B24: next (PromptToAdd ⇒ PromptToAdd) | C24: 0
... A43: State | B43: Ready | C43: 1
A44: Transition | B44: after 14min 30sec (Ready ⇒ Preparing Shutdown) | C44: 0.5 | D44: shutdown -> homescreen
A45: State | B45: additional elements | C45: 0
A46: Transition | B46: additional elements | C46: 0
A47: Guard | B47: additional elements | C47: 0
A48: Action | B48: additional elements | C48: 0
A49: Composite State | B49: additional elements | C49: 0
A50: Region | B50: additional elements | C50: 0
A51: History State | B51: additional elements | C51: 0

Sheet Metrics
A1: Claude Grader #1 | J1: Date
A2: Type | B2: Ground Truth Count | C2: True Positive | D2: False Positive | E2: False Negative | F2: Precision | G2: Recall | H2: F1 Score | J2: March 16th, 2026
A3: Composite State | B3: =COUNTIF(Thermonix!$A$2:$A$44, A3) -> 1 | C3: =SUMIF('Thermonix Grader #1'!$A$2:$A$44, $A3, 'Thermonix Grader #1'!$C$2:$C$44) -> 0 | D3: =SUMIF('Thermonix Grader #1'!$A$45:$A$51, $A3, 'Thermonix Grader #1'!$C$45:$C$51) -> 0 | E3: =COUNTIFS('Thermonix Grader #1'!$A$2:$A$44, $A3, 'Thermonix Grader #1'!$C$2:$C$44,0) -> 1 | F3: =IFERROR(C3 / (C3 + D3), "Not Available") -> Not Available | G3: =IFERROR(C3 / B3, "Not Available") -> 0 | H3: =IFERROR(2*((F3*G3)/(F3+G3)),"Not Available") -> Not Available
A4: State | B4: =COUNTIF(Thermonix!$A$2:$A$44, A4) -> 11 | C4: =SUMIF('Thermonix Grader #1'!$A$2:$A$44, $A4, 'Thermonix Grader #1'!$C$2:$C$44) -> 9 | D4: =SUMIF('Thermonix Grader #1'!$A$45:$A$51, $A4, 'Thermonix Grader #1'!$C$45:$C$51) -> 0 | E4: =COUNTIFS('Thermonix Grader #1'!$A$2:$A$44, $A4, 'Thermonix Grader #1'!$C$2:$C$44,0) -> 2 | F4: =IFERROR(C4 / (C4 + D4), "Not Available") -> 1 | G4: =IFERROR(C4 / B4, "Not Available") -> 0.81818182 | H4: =IFERROR(2*((F4*G4)/(F4+G4)),"Not Available") -> 0.9 | J4: Grader #1 ID
A5: Transition | B5: =COUNTIF(Thermonix!$A$2:$A$44, A5) -> 17 | C5: =SUMIF('Thermonix Grader #1'!$A$2:$A$44, $A5, 'Thermonix Grader #1'!$C$2:$C$44) -> 14 | D5: =SUMIF('Thermonix Grader #1'!$A$45:$A$51, $A5, 'Thermonix Grader #1'!$C$45:$C$51) -> 0 | E5: =COUNTIFS('Thermonix Grader #1'!$A$2:$A$44, $A5, 'Thermonix Grader #1'!$C$2:$C$44,0) -> 3 | F5: =IFERROR(C5 / (C5 + D5), "Not Available") -> 1 | G5: =IFERROR(C5 / B5, "Not Available") -> 0.82352941 | H5: =IFERROR(2*((F5*G5)/(F5+G5)),"Not Available") -> 0.90322581 | J5: 2
A6: Action | B6: =COUNTIF(Thermonix!$A$2:$A$44, A6) -> 6 | C6: =SUMIF('Thermonix Grader #1'!$A$2:$A$44, $A6, 'Thermonix Grader #1'!$C$2:$C$44) -> 1 | D6: =SUMIF('Thermonix Grader #1'!$A$45:$A$51, $A6, 'Thermonix Grader #1'!$C$45:$C$51) -> 0 | E6: =COUNTIFS('Thermonix Grader #1'!$A$2:$A$44, $A6, 'Thermonix Grader #1'!$C$2:$C$44,0) -> 5 | F6: =IFERROR(C6 / (C6 + D6), "Not Available") -> 1 | G6: =IFERROR(C6 / B6, "Not Available") -> 0.16666667 | H6: =IFERROR(2*((F6*G6)/(F6+G6)),"Not Available") -> 0.28571429
A7: Region | B7: =COUNTIF(Thermonix!$A$2:$A$44, A7) -> 0 | C7: =SUMIF('Thermonix Grader #1'!$A$2:$A$44, $A7, 'Thermonix Grader #1'!$C$2:$C$44) -> 0 | D7: =SUMIF('Thermonix Grader #1'!$A$45:$A$51, $A7, 'Thermonix Grader #1'!$C$45:$C$51) -> 0 | E7: =COUNTIFS('Thermonix Grader #1'!$A$2:$A$44, $A7, 'Thermonix Grader #1'!$C$2:$C$44,0) -> 0 | F7: =IFERROR(C7 / (C7 + D7), "Not Available") -> Not Available | G7: =IFERROR(C7 / B7, "Not Available") -> Not Available | H7: =IFERROR(2*((F7*G7)/(F7+G7)),"Not Available") -> Not Available | J7: Grader #2 ID
A8: History State | B8: =COUNTIF(Thermonix!$A$2:$A$44, A8) -> 1 | C8: =SUMIF('Thermonix Grader #1'!$A$2:$A$44, $A8, 'Thermonix Grader #1'!$C$2:$C$44) -> 0 | D8: =SUMIF('Thermonix Grader #1'!$A$45:$A$51, $A8, 'Thermonix Grader #1'!$C$45:$C$51) -> 0 | E8: =COUNTIFS('Thermonix Grader #1'!$A$2:$A$44, $A8, 'Thermonix Grader #1'!$C$2:$C$44,0) -> 1 | F8: =IFERROR(C8 / (C8 + D8), "Not Available") -> Not Available | G8: =IFERROR(C8 / B8, "Not Available") -> 0 | H8: =IFERROR(2*((F8*G8)/(F8+G8)),"Not Available") -> Not Available | J8: 4
A9: Guard | B9: =COUNTIF(Thermonix!$A$2:$A$44, A9) -> 7 | C9: =SUMIF('Thermonix Grader #1'!$A$2:$A$44, $A9, 'Thermonix Grader #1'!$C$2:$C$44) -> 3 | D9: =SUMIF('Thermonix Grader #1'!$A$45:$A$51, $A9, 'Thermonix Grader #1'!$C$45:$C$51) -> 0 | E9: =COUNTIFS('Thermonix Grader #1'!$A$2:$A$44, $A9, 'Thermonix Grader #1'!$C$2:$C$44,0) -> 3 | F9: =IFERROR(C9 / (C9 + D9), "Not Available") -> 1 | G9: =IFERROR(C9 / B9, "Not Available") -> 0.42857143 | H9: =IFERROR(2*((F9*G9)/(F9+G9)),"Not Available") -> 0.6
A10: Overall Score | B10: =SUM(B3:B9) -> 43 | C10: =SUM(C3:C9) -> 27 | D10: =SUM(D3:D9) -> 0 | E10: =SUM(E3:E9) -> 15 | F10: =IFERROR(C10 / (C10 + D10), "Not Available") -> 1 | G10: =IFERROR(C10 / B10, "Not Available") -> 0.62790698 | H10: =IFERROR(2*((F10*G10)/(F10+G10)),"Not Available") -> 0.77142857 | J10: LLM Used
J11: Claude 4.5 Sonnet
A12: Claude Grader #2
A13: Type | B13: Ground Truth Count | C13: True Positive | D13: False Positive | E13: False Negative | F13: Precision | G13: Recall | H13: F1 Score
A14: Composite state | B14: =COUNTIF(Thermonix!$A$2:$A$44, A14) -> 1 | C14: =SUMIF('Thermonix Grader #2'!$A$2:$A$44, $A14, 'Thermonix Grader #2'!$C$2:$C$44) -> 1 | D14: =SUMIF('Thermonix Grader #2'!$A$45:$A$51, $A14, 'Thermonix Grader #2'!$C$45:$C$51) -> 0 | E14: =COUNTIFS('Thermonix Grader #2'!$A$2:$A$44, $A14, 'Thermonix Grader #2'!$C$2:$C$44,0) -> 0 | F14: =IFERROR(C14 / (C14 + D14), "Not Available") -> 1 | G14: =IFERROR(C14 / B14, "Not Available") -> 1 | H14: =IFERROR(2*((F14*G14)/(F14+G14)),"Not Available") -> 1
A15: State | B15: =COUNTIF(Thermonix!$A$2:$A$44, A15) -> 11 | C15: =SUMIF('Thermonix Grader #2'!$A$2:$A$44, $A15, 'Thermonix Grader #2'!$C$2:$C$44) -> 9 | D15: =SUMIF('Thermonix Grader #2'!$A$45:$A$51, $A15, 'Thermonix Grader #2'!$C$45:$C$51) -> 0 | E15: =COUNTIFS('Thermonix Grader #2'!$A$2:$A$44, $A15, 'Thermonix Grader #2'!$C$2:$C$44,0) -> 2 | F15: =IFERROR(C15 / (C15 + D15), "Not Available") -> 1 | G15: =IFERROR(C15 / B15, "Not Available") -> 0.81818182 | H15: =IFERROR(2*((F15*G15)/(F15+G15)),"Not Available") -> 0.9
A16: Transition | B16: =COUNTIF(Thermonix!$A$2:$A$44, A16) -> 17 | C16: =SUMIF('Thermonix Grader #2'!$A$2:$A$44, $A16, 'Thermonix Grader #2'!$C$2:$C$44) -> 14 | D16: =SUMIF('Thermonix Grader #2'!$A$45:$A$51, $A16, 'Thermonix Grader #2'!$C$45:$C$51) -> 0 | E16: =COUNTIFS('Thermonix Grader #2'!$A$2:$A$44, $A16, 'Thermonix Grader #2'!$C$2:$C$44,0) -> 2 | F16: =IFERROR(C16 / (C16 + D16), "Not Available") -> 1 | G16: =IFERROR(C16 / B16, "Not Available") -> 0.82352941 | H16: =IFERROR(2*((F16*G16)/(F16+G16)),"Not Available") -> 0.90322581
A17: Action | B17: =COUNTIF(Thermonix!$A$2:$A$44, A17) -> 6 | C17: =SUMIF('Thermonix Grader #2'!$A$2:$A$44, $A17, 'Thermonix Grader #2'!$C$2:$C$44) -> 1 | D17: =SUMIF('Thermonix Grader #2'!$A$45:$A$51, $A17, 'Thermonix Grader #2'!$C$45:$C$51) -> 0 | E17: =COUNTIFS('Thermonix Grader #2'!$A$2:$A$44, $A17, 'Thermonix Grader #2'!$C$2:$C$44,0) -> 5 | F17: =IFERROR(C17 / (C17 + D17), "Not Available") -> 1 | G17: =IFERROR(C17 / B17, "Not Available") -> 0.16666667 | H17: =IFERROR(2*((F17*G17)/(F17+G17)),"Not Available") -> 0.28571429
A18: Region | B18: =COUNTIF(Thermonix!$A$2:$A$44, A18) -> 0 | C18: =SUMIF('Thermonix Grader #2'!$A$2:$A$44, $A18, 'Thermonix Grader #2'!$C$2:$C$44) -> 0 | D18: =SUMIF('Thermonix Grader #2'!$A$45:$A$51, $A18, 'Thermonix Grader #2'!$C$45:$C$51) -> 0 | E18: =COUNTIFS('Thermonix Grader #2'!$A$2:$A$44, $A18, 'Thermonix Grader #2'!$C$2:$C$44,0) -> 0 | F18: =IFERROR(C18 / (C18 + D18), "Not Available") -> Not Available | G18: =IFERROR(C18 / B18, "Not Available") -> Not Available | H18: =IFERROR(2*((F18*G18)/(F18+G18)),"Not Available") -> Not Available
A19: History State | B19: =COUNTIF(Thermonix!$A$2:$A$44, A19) -> 1 | C19: =SUMIF('Thermonix Grader #2'!$A$2:$A$44, $A19, 'Thermonix Grader #2'!$C$2:$C$44) -> 0 | D19: =SUMIF('Thermonix Grader #2'!$A$45:$A$51, $A19, 'Thermonix Grader #2'!$C$45:$C$51) -> 0 | E19: =COUNTIFS('Thermonix Grader #2'!$A$2:$A$44, $A19, 'Thermonix Grader #2'!$C$2:$C$44,0) -> 1 | F19: =IFERROR(C19 / (C19 + D19), "Not Available") -> Not Available | G19: =IFERROR(C19 / B19, "Not Available") -> 0 | H19: =IFERROR(2*((F19*G19)/(F19+G19)),"Not Available") -> Not Available
A20: Guard | B20: =COUNTIF(Thermonix!$A$2:$A$44, A20) -> 7 | C20: =SUMIF('Thermonix Grader #2'!$A$2:$A$44, $A20, 'Thermonix Grader #2'!$C$2:$C$44) -> 3 | D20: =SUMIF('Thermonix Grader #2'!$A$45:$A$51, $A20, 'Thermonix Grader #2'!$C$45:$C$51) -> 0 | E20: =COUNTIFS('Thermonix Grader #2'!$A$2:$A$44, $A20, 'Thermonix Grader #2'!$C$2:$C$44,0) -> 4 | F20: =IFERROR(C20 / (C20 + D20), "Not Available") -> 1 | G20: =IFERROR(C20 / B20, "Not Available") -> 0.42857143 | H20: =IFERROR(2*((F20*G20)/(F20+G20)),"Not Available") -> 0.6
A21: Overall Score | B21: =SUM(B14:B20) -> 43 | C21: =SUM(C14:C20) -> 28 | D21: =SUM(D14:D20) -> 0 | E21: =SUM(E14:E20) -> 14 | F21: =IFERROR(C21 / (C21 + D21), "Not Available") -> 1 | G21: =IFERROR(C21 / B21, "Not Available") -> 0.65116279 | H21: =IFERROR(2*((F21*G21)/(F21+G21)),"Not Available") -> 0.78873239

Sheet Inter-rater
A1: Type | B1: Element | C1: Rater1 | D1: Rater2 | F1: Confusion Matrix | L1: Cohen's Kappa
A2: =Thermonix!A2 -> State | B2: =Thermonix!B2 -> initial state (⇒ TransportationMode) | C2: ='Thermonix Grader #1'!C2 -> 1 | D2: ='Thermonix Grader #2'!C2 -> 1 | F2: Global | G2: 0 | H2: 0.5 | I2: 1 | J2: Row Totals | L2: Metric | M2: Value | N2: Note
A3: =Thermonix!A3 -> State | B3: =Thermonix!B3 -> TransportationMode | C3: ='Thermonix Grader #1'!C3 -> 1 | D3: ='Thermonix Grader #2'!C3 -> 1 | F3: 0 | G3: =COUNTIFS($C$2:$C$88, $F3, $D$2:$D$88, G$2) -> 20 | H3: =COUNTIFS($C$2:$C$44, $F3, $D$2:$D$44, H$2) -> 1 | I3: =COUNTIFS($C$2:$C$44, $F3, $D$2:$D$44, I$2)+MAX(D45-C45,0)+MAX(D46-C46,0)+MAX(D47-C47,0)+MAX(D48-C48,0)+MAX(D49-C49,0)+MAX(D50-C50,0)+MAX(D51-C51,0) -> 1 | J3: =SUM(G3:I3) -> 22 | L3: Observed Agreement (Po) | M3: =(G3+H4+I5)/COUNTA($C$2:$C$98) -> 0.9 | N3: This sums the diagonal of your matrix divided by total rows.
A4: =Thermonix!A4 -> Transition | B4: =Thermonix!B4 -> selectorPressed (TransportationMode ⇒ On) | C4: ='Thermonix Grader #1'!C4 -> 1 | D4: ='Thermonix Grader #2'!C4 -> 1 | F4: 0.5 | G4: =COUNTIFS($C$2:$C$44, $F4, $D$2:$D$44, G$2) -> 1 | H4: =COUNTIFS($C$2:$C$44, $F4, $D$2:$D$44, H$2) -> 0 | I4: =COUNTIFS($C$2:$C$44, $F4, $D$2:$D$44, I$2) -> 1 | J4: =SUM(G4:I4) -> 2 | L4: Expected Agreement (Pe) | M4: {=SUMPRODUCT(J3:J5/COUNTA($C$2:$C$98), TRANSPOSE(G6:I6)/COUNTA($C$2:$C$98))} -> 0.4672 | N4: This computes the sum of row proportion times column proportion.
A5: =Thermonix!A5 -> State | B5: =Thermonix!B5 -> PreparingOff | C5: ='Thermonix Grader #1'!C5 -> 1 | D5: ='Thermonix Grader #2'!C5 -> 1 | F5: 1 | G5: =COUNTIFS($C$2:$C$44, $F5, $D$2:$D$44, G$2)+MAX(C45-D45,0)+MAX(C46-D46,0)+MAX(C47-D47,0)+MAX(C48-D48,0)+MAX(C49-D49,0)+MAX(C50-D50,0)+MAX(C51-D51,0) -> 0 | H5: =COUNTIFS($C$2:$C$44, $F5, $D$2:$D$44, H$2) -> 1 | I5: =COUNTIFS($C$2:$C$44, $F5, $D$2:$D$44, I$2)+ SUM(MIN(C45,D45), MIN(C46,D46), MIN(C47,D47), MIN(C48,D48), MIN(C49,D49), MIN(C50,D50), MIN(C51,D51)) -> 25 | J5: =SUM(G5:I5) -> 26 | L5: Cohen's Kappa | M5: =(M3-M4)/(1-M4) -> 0.81231231 | N5: (Po - Pe) / (1 - Pe)
A6: =Thermonix!A6 -> Transition | B6: =Thermonix!B6 -> selectorReleased (PreparingOff ⇒ On) | C6: ='Thermonix Grader #1'!C6 -> 1 | D6: ='Thermonix Grader #2'!C6 -> 1 | F6: Column Totals | G6: =SUM(G3:G5) -> 21 | H6: =SUM(H3:H5) -> 2 | I6: =SUM(I3:I5) -> 27
A7: =Thermonix!A7 -> Transition | B7: =Thermonix!B7 -> after 5sec (PreparingOff ⇒ Off) | C7: ='Thermonix Grader #1'!C7 -> 1 | D7: ='Thermonix Grader #2'!C7 -> 1
A8: =Thermonix!A8 -> State | B8: =Thermonix!B8 -> Off | C8: ='Thermonix Grader #1'!C8 -> 1 | D8: ='Thermonix Grader #2'!C8 -> 1 | F8: Confusion Matrix (State) | L8: Cohen's Kappa (State)
A9: =Thermonix!A9 -> Transition | B9: =Thermonix!B9 -> selectorPressed (Off ⇒ On) | C9: ='Thermonix Grader #1'!C9 -> 1 | D9: ='Thermonix Grader #2'!C9 -> 1 | F9: State | G9: 0 | H9: 0.5 | I9: 1 | J9: Row Totals | L9: Metric | M9: Value | N9: Note
A10: =Thermonix!A10 -> Composite State | B10: =Thermonix!B10 -> On | C10: ='Thermonix Grader #1'!C10 -> 0 | D10: ='Thermonix Grader #2'!C10 -> 1 | F10: 0.5 | G10: =COUNTIFS($A$2:$A$88,$F$9,$C$2:$C$88,$F10,$D$2:$D$88,G$9) -> 0 | H10: =COUNTIFS($A$2:$A$88,$F$9,$C$2:$C$88,$F10,$D$2:$D$88,H$9) -> 0 | I10: =COUNTIFS($A$2:$A$88,$F$9,$C$2:$C$88,$F10,$D$2:$D$88,I$9) -> 0 | J10: =SUM(G10:I10) -> 0 | L10: Expected Agreement (Pe) | M10: {=SUMPRODUCT(J10:J11/COUNTIF($A$2:$A$98,F9), TRANSPOSE(G12:I12)/COUNTIF($A$2:$A$98,F9))} -> #VALUE! | N10: This computes the sum of row proportion times column proportion.
A11: =Thermonix!A11 -> History State | B11: =Thermonix!B11 -> History State for On | C11: ='Thermonix Grader #1'!C11 -> 0 | D11: ='Thermonix Grader #2'!C11 -> 0 | F11: 1 | G11: =COUNTIFS($A$2:$A$44,$F$9,$C$2:$C$44,$F11,$D$2:$D$44,G$9)+MAX(C45-D45,0) -> 0 | H11: =COUNTIFS($A$2:$A$88,$F$9,$C$2:$C$88,$F11,$D$2:$D$88,H$9) -> 0 | I11: =COUNTIFS($A$2:$A$44,$F$9,$C$2:$C$44,$F11,$D$2:$D$44,I$9)+MIN(C45-D45) -> 9 | J11: =SUM(G11:I11) -> 9 | L11: Cohen's Kappa | M11: =(#REF!-M10)/(1-M10) -> #REF! | N11: (Po - Pe) / (1 - Pe)
A12: =Thermonix!A12 -> Transition | B12: =Thermonix!B12 -> selectorHeld (On ⇒ PreparingOff) | C12: ='Thermonix Grader #1'!C12 -> 1 | D12: ='Thermonix Grader #2'!C12 -> 0.5 | F12: Column Totals | G12: =SUM(G10:G11) -> 0 | H12: =SUM(H10:H11) -> 0 | I12: =SUM(I10:I11) -> 9
A13: =Thermonix!A13 -> Transition | B13: =Thermonix!B13 -> bowlRemoved (On ⇒ On) | C13: ='Thermonix Grader #1'!C13 -> 1 | D13: ='Thermonix Grader #2'!C13 -> 1
A14: =Thermonix!A14 -> State | B14: =Thermonix!B14 -> Initial State (On ⇒ Home) | C14: ='Thermonix Grader #1'!C14 -> 0 | D14: ='Thermonix Grader #2'!C14 -> 0 | F14: Confusion Matrix (Transition) | L14: Cohen's Kappa (Transition)
A15: =Thermonix!A15 -> State | B15: =Thermonix!B15 -> Home | C15: ='Thermonix Grader #1'!C15 -> 1 | D15: ='Thermonix Grader #2'!C15 -> 1 | F15: Transition | G15: 0 | H15: 0.5 | I15: 1 | J15: Row Totals | L15: Metric | M15: Value | N15: Note
A16: =Thermonix!A16 -> Transition | B16: =Thermonix!B16 -> after 14min 30sec (Home ⇒ Preparing Shutdown) | C16: ='Thermonix Grader #1'!C16 -> 1 | D16: ='Thermonix Grader #2'!C16 -> 1 | F16: 0 | G16: =COUNTIFS($A$2:$A$88,$F$15,$C$2:$C$88,$F16,$D$2:$D$88,G$15) -> 3 | H16: =COUNTIFS($A$2:$A$88,$F$15,$C$2:$C$88,$F16,$D$2:$D$88,H$15) -> 1 | I16: =COUNTIFS($A$2:$A$44,$F$15,$C$2:$C$44,$F16,$D$2:$D$44,I$15) + MAX(D46-C46,0) -> 0 | J16: =SUM(G16:I16) -> 4 | L16: Observed Agreement (Po) | M16: =(G16+H17+I18)/COUNTIF($A$2:$A$98,F15) -> 0.88888889 | N16: This sums the diagonal of your matrix divided by total rows.
A17: =Thermonix!A17 -> Transition | B17: =Thermonix!B17 -> start (Home ⇒ PromptToAdd) | C17: ='Thermonix Grader #1'!C17 -> 1 | D17: ='Thermonix Grader #2'!C17 -> 1 | F17: 0.5 | G17: =COUNTIFS($A$2:$A$88,$F$15,$C$2:$C$88,$F17,$D$2:$D$88,G$15) -> 0 | H17: =COUNTIFS($A$2:$A$88,$F$15,$C$2:$C$88,$F17,$D$2:$D$88,H$15) -> 0 | I17: =COUNTIFS($A$2:$A$88,$F$15,$C$2:$C$88,$F17,$D$2:$D$88,I$15) -> 0 | J17: =SUM(G17:I17) -> 0 | L17: Expected Agreement (Pe) | M17: {=SUMPRODUCT(J16:J18/COUNTIF($A$2:$A$98,F15), TRANSPOSE(G19:I19)/COUNTIF($A$2:$A$98,F15))} -> 0.59876543 | N17: This computes the sum of row proportion times column proportion.
A18: =Thermonix!A18 -> Guard | B18: =Thermonix!B18 -> [!bowlRemoved()] | C18: ='Thermonix Grader #1'!C18 -> 1 | D18: ='Thermonix Grader #2'!C18 -> 1 | F18: 1 | G18: =COUNTIFS($A$2:$A$44,$F$15,$C$2:$C$44,$F18,$D$2:$D$44,G$15)+MAX(C46-D46,0) -> 0 | H18: =COUNTIFS($A$2:$A$88,$F$15,$C$2:$C$88,$F18,$D$2:$D$88,H$15) -> 1 | I18: =COUNTIFS($A$2:$A$44,$F$15,$C$2:$C$44,$F18,$D$2:$D$44,I$15) + MIN(C46,D46) -> 13 | J18: =SUM(G18:I18) -> 14 | L18: Cohen's Kappa | M18: =(M16-M17)/(1-M17) -> 0.72307692 | N18: (Po - Pe) / (1 - Pe)
A19: =Thermonix!A19 -> Action | B19: =Thermonix!B19 -> setIngredients() | C19: ='Thermonix Grader #1'!C19 -> 1 | D19: ='Thermonix Grader #2'!C19 -> 1 | F19: Column Totals | G19: =SUM(G16:G18) -> 3 | H19: =SUM(H16:H18) -> 2 | I19: =SUM(I16:I18) -> 13
A20: =Thermonix!A20 -> State | B20: =Thermonix!B20 -> Preparing Shutdown | C20: ='Thermonix Grader #1'!C20 -> 1 | D20: ='Thermonix Grader #2'!C20 -> 1
A21: =Thermonix!A21 -> Transition | B21: =Thermonix!B21 -> after 30sec (Preparing Shutdown ⇒ Off) | C21: ='Thermonix Grader #1'!C21 -> 1 | D21: ='Thermonix Grader #2'!C21 -> 1 | F21: Confusion Matrix (Composite State) | L21: Cohen's Kappa (Composite State)
A22: =Thermonix!A22 -> Transition | B22: =Thermonix!B22 -> cancel (Preparing Shutdown ⇒ Home) | C22: ='Thermonix Grader #1'!C22 -> 1 | D22: ='Thermonix Grader #2'!C22 -> 1 | F22: Composite State | G22: 0 | H22: 0.5 | I22: 1 | J22: Row Totals | L22: Metric | M22: Value | N22: Note
A23: =Thermonix!A23 -> State | B23: =Thermonix!B23 -> PromptToAdd | C23: ='Thermonix Grader #1'!C23 -> 0 | D23: ='Thermonix Grader #2'!C23 -> 0 | F23: 0 | G23: =COUNTIFS($A$2:$A$88,$F$22,$C$2:$C$88,$F23,$D$2:$D$88,G$22) -> 1 | H23: =COUNTIFS($A$2:$A$88,$F$22,$C$2:$C$88,$F23,$D$2:$D$88,H$22) -> 0 | I23: =COUNTIFS($A$2:$A$44,$F$22,$C$2:$C$44,$F23,$D$2:$D$44,I$22) + MAX(D49-C49,0) -> 1 | J23: =SUM(G23:I23) -> 2 | L23: Observed Agreement (Po) | M23: =(G23+H24+I25)/COUNTIF($A$2:$A$98,F22) -> 0.5 | N23: This sums the diagonal of your matrix divided by total rows.
A24: =Thermonix!A24 -> Transition | B24: =Thermonix!B24 -> next (PromptToAdd ⇒ PromptToAdd) | C24: ='Thermonix Grader #1'!C24 -> 0 | D24: ='Thermonix Grader #2'!C24 -> 0 | F24: 0.5 | G24: =COUNTIFS($A$2:$A$88,$F$22,$C$2:$C$88,$F24,$D$2:$D$88,G$22) -> 0 | H24: =COUNTIFS($A$2:$A$88,$F$22,$C$2:$C$88,$F24,$D$2:$D$88,H$22) -> 0 | I24: =COUNTIFS($A$2:$A$88,$F$22,$C$2:$C$88,$F24,$D$2:$D$88,I$22) -> 0 | J24: =SUM(G24:I24) -> 0 | L24: Expected Agreement (Pe) | M24: {=SUMPRODUCT(J23:J25/COUNTIF($A$2:$A$98,F22), TRANSPOSE(#REF!)/COUNTIF($A$2:$A$98,F22))} -> #REF! | N24: This computes the sum of row proportion times column proportion.
A25: =Thermonix!A25 -> Guard | B25: =Thermonix!B25 -> [weightCorrect() && moreIngredientsRequired()] | C25: ='Thermonix Grader #1'!C25 -> 0 | D25: ='Thermonix Grader #2'!C25 -> 0 | F25: 1 | G25: =COUNTIFS($A$2:$A$44,$F$22,$C$2:$C$44,$F25,$D$2:$D$44,G$22) + MAX(C49-D49,0) -> 0 | H25: =COUNTIFS($A$2:$A$88,$F$22,$C$2:$C$88,$F25,$D$2:$D$88,H$22) -> 0 | I25: =COUNTIFS($A$2:$A$44,$F$22,$C$2:$C$44,$F25,$D$2:$D$44,I$22) + MIN(C49,D49) -> 0 | J25: =SUM(G25:I25) -> 0 | L25: Cohen's Kappa | M25: =(M23-M24)/(1-M24) -> #REF! | N25: (Po - Pe) / (1 - Pe)
A26: =Thermonix!A26 -> Action | B26: =Thermonix!B26 -> setIngredients() | C26: ='Thermonix Grader #1'!C26 -> 0 | D26: ='Thermonix Grader #2'!C26 -> 0
A27: =Thermonix!A27 -> Transition | B27: =Thermonix!B27 -> next (PromptToAdd ⇒ Chop) | C27: ='Thermonix Grader #1'!C27 -> 1 | D27: ='Thermonix Grader #2'!C27 -> 1 | F27: Confusion Matrix (Guard) | L27: Cohen's Kappa (Guard)
A28: =Thermonix!A28 -> Guard | B28: =Thermonix!B28 -> [weightCorrect() && !moreIngredientsRequired()] | C28: ='Thermonix Grader #1'!C28 -> 0.5 | D28: ='Thermonix Grader #2'!C28 -> 0 | F28: Guard | G28: 0 | H28: 0.5 | I28: 1 | J28: Row Totals | L28: Metric | M28: Value | N28: Note
A29: =Thermonix!A29 -> Action | B29: =Thermonix!B29 -> setChoppingSpeedAndTime() | C29: ='Thermonix Grader #1'!C29 -> 0 | D29: ='Thermonix Grader #2'!C29 -> 0 | F29: 0 | G29: =COUNTIFS($A$2:$A$88,$F$28,$C$2:$C$88,$F29,$D$2:$D$88,G$28) -> 4 | H29: =COUNTIFS($A$2:$A$88,$F$28,$C$2:$C$88,$F29,$D$2:$D$88,H$28) -> 0 | I29: =COUNTIFS($A$2:$A$44,$F$28,$C$2:$C$44,$F29,$D$2:$D$44,I$28) + MAX(D47-C47,0) -> 0 | J29: =SUM(G29:I29) -> 4 | L29: Observed Agreement (Po) | M29: =(G29+H30+I31)/COUNTIF($A$2:$A$98,F28) -> 0.75 | N29: This sums the diagonal of your matrix divided by total rows.
A30: =Thermonix!A30 -> State | B30: =Thermonix!B30 -> Chop | C30: ='Thermonix Grader #1'!C30 -> 1 | D30: ='Thermonix Grader #2'!C30 -> 1 | F30: 0.5 | G30: =COUNTIFS($A$2:$A$88,$F$28,$C$2:$C$88,$F30,$D$2:$D$88,G$28) -> 1 | H30: =COUNTIFS($A$2:$A$88,$F$28,$C$2:$C$88,$F30,$D$2:$D$88,H$28) -> 0 | I30: =COUNTIFS($A$2:$A$88,$F$28,$C$2:$C$88,$F30,$D$2:$D$88,I$28) -> 1 | J30: =SUM(G30:I30) -> 2 | L30: Expected Agreement (Pe) | M30: {=SUMPRODUCT(J29:J31/COUNTIF($A$2:$A$98,F28), TRANSPOSE(G32:I32)/COUNTIF($A$2:$A$98,F28))} -> 0.40625 | N30: This computes the sum of row proportion times column proportion.
A31: =Thermonix!A31 -> Transition | B31: =Thermonix!B31 -> next (Chop ⇒ PromptToAdd) | C31: ='Thermonix Grader #1'!C31 -> 0 | D31: ='Thermonix Grader #2'!C31 -> 0 | F31: 1 | G31: =COUNTIFS($A$2:$A$44,$F$28,$C$2:$C$44,$F31,$D$2:$D$44,G$28) + MAX(C47-D47,0) -> 0 | H31: =COUNTIFS($A$2:$A$88,$F$28,$C$2:$C$88,$F31,$D$2:$D$88,H$28) -> 0 | I31: =COUNTIFS($A$2:$A$44,$F$28,$C$2:$C$44,$F31,$D$2:$D$44,I$28) + MIN(C47,D47) -> 2 | J31: =SUM(G31:I31) -> 2 | L31: Cohen's Kappa | M31: =(M29-M30)/(1-M30) -> 0.57894737 | N31: (Po - Pe) / (1 - Pe)
A32: =Thermonix!A32 -> Guard | B32: =Thermonix!B32 -> [choppingTimeDone && moreIngredientsRequired()] | C32: ='Thermonix Grader #1'!C32 -> 0 | D32: ='Thermonix Grader #2'!C32 -> 0 | F32: Column Totals | G32: =SUM(G29:G31) -> 5 | H32: =SUM(H29:H31) -> 0 | I32: =SUM(I29:I31) -> 3
A33: =Thermonix!A33 -> Action | B33: =Thermonix!B33 -> setIngredients() | C33: ='Thermonix Grader #1'!C33 -> 0 | D33: ='Thermonix Grader #2'!C33 -> 0
A34: =Thermonix!A34 -> Transition | B34: =Thermonix!B34 -> next (Chop ⇒ Cook) | C34: ='Thermonix Grader #1'!C34 -> 1 | D34: ='Thermonix Grader #2'!C34 -> 1 | F34: Confusion Matrix (Action) | L34: Cohen's Kappa (Action)
A35: =Thermonix!A35 -> Guard | B35: =Thermonix!B35 -> [choppingTimeDone && !moreIngredientsRequired()] | C35: ='Thermonix Grader #1'!C35 -> 0 | D35: ='Thermonix Grader #2'!C35 -> 0 | F35: Action | G35: 0 | H35: 0.5 | I35: 1 | J35: Row Totals | L35: Metric | M35: Value | N35: Note
A36: =Thermonix!A36 -> Action | B36: =Thermonix!B36 -> setCookingSpeedAndTime() | C36: ='Thermonix Grader #1'!C36 -> 0 | D36: ='Thermonix Grader #2'!C36 -> 0 | F36: 0 | G36: =COUNTIFS($A$2:$A$88,$F$35,$C$2:$C$88,$F36,$D$2:$D$88,G$35) -> 6 | H36: =COUNTIFS($A$2:$A$88,$F$35,$C$2:$C$88,$F36,$D$2:$D$88,H$35) -> 0 | I36: =COUNTIFS($A$2:$A$44,$F$35,$C$2:$C$44,$F36,$D$2:$D$44,I$35)+MAX(D48-C48,0) -> 0 | J36: =SUM(G36:I36) -> 6 | L36: Observed Agreement (Po) | M36: =(G36+H37+I38)/COUNTIF($A$2:$A$98,F35) -> 1 | N36: This sums the diagonal of your matrix divided by total rows.
A37: =Thermonix!A37 -> State | B37: =Thermonix!B37 -> Cook | C37: ='Thermonix Grader #1'!C37 -> 1 | D37: ='Thermonix Grader #2'!C37 -> 1 | F37: 0.5 | G37: =COUNTIFS($A$2:$A$88,$F$35,$C$2:$C$88,$F37,$D$2:$D$88,G$35) -> 0 | H37: =COUNTIFS($A$2:$A$88,$F$35,$C$2:$C$88,$F37,$D$2:$D$88,H$35) -> 0 | I37: =COUNTIFS($A$2:$A$88,$F$35,$C$2:$C$88,$F37,$D$2:$D$88,I$35) -> 0 | J37: =SUM(G37:I37) -> 0 | L37: Expected Agreement (Pe) | M37: {=SUMPRODUCT(J36:J38/COUNTIF($A$2:$A$98,F35), TRANSPOSE(G39:I39)/COUNTIF($A$2:$A$98,F35))} -> 0.75510204 | N37: This computes the sum of row proportion times column proportion.
A38: =Thermonix!A38 -> Transition | B38: =Thermonix!B38 -> after choppingTime (Cook ⇒ PromptToAdd) | C38: ='Thermonix Grader #1'!C38 -> 1 | D38: ='Thermonix Grader #2'!C38 -> 1 | F38: 1 | G38: =COUNTIFS($A$2:$A$44,$F$35,$C$2:$C$44,$F38,$D$2:$D$44,G$35)+MAX(C48-D48,0) -> 0 | H38: =COUNTIFS($A$2:$A$88,$F$35,$C$2:$C$88,$F38,$D$2:$D$88,H$35) -> 0 | I38: =COUNTIFS($A$2:$A$44,$F$35,$C$2:$C$44,$F38,$D$2:$D$44,I$35) + MIN(C48,D48) -> 1 | J38: =SUM(G38:I38) -> 1 | L38: Cohen's Kappa | M38: =(M36-M37)/(1-M37) -> 1 | N38: (Po - Pe) / (1 - Pe)
A39: =Thermonix!A39 -> Guard | B39: =Thermonix!B39 -> [choppingTimeDone && moreIngredientsRequired()] | C39: ='Thermonix Grader #1'!C39 -> 0.5 | D39: ='Thermonix Grader #2'!C39 -> 1 | F39: Column Totals | G39: =SUM(G36:G38) -> 6 | H39: =SUM(H36:H38) -> 0 | I39: =SUM(I36:I38) -> 1
A40: =Thermonix!A40 -> Action | B40: =Thermonix!B40 -> setIngredients() | C40: ='Thermonix Grader #1'!C40 -> 0 | D40: ='Thermonix Grader #2'!C40 -> 0
...

Sheet Weighted Cohens Kappa
A1: Type | B1: Element | C1: Rater 1 | D1: Rater 2 | F1: Confusion Matrix | L1: Weight Matrix
A2: =Thermonix!A2 -> State | B2: =Thermonix!B2 -> initial state (⇒ TransportationMode) | C2: ='Thermonix Grader #1'!C2 -> 1 | D2: ='Thermonix Grader #2'!C2 -> 1 | F2: Global | G2: 0 | H2: 0.5 | I2: 1 | J2: Row Totals | L2: Global | M2: 0 | N2: 0.5 | O2: 1 | Q2: Global | R2: 0 | S2: 0.5 | T2: 1 | V2: Metric | W2: Value | X2: Note
A3: =Thermonix!A3 -> State | B3: =Thermonix!B3 -> TransportationMode | C3: ='Thermonix Grader #1'!C3 -> 1 | D3: ='Thermonix Grader #2'!C3 -> 1 | F3: 0 | G3: =COUNTIFS($C$2:$C$89, $F3, $D$2:$D$89, G$2) -> 20 | H3: =COUNTIFS($C$2:$C$45, $F3, $D$2:$D$45, H$2) -> 1 | I3: =COUNTIFS($C$2:$C$45, $F3, $D$2:$D$45, I$2)+MAX(D46-C46,0)+MAX(D47-C47,0)+MAX(D48-C48,0)+MAX(D49-C49,0)+MAX(D50-C50,0)+MAX(D51-C51,0)+MAX(D52-C52,0) -> 1 | J3: =SUM(G3:I3) -> 22 | L3: 0 | M3: =ABS(G$2-$F3)/1 -> 0 | N3: =ABS(H$2-$F3)/1 -> 0.5 | O3: =ABS(I$2-$F3)/1 -> 1 | Q3: 0 | R3: =($J3/$J$6) * (G$6/$J$6) -> 0.1848 | S3: =($J3/$J$6) * (H$6/$J$6) -> 0.0176 | T3: =($J3/$J$6) * (I$6/$J$6) -> 0.2376 | V3: Observed Weighted Disagreement (D_obs) | W3: =SUMPRODUCT(G3:I5, M3:O5) /$J$6 -> 0.06 | X3: Sum of (confusion-matrix counts × weights) divided by total items.
A4: =Thermonix!A4 -> Transition | B4: =Thermonix!B4 -> selectorPressed (TransportationMode ⇒ On) | C4: ='Thermonix Grader #1'!C4 -> 1 | D4: ='Thermonix Grader #2'!C4 -> 1 | F4: 0.5 | G4: =COUNTIFS($C$2:$C$45, $F4, $D$2:$D$45, G$2) -> 1 | H4: =COUNTIFS($C$2:$C$45, $F4, $D$2:$D$45, H$2) -> 0 | I4: =COUNTIFS($C$2:$C$45, $F4, $D$2:$D$45, I$2) -> 1 | J4: =SUM(G4:I4) -> 2 | L4: 0.5 | M4: =ABS(G$2-$F4)/1 -> 0.5 | N4: =ABS(H$2-$F4)/3 -> 0 | O4: =ABS(I$2-$F4)/1 -> 0.5 | Q4: 0.5 | R4: =($J4/$J$6) * (G$6/$J$6) -> 0.0168 | S4: =($J4/$J$6) * (H$6/$J$6) -> 0.0016 | T4: =($J4/$J$6) * (I$6/$J$6) -> 0.0216 | V4: Expected Weighted Disagreement (D_exp) | W4: =SUMPRODUCT(R3:T5, M3:O5) -> 0.4944 | X4: Sum of (expected cell proportions × weights) under chance agreement.
A5: =Thermonix!A5 -> State | B5: =Thermonix!B5 -> PreparingOff | C5: ='Thermonix Grader #1'!C5 -> 1 | D5: ='Thermonix Grader #2'!C5 -> 1 | F5: 1 | G5: =COUNTIFS($C$2:$C$45, $F5, $D$2:$D$45, G$2)+MAX(C46-D46,0)+MAX(C47-D47,0)+MAX(C48-D48,0)+MAX(C49-D49,0)+MAX(C50-D50,0)+MAX(C51-D51,0)+MAX(C52-D52,0) -> 0 | H5: =COUNTIFS($C$2:$C$45, $F5, $D$2:$D$45, H$2) -> 1 | I5: =COUNTIFS($C$2:$C$45, $F5, $D$2:$D$45, I$2)+ SUM(MIN(C46,D46), MIN(C47,D47), MIN(C48,D48), MIN(C49,D49), MIN(C50,D50), MIN(C51,D51), MIN(C52,D52)) -> 25 | J5: =SUM(G5:I5) -> 26 | L5: 1 | M5: =ABS(G$2-$F5)/1 -> 1 | N5: =ABS(H$2-$F5)/1 -> 0.5 | O5: =ABS(I$2-$F5)/1 -> 0 | Q5: 1 | R5: =($J5/$J$6) * (G$6/$J$6) -> 0.2184 | S5: =($J5/$J$6) * (H$6/$J$6) -> 0.0208 | T5: =($J5/$J$6) * (I$6/$J$6) -> 0.2808 | V5: Cohen's Kappa | W5: =1-W3/W4 -> 0.87864078 | X5: 1 - (D_obs / D_exp)
A6: =Thermonix!A6 -> Transition | B6: =Thermonix!B6 -> selectorReleased (PreparingOff ⇒ On) | C6: ='Thermonix Grader #1'!C6 -> 1 | D6: ='Thermonix Grader #2'!C6 -> 1 | F6: Column Totals | G6: =SUM(G3:G5) -> 21 | H6: =SUM(H3:H5) -> 2 | I6: =SUM(I3:I5) -> 27 | J6: =SUM(G3:I5) -> 50
A7: =Thermonix!A7 -> Transition | B7: =Thermonix!B7 -> after 5sec (PreparingOff ⇒ Off) | C7: ='Thermonix Grader #1'!C7 -> 1 | D7: ='Thermonix Grader #2'!C7 -> 1
A8: =Thermonix!A8 -> State | B8: =Thermonix!B8 -> Off | C8: ='Thermonix Grader #1'!C8 -> 1 | D8: ='Thermonix Grader #2'!C8 -> 1 | F8: Confusion Matrix (State)
A9: =Thermonix!A9 -> Transition | B9: =Thermonix!B9 -> selectorPressed (Off ⇒ On) | C9: ='Thermonix Grader #1'!C9 -> 1 | D9: ='Thermonix Grader #2'!C9 -> 1 | F9: State | G9: 0 | H9: 0.5 | I9: 1 | J9: Row Totals | L9: Global | M9: 0 | N9: 0.5 | O9: 1 | Q9: Global | R9: 0 | S9: 0.5 | T9: 1 | V9: Metric | W9: Value | X9: Note
A10: =Thermonix!A10 -> Composite State | B10: =Thermonix!B10 -> On | C10: ='Thermonix Grader #1'!C10 -> 0 | D10: ='Thermonix Grader #2'!C10 -> 1 | F10: 0.5 | G10: =COUNTIFS($A$2:$A$89,$F$9,$C$2:$C$89,$F10,$D$2:$D$89,G$9) -> 0 | H10: =COUNTIFS($A$2:$A$89,$F$9,$C$2:$C$89,$F10,$D$2:$D$89,H$9) -> 0 | I10: =COUNTIFS($A$2:$A$89,$F$9,$C$2:$C$89,$F10,$D$2:$D$89,I$9) -> 0 | J10: =SUM(G10:I10) -> 0 | L10: 0.5 | M10: =ABS(G$2-$F10)/1 -> 0.5 | N10: =ABS(H$2-$F10)/3 -> 0 | O10: =ABS(I$2-$F10)/1 -> 0.5 | Q10: 0.5 | R10: =($J10/$J$12) * (G$12/$J$12) -> 0 | S10: =($J10/$J$12) * (H$12/$J$12) -> 0 | T10: =($J10/$J$12) * (I$12/$J$12) -> 0 | V10: Expected Weighted Disagreement (D_exp) | W10: =SUMPRODUCT(R10:T11, M10:O11) -> 0 | X10: Sum of (expected cell proportions × weights) under chance agreement.
A11: =Thermonix!A11 -> History State | B11: =Thermonix!B11 -> History State for On | C11: ='Thermonix Grader #1'!C11 -> 0 | D11: ='Thermonix Grader #2'!C11 -> 0 | F11: 1 | G11: =COUNTIFS($A$2:$A$45,$F$9,$C$2:$C$45,$F11,$D$2:$D$45,G$9)+MAX(C46-D46,0) -> 0 | H11: =COUNTIFS($A$2:$A$89,$F$9,$C$2:$C$89,$F11,$D$2:$D$89,H$9) -> 0 | I11: =COUNTIFS($A$2:$A$45,$F$9,$C$2:$C$45,$F11,$D$2:$D$45,I$9)+MIN(C46-D46) -> 9 | J11: =SUM(G11:I11) -> 9 | L11: 1 | M11: =ABS(G$2-$F11)/1 -> 1 | N11: =ABS(H$2-$F11)/1 -> 0.5 | O11: =ABS(I$2-$F11)/1 -> 0 | Q11: 1 | R11: =($J11/$J$12) * (G$12/$J$12) -> 0 | S11: =($J11/$J$12) * (H$12/$J$12) -> 0 | T11: =($J11/$J$12) * (I$12/$J$12) -> 1 | V11: Cohen's Kappa | W11: =1-#REF!/W10 -> #REF! | X11: 1 - (D_obs / D_exp)
A12: =Thermonix!A12 -> Transition | B12: =Thermonix!B12 -> selectorHeld (On ⇒ PreparingOff) | C12: ='Thermonix Grader #1'!C12 -> 1 | D12: ='Thermonix Grader #2'!C12 -> 0.5 | F12: Column Totals | G12: =SUM(G10:G11) -> 0 | H12: =SUM(H10:H11) -> 0 | I12: =SUM(I10:I11) -> 9 | J12: =SUM(G10:I11) -> 9
A13: =Thermonix!A13 -> Transition | B13: =Thermonix!B13 -> bowlRemoved (On ⇒ On) | C13: ='Thermonix Grader #1'!C13 -> 1 | D13: ='Thermonix Grader #2'!C13 -> 1
A14: =Thermonix!A14 -> State | B14: =Thermonix!B14 -> Initial State (On ⇒ Home) | C14: ='Thermonix Grader #1'!C14 -> 0 | D14: ='Thermonix Grader #2'!C14 -> 0 | F14: Confusion Matrix (Transition)
A15: =Thermonix!A15 -> State | B15: =Thermonix!B15 -> Home | C15: ='Thermonix Grader #1'!C15 -> 1 | D15: ='Thermonix Grader #2'!C15 -> 1 | F15: Transition | G15: 0 | H15: 0.5 | I15: 1 | J15: Row Totals | L15: Global | M15: 0 | N15: 0.5 | O15: 1 | Q15: Global | R15: 0 | S15: 0.5 | T15: 1 | V15: Metric | W15: Value | X15: Note
A16: =Thermonix!A16 -> Transition | B16: =Thermonix!B16 -> after 14min 30sec (Home ⇒ Preparing Shutdown) | C16: ='Thermonix Grader #1'!C16 -> 1 | D16: ='Thermonix Grader #2'!C16 -> 1 | F16: 0 | G16: =COUNTIFS($A$2:$A$89,$F$15,$C$2:$C$89,$F16,$D$2:$D$89,G$15) -> 3 | H16: =COUNTIFS($A$2:$A$89,$F$15,$C$2:$C$89,$F16,$D$2:$D$89,H$15) -> 1 | I16: =COUNTIFS($A$2:$A$45,$F$15,$C$2:$C$45,$F16,$D$2:$D$45,I$15) + MAX(D47-C47,0) -> 0 | J16: =SUM(G16:I16) -> 4 | L16: 0 | M16: =ABS(G$2-$F16)/1 -> 0 | N16: =ABS(H$2-$F16)/1 -> 0.5 | O16: =ABS(I$2-$F16)/1 -> 1 | Q16: 0 | R16: =($J16/$J$19) * (G$19/$J$19) -> 0.037037037 | S16: =($J16/$J$19) * (H$19/$J$19) -> 0.024691358 | T16: =($J16/$J$19) * (I$19/$J$19) -> 0.16049383 | V16: Observed Weighted Disagreement (D_obs) | W16: =SUMPRODUCT(G16:I18, M16:O18) /$J$19 -> 0.055555556 | X16: Sum of (confusion-matrix counts × weights) divided by total items.
A17: =Thermonix!A17 -> Transition | B17: =Thermonix!B17 -> start (Home ⇒ PromptToAdd) | C17: ='Thermonix Grader #1'!C17 -> 1 | D17: ='Thermonix Grader #2'!C17 -> 1 | F17: 0.5 | G17: =COUNTIFS($A$2:$A$89,$F$15,$C$2:$C$89,$F17,$D$2:$D$89,G$15) -> 0 | H17: =COUNTIFS($A$2:$A$89,$F$15,$C$2:$C$89,$F17,$D$2:$D$89,H$15) -> 0 | I17: =COUNTIFS($A$2:$A$89,$F$15,$C$2:$C$89,$F17,$D$2:$D$89,I$15) -> 0 | J17: =SUM(G17:I17) -> 0 | L17: 0.5 | M17: =ABS(G$2-$F17)/1 -> 0.5 | N17: =ABS(H$2-$F17)/3 -> 0 | O17: =ABS(I$2-$F17)/1 -> 0.5 | Q17: 0.5 | R17: =($J17/$J$19) * (G$19/$J$19) -> 0 | S17: =($J17/$J$19) * (H$19/$J$19) -> 0 | T17: =($J17/$J$19) * (I$19/$J$19) -> 0 | V17: Expected Weighted Disagreement (D_exp) | W17: =SUMPRODUCT(R16:T18, M16:O18) -> 0.34567901 | X17: Sum of (expected cell proportions × weights) under chance agreement.
A18: =Thermonix!A18 -> Guard | B18: =Thermonix!B18 -> [!bowlRemoved()] | C18: ='Thermonix Grader #1'!C18 -> 1 | D18: ='Thermonix Grader #2'!C18 -> 1 | F18: 1 | G18: =COUNTIFS($A$2:$A$45,$F$15,$C$2:$C$45,$F18,$D$2:$D$45,G$15)+MAX(C47-D47,0) -> 0 | H18: =COUNTIFS($A$2:$A$89,$F$15,$C$2:$C$89,$F18,$D$2:$D$89,H$15) -> 1 | I18: =COUNTIFS($A$2:$A$45,$F$15,$C$2:$C$45,$F18,$D$2:$D$45,I$15) + MIN(C47,D47) -> 13 | J18: =SUM(G18:I18) -> 14 | L18: 1 | M18: =ABS(G$2-$F18)/1 -> 1 | N18: =ABS(H$2-$F18)/1 -> 0.5 | O18: =ABS(I$2-$F18)/1 -> 0 | Q18: 1 | R18: =($J18/$J$19) * (G$19/$J$19) -> 0.12962963 | S18: =($J18/$J$19) * (H$19/$J$19) -> 0.086419753 | T18: =($J18/$J$19) * (I$19/$J$19) -> 0.5617284 | V18: Cohen's Kappa | W18: =1-W16/W17 -> 0.83928571 | X18: 1 - (D_obs / D_exp)
A19: =Thermonix!A19 -> Action | B19: =Thermonix!B19 -> setIngredients() | C19: ='Thermonix Grader #1'!C19 -> 1 | D19: ='Thermonix Grader #2'!C19 -> 1 | F19: Column Totals | G19: =SUM(G16:G18) -> 3 | H19: =SUM(H16:H18) -> 2 | I19: =SUM(I16:I18) -> 13 | J19: =SUM(G16:I18) -> 18
A20: =Thermonix!A20 -> State | B20: =Thermonix!B20 -> Preparing Shutdown | C20: ='Thermonix Grader #1'!C20 -> 1 | D20: ='Thermonix Grader #2'!C20 -> 1
A21: =Thermonix!A21 -> Transition | B21: =Thermonix!B21 -> after 30sec (Preparing Shutdown ⇒ Off) | C21: ='Thermonix Grader #1'!C21 -> 1 | D21: ='Thermonix Grader #2'!C21 -> 1 | F21: Confusion Matrix (Composite State)
A22: =Thermonix!A22 -> Transition | B22: =Thermonix!B22 -> cancel (Preparing Shutdown ⇒ Home) | C22: ='Thermonix Grader #1'!C22 -> 1 | D22: ='Thermonix Grader #2'!C22 -> 1 | F22: Composite State | G22: 0 | H22: 0.5 | I22: 1 | J22: Row Totals | L22: Global | M22: 0 | N22: 0.5 | O22: 1 | Q22: Global | R22: 0 | S22: 0.5 | T22: 1 | V22: Metric | W22: Value | X22: Note
A23: =Thermonix!A23 -> State | B23: =Thermonix!B23 -> PromptToAdd | C23: ='Thermonix Grader #1'!C23 -> 0 | D23: ='Thermonix Grader #2'!C23 -> 0 | F23: 0 | G23: =COUNTIFS($A$2:$A$89,$F$22,$C$2:$C$89,$F23,$D$2:$D$89,G$22) -> 1 | H23: =COUNTIFS($A$2:$A$89,$F$22,$C$2:$C$89,$F23,$D$2:$D$89,H$22) -> 0 | I23: =COUNTIFS($A$2:$A$45,$F$22,$C$2:$C$45,$F23,$D$2:$D$45,I$22) + MAX(D50-C50,0) -> 1 | J23: =SUM(G23:I23) -> 2 | L23: 0 | M23: =ABS(G$2-$F23)/1 -> 0 | N23: =ABS(H$2-$F23)/1 -> 0.5 | O23: =ABS(I$2-$F23)/1 -> 1 | Q23: 0 | R23: =($J23/$J$26) * (G$26/$J$26) -> 0.5 | S23: =($J23/$J$26) * (H$26/$J$26) -> 0 | T23: =($J23/$J$26) * (I$26/$J$26) -> 0.5 | V23: Observed Weighted Disagreement (D_obs) | W23: =SUMPRODUCT(G23:I25, M23:O25) /$J$26 -> 0.5 | X23: Sum of (confusion-matrix counts × weights) divided by total items.
A24: =Thermonix!A24 -> Transition | B24: =Thermonix!B24 -> next (PromptToAdd ⇒ PromptToAdd) | C24: ='Thermonix Grader #1'!C24 -> 0 | D24: ='Thermonix Grader #2'!C24 -> 0 | F24: 0.5 | G24: =COUNTIFS($A$2:$A$89,$F$22,$C$2:$C$89,$F24,$D$2:$D$89,G$22) -> 0 | H24: =COUNTIFS($A$2:$A$89,$F$22,$C$2:$C$89,$F24,$D$2:$D$89,H$22) -> 0 | I24: =COUNTIFS($A$2:$A$89,$F$22,$C$2:$C$89,$F24,$D$2:$D$89,I$22) -> 0 | J24: =SUM(G24:I24) -> 0 | L24: 0.5 | M24: =ABS(G$2-$F24)/1 -> 0.5 | N24: =ABS(H$2-$F24)/3 -> 0 | O24: =ABS(I$2-$F24)/1 -> 0.5 | Q24: 0.5 | R24: =($J24/$J$26) * (G$26/$J$26) -> 0 | S24: =($J24/$J$26) * (H$26/$J$26) -> 0 | T24: =($J24/$J$26) * (I$26/$J$26) -> 0 | V24: Expected Weighted Disagreement (D_exp) | W24: =SUMPRODUCT(R23:T25, M23:O25) -> 0.5 | X24: Sum of (expected cell proportions × weights) under chance agreement.
A25: =Thermonix!A25 -> Guard | B25: =Thermonix!B25 -> [weightCorrect() && moreIngredientsRequired()] | C25: ='Thermonix Grader #1'!C25 -> 0 | D25: ='Thermonix Grader #2'!C25 -> 0 | F25: 1 | G25: =COUNTIFS($A$2:$A$45,$F$22,$C$2:$C$45,$F25,$D$2:$D$45,G$22) + MAX(C50-D50,0) -> 0 | H25: =COUNTIFS($A$2:$A$89,$F$22,$C$2:$C$89,$F25,$D$2:$D$89,H$22) -> 0 | I25: =COUNTIFS($A$2:$A$45,$F$22,$C$2:$C$45,$F25,$D$2:$D$45,I$22) + MIN(C50,D50) -> 0 | J25: =SUM(G25:I25) -> 0 | L25: 1 | M25: =ABS(G$2-$F25)/1 -> 1 | N25: =ABS(H$2-$F25)/1 -> 0.5 | O25: =ABS(I$2-$F25)/1 -> 0 | Q25: 1 | R25: =($J25/$J$26) * (G$26/$J$26) -> 0 | S25: =($J25/$J$26) * (H$26/$J$26) -> 0 | T25: =($J25/$J$26) * (I$26/$J$26) -> 0 | V25: Cohen's Kappa | W25: =1-W23/W24 -> 0 | X25: 1 - (D_obs / D_exp)
A26: =#REF! -> #REF! | B26: =#REF! -> #REF! | C26: =#REF! -> #REF! | D26: =#REF! -> #REF! | F26: Column Totals | G26: =SUM(G23:G25) -> 1 | H26: =SUM(H23:H25) -> 0 | I26: =SUM(I23:I25) -> 1 | J26: =SUM(G23:I25) -> 2
A27: =Thermonix!A26 -> Action | B27: =Thermonix!B26 -> setIngredients() | C27: ='Thermonix Grader #1'!C26 -> 0 | D27: ='Thermonix Grader #2'!C26 -> 0
A28: =Thermonix!A27 -> Transition | B28: =Thermonix!B27 -> next (PromptToAdd ⇒ Chop) | C28: ='Thermonix Grader #1'!C27 -> 1 | D28: ='Thermonix Grader #2'!C27 -> 1 | F28: Confusion Matrix (Guard)
A29: =Thermonix!A28 -> Guard | B29: =Thermonix!B28 -> [weightCorrect() && !moreIngredientsRequired()] | C29: ='Thermonix Grader #1'!C28 -> 0.5 | D29: ='Thermonix Grader #2'!C28 -> 0 | F29: Guard | G29: 0 | H29: 0.5 | I29: 1 | J29: Row Totals | L29: Global | M29: 0 | N29: 0.5 | O29: 1 | Q29: Global | R29: 0 | S29: 0.5 | T29: 1 | V29: Metric | W29: Value | X29: Note
A30: =Thermonix!A29 -> Action | B30: =Thermonix!B29 -> setChoppingSpeedAndTime() | C30: ='Thermonix Grader #1'!C29 -> 0 | D30: ='Thermonix Grader #2'!C29 -> 0 | F30: 0 | G30: =COUNTIFS($A$2:$A$89,$F$29,$C$2:$C$89,$F30,$D$2:$D$89,G$29) -> 4 | H30: =COUNTIFS($A$2:$A$89,$F$29,$C$2:$C$89,$F30,$D$2:$D$89,H$29) -> 0 | I30: =COUNTIFS($A$2:$A$45,$F$29,$C$2:$C$45,$F30,$D$2:$D$45,I$29) + MAX(D48-C48,0) -> 0 | J30: =SUM(G30:I30) -> 4 | L30: 0 | M30: =ABS(G$2-$F30)/1 -> 0 | N30: =ABS(H$2-$F30)/1 -> 0.5 | O30: =ABS(I$2-$F30)/1 -> 1 | Q30: 0 | R30: =($J30/$J$33) * (G$33/$J$33) -> 0.3125 | S30: =($J30/$J$33) * (H$33/$J$33) -> 0 | T30: =($J30/$J$33) * (I$33/$J$33) -> 0.1875 | V30: Observed Weighted Disagreement (D_obs) | W30: =SUMPRODUCT(G30:I32, M30:O32) /$J$33 -> 0.125 | X30: Sum of (confusion-matrix counts × weights) divided by total items.
A31: =Thermonix!A30 -> State | B31: =Thermonix!B30 -> Chop | C31: ='Thermonix Grader #1'!C30 -> 1 | D31: ='Thermonix Grader #2'!C30 -> 1 | F31: 0.5 | G31: =COUNTIFS($A$2:$A$89,$F$29,$C$2:$C$89,$F31,$D$2:$D$89,G$29) -> 1 | H31: =COUNTIFS($A$2:$A$89,$F$29,$C$2:$C$89,$F31,$D$2:$D$89,H$29) -> 0 | I31: =COUNTIFS($A$2:$A$89,$F$29,$C$2:$C$89,$F31,$D$2:$D$89,I$29) -> 1 | J31: =SUM(G31:I31) -> 2 | L31: 0.5 | M31: =ABS(G$2-$F31)/1 -> 0.5 | N31: =ABS(H$2-$F31)/3 -> 0 | O31: =ABS(I$2-$F31)/1 -> 0.5 | Q31: 0.5 | R31: =($J31/$J$33) * (G$33/$J$33) -> 0.15625 | S31: =($J31/$J$33) * (H$33/$J$33) -> 0 | T31: =($J31/$J$33) * (I$33/$J$33) -> 0.09375 | V31: Expected Weighted Disagreement (D_exp) | W31: =SUMPRODUCT(R30:T32, M30:O32) -> 0.46875 | X31: Sum of (expected cell proportions × weights) under chance agreement.
A32: =Thermonix!A31 -> Transition | B32: =Thermonix!B31 -> next (Chop ⇒ PromptToAdd) | C32: ='Thermonix Grader #1'!C31 -> 0 | D32: ='Thermonix Grader #2'!C31 -> 0 | F32: 1 | G32: =COUNTIFS($A$2:$A$45,$F$29,$C$2:$C$45,$F32,$D$2:$D$45,G$29) + MAX(C48-D48,0) -> 0 | H32: =COUNTIFS($A$2:$A$89,$F$29,$C$2:$C$89,$F32,$D$2:$D$89,H$29) -> 0 | I32: =COUNTIFS($A$2:$A$45,$F$29,$C$2:$C$45,$F32,$D$2:$D$45,I$29) + MIN(C48,D48) -> 2 | J32: =SUM(G32:I32) -> 2 | L32: 1 | M32: =ABS(G$2-$F32)/1 -> 1 | N32: =ABS(H$2-$F32)/1 -> 0.5 | O32: =ABS(I$2-$F32)/1 -> 0 | Q32: 1 | R32: =($J32/$J$33) * (G$33/$J$33) -> 0.15625 | S32: =($J32/$J$33) * (H$33/$J$33) -> 0 | T32: =($J32/$J$33) * (I$33/$J$33) -> 0.09375 | V32: Cohen's Kappa | W32: =1-W30/W31 -> 0.73333333 | X32: 1 - (D_obs / D_exp)
A33: =Thermonix!A32 -> Guard | B33: =Thermonix!B32 -> [choppingTimeDone && moreIngredientsRequired()] | C33: ='Thermonix Grader #1'!C32 -> 0 | D33: ='Thermonix Grader #2'!C32 -> 0 | F33: Column Totals | G33: =SUM(G30:G32) -> 5 | H33: =SUM(H30:H32) -> 0 | I33: =SUM(I30:I32) -> 3 | J33: =SUM(G30:I32) -> 8
A34: =Thermonix!A33 -> Action | B34: =Thermonix!B33 -> setIngredients() | C34: ='Thermonix Grader #1'!C33 -> 0 | D34: ='Thermonix Grader #2'!C33 -> 0
A35: =Thermonix!A34 -> Transition | B35: =Thermonix!B34 -> next (Chop ⇒ Cook) | C35: ='Thermonix Grader #1'!C34 -> 1 | D35: ='Thermonix Grader #2'!C34 -> 1 | F35: Confusion Matrix (Action)
A36: =Thermonix!A35 -> Guard | B36: =Thermonix!B35 -> [choppingTimeDone && !moreIngredientsRequired()] | C36: ='Thermonix Grader #1'!C35 -> 0 | D36: ='Thermonix Grader #2'!C35 -> 0 | F36: Action | G36: 0 | H36: 0.5 | I36: 1 | J36: Row Totals | L36: Global | M36: 0 | N36: 0.5 | O36: 1 | Q36: Global | R36: 0 | S36: 0.5 | T36: 1 | V36: Metric | W36: Value | X36: Note
A37: =Thermonix!A36 -> Action | B37: =Thermonix!B36 -> setCookingSpeedAndTime() | C37: ='Thermonix Grader #1'!C36 -> 0 | D37: ='Thermonix Grader #2'!C36 -> 0 | F37: 0 | G37: =COUNTIFS($A$2:$A$89,$F$36,$C$2:$C$89,$F37,$D$2:$D$89,G$36) -> 6 | H37: =COUNTIFS($A$2:$A$89,$F$36,$C$2:$C$89,$F37,$D$2:$D$89,H$36) -> 0 | I37: =COUNTIFS($A$2:$A$45,$F$36,$C$2:$C$45,$F37,$D$2:$D$45,I$36)+MAX(D49-C49,0) -> 0 | J37: =SUM(G37:I37) -> 6 | L37: 0 | M37: =ABS(G$2-$F37)/1 -> 0 | N37: =ABS(H$2-$F37)/1 -> 0.5 | O37: =ABS(I$2-$F37)/1 -> 1 | Q37: 0 | R37: =($J37/$J$40) * (G$41/$J$40) -> 0 | S37: =($J37/$J$40) * (H$41/$J$40) -> 0 | T37: =($J37/$J$40) * (I$41/$J$40) -> 0 | V37: Observed Weighted Disagreement (D_obs) | W37: =SUMPRODUCT(G37:I39, M37:O39) /$J$40 -> 0 | X37: Sum of (confusion-matrix counts × weights) divided by total items.
A38: =Thermonix!A37 -> State | B38: =Thermonix!B37 -> Cook | C38: ='Thermonix Grader #1'!C37 -> 1 | D38: ='Thermonix Grader #2'!C37 -> 1 | F38: 0.5 | G38: =COUNTIFS($A$2:$A$89,$F$36,$C$2:$C$89,$F38,$D$2:$D$89,G$36) -> 0 | H38: =COUNTIFS($A$2:$A$89,$F$36,$C$2:$C$89,$F38,$D$2:$D$89,H$36) -> 0 | I38: =COUNTIFS($A$2:$A$89,$F$36,$C$2:$C$89,$F38,$D$2:$D$89,I$36) -> 0 | J38: =SUM(G38:I38) -> 0 | L38: 0.5 | M38: =ABS(G$2-$F38)/1 -> 0.5 | N38: =ABS(H$2-$F38)/3 -> 0 | O38: =ABS(I$2-$F38)/1 -> 0.5 | Q38: 0.5 | R38: =($J38/$J$40) * (G$41/$J$40) -> 0 | S38: =($J38/$J$40) * (H$41/$J$40) -> 0 | T38: =($J38/$J$40) * (I$41/$J$40) -> 0 | V38: Expected Weighted Disagreement (D_exp) | W38: =SUMPRODUCT(R37:T39, M37:O39) -> 0 | X38: Sum of (expected cell proportions × weights) under chance agreement.
A39: =Thermonix!A38 -> Transition | B39: =Thermonix!B38 -> after choppingTime (Cook ⇒ PromptToAdd) | C39: ='Thermonix Grader #1'!C38 -> 1 | D39: ='Thermonix Grader #2'!C38 -> 1 | F39: 1 | G39: =COUNTIFS($A$2:$A$45,$F$36,$C$2:$C$45,$F39,$D$2:$D$45,G$36)+MAX(C49-D49,0) -> 0 | H39: =COUNTIFS($A$2:$A$89,$F$36,$C$2:$C$89,$F39,$D$2:$D$89,H$36) -> 0 | I39: =COUNTIFS($A$2:$A$45,$F$36,$C$2:$C$45,$F39,$D$2:$D$45,I$36) + MIN(C49,D49) -> 1 | J39: =SUM(G39:I39) -> 1 | L39: 1 | M39: =ABS(G$2-$F39)/1 -> 1 | N39: =ABS(H$2-$F39)/1 -> 0.5 | O39: =ABS(I$2-$F39)/1 -> 0 | Q39: 1 | R39: =($J39/$J$40) * (G$41/$J$40) -> 0 | S39: =($J39/$J$40) * (H$41/$J$40) -> 0 | T39: =($J39/$J$40) * (I$41/$J$40) -> 0 | V39: Cohen's Kappa | W39: =1-W37/W38 -> #DIV/0! | X39: 1 - (D_obs / D_exp)
A40: =Thermonix!A39 -> Guard | B40: =Thermonix!B39 -> [choppingTimeDone && moreIngredientsRequired()] | C40: ='Thermonix Grader #1'!C39 -> 0.5 | D40: ='Thermonix Grader #2'!C39 -> 1 | F40: Column Totals | G40: =SUM(G37:G39) -> 6 | H40: =SUM(H37:H39) -> 0 | I40: =SUM(I37:I39) -> 1 | J40: =SUM(G37:I39) -> 7
...
