Workbook

Sheet Thermonix
A1: Type | B1: Element
A2: State | B2: initial state (⇒ TransportationMode)
A3: State | B3: TransportationMode
A4: Transition | B4: selectorPressed (TransportationMode ⇒ On)
A5: State | B5: PreparingOff
A6: Transition | B6: selectorReleased (PreparingOff ⇒ On)
A7: Transition | B7: after 5sec (PreparingOff ⇒ Off)
A8: State | B8: Off
A9: Transition | B9: selectorPressed (Off ⇒ On)
A10: Composite State | B10: On
A11: History State | B11: History State for On
A12: Transition | B12: selectorHeld (On ⇒ PreparingOff)
... A51: History State | B51: additional elements

Sheet CombinedHumanGrading
A1: Type | B1: Element | C1: Rater 1 | D1: Notes
A2: State | B2: initial state (⇒ TransportationMode) | C2: 1
A3: State | B3: TransportationMode | C3: 1
A4: Transition | B4: selectorPressed (TransportationMode ⇒ On) | C4: 1 | D4: goes to homescreen instead of on, same concept, problem doesnt specify a ON mode
A5: State | B5: PreparingOff | C5: 1 | D5: shutting down state
A6: Transition | B6: selectorReleased (PreparingOff ⇒ On) | C6: 1 | D6: goes back to homescreen
A7: Transition | B7: after 5sec (PreparingOff ⇒ Off) | C7: 1 | D7: shows shutdown message, then turns off
A8: State | B8: Off | C8: 1
A9: Transition | B9: selectorPressed (Off ⇒ On) | C9: 1
A10: Composite State | B10: On | C10: 0
A11: History State | B11: History State for On | C11: 0
A12: Transition | B12: selectorHeld (On ⇒ PreparingOff) | C12: 1
A13: Transition | B13: bowlRemoved (On ⇒ On) | C13: 1 | D13: same logic but shown with homescreen instead of on
A14: State | B14: Initial State (On ⇒ Home) | C14: 0
A15: State | B15: Home | C15: 1
A16: Transition | B16: after 14min 30sec (Home ⇒ Preparing Shutdown) | C16: 1
A17: Transition | B17: start (Home ⇒ PromptToAdd) | C17: 1
A18: Guard | B18: [!bowlRemoved()] | C18: 1 | D18: shown in [bowlplaced] (recipeselected => addingIngredients)
A19: Action | B19: setIngredients() | C19: 1 | D19: select recipe
A20: State | B20: Preparing Shutdown | C20: 1
A21: Transition | B21: after 30sec (Preparing Shutdown ⇒ Off) | C21: 1
A22: Transition | B22: cancel (Preparing Shutdown ⇒ Home) | C22: 1
A23: State | B23: PromptToAdd | C23: 0
A24: Transition | B24: next (PromptToAdd ⇒ PromptToAdd) | C24: 0
A25: Guard | B25: [weightCorrect() && moreIngredientsRequired()] | C25: 0
A26: Action | B26: setIngredients() | C26: 0
A27: Transition | B27: next (PromptToAdd ⇒ Chop) | C27: 1
A28: Guard | B28: [weightCorrect() && !moreIngredientsRequired()] | C28: 0.5 | D28: correctAmount is not detailed enough
A29: Action | B29: setChoppingSpeedAndTime() | C29: 0
A30: State | B30: Chop | C30: 1
A31: Transition | B31: next (Chop ⇒ PromptToAdd) | C31: 0
A32: Guard | B32: [choppingTimeDone && moreIngredientsRequired()] | C32: 0
A33: Action | B33: setIngredients() | C33: 0
A34: Transition | B34: next (Chop ⇒ Cook) | C34: 1
A35: Guard | B35: [choppingTimeDone && !moreIngredientsRequired()] | C35: 0
A36: Action | B36: setCookingSpeedAndTime() | C36: 0
A37: State | B37: Cook | C37: 1
A38: Transition | B38: after choppingTime (Cook ⇒ PromptToAdd) | C38: 1
A39: Guard | B39: [choppingTimeDone && moreIngredientsRequired()] | C39: 0.5
A40: Action | B40: setIngredients() | C40: 0
...

Sheet GPT-5.5 Grading
A1: Type | B1: Element | C1: GPT-5.5 Grading | D1: Notes
A2: State | B2: initial state (⇒ TransportationMode) | C2: 1 | D2: Initial pseudostate explicitly enters TransportationMode.
A3: State | B3: TransportationMode | C3: 1 | D3: TransportationMode state is explicitly modeled.
A4: Transition | B4: selectorPressed (TransportationMode ⇒ On) | C4: 1 | D4: selectorPressed leaves TransportationMode and shows HomeScreen which represents being on.
A5: State | B5: PreparingOff | C5: 1 | D5: ShuttingDown and ShutdownReady together represent the shutdown preparation behavior.
A6: Transition | B6: selectorReleased (PreparingOff ⇒ On) | C6: 1 | D6: Releasing during ShuttingDown before the five second threshold returns to HomeScreen.
A7: Transition | B7: after 5sec (PreparingOff ⇒ Off) | C7: 0.5 | D7: The five second threshold is modeled but it goes to ShutdownReady and requires selectorReleased before Off.
A8: State | B8: Off | C8: 1 | D8: Off state is explicitly modeled.
A9: Transition | B9: selectorPressed (Off ⇒ On) | C9: 1 | D9: selectorPressed from Off returns to HomeScreen.
A10: Composite State | B10: On | C10: 0.5 | D10: Operational on behavior is represented but there is no enclosing On composite state.
A11: History State | B11: History State for On | C11: 0 | D11: No history pseudostate for returning to the previous on substate is modeled.
A12: Transition | B12: selectorHeld (On ⇒ PreparingOff) | C12: 0.5 | D12: selectorHeld starts shutdown only from HomeScreen rather than from all on states.
A13: Transition | B13: bowlRemoved (On ⇒ On) | C13: 0.5 | D13: bowlRemoved is handled in recipe execution and shutdown warning but not as a general on self transition.
... A51: History State | B51: additional elements | C51: 0 | D51: No fundamentally incorrect extra history states are present.

Sheet Metrics
A1: Claude Grader Human | J1: Date
A2: Type | B2: Ground Truth Count | C2: True Positive | D2: False Positive | E2: False Negative | F2: Precision | G2: Recall | H2: F1 Score | J2: May 6th, 2026
A3: Composite State | B3: =COUNTIF(Thermonix!$A$2:$A$44, A3) -> 1 | C3: =SUMIF(CombinedHumanGrading!$A$2:$A$44, $A3, CombinedHumanGrading!$C$2:$C$44) -> 0 | D3: =SUMIF(CombinedHumanGrading!$A$45:$A$51, $A3, CombinedHumanGrading!$C$45:$C$51) -> 0 | E3: =COUNTIFS(CombinedHumanGrading!$A$2:$A$44, $A3, CombinedHumanGrading!$C$2:$C$44,0) -> 1 | F3: =IFERROR(C3 / (C3 + D3), "Not Available") -> Not Available | G3: =IFERROR(C3 / B3, "Not Available") -> 0 | H3: =IFERROR(2*((F3*G3)/(F3+G3)),"Not Available") -> Not Available
A4: State | B4: =COUNTIF(Thermonix!$A$2:$A$44, A4) -> 11 | C4: =SUMIF(CombinedHumanGrading!$A$2:$A$44, $A4, CombinedHumanGrading!$C$2:$C$44) -> 9 | D4: =SUMIF(CombinedHumanGrading!$A$45:$A$51, $A4, CombinedHumanGrading!$C$45:$C$51) -> 0 | E4: =COUNTIFS(CombinedHumanGrading!$A$2:$A$44, $A4, CombinedHumanGrading!$C$2:$C$44,0) -> 2 | F4: =IFERROR(C4 / (C4 + D4), "Not Available") -> 1 | G4: =IFERROR(C4 / B4, "Not Available") -> 0.81818182 | H4: =IFERROR(2*((F4*G4)/(F4+G4)),"Not Available") -> 0.9 | J4: Generation LLM
A5: Transition | B5: =COUNTIF(Thermonix!$A$2:$A$44, A5) -> 17 | C5: =SUMIF(CombinedHumanGrading!$A$2:$A$44, $A5, CombinedHumanGrading!$C$2:$C$44) -> 14 | D5: =SUMIF(CombinedHumanGrading!$A$45:$A$51, $A5, CombinedHumanGrading!$C$45:$C$51) -> 0 | E5: =COUNTIFS(CombinedHumanGrading!$A$2:$A$44, $A5, CombinedHumanGrading!$C$2:$C$44,0) -> 3 | F5: =IFERROR(C5 / (C5 + D5), "Not Available") -> 1 | G5: =IFERROR(C5 / B5, "Not Available") -> 0.82352941 | H5: =IFERROR(2*((F5*G5)/(F5+G5)),"Not Available") -> 0.90322581 | J5: Claude 4.5 Sonnet
A6: Action | B6: =COUNTIF(Thermonix!$A$2:$A$44, A6) -> 6 | C6: =SUMIF(CombinedHumanGrading!$A$2:$A$44, $A6, CombinedHumanGrading!$C$2:$C$44) -> 1 | D6: =SUMIF(CombinedHumanGrading!$A$45:$A$51, $A6, CombinedHumanGrading!$C$45:$C$51) -> 0 | E6: =COUNTIFS(CombinedHumanGrading!$A$2:$A$44, $A6, CombinedHumanGrading!$C$2:$C$44,0) -> 5 | F6: =IFERROR(C6 / (C6 + D6), "Not Available") -> 1 | G6: =IFERROR(C6 / B6, "Not Available") -> 0.16666667 | H6: =IFERROR(2*((F6*G6)/(F6+G6)),"Not Available") -> 0.28571429
A7: Region | B7: =COUNTIF(Thermonix!$A$2:$A$44, A7) -> 0 | C7: =SUMIF(CombinedHumanGrading!$A$2:$A$44, $A7, CombinedHumanGrading!$C$2:$C$44) -> 0 | D7: =SUMIF(CombinedHumanGrading!$A$45:$A$51, $A7, CombinedHumanGrading!$C$45:$C$51) -> 0 | E7: =COUNTIFS(CombinedHumanGrading!$A$2:$A$44, $A7, CombinedHumanGrading!$C$2:$C$44,0) -> 0 | F7: =IFERROR(C7 / (C7 + D7), "Not Available") -> Not Available | G7: =IFERROR(C7 / B7, "Not Available") -> Not Available | H7: =IFERROR(2*((F7*G7)/(F7+G7)),"Not Available") -> Not Available | J7: Grading LLMs
A8: History State | B8: =COUNTIF(Thermonix!$A$2:$A$44, A8) -> 1 | C8: =SUMIF(CombinedHumanGrading!$A$2:$A$44, $A8, CombinedHumanGrading!$C$2:$C$44) -> 0 | D8: =SUMIF(CombinedHumanGrading!$A$45:$A$51, $A8, CombinedHumanGrading!$C$45:$C$51) -> 0 | E8: =COUNTIFS(CombinedHumanGrading!$A$2:$A$44, $A8, CombinedHumanGrading!$C$2:$C$44,0) -> 1 | F8: =IFERROR(C8 / (C8 + D8), "Not Available") -> Not Available | G8: =IFERROR(C8 / B8, "Not Available") -> 0 | H8: =IFERROR(2*((F8*G8)/(F8+G8)),"Not Available") -> Not Available | J8: GPT-5.5
A9: Guard | B9: =COUNTIF(Thermonix!$A$2:$A$44, A9) -> 7 | C9: =SUMIF(CombinedHumanGrading!$A$2:$A$44, $A9, CombinedHumanGrading!$C$2:$C$44) -> 3 | D9: =SUMIF(CombinedHumanGrading!$A$45:$A$51, $A9, CombinedHumanGrading!$C$45:$C$51) -> 0 | E9: =COUNTIFS(CombinedHumanGrading!$A$2:$A$44, $A9, CombinedHumanGrading!$C$2:$C$44,0) -> 3 | F9: =IFERROR(C9 / (C9 + D9), "Not Available") -> 1 | G9: =IFERROR(C9 / B9, "Not Available") -> 0.42857143 | H9: =IFERROR(2*((F9*G9)/(F9+G9)),"Not Available") -> 0.6
A10: Overall Score | B10: =SUM(B3:B9) -> 43 | C10: =SUM(C3:C9) -> 27 | D10: =SUM(D3:D9) -> 0 | E10: =SUM(E3:E9) -> 15 | F10: =IFERROR(C10 / (C10 + D10), "Not Available") -> 1 | G10: =IFERROR(C10 / B10, "Not Available") -> 0.62790698 | H10: =IFERROR(2*((F10*G10)/(F10+G10)),"Not Available") -> 0.77142857
A12: Graded by GPT-5.5
A13: Type | B13: Ground Truth Count | C13: True Positive | D13: False Positive | E13: False Negative | F13: Precision | G13: Recall | H13: F1 Score
A14: Composite state | B14: =COUNTIF(Thermonix!$A$2:$A$44, A14) -> 1 | C14: =SUMIF('GPT-5.5 Grading'!$A$2:$A$44, $A14, 'GPT-5.5 Grading'!$C$2:$C$44) -> 0.5 | D14: =SUMIF('GPT-5.5 Grading'!$A$45:$A$51, $A14, 'GPT-5.5 Grading'!$C$45:$C$51) -> 0 | E14: =COUNTIFS('GPT-5.5 Grading'!$A$2:$A$44, $A14, 'GPT-5.5 Grading'!$C$2:$C$44,0) -> 0 | F14: =IFERROR(C14 / (C14 + D14), "Not Available") -> 1 | G14: =IFERROR(C14 / B14, "Not Available") -> 0.5 | H14: =IFERROR(2*((F14*G14)/(F14+G14)),"Not Available") -> 0.66666667
A15: State | B15: =COUNTIF(Thermonix!$A$2:$A$44, A15) -> 11 | C15: =SUMIF('GPT-5.5 Grading'!$A$2:$A$44, $A15, 'GPT-5.5 Grading'!$C$2:$C$44) -> 11 | D15: =SUMIF('GPT-5.5 Grading'!$A$45:$A$51, $A15, 'GPT-5.5 Grading'!$C$45:$C$51) -> 0 | E15: =COUNTIFS('GPT-5.5 Grading'!$A$2:$A$44, $A15, 'GPT-5.5 Grading'!$C$2:$C$44,0) -> 0 | F15: =IFERROR(C15 / (C15 + D15), "Not Available") -> 1 | G15: =IFERROR(C15 / B15, "Not Available") -> 1 | H15: =IFERROR(2*((F15*G15)/(F15+G15)),"Not Available") -> 1
A16: Transition | B16: =COUNTIF(Thermonix!$A$2:$A$44, A16) -> 17 | C16: =SUMIF('GPT-5.5 Grading'!$A$2:$A$44, $A16, 'GPT-5.5 Grading'!$C$2:$C$44) -> 12.5 | D16: =SUMIF('GPT-5.5 Grading'!$A$45:$A$51, $A16, 'GPT-5.5 Grading'!$C$45:$C$51) -> 0 | E16: =COUNTIFS('GPT-5.5 Grading'!$A$2:$A$44, $A16, 'GPT-5.5 Grading'!$C$2:$C$44,0) -> 3 | F16: =IFERROR(C16 / (C16 + D16), "Not Available") -> 1 | G16: =IFERROR(C16 / B16, "Not Available") -> 0.73529412 | H16: =IFERROR(2*((F16*G16)/(F16+G16)),"Not Available") -> 0.84745763
A17: Action | B17: =COUNTIF(Thermonix!$A$2:$A$44, A17) -> 6 | C17: =SUMIF('GPT-5.5 Grading'!$A$2:$A$44, $A17, 'GPT-5.5 Grading'!$C$2:$C$44) -> 2 | D17: =SUMIF('GPT-5.5 Grading'!$A$45:$A$51, $A17, 'GPT-5.5 Grading'!$C$45:$C$51) -> 0 | E17: =COUNTIFS('GPT-5.5 Grading'!$A$2:$A$44, $A17, 'GPT-5.5 Grading'!$C$2:$C$44,0) -> 2 | F17: =IFERROR(C17 / (C17 + D17), "Not Available") -> 1 | G17: =IFERROR(C17 / B17, "Not Available") -> 0.33333333 | H17: =IFERROR(2*((F17*G17)/(F17+G17)),"Not Available") -> 0.5
A18: Region | B18: =COUNTIF(Thermonix!$A$2:$A$44, A18) -> 0 | C18: =SUMIF('GPT-5.5 Grading'!$A$2:$A$44, $A18, 'GPT-5.5 Grading'!$C$2:$C$44) -> 0 | D18: =SUMIF('GPT-5.5 Grading'!$A$45:$A$51, $A18, 'GPT-5.5 Grading'!$C$45:$C$51) -> 0 | E18: =COUNTIFS('GPT-5.5 Grading'!$A$2:$A$44, $A18, 'GPT-5.5 Grading'!$C$2:$C$44,0) -> 0 | F18: =IFERROR(C18 / (C18 + D18), "Not Available") -> Not Available | G18: =IFERROR(C18 / B18, "Not Available") -> Not Available | H18: =IFERROR(2*((F18*G18)/(F18+G18)),"Not Available") -> Not Available
A19: History State | B19: =COUNTIF(Thermonix!$A$2:$A$44, A19) -> 1 | C19: =SUMIF('GPT-5.5 Grading'!$A$2:$A$44, $A19, 'GPT-5.5 Grading'!$C$2:$C$44) -> 0 | D19: =SUMIF('GPT-5.5 Grading'!$A$45:$A$51, $A19, 'GPT-5.5 Grading'!$C$45:$C$51) -> 0 | E19: =COUNTIFS('GPT-5.5 Grading'!$A$2:$A$44, $A19, 'GPT-5.5 Grading'!$C$2:$C$44,0) -> 1 | F19: =IFERROR(C19 / (C19 + D19), "Not Available") -> Not Available | G19: =IFERROR(C19 / B19, "Not Available") -> 0 | H19: =IFERROR(2*((F19*G19)/(F19+G19)),"Not Available") -> Not Available
A20: Guard | B20: =COUNTIF(Thermonix!$A$2:$A$44, A20) -> 7 | C20: =SUMIF('GPT-5.5 Grading'!$A$2:$A$44, $A20, 'GPT-5.5 Grading'!$C$2:$C$44) -> 3.5 | D20: =SUMIF('GPT-5.5 Grading'!$A$45:$A$51, $A20, 'GPT-5.5 Grading'!$C$45:$C$51) -> 0 | E20: =COUNTIFS('GPT-5.5 Grading'!$A$2:$A$44, $A20, 'GPT-5.5 Grading'!$C$2:$C$44,0) -> 3 | F20: =IFERROR(C20 / (C20 + D20), "Not Available") -> 1 | G20: =IFERROR(C20 / B20, "Not Available") -> 0.5 | H20: =IFERROR(2*((F20*G20)/(F20+G20)),"Not Available") -> 0.66666667
A21: Overall Score | B21: =SUM(B14:B20) -> 43 | C21: =SUM(C14:C20) -> 29.5 | D21: =SUM(D14:D20) -> 0 | E21: =SUM(E14:E20) -> 9 | F21: =IFERROR(C21 / (C21 + D21), "Not Available") -> 1 | G21: =IFERROR(C21 / B21, "Not Available") -> 0.68604651 | H21: =IFERROR(2*((F21*G21)/(F21+G21)),"Not Available") -> 0.8137931

Sheet Inter-rater
A1: Type | B1: Element | C1: CombinedHumanGrading | D1: GPT-5.5 | F1: Confusion Matrix | L1: Cohen's Kappa
A2: =Thermonix!A2 -> State | B2: =Thermonix!B2 -> initial state (⇒ TransportationMode) | C2: =CombinedHumanGrading!C2 -> 1 | D2: ='GPT-5.5 Grading'!C2 -> 1 | F2: Global | G2: 0 | H2: 0.5 | I2: 1 | J2: Row Totals | L2: Metric | M2: Value | N2: Note
A3: =Thermonix!A3 -> State | B3: =Thermonix!B3 -> TransportationMode | C3: =CombinedHumanGrading!C3 -> 1 | D3: ='GPT-5.5 Grading'!C3 -> 1 | F3: 0 | G3: =COUNTIFS($C$2:$C$84, $F3, $D$2:$D$84, G$2) -> 16 | H3: =COUNTIFS($C$2:$C$44, $F3, $D$2:$D$44, H$2) -> 4 | I3: =COUNTIFS($C$2:$C$44, $F3, $D$2:$D$44, I$2)+MAX(D45-C45,0)+MAX(D46-C46,0)+MAX(D47-C47,0)+MAX(D48-C48,0)+MAX(D49-C49,0)+MAX(D50-C50,0)+MAX(D51-C51,0) -> 2 | J3: =SUM(G3:I3) -> 22 | L3: Observed Agreement (Po) | M3: =(G3+H4+I5)/COUNTA($C$2:$C$94) -> 0.78 | N3: This sums the diagonal of your matrix divided by total rows.
A4: =Thermonix!A4 -> Transition | B4: =Thermonix!B4 -> selectorPressed (TransportationMode ⇒ On) | C4: =CombinedHumanGrading!C4 -> 1 | D4: ='GPT-5.5 Grading'!C4 -> 1 | F4: 0.5 | G4: =COUNTIFS($C$2:$C$44, $F4, $D$2:$D$44, G$2) -> 0 | H4: =COUNTIFS($C$2:$C$44, $F4, $D$2:$D$44, H$2) -> 1 | I4: =COUNTIFS($C$2:$C$44, $F4, $D$2:$D$44, I$2) -> 1 | J4: =SUM(G4:I4) -> 2 | L4: Expected Agreement (Pe) | M4: {=SUMPRODUCT(J3:J5/COUNTA($C$2:$C$94), TRANSPOSE(G6:I6)/COUNTA($C$2:$C$94))} -> 0.408 | N4: This computes the sum of row proportion times column proportion.
A5: =Thermonix!A5 -> State | B5: =Thermonix!B5 -> PreparingOff | C5: =CombinedHumanGrading!C5 -> 1 | D5: ='GPT-5.5 Grading'!C5 -> 1 | F5: 1 | G5: =COUNTIFS($C$2:$C$44, $F5, $D$2:$D$44, G$2)+MAX(C45-D45,0)+MAX(C46-D46,0)+MAX(C47-D47,0)+MAX(C48-D48,0)+MAX(C49-D49,0)+MAX(C50-D50,0)+MAX(C51-D51,0) -> 0 | H5: =COUNTIFS($C$2:$C$44, $F5, $D$2:$D$44, H$2) -> 4 | I5: =COUNTIFS($C$2:$C$44, $F5, $D$2:$D$44, I$2)+ SUM(MIN(C45,D45), MIN(C46,D46), MIN(C47,D47), MIN(C48,D48), MIN(C49,D49), MIN(C50,D50), MIN(C51,D51)) -> 22 | J5: =SUM(G5:I5) -> 26 | L5: Cohen's Kappa | M5: =(M3-M4)/(1-M4) -> 0.62837838 | N5: (Po - Pe) / (1 - Pe)
A6: =Thermonix!A6 -> Transition | B6: =Thermonix!B6 -> selectorReleased (PreparingOff ⇒ On) | C6: =CombinedHumanGrading!C6 -> 1 | D6: ='GPT-5.5 Grading'!C6 -> 1 | F6: Column Totals | G6: =SUM(G3:G5) -> 16 | H6: =SUM(H3:H5) -> 9 | I6: =SUM(I3:I5) -> 25
A7: =Thermonix!A7 -> Transition | B7: =Thermonix!B7 -> after 5sec (PreparingOff ⇒ Off) | C7: =CombinedHumanGrading!C7 -> 1 | D7: ='GPT-5.5 Grading'!C7 -> 0.5
A8: =Thermonix!A8 -> State | B8: =Thermonix!B8 -> Off | C8: =CombinedHumanGrading!C8 -> 1 | D8: ='GPT-5.5 Grading'!C8 -> 1 | F8: Confusion Matrix (State) | L8: Cohen's Kappa (State)
A9: =Thermonix!A9 -> Transition | B9: =Thermonix!B9 -> selectorPressed (Off ⇒ On) | C9: =CombinedHumanGrading!C9 -> 1 | D9: ='GPT-5.5 Grading'!C9 -> 1 | F9: State | G9: 0 | H9: 0.5 | I9: 1 | J9: Row Totals | L9: Metric | M9: Value | N9: Note
A10: =Thermonix!A10 -> Composite State | B10: =Thermonix!B10 -> On | C10: =CombinedHumanGrading!C10 -> 0 | D10: ='GPT-5.5 Grading'!C10 -> 0.5 | F10: 0 | G10: =COUNTIFS($A$2:$A$84,$F$9,$C$2:$C$84,$F10,$D$2:$D$84,G$16) -> 1 | H10: =COUNTIFS($A$2:$A$84,$F$9,$C$2:$C$84,$F10,$D$2:$D$84,H$9) -> 0 | I10: =COUNTIFS($A$2:$A$44,$F$9,$C$2:$C$44,$F10,$D$2:$D$44,I$16) + MAX(D39-C39,0) -> 2.5 | J10: =SUM(G10:I10) -> 3.5 | M10: =(G10+H11+I12)/COUNTIF($A$2:$A$94,F9) -> 0.83333333 | N10: This sums the diagonal of your matrix divided by total rows.
A11: =Thermonix!A11 -> History State | B11: =Thermonix!B11 -> History State for On | C11: =CombinedHumanGrading!C11 -> 0 | D11: ='GPT-5.5 Grading'!C11 -> 0 | F11: 0.5 | G11: =COUNTIFS($A$2:$A$84,$F$9,$C$2:$C$84,$F11,$D$2:$D$84,G$9) -> 0 | H11: =COUNTIFS($A$2:$A$84,$F$9,$C$2:$C$84,$F11,$D$2:$D$84,H$9) -> 0 | I11: =COUNTIFS($A$2:$A$84,$F$9,$C$2:$C$84,$F11,$D$2:$D$84,I$9) -> 0 | J11: =SUM(G11:I11) -> 0 | L11: Expected Agreement (Pe) | M11: {=SUMPRODUCT(J10:J12/COUNTIF($A$2:$A$94,F9), TRANSPOSE(G13:I13)/COUNTIF($A$2:$A$94,F9))} -> 0.5625 | N11: This computes the sum of row proportion times column proportion.
A12: =Thermonix!A12 -> Transition | B12: =Thermonix!B12 -> selectorHeld (On ⇒ PreparingOff) | C12: =CombinedHumanGrading!C12 -> 1 | D12: ='GPT-5.5 Grading'!C12 -> 0.5 | F12: 1 | G12: =COUNTIFS($A$2:$A$44,$F$9,$C$2:$C$44,$F12,$D$2:$D$44,G$9)+MAX(C45-D45,0) -> 0 | H12: =COUNTIFS($A$2:$A$84,$F$9,$C$2:$C$84,$F12,$D$2:$D$84,H$9) -> 0 | I12: =COUNTIFS($A$2:$A$44,$F$9,$C$2:$C$44,$F12,$D$2:$D$44,I$9)+MIN(C45-D45) -> 9 | J12: =SUM(G12:I12) -> 9 | L12: Cohen's Kappa | M12: =(M10-M11)/(1-M11) -> 0.61904762 | N12: (Po - Pe) / (1 - Pe)
A13: =Thermonix!A13 -> Transition | B13: =Thermonix!B13 -> bowlRemoved (On ⇒ On) | C13: =CombinedHumanGrading!C13 -> 1 | D13: ='GPT-5.5 Grading'!C13 -> 0.5 | F13: Column Totals | G13: =SUM(G11:G12) -> 0 | H13: =SUM(H11:H12) -> 0 | I13: =SUM(I11:I12) -> 9
A14: =Thermonix!A14 -> State | B14: =Thermonix!B14 -> Initial State (On ⇒ Home) | C14: =CombinedHumanGrading!C14 -> 0 | D14: ='GPT-5.5 Grading'!C14 -> 1
A15: =Thermonix!A15 -> State | B15: =Thermonix!B15 -> Home | C15: =CombinedHumanGrading!C15 -> 1 | D15: ='GPT-5.5 Grading'!C15 -> 1 | F15: Confusion Matrix (Transition) | L15: Cohen's Kappa (Transition)
A16: =Thermonix!A16 -> Transition | B16: =Thermonix!B16 -> after 14min 30sec (Home ⇒ Preparing Shutdown) | C16: =CombinedHumanGrading!C16 -> 1 | D16: ='GPT-5.5 Grading'!C16 -> 1 | F16: Transition | G16: 0 | H16: 0.5 | I16: 1 | J16: Row Totals | L16: Metric | M16: Value | N16: Note
A17: =Thermonix!A17 -> Transition | B17: =Thermonix!B17 -> start (Home ⇒ PromptToAdd) | C17: =CombinedHumanGrading!C17 -> 1 | D17: ='GPT-5.5 Grading'!C17 -> 1 | F17: 0 | G17: =COUNTIFS($A$2:$A$84,$F$16,$C$2:$C$84,$F17,$D$2:$D$84,G$16) -> 4 | H17: =COUNTIFS($A$2:$A$84,$F$16,$C$2:$C$84,$F17,$D$2:$D$84,H$16) -> 0 | I17: =COUNTIFS($A$2:$A$44,$F$16,$C$2:$C$44,$F17,$D$2:$D$44,I$16) + MAX(D46-C46,0) -> 0 | J17: =SUM(G17:I17) -> 4 | L17: Observed Agreement (Po) | M17: =(G17+H18+I19)/COUNTIF($A$2:$A$94,F16) -> 0.83333333 | N17: This sums the diagonal of your matrix divided by total rows.
A18: =Thermonix!A18 -> Guard | B18: =Thermonix!B18 -> [!bowlRemoved()] | C18: =CombinedHumanGrading!C18 -> 1 | D18: ='GPT-5.5 Grading'!C18 -> 1 | F18: 0.5 | G18: =COUNTIFS($A$2:$A$84,$F$16,$C$2:$C$84,$F18,$D$2:$D$84,G$16) -> 0 | H18: =COUNTIFS($A$2:$A$84,$F$16,$C$2:$C$84,$F18,$D$2:$D$84,H$16) -> 0 | I18: =COUNTIFS($A$2:$A$84,$F$16,$C$2:$C$84,$F18,$D$2:$D$84,I$16) -> 0 | J18: =SUM(G18:I18) -> 0 | L18: Expected Agreement (Pe) | M18: {=SUMPRODUCT(J17:J19/COUNTIF($A$2:$A$94,F16), TRANSPOSE(G20:I20)/COUNTIF($A$2:$A$94,F16))} -> 0.52469136 | N18: This computes the sum of row proportion times column proportion.
A19: =Thermonix!A19 -> Action | B19: =Thermonix!B19 -> setIngredients() | C19: =CombinedHumanGrading!C19 -> 1 | D19: ='GPT-5.5 Grading'!C19 -> 0.5 | F19: 1 | G19: =COUNTIFS($A$2:$A$44,$F$16,$C$2:$C$44,$F19,$D$2:$D$44,G$16)+MAX(C46-D46,0) -> 0 | H19: =COUNTIFS($A$2:$A$84,$F$16,$C$2:$C$84,$F19,$D$2:$D$84,H$16) -> 3 | I19: =COUNTIFS($A$2:$A$44,$F$16,$C$2:$C$44,$F19,$D$2:$D$44,I$16) + MIN(C46,D46) -> 11 | J19: =SUM(G19:I19) -> 14 | L19: Cohen's Kappa | M19: =(M17-M18)/(1-M18) -> 0.64935065 | N19: (Po - Pe) / (1 - Pe)
A20: =Thermonix!A20 -> State | B20: =Thermonix!B20 -> Preparing Shutdown | C20: =CombinedHumanGrading!C20 -> 1 | D20: ='GPT-5.5 Grading'!C20 -> 1 | F20: Column Totals | G20: =SUM(G17:G19) -> 4 | H20: =SUM(H17:H19) -> 3 | I20: =SUM(I17:I19) -> 11
A21: =Thermonix!A21 -> Transition | B21: =Thermonix!B21 -> after 30sec (Preparing Shutdown ⇒ Off) | C21: =CombinedHumanGrading!C21 -> 1 | D21: ='GPT-5.5 Grading'!C21 -> 1
A22: =Thermonix!A22 -> Transition | B22: =Thermonix!B22 -> cancel (Preparing Shutdown ⇒ Home) | C22: =CombinedHumanGrading!C22 -> 1 | D22: ='GPT-5.5 Grading'!C22 -> 1 | F22: Confusion Matrix (Composite State) | L22: Cohen's Kappa (Composite State)
A23: =Thermonix!A23 -> State | B23: =Thermonix!B23 -> PromptToAdd | C23: =CombinedHumanGrading!C23 -> 0 | D23: ='GPT-5.5 Grading'!C23 -> 1 | F23: Composite State | G23: 0 | H23: 0.5 | I23: 1 | J23: Row Totals | L23: Metric | M23: Value | N23: Note
A24: =Thermonix!A24 -> Transition | B24: =Thermonix!B24 -> next (PromptToAdd ⇒ PromptToAdd) | C24: =CombinedHumanGrading!C24 -> 0 | D24: ='GPT-5.5 Grading'!C24 -> 0 | F24: 0 | G24: =COUNTIFS($A$2:$A$84,$F$23,$C$2:$C$84,$F24,$D$2:$D$84,G$23) -> 1 | H24: =COUNTIFS($A$2:$A$84,$F$23,$C$2:$C$84,$F24,$D$2:$D$84,H$23) -> 1 | I24: =COUNTIFS($A$2:$A$44,$F$23,$C$2:$C$44,$F24,$D$2:$D$44,I$23) + MAX(D49-C49,0) -> 0 | J24: =SUM(G24:I24) -> 2 | L24: Observed Agreement (Po) | M24: =(G24+H25+I26)/COUNTIF($A$2:$A$94,F23) -> 0.5 | N24: This sums the diagonal of your matrix divided by total rows.
A25: =Thermonix!A25 -> Guard | B25: =Thermonix!B25 -> [weightCorrect() && moreIngredientsRequired()] | C25: =CombinedHumanGrading!C25 -> 0 | D25: ='GPT-5.5 Grading'!C25 -> 0 | F25: 0.5 | G25: =COUNTIFS($A$2:$A$84,$F$23,$C$2:$C$84,$F25,$D$2:$D$84,G$23) -> 0 | H25: =COUNTIFS($A$2:$A$84,$F$23,$C$2:$C$84,$F25,$D$2:$D$84,H$23) -> 0 | I25: =COUNTIFS($A$2:$A$84,$F$23,$C$2:$C$84,$F25,$D$2:$D$84,I$23) -> 0 | J25: =SUM(G25:I25) -> 0 | L25: Expected Agreement (Pe) | M25: {=SUMPRODUCT(J24:J26/COUNTIF($A$2:$A$94,F23), TRANSPOSE(G27:I27)/COUNTIF($A$2:$A$94,F23))} -> 0.5 | N25: This computes the sum of row proportion times column proportion.
A26: =Thermonix!A26 -> Action | B26: =Thermonix!B26 -> setIngredients() | C26: =CombinedHumanGrading!C26 -> 0 | D26: ='GPT-5.5 Grading'!C26 -> 0 | F26: 1 | G26: =COUNTIFS($A$2:$A$44,$F$23,$C$2:$C$44,$F26,$D$2:$D$44,G$23) + MAX(C49-D49,0) -> 0 | H26: =COUNTIFS($A$2:$A$84,$F$23,$C$2:$C$84,$F26,$D$2:$D$84,H$23) -> 0 | I26: =COUNTIFS($A$2:$A$44,$F$23,$C$2:$C$44,$F26,$D$2:$D$44,I$23) + MIN(C49,D49) -> 0 | J26: =SUM(G26:I26) -> 0 | L26: Cohen's Kappa | M26: =(M24-M25)/(1-M25) -> 0 | N26: (Po - Pe) / (1 - Pe)
A27: =Thermonix!A27 -> Transition | B27: =Thermonix!B27 -> next (PromptToAdd ⇒ Chop) | C27: =CombinedHumanGrading!C27 -> 1 | D27: ='GPT-5.5 Grading'!C27 -> 1 | F27: Column Totals | G27: =SUM(G24:G26) -> 1 | H27: =SUM(H24:H26) -> 1 | I27: =SUM(I24:I26) -> 0
A28: =Thermonix!A28 -> Guard | B28: =Thermonix!B28 -> [weightCorrect() && !moreIngredientsRequired()] | C28: =CombinedHumanGrading!C28 -> 0.5 | D28: ='GPT-5.5 Grading'!C28 -> 0.5
A29: =Thermonix!A29 -> Action | B29: =Thermonix!B29 -> setChoppingSpeedAndTime() | C29: =CombinedHumanGrading!C29 -> 0 | D29: ='GPT-5.5 Grading'!C29 -> 0.5 | F29: Confusion Matrix (Guard) | L29: Cohen's Kappa (Guard)
A30: =Thermonix!A30 -> State | B30: =Thermonix!B30 -> Chop | C30: =CombinedHumanGrading!C30 -> 1 | D30: ='GPT-5.5 Grading'!C30 -> 1 | F30: Guard | G30: 0 | H30: 0.5 | I30: 1 | J30: Row Totals | L30: Metric | M30: Value | N30: Note
A31: =Thermonix!A31 -> Transition | B31: =Thermonix!B31 -> next (Chop ⇒ PromptToAdd) | C31: =CombinedHumanGrading!C31 -> 0 | D31: ='GPT-5.5 Grading'!C31 -> 0 | F31: 0 | G31: =COUNTIFS($A$2:$A$84,$F$30,$C$2:$C$84,$F31,$D$2:$D$84,G$30) -> 4 | H31: =COUNTIFS($A$2:$A$84,$F$30,$C$2:$C$84,$F31,$D$2:$D$84,H$30) -> 0 | I31: =COUNTIFS($A$2:$A$44,$F$30,$C$2:$C$44,$F31,$D$2:$D$44,I$30) + MAX(D47-C47,0) -> 0 | J31: =SUM(G31:I31) -> 4 | L31: Observed Agreement (Po) | M31: =(G31+H32+I33)/COUNTIF($A$2:$A$94,F30) -> 0.875 | N31: This sums the diagonal of your matrix divided by total rows.
A32: =Thermonix!A32 -> Guard | B32: =Thermonix!B32 -> [choppingTimeDone && moreIngredientsRequired()] | C32: =CombinedHumanGrading!C32 -> 0 | D32: ='GPT-5.5 Grading'!C32 -> 0 | F32: 0.5 | G32: =COUNTIFS($A$2:$A$84,$F$30,$C$2:$C$84,$F32,$D$2:$D$84,G$30) -> 0 | H32: =COUNTIFS($A$2:$A$84,$F$30,$C$2:$C$84,$F32,$D$2:$D$84,H$30) -> 1 | I32: =COUNTIFS($A$2:$A$84,$F$30,$C$2:$C$84,$F32,$D$2:$D$84,I$30) -> 1 | J32: =SUM(G32:I32) -> 2 | L32: Expected Agreement (Pe) | M32: {=SUMPRODUCT(J31:J33/COUNTIF($A$2:$A$94,F30), TRANSPOSE(G34:I34)/COUNTIF($A$2:$A$94,F30))} -> 0.375 | N32: This computes the sum of row proportion times column proportion.
A33: =Thermonix!A33 -> Action | B33: =Thermonix!B33 -> setIngredients() | C33: =CombinedHumanGrading!C33 -> 0 | D33: ='GPT-5.5 Grading'!C33 -> 0 | F33: 1 | G33: =COUNTIFS($A$2:$A$44,$F$30,$C$2:$C$44,$F33,$D$2:$D$44,G$30) + MAX(C47-D47,0) -> 0 | H33: =COUNTIFS($A$2:$A$84,$F$30,$C$2:$C$84,$F33,$D$2:$D$84,H$30) -> 0 | I33: =COUNTIFS($A$2:$A$44,$F$30,$C$2:$C$44,$F33,$D$2:$D$44,I$30) + MIN(C47,D47) -> 2 | J33: =SUM(G33:I33) -> 2 | L33: Cohen's Kappa | M33: =(M31-M32)/(1-M32) -> 0.8 | N33: (Po - Pe) / (1 - Pe)
A34: =Thermonix!A34 -> Transition | B34: =Thermonix!B34 -> next (Chop ⇒ Cook) | C34: =CombinedHumanGrading!C34 -> 1 | D34: ='GPT-5.5 Grading'!C34 -> 1 | F34: Column Totals | G34: =SUM(G31:G33) -> 4 | H34: =SUM(H31:H33) -> 1 | I34: =SUM(I31:I33) -> 3
A35: =Thermonix!A35 -> Guard | B35: =Thermonix!B35 -> [choppingTimeDone && !moreIngredientsRequired()] | C35: =CombinedHumanGrading!C35 -> 0 | D35: ='GPT-5.5 Grading'!C35 -> 0
A36: =Thermonix!A36 -> Action | B36: =Thermonix!B36 -> setCookingSpeedAndTime() | C36: =CombinedHumanGrading!C36 -> 0 | D36: ='GPT-5.5 Grading'!C36 -> 0.5 | F36: Confusion Matrix (Action) | L36: Cohen's Kappa (Action)
A37: =Thermonix!A37 -> State | B37: =Thermonix!B37 -> Cook | C37: =CombinedHumanGrading!C37 -> 1 | D37: ='GPT-5.5 Grading'!C37 -> 1 | F37: Action | G37: 0 | H37: 0.5 | I37: 1 | J37: Row Totals | L37: Metric | M37: Value | N37: Note
A38: =Thermonix!A38 -> Transition | B38: =Thermonix!B38 -> after choppingTime (Cook ⇒ PromptToAdd) | C38: =CombinedHumanGrading!C38 -> 1 | D38: ='GPT-5.5 Grading'!C38 -> 1 | F38: 0 | G38: =COUNTIFS($A$2:$A$84,$F$37,$C$2:$C$84,$F38,$D$2:$D$84,G$37) -> 3 | H38: =COUNTIFS($A$2:$A$84,$F$37,$C$2:$C$84,$F38,$D$2:$D$84,H$37) -> 3 | I38: =COUNTIFS($A$2:$A$44,$F$37,$C$2:$C$44,$F38,$D$2:$D$44,I$37)+MAX(D48-C48,0) -> 0 | J38: =SUM(G38:I38) -> 6 | L38: Observed Agreement (Po) | M38: =(G38+H39+I40)/COUNTIF($A$2:$A$94,F37) -> 0.42857143 | N38: This sums the diagonal of your matrix divided by total rows.
A39: =Thermonix!A39 -> Guard | B39: =Thermonix!B39 -> [choppingTimeDone && moreIngredientsRequired()] | C39: =CombinedHumanGrading!C39 -> 0.5 | D39: ='GPT-5.5 Grading'!C39 -> 1 | F39: 0.5 | G39: =COUNTIFS($A$2:$A$84,$F$37,$C$2:$C$84,$F39,$D$2:$D$84,G$37) -> 0 | H39: =COUNTIFS($A$2:$A$84,$F$37,$C$2:$C$84,$F39,$D$2:$D$84,H$37) -> 0 | I39: =COUNTIFS($A$2:$A$84,$F$37,$C$2:$C$84,$F39,$D$2:$D$84,I$37) -> 0 | J39: =SUM(G39:I39) -> 0 | L39: Expected Agreement (Pe) | M39: {=SUMPRODUCT(J38:J40/COUNTIF($A$2:$A$94,F37), TRANSPOSE(G41:I41)/COUNTIF($A$2:$A$94,F37))} -> 0.36734694 | N39: This computes the sum of row proportion times column proportion.
A40: =Thermonix!A40 -> Action | B40: =Thermonix!B40 -> setIngredients() | C40: =CombinedHumanGrading!C40 -> 0 | D40: ='GPT-5.5 Grading'!C40 -> 0.5 | F40: 1 | G40: =COUNTIFS($A$2:$A$44,$F$37,$C$2:$C$44,$F40,$D$2:$D$44,G$37)+MAX(C48-D48,0) -> 0 | H40: =COUNTIFS($A$2:$A$84,$F$37,$C$2:$C$84,$F40,$D$2:$D$84,H$37) -> 1 | I40: =COUNTIFS($A$2:$A$44,$F$37,$C$2:$C$44,$F40,$D$2:$D$44,I$37) + MIN(C48,D48) -> 0 | J40: =SUM(G40:I40) -> 1 | L40: Cohen's Kappa | M40: =(M38-M39)/(1-M39) -> 0.096774194 | N40: (Po - Pe) / (1 - Pe)
...

Sheet Weighted Cohens Kappa
A1: Type | B1: Element | C1: CombinedHumanGrading | D1: GPT-5.5 | F1: Confusion Matrix | L1: Weight Matrix
A2: =Thermonix!A2 -> State | B2: =Thermonix!B2 -> initial state (⇒ TransportationMode) | C2: =CombinedHumanGrading!C2 -> 1 | D2: ='GPT-5.5 Grading'!C2 -> 1 | F2: Global | G2: 0 | H2: 0.5 | I2: 1 | J2: Row Totals | L2: Global | M2: 0 | N2: 0.5 | O2: 1 | Q2: Global | R2: 0 | S2: 0.5 | T2: 1 | V2: ="Metrics" & " " & F2 -> Metrics Global | W2: Value | X2: Note
A3: =Thermonix!A3 -> State | B3: =Thermonix!B3 -> TransportationMode | C3: =CombinedHumanGrading!C3 -> 1 | D3: ='GPT-5.5 Grading'!C3 -> 1 | F3: 0 | G3: =COUNTIFS($C$2:$C$84, $F3, $D$2:$D$84, G$2) -> 16 | H3: =COUNTIFS($C$2:$C$44, $F3, $D$2:$D$44, H$2) -> 4 | I3: =COUNTIFS($C$2:$C$44, $F3, $D$2:$D$44, I$2)+MAX(D45-C45,0)+MAX(D46-C46,0)+MAX(D47-C47,0)+MAX(D48-C48,0)+MAX(D49-C49,0)+MAX(D50-C50,0)+MAX(D51-C51,0) -> 2 | J3: =SUM(G3:I3) -> 22 | L3: 0 | M3: =ABS(G$2-$F3)/1 -> 0 | N3: =ABS(H$2-$F3)/1 -> 0.5 | O3: =ABS(I$2-$F3)/1 -> 1 | Q3: 0 | R3: =($J3/$J$6) * (G$6/$J$6) -> 0.1408 | S3: =($J3/$J$6) * (H$6/$J$6) -> 0.0792 | T3: =($J3/$J$6) * (I$6/$J$6) -> 0.22 | V3: Observed Weighted Disagreement (D_obs) | W3: =SUMPRODUCT(G3:I5, M3:O5) /$J$6 -> 0.13 | X3: Sum of (confusion-matrix counts × weights) divided by total items.
A4: =Thermonix!A4 -> Transition | B4: =Thermonix!B4 -> selectorPressed (TransportationMode ⇒ On) | C4: =CombinedHumanGrading!C4 -> 1 | D4: ='GPT-5.5 Grading'!C4 -> 1 | F4: 0.5 | G4: =COUNTIFS($C$2:$C$44, $F4, $D$2:$D$44, G$2) -> 0 | H4: =COUNTIFS($C$2:$C$44, $F4, $D$2:$D$44, H$2) -> 1 | I4: =COUNTIFS($C$2:$C$44, $F4, $D$2:$D$44, I$2) -> 1 | J4: =SUM(G4:I4) -> 2 | L4: 0.5 | M4: =ABS(G$2-$F4)/1 -> 0.5 | N4: =ABS(H$2-$F4)/3 -> 0 | O4: =ABS(I$2-$F4)/1 -> 0.5 | Q4: 0.5 | R4: =($J4/$J$6) * (G$6/$J$6) -> 0.0128 | S4: =($J4/$J$6) * (H$6/$J$6) -> 0.0072 | T4: =($J4/$J$6) * (I$6/$J$6) -> 0.02 | V4: Expected Weighted Disagreement (D_exp) | W4: =SUMPRODUCT(R3:T5, M3:O5) -> 0.4892 | X4: Sum of (expected cell proportions × weights) under chance agreement.
A5: =Thermonix!A5 -> State | B5: =Thermonix!B5 -> PreparingOff | C5: =CombinedHumanGrading!C5 -> 1 | D5: ='GPT-5.5 Grading'!C5 -> 1 | F5: 1 | G5: =COUNTIFS($C$2:$C$44, $F5, $D$2:$D$44, G$2)+MAX(C45-D45,0)+MAX(C46-D46,0)+MAX(C47-D47,0)+MAX(C48-D48,0)+MAX(C49-D49,0)+MAX(C50-D50,0)+MAX(C51-D51,0) -> 0 | H5: =COUNTIFS($C$2:$C$44, $F5, $D$2:$D$44, H$2) -> 4 | I5: =COUNTIFS($C$2:$C$44, $F5, $D$2:$D$44, I$2)+ SUM(MIN(C45,D45), MIN(C46,D46), MIN(C47,D47), MIN(C48,D48), MIN(C49,D49), MIN(C50,D50), MIN(C51,D51)) -> 22 | J5: =SUM(G5:I5) -> 26 | L5: 1 | M5: =ABS(G$2-$F5)/1 -> 1 | N5: =ABS(H$2-$F5)/1 -> 0.5 | O5: =ABS(I$2-$F5)/1 -> 0 | Q5: 1 | R5: =($J5/$J$6) * (G$6/$J$6) -> 0.1664 | S5: =($J5/$J$6) * (H$6/$J$6) -> 0.0936 | T5: =($J5/$J$6) * (I$6/$J$6) -> 0.26 | V5: Cohen's Kappa | W5: =1-W3/W4 -> 0.73426002 | X5: 1 - (D_obs / D_exp)
A6: =Thermonix!A6 -> Transition | B6: =Thermonix!B6 -> selectorReleased (PreparingOff ⇒ On) | C6: =CombinedHumanGrading!C6 -> 1 | D6: ='GPT-5.5 Grading'!C6 -> 1 | F6: Column Totals | G6: =SUM(G3:G5) -> 16 | H6: =SUM(H3:H5) -> 9 | I6: =SUM(I3:I5) -> 25 | J6: =SUM(G3:I5) -> 50
A7: =Thermonix!A7 -> Transition | B7: =Thermonix!B7 -> after 5sec (PreparingOff ⇒ Off) | C7: =CombinedHumanGrading!C7 -> 1 | D7: ='GPT-5.5 Grading'!C7 -> 0.5
A8: =Thermonix!A8 -> State | B8: =Thermonix!B8 -> Off | C8: =CombinedHumanGrading!C8 -> 1 | D8: ='GPT-5.5 Grading'!C8 -> 1 | F8: Confusion Matrix (State)
A9: =Thermonix!A9 -> Transition | B9: =Thermonix!B9 -> selectorPressed (Off ⇒ On) | C9: =CombinedHumanGrading!C9 -> 1 | D9: ='GPT-5.5 Grading'!C9 -> 1 | F9: State | G9: 0 | H9: 0.5 | I9: 1 | J9: Row Totals | L9: Global | M9: 0 | N9: 0.5 | O9: 1 | Q9: Global | R9: 0 | S9: 0.5 | T9: 1 | V9: ="Metrics" & " " & F9 -> Metrics State | W9: Value | X9: Note
A10: =Thermonix!A10 -> Composite State | B10: =Thermonix!B10 -> On | C10: =CombinedHumanGrading!C10 -> 0 | D10: ='GPT-5.5 Grading'!C10 -> 0.5 | F10: 0 | G10: =COUNTIFS($A$2:$A$84,$F$9,$C$2:$C$84,$F10,$D$2:$D$84,G$16) -> 1 | H10: =COUNTIFS($A$2:$A$84,$F$9,$C$2:$C$84,$F10,$D$2:$D$84,H$16) -> 0 | I10: =COUNTIFS($A$2:$A$44,$F$9,$C$2:$C$44,$F10,$D$2:$D$44,I$16) + MAX(D39-C39,0) -> 2.5 | J10: =SUM(G10:I10) -> 3.5 | L10: 0 | M10: =ABS(G$2-$F10)/1 -> 0 | N10: =ABS(H$2-$F10)/1 -> 0.5 | O10: =ABS(I$2-$F10)/1 -> 1 | Q10: 0 | R10: =($J10/$J$13) * (G$13/$J$13) -> 0 | S10: =($J10/$J$13) * (H$13/$J$13) -> 0 | T10: =($J10/$J$13) * (I$13/$J$13) -> 0.38888889 | V10: Observed Weighted Disagreement (D_obs) | W10: =SUMPRODUCT(G10:I12, M10:O12) /$J$13 -> 0.27777778 | X10: Sum of (confusion-matrix counts × weights) divided by total items.
A11: =Thermonix!A11 -> History State | B11: =Thermonix!B11 -> History State for On | C11: =CombinedHumanGrading!C11 -> 0 | D11: ='GPT-5.5 Grading'!C11 -> 0 | F11: 0.5 | G11: =COUNTIFS($A$2:$A$84,$F$9,$C$2:$C$84,$F11,$D$2:$D$84,G$9) -> 0 | H11: =COUNTIFS($A$2:$A$84,$F$9,$C$2:$C$84,$F11,$D$2:$D$84,H$9) -> 0 | I11: =COUNTIFS($A$2:$A$84,$F$9,$C$2:$C$84,$F11,$D$2:$D$84,I$9) -> 0 | J11: =SUM(G11:I11) -> 0 | L11: 0.5 | M11: =ABS(G$2-$F11)/1 -> 0.5 | N11: =ABS(H$2-$F11)/3 -> 0 | O11: =ABS(I$2-$F11)/1 -> 0.5 | Q11: 0.5 | R11: =($J11/$J$13) * (G$13/$J$13) -> 0 | S11: =($J11/$J$13) * (H$13/$J$13) -> 0 | T11: =($J11/$J$13) * (I$13/$J$13) -> 0 | V11: Expected Weighted Disagreement (D_exp) | W11: =SUMPRODUCT(R10:T12, M10:O12) -> 0.38888889 | X11: Sum of (expected cell proportions × weights) under chance agreement.
A12: =Thermonix!A12 -> Transition | B12: =Thermonix!B12 -> selectorHeld (On ⇒ PreparingOff) | C12: =CombinedHumanGrading!C12 -> 1 | D12: ='GPT-5.5 Grading'!C12 -> 0.5 | F12: 1 | G12: =COUNTIFS($A$2:$A$44,$F$9,$C$2:$C$44,$F12,$D$2:$D$44,G$9)+MAX(C45-D45,0) -> 0 | H12: =COUNTIFS($A$2:$A$84,$F$9,$C$2:$C$84,$F12,$D$2:$D$84,H$9) -> 0 | I12: =COUNTIFS($A$2:$A$44,$F$9,$C$2:$C$44,$F12,$D$2:$D$44,I$9)+MIN(C45-D45) -> 9 | J12: =SUM(G12:I12) -> 9 | L12: 1 | M12: =ABS(G$2-$F12)/1 -> 1 | N12: =ABS(H$2-$F12)/1 -> 0.5 | O12: =ABS(I$2-$F12)/1 -> 0 | Q12: 1 | R12: =($J12/$J$13) * (G$13/$J$13) -> 0 | S12: =($J12/$J$13) * (H$13/$J$13) -> 0 | T12: =($J12/$J$13) * (I$13/$J$13) -> 1 | V12: Cohen's Kappa | W12: =1-W10/W11 -> 0.28571429 | X12: 1 - (D_obs / D_exp)
A13: =Thermonix!A13 -> Transition | B13: =Thermonix!B13 -> bowlRemoved (On ⇒ On) | C13: =CombinedHumanGrading!C13 -> 1 | D13: ='GPT-5.5 Grading'!C13 -> 0.5 | F13: Column Totals | G13: =SUM(G11:G12) -> 0 | H13: =SUM(H11:H12) -> 0 | I13: =SUM(I11:I12) -> 9 | J13: =SUM(G11:I12) -> 9
A14: =Thermonix!A14 -> State | B14: =Thermonix!B14 -> Initial State (On ⇒ Home) | C14: =CombinedHumanGrading!C14 -> 0 | D14: ='GPT-5.5 Grading'!C14 -> 1
A15: =Thermonix!A15 -> State | B15: =Thermonix!B15 -> Home | C15: =CombinedHumanGrading!C15 -> 1 | D15: ='GPT-5.5 Grading'!C15 -> 1 | F15: Confusion Matrix (Transition)
A16: =Thermonix!A16 -> Transition | B16: =Thermonix!B16 -> after 14min 30sec (Home ⇒ Preparing Shutdown) | C16: =CombinedHumanGrading!C16 -> 1 | D16: ='GPT-5.5 Grading'!C16 -> 1 | F16: Transition | G16: 0 | H16: 0.5 | I16: 1 | J16: Row Totals | L16: Global | M16: 0 | N16: 0.5 | O16: 1 | Q16: Global | R16: 0 | S16: 0.5 | T16: 1 | V16: ="Metrics" & " " & F16 -> Metrics Transition | W16: Value | X16: Note
A17: =Thermonix!A17 -> Transition | B17: =Thermonix!B17 -> start (Home ⇒ PromptToAdd) | C17: =CombinedHumanGrading!C17 -> 1 | D17: ='GPT-5.5 Grading'!C17 -> 1 | F17: 0 | G17: =COUNTIFS($A$2:$A$84,$F$16,$C$2:$C$84,$F17,$D$2:$D$84,G$16) -> 4 | H17: =COUNTIFS($A$2:$A$84,$F$16,$C$2:$C$84,$F17,$D$2:$D$84,H$16) -> 0 | I17: =COUNTIFS($A$2:$A$44,$F$16,$C$2:$C$44,$F17,$D$2:$D$44,I$16) + MAX(D46-C46,0) -> 0 | J17: =SUM(G17:I17) -> 4 | L17: 0 | M17: =ABS(G$2-$F17)/1 -> 0 | N17: =ABS(H$2-$F17)/1 -> 0.5 | O17: =ABS(I$2-$F17)/1 -> 1 | Q17: 0 | R17: =($J17/$J$20) * (G$20/$J$20) -> 0.049382716 | S17: =($J17/$J$20) * (H$20/$J$20) -> 0.037037037 | T17: =($J17/$J$20) * (I$20/$J$20) -> 0.13580247 | V17: Observed Weighted Disagreement (D_obs) | W17: =SUMPRODUCT(G17:I19, M17:O19) /$J$20 -> 0.083333333 | X17: Sum of (confusion-matrix counts × weights) divided by total items.
A18: =Thermonix!A18 -> Guard | B18: =Thermonix!B18 -> [!bowlRemoved()] | C18: =CombinedHumanGrading!C18 -> 1 | D18: ='GPT-5.5 Grading'!C18 -> 1 | F18: 0.5 | G18: =COUNTIFS($A$2:$A$84,$F$16,$C$2:$C$84,$F18,$D$2:$D$84,G$16) -> 0 | H18: =COUNTIFS($A$2:$A$84,$F$16,$C$2:$C$84,$F18,$D$2:$D$84,H$16) -> 0 | I18: =COUNTIFS($A$2:$A$84,$F$16,$C$2:$C$84,$F18,$D$2:$D$84,I$16) -> 0 | J18: =SUM(G18:I18) -> 0 | L18: 0.5 | M18: =ABS(G$2-$F18)/1 -> 0.5 | N18: =ABS(H$2-$F18)/3 -> 0 | O18: =ABS(I$2-$F18)/1 -> 0.5 | Q18: 0.5 | R18: =($J18/$J$20) * (G$20/$J$20) -> 0 | S18: =($J18/$J$20) * (H$20/$J$20) -> 0 | T18: =($J18/$J$20) * (I$20/$J$20) -> 0 | V18: Expected Weighted Disagreement (D_exp) | W18: =SUMPRODUCT(R17:T19, M17:O19) -> 0.39197531 | X18: Sum of (expected cell proportions × weights) under chance agreement.
A19: =Thermonix!A19 -> Action | B19: =Thermonix!B19 -> setIngredients() | C19: =CombinedHumanGrading!C19 -> 1 | D19: ='GPT-5.5 Grading'!C19 -> 0.5 | F19: 1 | G19: =COUNTIFS($A$2:$A$44,$F$16,$C$2:$C$44,$F19,$D$2:$D$44,G$16)+MAX(C46-D46,0) -> 0 | H19: =COUNTIFS($A$2:$A$84,$F$16,$C$2:$C$84,$F19,$D$2:$D$84,H$16) -> 3 | I19: =COUNTIFS($A$2:$A$44,$F$16,$C$2:$C$44,$F19,$D$2:$D$44,I$16) + MIN(C46,D46) -> 11 | J19: =SUM(G19:I19) -> 14 | L19: 1 | M19: =ABS(G$2-$F19)/1 -> 1 | N19: =ABS(H$2-$F19)/1 -> 0.5 | O19: =ABS(I$2-$F19)/1 -> 0 | Q19: 1 | R19: =($J19/$J$20) * (G$20/$J$20) -> 0.17283951 | S19: =($J19/$J$20) * (H$20/$J$20) -> 0.12962963 | T19: =($J19/$J$20) * (I$20/$J$20) -> 0.47530864 | V19: Cohen's Kappa | W19: =1-W17/W18 -> 0.78740157 | X19: 1 - (D_obs / D_exp)
A20: =Thermonix!A20 -> State | B20: =Thermonix!B20 -> Preparing Shutdown | C20: =CombinedHumanGrading!C20 -> 1 | D20: ='GPT-5.5 Grading'!C20 -> 1 | F20: Column Totals | G20: =SUM(G17:G19) -> 4 | H20: =SUM(H17:H19) -> 3 | I20: =SUM(I17:I19) -> 11 | J20: =SUM(G17:I19) -> 18
A21: =Thermonix!A21 -> Transition | B21: =Thermonix!B21 -> after 30sec (Preparing Shutdown ⇒ Off) | C21: =CombinedHumanGrading!C21 -> 1 | D21: ='GPT-5.5 Grading'!C21 -> 1
A22: =Thermonix!A22 -> Transition | B22: =Thermonix!B22 -> cancel (Preparing Shutdown ⇒ Home) | C22: =CombinedHumanGrading!C22 -> 1 | D22: ='GPT-5.5 Grading'!C22 -> 1 | F22: Confusion Matrix (Composite State)
A23: =Thermonix!A23 -> State | B23: =Thermonix!B23 -> PromptToAdd | C23: =CombinedHumanGrading!C23 -> 0 | D23: ='GPT-5.5 Grading'!C23 -> 1 | F23: Composite State | G23: 0 | H23: 0.5 | I23: 1 | J23: Row Totals | L23: Global | M23: 0 | N23: 0.5 | O23: 1 | Q23: Global | R23: 0 | S23: 0.5 | T23: 1 | V23: ="Metrics" & " " & F23 -> Metrics Composite State | W23: Value | X23: Note
A24: =Thermonix!A24 -> Transition | B24: =Thermonix!B24 -> next (PromptToAdd ⇒ PromptToAdd) | C24: =CombinedHumanGrading!C24 -> 0 | D24: ='GPT-5.5 Grading'!C24 -> 0 | F24: 0 | G24: =COUNTIFS($A$2:$A$84,$F$23,$C$2:$C$84,$F24,$D$2:$D$84,G$23) -> 1 | H24: =COUNTIFS($A$2:$A$84,$F$23,$C$2:$C$84,$F24,$D$2:$D$84,H$23) -> 1 | I24: =COUNTIFS($A$2:$A$44,$F$23,$C$2:$C$44,$F24,$D$2:$D$44,I$23) + MAX(D49-C49,0) -> 0 | J24: =SUM(G24:I24) -> 2 | L24: 0 | M24: =ABS(G$2-$F24)/1 -> 0 | N24: =ABS(H$2-$F24)/1 -> 0.5 | O24: =ABS(I$2-$F24)/1 -> 1 | Q24: 0 | R24: =($J24/$J$27) * (G$27/$J$27) -> 0.5 | S24: =($J24/$J$27) * (H$27/$J$27) -> 0.5 | T24: =($J24/$J$27) * (I$27/$J$27) -> 0 | V24: Observed Weighted Disagreement (D_obs) | W24: =SUMPRODUCT(G24:I26, M24:O26) /$J$27 -> 0.25 | X24: Sum of (confusion-matrix counts × weights) divided by total items.
A25: =Thermonix!A25 -> Guard | B25: =Thermonix!B25 -> [weightCorrect() && moreIngredientsRequired()] | C25: =CombinedHumanGrading!C25 -> 0 | D25: ='GPT-5.5 Grading'!C25 -> 0 | F25: 0.5 | G25: =COUNTIFS($A$2:$A$84,$F$23,$C$2:$C$84,$F25,$D$2:$D$84,G$23) -> 0 | H25: =COUNTIFS($A$2:$A$84,$F$23,$C$2:$C$84,$F25,$D$2:$D$84,H$23) -> 0 | I25: =COUNTIFS($A$2:$A$84,$F$23,$C$2:$C$84,$F25,$D$2:$D$84,I$23) -> 0 | J25: =SUM(G25:I25) -> 0 | L25: 0.5 | M25: =ABS(G$2-$F25)/1 -> 0.5 | N25: =ABS(H$2-$F25)/3 -> 0 | O25: =ABS(I$2-$F25)/1 -> 0.5 | Q25: 0.5 | R25: =($J25/$J$27) * (G$27/$J$27) -> 0 | S25: =($J25/$J$27) * (H$27/$J$27) -> 0 | T25: =($J25/$J$27) * (I$27/$J$27) -> 0 | V25: Expected Weighted Disagreement (D_exp) | W25: =SUMPRODUCT(R24:T26, M24:O26) -> 0.25 | X25: Sum of (expected cell proportions × weights) under chance agreement.
A26: =Thermonix!A26 -> Action | B26: =Thermonix!B26 -> setIngredients() | C26: =CombinedHumanGrading!C26 -> 0 | D26: ='GPT-5.5 Grading'!C26 -> 0 | F26: 1 | G26: =COUNTIFS($A$2:$A$44,$F$23,$C$2:$C$44,$F26,$D$2:$D$44,G$23) + MAX(C49-D49,0) -> 0 | H26: =COUNTIFS($A$2:$A$84,$F$23,$C$2:$C$84,$F26,$D$2:$D$84,H$23) -> 0 | I26: =COUNTIFS($A$2:$A$44,$F$23,$C$2:$C$44,$F26,$D$2:$D$44,I$23) + MIN(C49,D49) -> 0 | J26: =SUM(G26:I26) -> 0 | L26: 1 | M26: =ABS(G$2-$F26)/1 -> 1 | N26: =ABS(H$2-$F26)/1 -> 0.5 | O26: =ABS(I$2-$F26)/1 -> 0 | Q26: 1 | R26: =($J26/$J$27) * (G$27/$J$27) -> 0 | S26: =($J26/$J$27) * (H$27/$J$27) -> 0 | T26: =($J26/$J$27) * (I$27/$J$27) -> 0 | V26: Cohen's Kappa | W26: =1-W24/W25 -> 0 | X26: 1 - (D_obs / D_exp)
A27: =Thermonix!A27 -> Transition | B27: =Thermonix!B27 -> next (PromptToAdd ⇒ Chop) | C27: =CombinedHumanGrading!C27 -> 1 | D27: ='GPT-5.5 Grading'!C27 -> 1 | F27: Column Totals | G27: =SUM(G24:G26) -> 1 | H27: =SUM(H24:H26) -> 1 | I27: =SUM(I24:I26) -> 0 | J27: =SUM(G24:I26) -> 2
A28: =Thermonix!A28 -> Guard | B28: =Thermonix!B28 -> [weightCorrect() && !moreIngredientsRequired()] | C28: =CombinedHumanGrading!C28 -> 0.5 | D28: ='GPT-5.5 Grading'!C28 -> 0.5
A29: =Thermonix!A29 -> Action | B29: =Thermonix!B29 -> setChoppingSpeedAndTime() | C29: =CombinedHumanGrading!C29 -> 0 | D29: ='GPT-5.5 Grading'!C29 -> 0.5 | F29: Confusion Matrix (Guard)
A30: =Thermonix!A30 -> State | B30: =Thermonix!B30 -> Chop | C30: =CombinedHumanGrading!C30 -> 1 | D30: ='GPT-5.5 Grading'!C30 -> 1 | F30: Guard | G30: 0 | H30: 0.5 | I30: 1 | J30: Row Totals | L30: Global | M30: 0 | N30: 0.5 | O30: 1 | Q30: Global | R30: 0 | S30: 0.5 | T30: 1 | V30: ="Metrics" & " " & F30 -> Metrics Guard | W30: Value | X30: Note
A31: =Thermonix!A31 -> Transition | B31: =Thermonix!B31 -> next (Chop ⇒ PromptToAdd) | C31: =CombinedHumanGrading!C31 -> 0 | D31: ='GPT-5.5 Grading'!C31 -> 0 | F31: 0 | G31: =COUNTIFS($A$2:$A$84,$F$30,$C$2:$C$84,$F31,$D$2:$D$84,G$30) -> 4 | H31: =COUNTIFS($A$2:$A$84,$F$30,$C$2:$C$84,$F31,$D$2:$D$84,H$30) -> 0 | I31: =COUNTIFS($A$2:$A$44,$F$30,$C$2:$C$44,$F31,$D$2:$D$44,I$30) + MAX(D47-C47,0) -> 0 | J31: =SUM(G31:I31) -> 4 | L31: 0 | M31: =ABS(G$2-$F31)/1 -> 0 | N31: =ABS(H$2-$F31)/1 -> 0.5 | O31: =ABS(I$2-$F31)/1 -> 1 | Q31: 0 | R31: =($J31/$J$34) * (G$34/$J$34) -> 0.25 | S31: =($J31/$J$34) * (H$34/$J$34) -> 0.0625 | T31: =($J31/$J$34) * (I$34/$J$34) -> 0.1875 | V31: Observed Weighted Disagreement (D_obs) | W31: =SUMPRODUCT(G31:I33, M31:O33) /$J$34 -> 0.0625 | X31: Sum of (confusion-matrix counts × weights) divided by total items.
A32: =Thermonix!A32 -> Guard | B32: =Thermonix!B32 -> [choppingTimeDone && moreIngredientsRequired()] | C32: =CombinedHumanGrading!C32 -> 0 | D32: ='GPT-5.5 Grading'!C32 -> 0 | F32: 0.5 | G32: =COUNTIFS($A$2:$A$84,$F$30,$C$2:$C$84,$F32,$D$2:$D$84,G$30) -> 0 | H32: =COUNTIFS($A$2:$A$84,$F$30,$C$2:$C$84,$F32,$D$2:$D$84,H$30) -> 1 | I32: =COUNTIFS($A$2:$A$84,$F$30,$C$2:$C$84,$F32,$D$2:$D$84,I$30) -> 1 | J32: =SUM(G32:I32) -> 2 | L32: 0.5 | M32: =ABS(G$2-$F32)/1 -> 0.5 | N32: =ABS(H$2-$F32)/3 -> 0 | O32: =ABS(I$2-$F32)/1 -> 0.5 | Q32: 0.5 | R32: =($J32/$J$34) * (G$34/$J$34) -> 0.125 | S32: =($J32/$J$34) * (H$34/$J$34) -> 0.03125 | T32: =($J32/$J$34) * (I$34/$J$34) -> 0.09375 | V32: Expected Weighted Disagreement (D_exp) | W32: =SUMPRODUCT(R31:T33, M31:O33) -> 0.46875 | X32: Sum of (expected cell proportions × weights) under chance agreement.
A33: =Thermonix!A33 -> Action | B33: =Thermonix!B33 -> setIngredients() | C33: =CombinedHumanGrading!C33 -> 0 | D33: ='GPT-5.5 Grading'!C33 -> 0 | F33: 1 | G33: =COUNTIFS($A$2:$A$44,$F$30,$C$2:$C$44,$F33,$D$2:$D$44,G$30) + MAX(C47-D47,0) -> 0 | H33: =COUNTIFS($A$2:$A$84,$F$30,$C$2:$C$84,$F33,$D$2:$D$84,H$30) -> 0 | I33: =COUNTIFS($A$2:$A$44,$F$30,$C$2:$C$44,$F33,$D$2:$D$44,I$30) + MIN(C47,D47) -> 2 | J33: =SUM(G33:I33) -> 2 | L33: 1 | M33: =ABS(G$2-$F33)/1 -> 1 | N33: =ABS(H$2-$F33)/1 -> 0.5 | O33: =ABS(I$2-$F33)/1 -> 0 | Q33: 1 | R33: =($J33/$J$34) * (G$34/$J$34) -> 0.125 | S33: =($J33/$J$34) * (H$34/$J$34) -> 0.03125 | T33: =($J33/$J$34) * (I$34/$J$34) -> 0.09375 | V33: Cohen's Kappa | W33: =1-W31/W32 -> 0.86666667 | X33: 1 - (D_obs / D_exp)
A34: =Thermonix!A34 -> Transition | B34: =Thermonix!B34 -> next (Chop ⇒ Cook) | C34: =CombinedHumanGrading!C34 -> 1 | D34: ='GPT-5.5 Grading'!C34 -> 1 | F34: Column Totals | G34: =SUM(G31:G33) -> 4 | H34: =SUM(H31:H33) -> 1 | I34: =SUM(I31:I33) -> 3 | J34: =SUM(G31:I33) -> 8
A35: =Thermonix!A35 -> Guard | B35: =Thermonix!B35 -> [choppingTimeDone && !moreIngredientsRequired()] | C35: =CombinedHumanGrading!C35 -> 0 | D35: ='GPT-5.5 Grading'!C35 -> 0
A36: =Thermonix!A36 -> Action | B36: =Thermonix!B36 -> setCookingSpeedAndTime() | C36: =CombinedHumanGrading!C36 -> 0 | D36: ='GPT-5.5 Grading'!C36 -> 0.5 | F36: Confusion Matrix (Action)
A37: =Thermonix!A37 -> State | B37: =Thermonix!B37 -> Cook | C37: =CombinedHumanGrading!C37 -> 1 | D37: ='GPT-5.5 Grading'!C37 -> 1 | F37: Action | G37: 0 | H37: 0.5 | I37: 1 | J37: Row Totals | L37: Global | M37: 0 | N37: 0.5 | O37: 1 | Q37: Global | R37: 0 | S37: 0.5 | T37: 1 | V37: ="Metrics" & " " & F37 -> Metrics Action | W37: Value | X37: Note
A38: =Thermonix!A38 -> Transition | B38: =Thermonix!B38 -> after choppingTime (Cook ⇒ PromptToAdd) | C38: =CombinedHumanGrading!C38 -> 1 | D38: ='GPT-5.5 Grading'!C38 -> 1 | F38: 0 | G38: =COUNTIFS($A$2:$A$84,$F$37,$C$2:$C$84,$F38,$D$2:$D$84,G$37) -> 3 | H38: =COUNTIFS($A$2:$A$84,$F$37,$C$2:$C$84,$F38,$D$2:$D$84,H$37) -> 3 | I38: =COUNTIFS($A$2:$A$44,$F$37,$C$2:$C$44,$F38,$D$2:$D$44,I$37)+MAX(D48-C48,0) -> 0 | J38: =SUM(G38:I38) -> 6 | L38: 0 | M38: =ABS(G$2-$F38)/1 -> 0 | N38: =ABS(H$2-$F38)/1 -> 0.5 | O38: =ABS(I$2-$F38)/1 -> 1 | Q38: 0 | R38: =($J38/$J$41) * (G$41/$J$41) -> 0.36734694 | S38: =($J38/$J$41) * (H$41/$J$41) -> 0.48979592 | T38: =($J38/$J$41) * (I$41/$J$41) -> 0 | V38: Observed Weighted Disagreement (D_obs) | W38: =SUMPRODUCT(G38:I40, M38:O40) /$J$41 -> 0.28571429 | X38: Sum of (confusion-matrix counts × weights) divided by total items.
A39: =Thermonix!A39 -> Guard | B39: =Thermonix!B39 -> [choppingTimeDone && moreIngredientsRequired()] | C39: =CombinedHumanGrading!C39 -> 0.5 | D39: ='GPT-5.5 Grading'!C39 -> 1 | F39: 0.5 | G39: =COUNTIFS($A$2:$A$84,$F$37,$C$2:$C$84,$F39,$D$2:$D$84,G$37) -> 0 | H39: =COUNTIFS($A$2:$A$84,$F$37,$C$2:$C$84,$F39,$D$2:$D$84,H$37) -> 0 | I39: =COUNTIFS($A$2:$A$84,$F$37,$C$2:$C$84,$F39,$D$2:$D$84,I$37) -> 0 | J39: =SUM(G39:I39) -> 0 | L39: 0.5 | M39: =ABS(G$2-$F39)/1 -> 0.5 | N39: =ABS(H$2-$F39)/3 -> 0 | O39: =ABS(I$2-$F39)/1 -> 0.5 | Q39: 0.5 | R39: =($J39/$J$41) * (G$41/$J$41) -> 0 | S39: =($J39/$J$41) * (H$41/$J$41) -> 0 | T39: =($J39/$J$41) * (I$41/$J$41) -> 0 | V39: Expected Weighted Disagreement (D_exp) | W39: =SUMPRODUCT(R38:T40, M38:O40) -> 0.34693878 | X39: Sum of (expected cell proportions × weights) under chance agreement.
A40: =Thermonix!A40 -> Action | B40: =Thermonix!B40 -> setIngredients() | C40: =CombinedHumanGrading!C40 -> 0 | D40: ='GPT-5.5 Grading'!C40 -> 0.5 | F40: 1 | G40: =COUNTIFS($A$2:$A$44,$F$37,$C$2:$C$44,$F40,$D$2:$D$44,G$37)+MAX(C48-D48,0) -> 0 | H40: =COUNTIFS($A$2:$A$84,$F$37,$C$2:$C$84,$F40,$D$2:$D$84,H$37) -> 1 | I40: =COUNTIFS($A$2:$A$44,$F$37,$C$2:$C$44,$F40,$D$2:$D$44,I$37) + MIN(C48,D48) -> 0 | J40: =SUM(G40:I40) -> 1 | L40: 1 | M40: =ABS(G$2-$F40)/1 -> 1 | N40: =ABS(H$2-$F40)/1 -> 0.5 | O40: =ABS(I$2-$F40)/1 -> 0 | Q40: 1 | R40: =($J40/$J$41) * (G$41/$J$41) -> 0.06122449 | S40: =($J40/$J$41) * (H$41/$J$41) -> 0.081632653 | T40: =($J40/$J$41) * (I$41/$J$41) -> 0 | V40: Cohen's Kappa | W40: =1-W38/W39 -> 0.17647059 | X40: 1 - (D_obs / D_exp)
...
