Workbook

Sheet Dishwasher
A1: Type | B1: Element
A2: Composite State | B2: DishwasherOn
A3: Region | B3: Door
A4: State | B4: initial state (⇒ Closed)
A5: State | B5: Closed
A6: Transition | B6: open (Closed ⇒ Open)
A7: Transition | B7: lock (Closed ⇒ Locked)
A8: State | B8: Open
A9: Transition | B9: close (Open ⇒ Closed)
A10: State | B10: Locked
A11: Transition | B11: unlock (Locked ⇒ Closed)
A12: Region | B12: Washer
... A55: History State | B55: additional elements

Sheet Gemini 3 Pro Generation
A1: Type | B1: Element | C1: Claude | D1: Notes
A2: Composite State | B2: DishwasherOn
A3: Region | B3: Door
A4: State | B4: initial state (⇒ Closed)
A5: State | B5: Closed
A6: Transition | B6: open (Closed ⇒ Open)
A7: Transition | B7: lock (Closed ⇒ Locked)
A8: State | B8: Open
A9: Transition | B9: close (Open ⇒ Closed)
A10: State | B10: Locked
A11: Transition | B11: unlock (Locked ⇒ Closed)
A12: Region | B12: Washer
A13: State | B13: initial state
... A55: History State | B55: additional elements

Sheet Claude Sonnet 4.5 Gen
A1: Type | B1: Element | C1: Claude Sonnet 4.5 Generation | D1: Notes
A2: Composite State | B2: DishwasherOn | C2: 0 | D2: No top-level composite state encompassing the entire system; student model starts directly with Idle
A3: Region | B3: Door | C3: 0 | D3: No separate Door region modeling door states (Closed/Open/Locked)
A4: State | B4: initial state (⇒ Closed) | C4: 0 | D4: No Door region or Closed state
A5: State | B5: Closed | C5: 0 | D5: No Door region or Closed state
A6: Transition | B6: open (Closed ⇒ Open) | C6: 0 | D6: No Door region or open transition between door states
A7: Transition | B7: lock (Closed ⇒ Locked) | C7: 0 | D7: No Door region or lock transition
A8: State | B8: Open | C8: 0 | D8: No Door region; DoorOpen state exists but in different context
A9: Transition | B9: close (Open ⇒ Closed) | C9: 0 | D9: No Door region or close transition between door states
A10: State | B10: Locked | C10: 0 | D10: No Door region or Locked state
A11: Transition | B11: unlock (Locked ⇒ Closed) | C11: 0 | D11: No Door region or unlock transition
A12: Region | B12: Washer | C12: 0 | D12: No separate Washer region; functionality exists but not as a parallel region
A13: State | B13: initial state | C13: 1 | D13: Initial state correctly transitions to Idle
... A55: History State | B55: additional elements | C55: 0 | D55: No incorrect additional history states

Sheet Metrics
A1: Generated by Gemini 3 Pro | J1: Date
A2: Type | B2: Ground Truth Count | C2: True Positive | D2: False Positive | E2: False Negative | F2: Precision | G2: Recall | H2: F1 Score | J2: March 16th, 2026
A3: Composite State | B3: =COUNTIF(Dishwasher!$A$2:$A$48, A3) | C3: =SUMIF('Gemini 3 Pro Generation'!$A$2:$A$48, $A3, 'Gemini 3 Pro Generation'!$C$2:$C$48) | D3: =SUMIF('Gemini 3 Pro Generation'!$A$49:$A$55, $A3, 'Gemini 3 Pro Generation'!$C$49:$C$55) | E3: =COUNTIFS('Gemini 3 Pro Generation'!$A$2:$A$48, $A3, 'Gemini 3 Pro Generation'!$C$2:$C$48,0) | F3: =IFERROR(C3 / (C3 + D3), "Not Available") | G3: =IFERROR(C3 / B3, "Not Available") | H3: =IFERROR(2*((F3*G3)/(F3+G3)),"Not Available")
A4: State | B4: =COUNTIF(Dishwasher!$A$2:$A$48, A4) | C4: =SUMIF('Gemini 3 Pro Generation'!$A$2:$A$48, $A4, 'Gemini 3 Pro Generation'!$C$2:$C$48) | D4: =SUMIF('Gemini 3 Pro Generation'!$A$49:$A$55, $A4, 'Gemini 3 Pro Generation'!$C$49:$C$55) | E4: =COUNTIFS('Gemini 3 Pro Generation'!$A$2:$A$48, $A4, 'Gemini 3 Pro Generation'!$C$2:$C$48,0) | F4: =IFERROR(C4 / (C4 + D4), "Not Available") | G4: =IFERROR(C4 / B4, "Not Available") | H4: =IFERROR(2*((F4*G4)/(F4+G4)),"Not Available") | J4: Grading LLM
A5: Transition | B5: =COUNTIF(Dishwasher!$A$2:$A$48, A5) | C5: =SUMIF('Gemini 3 Pro Generation'!$A$2:$A$48, $A5, 'Gemini 3 Pro Generation'!$C$2:$C$48) | D5: =SUMIF('Gemini 3 Pro Generation'!$A$49:$A$55, $A5, 'Gemini 3 Pro Generation'!$C$49:$C$55) | E5: =COUNTIFS('Gemini 3 Pro Generation'!$A$2:$A$48, $A5, 'Gemini 3 Pro Generation'!$C$2:$C$48,0) | F5: =IFERROR(C5 / (C5 + D5), "Not Available") | G5: =IFERROR(C5 / B5, "Not Available") | H5: =IFERROR(2*((F5*G5)/(F5+G5)),"Not Available") | J5: Claude Sonnet 4.5
A6: Action | B6: =COUNTIF(Dishwasher!$A$2:$A$48, A6) | C6: =SUMIF('Gemini 3 Pro Generation'!$A$2:$A$48, $A6, 'Gemini 3 Pro Generation'!$C$2:$C$48) | D6: =SUMIF('Gemini 3 Pro Generation'!$A$49:$A$55, $A6, 'Gemini 3 Pro Generation'!$C$49:$C$55) | E6: =COUNTIFS('Gemini 3 Pro Generation'!$A$2:$A$48, $A6, 'Gemini 3 Pro Generation'!$C$2:$C$48,0) | F6: =IFERROR(C6 / (C6 + D6), "Not Available") | G6: =IFERROR(C6 / B6, "Not Available") | H6: =IFERROR(2*((F6*G6)/(F6+G6)),"Not Available")
A7: Region | B7: =COUNTIF(Dishwasher!$A$2:$A$48, A7) | C7: =SUMIF('Gemini 3 Pro Generation'!$A$2:$A$48, $A7, 'Gemini 3 Pro Generation'!$C$2:$C$48) | D7: =SUMIF('Gemini 3 Pro Generation'!$A$49:$A$55, $A7, 'Gemini 3 Pro Generation'!$C$49:$C$55) | E7: =COUNTIFS('Gemini 3 Pro Generation'!$A$2:$A$48, $A7, 'Gemini 3 Pro Generation'!$C$2:$C$48,0) | F7: =IFERROR(C7 / (C7 + D7), "Not Available") | G7: =IFERROR(C7 / B7, "Not Available") | H7: =IFERROR(2*((F7*G7)/(F7+G7)),"Not Available") | J7: Generation LLMs
A8: History State | B8: =COUNTIF(Dishwasher!$A$2:$A$48, A8) | C8: =SUMIF('Gemini 3 Pro Generation'!$A$2:$A$48, $A8, 'Gemini 3 Pro Generation'!$C$2:$C$48) | D8: =SUMIF('Gemini 3 Pro Generation'!$A$49:$A$55, $A8, 'Gemini 3 Pro Generation'!$C$49:$C$55) | E8: =COUNTIFS('Gemini 3 Pro Generation'!$A$2:$A$48, $A8, 'Gemini 3 Pro Generation'!$C$2:$C$48,0) | F8: =IFERROR(C8 / (C8 + D8), "Not Available") | G8: =IFERROR(C8 / B8, "Not Available") | H8: =IFERROR(2*((F8*G8)/(F8+G8)),"Not Available") | J8: Gemini 3 Pro
A9: Guard | B9: =COUNTIF(Dishwasher!$A$2:$A$48, A9) | C9: =SUMIF('Gemini 3 Pro Generation'!$A$2:$A$48, $A9, 'Gemini 3 Pro Generation'!$C$2:$C$48) | D9: =SUMIF('Gemini 3 Pro Generation'!$A$49:$A$55, $A9, 'Gemini 3 Pro Generation'!$C$49:$C$55) | E9: =COUNTIFS('Gemini 3 Pro Generation'!$A$2:$A$48, $A9, 'Gemini 3 Pro Generation'!$C$2:$C$48,0) | F9: =IFERROR(C9 / (C9 + D9), "Not Available") | G9: =IFERROR(C9 / B9, "Not Available") | H9: =IFERROR(2*((F9*G9)/(F9+G9)),"Not Available") | J9: Claude Sonnet 4.5
A10: Overall Score | B10: =SUM(B3:B9) | C10: =SUM(C3:C9) | D10: =SUM(D3:D9) | E10: =SUM(E3:E9) | F10: =IFERROR(C10 / (C10 + D10), "Not Available") | G10: =IFERROR(C10 / B10, "Not Available") | H10: =IFERROR(2*((F10*G10)/(F10+G10)),"Not Available")
A12: Generated by Claude Sonnet 4.5
A13: Type | B13: Ground Truth Count | C13: True Positive | D13: False Positive | E13: False Negative | F13: Precision | G13: Recall | H13: F1 Score
A14: Composite state | B14: =COUNTIF(Dishwasher!$A$2:$A$48, A14) | C14: =SUMIF('Claude Sonnet 4.5 Gen'!$A$2:$A$48, $A14, 'Claude Sonnet 4.5 Gen'!$C$2:$C$48) | D14: =SUMIF('Claude Sonnet 4.5 Gen'!$A$49:$A$55, $A14, 'Claude Sonnet 4.5 Gen'!$C$49:$C$55) | E14: =COUNTIFS('Claude Sonnet 4.5 Gen'!$A$2:$A$48, $A3, 'Claude Sonnet 4.5 Gen'!$C$2:$C$48,0) | F14: =IFERROR(C14 / (C14 + D14), "Not Available") | G14: =IFERROR(C14 / B14, "Not Available") | H14: =IFERROR(2*((F14*G14)/(F14+G14)),"Not Available")
A15: State | B15: =COUNTIF(Dishwasher!$A$2:$A$48, A15) | C15: =SUMIF('Claude Sonnet 4.5 Gen'!$A$2:$A$48, $A15, 'Claude Sonnet 4.5 Gen'!$C$2:$C$48) | D15: =SUMIF('Claude Sonnet 4.5 Gen'!$A$49:$A$55, $A15, 'Claude Sonnet 4.5 Gen'!$C$49:$C$55) | E15: =COUNTIFS('Claude Sonnet 4.5 Gen'!$A$2:$A$48, $A4, 'Claude Sonnet 4.5 Gen'!$C$2:$C$48,0) | F15: =IFERROR(C15 / (C15 + D15), "Not Available") | G15: =IFERROR(C15 / B15, "Not Available") | H15: =IFERROR(2*((F15*G15)/(F15+G15)),"Not Available")
A16: Transition | B16: =COUNTIF(Dishwasher!$A$2:$A$48, A16) | C16: =SUMIF('Claude Sonnet 4.5 Gen'!$A$2:$A$48, $A16, 'Claude Sonnet 4.5 Gen'!$C$2:$C$48) | D16: =SUMIF('Claude Sonnet 4.5 Gen'!$A$49:$A$55, $A16, 'Claude Sonnet 4.5 Gen'!$C$49:$C$55) | E16: =COUNTIFS('Claude Sonnet 4.5 Gen'!$A$2:$A$48, $A5, 'Claude Sonnet 4.5 Gen'!$C$2:$C$48,0) | F16: =IFERROR(C16 / (C16 + D16), "Not Available") | G16: =IFERROR(C16 / B16, "Not Available") | H16: =IFERROR(2*((F16*G16)/(F16+G16)),"Not Available")
A17: Action | B17: =COUNTIF(Dishwasher!$A$2:$A$48, A17) | C17: =SUMIF('Claude Sonnet 4.5 Gen'!$A$2:$A$48, $A17, 'Claude Sonnet 4.5 Gen'!$C$2:$C$48) | D17: =SUMIF('Claude Sonnet 4.5 Gen'!$A$49:$A$55, $A17, 'Claude Sonnet 4.5 Gen'!$C$49:$C$55) | E17: =COUNTIFS('Claude Sonnet 4.5 Gen'!$A$2:$A$48, $A6, 'Claude Sonnet 4.5 Gen'!$C$2:$C$48,0) | F17: =IFERROR(C17 / (C17 + D17), "Not Available") | G17: =IFERROR(C17 / B17, "Not Available") | H17: =IFERROR(2*((F17*G17)/(F17+G17)),"Not Available")
A18: Region | B18: =COUNTIF(Dishwasher!$A$2:$A$48, A18) | C18: =SUMIF('Claude Sonnet 4.5 Gen'!$A$2:$A$48, $A18, 'Claude Sonnet 4.5 Gen'!$C$2:$C$48) | D18: =SUMIF('Claude Sonnet 4.5 Gen'!$A$49:$A$55, $A18, 'Claude Sonnet 4.5 Gen'!$C$49:$C$55) | E18: =COUNTIFS('Claude Sonnet 4.5 Gen'!$A$2:$A$48, $A7, 'Claude Sonnet 4.5 Gen'!$C$2:$C$48,0) | F18: =IFERROR(C18 / (C18 + D18), "Not Available") | G18: =IFERROR(C18 / B18, "Not Available") | H18: =IFERROR(2*((F18*G18)/(F18+G18)),"Not Available")
A19: History State | B19: =COUNTIF(Dishwasher!$A$2:$A$48, A19) | C19: =SUMIF('Claude Sonnet 4.5 Gen'!$A$2:$A$48, $A19, 'Claude Sonnet 4.5 Gen'!$C$2:$C$48) | D19: =SUMIF('Claude Sonnet 4.5 Gen'!$A$49:$A$55, $A19, 'Claude Sonnet 4.5 Gen'!$C$49:$C$55) | E19: =COUNTIFS('Claude Sonnet 4.5 Gen'!$A$2:$A$48, $A8, 'Claude Sonnet 4.5 Gen'!$C$2:$C$48,0) | F19: =IFERROR(C19 / (C19 + D19), "Not Available") | G19: =IFERROR(C19 / B19, "Not Available") | H19: =IFERROR(2*((F19*G19)/(F19+G19)),"Not Available")
A20: Guard | B20: =COUNTIF(Dishwasher!$A$2:$A$48, A20) | C20: =SUMIF('Claude Sonnet 4.5 Gen'!$A$2:$A$48, $A20, 'Claude Sonnet 4.5 Gen'!$C$2:$C$48) | D20: =SUMIF('Claude Sonnet 4.5 Gen'!$A$49:$A$55, $A20, 'Claude Sonnet 4.5 Gen'!$C$49:$C$55) | E20: =COUNTIFS('Claude Sonnet 4.5 Gen'!$A$2:$A$48, $A9, 'Claude Sonnet 4.5 Gen'!$C$2:$C$48,0) | F20: =IFERROR(C20 / (C20 + D20), "Not Available") | G20: =IFERROR(C20 / B20, "Not Available") | H20: =IFERROR(2*((F20*G20)/(F20+G20)),"Not Available")
A21: Overall Score | B21: =SUM(B14:B20) | C21: =SUM(C14:C20) | D21: =SUM(D14:D20) | E21: =SUM(E14:E20) | F21: =IFERROR(C21 / (C21 + D21), "Not Available") | G21: =IFERROR(C21 / B21, "Not Available") | H21: =IFERROR(2*((F21*G21)/(F21+G21)),"Not Available")

Sheet Inter-rater
A1: Type | B1: Element | C1: Gemini 3 Pro | D1: Claude Sonnet 4.5 | F1: Confusion Matrix | L1: Cohen's Kappa
A2: ='Gemini 3 Pro Generation'!A2 | B2: ='Gemini 3 Pro Generation'!B2 | C2: ='Gemini 3 Pro Generation'!C2 | D2: ='Claude Sonnet 4.5 Gen'!C2 | F2: Global | G2: 0 | H2: 0.5 | I2: 1 | J2: Row Totals | L2: Metric | M2: Value | N2: Note
A3: ='Gemini 3 Pro Generation'!A3 | B3: ='Gemini 3 Pro Generation'!B3 | C3: ='Gemini 3 Pro Generation'!C3 | D3: ='Claude Sonnet 4.5 Gen'!C3 | F3: 0 | G3: =COUNTIFS($C$2:$C$92, $F3, $D$2:$D$92, G$2) | H3: =COUNTIFS($C$2:$C$48, $F3, $D$2:$D$48, H$2) | I3: =COUNTIFS($C$2:$C$48, $F3, $D$2:$D$48, I$2)+MAX(D49-C49,0)+MAX(D50-C50,0)+MAX(D51-C51,0)+MAX(D52-C52,0)+MAX(D53-C53,0)+MAX(D54-C54,0)+MAX(D55-C55,0) | J3: =SUM(G3:I3) | L3: Observed Agreement (Po) | M3: =(G3+H4+I5)/COUNTA($C$2:$C$102) | N3: This sums the diagonal of your matrix divided by total rows.
A4: ='Gemini 3 Pro Generation'!A4 | B4: ='Gemini 3 Pro Generation'!B4 | C4: ='Gemini 3 Pro Generation'!C4 | D4: ='Claude Sonnet 4.5 Gen'!C4 | F4: 0.5 | G4: =COUNTIFS($C$2:$C$48, $F4, $D$2:$D$48, G$2) | H4: =COUNTIFS($C$2:$C$48, $F4, $D$2:$D$48, H$2) | I4: =COUNTIFS($C$2:$C$48, $F4, $D$2:$D$48, I$2) | J4: =SUM(G4:I4) | L4: Expected Agreement (Pe) | M4: {=SUMPRODUCT(J3:J5/COUNTA($C$2:$C$102), TRANSPOSE(G6:I6)/COUNTA($C$2:$C$102))} | N4: This computes the sum of row proportion times column proportion.
A5: ='Gemini 3 Pro Generation'!A5 | B5: ='Gemini 3 Pro Generation'!B5 | C5: ='Gemini 3 Pro Generation'!C5 | D5: ='Claude Sonnet 4.5 Gen'!C5 | F5: 1 | G5: =COUNTIFS($C$2:$C$48, $F5, $D$2:$D$48, G$2)+MAX(C49-D49,0)+MAX(C50-D50,0)+MAX(C51-D51,0)+MAX(C52-D52,0)+MAX(C53-D53,0)+MAX(C54-D54,0)+MAX(C55-D55,0) | H5: =COUNTIFS($C$2:$C$48, $F5, $D$2:$D$48, H$2) | I5: =COUNTIFS($C$2:$C$48, $F5, $D$2:$D$48, I$2)+ SUM(MIN(C49,D49), MIN(C50,D50), MIN(C51,D51), MIN(C52,D52), MIN(C53,D53), MIN(C54,D54), MIN(C55,D55)) | J5: =SUM(G5:I5) | L5: Cohen's Kappa | M5: =(M3-M4)/(1-M4) | N5: (Po - Pe) / (1 - Pe)
A6: ='Gemini 3 Pro Generation'!A6 | B6: ='Gemini 3 Pro Generation'!B6 | C6: ='Gemini 3 Pro Generation'!C6 | D6: ='Claude Sonnet 4.5 Gen'!C6 | F6: Column Totals | G6: =SUM(G3:G5) | H6: =SUM(H3:H5) | I6: =SUM(I3:I5)
A7: ='Gemini 3 Pro Generation'!A7 | B7: ='Gemini 3 Pro Generation'!B7 | C7: ='Gemini 3 Pro Generation'!C7 | D7: ='Claude Sonnet 4.5 Gen'!C7
A8: ='Gemini 3 Pro Generation'!A8 | B8: ='Gemini 3 Pro Generation'!B8 | C8: ='Gemini 3 Pro Generation'!C8 | D8: ='Claude Sonnet 4.5 Gen'!C8 | F8: Confusion Matrix (State) | L8: Cohen's Kappa (State)
A9: ='Gemini 3 Pro Generation'!A9 | B9: ='Gemini 3 Pro Generation'!B9 | C9: ='Gemini 3 Pro Generation'!C9 | D9: ='Claude Sonnet 4.5 Gen'!C9 | F9: State | G9: 0 | H9: 0.5 | I9: 1 | J9: Row Totals | L9: Metric | M9: Value | N9: Note
A10: ='Gemini 3 Pro Generation'!A10 | B10: ='Gemini 3 Pro Generation'!B10 | C10: ='Gemini 3 Pro Generation'!C10 | D10: ='Claude Sonnet 4.5 Gen'!C10 | F10: 0 | G10: =COUNTIFS($A$2:$A$92,$F$9,$C$2:$C$92,$F10,$D$2:$D$92,G$9) | H10: =COUNTIFS($A$2:$A$92,$F$9,$C$2:$C$92,$F10,$D$2:$D$92,H$9) | I10: =COUNTIFS($A$2:$A$48,$F$9,$C$2:$C$48,$F10,$D$2:$D$48,I$9)+MAX(D49-C49,0) | J10: =SUM(G10:I10) | L10: Observed Agreement (Po) | M10: =(G10+H11+I12)/COUNTIF($A$2:$A$102,F9) | N10: This sums the diagonal of your matrix divided by total rows.
A11: ='Gemini 3 Pro Generation'!A11 | B11: ='Gemini 3 Pro Generation'!B11 | C11: ='Gemini 3 Pro Generation'!C11 | D11: ='Claude Sonnet 4.5 Gen'!C11 | F11: 0.5 | G11: =COUNTIFS($A$2:$A$92,$F$9,$C$2:$C$92,$F11,$D$2:$D$92,G$9) | H11: =COUNTIFS($A$2:$A$92,$F$9,$C$2:$C$92,$F11,$D$2:$D$92,H$9) | I11: =COUNTIFS($A$2:$A$92,$F$9,$C$2:$C$92,$F11,$D$2:$D$92,I$9) | J11: =SUM(G11:I11) | L11: Expected Agreement (Pe) | M11: {=SUMPRODUCT(J10:J12/COUNTIF($A$2:$A$102,F9), TRANSPOSE(G13:I13)/COUNTIF($A$2:$A$102,F9))} | N11: This computes the sum of row proportion times column proportion.
A12: ='Gemini 3 Pro Generation'!A12 | B12: ='Gemini 3 Pro Generation'!B12 | C12: ='Gemini 3 Pro Generation'!C12 | D12: ='Claude Sonnet 4.5 Gen'!C12 | F12: 1 | G12: =COUNTIFS($A$2:$A$48,$F$9,$C$2:$C$48,$F12,$D$2:$D$48,G$9)+MAX(C49-D49,0) | H12: =COUNTIFS($A$2:$A$92,$F$9,$C$2:$C$92,$F12,$D$2:$D$92,H$9) | I12: =COUNTIFS($A$2:$A$48,$F$9,$C$2:$C$48,$F12,$D$2:$D$48,I$9)+MIN(C49-D49) | J12: =SUM(G12:I12) | L12: Cohen's Kappa | M12: =(M10-M11)/(1-M11) | N12: (Po - Pe) / (1 - Pe)
A13: ='Gemini 3 Pro Generation'!A13 | B13: ='Gemini 3 Pro Generation'!B13 | C13: ='Gemini 3 Pro Generation'!C13 | D13: ='Claude Sonnet 4.5 Gen'!C13 | F13: Column Totals | G13: =SUM(G10:G12) | H13: =SUM(H10:H12) | I13: =SUM(I10:I12)
A14: ='Gemini 3 Pro Generation'!A14 | B14: ='Gemini 3 Pro Generation'!B14 | C14: ='Gemini 3 Pro Generation'!C14 | D14: ='Claude Sonnet 4.5 Gen'!C14
A15: ='Gemini 3 Pro Generation'!A15 | B15: ='Gemini 3 Pro Generation'!B15 | C15: ='Gemini 3 Pro Generation'!C15 | D15: ='Claude Sonnet 4.5 Gen'!C15 | F15: Confusion Matrix (Transition) | L15: Cohen's Kappa (Transition)
A16: ='Gemini 3 Pro Generation'!A16 | B16: ='Gemini 3 Pro Generation'!B16 | C16: ='Gemini 3 Pro Generation'!C16 | D16: ='Claude Sonnet 4.5 Gen'!C16 | F16: Transition | G16: 0 | H16: 0.5 | I16: 1 | J16: Row Totals | L16: Metric | M16: Value | N16: Note
A17: ='Gemini 3 Pro Generation'!A17 | B17: ='Gemini 3 Pro Generation'!B17 | C17: ='Gemini 3 Pro Generation'!C17 | D17: ='Claude Sonnet 4.5 Gen'!C17 | F17: 0 | G17: =COUNTIFS($A$2:$A$92,$F$16,$C$2:$C$92,$F17,$D$2:$D$92,G$16) | H17: =COUNTIFS($A$2:$A$92,$F$16,$C$2:$C$92,$F17,$D$2:$D$92,H$16) | I17: =COUNTIFS($A$2:$A$48,$F$16,$C$2:$C$48,$F17,$D$2:$D$48,I$16) + MAX(D50-C50,0) | J17: =SUM(G17:I17) | L17: Observed Agreement (Po) | M17: =(G17+H18+I19)/COUNTIF($A$2:$A$102,F16) | N17: This sums the diagonal of your matrix divided by total rows.
A18: ='Gemini 3 Pro Generation'!A18 | B18: ='Gemini 3 Pro Generation'!B18 | C18: ='Gemini 3 Pro Generation'!C18 | D18: ='Claude Sonnet 4.5 Gen'!C18 | F18: 0.5 | G18: =COUNTIFS($A$2:$A$92,$F$16,$C$2:$C$92,$F18,$D$2:$D$92,G$16) | H18: =COUNTIFS($A$2:$A$92,$F$16,$C$2:$C$92,$F18,$D$2:$D$92,H$16) | I18: =COUNTIFS($A$2:$A$92,$F$16,$C$2:$C$92,$F18,$D$2:$D$92,I$16) | J18: =SUM(G18:I18) | L18: Expected Agreement (Pe) | M18: {=SUMPRODUCT(J17:J19/COUNTIF($A$2:$A$102,F16), TRANSPOSE(G20:I20)/COUNTIF($A$2:$A$102,F16))} | N18: This computes the sum of row proportion times column proportion.
A19: ='Gemini 3 Pro Generation'!A19 | B19: ='Gemini 3 Pro Generation'!B19 | C19: ='Gemini 3 Pro Generation'!C19 | D19: ='Claude Sonnet 4.5 Gen'!C19 | F19: 1 | G19: =COUNTIFS($A$2:$A$48,$F$16,$C$2:$C$48,$F19,$D$2:$D$48,G$16)+MAX(C50-D50,0) | H19: =COUNTIFS($A$2:$A$92,$F$16,$C$2:$C$92,$F19,$D$2:$D$92,H$16) | I19: =COUNTIFS($A$2:$A$48,$F$16,$C$2:$C$48,$F19,$D$2:$D$48,I$16) + MIN(C50,D50) | J19: =SUM(G19:I19) | L19: Cohen's Kappa | M19: =(M17-M18)/(1-M18) | N19: (Po - Pe) / (1 - Pe)
A20: ='Gemini 3 Pro Generation'!A20 | B20: ='Gemini 3 Pro Generation'!B20 | C20: ='Gemini 3 Pro Generation'!C20 | D20: ='Claude Sonnet 4.5 Gen'!C20 | F20: Column Totals | G20: =SUM(G17:G19) | H20: =SUM(H17:H19) | I20: =SUM(I17:I19)
A21: ='Gemini 3 Pro Generation'!A21 | B21: ='Gemini 3 Pro Generation'!B21 | C21: ='Gemini 3 Pro Generation'!C21 | D21: ='Claude Sonnet 4.5 Gen'!C21
A22: ='Gemini 3 Pro Generation'!A22 | B22: ='Gemini 3 Pro Generation'!B22 | C22: ='Gemini 3 Pro Generation'!C22 | D22: ='Claude Sonnet 4.5 Gen'!C22 | F22: Confusion Matrix (Composite State) | L22: Cohen's Kappa (Composite State)
A23: ='Gemini 3 Pro Generation'!A23 | B23: ='Gemini 3 Pro Generation'!B23 | C23: ='Gemini 3 Pro Generation'!C23 | D23: ='Claude Sonnet 4.5 Gen'!C23 | F23: Composite State | G23: 0 | H23: 0.5 | I23: 1 | J23: Row Totals | L23: Metric | M23: Value | N23: Note
A24: ='Gemini 3 Pro Generation'!A24 | B24: ='Gemini 3 Pro Generation'!B24 | C24: ='Gemini 3 Pro Generation'!C24 | D24: ='Claude Sonnet 4.5 Gen'!C24 | F24: 0 | G24: =COUNTIFS($A$2:$A$92,$F$23,$C$2:$C$92,$F24,$D$2:$D$92,G$23) | H24: =COUNTIFS($A$2:$A$92,$F$23,$C$2:$C$92,$F24,$D$2:$D$92,H$23) | I24: =COUNTIFS($A$2:$A$48,$F$23,$C$2:$C$48,$F24,$D$2:$D$48,I$23) + MAX(D53-C53,0) | J24: =SUM(G24:I24) | L24: Observed Agreement (Po) | M24: =(G24+H25+I26)/COUNTIF($A$2:$A$102,F23) | N24: This sums the diagonal of your matrix divided by total rows.
A25: ='Gemini 3 Pro Generation'!A25 | B25: ='Gemini 3 Pro Generation'!B25 | C25: ='Gemini 3 Pro Generation'!C25 | D25: ='Claude Sonnet 4.5 Gen'!C25 | F25: 0.5 | G25: =COUNTIFS($A$2:$A$92,$F$23,$C$2:$C$92,$F25,$D$2:$D$92,G$23) | H25: =COUNTIFS($A$2:$A$92,$F$23,$C$2:$C$92,$F25,$D$2:$D$92,H$23) | I25: =COUNTIFS($A$2:$A$92,$F$23,$C$2:$C$92,$F25,$D$2:$D$92,I$23) | J25: =SUM(G25:I25) | L25: Expected Agreement (Pe) | M25: {=SUMPRODUCT(J24:J26/COUNTIF($A$2:$A$102,F23), TRANSPOSE(G27:I27)/COUNTIF($A$2:$A$102,F23))} | N25: This computes the sum of row proportion times column proportion.
A26: ='Gemini 3 Pro Generation'!A26 | B26: ='Gemini 3 Pro Generation'!B26 | C26: ='Gemini 3 Pro Generation'!C26 | D26: ='Claude Sonnet 4.5 Gen'!C26 | F26: 1 | G26: =COUNTIFS($A$2:$A$48,$F$23,$C$2:$C$48,$F26,$D$2:$D$48,G$23) + MAX(C53-D53,0) | H26: =COUNTIFS($A$2:$A$92,$F$23,$C$2:$C$92,$F26,$D$2:$D$92,H$23) | I26: =COUNTIFS($A$2:$A$48,$F$23,$C$2:$C$48,$F26,$D$2:$D$48,I$23) + MIN(C53,D53) | J26: =SUM(G26:I26) | L26: Cohen's Kappa | M26: =(M24-M25)/(1-M25) | N26: (Po - Pe) / (1 - Pe)
A27: ='Gemini 3 Pro Generation'!A27 | B27: ='Gemini 3 Pro Generation'!B27 | C27: ='Gemini 3 Pro Generation'!C27 | D27: ='Claude Sonnet 4.5 Gen'!C27 | F27: Column Totals | G27: =SUM(G24:G26) | H27: =SUM(H24:H26) | I27: =SUM(I24:I26)
A28: ='Gemini 3 Pro Generation'!A28 | B28: ='Gemini 3 Pro Generation'!B28 | C28: ='Gemini 3 Pro Generation'!C28 | D28: ='Claude Sonnet 4.5 Gen'!C28
A29: ='Gemini 3 Pro Generation'!A29 | B29: ='Gemini 3 Pro Generation'!B29 | C29: ='Gemini 3 Pro Generation'!C29 | D29: ='Claude Sonnet 4.5 Gen'!C29 | F29: Confusion Matrix (Guard) | L29: Cohen's Kappa (Guard)
A30: ='Gemini 3 Pro Generation'!A30 | B30: ='Gemini 3 Pro Generation'!B30 | C30: ='Gemini 3 Pro Generation'!C30 | D30: ='Claude Sonnet 4.5 Gen'!C30 | F30: Guard | G30: 0 | H30: 0.5 | I30: 1 | J30: Row Totals | L30: Metric | M30: Value | N30: Note
A31: ='Gemini 3 Pro Generation'!A31 | B31: ='Gemini 3 Pro Generation'!B31 | C31: ='Gemini 3 Pro Generation'!C31 | D31: ='Claude Sonnet 4.5 Gen'!C31 | F31: 0 | G31: =COUNTIFS($A$2:$A$92,$F$30,$C$2:$C$92,$F31,$D$2:$D$92,G$30) | H31: =COUNTIFS($A$2:$A$92,$F$30,$C$2:$C$92,$F31,$D$2:$D$92,H$30) | I31: =COUNTIFS($A$2:$A$48,$F$30,$C$2:$C$48,$F31,$D$2:$D$48,I$30) + MAX(D51-C51,0) | J31: =SUM(G31:I31) | L31: Observed Agreement (Po) | M31: =(G31+H32+I33)/COUNTIF($A$2:$A$102,F30) | N31: This sums the diagonal of your matrix divided by total rows.
A32: ='Gemini 3 Pro Generation'!A32 | B32: ='Gemini 3 Pro Generation'!B32 | C32: ='Gemini 3 Pro Generation'!C32 | D32: ='Claude Sonnet 4.5 Gen'!C32 | F32: 0.5 | G32: =COUNTIFS($A$2:$A$92,$F$30,$C$2:$C$92,$F32,$D$2:$D$92,G$30) | H32: =COUNTIFS($A$2:$A$92,$F$30,$C$2:$C$92,$F32,$D$2:$D$92,H$30) | I32: =COUNTIFS($A$2:$A$92,$F$30,$C$2:$C$92,$F32,$D$2:$D$92,I$30) | J32: =SUM(G32:I32) | L32: Expected Agreement (Pe) | M32: {=SUMPRODUCT(J31:J33/COUNTIF($A$2:$A$102,F30), TRANSPOSE(G34:I34)/COUNTIF($A$2:$A$102,F30))} | N32: This computes the sum of row proportion times column proportion.
A33: ='Gemini 3 Pro Generation'!A33 | B33: ='Gemini 3 Pro Generation'!B33 | C33: ='Gemini 3 Pro Generation'!C33 | D33: ='Claude Sonnet 4.5 Gen'!C33 | F33: 1 | G33: =COUNTIFS($A$2:$A$48,$F$30,$C$2:$C$48,$F33,$D$2:$D$48,G$30) + MAX(C51-D51,0) | H33: =COUNTIFS($A$2:$A$92,$F$30,$C$2:$C$92,$F33,$D$2:$D$92,H$30) | I33: =COUNTIFS($A$2:$A$48,$F$30,$C$2:$C$48,$F33,$D$2:$D$48,I$30) + MIN(C51,D51) | J33: =SUM(G33:I33) | L33: Cohen's Kappa | M33: =(M31-M32)/(1-M32) | N33: (Po - Pe) / (1 - Pe)
A34: ='Gemini 3 Pro Generation'!A34 | B34: ='Gemini 3 Pro Generation'!B34 | C34: ='Gemini 3 Pro Generation'!C34 | D34: ='Claude Sonnet 4.5 Gen'!C34 | F34: Column Totals | G34: =SUM(G31:G33) | H34: =SUM(H31:H33) | I34: =SUM(I31:I33)
A35: ='Gemini 3 Pro Generation'!A35 | B35: ='Gemini 3 Pro Generation'!B35 | C35: ='Gemini 3 Pro Generation'!C35 | D35: ='Claude Sonnet 4.5 Gen'!C35
A36: ='Gemini 3 Pro Generation'!A36 | B36: ='Gemini 3 Pro Generation'!B36 | C36: ='Gemini 3 Pro Generation'!C36 | D36: ='Claude Sonnet 4.5 Gen'!C36 | F36: Confusion Matrix (Action) | L36: Cohen's Kappa (Action)
A37: ='Gemini 3 Pro Generation'!A37 | B37: ='Gemini 3 Pro Generation'!B37 | C37: ='Gemini 3 Pro Generation'!C37 | D37: ='Claude Sonnet 4.5 Gen'!C37 | F37: Action | G37: 0 | H37: 0.5 | I37: 1 | J37: Row Totals | L37: Metric | M37: Value | N37: Note
A38: ='Gemini 3 Pro Generation'!A38 | B38: ='Gemini 3 Pro Generation'!B38 | C38: ='Gemini 3 Pro Generation'!C38 | D38: ='Claude Sonnet 4.5 Gen'!C38 | F38: 0 | G38: =COUNTIFS($A$2:$A$92,$F$37,$C$2:$C$92,$F38,$D$2:$D$92,G$37) | H38: =COUNTIFS($A$2:$A$92,$F$37,$C$2:$C$92,$F38,$D$2:$D$92,H$37) | I38: =COUNTIFS($A$2:$A$48,$F$37,$C$2:$C$48,$F38,$D$2:$D$48,I$37)+MAX(D52-C52,0) | J38: =SUM(G38:I38) | L38: Observed Agreement (Po) | M38: =(G38+H39+I40)/COUNTIF($A$2:$A$102,F37) | N38: This sums the diagonal of your matrix divided by total rows.
A39: ='Gemini 3 Pro Generation'!A39 | B39: ='Gemini 3 Pro Generation'!B39 | C39: ='Gemini 3 Pro Generation'!C39 | D39: ='Claude Sonnet 4.5 Gen'!C39 | F39: 0.5 | G39: =COUNTIFS($A$2:$A$92,$F$37,$C$2:$C$92,$F39,$D$2:$D$92,G$37) | H39: =COUNTIFS($A$2:$A$92,$F$37,$C$2:$C$92,$F39,$D$2:$D$92,H$37) | I39: =COUNTIFS($A$2:$A$92,$F$37,$C$2:$C$92,$F39,$D$2:$D$92,I$37) | J39: =SUM(G39:I39) | L39: Expected Agreement (Pe) | M39: {=SUMPRODUCT(J38:J40/COUNTIF($A$2:$A$102,F37), TRANSPOSE(G41:I41)/COUNTIF($A$2:$A$102,F37))} | N39: This computes the sum of row proportion times column proportion.
A40: ='Gemini 3 Pro Generation'!A40 | B40: ='Gemini 3 Pro Generation'!B40 | C40: ='Gemini 3 Pro Generation'!C40 | D40: ='Claude Sonnet 4.5 Gen'!C40 | F40: 1 | G40: =COUNTIFS($A$2:$A$48,$F$37,$C$2:$C$48,$F40,$D$2:$D$48,G$37)+MAX(C52-D52,0) | H40: =COUNTIFS($A$2:$A$92,$F$37,$C$2:$C$92,$F40,$D$2:$D$92,H$37) | I40: =COUNTIFS($A$2:$A$48,$F$37,$C$2:$C$48,$F40,$D$2:$D$48,I$37) + MIN(C52,D52) | J40: =SUM(G40:I40) | L40: Cohen's Kappa | M40: =(M38-M39)/(1-M39) | N40: (Po - Pe) / (1 - Pe)
...

Sheet Weighted Cohens Kappa
A1: Type | B1: Element | C1: Gemini 3 Pro | D1: Claude Sonnet 4.5 | F1: Confusion Matrix | L1: Weight Matrix
A2: ='Gemini 3 Pro Generation'!A2 | B2: ='Gemini 3 Pro Generation'!B2 | C2: ='Gemini 3 Pro Generation'!C2 | D2: ='Claude Sonnet 4.5 Gen'!C2 | F2: Global | G2: 0 | H2: 0.5 | I2: 1 | J2: Row Totals | L2: Global | M2: 0 | N2: 0.5 | O2: 1 | Q2: Global | R2: 0 | S2: 0.5 | T2: 1 | V2: ="Metrics" & " " & F2 | W2: Value | X2: Note
A3: ='Gemini 3 Pro Generation'!A3 | B3: ='Gemini 3 Pro Generation'!B3 | C3: ='Gemini 3 Pro Generation'!C3 | D3: ='Claude Sonnet 4.5 Gen'!C3 | F3: 0 | G3: =COUNTIFS($C$2:$C$92, $F3, $D$2:$D$92, G$2) | H3: =COUNTIFS($C$2:$C$48, $F3, $D$2:$D$48, H$2) | I3: =COUNTIFS($C$2:$C$48, $F3, $D$2:$D$48, I$2)+MAX(D49-C49,0)+MAX(D50-C50,0)+MAX(D51-C51,0)+MAX(D52-C52,0)+MAX(D53-C53,0)+MAX(D54-C54,0)+MAX(D55-C55,0) | J3: =SUM(G3:I3) | L3: 0 | M3: =ABS(G$2-$F3)/1 | N3: =ABS(H$2-$F3)/1 | O3: =ABS(I$2-$F3)/1 | Q3: 0 | R3: =($J3/$J$6) * (G$6/$J$6) | S3: =($J3/$J$6) * (H$6/$J$6) | T3: =($J3/$J$6) * (I$6/$J$6) | V3: Observed Weighted Disagreement (D_obs) | W3: =SUMPRODUCT(G3:I5, M3:O5) /$J$6 | X3: Sum of (confusion-matrix counts × weights) divided by total items.
A4: ='Gemini 3 Pro Generation'!A4 | B4: ='Gemini 3 Pro Generation'!B4 | C4: ='Gemini 3 Pro Generation'!C4 | D4: ='Claude Sonnet 4.5 Gen'!C4 | F4: 0.5 | G4: =COUNTIFS($C$2:$C$48, $F4, $D$2:$D$48, G$2) | H4: =COUNTIFS($C$2:$C$48, $F4, $D$2:$D$48, H$2) | I4: =COUNTIFS($C$2:$C$48, $F4, $D$2:$D$48, I$2) | J4: =SUM(G4:I4) | L4: 0.5 | M4: =ABS(G$2-$F4)/1 | N4: =ABS(H$2-$F4)/3 | O4: =ABS(I$2-$F4)/1 | Q4: 0.5 | R4: =($J4/$J$6) * (G$6/$J$6) | S4: =($J4/$J$6) * (H$6/$J$6) | T4: =($J4/$J$6) * (I$6/$J$6) | V4: Expected Weighted Disagreement (D_exp) | W4: =SUMPRODUCT(R3:T5, M3:O5) | X4: Sum of (expected cell proportions × weights) under chance agreement.
A5: ='Gemini 3 Pro Generation'!A5 | B5: ='Gemini 3 Pro Generation'!B5 | C5: ='Gemini 3 Pro Generation'!C5 | D5: ='Claude Sonnet 4.5 Gen'!C5 | F5: 1 | G5: =COUNTIFS($C$2:$C$48, $F5, $D$2:$D$48, G$2)+MAX(C49-D49,0)+MAX(C50-D50,0)+MAX(C51-D51,0)+MAX(C52-D52,0)+MAX(C53-D53,0)+MAX(C54-D54,0)+MAX(C55-D55,0) | H5: =COUNTIFS($C$2:$C$48, $F5, $D$2:$D$48, H$2) | I5: =COUNTIFS($C$2:$C$48, $F5, $D$2:$D$48, I$2)+ SUM(MIN(C49,D49), MIN(C50,D50), MIN(C51,D51), MIN(C52,D52), MIN(C53,D53), MIN(C54,D54), MIN(C55,D55)) | J5: =SUM(G5:I5) | L5: 1 | M5: =ABS(G$2-$F5)/1 | N5: =ABS(H$2-$F5)/1 | O5: =ABS(I$2-$F5)/1 | Q5: 1 | R5: =($J5/$J$6) * (G$6/$J$6) | S5: =($J5/$J$6) * (H$6/$J$6) | T5: =($J5/$J$6) * (I$6/$J$6) | V5: Cohen's Kappa | W5: =1-W3/W4 | X5: 1 - (D_obs / D_exp)
A6: ='Gemini 3 Pro Generation'!A6 | B6: ='Gemini 3 Pro Generation'!B6 | C6: ='Gemini 3 Pro Generation'!C6 | D6: ='Claude Sonnet 4.5 Gen'!C6 | F6: Column Totals | G6: =SUM(G3:G5) | H6: =SUM(H3:H5) | I6: =SUM(I3:I5) | J6: =SUM(G3:I5)
A7: ='Gemini 3 Pro Generation'!A7 | B7: ='Gemini 3 Pro Generation'!B7 | C7: ='Gemini 3 Pro Generation'!C7 | D7: ='Claude Sonnet 4.5 Gen'!C7
A8: ='Gemini 3 Pro Generation'!A8 | B8: ='Gemini 3 Pro Generation'!B8 | C8: ='Gemini 3 Pro Generation'!C8 | D8: ='Claude Sonnet 4.5 Gen'!C8 | F8: Confusion Matrix (State)
A9: ='Gemini 3 Pro Generation'!A9 | B9: ='Gemini 3 Pro Generation'!B9 | C9: ='Gemini 3 Pro Generation'!C9 | D9: ='Claude Sonnet 4.5 Gen'!C9 | F9: State | G9: 0 | H9: 0.5 | I9: 1 | J9: Row Totals | L9: Global | M9: 0 | N9: 0.5 | O9: 1 | Q9: Global | R9: 0 | S9: 0.5 | T9: 1 | V9: ="Metrics" & " " & F9 | W9: Value | X9: Note
A10: ='Gemini 3 Pro Generation'!A10 | B10: ='Gemini 3 Pro Generation'!B10 | C10: ='Gemini 3 Pro Generation'!C10 | D10: ='Claude Sonnet 4.5 Gen'!C10 | F10: 0 | G10: =COUNTIFS($A$2:$A$92,$F$9,$C$2:$C$92,$F10,$D$2:$D$92,G$9) | H10: =COUNTIFS($A$2:$A$92,$F$9,$C$2:$C$92,$F10,$D$2:$D$92,H$9) | I10: =COUNTIFS($A$2:$A$48,$F$9,$C$2:$C$48,$F10,$D$2:$D$48,I$9)+MAX(D49-C49,0) | J10: =SUM(G10:I10) | L10: 0 | M10: =ABS(G$2-$F10)/1 | N10: =ABS(H$2-$F10)/1 | O10: =ABS(I$2-$F10)/1 | Q10: 0 | R10: =($J10/$J$13) * (G$13/$J$13) | S10: =($J10/$J$13) * (H$13/$J$13) | T10: =($J10/$J$13) * (I$13/$J$13) | V10: Observed Weighted Disagreement (D_obs) | W10: =SUMPRODUCT(G10:I12, M10:O12) /$J$13 | X10: Sum of (confusion-matrix counts × weights) divided by total items.
A11: ='Gemini 3 Pro Generation'!A11 | B11: ='Gemini 3 Pro Generation'!B11 | C11: ='Gemini 3 Pro Generation'!C11 | D11: ='Claude Sonnet 4.5 Gen'!C11 | F11: 0.5 | G11: =COUNTIFS($A$2:$A$92,$F$9,$C$2:$C$92,$F11,$D$2:$D$92,G$9) | H11: =COUNTIFS($A$2:$A$92,$F$9,$C$2:$C$92,$F11,$D$2:$D$92,H$9) | I11: =COUNTIFS($A$2:$A$92,$F$9,$C$2:$C$92,$F11,$D$2:$D$92,I$9) | J11: =SUM(G11:I11) | L11: 0.5 | M11: =ABS(G$2-$F11)/1 | N11: =ABS(H$2-$F11)/3 | O11: =ABS(I$2-$F11)/1 | Q11: 0.5 | R11: =($J11/$J$13) * (G$13/$J$13) | S11: =($J11/$J$13) * (H$13/$J$13) | T11: =($J11/$J$13) * (I$13/$J$13) | V11: Expected Weighted Disagreement (D_exp) | W11: =SUMPRODUCT(R10:T12, M10:O12) | X11: Sum of (expected cell proportions × weights) under chance agreement.
A12: ='Gemini 3 Pro Generation'!A12 | B12: ='Gemini 3 Pro Generation'!B12 | C12: ='Gemini 3 Pro Generation'!C12 | D12: ='Claude Sonnet 4.5 Gen'!C12 | F12: 1 | G12: =COUNTIFS($A$2:$A$48,$F$9,$C$2:$C$48,$F12,$D$2:$D$48,G$9)+MAX(C49-D49,0) | H12: =COUNTIFS($A$2:$A$92,$F$9,$C$2:$C$92,$F12,$D$2:$D$92,H$9) | I12: =COUNTIFS($A$2:$A$48,$F$9,$C$2:$C$48,$F12,$D$2:$D$48,I$9)+MIN(C49-D49) | J12: =SUM(G12:I12) | L12: 1 | M12: =ABS(G$2-$F12)/1 | N12: =ABS(H$2-$F12)/1 | O12: =ABS(I$2-$F12)/1 | Q12: 1 | R12: =($J12/$J$13) * (G$13/$J$13) | S12: =($J12/$J$13) * (H$13/$J$13) | T12: =($J12/$J$13) * (I$13/$J$13) | V12: Cohen's Kappa | W12: =1-W10/W11 | X12: 1 - (D_obs / D_exp)
A13: ='Gemini 3 Pro Generation'!A13 | B13: ='Gemini 3 Pro Generation'!B13 | C13: ='Gemini 3 Pro Generation'!C13 | D13: ='Claude Sonnet 4.5 Gen'!C13 | F13: Column Totals | G13: =SUM(G10:G12) | H13: =SUM(H10:H12) | I13: =SUM(I10:I12) | J13: =SUM(G10:I12)
A14: ='Gemini 3 Pro Generation'!A14 | B14: ='Gemini 3 Pro Generation'!B14 | C14: ='Gemini 3 Pro Generation'!C14 | D14: ='Claude Sonnet 4.5 Gen'!C14
A15: ='Gemini 3 Pro Generation'!A15 | B15: ='Gemini 3 Pro Generation'!B15 | C15: ='Gemini 3 Pro Generation'!C15 | D15: ='Claude Sonnet 4.5 Gen'!C15 | F15: Confusion Matrix (Transition)
A16: ='Gemini 3 Pro Generation'!A16 | B16: ='Gemini 3 Pro Generation'!B16 | C16: ='Gemini 3 Pro Generation'!C16 | D16: ='Claude Sonnet 4.5 Gen'!C16 | F16: Transition | G16: 0 | H16: 0.5 | I16: 1 | J16: Row Totals | L16: Global | M16: 0 | N16: 0.5 | O16: 1 | Q16: Global | R16: 0 | S16: 0.5 | T16: 1 | V16: ="Metrics" & " " & F16 | W16: Value | X16: Note
A17: ='Gemini 3 Pro Generation'!A17 | B17: ='Gemini 3 Pro Generation'!B17 | C17: ='Gemini 3 Pro Generation'!C17 | D17: ='Claude Sonnet 4.5 Gen'!C17 | F17: 0 | G17: =COUNTIFS($A$2:$A$92,$F$16,$C$2:$C$92,$F17,$D$2:$D$92,G$16) | H17: =COUNTIFS($A$2:$A$92,$F$16,$C$2:$C$92,$F17,$D$2:$D$92,H$16) | I17: =COUNTIFS($A$2:$A$48,$F$16,$C$2:$C$48,$F17,$D$2:$D$48,I$16) + MAX(D50-C50,0) | J17: =SUM(G17:I17) | L17: 0 | M17: =ABS(G$2-$F17)/1 | N17: =ABS(H$2-$F17)/1 | O17: =ABS(I$2-$F17)/1 | Q17: 0 | R17: =($J17/$J$20) * (G$20/$J$20) | S17: =($J17/$J$20) * (H$20/$J$20) | T17: =($J17/$J$20) * (I$20/$J$20) | V17: Observed Weighted Disagreement (D_obs) | W17: =SUMPRODUCT(G17:I19, M17:O19) /$J$20 | X17: Sum of (confusion-matrix counts × weights) divided by total items.
A18: ='Gemini 3 Pro Generation'!A18 | B18: ='Gemini 3 Pro Generation'!B18 | C18: ='Gemini 3 Pro Generation'!C18 | D18: ='Claude Sonnet 4.5 Gen'!C18 | F18: 0.5 | G18: =COUNTIFS($A$2:$A$92,$F$16,$C$2:$C$92,$F18,$D$2:$D$92,G$16) | H18: =COUNTIFS($A$2:$A$92,$F$16,$C$2:$C$92,$F18,$D$2:$D$92,H$16) | I18: =COUNTIFS($A$2:$A$92,$F$16,$C$2:$C$92,$F18,$D$2:$D$92,I$16) | J18: =SUM(G18:I18) | L18: 0.5 | M18: =ABS(G$2-$F18)/1 | N18: =ABS(H$2-$F18)/3 | O18: =ABS(I$2-$F18)/1 | Q18: 0.5 | R18: =($J18/$J$20) * (G$20/$J$20) | S18: =($J18/$J$20) * (H$20/$J$20) | T18: =($J18/$J$20) * (I$20/$J$20) | V18: Expected Weighted Disagreement (D_exp) | W18: =SUMPRODUCT(R17:T19, M17:O19) | X18: Sum of (expected cell proportions × weights) under chance agreement.
A19: ='Gemini 3 Pro Generation'!A19 | B19: ='Gemini 3 Pro Generation'!B19 | C19: ='Gemini 3 Pro Generation'!C19 | D19: ='Claude Sonnet 4.5 Gen'!C19 | F19: 1 | G19: =COUNTIFS($A$2:$A$48,$F$16,$C$2:$C$48,$F19,$D$2:$D$48,G$16)+MAX(C50-D50,0) | H19: =COUNTIFS($A$2:$A$92,$F$16,$C$2:$C$92,$F19,$D$2:$D$92,H$16) | I19: =COUNTIFS($A$2:$A$48,$F$16,$C$2:$C$48,$F19,$D$2:$D$48,I$16) + MIN(C50,D50) | J19: =SUM(G19:I19) | L19: 1 | M19: =ABS(G$2-$F19)/1 | N19: =ABS(H$2-$F19)/1 | O19: =ABS(I$2-$F19)/1 | Q19: 1 | R19: =($J19/$J$20) * (G$20/$J$20) | S19: =($J19/$J$20) * (H$20/$J$20) | T19: =($J19/$J$20) * (I$20/$J$20) | V19: Cohen's Kappa | W19: =1-W17/W18 | X19: 1 - (D_obs / D_exp)
A20: ='Gemini 3 Pro Generation'!A20 | B20: ='Gemini 3 Pro Generation'!B20 | C20: ='Gemini 3 Pro Generation'!C20 | D20: ='Claude Sonnet 4.5 Gen'!C20 | F20: Column Totals | G20: =SUM(G17:G19) | H20: =SUM(H17:H19) | I20: =SUM(I17:I19) | J20: =SUM(G17:I19)
A21: ='Gemini 3 Pro Generation'!A21 | B21: ='Gemini 3 Pro Generation'!B21 | C21: ='Gemini 3 Pro Generation'!C21 | D21: ='Claude Sonnet 4.5 Gen'!C21
A22: ='Gemini 3 Pro Generation'!A22 | B22: ='Gemini 3 Pro Generation'!B22 | C22: ='Gemini 3 Pro Generation'!C22 | D22: ='Claude Sonnet 4.5 Gen'!C22 | F22: Confusion Matrix (Composite State)
A23: ='Gemini 3 Pro Generation'!A23 | B23: ='Gemini 3 Pro Generation'!B23 | C23: ='Gemini 3 Pro Generation'!C23 | D23: ='Claude Sonnet 4.5 Gen'!C23 | F23: Composite State | G23: 0 | H23: 0.5 | I23: 1 | J23: Row Totals | L23: Global | M23: 0 | N23: 0.5 | O23: 1 | Q23: Global | R23: 0 | S23: 0.5 | T23: 1 | V23: ="Metrics" & " " & F23 | W23: Value | X23: Note
A24: ='Gemini 3 Pro Generation'!A24 | B24: ='Gemini 3 Pro Generation'!B24 | C24: ='Gemini 3 Pro Generation'!C24 | D24: ='Claude Sonnet 4.5 Gen'!C24 | F24: 0 | G24: =COUNTIFS($A$2:$A$92,$F$23,$C$2:$C$92,$F24,$D$2:$D$92,G$23) | H24: =COUNTIFS($A$2:$A$92,$F$23,$C$2:$C$92,$F24,$D$2:$D$92,H$23) | I24: =COUNTIFS($A$2:$A$48,$F$23,$C$2:$C$48,$F24,$D$2:$D$48,I$23) + MAX(D53-C53,0) | J24: =SUM(G24:I24) | L24: 0 | M24: =ABS(G$2-$F24)/1 | N24: =ABS(H$2-$F24)/1 | O24: =ABS(I$2-$F24)/1 | Q24: 0 | R24: =($J24/$J$27) * (G$27/$J$27) | S24: =($J24/$J$27) * (H$27/$J$27) | T24: =($J24/$J$27) * (I$27/$J$27) | V24: Observed Weighted Disagreement (D_obs) | W24: =SUMPRODUCT(G24:I26, M24:O26) /$J$27 | X24: Sum of (confusion-matrix counts × weights) divided by total items.
A25: ='Gemini 3 Pro Generation'!A25 | B25: ='Gemini 3 Pro Generation'!B25 | C25: ='Gemini 3 Pro Generation'!C25 | D25: ='Claude Sonnet 4.5 Gen'!C25 | F25: 0.5 | G25: =COUNTIFS($A$2:$A$92,$F$23,$C$2:$C$92,$F25,$D$2:$D$92,G$23) | H25: =COUNTIFS($A$2:$A$92,$F$23,$C$2:$C$92,$F25,$D$2:$D$92,H$23) | I25: =COUNTIFS($A$2:$A$92,$F$23,$C$2:$C$92,$F25,$D$2:$D$92,I$23) | J25: =SUM(G25:I25) | L25: 0.5 | M25: =ABS(G$2-$F25)/1 | N25: =ABS(H$2-$F25)/3 | O25: =ABS(I$2-$F25)/1 | Q25: 0.5 | R25: =($J25/$J$27) * (G$27/$J$27) | S25: =($J25/$J$27) * (H$27/$J$27) | T25: =($J25/$J$27) * (I$27/$J$27) | V25: Expected Weighted Disagreement (D_exp) | W25: =SUMPRODUCT(R24:T26, M24:O26) | X25: Sum of (expected cell proportions × weights) under chance agreement.
A26: ='Gemini 3 Pro Generation'!A26 | B26: ='Gemini 3 Pro Generation'!B26 | C26: ='Gemini 3 Pro Generation'!C26 | D26: ='Claude Sonnet 4.5 Gen'!C26 | F26: 1 | G26: =COUNTIFS($A$2:$A$48,$F$23,$C$2:$C$48,$F26,$D$2:$D$48,G$23) + MAX(C53-D53,0) | H26: =COUNTIFS($A$2:$A$92,$F$23,$C$2:$C$92,$F26,$D$2:$D$92,H$23) | I26: =COUNTIFS($A$2:$A$48,$F$23,$C$2:$C$48,$F26,$D$2:$D$48,I$23) + MIN(C53,D53) | J26: =SUM(G26:I26) | L26: 1 | M26: =ABS(G$2-$F26)/1 | N26: =ABS(H$2-$F26)/1 | O26: =ABS(I$2-$F26)/1 | Q26: 1 | R26: =($J26/$J$27) * (G$27/$J$27) | S26: =($J26/$J$27) * (H$27/$J$27) | T26: =($J26/$J$27) * (I$27/$J$27) | V26: Cohen's Kappa | W26: =1-W24/W25 | X26: 1 - (D_obs / D_exp)
A27: ='Gemini 3 Pro Generation'!A27 | B27: ='Gemini 3 Pro Generation'!B27 | C27: ='Gemini 3 Pro Generation'!C27 | D27: ='Claude Sonnet 4.5 Gen'!C27 | F27: Column Totals | G27: =SUM(G24:G26) | H27: =SUM(H24:H26) | I27: =SUM(I24:I26) | J27: =SUM(G24:I26)
A28: ='Gemini 3 Pro Generation'!A28 | B28: ='Gemini 3 Pro Generation'!B28 | C28: ='Gemini 3 Pro Generation'!C28 | D28: ='Claude Sonnet 4.5 Gen'!C28
A29: ='Gemini 3 Pro Generation'!A29 | B29: ='Gemini 3 Pro Generation'!B29 | C29: ='Gemini 3 Pro Generation'!C29 | D29: ='Claude Sonnet 4.5 Gen'!C29 | F29: Confusion Matrix (Guard)
A30: ='Gemini 3 Pro Generation'!A30 | B30: ='Gemini 3 Pro Generation'!B30 | C30: ='Gemini 3 Pro Generation'!C30 | D30: ='Claude Sonnet 4.5 Gen'!C30 | F30: Guard | G30: 0 | H30: 0.5 | I30: 1 | J30: Row Totals | L30: Global | M30: 0 | N30: 0.5 | O30: 1 | Q30: Global | R30: 0 | S30: 0.5 | T30: 1 | V30: ="Metrics" & " " & F30 | W30: Value | X30: Note
A31: ='Gemini 3 Pro Generation'!A31 | B31: ='Gemini 3 Pro Generation'!B31 | C31: ='Gemini 3 Pro Generation'!C31 | D31: ='Claude Sonnet 4.5 Gen'!C31 | F31: 0 | G31: =COUNTIFS($A$2:$A$92,$F$30,$C$2:$C$92,$F31,$D$2:$D$92,G$30) | H31: =COUNTIFS($A$2:$A$92,$F$30,$C$2:$C$92,$F31,$D$2:$D$92,H$30) | I31: =COUNTIFS($A$2:$A$48,$F$30,$C$2:$C$48,$F31,$D$2:$D$48,I$30) + MAX(D51-C51,0) | J31: =SUM(G31:I31) | L31: 0 | M31: =ABS(G$2-$F31)/1 | N31: =ABS(H$2-$F31)/1 | O31: =ABS(I$2-$F31)/1 | Q31: 0 | R31: =($J31/$J$34) * (G$34/$J$34) | S31: =($J31/$J$34) * (H$34/$J$34) | T31: =($J31/$J$34) * (I$34/$J$34) | V31: Observed Weighted Disagreement (D_obs) | W31: =SUMPRODUCT(G31:I33, M31:O33) /$J$34 | X31: Sum of (confusion-matrix counts × weights) divided by total items.
A32: ='Gemini 3 Pro Generation'!A32 | B32: ='Gemini 3 Pro Generation'!B32 | C32: ='Gemini 3 Pro Generation'!C32 | D32: ='Claude Sonnet 4.5 Gen'!C32 | F32: 0.5 | G32: =COUNTIFS($A$2:$A$92,$F$30,$C$2:$C$92,$F32,$D$2:$D$92,G$30) | H32: =COUNTIFS($A$2:$A$92,$F$30,$C$2:$C$92,$F32,$D$2:$D$92,H$30) | I32: =COUNTIFS($A$2:$A$92,$F$30,$C$2:$C$92,$F32,$D$2:$D$92,I$30) | J32: =SUM(G32:I32) | L32: 0.5 | M32: =ABS(G$2-$F32)/1 | N32: =ABS(H$2-$F32)/3 | O32: =ABS(I$2-$F32)/1 | Q32: 0.5 | R32: =($J32/$J$34) * (G$34/$J$34) | S32: =($J32/$J$34) * (H$34/$J$34) | T32: =($J32/$J$34) * (I$34/$J$34) | V32: Expected Weighted Disagreement (D_exp) | W32: =SUMPRODUCT(R31:T33, M31:O33) | X32: Sum of (expected cell proportions × weights) under chance agreement.
A33: ='Gemini 3 Pro Generation'!A33 | B33: ='Gemini 3 Pro Generation'!B33 | C33: ='Gemini 3 Pro Generation'!C33 | D33: ='Claude Sonnet 4.5 Gen'!C33 | F33: 1 | G33: =COUNTIFS($A$2:$A$48,$F$30,$C$2:$C$48,$F33,$D$2:$D$48,G$30) + MAX(C51-D51,0) | H33: =COUNTIFS($A$2:$A$92,$F$30,$C$2:$C$92,$F33,$D$2:$D$92,H$30) | I33: =COUNTIFS($A$2:$A$48,$F$30,$C$2:$C$48,$F33,$D$2:$D$48,I$30) + MIN(C51,D51) | J33: =SUM(G33:I33) | L33: 1 | M33: =ABS(G$2-$F33)/1 | N33: =ABS(H$2-$F33)/1 | O33: =ABS(I$2-$F33)/1 | Q33: 1 | R33: =($J33/$J$34) * (G$34/$J$34) | S33: =($J33/$J$34) * (H$34/$J$34) | T33: =($J33/$J$34) * (I$34/$J$34) | V33: Cohen's Kappa | W33: =1-W31/W32 | X33: 1 - (D_obs / D_exp)
A34: ='Gemini 3 Pro Generation'!A34 | B34: ='Gemini 3 Pro Generation'!B34 | C34: ='Gemini 3 Pro Generation'!C34 | D34: ='Claude Sonnet 4.5 Gen'!C34 | F34: Column Totals | G34: =SUM(G31:G33) | H34: =SUM(H31:H33) | I34: =SUM(I31:I33) | J34: =SUM(G31:I33)
A35: ='Gemini 3 Pro Generation'!A35 | B35: ='Gemini 3 Pro Generation'!B35 | C35: ='Gemini 3 Pro Generation'!C35 | D35: ='Claude Sonnet 4.5 Gen'!C35
A36: ='Gemini 3 Pro Generation'!A36 | B36: ='Gemini 3 Pro Generation'!B36 | C36: ='Gemini 3 Pro Generation'!C36 | D36: ='Claude Sonnet 4.5 Gen'!C36 | F36: Confusion Matrix (Action)
A37: ='Gemini 3 Pro Generation'!A37 | B37: ='Gemini 3 Pro Generation'!B37 | C37: ='Gemini 3 Pro Generation'!C37 | D37: ='Claude Sonnet 4.5 Gen'!C37 | F37: Action | G37: 0 | H37: 0.5 | I37: 1 | J37: Row Totals | L37: Global | M37: 0 | N37: 0.5 | O37: 1 | Q37: Global | R37: 0 | S37: 0.5 | T37: 1 | V37: ="Metrics" & " " & F37 | W37: Value | X37: Note
A38: ='Gemini 3 Pro Generation'!A38 | B38: ='Gemini 3 Pro Generation'!B38 | C38: ='Gemini 3 Pro Generation'!C38 | D38: ='Claude Sonnet 4.5 Gen'!C38 | F38: 0 | G38: =COUNTIFS($A$2:$A$92,$F$37,$C$2:$C$92,$F38,$D$2:$D$92,G$37) | H38: =COUNTIFS($A$2:$A$92,$F$37,$C$2:$C$92,$F38,$D$2:$D$92,H$37) | I38: =COUNTIFS($A$2:$A$48,$F$37,$C$2:$C$48,$F38,$D$2:$D$48,I$37)+MAX(D52-C52,0) | J38: =SUM(G38:I38) | L38: 0 | M38: =ABS(G$2-$F38)/1 | N38: =ABS(H$2-$F38)/1 | O38: =ABS(I$2-$F38)/1 | Q38: 0 | R38: =($J38/$J$41) * (G$41/$J$41) | S38: =($J38/$J$41) * (H$41/$J$41) | T38: =($J38/$J$41) * (I$41/$J$41) | V38: Observed Weighted Disagreement (D_obs) | W38: =SUMPRODUCT(G38:I40, M38:O40) /$J$41 | X38: Sum of (confusion-matrix counts × weights) divided by total items.
A39: ='Gemini 3 Pro Generation'!A39 | B39: ='Gemini 3 Pro Generation'!B39 | C39: ='Gemini 3 Pro Generation'!C39 | D39: ='Claude Sonnet 4.5 Gen'!C39 | F39: 0.5 | G39: =COUNTIFS($A$2:$A$92,$F$37,$C$2:$C$92,$F39,$D$2:$D$92,G$37) | H39: =COUNTIFS($A$2:$A$92,$F$37,$C$2:$C$92,$F39,$D$2:$D$92,H$37) | I39: =COUNTIFS($A$2:$A$92,$F$37,$C$2:$C$92,$F39,$D$2:$D$92,I$37) | J39: =SUM(G39:I39) | L39: 0.5 | M39: =ABS(G$2-$F39)/1 | N39: =ABS(H$2-$F39)/3 | O39: =ABS(I$2-$F39)/1 | Q39: 0.5 | R39: =($J39/$J$41) * (G$41/$J$41) | S39: =($J39/$J$41) * (H$41/$J$41) | T39: =($J39/$J$41) * (I$41/$J$41) | V39: Expected Weighted Disagreement (D_exp) | W39: =SUMPRODUCT(R38:T40, M38:O40) | X39: Sum of (expected cell proportions × weights) under chance agreement.
A40: ='Gemini 3 Pro Generation'!A40 | B40: ='Gemini 3 Pro Generation'!B40 | C40: ='Gemini 3 Pro Generation'!C40 | D40: ='Claude Sonnet 4.5 Gen'!C40 | F40: 1 | G40: =COUNTIFS($A$2:$A$48,$F$37,$C$2:$C$48,$F40,$D$2:$D$48,G$37)+MAX(C52-D52,0) | H40: =COUNTIFS($A$2:$A$92,$F$37,$C$2:$C$92,$F40,$D$2:$D$92,H$37) | I40: =COUNTIFS($A$2:$A$48,$F$37,$C$2:$C$48,$F40,$D$2:$D$48,I$37) + MIN(C52,D52) | J40: =SUM(G40:I40) | L40: 1 | M40: =ABS(G$2-$F40)/1 | N40: =ABS(H$2-$F40)/1 | O40: =ABS(I$2-$F40)/1 | Q40: 1 | R40: =($J40/$J$41) * (G$41/$J$41) | S40: =($J40/$J$41) * (H$41/$J$41) | T40: =($J40/$J$41) * (I$41/$J$41) | V40: Cohen's Kappa | W40: =1-W38/W39 | X40: 1 - (D_obs / D_exp)
...
